{"channel":"l2_data","client_id":"","timestamp":"2025-10-27T17:39:38.270327702Z","sequence_num":137496,"events":[{"type":"update","product_id":"ETH-USD","updates":[{"side":"bid","event_time":"2025-10-27T17:39:38.225961Z","price_level":"4218.71","new_quantity":"0.06811418"},{"side":"bid","event_time":"2025-10-27T17:39:38.225961Z","price_level":"4217.94","new_quantity":"0.002"},{"side":"bid","event_time":"2025-10-27T17:39:38.225961Z","price_level":"4215.84","new_quantity":"0.37635091"},{"side":"offer","event_time":"2025-10-27T17:39:38.225961Z","price_level":"4220","new_quantity":"22.80517286"},{"side":"offer","event_time":"2025-10-27T17:39:38.225961Z","price_level":"4220.2","new_quantity":"20"}]}]}
{"channel":"l2_data","client_id":"","timestamp":"2025-10-27T17:39:38.297653834Z","sequence_num":137497,"events":[{"type":"update","product_id":"BTC-USD","updates":[{"side":"bid","event_time":"2025-10-27T17:39:38.242825Z","price_level":"115634","new_quantity":"0.4"},{"side":"bid","event_time":"2025-10-27T17:39:38.242825Z","price_level":"115633.01","new_quantity":"1.19351579"},{"side":"bid","event_time":"2025-10-27T17:39:38.242825Z","price_level":"115633","new_quantity":"0"},{"side":"bid","event_time":"2025-10-27T17:39:38.242825Z","price_level":"115632","new_quantity":"0"},{"side":"offer","event_time":"2025-10-27T17:39:38.242825Z","price_level":"115689.59","new_quantity":"0.00163919"}]}]}
{"channel":"l2_data","client_id":"","timestamp":"2025-10-27T17:39:39.550105628Z","sequence_num":137555,"events":[{"type":"update","product_id":"BTC-USD","updates":[{"side":"bid","event_time":"2025-10-27T17:39:39.509102Z","price_level":"115662.06","new_quantity":"0.00008646"},{"side":"bid","event_time":"2025-10-27T17:39:39.509102Z","price_level":"115662","new_quantity":"0"},{"side":"bid","event_time":"2025-10-27T17:39:39.509102Z","price_level":"115658.01","new_quantity":"0.00172923"},{"side":"bid","event_time":"2025-10-27T17:39:39.509102Z","price_level":"115658","new_quantity":"0.0236"},{"side":"bid","event_time":"2025-10-27T17:39:39.509102Z","price_level":"115657.17","new_quantity":"0.00017293"},{"side":"bid","event_time":"2025-10-27T17:39:39.509102Z","price_level":"115652.89","new_quantity":"0"},{"side":"bid","event_time":"2025-10-27T17:39:39.509102Z","price_level":"115651.24","new_quantity":"0.02160751"},{"side":"bid","event_time":"2025-10-27T17:39:39.509102Z","price_level":"115640.32","new_quantity":"0.32979813"},{"side":"bid","event_time":"2025-10-27T17:39:39.509102Z","price_level":"115638","new_quantity":"0"},{"side":"bid","event_time":"2025-10-27T17:39:39.509102Z","price_level":"115637","new_quantity":"0.4"},{"side":"bid","event_time":"2025-10-27T17:39:39.509102Z","price_level":"115634.69","new_quantity":"0"},{"side":"bid","event_time":"2025-10-27T17:39:39.509102Z","price_level":"115634","new_quantity":"0"},{"side":"bid","event_time":"2025-10-27T17:39:39.509102Z","price_level":"115633.02","new_quantity":"0.33119962"},{"side":"bid","event_time":"2025-10-27T17:39:39.509102Z","price_level":"115633.01","new_quantity":"1.99612714"},{"side":"bid","event_time":"2025-10-27T17:39:39.509102Z","price_level":"115632","new_quantity":"0"},{"side":"bid","event_time":"2025-10-27T17:39:39.509102Z","price_level":"115631","new_quantity":"2"},{"side":"bid","event_time":"2025-10-27T17:39:39.509102Z","price_level":"115627.77","new_quantity":"0"},{"side":"bid","event_time":"2025-10-27T17:39:39.509102Z","price_level":"115620.65","new_quantity":"0"},{"side":"bid","event_time":"2025-10-27T17:39:39.509102Z","price_level":"115617.03","new_quantity":"0.52630163"},{"side":"bid","event_time":"2025-10-27T17:39:39.509102Z","price_level":"115600.02","new_quantity":"0"},{"side":"bid","event_time":"2025-10-27T17:39:39.509102Z","price_level":"115596.71","new_quantity":"0.76375243"},{"side":"bid","event_time":"2025-10-27T17:39:39.509102Z","price_level":"115594.8","new_quantity":"0"},{"side":"bid","event_time":"2025-10-27T17:39:39.509102Z","price_level":"115587.8","new_quantity":"1.5"},{"side":"bid","event_time":"2025-10-27T17:39:39.509102Z","price_level":"115587.2","new_quantity":"0"},{"side":"bid","event_time":"2025-10-27T17:39:39.509102Z","price_level":"114125.84","new_quantity":"0.07007"},{"side":"bid","event_time":"2025-10-27T17:39:39.509102Z","price_level":"114125.55","new_quantity":"0"},{"side":"bid","event_time":"2025-10-27T17:39:39.509102Z","price_level":"101204.31","new_quantity":"0.0049568"},{"side":"offer","event_time":"2025-10-27T17:39:39.509102Z","price_level":"115689.73","new_quantity":"0.16808983"},{"side":"offer","event_time":"2025-10-27T17:39:39.509102Z","price_level":"115697.98","new_quantity":"0.13833542"},{"side":"offer","event_time":"2025-10-27T17:39:39.509102Z","price_level":"115700","new_quantity":"0"},{"side":"offer","event_time":"2025-10-27T17:39:39.509102Z","price_level":"115707.19","new_quantity":"0"},{"side":"offer","event_time":"2025-10-27T17:39:39.509102Z","price_level":"115708.17","new_quantity":"0"},{"side":"offer","event_time":"2025-10-27T17:39:39.509102Z","price_level":"115715.05","new_quantity":"0.08"},{"side":"offer","event_time":"2025-10-27T17:39:39.509102Z","price_level":"115729.98","new_quantity":"0.25112503"},{"side":"offer","event_time":"2025-10-27T17:39:39.509102Z","price_level":"115735.11","new_quantity":"0"},{"side":"offer","event_time":"2025-10-27T17:39:39.509102Z","price_level":"115737.89","new_quantity":"0.37930022"},{"side":"offer","event_time":"2025-10-27T17:39:39.509102Z","price_level":"115737.9","new_quantity":"0"},{"side":"offer","event_time":"2025-10-27T17:39:39.509102Z","price_level":"115738","new_quantity":"1"},{"side":"offer","event_time":"2025-10-27T17:39:39.509102Z","price_level":"115738.6","new_quantity":"0"},{"side":"offer","event_time":"2025-10-27T17:39:39.509102Z","price_level":"115743.91","new_quantity":"0.57739702"},{"side":"offer","event_time":"2025-10-27T17:39:39.509102Z","price_level":"115743.92","new_quantity":"0"},{"side":"offer","event_time":"2025-10-27T17:39:39.509102Z","price_level":"115747.15","new_quantity":"0"}]}]}
{"channel":"l2_data","client_id":"","timestamp":"2025-10-27T17:39:39.570736653Z","sequence_num":137556,"events":[{"type":"update","product_id":"ETH-USD","updates":[{"side":"bid","event_time":"2025-10-27T17:39:39.527837Z","price_level":"4218.67","new_quantity":"0.51587403"},{"side":"bid","event_time":"2025-10-27T17:39:39.527837Z","price_level":"4218.63","new_quantity":"0.07108939"},{"side":"bid","event_time":"2025-10-27T17:39:39.527837Z","price_level":"4218.5","new_quantity":"20"},{"side":"bid","event_time":"2025-10-27T17:39:39.527837Z","price_level":"4218.28","new_quantity":"0"},{"side":"bid","event_time":"2025-10-27T17:39:39.527837Z","price_level":"4218.05","new_quantity":"0.11853807"},{"side":"offer","event_time":"2025-10-27T17:39:39.527837Z","price_level":"4218.68","new_quantity":"0.19658461"},{"side":"offer","event_time":"2025-10-27T17:39:39.527837Z","price_level":"4218.7","new_quantity":"0.519"},{"side":"offer","event_time":"2025-10-27T17:39:39.527837Z","price_level":"4218.99","new_quantity":"0.981468"},{"side":"offer","event_time":"2025-10-27T17:39:39.527837Z","price_level":"4219.2","new_quantity":"0.5610979"},{"side":"offer","event_time":"2025-10-27T17:39:39.527837Z","price_level":"4219.56","new_quantity":"1.51597847"},{"side":"offer","event_time":"2025-10-27T17:39:39.527837Z","price_level":"4221.96","new_quantity":"13.30031746"},{"side":"offer","event_time":"2025-10-27T17:39:39.527837Z","price_level":"4222.18","new_quantity":"0"},{"side":"offer","event_time":"2025-10-27T17:39:39.527837Z","price_level":"4222.19","new_quantity":"0"},{"side":"offer","event_time":"2025-10-27T17:39:39.527837Z","price_level":"4222.38","new_quantity":"1.94391607"}]}]}
{"channel":"l2_data","client_id":"","timestamp":"2025-10-27T17:39:39.598424754Z","sequence_num":137558,"events":[{"type":"update","product_id":"BTC-USD","updates":[{"side":"bid","event_time":"2025-10-27T17:39:39.561886Z","price_level":"115631","new_quantity":"2.4"},{"side":"bid","event_time":"2025-10-27T17:39:39.561886Z","price_level":"115587.8","new_quantity":"0"},{"side":"bid","event_time":"2025-10-27T17:39:39.561886Z","price_level":"115587.3","new_quantity":"1.5"},{"side":"bid","event_time":"2025-10-27T17:39:39.561886Z","price_level":"114933.48","new_quantity":"0"},{"side":"offer","event_time":"2025-10-27T17:39:39.561886Z","price_level":"115689.73","new_quantity":"0.21584984"},{"side":"offer","event_time":"2025-10-27T17:39:39.561886Z","price_level":"115707.67","new_quantity":"0.5"},{"side":"offer","event_time":"2025-10-27T17:39:39.561886Z","price_level":"115714.35","new_quantity":"0.2"},{"side":"offer","event_time":"2025-10-27T17:39:39.561886Z","price_level":"115737.9","new_quantity":"1"},{"side":"offer","event_time":"2025-10-27T17:39:39.561886Z","price_level":"115738","new_quantity":"0"}]}]}
{"channel":"l2_data","client_id":"","timestamp":"2025-10-27T17:39:39.619753275Z","sequence_num":137559,"events":[{"type":"update","product_id":"ETH-USD","updates":[{"side":"bid","event_time":"2025-10-27T17:39:39.562464Z","price_level":"4218.52","new_quantity":"0.00199465"},{"side":"bid","event_time":"2025-10-27T17:39:39.562464Z","price_level":"4218.48","new_quantity":"0.09083226"},{"side":"bid","event_time":"2025-10-27T17:39:39.562464Z","price_level":"4218.47","new_quantity":"0.00198373"},{"side":"bid","event_time":"2025-10-27T17:39:39.562464Z","price_level":"4218.41","new_quantity":"0"},{"side":"bid","event_time":"2025-10-27T17:39:39.562464Z","price_level":"4218.17","new_quantity":"0.59267306"}]}]}
{"channel":"l2_data","client_id":"","timestamp":"2025-10-27T17:39:39.644385805Z","sequence_num":137561,"events":[{"type":"update","product_id":"BTC-USD","updates":[{"side":"offer","event_time":"2025-10-27T17:39:39.590131Z","price_level":"115689.73","new_quantity":"1.80525587"},{"side":"offer","event_time":"2025-10-27T17:39:39.590131Z","price_level":"115692","new_quantity":"2.4"},{"side":"offer","event_time":"2025-10-27T17:39:39.590131Z","price_level":"115700","new_quantity":"1"},{"side":"offer","event_time":"2025-10-27T17:39:39.590131Z","price_level":"115707.67","new_quantity":"0"},{"side":"offer","event_time":"2025-10-27T17:39:39.590131Z","price_level":"115708.19","new_quantity":"0.5"},{"side":"offer","event_time":"2025-10-27T17:39:39.590131Z","price_level":"115737.89","new_quantity":"0.37973245"},{"side":"offer","event_time":"2025-10-27T17:39:39.590131Z","price_level":"115738.38","new_quantity":"0"}]}]}
{"channel":"l2_data","client_id":"","timestamp":"2025-10-27T17:39:39.668689004Z","sequence_num":137562,"events":[{"type":"update","product_id":"ETH-USD","updates":[{"side":"bid","event_time":"2025-10-27T17:39:39.63434Z","price_level":"4218.11","new_quantity":"0"},{"side":"bid","event_time":"2025-10-27T17:39:39.63434Z","price_level":"4217.96","new_quantity":"1.65749"}]}]}
{"channel":"l2_data","client_id":"","timestamp":"2025-10-27T17:39:39.698746537Z","sequence_num":137563,"events":[{"type":"update","product_id":"BTC-USD","updates":[{"side":"bid","event_time":"2025-10-27T17:39:39.645514Z","price_level":"115640.32","new_quantity":"0.10433747"},{"side":"bid","event_time":"2025-10-27T17:39:39.645514Z","price_level":"115637","new_quantity":"0"},{"side":"bid","event_time":"2025-10-27T17:39:39.645514Z","price_level":"115629","new_quantity":"0"},{"side":"bid","event_time":"2025-10-27T17:39:39.645514Z","price_level":"115627.46","new_quantity":"0.0069609"},{"side":"offer","event_time":"2025-10-27T17:39:39.645514Z","price_level":"115689.73","new_quantity":"0.21584984"},{"side":"offer","event_time":"2025-10-27T17:39:39.645514Z","price_level":"115692","new_quantity":"0"},{"side":"offer","event_time":"2025-10-27T17:39:39.645514Z","price_level":"115692.99","new_quantity":"0.13833542"},{"side":"offer","event_time":"2025-10-27T17:39:39.645514Z","price_level":"115697.98","new_quantity":"0"},{"side":"offer","event_time":"2025-10-27T17:39:39.645514Z","price_level":"115698","new_quantity":"0"},{"side":"offer","event_time":"2025-10-27T17:39:39.645514Z","price_level":"115700","new_quantity":"0"},{"side":"offer","event_time":"2025-10-27T17:39:39.645514Z","price_level":"115708.19","new_quantity":"0"}]}]}
{"channel":"l2_data","client_id":"","timestamp":"2025-10-27T17:39:39.746847591Z","sequence_num":137564,"events":[{"type":"update","product_id":"BTC-USD","updates":[{"side":"bid","event_time":"2025-10-27T17:39:39.696359Z","price_level":"115640.32","new_quantity":"0.32979813"},{"side":"bid","event_time":"2025-10-27T17:39:39.696359Z","price_level":"115636","new_quantity":"0.4"},{"side":"bid","event_time":"2025-10-27T17:39:39.696359Z","price_level":"115631","new_quantity":"2"},{"side":"offer","event_time":"2025-10-27T17:39:39.696359Z","price_level":"115689.73","new_quantity":"0.42705386"},{"side":"offer","event_time":"2025-10-27T17:39:39.696359Z","price_level":"115690","new_quantity":"0.4"},{"side":"offer","event_time":"2025-10-27T17:39:39.696359Z","price_level":"115696","new_quantity":"0.4"}]}]}
{"channel":"l2_data","client_id":"","timestamp":"2025-10-27T17:39:39.771738865Z","sequence_num":137565,"events":[{"type":"update","product_id":"ETH-USD","updates":[{"side":"bid","event_time":"2025-10-27T17:39:39.73383Z","price_level":"4218.67","new_quantity":"0"},{"side":"bid","event_time":"2025-10-27T17:39:39.73383Z","price_level":"4218.63","new_quantity":"0"},{"side":"bid","event_time":"2025-10-27T17:39:39.73383Z","price_level":"4218.61","new_quantity":"0"},{"side":"bid","event_time":"2025-10-27T17:39:39.73383Z","price_level":"4218.6","new_quantity":"0"},{"side":"bid","event_time":"2025-10-27T17:39:39.73383Z","price_level":"4218.4","new_quantity":"30"},{"side":"bid","event_time":"2025-10-27T17:39:39.73383Z","price_level":"4218.33","new_quantity":"0"},{"side":"bid","event_time":"2025-10-27T17:39:39.73383Z","price_level":"4218.22","new_quantity":"0"},{"side":"bid","event_time":"2025-10-27T17:39:39.73383Z","price_level":"4218.21","new_quantity":"0.00237068"},{"side":"bid","event_time":"2025-10-27T17:39:39.73383Z","price_level":"4218.17","new_quantity":"0"},{"side":"bid","event_time":"2025-10-27T17:39:39.73383Z","price_level":"4218.05","new_quantity":"0"},{"side":"bid","event_time":"2025-10-27T17:39:39.73383Z","price_level":"4218.02","new_quantity":"0"},{"side":"bid","event_time":"2025-10-27T17:39:39.73383Z","price_level":"4218.01","new_quantity":"6.591477"},{"side":"bid","event_time":"2025-10-27T17:39:39.73383Z","price_level":"4218","new_quantity":"10.52"},{"side":"bid","event_time":"2025-10-27T17:39:39.73383Z","price_level":"4217.96","new_quantity":"0"},{"side":"bid","event_time":"2025-10-27T17:39:39.73383Z","price_level":"4217.9","new_quantity":"0.519"},{"side":"bid","event_time":"2025-10-27T17:39:39.73383Z","price_level":"4217.88","new_quantity":"0"},{"side":"bid","event_time":"2025-10-27T17:39:39.73383Z","price_level":"4217.85","new_quantity":"1.09587805"},{"side":"bid","event_time":"2025-10-27T17:39:39.73383Z","price_level":"4217.76","new_quantity":"0"},{"side":"bid","event_time":"2025-10-27T17:39:39.73383Z","price_level":"4217.74","new_quantity":"1.71773449"},{"side":"bid","event_time":"2025-10-27T17:39:39.73383Z","price_level":"4217.62","new_quantity":"5.7793701"},{"side":"bid","event_time":"2025-10-27T17:39:39.73383Z","price_level":"4217.5","new_quantity":"0.147968"},{"side":"bid","event_time":"2025-10-27T17:39:39.73383Z","price_level":"4217.45","new_quantity":"0.5927752"},{"side":"bid","event_time":"2025-10-27T17:39:39.73383Z","price_level":"4216.34","new_quantity":"4.59332125"},{"side":"bid","event_time":"2025-10-27T17:39:39.73383Z","price_level":"4215.46","new_quantity":"0"},{"side":"bid","event_time":"2025-10-27T17:39:39.73383Z","price_level":"4215.34","new_quantity":"0"},{"side":"bid","event_time":"2025-10-27T17:39:39.73383Z","price_level":"4215.01","new_quantity":"8.84592291"},{"side":"bid","event_time":"2025-10-27T17:39:39.73383Z","price_level":"4214.51","new_quantity":"0"},{"side":"bid","event_time":"2025-10-27T17:39:39.73383Z","price_level":"4214.3","new_quantity":"12.86558314"},{"side":"bid","event_time":"2025-10-27T17:39:39.73383Z","price_level":"4214.29","new_quantity":"11.71776636"},{"side":"bid","event_time":"2025-10-27T17:39:39.73383Z","price_level":"4214.28","new_quantity":"0.0019612"},{"side":"bid","event_time":"2025-10-27T17:39:39.73383Z","price_level":"4214.02","new_quantity":"19.62370173"},{"side":"bid","event_time":"2025-10-27T17:39:39.73383Z","price_level":"4212.01","new_quantity":"27.61107902"},{"side":"bid","event_time":"2025-10-27T17:39:39.73383Z","price_level":"4211.1","new_quantity":"0"},{"side":"offer","event_time":"2025-10-27T17:39:39.73383Z","price_level":"4218.61","new_quantity":"0.00237033"},{"side":"offer","event_time":"2025-10-27T17:39:39.73383Z","price_level":"4218.63","new_quantity":"0.11852188"},{"side":"offer","event_time":"2025-10-27T17:39:39.73383Z","price_level":"4218.67","new_quantity":"0.59260435"},{"side":"offer","event_time":"2025-10-27T17:39:39.73383Z","price_level":"4218.68","new_quantity":"0.01682268"},{"side":"offer","event_time":"2025-10-27T17:39:39.73383Z","price_level":"4218.69","new_quantity":"0"},{"side":"offer","event_time":"2025-10-27T17:39:39.73383Z","price_level":"4218.83","new_quantity":"0.59258135"},{"side":"offer","event_time":"2025-10-27T17:39:39.73383Z","price_level":"4219.55","new_quantity":"0.01508562"},{"side":"offer","event_time":"2025-10-27T17:39:39.73383Z","price_level":"4219.84","new_quantity":"4.244419"},{"side":"offer","event_time":"2025-10-27T17:39:39.73383Z","price_level":"4220.5","new_quantity":"14.32066043"},{"side":"offer","event_time":"2025-10-27T17:39:39.73383Z","price_level":"4220.83","new_quantity":"8.54377496"},{"side":"offer","event_time":"2025-10-27T17:39:39.73383Z","price_level":"4221.1","new_quantity":"0"},{"side":"offer","event_time":"2025-10-27T17:39:39.73383Z","price_level":"4221.9","new_quantity":"13.50968709"},{"side":"offer","event_time":"2025-10-27T17:39:39.73383Z","price_level":"4221.95","new_quantity":"1.94391607"},{"side":"offer","event_time":"2025-10-27T17:39:39.73383Z","price_level":"4221.96","new_quantity":"0"},{"side":"offer","event_time":"2025-10-27T17:39:39.73383Z","price_level":"4222.38","new_quantity":"0"},{"side":"offer","event_time":"2025-10-27T17:39:39.73383Z","price_level":"4223.25","new_quantity":"9.52576174"},{"side":"offer","event_time":"2025-10-27T17:39:39.73383Z","price_level":"4223.45","new_quantity":"0.19999622"}]}]}
{"channel":"l2_data","client_id":"","timestamp":"2025-10-27T17:39:39.297845041Z","sequence_num":137550,"events":[{"type":"update","product_id":"BTC-USD","updates":[{"side":"bid","event_time":"2025-10-27T17:39:39.210514Z","price_level":"115652.89","new_quantity":"0.02160751"},{"side":"bid","event_time":"2025-10-27T17:39:39.210514Z","price_level":"115651.75","new_quantity":"0"},{"side":"bid","event_time":"2025-10-27T17:39:39.210514Z","price_level":"115640.32","new_quantity":"0.53977343"},{"side":"bid","event_time":"2025-10-27T17:39:39.210514Z","price_level":"115636","new_quantity":"0.4"},{"side":"bid","event_time":"2025-10-27T17:39:39.210514Z","price_level":"115634.01","new_quantity":"0.33119679"},{"side":"bid","event_time":"2025-10-27T17:39:39.210514Z","price_level":"115634","new_quantity":"0.4"},{"side":"bid","event_time":"2025-10-27T17:39:39.210514Z","price_level":"115633.02","new_quantity":"0"},{"side":"bid","event_time":"2025-10-27T17:39:39.210514Z","price_level":"115633","new_quantity":"0"},{"side":"bid","event_time":"2025-10-27T17:39:39.210514Z","price_level":"115617.03","new_quantity":"0.52630163"},{"side":"bid","event_time":"2025-10-27T17:39:39.210514Z","price_level":"115617.02","new_quantity":"0.65208427"},{"side":"bid","event_time":"2025-10-27T17:39:39.210514Z","price_level":"115612.8","new_quantity":"0"},{"side":"bid","event_time":"2025-10-27T17:39:39.210514Z","price_level":"115582.34","new_quantity":"1.22293397"},{"side":"bid","event_time":"2025-10-27T17:39:39.210514Z","price_level":"114364.17","new_quantity":"0.02798079"},{"side":"bid","event_time":"2025-10-27T17:39:39.210514Z","price_level":"113808.49","new_quantity":"0.04217612"},{"side":"bid","event_time":"2025-10-27T17:39:39.210514Z","price_level":"113252.8","new_quantity":"0.05651074"},{"side":"offer","event_time":"2025-10-27T17:39:39.210514Z","price_level":"115697.98","new_quantity":"0.13833542"},{"side":"offer","event_time":"2025-10-27T17:39:39.210514Z","price_level":"115697.99","new_quantity":"0.38903253"},{"side":"offer","event_time":"2025-10-27T17:39:39.210514Z","price_level":"115698","new_quantity":"0.4"},{"side":"offer","event_time":"2025-10-27T17:39:39.210514Z","price_level":"115699","new_quantity":"0"},{"side":"offer","event_time":"2025-10-27T17:39:39.210514Z","price_level":"115706.52","new_quantity":"0.02014916"}]}]}
{"channel":"l2_data","client_id":"","timestamp":"2025-10-27T17:39:39.499095059Z","sequence_num":137553,"events":[{"type":"update","product_id":"BTC-USD","updates":[{"side":"bid","event_time":"2025-10-27T17:39:39.394806Z","price_level":"115662.06","new_quantity":"0.03497193"},{"side":"bid","event_time":"2025-10-27T17:39:39.394806Z","price_level":"115653.47","new_quantity":"0.011239"},{"side":"bid","event_time":"2025-10-27T17:39:39.394806Z","price_level":"115652.78","new_quantity":"0"},{"side":"bid","event_time":"2025-10-27T17:39:39.394806Z","price_level":"115650.65","new_quantity":"0.00864673"},{"side":"bid","event_time":"2025-10-27T17:39:39.394806Z","price_level":"115646.83","new_quantity":"0"},{"side":"bid","event_time":"2025-10-27T17:39:39.394806Z","price_level":"115646.8","new_quantity":"0"},{"side":"bid","event_time":"2025-10-27T17:39:39.394806Z","price_level":"115640.32","new_quantity":"0.50224291"},{"side":"bid","event_time":"2025-10-27T17:39:39.394806Z","price_level":"115639","new_quantity":"0"},{"side":"bid","event_time":"2025-10-27T17:39:39.394806Z","price_level":"115638","new_quantity":"0.4"},{"side":"bid","event_time":"2025-10-27T17:39:39.394806Z","price_level":"115636","new_quantity":"0"},{"side":"bid","event_time":"2025-10-27T17:39:39.394806Z","price_level":"115634.69","new_quantity":"0.33119484"},{"side":"bid","event_time":"2025-10-27T17:39:39.394806Z","price_level":"115634.01","new_quantity":"0"},{"side":"bid","event_time":"2025-10-27T17:39:39.394806Z","price_level":"115620.65","new_quantity":"0.52628515"},{"side":"bid","event_time":"2025-10-27T17:39:39.394806Z","price_level":"115617.03","new_quantity":"0"},{"side":"bid","event_time":"2025-10-27T17:39:39.394806Z","price_level":"115600.02","new_quantity":"0.76373056"},{"side":"bid","event_time":"2025-10-27T17:39:39.394806Z","price_level":"115596.71","new_quantity":"0"},{"side":"bid","event_time":"2025-10-27T17:39:39.394806Z","price_level":"115511.79","new_quantity":"0"},{"side":"bid","event_time":"2025-10-27T17:39:39.394806Z","price_level":"114933.48","new_quantity":"0.045"},{"side":"bid","event_time":"2025-10-27T17:39:39.394806Z","price_level":"114769.33","new_quantity":"0.07007"},{"side":"bid","event_time":"2025-10-27T17:39:39.394806Z","price_level":"114769.28","new_quantity":"0"},{"side":"bid","event_time":"2025-10-27T17:39:39.394806Z","price_level":"114125.55","new_quantity":"0.07007"},{"side":"bid","event_time":"2025-10-27T17:39:39.394806Z","price_level":"101204.31","new_quantity":"0.00099136"},{"side":"offer","event_time":"2025-10-27T17:39:39.394806Z","price_level":"115662.38","new_quantity":"0.02593756"},{"side":"offer","event_time":"2025-10-27T17:39:39.394806Z","price_level":"115663.93","new_quantity":"0"},{"side":"offer","event_time":"2025-10-27T17:39:39.394806Z","price_level":"115663.94","new_quantity":"0"},{"side":"offer","event_time":"2025-10-27T17:39:39.394806Z","price_level":"115664.42","new_quantity":"0"},{"side":"offer","event_time":"2025-10-27T17:39:39.394806Z","price_level":"115666.37","new_quantity":"0.00006599"},{"side":"offer","event_time":"2025-10-27T17:39:39.394806Z","price_level":"115675.79","new_quantity":"0.17852711"},{"side":"offer","event_time":"2025-10-27T17:39:39.394806Z","price_level":"115676.95","new_quantity":"0.16611"},{"side":"offer","event_time":"2025-10-27T17:39:39.394806Z","price_level":"115679.24","new_quantity":"0.00432"},{"side":"offer","event_time":"2025-10-27T17:39:39.394806Z","price_level":"115679.25","new_quantity":"0.00432"},{"side":"offer","event_time":"2025-10-27T17:39:39.394806Z","price_level":"115681.55","new_quantity":"0.01055212"},{"side":"offer","event_time":"2025-10-27T17:39:39.394806Z","price_level":"115683.17","new_quantity":"0"},{"side":"offer","event_time":"2025-10-27T17:39:39.394806Z","price_level":"115683.18","new_quantity":"0"},{"side":"offer","event_time":"2025-10-27T17:39:39.394806Z","price_level":"115683.88","new_quantity":"0"},{"side":"offer","event_time":"2025-10-27T17:39:39.394806Z","price_level":"115683.89","new_quantity":"0"},{"side":"offer","event_time":"2025-10-27T17:39:39.394806Z","price_level":"115689.73","new_quantity":"0.43315989"},{"side":"offer","event_time":"2025-10-27T17:39:39.394806Z","price_level":"115692","new_quantity":"0"},{"side":"offer","event_time":"2025-10-27T17:39:39.394806Z","price_level":"115693.99","new_quantity":"0"},{"side":"offer","event_time":"2025-10-27T17:39:39.394806Z","price_level":"115694","new_quantity":"0"},{"side":"offer","event_time":"2025-10-27T17:39:39.394806Z","price_level":"115694.04","new_quantity":"0.00973843"},{"side":"offer","event_time":"2025-10-27T17:39:39.394806Z","price_level":"115697.98","new_quantity":"0"},{"side":"offer","event_time":"2025-10-27T17:39:39.394806Z","price_level":"115708.17","new_quantity":"0.5"},{"side":"offer","event_time":"2025-10-27T17:39:39.394806Z","price_level":"115711.49","new_quantity":"0"},{"side":"offer","event_time":"2025-10-27T17:39:39.394806Z","price_level":"115711.99","new_quantity":"0.1680972"},{"side":"offer","event_time":"2025-10-27T17:39:39.394806Z","price_level":"115714.18","new_quantity":"0"},{"side":"offer","event_time":"2025-10-27T17:39:39.394806Z","price_level":"115717.86","new_quantity":"0"},{"side":"offer","event_time":"2025-10-27T17:39:39.394806Z","price_level":"115717.96","new_quantity":"0"},{"side":"offer","event_time":"2025-10-27T17:39:39.394806Z","price_level":"115729.98","new_quantity":"0"},{"side":"offer","event_time":"2025-10-27T17:39:39.394806Z","price_level":"115735.11","new_quantity":"0.2511139"},{"side":"offer","event_time":"2025-10-27T17:39:39.394806Z","price_level":"115738.6","new_quantity":"1"},{"side":"offer","event_time":"2025-10-27T17:39:39.394806Z","price_level":"115745.2","new_quantity":"0"}]}]}
{"channel":"l2_data","client_id":"","timestamp":"2025-10-27T17:39:39.521397239Z","sequence_num":137554,"events":[{"type":"update","product_id":"ETH-USD","updates":[{"side":"bid","event_time":"2025-10-27T17:39:39.477537Z","price_level":"4218.67","new_quantity":"0.58696342"},{"side":"bid","event_time":"2025-10-27T17:39:39.477537Z","price_level":"4218.6","new_quantity":"10"},{"side":"offer","event_time":"2025-10-27T17:39:39.477537Z","price_level":"4218.68","new_quantity":"0.19658461"},{"side":"offer","event_time":"2025-10-27T17:39:39.477537Z","price_level":"4218.69","new_quantity":"0.11852042"},{"side":"offer","event_time":"2025-10-27T17:39:39.477537Z","price_level":"4218.8","new_quantity":"0.519"},{"side":"offer","event_time":"2025-10-27T17:39:39.477537Z","price_level":"4218.85","new_quantity":"0"},{"side":"offer","event_time":"2025-10-27T17:39:39.477537Z","price_level":"4218.9","new_quantity":"0.519"},{"side":"offer","event_time":"2025-10-27T17:39:39.477537Z","price_level":"4219.11","new_quantity":"1.125"},{"side":"offer","event_time":"2025-10-27T17:39:39.477537Z","price_level":"4219.14","new_quantity":"0.8392796"},{"side":"offer","event_time":"2025-10-27T17:39:39.477537Z","price_level":"4219.15","new_quantity":"0.71154204"},{"side":"offer","event_time":"2025-10-27T17:39:39.477537Z","price_level":"4219.18","new_quantity":"0"},{"side":"offer","event_time":"2025-10-27T17:39:39.477537Z","price_level":"4219.25","new_quantity":"0.001"},{"side":"offer","event_time":"2025-10-27T17:39:39.477537Z","price_level":"4220.4","new_quantity":"0.102877"},{"side":"offer","event_time":"2025-10-27T17:39:39.477537Z","price_level":"4220.71","new_quantity":"0.17999383"},{"side":"offer","event_time":"2025-10-27T17:39:39.477537Z","price_level":"4222.18","new_quantity":"1.94391607"},{"side":"offer","event_time":"2025-10-27T17:39:39.477537Z","price_level":"4222.19","new_quantity":"13.29959294"},{"side":"offer","event_time":"2025-10-27T17:39:39.477537Z","price_level":"4222.22","new_quantity":"0"},{"side":"offer","event_time":"2025-10-27T17:39:39.477537Z","price_level":"4222.23","new_quantity":"0"},{"side":"offer","event_time":"2025-10-27T17:39:39.477537Z","price_level":"4244.82","new_quantity":"0"}]}]}
{"channel":"l2_data","client_id":"","timestamp":"2025-10-27T17:39:39.921984205Z","sequence_num":137571,"events":[{"type":"update","product_id":"ETH-USD","updates":[{"side":"bid","event_time":"2025-10-27T17:39:39.884581Z","price_level":"4218.52","new_quantity":"0.91928665"},{"side":"bid","event_time":"2025-10-27T17:39:39.884581Z","price_level":"4218.51","new_quantity":"0.06439185"},{"side":"bid","event_time":"2025-10-27T17:39:39.884581Z","price_level":"4218.21","new_quantity":"0.00237068"},{"side":"bid","event_time":"2025-10-27T17:39:39.884581Z","price_level":"4217.85","new_quantity":"2.54304549"},{"side":"bid","event_time":"2025-10-27T17:39:39.884581Z","price_level":"4217.81","new_quantity":"1.65484"},{"side":"bid","event_time":"2025-10-27T17:39:39.884581Z","price_level":"4217.36","new_quantity":"0.45865128"},{"side":"bid","event_time":"2025-10-27T17:39:39.884581Z","price_level":"4217.19","new_quantity":"1.41082494"},{"side":"bid","event_time":"2025-10-27T17:39:39.884581Z","price_level":"4217.17","new_quantity":"1.65749"},{"side":"offer","event_time":"2025-10-27T17:39:39.884581Z","price_level":"4218.86","new_quantity":"0.52215298"},{"side":"offer","event_time":"2025-10-27T17:39:39.884581Z","price_level":"4219.36","new_quantity":"0"},{"side":"offer","event_time":"2025-10-27T17:39:39.884581Z","price_level":"4219.85","new_quantity":"0"},{"side":"offer","event_time":"2025-10-27T17:39:39.884581Z","price_level":"4221.85","new_quantity":"13.60718951"},{"side":"offer","event_time":"2025-10-27T17:39:39.884581Z","price_level":"4221.89","new_quantity":"1.94391607"},{"side":"offer","event_time":"2025-10-27T17:39:39.884581Z","price_level":"4221.9","new_quantity":"0.20918061"},{"side":"offer","event_time":"2025-10-27T17:39:39.884581Z","price_level":"4221.95","new_quantity":"0"},{"side":"offer","event_time":"2025-10-27T17:39:39.884581Z","price_level":"4223.22","new_quantity":"9.52582941"},{"side":"offer","event_time":"2025-10-27T17:39:39.884581Z","price_level":"4223.25","new_quantity":"0"}]}]}
{"channel":"l2_data","client_id":"","timestamp":"2025-10-27T17:39:39.971682718Z","sequence_num":137572,"events":[{"type":"update","product_id":"ETH-USD","updates":[{"side":"bid","event_time":"2025-10-27T17:39:39.934967Z","price_level":"4218.5","new_quantity":"10"},{"side":"bid","event_time":"2025-10-27T17:39:39.934967Z","price_level":"4218.4","new_quantity":"20"},{"side":"bid","event_time":"2025-10-27T17:39:39.934967Z","price_level":"4218.01","new_quantity":"1.65484"},{"side":"bid","event_time":"2025-10-27T17:39:39.934967Z","price_level":"4217.47","new_quantity":"0.6"},{"side":"bid","event_time":"2025-10-27T17:39:39.934967Z","price_level":"4217.39","new_quantity":"1.65749"},{"side":"bid","event_time":"2025-10-27T17:39:39.934967Z","price_level":"4215.84","new_quantity":"0"},{"side":"offer","event_time":"2025-10-27T17:39:39.934967Z","price_level":"4219.1","new_quantity":"0.01474346"},{"side":"offer","event_time":"2025-10-27T17:39:39.934967Z","price_level":"4219.33","new_quantity":"0"},{"side":"offer","event_time":"2025-10-27T17:39:39.934967Z","price_level":"4219.58","new_quantity":"0.6"},{"side":"offer","event_time":"2025-10-27T17:39:39.934967Z","price_level":"4220","new_quantity":"42.20517286"},{"side":"offer","event_time":"2025-10-27T17:39:39.934967Z","price_level":"4221.84","new_quantity":"1.94391607"},{"side":"offer","event_time":"2025-10-27T17:39:39.934967Z","price_level":"4221.89","new_quantity":"0"},{"side":"offer","event_time":"2025-10-27T17:39:39.934967Z","price_level":"4244.82","new_quantity":"0"}]}]}
{"channel":"l2_data","client_id":"","timestamp":"2025-10-27T17:39:40.000571846Z","sequence_num":137573,"events":[{"type":"update","product_id":"BTC-USD","updates":[{"side":"bid","event_time":"2025-10-27T17:39:39.863536Z","price_level":"115658.01","new_quantity":"0"},{"side":"bid","event_time":"2025-10-27T17:39:39.863536Z","price_level":"115658","new_quantity":"0"},{"side":"bid","event_time":"2025-10-27T17:39:39.863536Z","price_level":"115657.18","new_quantity":"0"},{"side":"bid","event_time":"2025-10-27T17:39:39.863536Z","price_level":"115654","new_quantity":"0.0262"},{"side":"bid","event_time":"2025-10-27T17:39:39.863536Z","price_level":"115653.47","new_quantity":"0"},{"side":"bid","event_time":"2025-10-27T17:39:39.863536Z","price_level":"115652.01","new_quantity":"0.03191892"},{"side":"bid","event_time":"2025-10-27T17:39:39.863536Z","price_level":"115652","new_quantity":"0.0249"},{"side":"bid","event_time":"2025-10-27T17:39:39.863536Z","price_level":"115651.24","new_quantity":"0"},{"side":"bid","event_time":"2025-10-27T17:39:39.863536Z","price_level":"115650","new_quantity":"0.00601642"},{"side":"bid","event_time":"2025-10-27T17:39:39.863536Z","price_level":"115649.08","new_quantity":"0"},{"side":"bid","event_time":"2025-10-27T17:39:39.863536Z","price_level":"115645.66","new_quantity":"0"},{"side":"bid","event_time":"2025-10-27T17:39:39.863536Z","price_level":"115645.65","new_quantity":"0"},{"side":"bid","event_time":"2025-10-27T17:39:39.863536Z","price_level":"115645.61","new_quantity":"0.00076159"},{"side":"bid","event_time":"2025-10-27T17:39:39.863536Z","price_level":"115644.01","new_quantity":"0.011239"},{"side":"bid","event_time":"2025-10-27T17:39:39.863536Z","price_level":"115643.98","new_quantity":"0.00864722"},{"side":"bid","event_time":"2025-10-27T17:39:39.863536Z","price_level":"115642.19","new_quantity":"0"},{"side":"bid","event_time":"2025-10-27T17:39:39.863536Z","price_level":"115642.16","new_quantity":"0"},{"side":"bid","event_time":"2025-10-27T17:39:39.863536Z","price_level":"115640.96","new_quantity":"0"},{"side":"bid","event_time":"2025-10-27T17:39:39.863536Z","price_level":"115640.43","new_quantity":"0.20387528"},{"side":"bid","event_time":"2025-10-27T17:39:39.863536Z","price_level":"115640.42","new_quantity":"0.16673"},{"side":"bid","event_time":"2025-10-27T17:39:39.863536Z","price_level":"115640.32","new_quantity":"0"},{"side":"bid","event_time":"2025-10-27T17:39:39.863536Z","price_level":"115636","new_quantity":"0"},{"side":"bid","event_time":"2025-10-27T17:39:39.863536Z","price_level":"115633.77","new_quantity":"0.08647992"},{"side":"bid","event_time":"2025-10-27T17:39:39.863536Z","price_level":"115633.01","new_quantity":"1.19351579"},{"side":"bid","event_time":"2025-10-27T17:39:39.863536Z","price_level":"115631.01","new_quantity":"0"},{"side":"bid","event_time":"2025-10-27T17:39:39.863536Z","price_level":"115631","new_quantity":"0.4"},{"side":"bid","event_time":"2025-10-27T17:39:39.863536Z","price_level":"115630","new_quantity":"0"},{"side":"bid","event_time":"2025-10-27T17:39:39.863536Z","price_level":"115629.15","new_quantity":"0.33121071"},{"side":"bid","event_time":"2025-10-27T17:39:39.863536Z","price_level":"115629","new_quantity":"0.4"},{"side":"bid","event_time":"2025-10-27T17:39:39.863536Z","price_level":"115628.54","new_quantity":"0"},{"side":"bid","event_time":"2025-10-27T17:39:39.863536Z","price_level":"115628.53","new_quantity":"2.42990915"},{"side":"bid","event_time":"2025-10-27T17:39:39.863536Z","price_level":"115627","new_quantity":"2.4"},{"side":"bid","event_time":"2025-10-27T17:39:39.863536Z","price_level":"115625.01","new_quantity":"0.36907022"},{"side":"bid","event_time":"2025-10-27T17:39:39.863536Z","price_level":"115617.05","new_quantity":"0"},{"side":"bid","event_time":"2025-10-27T17:39:39.863536Z","price_level":"115612.8","new_quantity":"0.52632089"},{"side":"bid","event_time":"2025-10-27T17:39:39.863536Z","price_level":"115596.71","new_quantity":"0"},{"side":"bid","event_time":"2025-10-27T17:39:39.863536Z","price_level":"115592.49","new_quantity":"0.76378031"},{"side":"bid","event_time":"2025-10-27T17:39:39.863536Z","price_level":"115587.3","new_quantity":"0"},{"side":"bid","event_time":"2025-10-27T17:39:39.863536Z","price_level":"115584.8","new_quantity":"0"},{"side":"bid","event_time":"2025-10-27T17:39:39.863536Z","price_level":"115582.35","new_quantity":"0"},{"side":"bid","event_time":"2025-10-27T17:39:39.863536Z","price_level":"115578.8","new_quantity":"1.5"},{"side":"bid","event_time":"2025-10-27T17:39:39.863536Z","price_level":"115546.59","new_quantity":"0.01730903"},{"side":"bid","event_time":"2025-10-27T17:39:39.863536Z","price_level":"115545.73","new_quantity":"0"},{"side":"bid","event_time":"2025-10-27T17:39:39.863536Z","price_level":"115545.72","new_quantity":"0"},{"side":"bid","event_time":"2025-10-27T17:39:39.863536Z","price_level":"101204.31","new_quantity":"0"},{"side":"offer","event_time":"2025-10-27T17:39:39.863536Z","price_level":"115662.07","new_quantity":"0.11789744"},{"side":"offer","event_time":"2025-10-27T17:39:39.863536Z","price_level":"115666.34","new_quantity":"0"},{"side":"offer","event_time":"2025-10-27T17:39:39.863536Z","price_level":"115666.35","new_quantity":"0"},{"side":"offer","event_time":"2025-10-27T17:39:39.863536Z","price_level":"115666.36","new_quantity":"0.00006605"},{"side":"offer","event_time":"2025-10-27T17:39:39.863536Z","price_level":"115674.6","new_quantity":"0"},{"side":"offer","event_time":"2025-10-27T17:39:39.863536Z","price_level":"115676.93","new_quantity":"0"},{"side":"offer","event_time":"2025-10-27T17:39:39.863536Z","price_level":"115679.25","new_quantity":"0"},{"side":"offer","event_time":"2025-10-27T17:39:39.863536Z","price_level":"115681.55","new_quantity":"0"},{"side":"offer","event_time":"2025-10-27T17:39:39.863536Z","price_level":"115686.73","new_quantity":"0.03458164"},{"side":"offer","event_time":"2025-10-27T17:39:39.863536Z","price_level":"115688.99","new_quantity":"0.51541097"},{"side":"offer","event_time":"2025-10-27T17:39:39.863536Z","price_level":"115689.6","new_quantity":"0.13834559"},{"side":"offer","event_time":"2025-10-27T17:39:39.863536Z","price_level":"115689.72","new_quantity":"0"},{"side":"offer","event_time":"2025-10-27T17:39:39.863536Z","price_level":"115689.73","new_quantity":"0"},{"side":"offer","event_time":"2025-10-27T17:39:39.863536Z","price_level":"115690","new_quantity":"0"},{"side":"offer","event_time":"2025-10-27T17:39:39.863536Z","price_level":"115691.92","new_quantity":"0.0069609"},{"side":"offer","event_time":"2025-10-27T17:39:39.863536Z","price_level":"115691.99","new_quantity":"0.38904236"},{"side":"offer","event_time":"2025-10-27T17:39:39.863536Z","price_level":"115692","new_quantity":"0"},{"side":"offer","event_time":"2025-10-27T17:39:39.863536Z","price_level":"115692.16","new_quantity":"0"},{"side":"offer","event_time":"2025-10-27T17:39:39.863536Z","price_level":"115692.99","new_quantity":"0"},{"side":"offer","event_time":"2025-10-27T17:39:39.863536Z","price_level":"115693","new_quantity":"0.4"},{"side":"offer","event_time":"2025-10-27T17:39:39.863536Z","price_level":"115695","new_quantity":"0"},{"side":"offer","event_time":"2025-10-27T17:39:39.863536Z","price_level":"115696","new_quantity":"0"},{"side":"offer","event_time":"2025-10-27T17:39:39.863536Z","price_level":"115697.99","new_quantity":"0"},{"side":"offer","event_time":"2025-10-27T17:39:39.863536Z","price_level":"115698.57","new_quantity":"0"},{"side":"offer","event_time":"2025-10-27T17:39:39.863536Z","price_level":"115700","new_quantity":"0"},{"side":"offer","event_time":"2025-10-27T17:39:39.863536Z","price_level":"115709.99","new_quantity":"0.1681001"},{"side":"offer","event_time":"2025-10-27T17:39:39.863536Z","price_level":"115711.99","new_quantity":"0"},{"side":"offer","event_time":"2025-10-27T17:39:39.863536Z","price_level":"115737.39","new_quantity":"0.37930186"},{"side":"offer","event_time":"2025-10-27T17:39:39.863536Z","price_level":"115737.4","new_quantity":"1"},{"side":"offer","event_time":"2025-10-27T17:39:39.863536Z","price_level":"115737.79","new_quantity":"0"},{"side":"offer","event_time":"2025-10-27T17:39:39.863536Z","price_level":"115737.8","new_quantity":"0"},{"side":"offer","event_time":"2025-10-27T17:39:39.863536Z","price_level":"115737.89","new_quantity":"0.00043223"},{"side":"offer","event_time":"2025-10-27T17:39:39.863536Z","price_level":"115737.9","new_quantity":"0"},{"side":"offer","event_time":"2025-10-27T17:39:39.863536Z","price_level":"115754.99","new_quantity":"0.48017812"},{"side":"offer","event_time":"2025-10-27T17:39:39.863536Z","price_level":"115807.95","new_quantity":"0.27725478"},{"side":"offer","event_time":"2025-10-27T17:39:39.863536Z","price_level":"115812.95","new_quantity":"0.045"},{"side":"offer","event_time":"2025-10-27T17:39:39.863536Z","price_level":"116121.72","new_quantity":"0.07007"},{"side":"offer","event_time":"2025-10-27T17:39:39.863536Z","price_level":"116122.56","new_quantity":"0"},{"side":"offer","event_time":"2025-10-27T17:39:39.863536Z","price_level":"116391.26","new_quantity":"0.045"},{"side":"offer","event_time":"2025-10-27T17:39:39.863536Z","price_level":"116551.68","new_quantity":"0"},{"side":"offer","event_time":"2025-10-27T17:39:39.863536Z","price_level":"116766.49","new_quantity":"0"},{"side":"offer","event_time":"2025-10-27T17:39:39.863536Z","price_level":"116766.64","new_quantity":"0"},{"side":"offer","event_time":"2025-10-27T17:39:39.863536Z","price_level":"116981.9","new_quantity":"0"},{"side":"offer","event_time":"2025-10-27T17:39:39.863536Z","price_level":"130120.17","new_quantity":"0.00005086"},{"side":"offer","event_time":"2025-10-27T17:39:39.863536Z","price_level":"130121.98","new_quantity":"0"}]}]}
{"channel":"l2_data","client_id":"","timestamp":"2025-10-27T17:39:40.020703516Z","sequence_num":137574,"events":[{"type":"update","product_id":"ETH-USD","updates":[{"side":"bid","event_time":"2025-10-27T17:39:39.946662Z","price_level":"4217.85","new_quantity":"1.76316554"},{"side":"bid","event_time":"2025-10-27T17:39:39.946662Z","price_level":"4217.81","new_quantity":"0"},{"side":"bid","event_time":"2025-10-27T17:39:39.946662Z","price_level":"4217.64","new_quantity":"0.52629589"},{"side":"bid","event_time":"2025-10-27T17:39:39.946662Z","price_level":"4217.31","new_quantity":"0"},{"side":"bid","event_time":"2025-10-27T17:39:39.946662Z","price_level":"4215.51","new_quantity":"0.37635091"},{"side":"offer","event_time":"2025-10-27T17:39:39.946662Z","price_level":"4221.83","new_quantity":"13.39837597"},{"side":"offer","event_time":"2025-10-27T17:39:39.946662Z","price_level":"4221.85","new_quantity":"0.30652551"}]}]}
{"channel":"l2_data","client_id":"","timestamp":"2025-10-27T17:39:40.048150416Z","sequence_num":137575,"events":[{"type":"update","product_id":"BTC-USD","updates":[{"side":"bid","event_time":"2025-10-27T17:39:39.946656Z","price_level":"115652.01","new_quantity":"0.00172932"},{"side":"bid","event_time":"2025-10-27T17:39:39.946656Z","price_level":"115648.41","new_quantity":"0"},{"side":"bid","event_time":"2025-10-27T17:39:39.946656Z","price_level":"115646.48","new_quantity":"0.02160734"},{"side":"bid","event_time":"2025-10-27T17:39:39.946656Z","price_level":"115645.71","new_quantity":"0.00082791"},{"side":"bid","event_time":"2025-10-27T17:39:39.946656Z","price_level":"115645.7","new_quantity":"0.0086471"},{"side":"bid","event_time":"2025-10-27T17:39:39.946656Z","price_level":"115645.61","new_quantity":"0"},{"side":"bid","event_time":"2025-10-27T17:39:39.946656Z","price_level":"115643.98","new_quantity":"0"},{"side":"bid","event_time":"2025-10-27T17:39:39.946656Z","price_level":"115637.55","new_quantity":"0.00432"},{"side":"bid","event_time":"2025-10-27T17:39:39.946656Z","price_level":"115635.23","new_quantity":"0.00432"},{"side":"bid","event_time":"2025-10-27T17:39:39.946656Z","price_level":"115635.2","new_quantity":"0.00432"},{"side":"bid","event_time":"2025-10-27T17:39:39.946656Z","price_level":"115630.11","new_quantity":"0.33120796"},{"side":"bid","event_time":"2025-10-27T17:39:39.946656Z","price_level":"115630.1","new_quantity":"0.08648266"},{"side":"bid","event_time":"2025-10-27T17:39:39.946656Z","price_level":"115629.15","new_quantity":"0"},{"side":"bid","event_time":"2025-10-27T17:39:39.946656Z","price_level":"115628.53","new_quantity":"2.20957423"},{"side":"bid","event_time":"2025-10-27T17:39:39.946656Z","price_level":"115627","new_quantity":"2.4"},{"side":"bid","event_time":"2025-10-27T17:39:39.946656Z","price_level":"115625.01","new_quantity":"0"},{"side":"bid","event_time":"2025-10-27T17:39:39.946656Z","price_level":"115620.65","new_quantity":"0.36927075"},{"side":"bid","event_time":"2025-10-27T17:39:39.946656Z","price_level":"115579.1","new_quantity":"1.5"},{"side":"bid","event_time":"2025-10-27T17:39:39.946656Z","price_level":"115578.8","new_quantity":"0"},{"side":"offer","event_time":"2025-10-27T17:39:39.946656Z","price_level":"115688.99","new_quantity":"1.63936103"},{"side":"offer","event_time":"2025-10-27T17:39:39.946656Z","price_level":"115689","new_quantity":"2"},{"side":"offer","event_time":"2025-10-27T17:39:39.946656Z","price_level":"115691","new_quantity":"0"},{"side":"offer","event_time":"2025-10-27T17:39:39.946656Z","price_level":"115691.92","new_quantity":"0"},{"side":"offer","event_time":"2025-10-27T17:39:39.946656Z","price_level":"115693","new_quantity":"0"},{"side":"offer","event_time":"2025-10-27T17:39:39.946656Z","price_level":"115700","new_quantity":"1"},{"side":"offer","event_time":"2025-10-27T17:39:39.946656Z","price_level":"115727.14","new_quantity":"0.00043223"},{"side":"offer","event_time":"2025-10-27T17:39:39.946656Z","price_level":"115727.15","new_quantity":"0.25113117"},{"side":"offer","event_time":"2025-10-27T17:39:39.946656Z","price_level":"115737.4","new_quantity":"0"},{"side":"offer","event_time":"2025-10-27T17:39:39.946656Z","price_level":"115737.6","new_quantity":"0"},{"side":"offer","event_time":"2025-10-27T17:39:39.946656Z","price_level":"115750.7","new_quantity":"0"},{"side":"offer","event_time":"2025-10-27T17:39:39.946656Z","price_level":"115750.8","new_quantity":"1"},{"side":"offer","event_time":"2025-10-27T17:39:39.946656Z","price_level":"116337.12","new_quantity":"0.07007"},{"side":"offer","event_time":"2025-10-27T17:39:39.946656Z","price_level":"116337.22","new_quantity":"0"},{"side":"offer","event_time":"2025-10-27T17:39:39.946656Z","price_level":"116391.26","new_quantity":"0"},{"side":"offer","event_time":"2025-10-27T17:39:39.946656Z","price_level":"116551.61","new_quantity":"0.07007"},{"side":"offer","event_time":"2025-10-27T17:39:39.946656Z","price_level":"116766.32","new_quantity":"0.07007"}]}]}
{"channel":"l2_data","client_id":"","timestamp":"2025-10-27T17:39:40.07123759Z","sequence_num":137576,"events":[{"type":"update","product_id":"ETH-USD","updates":[{"side":"bid","event_time":"2025-10-27T17:39:40.030493Z","price_level":"4218.5","new_quantity":"20"},{"side":"bid","event_time":"2025-10-27T17:39:40.030493Z","price_level":"4218.4","new_quantity":"30"},{"side":"bid","event_time":"2025-10-27T17:39:40.030493Z","price_level":"4218.39","new_quantity":"0.07109151"},{"side":"bid","event_time":"2025-10-27T17:39:40.030493Z","price_level":"4218.01","new_quantity":"8.246317"},{"side":"bid","event_time":"2025-10-27T17:39:40.030493Z","price_level":"4217.96","new_quantity":"0.1185407"},{"side":"bid","event_time":"2025-10-27T17:39:40.030493Z","price_level":"4217.69","new_quantity":"0.51161915"},{"side":"bid","event_time":"2025-10-27T17:39:40.030493Z","price_level":"4217.59","new_quantity":"1.65747"},{"side":"bid","event_time":"2025-10-27T17:39:40.030493Z","price_level":"4217.36","new_quantity":"0"},{"side":"bid","event_time":"2025-10-27T17:39:40.030493Z","price_level":"4217.19","new_quantity":"0.38246031"},{"side":"bid","event_time":"2025-10-27T17:39:40.030493Z","price_level":"4217.17","new_quantity":"0"},{"side":"bid","event_time":"2025-10-27T17:39:40.030493Z","price_level":"4216.9","new_quantity":"0.6"},{"side":"bid","event_time":"2025-10-27T17:39:40.030493Z","price_level":"4170.52","new_quantity":"0"},{"side":"bid","event_time":"2025-10-27T17:39:40.030493Z","price_level":"4150.57","new_quantity":"0.00028585"},{"side":"bid","event_time":"2025-10-27T17:39:40.030493Z","price_level":"4130.63","new_quantity":"0"},{"side":"offer","event_time":"2025-10-27T17:39:40.030493Z","price_level":"4218.53","new_quantity":"0"},{"side":"offer","event_time":"2025-10-27T17:39:40.030493Z","price_level":"4219.33","new_quantity":"0.01508562"},{"side":"offer","event_time":"2025-10-27T17:39:40.030493Z","price_level":"4219.45","new_quantity":"0.194152"},{"side":"offer","event_time":"2025-10-27T17:39:40.030493Z","price_level":"4219.9","new_quantity":"10"},{"side":"offer","event_time":"2025-10-27T17:39:40.030493Z","price_level":"4220.5","new_quantity":"10.10081343"}]}]}
{"channel":"l2_data","client_id":"","timestamp":"2025-10-27T17:39:40.098795298Z","sequence_num":137578,"events":[{"type":"update","product_id":"BTC-USD","updates":[{"side":"bid","event_time":"2025-10-27T17:39:40.041254Z","price_level":"115647.55","new_quantity":"0.00864696"},{"side":"bid","event_time":"2025-10-27T17:39:40.041254Z","price_level":"115645.7","new_quantity":"0"},{"side":"bid","event_time":"2025-10-27T17:39:40.041254Z","price_level":"115637.52","new_quantity":"0.00432"},{"side":"bid","event_time":"2025-10-27T17:39:40.041254Z","price_level":"115617.04","new_quantity":"0"},{"side":"bid","event_time":"2025-10-27T17:39:40.041254Z","price_level":"115617.02","new_quantity":"0"},{"side":"bid","event_time":"2025-10-27T17:39:40.041254Z","price_level":"115586.1","new_quantity":"1.5"},{"side":"bid","event_time":"2025-10-27T17:39:40.041254Z","price_level":"115582.34","new_quantity":"0"},{"side":"bid","event_time":"2025-10-27T17:39:40.041254Z","price_level":"115579.1","new_quantity":"0"},{"side":"offer","event_time":"2025-10-27T17:39:40.041254Z","price_level":"115674.6","new_quantity":"0.00432"},{"side":"offer","event_time":"2025-10-27T17:39:40.041254Z","price_level":"115674.61","new_quantity":"0.00432"},{"side":"offer","event_time":"2025-10-27T17:39:40.041254Z","price_level":"115687.99","new_quantity":"0.98885531"},{"side":"offer","event_time":"2025-10-27T17:39:40.041254Z","price_level":"115688.99","new_quantity":"0"},{"side":"offer","event_time":"2025-10-27T17:39:40.041254Z","price_level":"115689","new_quantity":"0"},{"side":"offer","event_time":"2025-10-27T17:39:40.041254Z","price_level":"115692","new_quantity":"0.4"},{"side":"offer","event_time":"2025-10-27T17:39:40.041254Z","price_level":"115696.71","new_quantity":"0.0069609"},{"side":"offer","event_time":"2025-10-27T17:39:40.041254Z","price_level":"115700","new_quantity":"0"},{"side":"offer","event_time":"2025-10-27T17:39:40.041254Z","price_level":"115706.52","new_quantity":"0"},{"side":"offer","event_time":"2025-10-27T17:39:40.041254Z","price_level":"115735.1","new_quantity":"0"},{"side":"offer","event_time":"2025-10-27T17:39:40.041254Z","price_level":"115735.11","new_quantity":"0.0004323"},{"side":"offer","event_time":"2025-10-27T17:39:40.041254Z","price_level":"115737.39","new_quantity":"0"},{"side":"offer","event_time":"2025-10-27T17:39:40.041254Z","price_level":"115743.89","new_quantity":"0.57739712"},{"side":"offer","event_time":"2025-10-27T17:39:40.041254Z","price_level":"115743.9","new_quantity":"0.37928053"},{"side":"offer","event_time":"2025-10-27T17:39:40.041254Z","price_level":"115743.91","new_quantity":"0"},{"side":"offer","event_time":"2025-10-27T17:39:40.041254Z","price_level":"115746.9","new_quantity":"1"},{"side":"offer","event_time":"2025-10-27T17:39:40.041254Z","price_level":"115750.8","new_quantity":"0"},{"side":"offer","event_time":"2025-10-27T17:39:40.041254Z","price_level":"116766.13","new_quantity":"0.07007"},{"side":"offer","event_time":"2025-10-27T17:39:40.041254Z","price_level":"116766.32","new_quantity":"0"},{"side":"offer","event_time":"2025-10-27T17:39:40.041254Z","price_level":"116980.84","new_quantity":"0.07007"}]}]}
{"channel":"l2_data","client_id":"","timestamp":"2025-10-27T17:39:40.119360962Z","sequence_num":137580,"events":[{"type":"update","product_id":"ETH-USD","updates":[{"side":"offer","event_time":"2025-10-27T17:39:40.084377Z","price_level":"4218.53","new_quantity":"0.18090629"},{"side":"offer","event_time":"2025-10-27T17:39:40.084377Z","price_level":"4218.54","new_quantity":"0.11852441"},{"side":"offer","event_time":"2025-10-27T17:39:40.084377Z","price_level":"4219.1","new_quantity":"0"},{"side":"offer","event_time":"2025-10-27T17:39:40.084377Z","price_level":"4221.81","new_quantity":"13.44506363"},{"side":"offer","event_time":"2025-10-27T17:39:40.084377Z","price_level":"4221.82","new_quantity":"2.04184294"},{"side":"offer","event_time":"2025-10-27T17:39:40.084377Z","price_level":"4221.83","new_quantity":"0.09764896"},{"side":"offer","event_time":"2025-10-27T17:39:40.084377Z","price_level":"4221.84","new_quantity":"0"}]}]}
{"channel":"l2_data","client_id":"","timestamp":"2025-10-27T17:39:40.169261694Z","sequence_num":137582,"events":[{"type":"update","product_id":"ETH-USD","updates":[{"side":"bid","event_time":"2025-10-27T17:39:40.101179Z","price_level":"4217.39","new_quantity":"0"},{"side":"bid","event_time":"2025-10-27T17:39:40.101179Z","price_level":"4216.9","new_quantity":"1.4"}]}]}
{"channel":"l2_data","client_id":"","timestamp":"2025-10-27T17:39:40.221823486Z","sequence_num":137583,"events":[{"type":"update","product_id":"ETH-USD","updates":[{"side":"bid","event_time":"2025-10-27T17:39:40.17868Z","price_level":"4218.5","new_quantity":"0"},{"side":"bid","event_time":"2025-10-27T17:39:40.17868Z","price_level":"4218.4","new_quantity":"0"},{"side":"bid","event_time":"2025-10-27T17:39:40.17868Z","price_level":"4218.39","new_quantity":"0"},{"side":"bid","event_time":"2025-10-27T17:39:40.17868Z","price_level":"4218.36","new_quantity":"0.07109151"},{"side":"bid","event_time":"2025-10-27T17:39:40.17868Z","price_level":"4217.76","new_quantity":"0.01707818"},{"side":"bid","event_time":"2025-10-27T17:39:40.17868Z","price_level":"4216.9","new_quantity":"0.6"},{"side":"bid","event_time":"2025-10-27T17:39:40.17868Z","price_level":"4212.73","new_quantity":"0"},{"side":"bid","event_time":"2025-10-27T17:39:40.17868Z","price_level":"4191.63","new_quantity":"0.1536"},{"side":"offer","event_time":"2025-10-27T17:39:40.17868Z","price_level":"4218.53","new_quantity":"0.34966629"},{"side":"offer","event_time":"2025-10-27T17:39:40.17868Z","price_level":"4218.78","new_quantity":"0.02279291"},{"side":"offer","event_time":"2025-10-27T17:39:40.17868Z","price_level":"4219.33","new_quantity":"0"}]}]}
{"channel":"l2_data","client_id":"","timestamp":"2025-10-27T17:39:40.27247215Z","sequence_num":137584,"events":[{"type":"update","product_id":"ETH-USD","updates":[{"side":"bid","event_time":"2025-10-27T17:39:40.230311Z","price_level":"4218.52","new_quantity":"0"},{"side":"bid","event_time":"2025-10-27T17:39:40.230311Z","price_level":"4218.51","new_quantity":"0"},{"side":"bid","event_time":"2025-10-27T17:39:40.230311Z","price_level":"4218.5","new_quantity":"0"},{"side":"bid","event_time":"2025-10-27T17:39:40.230311Z","price_level":"4218.41","new_quantity":"0.00237057"},{"side":"bid","event_time":"2025-10-27T17:39:40.230311Z","price_level":"4218.4","new_quantity":"10"},{"side":"bid","event_time":"2025-10-27T17:39:40.230311Z","price_level":"4218.36","new_quantity":"0"},{"side":"bid","event_time":"2025-10-27T17:39:40.230311Z","price_level":"4218.3","new_quantity":"0.07109151"},{"side":"bid","event_time":"2025-10-27T17:39:40.230311Z","price_level":"4218.21","new_quantity":"0"},{"side":"bid","event_time":"2025-10-27T17:39:40.230311Z","price_level":"4218.01","new_quantity":"0"},{"side":"bid","event_time":"2025-10-27T17:39:40.230311Z","price_level":"4218","new_quantity":"30.52"},{"side":"bid","event_time":"2025-10-27T17:39:40.230311Z","price_level":"4217.96","new_quantity":"0"},{"side":"bid","event_time":"2025-10-27T17:39:40.230311Z","price_level":"4217.76","new_quantity":"0"},{"side":"bid","event_time":"2025-10-27T17:39:40.230311Z","price_level":"4217.74","new_quantity":"1.125"},{"side":"bid","event_time":"2025-10-27T17:39:40.230311Z","price_level":"4217.62","new_quantity":"0"},{"side":"bid","event_time":"2025-10-27T17:39:40.230311Z","price_level":"4217.59","new_quantity":"0"},{"side":"bid","event_time":"2025-10-27T17:39:40.230311Z","price_level":"4217.45","new_quantity":"0.59277513"},{"side":"bid","event_time":"2025-10-27T17:39:40.230311Z","price_level":"4217.44","new_quantity":"5.77961676"},{"side":"bid","event_time":"2025-10-27T17:39:40.230311Z","price_level":"4217.39","new_quantity":"1.65747"},{"side":"bid","event_time":"2025-10-27T17:39:40.230311Z","price_level":"4216.9","new_quantity":"0"},{"side":"bid","event_time":"2025-10-27T17:39:40.230311Z","price_level":"4206.95","new_quantity":"0"},{"side":"offer","event_time":"2025-10-27T17:39:40.230311Z","price_level":"4218.49","new_quantity":"0.51959741"},{"side":"offer","event_time":"2025-10-27T17:39:40.230311Z","price_level":"4218.5","new_quantity":"0.545"},{"side":"offer","event_time":"2025-10-27T17:39:40.230311Z","price_level":"4218.51","new_quantity":"0"},{"side":"offer","event_time":"2025-10-27T17:39:40.230311Z","price_level":"4218.52","new_quantity":"0"},{"side":"offer","event_time":"2025-10-27T17:39:40.230311Z","price_level":"4218.53","new_quantity":"0"},{"side":"offer","event_time":"2025-10-27T17:39:40.230311Z","price_level":"4218.54","new_quantity":"0"},{"side":"offer","event_time":"2025-10-27T17:39:40.230311Z","price_level":"4218.78","new_quantity":"0"},{"side":"offer","event_time":"2025-10-27T17:39:40.230311Z","price_level":"4219","new_quantity":"0.52"},{"side":"offer","event_time":"2025-10-27T17:39:40.230311Z","price_level":"4219.6","new_quantity":"0"},{"side":"offer","event_time":"2025-10-27T17:39:40.230311Z","price_level":"4219.76","new_quantity":"5.615029"},{"side":"offer","event_time":"2025-10-27T17:39:40.230311Z","price_level":"4220.42","new_quantity":"4.390353"},{"side":"offer","event_time":"2025-10-27T17:39:40.230311Z","price_level":"4220.67","new_quantity":"8.5438493"},{"side":"offer","event_time":"2025-10-27T17:39:40.230311Z","price_level":"4220.82","new_quantity":"0.46685028"},{"side":"offer","event_time":"2025-10-27T17:39:40.230311Z","price_level":"4220.83","new_quantity":"0.00911344"},{"side":"offer","event_time":"2025-10-27T17:39:40.230311Z","price_level":"4221.79","new_quantity":"13.39872769"},{"side":"offer","event_time":"2025-10-27T17:39:40.230311Z","price_level":"4221.8","new_quantity":"1.94391607"},{"side":"offer","event_time":"2025-10-27T17:39:40.230311Z","price_level":"4221.81","new_quantity":"0.14427361"},{"side":"offer","event_time":"2025-10-27T17:39:40.230311Z","price_level":"4221.82","new_quantity":"0.09792687"},{"side":"offer","event_time":"2025-10-27T17:39:40.230311Z","price_level":"4229.28","new_quantity":"1.15467008"}]}]}
{"channel":"l2_data","client_id":"","timestamp":"2025-10-27T17:39:40.294608073Z","sequence_num":137585,"events":[{"type":"update","product_id":"BTC-USD","updates":[{"side":"offer","event_time":"2025-10-27T17:39:40.25229Z","price_level":"115662.07","new_quantity":"0.08564744"}]}]}
{"channel":"l2_data","client_id":"","timestamp":"2025-10-27T17:39:40.321692535Z","sequence_num":137586,"events":[{"type":"update","product_id":"ETH-USD","updates":[{"side":"bid","event_time":"2025-10-27T17:39:40.287732Z","price_level":"4218.3","new_quantity":"10"},{"side":"bid","event_time":"2025-10-27T17:39:40.287732Z","price_level":"4218.24","new_quantity":"0"},{"side":"bid","event_time":"2025-10-27T17:39:40.287732Z","price_level":"4218.19","new_quantity":"0.07109151"},{"side":"bid","event_time":"2025-10-27T17:39:40.287732Z","price_level":"4218.13","new_quantity":"0"},{"side":"bid","event_time":"2025-10-27T17:39:40.287732Z","price_level":"4217.85","new_quantity":"2.79146057"},{"side":"bid","event_time":"2025-10-27T17:39:40.287732Z","price_level":"4217.75","new_quantity":"2.36748162"},{"side":"bid","event_time":"2025-10-27T17:39:40.287732Z","price_level":"4217.64","new_quantity":"0"},{"side":"bid","event_time":"2025-10-27T17:39:40.287732Z","price_level":"4217.39","new_quantity":"0"},{"side":"bid","event_time":"2025-10-27T17:39:40.287732Z","price_level":"4217.18","new_quantity":"0.146968"},{"side":"bid","event_time":"2025-10-27T17:39:40.287732Z","price_level":"4215.33","new_quantity":"4.21299562"},{"side":"bid","event_time":"2025-10-27T17:39:40.287732Z","price_level":"4215.18","new_quantity":"6.20119475"},{"side":"offer","event_time":"2025-10-27T17:39:40.287732Z","price_level":"4219.1","new_quantity":"0.01508562"},{"side":"offer","event_time":"2025-10-27T17:39:40.287732Z","price_level":"4219.34","new_quantity":"1.91443799"},{"side":"offer","event_time":"2025-10-27T17:39:40.287732Z","price_level":"4219.4","new_quantity":"1.64349"},{"side":"offer","event_time":"2025-10-27T17:39:40.287732Z","price_level":"4219.9","new_quantity":"0"}]}]}
{"channel":"l2_data","client_id":"","timestamp":"2025-10-27T17:39:40.34890236Z","sequence_num":137588,"events":[{"type":"update","product_id":"BTC-USD","updates":[{"side":"bid","event_time":"2025-10-27T17:39:40.308927Z","price_level":"115662.06","new_quantity":"0"},{"side":"bid","event_time":"2025-10-27T17:39:40.308927Z","price_level":"115657.18","new_quantity":"0.07021247"},{"side":"bid","event_time":"2025-10-27T17:39:40.308927Z","price_level":"115656","new_quantity":"0"},{"side":"bid","event_time":"2025-10-27T17:39:40.308927Z","price_level":"115654.77","new_quantity":"0"},{"side":"bid","event_time":"2025-10-27T17:39:40.308927Z","price_level":"115654","new_quantity":"0.0236"},{"side":"bid","event_time":"2025-10-27T17:39:40.308927Z","price_level":"115652.01","new_quantity":"0"},{"side":"bid","event_time":"2025-10-27T17:39:40.308927Z","price_level":"115650.01","new_quantity":"0.00172935"},{"side":"bid","event_time":"2025-10-27T17:39:40.308927Z","price_level":"115647.55","new_quantity":"0"},{"side":"bid","event_time":"2025-10-27T17:39:40.308927Z","price_level":"115646.48","new_quantity":"0"},{"side":"bid","event_time":"2025-10-27T17:39:40.308927Z","price_level":"115645.71","new_quantity":"0"},{"side":"bid","event_time":"2025-10-27T17:39:40.308927Z","price_level":"115645.6","new_quantity":"0.17899101"},{"side":"bid","event_time":"2025-10-27T17:39:40.308927Z","price_level":"115645.59","new_quantity":"0"},{"side":"bid","event_time":"2025-10-27T17:39:40.308927Z","price_level":"115644.93","new_quantity":"0.02160734"},{"side":"bid","event_time":"2025-10-27T17:39:40.308927Z","price_level":"115640.43","new_quantity":"0.10433747"},{"side":"bid","event_time":"2025-10-27T17:39:40.308927Z","price_level":"115640.42","new_quantity":"0"},{"side":"bid","event_time":"2025-10-27T17:39:40.308927Z","price_level":"115637.55","new_quantity":"0"},{"side":"bid","event_time":"2025-10-27T17:39:40.308927Z","price_level":"115637.52","new_quantity":"0"},{"side":"bid","event_time":"2025-10-27T17:39:40.308927Z","price_level":"115635.23","new_quantity":"0.00432"},{"side":"bid","event_time":"2025-10-27T17:39:40.308927Z","price_level":"115635.2","new_quantity":"0.00432"},{"side":"bid","event_time":"2025-10-27T17:39:40.308927Z","price_level":"115634.61","new_quantity":"0"},{"side":"bid","event_time":"2025-10-27T17:39:40.308927Z","price_level":"115633.28","new_quantity":"0.08648028"},{"side":"bid","event_time":"2025-10-27T17:39:40.308927Z","price_level":"115632.61","new_quantity":"0.04"},{"side":"bid","event_time":"2025-10-27T17:39:40.308927Z","price_level":"115632.19","new_quantity":"0.16647"},{"side":"bid","event_time":"2025-10-27T17:39:40.308927Z","price_level":"115631","new_quantity":"0.4"},{"side":"bid","event_time":"2025-10-27T17:39:40.308927Z","price_level":"115630.11","new_quantity":"0"},{"side":"bid","event_time":"2025-10-27T17:39:40.308927Z","price_level":"115630.1","new_quantity":"0"},{"side":"bid","event_time":"2025-10-27T17:39:40.308927Z","price_level":"115629.14","new_quantity":"0"},{"side":"bid","event_time":"2025-10-27T17:39:40.308927Z","price_level":"115628.24","new_quantity":"0.33121331"},{"side":"bid","event_time":"2025-10-27T17:39:40.308927Z","price_level":"115627","new_quantity":"2.4"},{"side":"bid","event_time":"2025-10-27T17:39:40.308927Z","price_level":"115625.4","new_quantity":"0"},{"side":"bid","event_time":"2025-10-27T17:39:40.308927Z","price_level":"115620.65","new_quantity":"0"},{"side":"bid","event_time":"2025-10-27T17:39:40.308927Z","price_level":"115620.01","new_quantity":"0.597"},{"side":"bid","event_time":"2025-10-27T17:39:40.308927Z","price_level":"115614.45","new_quantity":"0.07007"},{"side":"bid","event_time":"2025-10-27T17:39:40.308927Z","price_level":"115613.97","new_quantity":"0.64590862"},{"side":"bid","event_time":"2025-10-27T17:39:40.308927Z","price_level":"115612.82","new_quantity":"0.5263208"},{"side":"bid","event_time":"2025-10-27T17:39:40.308927Z","price_level":"115612.81","new_quantity":"0.3694235"},{"side":"bid","event_time":"2025-10-27T17:39:40.308927Z","price_level":"115612.8","new_quantity":"0"},{"side":"bid","event_time":"2025-10-27T17:39:40.308927Z","price_level":"115587.5","new_quantity":"1.5"},{"side":"bid","event_time":"2025-10-27T17:39:40.308927Z","price_level":"115586.1","new_quantity":"0"},{"side":"bid","event_time":"2025-10-27T17:39:40.308927Z","price_level":"115579.28","new_quantity":"1.22762683"},{"side":"bid","event_time":"2025-10-27T17:39:40.308927Z","price_level":"115511.79","new_quantity":"0.045"},{"side":"bid","event_time":"2025-10-27T17:39:40.308927Z","price_level":"114933.48","new_quantity":"0"},{"side":"offer","event_time":"2025-10-27T17:39:40.308927Z","price_level":"115657.19","new_quantity":"0.09124359"},{"side":"offer","event_time":"2025-10-27T17:39:40.308927Z","price_level":"115662.02","new_quantity":"0.0000661"},{"side":"offer","event_time":"2025-10-27T17:39:40.308927Z","price_level":"115662.03","new_quantity":"0.25937641"},{"side":"offer","event_time":"2025-10-27T17:39:40.308927Z","price_level":"115662.07","new_quantity":"0.1425"},{"side":"offer","event_time":"2025-10-27T17:39:40.308927Z","price_level":"115662.38","new_quantity":"0"},{"side":"offer","event_time":"2025-10-27T17:39:40.308927Z","price_level":"115666.36","new_quantity":"0.02"},{"side":"offer","event_time":"2025-10-27T17:39:40.308927Z","price_level":"115670.62","new_quantity":"0.16585"},{"side":"offer","event_time":"2025-10-27T17:39:40.308927Z","price_level":"115671.14","new_quantity":"0"},{"side":"offer","event_time":"2025-10-27T17:39:40.308927Z","price_level":"115671.15","new_quantity":"0"},{"side":"offer","event_time":"2025-10-27T17:39:40.308927Z","price_level":"115674.6","new_quantity":"0"},{"side":"offer","event_time":"2025-10-27T17:39:40.308927Z","price_level":"115674.61","new_quantity":"0"},{"side":"offer","event_time":"2025-10-27T17:39:40.308927Z","price_level":"115675.79","new_quantity":"0.08507847"},{"side":"offer","event_time":"2025-10-27T17:39:40.308927Z","price_level":"115676.95","new_quantity":"0"},{"side":"offer","event_time":"2025-10-27T17:39:40.308927Z","price_level":"115683","new_quantity":"0.4"},{"side":"offer","event_time":"2025-10-27T17:39:40.308927Z","price_level":"115686.72","new_quantity":"0.138338"},{"side":"offer","event_time":"2025-10-27T17:39:40.308927Z","price_level":"115687","new_quantity":"2"},{"side":"offer","event_time":"2025-10-27T17:39:40.308927Z","price_level":"115687.99","new_quantity":"0.98885531"},{"side":"offer","event_time":"2025-10-27T17:39:40.308927Z","price_level":"115689.6","new_quantity":"0.00001"},{"side":"offer","event_time":"2025-10-27T17:39:40.308927Z","price_level":"115690","new_quantity":"1.4"},{"side":"offer","event_time":"2025-10-27T17:39:40.308927Z","price_level":"115690.32","new_quantity":"0.07007"},{"side":"offer","event_time":"2025-10-27T17:39:40.308927Z","price_level":"115696.71","new_quantity":"0"},{"side":"offer","event_time":"2025-10-27T17:39:40.308927Z","price_level":"115704.69","new_quantity":"0.02014916"},{"side":"offer","event_time":"2025-10-27T17:39:40.308927Z","price_level":"115706.38","new_quantity":"0.16810535"},{"side":"offer","event_time":"2025-10-27T17:39:40.308927Z","price_level":"115709.99","new_quantity":"0"},{"side":"offer","event_time":"2025-10-27T17:39:40.308927Z","price_level":"115729.5","new_quantity":"1"},{"side":"offer","event_time":"2025-10-27T17:39:40.308927Z","price_level":"115731.23","new_quantity":"0.02204637"},{"side":"offer","event_time":"2025-10-27T17:39:40.308927Z","price_level":"115735.11","new_quantity":"0.37974163"},{"side":"offer","event_time":"2025-10-27T17:39:40.308927Z","price_level":"115743.87","new_quantity":"0.57739722"},{"side":"offer","event_time":"2025-10-27T17:39:40.308927Z","price_level":"115743.89","new_quantity":"0"},{"side":"offer","event_time":"2025-10-27T17:39:40.308927Z","price_level":"115743.9","new_quantity":"0"},{"side":"offer","event_time":"2025-10-27T17:39:40.308927Z","price_level":"115746.9","new_quantity":"0"},{"side":"offer","event_time":"2025-10-27T17:39:40.308927Z","price_level":"115749.58","new_quantity":"0"},{"side":"offer","event_time":"2025-10-27T17:39:40.308927Z","price_level":"116336.76","new_quantity":"0.07007"},{"side":"offer","event_time":"2025-10-27T17:39:40.308927Z","price_level":"116337.12","new_quantity":"0"},{"side":"offer","event_time":"2025-10-27T17:39:40.308927Z","price_level":"116551.35","new_quantity":"0.07007"},{"side":"offer","event_time":"2025-10-27T17:39:40.308927Z","price_level":"116551.61","new_quantity":"0"},{"side":"offer","event_time":"2025-10-27T17:39:40.308927Z","price_level":"116766.13","new_quantity":"0"},{"side":"offer","event_time":"2025-10-27T17:39:40.308927Z","price_level":"116980.84","new_quantity":"0"},{"side":"offer","event_time":"2025-10-27T17:39:40.308927Z","price_level":"130120.17","new_quantity":"0"}]}]}
{"channel":"l2_data","client_id":"","timestamp":"2025-10-27T17:39:39.798749031Z","sequence_num":137566,"events":[{"type":"update","product_id":"BTC-USD","updates":[{"side":"bid","event_time":"2025-10-27T17:39:39.722977Z","price_level":"115660","new_quantity":"0"},{"side":"bid","event_time":"2025-10-27T17:39:39.722977Z","price_level":"115656.43","new_quantity":"0"},{"side":"bid","event_time":"2025-10-27T17:39:39.722977Z","price_level":"115650.65","new_quantity":"0"},{"side":"bid","event_time":"2025-10-27T17:39:39.722977Z","price_level":"115649.08","new_quantity":"0.00864684"},{"side":"bid","event_time":"2025-10-27T17:39:39.722977Z","price_level":"115648.63","new_quantity":"0"},{"side":"bid","event_time":"2025-10-27T17:39:39.722977Z","price_level":"115644.51","new_quantity":"0"},{"side":"bid","event_time":"2025-10-27T17:39:39.722977Z","price_level":"115644.48","new_quantity":"0"},{"side":"bid","event_time":"2025-10-27T17:39:39.722977Z","price_level":"115633.02","new_quantity":"0"},{"side":"bid","event_time":"2025-10-27T17:39:39.722977Z","price_level":"115631.01","new_quantity":"0.33120538"},{"side":"bid","event_time":"2025-10-27T17:39:39.722977Z","price_level":"115627.46","new_quantity":"0"},{"side":"bid","event_time":"2025-10-27T17:39:39.722977Z","price_level":"115617.05","new_quantity":"0.52630154"},{"side":"bid","event_time":"2025-10-27T17:39:39.722977Z","price_level":"115617.04","new_quantity":"1.25045525"},{"side":"bid","event_time":"2025-10-27T17:39:39.722977Z","price_level":"115617.03","new_quantity":"0"},{"side":"bid","event_time":"2025-10-27T17:39:39.722977Z","price_level":"115582.35","new_quantity":"1.45013724"},{"side":"bid","event_time":"2025-10-27T17:39:39.722977Z","price_level":"115579.95","new_quantity":"0"},{"side":"bid","event_time":"2025-10-27T17:39:39.722977Z","price_level":"115567.27","new_quantity":"1.20666121"},{"side":"bid","event_time":"2025-10-27T17:39:39.722977Z","price_level":"115528.01","new_quantity":"0.1416084"},{"side":"bid","event_time":"2025-10-27T17:39:39.722977Z","price_level":"114933.48","new_quantity":"0.045"},{"side":"offer","event_time":"2025-10-27T17:39:39.722977Z","price_level":"115666.36","new_quantity":"0.00006605"},{"side":"offer","event_time":"2025-10-27T17:39:39.722977Z","price_level":"115666.37","new_quantity":"0.32405738"},{"side":"offer","event_time":"2025-10-27T17:39:39.722977Z","price_level":"115674.6","new_quantity":"0.00432"},{"side":"offer","event_time":"2025-10-27T17:39:39.722977Z","price_level":"115676.93","new_quantity":"0.00432"},{"side":"offer","event_time":"2025-10-27T17:39:39.722977Z","price_level":"115679.24","new_quantity":"0"},{"side":"offer","event_time":"2025-10-27T17:39:39.722977Z","price_level":"115681.56","new_quantity":"0"},{"side":"offer","event_time":"2025-10-27T17:39:39.722977Z","price_level":"115681.57","new_quantity":"0"},{"side":"offer","event_time":"2025-10-27T17:39:39.722977Z","price_level":"115689.73","new_quantity":"0.21584984"},{"side":"offer","event_time":"2025-10-27T17:39:39.722977Z","price_level":"115690","new_quantity":"0"},{"side":"offer","event_time":"2025-10-27T17:39:39.722977Z","price_level":"115727.15","new_quantity":"0.2515634"},{"side":"offer","event_time":"2025-10-27T17:39:39.722977Z","price_level":"115729.98","new_quantity":"0"},{"side":"offer","event_time":"2025-10-27T17:39:39.722977Z","price_level":"115729.99","new_quantity":"0"}]}]}
{"channel":"l2_data","client_id":"","timestamp":"2025-10-27T17:39:39.820790046Z","sequence_num":137567,"events":[{"type":"update","product_id":"ETH-USD","updates":[{"side":"bid","event_time":"2025-10-27T17:39:39.782567Z","price_level":"4218.41","new_quantity":"0.00237057"},{"side":"bid","event_time":"2025-10-27T17:39:39.782567Z","price_level":"4218.21","new_quantity":"0"},{"side":"bid","event_time":"2025-10-27T17:39:39.782567Z","price_level":"4218.01","new_quantity":"8.246317"},{"side":"bid","event_time":"2025-10-27T17:39:39.782567Z","price_level":"4217.85","new_quantity":"1.6273972"},{"side":"bid","event_time":"2025-10-27T17:39:39.782567Z","price_level":"4217.8","new_quantity":"0.63754502"},{"side":"bid","event_time":"2025-10-27T17:39:39.782567Z","price_level":"4217.59","new_quantity":"1.65749"},{"side":"bid","event_time":"2025-10-27T17:39:39.782567Z","price_level":"4217.5","new_quantity":"0.001"},{"side":"bid","event_time":"2025-10-27T17:39:39.782567Z","price_level":"4217.31","new_quantity":"0.55167587"},{"side":"bid","event_time":"2025-10-27T17:39:39.782567Z","price_level":"4217.18","new_quantity":"0.36261849"},{"side":"bid","event_time":"2025-10-27T17:39:39.782567Z","price_level":"4216.34","new_quantity":"0.13542551"},{"side":"bid","event_time":"2025-10-27T17:39:39.782567Z","price_level":"4216.17","new_quantity":"0"},{"side":"bid","event_time":"2025-10-27T17:39:39.782567Z","price_level":"4216.02","new_quantity":"3.27151726"},{"side":"bid","event_time":"2025-10-27T17:39:39.782567Z","price_level":"4215.48","new_quantity":"0"},{"side":"bid","event_time":"2025-10-27T17:39:39.782567Z","price_level":"4214.29","new_quantity":"0.00196837"},{"side":"offer","event_time":"2025-10-27T17:39:39.782567Z","price_level":"4218.53","new_quantity":"0.17976173"},{"side":"offer","event_time":"2025-10-27T17:39:39.782567Z","price_level":"4218.54","new_quantity":"0.11852441"},{"side":"offer","event_time":"2025-10-27T17:39:39.782567Z","price_level":"4218.56","new_quantity":"0"},{"side":"offer","event_time":"2025-10-27T17:39:39.782567Z","price_level":"4218.57","new_quantity":"0"},{"side":"offer","event_time":"2025-10-27T17:39:39.782567Z","price_level":"4218.6","new_quantity":"0.519"},{"side":"offer","event_time":"2025-10-27T17:39:39.782567Z","price_level":"4218.61","new_quantity":"0"},{"side":"offer","event_time":"2025-10-27T17:39:39.782567Z","price_level":"4218.63","new_quantity":"0"},{"side":"offer","event_time":"2025-10-27T17:39:39.782567Z","price_level":"4218.79","new_quantity":"1.28842825"},{"side":"offer","event_time":"2025-10-27T17:39:39.782567Z","price_level":"4218.88","new_quantity":"0.52758993"},{"side":"offer","event_time":"2025-10-27T17:39:39.782567Z","price_level":"4219.2","new_quantity":"0"},{"side":"offer","event_time":"2025-10-27T17:39:39.782567Z","price_level":"4219.34","new_quantity":"1.28586114"},{"side":"offer","event_time":"2025-10-27T17:39:39.782567Z","price_level":"4219.49","new_quantity":"0.01508562"},{"side":"offer","event_time":"2025-10-27T17:39:39.782567Z","price_level":"4219.51","new_quantity":"1.64349"},{"side":"offer","event_time":"2025-10-27T17:39:39.782567Z","price_level":"4219.55","new_quantity":"0"},{"side":"offer","event_time":"2025-10-27T17:39:39.782567Z","price_level":"4219.84","new_quantity":"0"},{"side":"offer","event_time":"2025-10-27T17:39:39.782567Z","price_level":"4220.1","new_quantity":"0.102877"},{"side":"offer","event_time":"2025-10-27T17:39:39.782567Z","price_level":"4220.4","new_quantity":"0"}]}]}
{"channel":"l2_data","client_id":"","timestamp":"2025-10-27T17:39:39.871342967Z","sequence_num":137569,"events":[{"type":"update","product_id":"ETH-USD","updates":[{"side":"bid","event_time":"2025-10-27T17:39:39.82908Z","price_level":"4218.48","new_quantity":"0.19015941"},{"side":"bid","event_time":"2025-10-27T17:39:39.82908Z","price_level":"4218.45","new_quantity":"0.00198654"},{"side":"bid","event_time":"2025-10-27T17:39:39.82908Z","price_level":"4218.43","new_quantity":"0.06408327"},{"side":"bid","event_time":"2025-10-27T17:39:39.82908Z","price_level":"4218.41","new_quantity":"0"},{"side":"bid","event_time":"2025-10-27T17:39:39.82908Z","price_level":"4218.3","new_quantity":"0"},{"side":"bid","event_time":"2025-10-27T17:39:39.82908Z","price_level":"4218.13","new_quantity":"0.437"},{"side":"bid","event_time":"2025-10-27T17:39:39.82908Z","price_level":"4218.01","new_quantity":"0"},{"side":"bid","event_time":"2025-10-27T17:39:39.82908Z","price_level":"4217.81","new_quantity":"0.0023709"},{"side":"bid","event_time":"2025-10-27T17:39:39.82908Z","price_level":"4217.8","new_quantity":"0.519"},{"side":"bid","event_time":"2025-10-27T17:39:39.82908Z","price_level":"4217.66","new_quantity":"0.002"},{"side":"bid","event_time":"2025-10-27T17:39:39.82908Z","price_level":"4217.59","new_quantity":"0"},{"side":"bid","event_time":"2025-10-27T17:39:39.82908Z","price_level":"4216.9","new_quantity":"0.6"},{"side":"offer","event_time":"2025-10-27T17:39:39.82908Z","price_level":"4218.53","new_quantity":"0.33746083"},{"side":"offer","event_time":"2025-10-27T17:39:39.82908Z","price_level":"4218.59","new_quantity":"0.67367094"},{"side":"offer","event_time":"2025-10-27T17:39:39.82908Z","price_level":"4219.14","new_quantity":"0.6856796"},{"side":"offer","event_time":"2025-10-27T17:39:39.82908Z","price_level":"4219.33","new_quantity":"0.01508562"},{"side":"offer","event_time":"2025-10-27T17:39:39.82908Z","price_level":"4219.49","new_quantity":"0"},{"side":"offer","event_time":"2025-10-27T17:39:39.82908Z","price_level":"4219.56","new_quantity":"0.61452728"},{"side":"offer","event_time":"2025-10-27T17:39:39.82908Z","price_level":"4219.66","new_quantity":"0"},{"side":"offer","event_time":"2025-10-27T17:39:39.82908Z","price_level":"4220.13","new_quantity":"0"},{"side":"offer","event_time":"2025-10-27T17:39:39.82908Z","price_level":"4223.73","new_quantity":"0.1536"},{"side":"offer","event_time":"2025-10-27T17:39:39.82908Z","price_level":"4244.82","new_quantity":"0.1536"},{"side":"offer","event_time":"2025-10-27T17:39:39.82908Z","price_level":"4267.21","new_quantity":"0.59881196"},{"side":"offer","event_time":"2025-10-27T17:39:39.82908Z","price_level":"4273.22","new_quantity":"2.25648184"}]}]}
{"channel":"l2_data","client_id":"","timestamp":"2025-10-27T17:39:40.371764669Z","sequence_num":137590,"events":[{"type":"update","product_id":"ETH-USD","updates":[{"side":"bid","event_time":"2025-10-27T17:39:40.334798Z","price_level":"4217.33","new_quantity":"1.65747"},{"side":"bid","event_time":"2025-10-27T17:39:40.334798Z","price_level":"4216.75","new_quantity":"1.401"},{"side":"bid","event_time":"2025-10-27T17:39:40.334798Z","price_level":"4191.63","new_quantity":"0"},{"side":"bid","event_time":"2025-10-27T17:39:40.334798Z","price_level":"4169.88","new_quantity":"0.76740909"},{"side":"bid","event_time":"2025-10-27T17:39:40.334798Z","price_level":"4149.61","new_quantity":"1.15673542"},{"side":"bid","event_time":"2025-10-27T17:39:40.334798Z","price_level":"4129.34","new_quantity":"1.54988319"},{"side":"offer","event_time":"2025-10-27T17:39:40.334798Z","price_level":"4219.34","new_quantity":"1.09766927"},{"side":"offer","event_time":"2025-10-27T17:39:40.334798Z","price_level":"4219.51","new_quantity":"0"},{"side":"offer","event_time":"2025-10-27T17:39:40.334798Z","price_level":"4219.76","new_quantity":"1.4"},{"side":"offer","event_time":"2025-10-27T17:39:40.334798Z","price_level":"4219.8","new_quantity":"10"},{"side":"offer","event_time":"2025-10-27T17:39:40.334798Z","price_level":"4219.9","new_quantity":"10"},{"side":"offer","event_time":"2025-10-27T17:39:40.334798Z","price_level":"4220.2","new_quantity":"0"},{"side":"offer","event_time":"2025-10-27T17:39:40.334798Z","price_level":"4220.42","new_quantity":"0"},{"side":"offer","event_time":"2025-10-27T17:39:40.334798Z","price_level":"4221.77","new_quantity":"13.30091604"},{"side":"offer","event_time":"2025-10-27T17:39:40.334798Z","price_level":"4221.78","new_quantity":"1.95305281"},{"side":"offer","event_time":"2025-10-27T17:39:40.334798Z","price_level":"4221.79","new_quantity":"0.09787466"},{"side":"offer","event_time":"2025-10-27T17:39:40.334798Z","price_level":"4221.8","new_quantity":"0"}]}]}
{"channel":"l2_data","client_id":"","timestamp":"2025-10-27T17:39:40.397266794Z","sequence_num":137592,"events":[{"type":"update","product_id":"BTC-USD","updates":[{"side":"bid","event_time":"2025-10-27T17:39:40.336249Z","price_level":"115644.93","new_quantity":"0"},{"side":"bid","event_time":"2025-10-27T17:39:40.336249Z","price_level":"115617.36","new_quantity":"0.00703181"},{"side":"bid","event_time":"2025-10-27T17:39:40.336249Z","price_level":"115587.5","new_quantity":"0"},{"side":"bid","event_time":"2025-10-27T17:39:40.336249Z","price_level":"115584.1","new_quantity":"1.5"},{"side":"bid","event_time":"2025-10-27T17:39:40.336249Z","price_level":"115414.52","new_quantity":"0"},{"side":"offer","event_time":"2025-10-27T17:39:40.336249Z","price_level":"115683","new_quantity":"0"},{"side":"offer","event_time":"2025-10-27T17:39:40.336249Z","price_level":"115687","new_quantity":"0"},{"side":"offer","event_time":"2025-10-27T17:39:40.336249Z","price_level":"115723.73","new_quantity":"0.00043224"},{"side":"offer","event_time":"2025-10-27T17:39:40.336249Z","price_level":"115727.14","new_quantity":"0"},{"side":"offer","event_time":"2025-10-27T17:39:40.336249Z","price_level":"115728.9","new_quantity":"1"},{"side":"offer","event_time":"2025-10-27T17:39:40.336249Z","price_level":"115729.5","new_quantity":"0"},{"side":"offer","event_time":"2025-10-27T17:39:40.336249Z","price_level":"115735.1","new_quantity":"0.00043224"},{"side":"offer","event_time":"2025-10-27T17:39:40.336249Z","price_level":"115735.11","new_quantity":"0.37930933"},{"side":"offer","event_time":"2025-10-27T17:39:40.336249Z","price_level":"115737.89","new_quantity":"0"}]}]}
{"channel":"l2_data","client_id":"","timestamp":"2025-10-27T17:39:40.420838963Z","sequence_num":137593,"events":[{"type":"update","product_id":"ETH-USD","updates":[{"side":"bid","event_time":"2025-10-27T17:39:40.386693Z","price_level":"4218.48","new_quantity":"0"},{"side":"bid","event_time":"2025-10-27T17:39:40.386693Z","price_level":"4218.08","new_quantity":"0.437"},{"side":"bid","event_time":"2025-10-27T17:39:40.386693Z","price_level":"4217.97","new_quantity":"1.65484"},{"side":"bid","event_time":"2025-10-27T17:39:40.386693Z","price_level":"4216.35","new_quantity":"2.37065727"},{"side":"bid","event_time":"2025-10-27T17:39:40.386693Z","price_level":"4215.85","new_quantity":"1.251"},{"side":"bid","event_time":"2025-10-27T17:39:40.386693Z","price_level":"4212.73","new_quantity":"0.1536"},{"side":"bid","event_time":"2025-10-27T17:39:40.386693Z","price_level":"4191.63","new_quantity":"0.1536"},{"side":"offer","event_time":"2025-10-27T17:39:40.386693Z","price_level":"4218.48","new_quantity":"0.51959741"},{"side":"offer","event_time":"2025-10-27T17:39:40.386693Z","price_level":"4218.49","new_quantity":"0"},{"side":"offer","event_time":"2025-10-27T17:39:40.386693Z","price_level":"4219.7","new_quantity":"10.49495661"},{"side":"offer","event_time":"2025-10-27T17:39:40.386693Z","price_level":"4219.71","new_quantity":"4.509848"},{"side":"offer","event_time":"2025-10-27T17:39:40.386693Z","price_level":"4219.8","new_quantity":"30"},{"side":"offer","event_time":"2025-10-27T17:39:40.386693Z","price_level":"4219.9","new_quantity":"0"},{"side":"offer","event_time":"2025-10-27T17:39:40.386693Z","price_level":"4220","new_quantity":"22.20517286"},{"side":"offer","event_time":"2025-10-27T17:39:40.386693Z","price_level":"4220.37","new_quantity":"4.712575"}]}]}
{"channel":"l2_data","client_id":"","timestamp":"2025-10-27T17:39:40.450001301Z","sequence_num":137594,"events":[{"type":"update","product_id":"BTC-USD","updates":[{"side":"bid","event_time":"2025-10-27T17:39:40.395914Z","price_level":"115643.67","new_quantity":"0.02160734"},{"side":"bid","event_time":"2025-10-27T17:39:40.395914Z","price_level":"101200.04","new_quantity":"0.0049568"},{"side":"offer","event_time":"2025-10-27T17:39:40.395914Z","price_level":"115687.98","new_quantity":"0.38907902"},{"side":"offer","event_time":"2025-10-27T17:39:40.395914Z","price_level":"115691.75","new_quantity":"0.0069609"},{"side":"offer","event_time":"2025-10-27T17:39:40.395914Z","price_level":"115691.99","new_quantity":"0"},{"side":"offer","event_time":"2025-10-27T17:39:40.395914Z","price_level":"115725.95","new_quantity":"0.01993432"},{"side":"offer","event_time":"2025-10-27T17:39:40.395914Z","price_level":"115726.67","new_quantity":"0.25113221"},{"side":"offer","event_time":"2025-10-27T17:39:40.395914Z","price_level":"115727.15","new_quantity":"0"},{"side":"offer","event_time":"2025-10-27T17:39:40.395914Z","price_level":"115742.5","new_quantity":"0"}]}]}
{"channel":"l2_data","client_id":"","timestamp":"2025-10-27T17:39:40.472360341Z","sequence_num":137595,"events":[{"type":"update","product_id":"ETH-USD","updates":[{"side":"bid","event_time":"2025-10-27T17:39:40.437415Z","price_level":"4217.56","new_quantity":"5.77945232"},{"side":"bid","event_time":"2025-10-27T17:39:40.437415Z","price_level":"4217.55","new_quantity":"1.65747"},{"side":"bid","event_time":"2025-10-27T17:39:40.437415Z","price_level":"4217.44","new_quantity":"0"},{"side":"offer","event_time":"2025-10-27T17:39:40.437415Z","price_level":"4219.71","new_quantity":"0"},{"side":"offer","event_time":"2025-10-27T17:39:40.437415Z","price_level":"4219.8","new_quantity":"30"},{"side":"offer","event_time":"2025-10-27T17:39:40.437415Z","price_level":"4220.37","new_quantity":"0"}]}]}
{"channel":"l2_data","client_id":"","timestamp":"2025-10-27T17:39:40.494731615Z","sequence_num":137596,"events":[{"type":"update","product_id":"BTC-USD","updates":[{"side":"offer","event_time":"2025-10-27T17:39:40.450609Z","price_level":"115683","new_quantity":"0.4"},{"side":"offer","event_time":"2025-10-27T17:39:40.450609Z","price_level":"115687","new_quantity":"2"}]}]}
{"channel":"l2_data","client_id":"","timestamp":"2025-10-27T17:39:40.522019125Z","sequence_num":137597,"events":[{"type":"update","product_id":"ETH-USD","updates":[{"side":"bid","event_time":"2025-10-27T17:39:40.484701Z","price_level":"4218.23","new_quantity":"0.07109151"},{"side":"bid","event_time":"2025-10-27T17:39:40.484701Z","price_level":"4218.19","new_quantity":"0"},{"side":"bid","event_time":"2025-10-27T17:39:40.484701Z","price_level":"4218.01","new_quantity":"19.51941648"},{"side":"bid","event_time":"2025-10-27T17:39:40.484701Z","price_level":"4217.85","new_quantity":"1.76316554"},{"side":"bid","event_time":"2025-10-27T17:39:40.484701Z","price_level":"4217.81","new_quantity":"0.11854485"},{"side":"bid","event_time":"2025-10-27T17:39:40.484701Z","price_level":"4217.75","new_quantity":"0.71264162"},{"side":"bid","event_time":"2025-10-27T17:39:40.484701Z","price_level":"4217.58","new_quantity":"0.59275561"},{"side":"bid","event_time":"2025-10-27T17:39:40.484701Z","price_level":"4217.51","new_quantity":"0.5143853"},{"side":"bid","event_time":"2025-10-27T17:39:40.484701Z","price_level":"4191.63","new_quantity":"0"},{"side":"offer","event_time":"2025-10-27T17:39:40.484701Z","price_level":"4218.48","new_quantity":"0.17206943"},{"side":"offer","event_time":"2025-10-27T17:39:40.484701Z","price_level":"4218.5","new_quantity":"0.11852554"},{"side":"offer","event_time":"2025-10-27T17:39:40.484701Z","price_level":"4219.1","new_quantity":"0"},{"side":"offer","event_time":"2025-10-27T17:39:40.484701Z","price_level":"4219.33","new_quantity":"0.01508562"},{"side":"offer","event_time":"2025-10-27T17:39:40.484701Z","price_level":"4219.78","new_quantity":"0.102888"},{"side":"offer","event_time":"2025-10-27T17:39:40.484701Z","price_level":"4220.1","new_quantity":"0"},{"side":"offer","event_time":"2025-10-27T17:39:40.484701Z","price_level":"4221.75","new_quantity":"13.39813267"},{"side":"offer","event_time":"2025-10-27T17:39:40.484701Z","price_level":"4221.76","new_quantity":"1.95300916"},{"side":"offer","event_time":"2025-10-27T17:39:40.484701Z","price_level":"4221.77","new_quantity":"0"},{"side":"offer","event_time":"2025-10-27T17:39:40.484701Z","price_level":"4221.78","new_quantity":"0.00913674"},{"side":"offer","event_time":"2025-10-27T17:39:40.484701Z","price_level":"4223.73","new_quantity":"0"},{"side":"offer","event_time":"2025-10-27T17:39:40.484701Z","price_level":"4244.82","new_quantity":"0.1536"}]}]}
{"channel":"l2_data","client_id":"","timestamp":"2025-10-27T17:39:40.549367574Z","sequence_num":137598,"events":[{"type":"update","product_id":"BTC-USD","updates":[{"side":"bid","event_time":"2025-10-27T17:39:40.503075Z","price_level":"115647.11","new_quantity":"0.00864699"},{"side":"bid","event_time":"2025-10-27T17:39:40.503075Z","price_level":"115645.62","new_quantity":"0.27696309"},{"side":"bid","event_time":"2025-10-27T17:39:40.503075Z","price_level":"115645.61","new_quantity":"0.1425"},{"side":"bid","event_time":"2025-10-27T17:39:40.503075Z","price_level":"115645.6","new_quantity":"0"},{"side":"bid","event_time":"2025-10-27T17:39:40.503075Z","price_level":"115645.31","new_quantity":"0"},{"side":"bid","event_time":"2025-10-27T17:39:40.503075Z","price_level":"115641.38","new_quantity":"0.08647422"},{"side":"bid","event_time":"2025-10-27T17:39:40.503075Z","price_level":"115640.43","new_quantity":"0.19588073"},{"side":"bid","event_time":"2025-10-27T17:39:40.503075Z","price_level":"115637.97","new_quantity":"0.16647"},{"side":"bid","event_time":"2025-10-27T17:39:40.503075Z","price_level":"115635.24","new_quantity":"0.00057275"},{"side":"bid","event_time":"2025-10-27T17:39:40.503075Z","price_level":"115633.28","new_quantity":"0"},{"side":"bid","event_time":"2025-10-27T17:39:40.503075Z","price_level":"115617.11","new_quantity":"0.07007"},{"side":"bid","event_time":"2025-10-27T17:39:40.503075Z","price_level":"115616.05","new_quantity":"0"},{"side":"bid","event_time":"2025-10-27T17:39:40.503075Z","price_level":"115614.45","new_quantity":"0"},{"side":"bid","event_time":"2025-10-27T17:39:40.503075Z","price_level":"114125.84","new_quantity":"0"},{"side":"offer","event_time":"2025-10-27T17:39:40.503075Z","price_level":"115657.19","new_quantity":"0.05713805"},{"side":"offer","event_time":"2025-10-27T17:39:40.503075Z","price_level":"115666.36","new_quantity":"0"},{"side":"offer","event_time":"2025-10-27T17:39:40.503075Z","price_level":"115683","new_quantity":"0"},{"side":"offer","event_time":"2025-10-27T17:39:40.503075Z","price_level":"115687","new_quantity":"0"},{"side":"offer","event_time":"2025-10-27T17:39:40.503075Z","price_level":"115689","new_quantity":"2"},{"side":"offer","event_time":"2025-10-27T17:39:40.503075Z","price_level":"115692","new_quantity":"0"},{"side":"offer","event_time":"2025-10-27T17:39:40.503075Z","price_level":"115692.17","new_quantity":"0"},{"side":"offer","event_time":"2025-10-27T17:39:40.503075Z","price_level":"115727.13","new_quantity":"0.0004323"},{"side":"offer","event_time":"2025-10-27T17:39:40.503075Z","price_level":"116978.5","new_quantity":"0.07007"}]}]}
{"channel":"l2_data","client_id":"","timestamp":"2025-10-27T17:39:40.571994908Z","sequence_num":137599,"events":[{"type":"update","product_id":"ETH-USD","updates":[{"side":"bid","event_time":"2025-10-27T17:39:40.534928Z","price_level":"4217.85","new_quantity":"2.54960331"},{"side":"bid","event_time":"2025-10-27T17:39:40.534928Z","price_level":"4217.75","new_quantity":"2.37011162"},{"side":"bid","event_time":"2025-10-27T17:39:40.534928Z","price_level":"4217.33","new_quantity":"0"},{"side":"bid","event_time":"2025-10-27T17:39:40.534928Z","price_level":"4217.26","new_quantity":"0.21565049"},{"side":"bid","event_time":"2025-10-27T17:39:40.534928Z","price_level":"4215.1","new_quantity":"0.64798652"},{"side":"bid","event_time":"2025-10-27T17:39:40.534928Z","price_level":"4206.71","new_quantity":"33.71033604"},{"side":"offer","event_time":"2025-10-27T17:39:40.534928Z","price_level":"4218.48","new_quantity":"0.00237033"},{"side":"offer","event_time":"2025-10-27T17:39:40.534928Z","price_level":"4219.8","new_quantity":"20"},{"side":"offer","event_time":"2025-10-27T17:39:40.534928Z","price_level":"4229.27","new_quantity":"32.94875798"}]}]}
{"channel":"l2_data","client_id":"","timestamp":"2025-10-27T17:39:40.597095515Z","sequence_num":137601,"events":[{"type":"update","product_id":"BTC-USD","updates":[{"side":"bid","event_time":"2025-10-27T17:39:40.55657Z","price_level":"115585.9","new_quantity":"1.5"},{"side":"bid","event_time":"2025-10-27T17:39:40.55657Z","price_level":"115584.1","new_quantity":"0"},{"side":"offer","event_time":"2025-10-27T17:39:40.55657Z","price_level":"115684","new_quantity":"0"},{"side":"offer","event_time":"2025-10-27T17:39:40.55657Z","price_level":"115688","new_quantity":"2"},{"side":"offer","event_time":"2025-10-27T17:39:40.55657Z","price_level":"115689","new_quantity":"0"},{"side":"offer","event_time":"2025-10-27T17:39:40.55657Z","price_level":"115691.75","new_quantity":"0"},{"side":"offer","event_time":"2025-10-27T17:39:40.55657Z","price_level":"115728.9","new_quantity":"0"},{"side":"offer","event_time":"2025-10-27T17:39:40.55657Z","price_level":"115729.3","new_quantity":"1"}]}]}
{"channel":"l2_data","client_id":"","timestamp":"2025-10-27T17:39:40.621852835Z","sequence_num":137603,"events":[{"type":"update","product_id":"ETH-USD","updates":[{"side":"bid","event_time":"2025-10-27T17:39:40.577735Z","price_level":"4218.28","new_quantity":"0"},{"side":"bid","event_time":"2025-10-27T17:39:40.577735Z","price_level":"4218.23","new_quantity":"0"},{"side":"bid","event_time":"2025-10-27T17:39:40.577735Z","price_level":"4218.01","new_quantity":"0"},{"side":"bid","event_time":"2025-10-27T17:39:40.577735Z","price_level":"4217.56","new_quantity":"0"},{"side":"bid","event_time":"2025-10-27T17:39:40.577735Z","price_level":"4217.47","new_quantity":"0"},{"side":"bid","event_time":"2025-10-27T17:39:40.577735Z","price_level":"4217.46","new_quantity":"5.77958935"},{"side":"offer","event_time":"2025-10-27T17:39:40.577735Z","price_level":"4218.48","new_quantity":"0.19718347"},{"side":"offer","event_time":"2025-10-27T17:39:40.577735Z","price_level":"4218.5","new_quantity":"0.66352554"},{"side":"offer","event_time":"2025-10-27T17:39:40.577735Z","price_level":"4218.68","new_quantity":"0"},{"side":"offer","event_time":"2025-10-27T17:39:40.577735Z","price_level":"4219.1","new_quantity":"0.01508562"},{"side":"offer","event_time":"2025-10-27T17:39:40.577735Z","price_level":"4219.33","new_quantity":"0"},{"side":"offer","event_time":"2025-10-27T17:39:40.577735Z","price_level":"4219.8","new_quantity":"0"},{"side":"offer","event_time":"2025-10-27T17:39:40.577735Z","price_level":"4221.73","new_quantity":"13.30104206"},{"side":"offer","event_time":"2025-10-27T17:39:40.577735Z","price_level":"4221.74","new_quantity":"1.94391607"},{"side":"offer","event_time":"2025-10-27T17:39:40.577735Z","price_level":"4221.75","new_quantity":"0.09715362"},{"side":"offer","event_time":"2025-10-27T17:39:40.577735Z","price_level":"4221.76","new_quantity":"0.00909309"}]}]}
{"channel":"l2_data","client_id":"","timestamp":"2025-10-27T17:39:40.647061042Z","sequence_num":137605,"events":[{"type":"update","product_id":"BTC-USD","updates":[{"side":"bid","event_time":"2025-10-27T17:39:40.610999Z","price_level":"115645.62","new_quantity":"0.3925616"},{"side":"bid","event_time":"2025-10-27T17:39:40.610999Z","price_level":"115643.75","new_quantity":"0.16647"},{"side":"bid","event_time":"2025-10-27T17:39:40.610999Z","price_level":"115643.67","new_quantity":"0"},{"side":"bid","event_time":"2025-10-27T17:39:40.610999Z","price_level":"115632.19","new_quantity":"0"},{"side":"bid","event_time":"2025-10-27T17:39:40.610999Z","price_level":"115628.53","new_quantity":"1.51954644"},{"side":"bid","event_time":"2025-10-27T17:39:40.610999Z","price_level":"115627","new_quantity":"0.4"},{"side":"bid","event_time":"2025-10-27T17:39:40.610999Z","price_level":"115585.9","new_quantity":"0"},{"side":"bid","event_time":"2025-10-27T17:39:40.610999Z","price_level":"115585","new_quantity":"1.5"},{"side":"offer","event_time":"2025-10-27T17:39:40.610999Z","price_level":"115685","new_quantity":"0"},{"side":"offer","event_time":"2025-10-27T17:39:40.610999Z","price_level":"115688","new_quantity":"0"},{"side":"offer","event_time":"2025-10-27T17:39:40.610999Z","price_level":"115690","new_quantity":"1"}]}]}
{"channel":"l2_data","client_id":"","timestamp":"2025-10-27T17:39:40.670431385Z","sequence_num":137606,"events":[{"type":"update","product_id":"ETH-USD","updates":[{"side":"bid","event_time":"2025-10-27T17:39:40.613993Z","price_level":"4217.55","new_quantity":"0"},{"side":"offer","event_time":"2025-10-27T17:39:40.613993Z","price_level":"4218.48","new_quantity":"0.37495145"},{"side":"offer","event_time":"2025-10-27T17:39:40.613993Z","price_level":"4220","new_quantity":"42.20517286"},{"side":"offer","event_time":"2025-10-27T17:39:40.613993Z","price_level":"4223.73","new_quantity":"0.1536"},{"side":"offer","event_time":"2025-10-27T17:39:40.613993Z","price_level":"4272.99","new_quantity":"7.33028311"}]}]}
{"channel":"l2_data","client_id":"","timestamp":"2025-10-27T17:39:40.698288271Z","sequence_num":137607,"events":[{"type":"update","product_id":"BTC-USD","updates":[{"side":"bid","event_time":"2025-10-27T17:39:40.662702Z","price_level":"115656","new_quantity":"0.0236"},{"side":"bid","event_time":"2025-10-27T17:39:40.662702Z","price_level":"115645.63","new_quantity":"0.00046705"},{"side":"bid","event_time":"2025-10-27T17:39:40.662702Z","price_level":"115640.43","new_quantity":"0.42297711"},{"side":"bid","event_time":"2025-10-27T17:39:40.662702Z","price_level":"115637.97","new_quantity":"0"},{"side":"bid","event_time":"2025-10-27T17:39:40.662702Z","price_level":"115637","new_quantity":"0.4"},{"side":"bid","event_time":"2025-10-27T17:39:40.662702Z","price_level":"115635.24","new_quantity":"0"},{"side":"bid","event_time":"2025-10-27T17:39:40.662702Z","price_level":"115633","new_quantity":"0.4"},{"side":"bid","event_time":"2025-10-27T17:39:40.662702Z","price_level":"115631","new_quantity":"0"},{"side":"bid","event_time":"2025-10-27T17:39:40.662702Z","price_level":"115628.53","new_quantity":"1.51954644"},{"side":"bid","event_time":"2025-10-27T17:39:40.662702Z","price_level":"115627","new_quantity":"0.4"},{"side":"bid","event_time":"2025-10-27T17:39:40.662702Z","price_level":"115620.01","new_quantity":"0"},{"side":"bid","event_time":"2025-10-27T17:39:40.662702Z","price_level":"115620","new_quantity":"0"},{"side":"offer","event_time":"2025-10-27T17:39:40.662702Z","price_level":"115657.19","new_quantity":"0.03148179"},{"side":"offer","event_time":"2025-10-27T17:39:40.662702Z","price_level":"115662.07","new_quantity":"0"},{"side":"offer","event_time":"2025-10-27T17:39:40.662702Z","price_level":"115664.43","new_quantity":"0"},{"side":"offer","event_time":"2025-10-27T17:39:40.662702Z","price_level":"115686.71","new_quantity":"0.00172383"},{"side":"offer","event_time":"2025-10-27T17:39:40.662702Z","price_level":"115686.72","new_quantity":"0.00323072"},{"side":"offer","event_time":"2025-10-27T17:39:40.662702Z","price_level":"115687.97","new_quantity":"0.138338"},{"side":"offer","event_time":"2025-10-27T17:39:40.662702Z","price_level":"115690","new_quantity":"1"},{"side":"offer","event_time":"2025-10-27T17:39:40.662702Z","price_level":"115695","new_quantity":"0.4"},{"side":"offer","event_time":"2025-10-27T17:39:40.662702Z","price_level":"115714.57","new_quantity":"0"},{"side":"offer","event_time":"2025-10-27T17:39:40.662702Z","price_level":"115718.25","new_quantity":"0"},{"side":"offer","event_time":"2025-10-27T17:39:40.662702Z","price_level":"115747.16","new_quantity":"0"}]}]}
{"channel":"l2_data","client_id":"","timestamp":"2025-10-27T17:39:40.719342565Z","sequence_num":137608,"events":[{"type":"update","product_id":"ETH-USD","updates":[{"side":"offer","event_time":"2025-10-27T17:39:40.6822Z","price_level":"4218.5","new_quantity":"0.66352554"},{"side":"offer","event_time":"2025-10-27T17:39:40.6822Z","price_level":"4219.1","new_quantity":"0"},{"side":"offer","event_time":"2025-10-27T17:39:40.6822Z","price_level":"4219.33","new_quantity":"0.01508562"},{"side":"offer","event_time":"2025-10-27T17:39:40.6822Z","price_level":"4219.76","new_quantity":"0"},{"side":"offer","event_time":"2025-10-27T17:39:40.6822Z","price_level":"4221.71","new_quantity":"13.30110507"},{"side":"offer","event_time":"2025-10-27T17:39:40.6822Z","price_level":"4221.72","new_quantity":"1.94391607"},{"side":"offer","event_time":"2025-10-27T17:39:40.6822Z","price_level":"4221.73","new_quantity":"0"},{"side":"offer","event_time":"2025-10-27T17:39:40.6822Z","price_level":"4221.74","new_quantity":"0"}]}]}
{"channel":"l2_data","client_id":"","timestamp":"2025-10-27T17:39:40.748537403Z","sequence_num":137609,"events":[{"type":"update","product_id":"BTC-USD","updates":[{"side":"bid","event_time":"2025-10-27T17:39:40.687296Z","price_level":"115654.77","new_quantity":"0.00990978"},{"side":"bid","event_time":"2025-10-27T17:39:40.687296Z","price_level":"115650.02","new_quantity":"0.00172935"},{"side":"bid","event_time":"2025-10-27T17:39:40.687296Z","price_level":"115650.01","new_quantity":"0"},{"side":"bid","event_time":"2025-10-27T17:39:40.687296Z","price_level":"115650","new_quantity":"0.00601642"},{"side":"bid","event_time":"2025-10-27T17:39:40.687296Z","price_level":"115636","new_quantity":"0.4"},{"side":"bid","event_time":"2025-10-27T17:39:40.687296Z","price_level":"115633.01","new_quantity":"2.21697535"},{"side":"bid","event_time":"2025-10-27T17:39:40.687296Z","price_level":"115633","new_quantity":"0"},{"side":"bid","event_time":"2025-10-27T17:39:40.687296Z","price_level":"115630","new_quantity":"2"},{"side":"bid","event_time":"2025-10-27T17:39:40.687296Z","price_level":"115620","new_quantity":"1"},{"side":"offer","event_time":"2025-10-27T17:39:40.687296Z","price_level":"115658.61","new_quantity":"0.0259384"},{"side":"offer","event_time":"2025-10-27T17:39:40.687296Z","price_level":"115686.71","new_quantity":"0"},{"side":"offer","event_time":"2025-10-27T17:39:40.687296Z","price_level":"115686.72","new_quantity":"0"},{"side":"offer","event_time":"2025-10-27T17:39:40.687296Z","price_level":"115687.99","new_quantity":"0"},{"side":"offer","event_time":"2025-10-27T17:39:40.687296Z","price_level":"115690","new_quantity":"0"},{"side":"offer","event_time":"2025-10-27T17:39:40.687296Z","price_level":"115729.3","new_quantity":"0"},{"side":"offer","event_time":"2025-10-27T17:39:40.687296Z","price_level":"115735.8","new_quantity":"1"}]}]}
{"channel":"l2_data","client_id":"","timestamp":"2025-10-27T17:39:40.770734969Z","sequence_num":137610,"events":[{"type":"update","product_id":"ETH-USD","updates":[{"side":"bid","event_time":"2025-10-27T17:39:40.735284Z","price_level":"4218.39","new_quantity":"0.07109351"},{"side":"bid","event_time":"2025-10-27T17:39:40.735284Z","price_level":"4218.01","new_quantity":"19.51941648"},{"side":"bid","event_time":"2025-10-27T17:39:40.735284Z","price_level":"4217.36","new_quantity":"0.6"},{"side":"bid","event_time":"2025-10-27T17:39:40.735284Z","price_level":"4216.36","new_quantity":"4.00100641"},{"side":"bid","event_time":"2025-10-27T17:39:40.735284Z","price_level":"4215.03","new_quantity":"8.84588093"},{"side":"bid","event_time":"2025-10-27T17:39:40.735284Z","price_level":"4215.01","new_quantity":"0"},{"side":"bid","event_time":"2025-10-27T17:39:40.735284Z","price_level":"4213.66","new_quantity":"0.42873289"},{"side":"bid","event_time":"2025-10-27T17:39:40.735284Z","price_level":"4212.2","new_quantity":"21.17883528"},{"side":"bid","event_time":"2025-10-27T17:39:40.735284Z","price_level":"4211.1","new_quantity":"3.9271013"},{"side":"offer","event_time":"2025-10-27T17:39:40.735284Z","price_level":"4218.5","new_quantity":"0.11852554"},{"side":"offer","event_time":"2025-10-27T17:39:40.735284Z","price_level":"4219.56","new_quantity":"4.93275114"},{"side":"offer","event_time":"2025-10-27T17:39:40.735284Z","price_level":"4222.74","new_quantity":"0"},{"side":"offer","event_time":"2025-10-27T17:39:40.735284Z","price_level":"4244.82","new_quantity":"0"}]}]}
{"channel":"l2_data","client_id":"","timestamp":"2025-10-27T17:39:40.798366095Z","sequence_num":137611,"events":[{"type":"update","product_id":"BTC-USD","updates":[{"side":"bid","event_time":"2025-10-27T17:39:40.7417Z","price_level":"115645.63","new_quantity":"0.00074869"},{"side":"bid","event_time":"2025-10-27T17:39:40.7417Z","price_level":"115645.09","new_quantity":"0.02160849"},{"side":"bid","event_time":"2025-10-27T17:39:40.7417Z","price_level":"115640.43","new_quantity":"0.33429676"},{"side":"bid","event_time":"2025-10-27T17:39:40.7417Z","price_level":"115638","new_quantity":"0.4"},{"side":"bid","event_time":"2025-10-27T17:39:40.7417Z","price_level":"115637.55","new_quantity":"0.00432"},{"side":"bid","event_time":"2025-10-27T17:39:40.7417Z","price_level":"115637.52","new_quantity":"0.00432"},{"side":"bid","event_time":"2025-10-27T17:39:40.7417Z","price_level":"115637","new_quantity":"0"},{"side":"bid","event_time":"2025-10-27T17:39:40.7417Z","price_level":"115636","new_quantity":"0"},{"side":"bid","event_time":"2025-10-27T17:39:40.7417Z","price_level":"115633.01","new_quantity":"2.17590839"},{"side":"bid","event_time":"2025-10-27T17:39:40.7417Z","price_level":"115630","new_quantity":"0"},{"side":"bid","event_time":"2025-10-27T17:39:40.7417Z","price_level":"115629.01","new_quantity":"0.33121111"},{"side":"bid","event_time":"2025-10-27T17:39:40.7417Z","price_level":"115629","new_quantity":"2.4"},{"side":"bid","event_time":"2025-10-27T17:39:40.7417Z","price_level":"115628.24","new_quantity":"0"},{"side":"bid","event_time":"2025-10-27T17:39:40.7417Z","price_level":"115613.99","new_quantity":"0.52631547"},{"side":"bid","event_time":"2025-10-27T17:39:40.7417Z","price_level":"115613.98","new_quantity":"1.46731969"},{"side":"bid","event_time":"2025-10-27T17:39:40.7417Z","price_level":"115612.82","new_quantity":"0"},{"side":"bid","event_time":"2025-10-27T17:39:40.7417Z","price_level":"115567.29","new_quantity":"1.20622876"},{"side":"bid","event_time":"2025-10-27T17:39:40.7417Z","price_level":"115567.27","new_quantity":"0.00043224"},{"side":"bid","event_time":"2025-10-27T17:39:40.7417Z","price_level":"115511.8","new_quantity":"0.06287431"},{"side":"bid","event_time":"2025-10-27T17:39:40.7417Z","price_level":"101200.04","new_quantity":"0"},{"side":"offer","event_time":"2025-10-27T17:39:40.7417Z","price_level":"115657.19","new_quantity":"0.0026124"},{"side":"offer","event_time":"2025-10-27T17:39:40.7417Z","price_level":"115672.28","new_quantity":"0.00432"},{"side":"offer","event_time":"2025-10-27T17:39:40.7417Z","price_level":"115674.61","new_quantity":"0.00432"},{"side":"offer","event_time":"2025-10-27T17:39:40.7417Z","price_level":"115694","new_quantity":"0"},{"side":"offer","event_time":"2025-10-27T17:39:40.7417Z","price_level":"115695","new_quantity":"0"},{"side":"offer","event_time":"2025-10-27T17:39:40.7417Z","price_level":"115698.57","new_quantity":"0.71177846"},{"side":"offer","event_time":"2025-10-27T17:39:40.7417Z","price_level":"115706.38","new_quantity":"0"},{"side":"offer","event_time":"2025-10-27T17:39:40.7417Z","price_level":"115709.99","new_quantity":"0.1681001"},{"side":"offer","event_time":"2025-10-27T17:39:40.7417Z","price_level":"115735.09","new_quantity":"0.3793094"},{"side":"offer","event_time":"2025-10-27T17:39:40.7417Z","price_level":"115735.1","new_quantity":"0.97756857"},{"side":"offer","event_time":"2025-10-27T17:39:40.7417Z","price_level":"115735.11","new_quantity":"0"}]}]}
{"channel":"l2_data","client_id":"","timestamp":"2025-10-27T17:39:40.847471651Z","sequence_num":137614,"events":[{"type":"update","product_id":"BTC-USD","updates":[{"side":"bid","event_time":"2025-10-27T17:39:40.806961Z","price_level":"115648.73","new_quantity":"0.00864687"},{"side":"bid","event_time":"2025-10-27T17:39:40.806961Z","price_level":"115647.11","new_quantity":"0"},{"side":"bid","event_time":"2025-10-27T17:39:40.806961Z","price_level":"115640.43","new_quantity":"0.10949555"},{"side":"bid","event_time":"2025-10-27T17:39:40.806961Z","price_level":"115639.87","new_quantity":"0.00432"},{"side":"bid","event_time":"2025-10-27T17:39:40.806961Z","price_level":"115638","new_quantity":"0"},{"side":"bid","event_time":"2025-10-27T17:39:40.806961Z","price_level":"115635.23","new_quantity":"0"},{"side":"bid","event_time":"2025-10-27T17:39:40.806961Z","price_level":"115633","new_quantity":"0"},{"side":"bid","event_time":"2025-10-27T17:39:40.806961Z","price_level":"115585","new_quantity":"0"},{"side":"bid","event_time":"2025-10-27T17:39:40.806961Z","price_level":"115582.1","new_quantity":"1.5"},{"side":"offer","event_time":"2025-10-27T17:39:40.806961Z","price_level":"115672.28","new_quantity":"0"},{"side":"offer","event_time":"2025-10-27T17:39:40.806961Z","price_level":"115686.72","new_quantity":"0.00189858"},{"side":"offer","event_time":"2025-10-27T17:39:40.806961Z","price_level":"115690","new_quantity":"2"},{"side":"offer","event_time":"2025-10-27T17:39:40.806961Z","price_level":"115695","new_quantity":"0.4"},{"side":"offer","event_time":"2025-10-27T17:39:40.806961Z","price_level":"115700","new_quantity":"1"},{"side":"offer","event_time":"2025-10-27T17:39:40.806961Z","price_level":"115735.1","new_quantity":"0.00043224"},{"side":"offer","event_time":"2025-10-27T17:39:40.806961Z","price_level":"115735.8","new_quantity":"0"},{"side":"offer","event_time":"2025-10-27T17:39:40.806961Z","price_level":"115736.1","new_quantity":"1"},{"side":"offer","event_time":"2025-10-27T17:39:40.806961Z","price_level":"115741.49","new_quantity":"0.57740909"},{"side":"offer","event_time":"2025-10-27T17:39:40.806961Z","price_level":"115741.5","new_quantity":"0"},{"side":"offer","event_time":"2025-10-27T17:39:40.806961Z","price_level":"115743.87","new_quantity":"0"}]}]}
{"channel":"l2_data","client_id":"","timestamp":"2025-10-27T17:39:40.86921632Z","sequence_num":137615,"events":[{"type":"update","product_id":"ETH-USD","updates":[{"side":"offer","event_time":"2025-10-27T17:39:40.838163Z","price_level":"4218.48","new_quantity":"0.19718347"},{"side":"offer","event_time":"2025-10-27T17:39:40.838163Z","price_level":"4218.5","new_quantity":"0.66352554"},{"side":"offer","event_time":"2025-10-27T17:39:40.838163Z","price_level":"4219.67","new_quantity":"1.4"}]}]}
{"channel":"l2_data","client_id":"","timestamp":"2025-10-27T17:39:40.897682474Z","sequence_num":137616,"events":[{"type":"update","product_id":"BTC-USD","updates":[{"side":"bid","event_time":"2025-10-27T17:39:40.855809Z","price_level":"115640.43","new_quantity":"0.33945484"},{"side":"bid","event_time":"2025-10-27T17:39:40.855809Z","price_level":"115636","new_quantity":"0.4"},{"side":"bid","event_time":"2025-10-27T17:39:40.855809Z","price_level":"115630","new_quantity":"0"},{"side":"bid","event_time":"2025-10-27T17:39:40.855809Z","price_level":"115629","new_quantity":"2"},{"side":"bid","event_time":"2025-10-27T17:39:40.855809Z","price_level":"115620.65","new_quantity":"0.36933322"},{"side":"bid","event_time":"2025-10-27T17:39:40.855809Z","price_level":"115619.13","new_quantity":"0.07007"},{"side":"bid","event_time":"2025-10-27T17:39:40.855809Z","price_level":"115613.98","new_quantity":"0"},{"side":"bid","event_time":"2025-10-27T17:39:40.855809Z","price_level":"115612.81","new_quantity":"0"},{"side":"bid","event_time":"2025-10-27T17:39:40.855809Z","price_level":"114118.12","new_quantity":"0.07007"},{"side":"offer","event_time":"2025-10-27T17:39:40.855809Z","price_level":"115662.3","new_quantity":"0.012556"},{"side":"offer","event_time":"2025-10-27T17:39:40.855809Z","price_level":"115674.6","new_quantity":"0.00432"},{"side":"offer","event_time":"2025-10-27T17:39:40.855809Z","price_level":"115686.72","new_quantity":"0"},{"side":"offer","event_time":"2025-10-27T17:39:40.855809Z","price_level":"115689","new_quantity":"0.4"},{"side":"offer","event_time":"2025-10-27T17:39:40.855809Z","price_level":"115690","new_quantity":"2"},{"side":"offer","event_time":"2025-10-27T17:39:40.855809Z","price_level":"115694","new_quantity":"0.4"},{"side":"offer","event_time":"2025-10-27T17:39:40.855809Z","price_level":"115695","new_quantity":"0"},{"side":"offer","event_time":"2025-10-27T17:39:40.855809Z","price_level":"115700","new_quantity":"1"},{"side":"offer","event_time":"2025-10-27T17:39:40.855809Z","price_level":"115712.72","new_quantity":"0.058098"},{"side":"offer","event_time":"2025-10-27T17:39:40.855809Z","price_level":"115716.33","new_quantity":"0.082997"},{"side":"offer","event_time":"2025-10-27T17:39:40.855809Z","price_level":"115745.24","new_quantity":"0.103747"},{"side":"offer","event_time":"2025-10-27T17:39:40.855809Z","price_level":"116766.89","new_quantity":"0.07007"},{"side":"offer","event_time":"2025-10-27T17:39:40.855809Z","price_level":"116767.16","new_quantity":"0.07007"},{"side":"offer","event_time":"2025-10-27T17:39:40.855809Z","price_level":"116978.5","new_quantity":"0"}]}]}
{"channel":"l2_data","client_id":"","timestamp":"2025-10-27T17:39:40.921288907Z","sequence_num":137617,"events":[{"type":"update","product_id":"ETH-USD","updates":[{"side":"bid","event_time":"2025-10-27T17:39:40.889524Z","price_level":"4218.44","new_quantity":"0.07109351"},{"side":"bid","event_time":"2025-10-27T17:39:40.889524Z","price_level":"4218.39","new_quantity":"0"},{"side":"bid","event_time":"2025-10-27T17:39:40.889524Z","price_level":"4217.85","new_quantity":"1.76316554"},{"side":"bid","event_time":"2025-10-27T17:39:40.889524Z","price_level":"4217.75","new_quantity":"0.71264162"},{"side":"bid","event_time":"2025-10-27T17:39:40.889524Z","price_level":"4212.73","new_quantity":"0"},{"side":"bid","event_time":"2025-10-27T17:39:40.889524Z","price_level":"4191.63","new_quantity":"0.1536"},{"side":"offer","event_time":"2025-10-27T17:39:40.889524Z","price_level":"4218.48","new_quantity":"0.35271943"},{"side":"offer","event_time":"2025-10-27T17:39:40.889524Z","price_level":"4218.88","new_quantity":"0"},{"side":"offer","event_time":"2025-10-27T17:39:40.889524Z","price_level":"4221.69","new_quantity":"13.30116809"},{"side":"offer","event_time":"2025-10-27T17:39:40.889524Z","price_level":"4221.7","new_quantity":"1.94391607"},{"side":"offer","event_time":"2025-10-27T17:39:40.889524Z","price_level":"4221.71","new_quantity":"0"},{"side":"offer","event_time":"2025-10-27T17:39:40.889524Z","price_level":"4221.72","new_quantity":"0"}]}]}
{"channel":"l2_data","client_id":"","timestamp":"2025-10-27T17:39:40.943640644Z","sequence_num":137619,"events":[{"type":"update","product_id":"BTC-USD","updates":[{"side":"offer","event_time":"2025-10-27T17:39:40.884823Z","price_level":"115686.72","new_quantity":"0.0023312"},{"side":"offer","event_time":"2025-10-27T17:39:40.884823Z","price_level":"115689","new_quantity":"0"},{"side":"offer","event_time":"2025-10-27T17:39:40.884823Z","price_level":"115690","new_quantity":"0"},{"side":"offer","event_time":"2025-10-27T17:39:40.884823Z","price_level":"115700","new_quantity":"0"},{"side":"offer","event_time":"2025-10-27T17:39:40.884823Z","price_level":"116765.94","new_quantity":"0.07007"},{"side":"offer","event_time":"2025-10-27T17:39:40.884823Z","price_level":"116766.2","new_quantity":"0.07007"},{"side":"offer","event_time":"2025-10-27T17:39:40.884823Z","price_level":"116766.89","new_quantity":"0"},{"side":"offer","event_time":"2025-10-27T17:39:40.884823Z","price_level":"116767.16","new_quantity":"0"}]}]}
{"channel":"l2_data","client_id":"","timestamp":"2025-10-27T17:39:40.971017778Z","sequence_num":137620,"events":[{"type":"update","product_id":"ETH-USD","updates":[{"side":"bid","event_time":"2025-10-27T17:39:40.925669Z","price_level":"4218.47","new_quantity":"1.43303545"},{"side":"bid","event_time":"2025-10-27T17:39:40.925669Z","price_level":"4218.44","new_quantity":"0"},{"side":"bid","event_time":"2025-10-27T17:39:40.925669Z","price_level":"4218.21","new_quantity":"14.5167714"},{"side":"bid","event_time":"2025-10-27T17:39:40.925669Z","price_level":"4217.96","new_quantity":"0"},{"side":"bid","event_time":"2025-10-27T17:39:40.925669Z","price_level":"4217.85","new_quantity":"3.07155062"},{"side":"bid","event_time":"2025-10-27T17:39:40.925669Z","price_level":"4217.81","new_quantity":"0"},{"side":"bid","event_time":"2025-10-27T17:39:40.925669Z","price_level":"4217.75","new_quantity":"2.37011162"},{"side":"bid","event_time":"2025-10-27T17:39:40.925669Z","price_level":"4217.62","new_quantity":"5.7793701"},{"side":"bid","event_time":"2025-10-27T17:39:40.925669Z","price_level":"4217.46","new_quantity":"0"},{"side":"bid","event_time":"2025-10-27T17:39:40.925669Z","price_level":"4217.45","new_quantity":"0"},{"side":"bid","event_time":"2025-10-27T17:39:40.925669Z","price_level":"4216.79","new_quantity":"2.37058253"},{"side":"bid","event_time":"2025-10-27T17:39:40.925669Z","price_level":"4216.36","new_quantity":"0"},{"side":"bid","event_time":"2025-10-27T17:39:40.925669Z","price_level":"4216.35","new_quantity":"0"},{"side":"bid","event_time":"2025-10-27T17:39:40.925669Z","price_level":"4215.11","new_quantity":"8.84571304"},{"side":"bid","event_time":"2025-10-27T17:39:40.925669Z","price_level":"4215.03","new_quantity":"0"},{"side":"bid","event_time":"2025-10-27T17:39:40.925669Z","price_level":"4214.51","new_quantity":"12.86295183"},{"side":"bid","event_time":"2025-10-27T17:39:40.925669Z","price_level":"4214.3","new_quantity":"0.00199035"},{"side":"bid","event_time":"2025-10-27T17:39:40.925669Z","price_level":"4214.2","new_quantity":"19.62286355"},{"side":"bid","event_time":"2025-10-27T17:39:40.925669Z","price_level":"4214.02","new_quantity":"0"},{"side":"bid","event_time":"2025-10-27T17:39:40.925669Z","price_level":"4212.73","new_quantity":"0.1536"},{"side":"offer","event_time":"2025-10-27T17:39:40.925669Z","price_level":"4218.48","new_quantity":"0.02748437"},{"side":"offer","event_time":"2025-10-27T17:39:40.925669Z","price_level":"4218.5","new_quantity":"0"},{"side":"offer","event_time":"2025-10-27T17:39:40.925669Z","price_level":"4218.59","new_quantity":"0"},{"side":"offer","event_time":"2025-10-27T17:39:40.925669Z","price_level":"4218.6","new_quantity":"0"},{"side":"offer","event_time":"2025-10-27T17:39:40.925669Z","price_level":"4218.67","new_quantity":"0.71112525"},{"side":"offer","event_time":"2025-10-27T17:39:40.925669Z","price_level":"4218.7","new_quantity":"0"},{"side":"offer","event_time":"2025-10-27T17:39:40.925669Z","price_level":"4218.99","new_quantity":"0.31044"},{"side":"offer","event_time":"2025-10-27T17:39:40.925669Z","price_level":"4219.11","new_quantity":"0"},{"side":"offer","event_time":"2025-10-27T17:39:40.925669Z","price_level":"4219.33","new_quantity":"0"},{"side":"offer","event_time":"2025-10-27T17:39:40.925669Z","price_level":"4219.34","new_quantity":"1.125"},{"side":"offer","event_time":"2025-10-27T17:39:40.925669Z","price_level":"4219.56","new_quantity":"0.61452728"},{"side":"offer","event_time":"2025-10-27T17:39:40.925669Z","price_level":"4219.58","new_quantity":"0"},{"side":"offer","event_time":"2025-10-27T17:39:40.925669Z","price_level":"4219.66","new_quantity":"0.01508562"},{"side":"offer","event_time":"2025-10-27T17:39:40.925669Z","price_level":"4219.7","new_quantity":"0.49495661"},{"side":"offer","event_time":"2025-10-27T17:39:40.925669Z","price_level":"4220","new_quantity":"22.20517286"},{"side":"offer","event_time":"2025-10-27T17:39:40.925669Z","price_level":"4220.67","new_quantity":"0.00886424"},{"side":"offer","event_time":"2025-10-27T17:39:40.925669Z","price_level":"4220.82","new_quantity":"9.00153202"}]}]}
{"channel":"l2_data","client_id":"","timestamp":"2025-10-27T17:39:40.99875497Z","sequence_num":137621,"events":[{"type":"update","product_id":"BTC-USD","updates":[{"side":"bid","event_time":"2025-10-27T17:39:40.940941Z","price_level":"115652.01","new_quantity":"0.00172932"},{"side":"bid","event_time":"2025-10-27T17:39:40.940941Z","price_level":"115650.02","new_quantity":"0"},{"side":"bid","event_time":"2025-10-27T17:39:40.940941Z","price_level":"115645.58","new_quantity":"0.08647108"},{"side":"bid","event_time":"2025-10-27T17:39:40.940941Z","price_level":"115639.84","new_quantity":"0.00432"},{"side":"bid","event_time":"2025-10-27T17:39:40.940941Z","price_level":"115635.2","new_quantity":"0"},{"side":"bid","event_time":"2025-10-27T17:39:40.940941Z","price_level":"115633.77","new_quantity":"0"},{"side":"bid","event_time":"2025-10-27T17:39:40.940941Z","price_level":"115619.83","new_quantity":"0.07007"},{"side":"bid","event_time":"2025-10-27T17:39:40.940941Z","price_level":"115619.13","new_quantity":"0"},{"side":"bid","event_time":"2025-10-27T17:39:40.940941Z","price_level":"115617.11","new_quantity":"0"},{"side":"bid","event_time":"2025-10-27T17:39:40.940941Z","price_level":"115404.54","new_quantity":"0.07007"},{"side":"bid","event_time":"2025-10-27T17:39:40.940941Z","price_level":"115199.12","new_quantity":"0"},{"side":"bid","event_time":"2025-10-27T17:39:40.940941Z","price_level":"114554.85","new_quantity":"0"},{"side":"bid","event_time":"2025-10-27T17:39:40.940941Z","price_level":"114381.78","new_quantity":"0.01398824"},{"side":"bid","event_time":"2025-10-27T17:39:40.940941Z","price_level":"114340.42","new_quantity":"0"},{"side":"bid","event_time":"2025-10-27T17:39:40.940941Z","price_level":"114118.12","new_quantity":"0"},{"side":"bid","event_time":"2025-10-27T17:39:40.940941Z","price_level":"113834.9","new_quantity":"0.02108316"},{"side":"bid","event_time":"2025-10-27T17:39:40.940941Z","price_level":"113288.02","new_quantity":"0.02824659"},{"side":"offer","event_time":"2025-10-27T17:39:40.940941Z","price_level":"115674.6","new_quantity":"0"},{"side":"offer","event_time":"2025-10-27T17:39:40.940941Z","price_level":"115674.61","new_quantity":"0"},{"side":"offer","event_time":"2025-10-27T17:39:40.940941Z","price_level":"115676.93","new_quantity":"0.00432"},{"side":"offer","event_time":"2025-10-27T17:39:40.940941Z","price_level":"115686.72","new_quantity":"0"},{"side":"offer","event_time":"2025-10-27T17:39:40.940941Z","price_level":"115687.97","new_quantity":"0"},{"side":"offer","event_time":"2025-10-27T17:39:40.940941Z","price_level":"115689","new_quantity":"0"},{"side":"offer","event_time":"2025-10-27T17:39:40.940941Z","price_level":"115689.6","new_quantity":"0.138348"},{"side":"offer","event_time":"2025-10-27T17:39:40.940941Z","price_level":"115690","new_quantity":"0"},{"side":"offer","event_time":"2025-10-27T17:39:40.940941Z","price_level":"115691.87","new_quantity":"0.0069609"},{"side":"offer","event_time":"2025-10-27T17:39:40.940941Z","price_level":"115700","new_quantity":"0"},{"side":"offer","event_time":"2025-10-27T17:39:40.940941Z","price_level":"115736.1","new_quantity":"0"},{"side":"offer","event_time":"2025-10-27T17:39:40.940941Z","price_level":"115739.6","new_quantity":"1"},{"side":"offer","event_time":"2025-10-27T17:39:40.940941Z","price_level":"115741.8","new_quantity":"0"},{"side":"offer","event_time":"2025-10-27T17:39:40.940941Z","price_level":"116766.2","new_quantity":"0"},{"side":"offer","event_time":"2025-10-27T17:39:40.940941Z","price_level":"116981.38","new_quantity":"0.07007"}]}]}
{"channel":"l2_data","client_id":"","timestamp":"2025-10-27T17:39:41.021820269Z","sequence_num":137622,"events":[{"type":"update","product_id":"ETH-USD","updates":[{"side":"bid","event_time":"2025-10-27T17:39:40.974271Z","price_level":"4218.41","new_quantity":"11.94"},{"side":"bid","event_time":"2025-10-27T17:39:40.974271Z","price_level":"4218.31","new_quantity":"0.00237062"},{"side":"bid","event_time":"2025-10-27T17:39:40.974271Z","price_level":"4218.14","new_quantity":"0.11853551"},{"side":"bid","event_time":"2025-10-27T17:39:40.974271Z","price_level":"4217.97","new_quantity":"3.90501202"},{"side":"bid","event_time":"2025-10-27T17:39:40.974271Z","price_level":"4217.58","new_quantity":"0"},{"side":"offer","event_time":"2025-10-27T17:39:40.974271Z","price_level":"4218.79","new_quantity":"0"},{"side":"offer","event_time":"2025-10-27T17:39:40.974271Z","price_level":"4219.33","new_quantity":"1.76929427"},{"side":"offer","event_time":"2025-10-27T17:39:40.974271Z","price_level":"4219.56","new_quantity":"1.06172911"},{"side":"offer","event_time":"2025-10-27T17:39:40.974271Z","price_level":"4220","new_quantity":"12.20517286"},{"side":"offer","event_time":"2025-10-27T17:39:40.974271Z","price_level":"4220.2","new_quantity":"10"},{"side":"offer","event_time":"2025-10-27T17:39:40.974271Z","price_level":"4220.4","new_quantity":"20"}]}]}
{"channel":"l2_data","client_id":"","timestamp":"2025-10-27T17:39:41.048117546Z","sequence_num":137623,"events":[{"type":"update","product_id":"BTC-USD","updates":[{"side":"bid","event_time":"2025-10-27T17:39:40.997705Z","price_level":"115657.18","new_quantity":"0.0685524"},{"side":"bid","event_time":"2025-10-27T17:39:40.997705Z","price_level":"115652.01","new_quantity":"0.00172932"},{"side":"bid","event_time":"2025-10-27T17:39:40.997705Z","price_level":"115645.63","new_quantity":"0"},{"side":"bid","event_time":"2025-10-27T17:39:40.997705Z","price_level":"115645.09","new_quantity":"0"},{"side":"bid","event_time":"2025-10-27T17:39:40.997705Z","price_level":"115643.53","new_quantity":"0.02160848"},{"side":"bid","event_time":"2025-10-27T17:39:40.997705Z","price_level":"115640.43","new_quantity":"0.10949555"},{"side":"bid","event_time":"2025-10-27T17:39:40.997705Z","price_level":"115636","new_quantity":"0"},{"side":"bid","event_time":"2025-10-27T17:39:40.997705Z","price_level":"115635","new_quantity":"0.4"},{"side":"bid","event_time":"2025-10-27T17:39:40.997705Z","price_level":"115633.01","new_quantity":"1.19351579"},{"side":"bid","event_time":"2025-10-27T17:39:40.997705Z","price_level":"115630.72","new_quantity":"0.33120621"},{"side":"bid","event_time":"2025-10-27T17:39:40.997705Z","price_level":"115629.01","new_quantity":"0"},{"side":"bid","event_time":"2025-10-27T17:39:40.997705Z","price_level":"115629","new_quantity":"0.4"},{"side":"bid","event_time":"2025-10-27T17:39:40.997705Z","price_level":"115628","new_quantity":"2"},{"side":"bid","event_time":"2025-10-27T17:39:40.997705Z","price_level":"115589.5","new_quantity":"1.5"},{"side":"bid","event_time":"2025-10-27T17:39:40.997705Z","price_level":"115582.1","new_quantity":"0"},{"side":"bid","event_time":"2025-10-27T17:39:40.997705Z","price_level":"115189.73","new_quantity":"0.07007"},{"side":"bid","event_time":"2025-10-27T17:39:40.997705Z","price_level":"114983.99","new_quantity":"0"},{"side":"offer","event_time":"2025-10-27T17:39:40.997705Z","price_level":"115658.61","new_quantity":"0"},{"side":"offer","event_time":"2025-10-27T17:39:40.997705Z","price_level":"115660.01","new_quantity":"0.02593809"},{"side":"offer","event_time":"2025-10-27T17:39:40.997705Z","price_level":"115676.92","new_quantity":"0.00432"},{"side":"offer","event_time":"2025-10-27T17:39:40.997705Z","price_level":"115678.14","new_quantity":"0.631443"},{"side":"offer","event_time":"2025-10-27T17:39:40.997705Z","price_level":"115686.72","new_quantity":"0.00206926"},{"side":"offer","event_time":"2025-10-27T17:39:40.997705Z","price_level":"115735.09","new_quantity":"0"},{"side":"offer","event_time":"2025-10-27T17:39:40.997705Z","price_level":"115739.6","new_quantity":"0"},{"side":"offer","event_time":"2025-10-27T17:39:40.997705Z","price_level":"115741.47","new_quantity":"0.57740919"},{"side":"offer","event_time":"2025-10-27T17:39:40.997705Z","price_level":"115741.48","new_quantity":"0.37928846"},{"side":"offer","event_time":"2025-10-27T17:39:40.997705Z","price_level":"115741.49","new_quantity":"0"},{"side":"offer","event_time":"2025-10-27T17:39:40.997705Z","price_level":"115745.8","new_quantity":"0"},{"side":"offer","event_time":"2025-10-27T17:39:40.997705Z","price_level":"115746.4","new_quantity":"1"}]}]}
{"channel":"l2_data","client_id":"","timestamp":"2025-10-27T17:39:41.071105776Z","sequence_num":137624,"events":[{"type":"update","product_id":"ETH-USD","updates":[{"side":"bid","event_time":"2025-10-27T17:39:41.003188Z","price_level":"4217.85","new_quantity":"2.35588413"},{"side":"bid","event_time":"2025-10-27T17:39:41.003188Z","price_level":"4217.75","new_quantity":"0.71264162"},{"side":"bid","event_time":"2025-10-27T17:39:41.003188Z","price_level":"4217.49","new_quantity":"0.146975"},{"side":"bid","event_time":"2025-10-27T17:39:41.003188Z","price_level":"4217.19","new_quantity":"0"},{"side":"bid","event_time":"2025-10-27T17:39:41.003188Z","price_level":"4217.18","new_quantity":"0"},{"side":"offer","event_time":"2025-10-27T17:39:41.003188Z","price_level":"4219.32","new_quantity":"0.01508562"},{"side":"offer","event_time":"2025-10-27T17:39:41.003188Z","price_level":"4219.61","new_quantity":"0.64"},{"side":"offer","event_time":"2025-10-27T17:39:41.003188Z","price_level":"4219.66","new_quantity":"0"},{"side":"offer","event_time":"2025-10-27T17:39:41.003188Z","price_level":"4220.3","new_quantity":"10"},{"side":"offer","event_time":"2025-10-27T17:39:41.003188Z","price_level":"4220.4","new_quantity":"0"}]}]}
{"channel":"l2_data","client_id":"","timestamp":"2025-10-27T17:39:41.298223107Z","sequence_num":137627,"events":[{"type":"update","product_id":"BTC-USD","updates":[{"side":"bid","event_time":"2025-10-27T17:39:41.056772Z","price_level":"115652.01","new_quantity":"0.0370811"},{"side":"bid","event_time":"2025-10-27T17:39:41.056772Z","price_level":"115640.43","new_quantity":"0.33945484"},{"side":"bid","event_time":"2025-10-27T17:39:41.056772Z","price_level":"115628.53","new_quantity":"2.20537653"},{"side":"offer","event_time":"2025-10-27T17:39:41.056772Z","price_level":"115678.14","new_quantity":"0"},{"side":"offer","event_time":"2025-10-27T17:39:41.056772Z","price_level":"115689","new_quantity":"0"},{"side":"offer","event_time":"2025-10-27T17:39:41.056772Z","price_level":"115694","new_quantity":"0"},{"side":"offer","event_time":"2025-10-27T17:39:41.056772Z","price_level":"115700","new_quantity":"0"}]}]}
{"channel":"l2_data","client_id":"","timestamp":"2025-10-27T17:39:41.420912454Z","sequence_num":137633,"events":[{"type":"update","product_id":"ETH-USD","updates":[{"side":"bid","event_time":"2025-10-27T17:39:41.37687Z","price_level":"4218.47","new_quantity":"0"},{"side":"bid","event_time":"2025-10-27T17:39:41.37687Z","price_level":"4218.45","new_quantity":"0"},{"side":"bid","event_time":"2025-10-27T17:39:41.37687Z","price_level":"4218.43","new_quantity":"0.07109172"},{"side":"bid","event_time":"2025-10-27T17:39:41.37687Z","price_level":"4218.41","new_quantity":"0.00237057"},{"side":"bid","event_time":"2025-10-27T17:39:41.37687Z","price_level":"4218.4","new_quantity":"0"},{"side":"bid","event_time":"2025-10-27T17:39:41.37687Z","price_level":"4218.3","new_quantity":"10"},{"side":"bid","event_time":"2025-10-27T17:39:41.37687Z","price_level":"4218.21","new_quantity":"12.200889"},{"side":"bid","event_time":"2025-10-27T17:39:41.37687Z","price_level":"4218.14","new_quantity":"0"},{"side":"bid","event_time":"2025-10-27T17:39:41.37687Z","price_level":"4218.11","new_quantity":"3.704919"},{"side":"bid","event_time":"2025-10-27T17:39:41.37687Z","price_level":"4218.09","new_quantity":"0"},{"side":"bid","event_time":"2025-10-27T17:39:41.37687Z","price_level":"4217.97","new_quantity":"1.65484"},{"side":"bid","event_time":"2025-10-27T17:39:41.37687Z","price_level":"4217.96","new_quantity":"0"},{"side":"bid","event_time":"2025-10-27T17:39:41.37687Z","price_level":"4217.85","new_quantity":"2.47971559"},{"side":"bid","event_time":"2025-10-27T17:39:41.37687Z","price_level":"4217.75","new_quantity":"2.37159162"},{"side":"bid","event_time":"2025-10-27T17:39:41.37687Z","price_level":"4217.62","new_quantity":"0"},{"side":"bid","event_time":"2025-10-27T17:39:41.37687Z","price_level":"4217.48","new_quantity":"0.5927698"},{"side":"bid","event_time":"2025-10-27T17:39:41.37687Z","price_level":"4217.44","new_quantity":"5.77961676"},{"side":"bid","event_time":"2025-10-27T17:39:41.37687Z","price_level":"4217.37","new_quantity":"0.59278532"},{"side":"bid","event_time":"2025-10-27T17:39:41.37687Z","price_level":"4216.79","new_quantity":"0"},{"side":"bid","event_time":"2025-10-27T17:39:41.37687Z","price_level":"4216.35","new_quantity":"2.37064854"},{"side":"bid","event_time":"2025-10-27T17:39:41.37687Z","price_level":"4215.19","new_quantity":"1.125"},{"side":"bid","event_time":"2025-10-27T17:39:41.37687Z","price_level":"4215.01","new_quantity":"8.84592291"},{"side":"bid","event_time":"2025-10-27T17:39:41.37687Z","price_level":"4214.51","new_quantity":"0"},{"side":"bid","event_time":"2025-10-27T17:39:41.37687Z","price_level":"4214.26","new_quantity":"12.86371489"},{"side":"offer","event_time":"2025-10-27T17:39:41.37687Z","price_level":"4218.45","new_quantity":"0.34152998"},{"side":"offer","event_time":"2025-10-27T17:39:41.37687Z","price_level":"4218.47","new_quantity":"0.00237042"},{"side":"offer","event_time":"2025-10-27T17:39:41.37687Z","price_level":"4218.48","new_quantity":"0.02511404"},{"side":"offer","event_time":"2025-10-27T17:39:41.37687Z","price_level":"4218.5","new_quantity":"0.545"},{"side":"offer","event_time":"2025-10-27T17:39:41.37687Z","price_level":"4218.52","new_quantity":"0"},{"side":"offer","event_time":"2025-10-27T17:39:41.37687Z","price_level":"4218.6","new_quantity":"0.545"},{"side":"offer","event_time":"2025-10-27T17:39:41.37687Z","price_level":"4218.66","new_quantity":"0"},{"side":"offer","event_time":"2025-10-27T17:39:41.37687Z","price_level":"4218.78","new_quantity":"1.32763532"},{"side":"offer","event_time":"2025-10-27T17:39:41.37687Z","price_level":"4218.79","new_quantity":"0"},{"side":"offer","event_time":"2025-10-27T17:39:41.37687Z","price_level":"4218.9","new_quantity":"1.501065"},{"side":"offer","event_time":"2025-10-27T17:39:41.37687Z","price_level":"4218.91","new_quantity":"1.125"},{"side":"offer","event_time":"2025-10-27T17:39:41.37687Z","price_level":"4218.99","new_quantity":"0"},{"side":"offer","event_time":"2025-10-27T17:39:41.37687Z","price_level":"4219.13","new_quantity":"0"},{"side":"offer","event_time":"2025-10-27T17:39:41.37687Z","price_level":"4219.32","new_quantity":"0.01508562"},{"side":"offer","event_time":"2025-10-27T17:39:41.37687Z","price_level":"4219.71","new_quantity":"4.594304"},{"side":"offer","event_time":"2025-10-27T17:39:41.37687Z","price_level":"4220.2","new_quantity":"20"},{"side":"offer","event_time":"2025-10-27T17:39:41.37687Z","price_level":"4220.37","new_quantity":"4.113752"},{"side":"offer","event_time":"2025-10-27T17:39:41.37687Z","price_level":"4220.67","new_quantity":"8.5438493"},{"side":"offer","event_time":"2025-10-27T17:39:41.37687Z","price_level":"4220.8","new_quantity":"0.30319008"},{"side":"offer","event_time":"2025-10-27T17:39:41.37687Z","price_level":"4221.67","new_quantity":"13.3012311"},{"side":"offer","event_time":"2025-10-27T17:39:41.37687Z","price_level":"4221.68","new_quantity":"2.0426284"},{"side":"offer","event_time":"2025-10-27T17:39:41.37687Z","price_level":"4221.69","new_quantity":"0"},{"side":"offer","event_time":"2025-10-27T17:39:41.37687Z","price_level":"4221.7","new_quantity":"0"},{"side":"offer","event_time":"2025-10-27T17:39:41.37687Z","price_level":"4272.99","new_quantity":"5.44940449"}]}]}
{"channel":"l2_data","client_id":"","timestamp":"2025-10-27T17:39:41.447367045Z","sequence_num":137635,"events":[{"type":"update","product_id":"BTC-USD","updates":[{"side":"bid","event_time":"2025-10-27T17:39:41.389533Z","price_level":"115652.01","new_quantity":"0.00172932"},{"side":"offer","event_time":"2025-10-27T17:39:41.389533Z","price_level":"115690","new_quantity":"0"},{"side":"offer","event_time":"2025-10-27T17:39:41.389533Z","price_level":"115700","new_quantity":"0"},{"side":"offer","event_time":"2025-10-27T17:39:41.389533Z","price_level":"115732.2","new_quantity":"1"},{"side":"offer","event_time":"2025-10-27T17:39:41.389533Z","price_level":"115746.4","new_quantity":"0"}]}]}
{"channel":"l2_data","client_id":"","timestamp":"2025-10-27T17:39:41.471052369Z","sequence_num":137636,"events":[{"type":"update","product_id":"ETH-USD","updates":[{"side":"bid","event_time":"2025-10-27T17:39:41.41903Z","price_level":"4218.46","new_quantity":"0.07109172"},{"side":"bid","event_time":"2025-10-27T17:39:41.41903Z","price_level":"4218.43","new_quantity":"0"},{"side":"bid","event_time":"2025-10-27T17:39:41.41903Z","price_level":"4218.41","new_quantity":"0"},{"side":"bid","event_time":"2025-10-27T17:39:41.41903Z","price_level":"4218.4","new_quantity":"10"},{"side":"bid","event_time":"2025-10-27T17:39:41.41903Z","price_level":"4218.31","new_quantity":"0.04978297"},{"side":"bid","event_time":"2025-10-27T17:39:41.41903Z","price_level":"4218.21","new_quantity":"0"},{"side":"bid","event_time":"2025-10-27T17:39:41.41903Z","price_level":"4218.11","new_quantity":"0"},{"side":"bid","event_time":"2025-10-27T17:39:41.41903Z","price_level":"4217.99","new_quantity":"3.860759"},{"side":"bid","event_time":"2025-10-27T17:39:41.41903Z","price_level":"4217.85","new_quantity":"2.59825919"},{"side":"bid","event_time":"2025-10-27T17:39:41.41903Z","price_level":"4217.37","new_quantity":"0"},{"side":"bid","event_time":"2025-10-27T17:39:41.41903Z","price_level":"4217.06","new_quantity":"0.64"},{"side":"offer","event_time":"2025-10-27T17:39:41.41903Z","price_level":"4218.44","new_quantity":"0"},{"side":"offer","event_time":"2025-10-27T17:39:41.41903Z","price_level":"4218.45","new_quantity":"0"},{"side":"offer","event_time":"2025-10-27T17:39:41.41903Z","price_level":"4218.47","new_quantity":"0.0071384"},{"side":"offer","event_time":"2025-10-27T17:39:41.41903Z","price_level":"4218.59","new_quantity":"0.0711138"},{"side":"offer","event_time":"2025-10-27T17:39:41.41903Z","price_level":"4218.77","new_quantity":"0.01235645"},{"side":"offer","event_time":"2025-10-27T17:39:41.41903Z","price_level":"4219.32","new_quantity":"0"},{"side":"offer","event_time":"2025-10-27T17:39:41.41903Z","price_level":"4220","new_quantity":"12.20517286"},{"side":"offer","event_time":"2025-10-27T17:39:41.41903Z","price_level":"4220.2","new_quantity":"0"}]}]}
{"channel":"l2_data","client_id":"","timestamp":"2025-10-27T17:39:41.320948014Z","sequence_num":137628,"events":[{"type":"update","product_id":"ETH-USD","updates":[{"side":"bid","event_time":"2025-10-27T17:39:41.274394Z","price_level":"4218.47","new_quantity":"1.15524645"},{"side":"bid","event_time":"2025-10-27T17:39:41.274394Z","price_level":"4218.45","new_quantity":"0.04939731"},{"side":"bid","event_time":"2025-10-27T17:39:41.274394Z","price_level":"4218.41","new_quantity":"0.00237057"},{"side":"bid","event_time":"2025-10-27T17:39:41.274394Z","price_level":"4218.31","new_quantity":"0"},{"side":"bid","event_time":"2025-10-27T17:39:41.274394Z","price_level":"4218.03","new_quantity":"0"},{"side":"bid","event_time":"2025-10-27T17:39:41.274394Z","price_level":"4217.51","new_quantity":"0"},{"side":"bid","event_time":"2025-10-27T17:39:41.274394Z","price_level":"4215.19","new_quantity":"9.97054516"},{"side":"bid","event_time":"2025-10-27T17:39:41.274394Z","price_level":"4215.11","new_quantity":"0"},{"side":"bid","event_time":"2025-10-27T17:39:41.274394Z","price_level":"4214.51","new_quantity":"12.86295183"},{"side":"bid","event_time":"2025-10-27T17:39:41.274394Z","price_level":"4214.26","new_quantity":"0"},{"side":"bid","event_time":"2025-10-27T17:39:41.274394Z","price_level":"4191.63","new_quantity":"0"},{"side":"offer","event_time":"2025-10-27T17:39:41.274394Z","price_level":"4218.52","new_quantity":"0.1185252"},{"side":"offer","event_time":"2025-10-27T17:39:41.274394Z","price_level":"4218.66","new_quantity":"0.07111262"},{"side":"offer","event_time":"2025-10-27T17:39:41.274394Z","price_level":"4218.67","new_quantity":"0.59260435"},{"side":"offer","event_time":"2025-10-27T17:39:41.274394Z","price_level":"4218.7","new_quantity":"0.545"},{"side":"offer","event_time":"2025-10-27T17:39:41.274394Z","price_level":"4218.79","new_quantity":"0.07111043"},{"side":"offer","event_time":"2025-10-27T17:39:41.274394Z","price_level":"4219.13","new_quantity":"0.01508562"},{"side":"offer","event_time":"2025-10-27T17:39:41.274394Z","price_level":"4219.3","new_quantity":"0.48848398"},{"side":"offer","event_time":"2025-10-27T17:39:41.274394Z","price_level":"4219.32","new_quantity":"0"},{"side":"offer","event_time":"2025-10-27T17:39:41.274394Z","price_level":"4219.77","new_quantity":"0.6"},{"side":"offer","event_time":"2025-10-27T17:39:41.274394Z","price_level":"4220","new_quantity":"22.20517286"},{"side":"offer","event_time":"2025-10-27T17:39:41.274394Z","price_level":"4220.1","new_quantity":"0"},{"side":"offer","event_time":"2025-10-27T17:39:41.274394Z","price_level":"4220.2","new_quantity":"30"},{"side":"offer","event_time":"2025-10-27T17:39:41.274394Z","price_level":"4220.3","new_quantity":"0"},{"side":"offer","event_time":"2025-10-27T17:39:41.274394Z","price_level":"4220.8","new_quantity":"8.83791227"},{"side":"offer","event_time":"2025-10-27T17:39:41.274394Z","price_level":"4220.81","new_quantity":"0.0052848"},{"side":"offer","event_time":"2025-10-27T17:39:41.274394Z","price_level":"4220.82","new_quantity":"0.46685028"},{"side":"offer","event_time":"2025-10-27T17:39:41.274394Z","price_level":"4223.73","new_quantity":"0"},{"side":"offer","event_time":"2025-10-27T17:39:41.274394Z","price_level":"4244.82","new_quantity":"0.1536"}]}]}
{"channel":"l2_data","client_id":"","timestamp":"2025-10-27T17:39:41.348343904Z","sequence_num":137629,"events":[{"type":"update","product_id":"BTC-USD","updates":[{"side":"bid","event_time":"2025-10-27T17:39:41.293982Z","price_level":"115656.42","new_quantity":"0"},{"side":"bid","event_time":"2025-10-27T17:39:41.293982Z","price_level":"115645.63","new_quantity":"0"},{"side":"bid","event_time":"2025-10-27T17:39:41.293982Z","price_level":"115644.76","new_quantity":"0.02160848"},{"side":"bid","event_time":"2025-10-27T17:39:41.293982Z","price_level":"115643.53","new_quantity":"0"},{"side":"bid","event_time":"2025-10-27T17:39:41.293982Z","price_level":"115640.43","new_quantity":"0.10949555"},{"side":"bid","event_time":"2025-10-27T17:39:41.293982Z","price_level":"115638","new_quantity":"0"},{"side":"bid","event_time":"2025-10-27T17:39:41.293982Z","price_level":"115635","new_quantity":"0"},{"side":"bid","event_time":"2025-10-27T17:39:41.293982Z","price_level":"115633.01","new_quantity":"2.17590839"},{"side":"bid","event_time":"2025-10-27T17:39:41.293982Z","price_level":"115630.72","new_quantity":"0"},{"side":"bid","event_time":"2025-10-27T17:39:41.293982Z","price_level":"115629.01","new_quantity":"0.33121111"},{"side":"bid","event_time":"2025-10-27T17:39:41.293982Z","price_level":"115629","new_quantity":"2.4"},{"side":"bid","event_time":"2025-10-27T17:39:41.293982Z","price_level":"115628.53","new_quantity":"1.51954644"},{"side":"bid","event_time":"2025-10-27T17:39:41.293982Z","price_level":"115628","new_quantity":"0"},{"side":"bid","event_time":"2025-10-27T17:39:41.293982Z","price_level":"115405.03","new_quantity":"0.07007"},{"side":"bid","event_time":"2025-10-27T17:39:41.293982Z","price_level":"115404.54","new_quantity":"0"},{"side":"bid","event_time":"2025-10-27T17:39:41.293982Z","price_level":"115190.29","new_quantity":"0.07007"},{"side":"bid","event_time":"2025-10-27T17:39:41.293982Z","price_level":"115189.73","new_quantity":"0"},{"side":"bid","event_time":"2025-10-27T17:39:41.293982Z","price_level":"114547.31","new_quantity":"0.07007"},{"side":"bid","event_time":"2025-10-27T17:39:41.293982Z","price_level":"114332.59","new_quantity":"0.07007"},{"side":"offer","event_time":"2025-10-27T17:39:41.293982Z","price_level":"115658.48","new_quantity":"0.02593843"},{"side":"offer","event_time":"2025-10-27T17:39:41.293982Z","price_level":"115660.01","new_quantity":"0"},{"side":"offer","event_time":"2025-10-27T17:39:41.293982Z","price_level":"115662.01","new_quantity":"0.00006833"},{"side":"offer","event_time":"2025-10-27T17:39:41.293982Z","price_level":"115662.02","new_quantity":"0.16234365"},{"side":"offer","event_time":"2025-10-27T17:39:41.293982Z","price_level":"115670.61","new_quantity":"0.09901842"},{"side":"offer","event_time":"2025-10-27T17:39:41.293982Z","price_level":"115674.6","new_quantity":"0.00432"},{"side":"offer","event_time":"2025-10-27T17:39:41.293982Z","price_level":"115674.61","new_quantity":"0.00432"},{"side":"offer","event_time":"2025-10-27T17:39:41.293982Z","price_level":"115686.72","new_quantity":"0"},{"side":"offer","event_time":"2025-10-27T17:39:41.293982Z","price_level":"115690","new_quantity":"0"},{"side":"offer","event_time":"2025-10-27T17:39:41.293982Z","price_level":"115695","new_quantity":"0.4"},{"side":"offer","event_time":"2025-10-27T17:39:41.293982Z","price_level":"115707.06","new_quantity":"0.16810436"},{"side":"offer","event_time":"2025-10-27T17:39:41.293982Z","price_level":"115709.99","new_quantity":"0"},{"side":"offer","event_time":"2025-10-27T17:39:41.293982Z","price_level":"115735.11","new_quantity":"0.37930933"},{"side":"offer","event_time":"2025-10-27T17:39:41.293982Z","price_level":"115741.48","new_quantity":"0"}]}]}
{"channel":"l2_data","client_id":"","timestamp":"2025-10-27T17:39:41.371225568Z","sequence_num":137630,"events":[{"type":"update","product_id":"ETH-USD","updates":[{"side":"bid","event_time":"2025-10-27T17:39:41.328886Z","price_level":"4216.05","new_quantity":"0.37635091"},{"side":"bid","event_time":"2025-10-27T17:39:41.328886Z","price_level":"4215.51","new_quantity":"0"},{"side":"offer","event_time":"2025-10-27T17:39:41.328886Z","price_level":"4232.72","new_quantity":"0"}]}]}
{"channel":"l2_data","client_id":"","timestamp":"2025-10-27T17:39:41.398891491Z","sequence_num":137632,"events":[{"type":"update","product_id":"BTC-USD","updates":[{"side":"bid","event_time":"2025-10-27T17:39:41.342992Z","price_level":"115656.38","new_quantity":"0.02595109"},{"side":"bid","event_time":"2025-10-27T17:39:41.342992Z","price_level":"115646.03","new_quantity":"0.02160848"},{"side":"bid","event_time":"2025-10-27T17:39:41.342992Z","price_level":"115644.76","new_quantity":"0"},{"side":"bid","event_time":"2025-10-27T17:39:41.342992Z","price_level":"115640.43","new_quantity":"0.33945484"},{"side":"bid","event_time":"2025-10-27T17:39:41.342992Z","price_level":"115637","new_quantity":"0.4"},{"side":"bid","event_time":"2025-10-27T17:39:41.342992Z","price_level":"115567.3","new_quantity":"0.00043224"},{"side":"bid","event_time":"2025-10-27T17:39:41.342992Z","price_level":"115567.27","new_quantity":"0"},{"side":"bid","event_time":"2025-10-27T17:39:41.342992Z","price_level":"114975.09","new_quantity":"0.07007"},{"side":"bid","event_time":"2025-10-27T17:39:41.342992Z","price_level":"114769.33","new_quantity":"0"},{"side":"bid","event_time":"2025-10-27T17:39:41.342992Z","price_level":"114117.37","new_quantity":"0.07007"},{"side":"offer","event_time":"2025-10-27T17:39:41.342992Z","price_level":"115690","new_quantity":"0"},{"side":"offer","event_time":"2025-10-27T17:39:41.342992Z","price_level":"115700","new_quantity":"0"},{"side":"offer","event_time":"2025-10-27T17:39:41.342992Z","price_level":"115726.65","new_quantity":"0.25113226"},{"side":"offer","event_time":"2025-10-27T17:39:41.342992Z","price_level":"115726.66","new_quantity":"0.0004323"},{"side":"offer","event_time":"2025-10-27T17:39:41.342992Z","price_level":"115726.67","new_quantity":"0"},{"side":"offer","event_time":"2025-10-27T17:39:41.342992Z","price_level":"115727.13","new_quantity":"0"},{"side":"offer","event_time":"2025-10-27T17:39:41.342992Z","price_level":"115735.09","new_quantity":"0.00043224"},{"side":"offer","event_time":"2025-10-27T17:39:41.342992Z","price_level":"115735.1","new_quantity":"0"},{"side":"offer","event_time":"2025-10-27T17:39:41.342992Z","price_level":"116980.81","new_quantity":"0.07007"},{"side":"offer","event_time":"2025-10-27T17:39:41.342992Z","price_level":"116981.38","new_quantity":"0"}]}]}
{"channel":"l2_data","client_id":"","timestamp":"2025-10-27T17:39:41.797071768Z","sequence_num":137650,"events":[{"type":"update","product_id":"BTC-USD","updates":[{"side":"bid","event_time":"2025-10-27T17:39:41.735416Z","price_level":"115657.18","new_quantity":"0.0685524"},{"side":"bid","event_time":"2025-10-27T17:39:41.735416Z","price_level":"115656","new_quantity":"0"},{"side":"bid","event_time":"2025-10-27T17:39:41.735416Z","price_level":"115652.01","new_quantity":"0"},{"side":"bid","event_time":"2025-10-27T17:39:41.735416Z","price_level":"115650.03","new_quantity":"0.00172935"},{"side":"bid","event_time":"2025-10-27T17:39:41.735416Z","price_level":"115650.02","new_quantity":"0.00172935"},{"side":"bid","event_time":"2025-10-27T17:39:41.735416Z","price_level":"115650.01","new_quantity":"0.00172935"},{"side":"bid","event_time":"2025-10-27T17:39:41.735416Z","price_level":"115650","new_quantity":"0.00774577"},{"side":"bid","event_time":"2025-10-27T17:39:41.735416Z","price_level":"115648.73","new_quantity":"0"},{"side":"bid","event_time":"2025-10-27T17:39:41.735416Z","price_level":"115647.05","new_quantity":"0.00864699"},{"side":"bid","event_time":"2025-10-27T17:39:41.735416Z","price_level":"115646.6","new_quantity":"0.01124"},{"side":"bid","event_time":"2025-10-27T17:39:41.735416Z","price_level":"115646.03","new_quantity":"0"},{"side":"bid","event_time":"2025-10-27T17:39:41.735416Z","price_level":"115643.75","new_quantity":"0"},{"side":"bid","event_time":"2025-10-27T17:39:41.735416Z","price_level":"115640.43","new_quantity":"0.10949555"},{"side":"bid","event_time":"2025-10-27T17:39:41.735416Z","price_level":"115639.87","new_quantity":"0"},{"side":"bid","event_time":"2025-10-27T17:39:41.735416Z","price_level":"115639.84","new_quantity":"0"},{"side":"bid","event_time":"2025-10-27T17:39:41.735416Z","price_level":"115637.55","new_quantity":"0"},{"side":"bid","event_time":"2025-10-27T17:39:41.735416Z","price_level":"115637.52","new_quantity":"0"},{"side":"bid","event_time":"2025-10-27T17:39:41.735416Z","price_level":"115637","new_quantity":"0"},{"side":"bid","event_time":"2025-10-27T17:39:41.735416Z","price_level":"115633.01","new_quantity":"1.19351579"},{"side":"bid","event_time":"2025-10-27T17:39:41.735416Z","price_level":"115629","new_quantity":"0.4"},{"side":"bid","event_time":"2025-10-27T17:39:41.735416Z","price_level":"115620.66","new_quantity":"0.94860196"},{"side":"bid","event_time":"2025-10-27T17:39:41.735416Z","price_level":"115590.01","new_quantity":"3.8805"},{"side":"bid","event_time":"2025-10-27T17:39:41.735416Z","price_level":"115552.03","new_quantity":"0.11825636"},{"side":"bid","event_time":"2025-10-27T17:39:41.735416Z","price_level":"101200.04","new_quantity":"0"},{"side":"offer","event_time":"2025-10-27T17:39:41.735416Z","price_level":"115658.47","new_quantity":"0.03008616"},{"side":"offer","event_time":"2025-10-27T17:39:41.735416Z","price_level":"115658.48","new_quantity":"0.04943151"},{"side":"offer","event_time":"2025-10-27T17:39:41.735416Z","price_level":"115672.28","new_quantity":"0.00432"},{"side":"offer","event_time":"2025-10-27T17:39:41.735416Z","price_level":"115672.29","new_quantity":"0.00432"},{"side":"offer","event_time":"2025-10-27T17:39:41.735416Z","price_level":"115676.92","new_quantity":"0"},{"side":"offer","event_time":"2025-10-27T17:39:41.735416Z","price_level":"115676.93","new_quantity":"0"},{"side":"offer","event_time":"2025-10-27T17:39:41.735416Z","price_level":"115690.04","new_quantity":"0"},{"side":"offer","event_time":"2025-10-27T17:39:41.735416Z","price_level":"115709.99","new_quantity":"0.69490281"},{"side":"offer","event_time":"2025-10-27T17:39:41.735416Z","price_level":"115732.19","new_quantity":"0"},{"side":"offer","event_time":"2025-10-27T17:39:41.735416Z","price_level":"115735.1","new_quantity":"0.00043224"},{"side":"offer","event_time":"2025-10-27T17:39:41.735416Z","price_level":"115745.89","new_quantity":"0.62176743"},{"side":"offer","event_time":"2025-10-27T17:39:41.735416Z","price_level":"115774.21","new_quantity":"0"},{"side":"offer","event_time":"2025-10-27T17:39:41.735416Z","price_level":"115807.95","new_quantity":"0"}]}]}
{"channel":"l2_data","client_id":"","timestamp":"2025-10-27T17:39:41.837355654Z","sequence_num":137652,"events":[{"type":"update","product_id":"ETH-USD","updates":[{"side":"bid","event_time":"2025-10-27T17:39:41.771747Z","price_level":"4218.41","new_quantity":"0"},{"side":"bid","event_time":"2025-10-27T17:39:41.771747Z","price_level":"4218.4","new_quantity":"0"},{"side":"bid","event_time":"2025-10-27T17:39:41.771747Z","price_level":"4218.3","new_quantity":"10.00237063"},{"side":"bid","event_time":"2025-10-27T17:39:41.771747Z","price_level":"4218.01","new_quantity":"0"},{"side":"bid","event_time":"2025-10-27T17:39:41.771747Z","price_level":"4218","new_quantity":"10.52"},{"side":"bid","event_time":"2025-10-27T17:39:41.771747Z","price_level":"4217.99","new_quantity":"0"},{"side":"bid","event_time":"2025-10-27T17:39:41.771747Z","price_level":"4217.98","new_quantity":"3.463711"},{"side":"bid","event_time":"2025-10-27T17:39:41.771747Z","price_level":"4217.97","new_quantity":"0"},{"side":"bid","event_time":"2025-10-27T17:39:41.771747Z","price_level":"4217.85","new_quantity":"2.54895519"},{"side":"bid","event_time":"2025-10-27T17:39:41.771747Z","price_level":"4217.8","new_quantity":"2.17538"},{"side":"bid","event_time":"2025-10-27T17:39:41.771747Z","price_level":"4217.75","new_quantity":"0.71264162"},{"side":"bid","event_time":"2025-10-27T17:39:41.771747Z","price_level":"4217.69","new_quantity":"0"},{"side":"bid","event_time":"2025-10-27T17:39:41.771747Z","price_level":"4217.65","new_quantity":"0.11854923"},{"side":"bid","event_time":"2025-10-27T17:39:41.771747Z","price_level":"4217.62","new_quantity":"0.01752193"},{"side":"bid","event_time":"2025-10-27T17:39:41.771747Z","price_level":"4217.34","new_quantity":"0.59279022"},{"side":"bid","event_time":"2025-10-27T17:39:41.771747Z","price_level":"4217.17","new_quantity":"1.62619011"},{"side":"bid","event_time":"2025-10-27T17:39:41.771747Z","price_level":"4217.16","new_quantity":"1.65895"},{"side":"bid","event_time":"2025-10-27T17:39:41.771747Z","price_level":"4217.08","new_quantity":"0"},{"side":"bid","event_time":"2025-10-27T17:39:41.771747Z","price_level":"4216.36","new_quantity":"4.0010012"},{"side":"bid","event_time":"2025-10-27T17:39:41.771747Z","price_level":"4216.05","new_quantity":"0"},{"side":"bid","event_time":"2025-10-27T17:39:41.771747Z","price_level":"4216.02","new_quantity":"0"},{"side":"bid","event_time":"2025-10-27T17:39:41.771747Z","price_level":"4215.84","new_quantity":"3.27167047"},{"side":"bid","event_time":"2025-10-27T17:39:41.771747Z","price_level":"4215.72","new_quantity":"1.02185091"},{"side":"bid","event_time":"2025-10-27T17:39:41.771747Z","price_level":"4215.12","new_quantity":"7.24905634"},{"side":"bid","event_time":"2025-10-27T17:39:41.771747Z","price_level":"4215.11","new_quantity":"0"},{"side":"bid","event_time":"2025-10-27T17:39:41.771747Z","price_level":"4214.92","new_quantity":"8.84611179"},{"side":"bid","event_time":"2025-10-27T17:39:41.771747Z","price_level":"4214.2","new_quantity":"0"},{"side":"bid","event_time":"2025-10-27T17:39:41.771747Z","price_level":"4213.97","new_quantity":"19.62393457"},{"side":"bid","event_time":"2025-10-27T17:39:41.771747Z","price_level":"4211.85","new_quantity":"0.671625"},{"side":"offer","event_time":"2025-10-27T17:39:41.771747Z","price_level":"4218.31","new_quantity":"0.50722708"},{"side":"offer","event_time":"2025-10-27T17:39:41.771747Z","price_level":"4218.37","new_quantity":"0.59264652"},{"side":"offer","event_time":"2025-10-27T17:39:41.771747Z","price_level":"4218.4","new_quantity":"0.545"},{"side":"offer","event_time":"2025-10-27T17:39:41.771747Z","price_level":"4218.41","new_quantity":"0"},{"side":"offer","event_time":"2025-10-27T17:39:41.771747Z","price_level":"4218.42","new_quantity":"0"},{"side":"offer","event_time":"2025-10-27T17:39:41.771747Z","price_level":"4218.45","new_quantity":"0"},{"side":"offer","event_time":"2025-10-27T17:39:41.771747Z","price_level":"4218.46","new_quantity":"0"},{"side":"offer","event_time":"2025-10-27T17:39:41.771747Z","price_level":"4218.47","new_quantity":"0"},{"side":"offer","event_time":"2025-10-27T17:39:41.771747Z","price_level":"4218.48","new_quantity":"0.02748446"},{"side":"offer","event_time":"2025-10-27T17:39:41.771747Z","price_level":"4218.49","new_quantity":"1.04696903"},{"side":"offer","event_time":"2025-10-27T17:39:41.771747Z","price_level":"4218.77","new_quantity":"0.01358913"},{"side":"offer","event_time":"2025-10-27T17:39:41.771747Z","price_level":"4218.83","new_quantity":"0"},{"side":"offer","event_time":"2025-10-27T17:39:41.771747Z","price_level":"4219.13","new_quantity":"0.01508562"},{"side":"offer","event_time":"2025-10-27T17:39:41.771747Z","price_level":"4219.14","new_quantity":"1.58058329"},{"side":"offer","event_time":"2025-10-27T17:39:41.771747Z","price_level":"4219.26","new_quantity":"1.64484"},{"side":"offer","event_time":"2025-10-27T17:39:41.771747Z","price_level":"4219.32","new_quantity":"0"},{"side":"offer","event_time":"2025-10-27T17:39:41.771747Z","price_level":"4219.69","new_quantity":"3.964433"},{"side":"offer","event_time":"2025-10-27T17:39:41.771747Z","price_level":"4219.76","new_quantity":"1.09124914"},{"side":"offer","event_time":"2025-10-27T17:39:41.771747Z","price_level":"4220","new_quantity":"22.20517286"},{"side":"offer","event_time":"2025-10-27T17:39:41.771747Z","price_level":"4220.2","new_quantity":"0"},{"side":"offer","event_time":"2025-10-27T17:39:41.771747Z","price_level":"4220.35","new_quantity":"4.366828"},{"side":"offer","event_time":"2025-10-27T17:39:41.771747Z","price_level":"4221.82","new_quantity":"15.34260145"},{"side":"offer","event_time":"2025-10-27T17:39:41.771747Z","price_level":"4221.85","new_quantity":"0.30652551"},{"side":"offer","event_time":"2025-10-27T17:39:41.771747Z","price_level":"4223.73","new_quantity":"0.1536"},{"side":"offer","event_time":"2025-10-27T17:39:41.771747Z","price_level":"4261.97","new_quantity":"0.06543771"},{"side":"offer","event_time":"2025-10-27T17:39:41.771747Z","price_level":"4272.5","new_quantity":"0.03583379"}]}]}
{"channel":"l2_data","client_id":"","timestamp":"2025-10-27T17:39:41.49786555Z","sequence_num":137637,"events":[{"type":"update","product_id":"BTC-USD","updates":[{"side":"bid","event_time":"2025-10-27T17:39:41.439275Z","price_level":"101200.04","new_quantity":"0.0049568"},{"side":"offer","event_time":"2025-10-27T17:39:41.439275Z","price_level":"115657.19","new_quantity":"0.00047263"},{"side":"offer","event_time":"2025-10-27T17:39:41.439275Z","price_level":"115690","new_quantity":"0"},{"side":"offer","event_time":"2025-10-27T17:39:41.439275Z","price_level":"115700","new_quantity":"0"}]}]}
{"channel":"l2_data","client_id":"","timestamp":"2025-10-27T17:39:41.520679991Z","sequence_num":137638,"events":[{"type":"update","product_id":"ETH-USD","updates":[{"side":"bid","event_time":"2025-10-27T17:39:41.476505Z","price_level":"4218.41","new_quantity":"0.03983875"},{"side":"bid","event_time":"2025-10-27T17:39:41.476505Z","price_level":"4218.4","new_quantity":"10"},{"side":"bid","event_time":"2025-10-27T17:39:41.476505Z","price_level":"4218.32","new_quantity":"0"},{"side":"bid","event_time":"2025-10-27T17:39:41.476505Z","price_level":"4218.31","new_quantity":"0"},{"side":"bid","event_time":"2025-10-27T17:39:41.476505Z","price_level":"4217.56","new_quantity":"0.47523547"},{"side":"offer","event_time":"2025-10-27T17:39:41.476505Z","price_level":"4218.47","new_quantity":"0.3338375"},{"side":"offer","event_time":"2025-10-27T17:39:41.476505Z","price_level":"4218.59","new_quantity":"0"},{"side":"offer","event_time":"2025-10-27T17:39:41.476505Z","price_level":"4218.66","new_quantity":"0.07111262"},{"side":"offer","event_time":"2025-10-27T17:39:41.476505Z","price_level":"4218.85","new_quantity":"0.51591236"},{"side":"offer","event_time":"2025-10-27T17:39:41.476505Z","price_level":"4219.3","new_quantity":"0"},{"side":"offer","event_time":"2025-10-27T17:39:41.476505Z","price_level":"4220","new_quantity":"22.20517286"},{"side":"offer","event_time":"2025-10-27T17:39:41.476505Z","price_level":"4220.2","new_quantity":"20"}]}]}
{"channel":"l2_data","client_id":"","timestamp":"2025-10-27T17:39:41.544138743Z","sequence_num":137639,"events":[{"type":"update","product_id":"BTC-USD","updates":[{"side":"offer","event_time":"2025-10-27T17:39:41.487373Z","price_level":"115690","new_quantity":"0"},{"side":"offer","event_time":"2025-10-27T17:39:41.487373Z","price_level":"115700","new_quantity":"0"}]}]}
{"channel":"l2_data","client_id":"","timestamp":"2025-10-27T17:39:41.570623134Z","sequence_num":137640,"events":[{"type":"update","product_id":"ETH-USD","updates":[{"side":"bid","event_time":"2025-10-27T17:39:41.529342Z","price_level":"4215.11","new_quantity":"8.84571304"},{"side":"bid","event_time":"2025-10-27T17:39:41.529342Z","price_level":"4215.01","new_quantity":"0"},{"side":"offer","event_time":"2025-10-27T17:39:41.529342Z","price_level":"4218.5","new_quantity":"0"},{"side":"offer","event_time":"2025-10-27T17:39:41.529342Z","price_level":"4218.77","new_quantity":"0"},{"side":"offer","event_time":"2025-10-27T17:39:41.529342Z","price_level":"4219.32","new_quantity":"0.01508562"},{"side":"offer","event_time":"2025-10-27T17:39:41.529342Z","price_level":"4219.71","new_quantity":"0"},{"side":"offer","event_time":"2025-10-27T17:39:41.529342Z","price_level":"4221.67","new_quantity":"0"},{"side":"offer","event_time":"2025-10-27T17:39:41.529342Z","price_level":"4221.68","new_quantity":"0.09871233"},{"side":"offer","event_time":"2025-10-27T17:39:41.529342Z","price_level":"4221.85","new_quantity":"15.55110558"}]}]}
{"channel":"l2_data","client_id":"","timestamp":"2025-10-27T17:39:41.598522678Z","sequence_num":137642,"events":[{"type":"update","product_id":"BTC-USD","updates":[{"side":"bid","event_time":"2025-10-27T17:39:41.536031Z","price_level":"115657.18","new_quantity":"0.0797924"},{"side":"bid","event_time":"2025-10-27T17:39:41.536031Z","price_level":"115652.01","new_quantity":"0.0370811"},{"side":"bid","event_time":"2025-10-27T17:39:41.536031Z","price_level":"115644.01","new_quantity":"0"},{"side":"bid","event_time":"2025-10-27T17:39:41.536031Z","price_level":"115190.35","new_quantity":"0.07007"},{"side":"bid","event_time":"2025-10-27T17:39:41.536031Z","price_level":"114332.63","new_quantity":"0.07007"},{"side":"bid","event_time":"2025-10-27T17:39:41.536031Z","price_level":"114117.37","new_quantity":"0"},{"side":"offer","event_time":"2025-10-27T17:39:41.536031Z","price_level":"115662.3","new_quantity":"0"},{"side":"offer","event_time":"2025-10-27T17:39:41.536031Z","price_level":"115690","new_quantity":"0"},{"side":"offer","event_time":"2025-10-27T17:39:41.536031Z","price_level":"115691.87","new_quantity":"0"},{"side":"offer","event_time":"2025-10-27T17:39:41.536031Z","price_level":"115700","new_quantity":"0"},{"side":"offer","event_time":"2025-10-27T17:39:41.536031Z","price_level":"115712.72","new_quantity":"0"},{"side":"offer","event_time":"2025-10-27T17:39:41.536031Z","price_level":"115716.33","new_quantity":"0"},{"side":"offer","event_time":"2025-10-27T17:39:41.536031Z","price_level":"115732.19","new_quantity":"0.00043224"},{"side":"offer","event_time":"2025-10-27T17:39:41.536031Z","price_level":"115735.09","new_quantity":"0"},{"side":"offer","event_time":"2025-10-27T17:39:41.536031Z","price_level":"115745.24","new_quantity":"0"}]}]}
{"channel":"l2_data","client_id":"","timestamp":"2025-10-27T17:39:41.621694092Z","sequence_num":137643,"events":[{"type":"update","product_id":"ETH-USD","updates":[{"side":"bid","event_time":"2025-10-27T17:39:41.550888Z","price_level":"4217.61","new_quantity":"23.7777398"},{"side":"bid","event_time":"2025-10-27T17:39:41.550888Z","price_level":"4217.44","new_quantity":"0"},{"side":"offer","event_time":"2025-10-27T17:39:41.550888Z","price_level":"4220.37","new_quantity":"0"},{"side":"offer","event_time":"2025-10-27T17:39:41.550888Z","price_level":"4220.67","new_quantity":"0.00886424"},{"side":"offer","event_time":"2025-10-27T17:39:41.550888Z","price_level":"4220.82","new_quantity":"9.00153202"}]}]}
{"channel":"l2_data","client_id":"","timestamp":"2025-10-27T17:39:41.643739267Z","sequence_num":137645,"events":[{"type":"update","product_id":"BTC-USD","updates":[{"side":"offer","event_time":"2025-10-27T17:39:41.608259Z","price_level":"115662.31","new_quantity":"0.012555"},{"side":"offer","event_time":"2025-10-27T17:39:41.608259Z","price_level":"115732.2","new_quantity":"0"},{"side":"offer","event_time":"2025-10-27T17:39:41.608259Z","price_level":"115739.99","new_quantity":"0.57741658"},{"side":"offer","event_time":"2025-10-27T17:39:41.608259Z","price_level":"115740","new_quantity":"1"},{"side":"offer","event_time":"2025-10-27T17:39:41.608259Z","price_level":"115741.47","new_quantity":"0"},{"side":"offer","event_time":"2025-10-27T17:39:41.608259Z","price_level":"115745.28","new_quantity":"0.103747"}]}]}
{"channel":"l2_data","client_id":"","timestamp":"2025-10-27T17:39:41.698169593Z","sequence_num":137647,"events":[{"type":"update","product_id":"BTC-USD","updates":[{"side":"bid","event_time":"2025-10-27T17:39:41.632263Z","price_level":"115190.29","new_quantity":"0"},{"side":"bid","event_time":"2025-10-27T17:39:41.632263Z","price_level":"114975.69","new_quantity":"0.07007"},{"side":"bid","event_time":"2025-10-27T17:39:41.632263Z","price_level":"114975.09","new_quantity":"0"},{"side":"bid","event_time":"2025-10-27T17:39:41.632263Z","price_level":"114332.59","new_quantity":"0"},{"side":"offer","event_time":"2025-10-27T17:39:41.632263Z","price_level":"115712.78","new_quantity":"0.058098"},{"side":"offer","event_time":"2025-10-27T17:39:41.632263Z","price_level":"115716.37","new_quantity":"0.082997"}]}]}
{"channel":"l2_data","client_id":"","timestamp":"2025-10-27T17:39:41.744162315Z","sequence_num":137648,"events":[{"type":"update","product_id":"BTC-USD","updates":[{"side":"offer","event_time":"2025-10-27T17:39:41.684811Z","price_level":"115740","new_quantity":"0"},{"side":"offer","event_time":"2025-10-27T17:39:41.684811Z","price_level":"115745.9","new_quantity":"1"}]}]}
{"channel":"l2_data","client_id":"","timestamp":"2025-10-27T17:39:41.771040004Z","sequence_num":137649,"events":[{"type":"update","product_id":"ETH-USD","updates":[{"side":"bid","event_time":"2025-10-27T17:39:41.721558Z","price_level":"4218.46","new_quantity":"0"},{"side":"bid","event_time":"2025-10-27T17:39:41.721558Z","price_level":"4217.61","new_quantity":"17.998356"},{"side":"bid","event_time":"2025-10-27T17:39:41.721558Z","price_level":"4217.44","new_quantity":"5.77961676"},{"side":"offer","event_time":"2025-10-27T17:39:41.721558Z","price_level":"4218.46","new_quantity":"0.1761384"},{"side":"offer","event_time":"2025-10-27T17:39:41.721558Z","price_level":"4218.47","new_quantity":"0.50022708"},{"side":"offer","event_time":"2025-10-27T17:39:41.721558Z","price_level":"4218.5","new_quantity":"0.545"},{"side":"offer","event_time":"2025-10-27T17:39:41.721558Z","price_level":"4220.67","new_quantity":"8.5438493"},{"side":"offer","event_time":"2025-10-27T17:39:41.721558Z","price_level":"4220.82","new_quantity":"0.46685028"}]}]}
{"channel":"l2_data","client_id":"","timestamp":"2025-10-27T17:39:41.898703441Z","sequence_num":137657,"events":[{"type":"update","product_id":"BTC-USD","updates":[{"side":"bid","event_time":"2025-10-27T17:39:41.834963Z","price_level":"115656","new_quantity":"0.0224"},{"side":"bid","event_time":"2025-10-27T17:39:41.834963Z","price_level":"115652.01","new_quantity":"0.04206214"},{"side":"bid","event_time":"2025-10-27T17:39:41.834963Z","price_level":"115645.63","new_quantity":"0.00074714"},{"side":"bid","event_time":"2025-10-27T17:39:41.834963Z","price_level":"115643.75","new_quantity":"0.16623"},{"side":"bid","event_time":"2025-10-27T17:39:41.834963Z","price_level":"115639.87","new_quantity":"0.00432"},{"side":"bid","event_time":"2025-10-27T17:39:41.834963Z","price_level":"115639.84","new_quantity":"0.00432"},{"side":"bid","event_time":"2025-10-27T17:39:41.834963Z","price_level":"115635.23","new_quantity":"0"},{"side":"bid","event_time":"2025-10-27T17:39:41.834963Z","price_level":"115635.2","new_quantity":"0"},{"side":"bid","event_time":"2025-10-27T17:39:41.834963Z","price_level":"115584.2","new_quantity":"0"},{"side":"bid","event_time":"2025-10-27T17:39:41.834963Z","price_level":"115583.6","new_quantity":"1.5"},{"side":"offer","event_time":"2025-10-27T17:39:41.834963Z","price_level":"115658.47","new_quantity":"0"},{"side":"offer","event_time":"2025-10-27T17:39:41.834963Z","price_level":"115662.01","new_quantity":"0"},{"side":"offer","event_time":"2025-10-27T17:39:41.834963Z","price_level":"115662.02","new_quantity":"0.00006753"},{"side":"offer","event_time":"2025-10-27T17:39:41.834963Z","price_level":"115666.37","new_quantity":"0"},{"side":"offer","event_time":"2025-10-27T17:39:41.834963Z","price_level":"115670.61","new_quantity":"0"},{"side":"offer","event_time":"2025-10-27T17:39:41.834963Z","price_level":"115670.62","new_quantity":"0"},{"side":"offer","event_time":"2025-10-27T17:39:41.834963Z","price_level":"115672.35","new_quantity":"0.16539"},{"side":"offer","event_time":"2025-10-27T17:39:41.834963Z","price_level":"115686.72","new_quantity":"0.00253179"},{"side":"offer","event_time":"2025-10-27T17:39:41.834963Z","price_level":"115687.97","new_quantity":"0.46351863"},{"side":"offer","event_time":"2025-10-27T17:39:41.834963Z","price_level":"115689","new_quantity":"0.4"},{"side":"offer","event_time":"2025-10-27T17:39:41.834963Z","price_level":"115690","new_quantity":"0"},{"side":"offer","event_time":"2025-10-27T17:39:41.834963Z","price_level":"115693","new_quantity":"0"},{"side":"offer","event_time":"2025-10-27T17:39:41.834963Z","price_level":"115694","new_quantity":"0.4"},{"side":"offer","event_time":"2025-10-27T17:39:41.834963Z","price_level":"115700","new_quantity":"1"},{"side":"offer","event_time":"2025-10-27T17:39:41.834963Z","price_level":"120000","new_quantity":"82.75246707"}]}]}
{"channel":"l2_data","client_id":"","timestamp":"2025-10-27T17:39:41.93197381Z","sequence_num":137658,"events":[{"type":"update","product_id":"ETH-USD","updates":[{"side":"bid","event_time":"2025-10-27T17:39:41.886538Z","price_level":"4218.47","new_quantity":"0.46453395"},{"side":"bid","event_time":"2025-10-27T17:39:41.886538Z","price_level":"4218.41","new_quantity":"0.00237057"},{"side":"bid","event_time":"2025-10-27T17:39:41.886538Z","price_level":"4218.29","new_quantity":"0.11853127"},{"side":"bid","event_time":"2025-10-27T17:39:41.886538Z","price_level":"4218.21","new_quantity":"18.170889"},{"side":"bid","event_time":"2025-10-27T17:39:41.886538Z","price_level":"4218.18","new_quantity":"0.59267214"},{"side":"bid","event_time":"2025-10-27T17:39:41.886538Z","price_level":"4217.97","new_quantity":"3.31533"},{"side":"bid","event_time":"2025-10-27T17:39:41.886538Z","price_level":"4217.9","new_quantity":"1.02424102"},{"side":"bid","event_time":"2025-10-27T17:39:41.886538Z","price_level":"4217.85","new_quantity":"2.54895519"},{"side":"bid","event_time":"2025-10-27T17:39:41.886538Z","price_level":"4215.2","new_quantity":"8.84552418"},{"side":"bid","event_time":"2025-10-27T17:39:41.886538Z","price_level":"4215.12","new_quantity":"0"},{"side":"bid","event_time":"2025-10-27T17:39:41.886538Z","price_level":"4214.92","new_quantity":"0"},{"side":"bid","event_time":"2025-10-27T17:39:41.886538Z","price_level":"4214.26","new_quantity":"19.62258417"},{"side":"bid","event_time":"2025-10-27T17:39:41.886538Z","price_level":"4213.97","new_quantity":"0"},{"side":"offer","event_time":"2025-10-27T17:39:41.886538Z","price_level":"4218.79","new_quantity":"0"},{"side":"offer","event_time":"2025-10-27T17:39:41.886538Z","price_level":"4218.8","new_quantity":"0"},{"side":"offer","event_time":"2025-10-27T17:39:41.886538Z","price_level":"4218.85","new_quantity":"0"},{"side":"offer","event_time":"2025-10-27T17:39:41.886538Z","price_level":"4218.86","new_quantity":"0"},{"side":"offer","event_time":"2025-10-27T17:39:41.886538Z","price_level":"4218.89","new_quantity":"0.00237053"},{"side":"offer","event_time":"2025-10-27T17:39:41.886538Z","price_level":"4218.99","new_quantity":"0.31044"},{"side":"offer","event_time":"2025-10-27T17:39:41.886538Z","price_level":"4219.13","new_quantity":"0.01508562"},{"side":"offer","event_time":"2025-10-27T17:39:41.886538Z","price_level":"4219.2","new_quantity":"0.11850597"},{"side":"offer","event_time":"2025-10-27T17:39:41.886538Z","price_level":"4219.32","new_quantity":"0"},{"side":"offer","event_time":"2025-10-27T17:39:41.886538Z","price_level":"4219.51","new_quantity":"0.592486"},{"side":"offer","event_time":"2025-10-27T17:39:41.886538Z","price_level":"4219.56","new_quantity":"2.11325858"},{"side":"offer","event_time":"2025-10-27T17:39:41.886538Z","price_level":"4219.71","new_quantity":"0"},{"side":"offer","event_time":"2025-10-27T17:39:41.886538Z","price_level":"4219.82","new_quantity":"0.671625"},{"side":"offer","event_time":"2025-10-27T17:39:41.886538Z","price_level":"4220.1","new_quantity":"0"},{"side":"offer","event_time":"2025-10-27T17:39:41.886538Z","price_level":"4220.2","new_quantity":"0"},{"side":"offer","event_time":"2025-10-27T17:39:41.886538Z","price_level":"4220.4","new_quantity":"0"},{"side":"offer","event_time":"2025-10-27T17:39:41.886538Z","price_level":"4221.82","new_quantity":"0.09792687"},{"side":"offer","event_time":"2025-10-27T17:39:41.886538Z","price_level":"4222.38","new_quantity":"15.24291055"}]}]}
{"channel":"l2_data","client_id":"","timestamp":"2025-10-27T17:39:41.947573506Z","sequence_num":137659,"events":[{"type":"update","product_id":"BTC-USD","updates":[{"side":"bid","event_time":"2025-10-27T17:39:41.894061Z","price_level":"115652.01","new_quantity":"0"},{"side":"bid","event_time":"2025-10-27T17:39:41.894061Z","price_level":"115647.48","new_quantity":"0.00864696"},{"side":"bid","event_time":"2025-10-27T17:39:41.894061Z","price_level":"115647.05","new_quantity":"0"},{"side":"bid","event_time":"2025-10-27T17:39:41.894061Z","price_level":"115645.63","new_quantity":"0"},{"side":"bid","event_time":"2025-10-27T17:39:41.894061Z","price_level":"115640.43","new_quantity":"0.10949555"},{"side":"bid","event_time":"2025-10-27T17:39:41.894061Z","price_level":"115639.87","new_quantity":"0"},{"side":"bid","event_time":"2025-10-27T17:39:41.894061Z","price_level":"115639.84","new_quantity":"0"},{"side":"bid","event_time":"2025-10-27T17:39:41.894061Z","price_level":"115637.97","new_quantity":"0"},{"side":"bid","event_time":"2025-10-27T17:39:41.894061Z","price_level":"115637.55","new_quantity":"0.00432"},{"side":"bid","event_time":"2025-10-27T17:39:41.894061Z","price_level":"115583.6","new_quantity":"0"},{"side":"bid","event_time":"2025-10-27T17:39:41.894061Z","price_level":"115582.4","new_quantity":"1.5"},{"side":"bid","event_time":"2025-10-27T17:39:41.894061Z","price_level":"114975.85","new_quantity":"0.07007"},{"side":"bid","event_time":"2025-10-27T17:39:41.894061Z","price_level":"114975.69","new_quantity":"0"},{"side":"bid","event_time":"2025-10-27T17:39:41.894061Z","price_level":"114761.25","new_quantity":"0.07007"},{"side":"bid","event_time":"2025-10-27T17:39:41.894061Z","price_level":"114547.31","new_quantity":"0"},{"side":"offer","event_time":"2025-10-27T17:39:41.894061Z","price_level":"115662.01","new_quantity":"0.00006753"},{"side":"offer","event_time":"2025-10-27T17:39:41.894061Z","price_level":"115662.02","new_quantity":"0.16234305"},{"side":"offer","event_time":"2025-10-27T17:39:41.894061Z","price_level":"115666.37","new_quantity":"0.32405738"},{"side":"offer","event_time":"2025-10-27T17:39:41.894061Z","price_level":"115672.34","new_quantity":"0.10389591"},{"side":"offer","event_time":"2025-10-27T17:39:41.894061Z","price_level":"115683.91","new_quantity":"0.04778044"},{"side":"offer","event_time":"2025-10-27T17:39:41.894061Z","price_level":"115683.92","new_quantity":"0.08"},{"side":"offer","event_time":"2025-10-27T17:39:41.894061Z","price_level":"115687.97","new_quantity":"0"},{"side":"offer","event_time":"2025-10-27T17:39:41.894061Z","price_level":"115689","new_quantity":"0"},{"side":"offer","event_time":"2025-10-27T17:39:41.894061Z","price_level":"115700","new_quantity":"0"}]}]}
{"channel":"l2_data","client_id":"","timestamp":"2025-10-27T17:39:41.982427007Z","sequence_num":137660,"events":[{"type":"update","product_id":"ETH-USD","updates":[{"side":"bid","event_time":"2025-10-27T17:39:41.929012Z","price_level":"4218.42","new_quantity":"0.00237056"},{"side":"bid","event_time":"2025-10-27T17:39:41.929012Z","price_level":"4218.41","new_quantity":"13.33311817"},{"side":"bid","event_time":"2025-10-27T17:39:41.929012Z","price_level":"4217.94","new_quantity":"0.47848945"},{"side":"bid","event_time":"2025-10-27T17:39:41.929012Z","price_level":"4217.85","new_quantity":"5.8055431"},{"side":"bid","event_time":"2025-10-27T17:39:41.929012Z","price_level":"4217.76","new_quantity":"5.77917826"},{"side":"bid","event_time":"2025-10-27T17:39:41.929012Z","price_level":"4217.62","new_quantity":"0"},{"side":"bid","event_time":"2025-10-27T17:39:41.929012Z","price_level":"4217.17","new_quantity":"0"},{"side":"bid","event_time":"2025-10-27T17:39:41.929012Z","price_level":"4217.16","new_quantity":"0"},{"side":"offer","event_time":"2025-10-27T17:39:41.929012Z","price_level":"4219.05","new_quantity":"0.11851018"},{"side":"offer","event_time":"2025-10-27T17:39:41.929012Z","price_level":"4219.11","new_quantity":"1.11917364"},{"side":"offer","event_time":"2025-10-27T17:39:41.929012Z","price_level":"4219.12","new_quantity":"0.436"},{"side":"offer","event_time":"2025-10-27T17:39:41.929012Z","price_level":"4219.14","new_quantity":"0"},{"side":"offer","event_time":"2025-10-27T17:39:41.929012Z","price_level":"4219.2","new_quantity":"0"},{"side":"offer","event_time":"2025-10-27T17:39:41.929012Z","price_level":"4219.33","new_quantity":"1.33555891"},{"side":"offer","event_time":"2025-10-27T17:39:41.929012Z","price_level":"4219.51","new_quantity":"0.49325793"},{"side":"offer","event_time":"2025-10-27T17:39:41.929012Z","price_level":"4219.81","new_quantity":"0.4"},{"side":"offer","event_time":"2025-10-27T17:39:41.929012Z","price_level":"4220.3","new_quantity":"10"},{"side":"offer","event_time":"2025-10-27T17:39:41.929012Z","price_level":"4220.35","new_quantity":"0"},{"side":"offer","event_time":"2025-10-27T17:39:41.929012Z","price_level":"4220.6","new_quantity":"20"},{"side":"offer","event_time":"2025-10-27T17:39:41.929012Z","price_level":"4220.85","new_quantity":"1.25414305"},{"side":"offer","event_time":"2025-10-27T17:39:41.929012Z","price_level":"4220.89","new_quantity":"0.13527952"},{"side":"offer","event_time":"2025-10-27T17:39:41.929012Z","price_level":"4221.1","new_quantity":"8.53411561"}]}]}
{"channel":"l2_data","client_id":"","timestamp":"2025-10-27T17:39:41.99710545Z","sequence_num":137661,"events":[{"type":"update","product_id":"BTC-USD","updates":[{"side":"bid","event_time":"2025-10-27T17:39:41.945523Z","price_level":"115637.52","new_quantity":"0.00432"},{"side":"bid","event_time":"2025-10-27T17:39:41.945523Z","price_level":"115405.16","new_quantity":"0.07007"},{"side":"bid","event_time":"2025-10-27T17:39:41.945523Z","price_level":"115405.03","new_quantity":"0"},{"side":"bid","event_time":"2025-10-27T17:39:41.945523Z","price_level":"114545.93","new_quantity":"0.07007"},{"side":"bid","event_time":"2025-10-27T17:39:41.945523Z","price_level":"114117.07","new_quantity":"0.07007"},{"side":"offer","event_time":"2025-10-27T17:39:41.945523Z","price_level":"115688","new_quantity":"0"},{"side":"offer","event_time":"2025-10-27T17:39:41.945523Z","price_level":"115689","new_quantity":"0"},{"side":"offer","event_time":"2025-10-27T17:39:41.945523Z","price_level":"116980.52","new_quantity":"0.07007"},{"side":"offer","event_time":"2025-10-27T17:39:41.945523Z","price_level":"116980.81","new_quantity":"0"}]}]}
{"channel":"l2_data","client_id":"","timestamp":"2025-10-27T17:39:42.031649705Z","sequence_num":137662,"events":[{"type":"update","product_id":"ETH-USD","updates":[{"side":"bid","event_time":"2025-10-27T17:39:41.981587Z","price_level":"4218.47","new_quantity":"0.25605395"},{"side":"bid","event_time":"2025-10-27T17:39:41.981587Z","price_level":"4218.31","new_quantity":"0"},{"side":"bid","event_time":"2025-10-27T17:39:41.981587Z","price_level":"4217.8","new_quantity":"0.519"},{"side":"offer","event_time":"2025-10-27T17:39:41.981587Z","price_level":"4219.05","new_quantity":"0"},{"side":"offer","event_time":"2025-10-27T17:39:41.981587Z","price_level":"4219.13","new_quantity":"0.60762603"},{"side":"offer","event_time":"2025-10-27T17:39:41.981587Z","price_level":"4221.96","new_quantity":"15.24423353"},{"side":"offer","event_time":"2025-10-27T17:39:41.981587Z","price_level":"4222.38","new_quantity":"0"}]}]}
{"channel":"l2_data","client_id":"","timestamp":"2025-10-27T17:39:42.047731476Z","sequence_num":137663,"events":[{"type":"update","product_id":"BTC-USD","updates":[{"side":"bid","event_time":"2025-10-27T17:39:42.003209Z","price_level":"115656","new_quantity":"0"},{"side":"bid","event_time":"2025-10-27T17:39:42.003209Z","price_level":"115654","new_quantity":"0"},{"side":"bid","event_time":"2025-10-27T17:39:42.003209Z","price_level":"115652","new_quantity":"0"},{"side":"bid","event_time":"2025-10-27T17:39:42.003209Z","price_level":"115648.36","new_quantity":"0.02360502"},{"side":"bid","event_time":"2025-10-27T17:39:42.003209Z","price_level":"115645.62","new_quantity":"0.27696309"},{"side":"bid","event_time":"2025-10-27T17:39:42.003209Z","price_level":"115645.61","new_quantity":"0"},{"side":"bid","event_time":"2025-10-27T17:39:42.003209Z","price_level":"115643.75","new_quantity":"0"},{"side":"bid","event_time":"2025-10-27T17:39:42.003209Z","price_level":"115637.55","new_quantity":"0"},{"side":"bid","event_time":"2025-10-27T17:39:42.003209Z","price_level":"115637.52","new_quantity":"0"},{"side":"bid","event_time":"2025-10-27T17:39:42.003209Z","price_level":"115633.01","new_quantity":"0.697964"},{"side":"bid","event_time":"2025-10-27T17:39:42.003209Z","price_level":"115632","new_quantity":"0"},{"side":"bid","event_time":"2025-10-27T17:39:42.003209Z","price_level":"115629.01","new_quantity":"0"},{"side":"bid","event_time":"2025-10-27T17:39:42.003209Z","price_level":"115629","new_quantity":"0"},{"side":"bid","event_time":"2025-10-27T17:39:42.003209Z","price_level":"115628.53","new_quantity":"0.68583009"},{"side":"bid","event_time":"2025-10-27T17:39:42.003209Z","price_level":"115628","new_quantity":"0"},{"side":"bid","event_time":"2025-10-27T17:39:42.003209Z","price_level":"115627","new_quantity":"0"},{"side":"bid","event_time":"2025-10-27T17:39:42.003209Z","price_level":"115625","new_quantity":"0"},{"side":"bid","event_time":"2025-10-27T17:39:42.003209Z","price_level":"115624.93","new_quantity":"0.3312228"},{"side":"bid","event_time":"2025-10-27T17:39:42.003209Z","price_level":"115620.66","new_quantity":"0"},{"side":"bid","event_time":"2025-10-27T17:39:42.003209Z","price_level":"115620","new_quantity":"0"},{"side":"bid","event_time":"2025-10-27T17:39:42.003209Z","price_level":"115600.01","new_quantity":"0"},{"side":"bid","event_time":"2025-10-27T17:39:42.003209Z","price_level":"115600","new_quantity":"0.00001798"},{"side":"bid","event_time":"2025-10-27T17:39:42.003209Z","price_level":"114546.03","new_quantity":"0.07007"},{"side":"bid","event_time":"2025-10-27T17:39:42.003209Z","price_level":"114545.93","new_quantity":"0"},{"side":"bid","event_time":"2025-10-27T17:39:42.003209Z","price_level":"114332.63","new_quantity":"0"},{"side":"bid","event_time":"2025-10-27T17:39:42.003209Z","price_level":"114331.1","new_quantity":"0.07007"},{"side":"bid","event_time":"2025-10-27T17:39:42.003209Z","price_level":"114117.07","new_quantity":"0"},{"side":"bid","event_time":"2025-10-27T17:39:42.003209Z","price_level":"114116.12","new_quantity":"0.07007"},{"side":"offer","event_time":"2025-10-27T17:39:42.003209Z","price_level":"115657.19","new_quantity":"0.17194468"},{"side":"offer","event_time":"2025-10-27T17:39:42.003209Z","price_level":"115661.99","new_quantity":"0"},{"side":"offer","event_time":"2025-10-27T17:39:42.003209Z","price_level":"115662","new_quantity":"0"},{"side":"offer","event_time":"2025-10-27T17:39:42.003209Z","price_level":"115662.01","new_quantity":"0.00006753"},{"side":"offer","event_time":"2025-10-27T17:39:42.003209Z","price_level":"115686.72","new_quantity":"0"},{"side":"offer","event_time":"2025-10-27T17:39:42.003209Z","price_level":"115687","new_quantity":"0.4"},{"side":"offer","event_time":"2025-10-27T17:39:42.003209Z","price_level":"115691.15","new_quantity":"0"},{"side":"offer","event_time":"2025-10-27T17:39:42.003209Z","price_level":"115706.38","new_quantity":"0.16810535"},{"side":"offer","event_time":"2025-10-27T17:39:42.003209Z","price_level":"115707.06","new_quantity":"0"},{"side":"offer","event_time":"2025-10-27T17:39:42.003209Z","price_level":"115730","new_quantity":"0.00001798"},{"side":"offer","event_time":"2025-10-27T17:39:42.003209Z","price_level":"116336.3","new_quantity":"0.07007"},{"side":"offer","event_time":"2025-10-27T17:39:42.003209Z","price_level":"116336.66","new_quantity":"0"},{"side":"offer","event_time":"2025-10-27T17:39:42.003209Z","price_level":"116336.76","new_quantity":"0"},{"side":"offer","event_time":"2025-10-27T17:39:42.003209Z","price_level":"116551.18","new_quantity":"0.07007"},{"side":"offer","event_time":"2025-10-27T17:39:42.003209Z","price_level":"116551.28","new_quantity":"0"},{"side":"offer","event_time":"2025-10-27T17:39:42.003209Z","price_level":"116551.35","new_quantity":"0"},{"side":"offer","event_time":"2025-10-27T17:39:42.003209Z","price_level":"116765.94","new_quantity":"0"},{"side":"offer","event_time":"2025-10-27T17:39:42.003209Z","price_level":"116980.52","new_quantity":"0"}]}]}
{"channel":"l2_data","client_id":"","timestamp":"2025-10-27T17:39:41.846936538Z","sequence_num":137653,"events":[{"type":"update","product_id":"BTC-USD","updates":[{"side":"bid","event_time":"2025-10-27T17:39:41.783105Z","price_level":"115650.03","new_quantity":"0"},{"side":"bid","event_time":"2025-10-27T17:39:41.783105Z","price_level":"115650.02","new_quantity":"0"},{"side":"bid","event_time":"2025-10-27T17:39:41.783105Z","price_level":"115650.01","new_quantity":"0"},{"side":"bid","event_time":"2025-10-27T17:39:41.783105Z","price_level":"115650","new_quantity":"0.00601642"},{"side":"bid","event_time":"2025-10-27T17:39:41.783105Z","price_level":"115646.12","new_quantity":"0.0216083"},{"side":"bid","event_time":"2025-10-27T17:39:41.783105Z","price_level":"115640.43","new_quantity":"0.19473607"},{"side":"bid","event_time":"2025-10-27T17:39:41.783105Z","price_level":"115637.97","new_quantity":"0.16623"},{"side":"bid","event_time":"2025-10-27T17:39:41.783105Z","price_level":"115635.23","new_quantity":"0.00432"},{"side":"bid","event_time":"2025-10-27T17:39:41.783105Z","price_level":"115635.2","new_quantity":"0.00432"},{"side":"bid","event_time":"2025-10-27T17:39:41.783105Z","price_level":"115632","new_quantity":"0.4"},{"side":"bid","event_time":"2025-10-27T17:39:41.783105Z","price_level":"115628.53","new_quantity":"2.20537653"},{"side":"bid","event_time":"2025-10-27T17:39:41.783105Z","price_level":"115628","new_quantity":"2"},{"side":"bid","event_time":"2025-10-27T17:39:41.783105Z","price_level":"115589.5","new_quantity":"0"},{"side":"bid","event_time":"2025-10-27T17:39:41.783105Z","price_level":"115584.2","new_quantity":"1.5"},{"side":"offer","event_time":"2025-10-27T17:39:41.783105Z","price_level":"115658.48","new_quantity":"0.02593843"},{"side":"offer","event_time":"2025-10-27T17:39:41.783105Z","price_level":"115672.28","new_quantity":"0"},{"side":"offer","event_time":"2025-10-27T17:39:41.783105Z","price_level":"115672.29","new_quantity":"0"},{"side":"offer","event_time":"2025-10-27T17:39:41.783105Z","price_level":"115690","new_quantity":"1"},{"side":"offer","event_time":"2025-10-27T17:39:41.783105Z","price_level":"115693","new_quantity":"0.4"},{"side":"offer","event_time":"2025-10-27T17:39:41.783105Z","price_level":"115695","new_quantity":"0"},{"side":"offer","event_time":"2025-10-27T17:39:41.783105Z","price_level":"115731.6","new_quantity":"1"},{"side":"offer","event_time":"2025-10-27T17:39:41.783105Z","price_level":"115745.89","new_quantity":"0"},{"side":"offer","event_time":"2025-10-27T17:39:41.783105Z","price_level":"115745.9","new_quantity":"0"}]}]}
5-10-27T17:39:42.027811Z","price_level":"4214.02","new_quantity":"19.62370173"},{"side":"bid","event_time":"2025-10-27T17:39:42.027811Z","price_level":"4213.16","new_quantity":"0"},{"side":"bid","event_time":"2025-10-27T17:39:42.027811Z","price_level":"4212.73","new_quantity":"0"},{"side":"bid","event_time":"2025-10-27T17:39:42.027811Z","price_level":"4192.06","new_quantity":"0.1536"},{"side":"offer","event_time":"2025-10-27T17:39:42.027811Z","price_level":"4218.48","new_quantity":"0.02399915"},{"side":"offer","event_time":"2025-10-27T17:39:42.027811Z","price_level":"4218.5","new_quantity":"0.572"},{"side":"offer","event_time":"2025-10-27T17:39:42.027811Z","price_level":"4218.59","new_quantity":"0.00237053"},{"side":"offer","event_time":"2025-10-27T17:39:42.027811Z","price_level":"4218.6","new_quantity":"0.572"},{"side":"offer","event_time":"2025-10-27T17:39:42.027811Z","price_level":"4218.7","new_quantity":"0.572"},{"side":"offer","event_time":"2025-10-27T17:39:42.027811Z","price_level":"4218.73","new_quantity":"0"},{"side":"offer","event_time":"2025-10-27T17:39:42.027811Z","price_level":"4218.74","new_quantity":"0.11851892"},{"side":"offer","event_time":"2025-10-27T17:39:42.027811Z","price_level":"4218.85","new_quantity":"0.59257886"},{"side":"offer","event_time":"2025-10-27T17:39:42.027811Z","price_level":"4218.89","new_quantity":"0.01508562"},{"side":"offer","event_time":"2025-10-27T17:39:42.027811Z","price_level":"4218.91","new_quantity":"1.125"},{"side":"offer","event_time":"2025-10-27T17:39:42.027811Z","price_level":"4219.1","new_quantity":"0"},{"side":"offer","event_time":"2025-10-27T17:39:42.027811Z","price_level":"4219.13","new_quantity":"0.59254041"},{"side":"offer","event_time":"2025-10-27T17:39:42.027811Z","price_level":"4219.2","new_quantity":"0.50067148"},{"side":"offer","event_time":"2025-10-27T17:39:42.027811Z","price_level":"4219.21","new_quantity":"0"},{"side":"offer","event_time":"2025-10-27T17:39:42.027811Z","price_level":"4219.33","new_quantity":"1.89382663"},{"side":"offer","event_time":"2025-10-27T17:39:42.027811Z","price_level":"4219.39","new_quantity":"1.64484"},{"side":"offer","event_time":"2025-10-27T17:39:42.027811Z","price_level":"4220.16","new_quantity":"0.47391568"},{"side":"offer","event_time":"2025-10-27T17:39:42.027811Z","price_level":"4220.3","new_quantity":"0"},{"side":"offer","event_time":"2025-10-27T17:39:42.027811Z","price_level":"4220.6","new_quantity":"0"}]}]}
{"channel":"l2_data","client_id":"","timestamp":"2025-10-27T17:39:42.098590787Z","sequence_num":137666,"events":[{"type":"update","product_id":"BTC-USD","updates":[{"side":"bid","event_time":"2025-10-27T17:39:42.059161Z","price_level":"115646.12","new_quantity":"0"},{"side":"bid","event_time":"2025-10-27T17:39:42.059161Z","price_level":"115643.36","new_quantity":"0.02160829"},{"side":"bid","event_time":"2025-10-27T17:39:42.059161Z","price_level":"115640.43","new_quantity":"0.18946456"},{"side":"bid","event_time":"2025-10-27T17:39:42.059161Z","price_level":"115637.97","new_quantity":"0.16604"},{"side":"bid","event_time":"2025-10-27T17:39:42.059161Z","price_level":"115587.7","new_quantity":"1.5"},{"side":"bid","event_time":"2025-10-27T17:39:42.059161Z","price_level":"115582.4","new_quantity":"0"},{"side":"bid","event_time":"2025-10-27T17:39:42.059161Z","price_level":"114364.17","new_quantity":"0"},{"side":"bid","event_time":"2025-10-27T17:39:42.059161Z","price_level":"113808.49","new_quantity":"0"},{"side":"bid","event_time":"2025-10-27T17:39:42.059161Z","price_level":"113252.8","new_quantity":"0"},{"side":"offer","event_time":"2025-10-27T17:39:42.059161Z","price_level":"115657.19","new_quantity":"0.02944468"},{"side":"offer","event_time":"2025-10-27T17:39:42.059161Z","price_level":"115662","new_quantity":"0.00006753"},{"side":"offer","event_time":"2025-10-27T17:39:42.059161Z","price_level":"115662.01","new_quantity":"0.00121353"},{"side":"offer","event_time":"2025-10-27T17:39:42.059161Z","price_level":"115668","new_quantity":"2"},{"side":"offer","event_time":"2025-10-27T17:39:42.059161Z","price_level":"115669","new_quantity":"2"},{"side":"offer","event_time":"2025-10-27T17:39:42.059161Z","price_level":"115670","new_quantity":"0"},{"side":"offer","event_time":"2025-10-27T17:39:42.059161Z","price_level":"115678","new_quantity":"2"},{"side":"offer","event_time":"2025-10-27T17:39:42.059161Z","price_level":"115704.66","new_quantity":"0.260793"},{"side":"offer","event_time":"2025-10-27T17:39:42.059161Z","price_level":"115710","new_quantity":"5.4000267"},{"side":"offer","event_time":"2025-10-27T17:39:42.059161Z","price_level":"115719.92","new_quantity":"0"},{"side":"offer","event_time":"2025-10-27T17:39:42.059161Z","price_level":"115720","new_quantity":"0"},{"side":"offer","event_time":"2025-10-27T17:39:42.059161Z","price_level":"115798.75","new_quantity":"0.08893198"},{"side":"offer","event_time":"2025-10-27T17:39:42.059161Z","price_level":"115906.66","new_quantity":"0.07007"},{"side":"offer","event_time":"2025-10-27T17:39:42.059161Z","price_level":"116978.81","new_quantity":"0.07007"}]}]}
{"channel":"l2_data","client_id":"","timestamp":"2025-10-27T17:39:42.133206598Z","sequence_num":137669,"events":[{"type":"update","product_id":"ETH-USD","updates":[{"side":"bid","event_time":"2025-10-27T17:39:42.08025Z","price_level":"4218.3","new_quantity":"0"},{"side":"bid","event_time":"2025-10-27T17:39:42.08025Z","price_level":"4218.21","new_quantity":"0.95856895"},{"side":"bid","event_time":"2025-10-27T17:39:42.08025Z","price_level":"4218.2","new_quantity":"0.572"},{"side":"bid","event_time":"2025-10-27T17:39:42.08025Z","price_level":"4217.85","new_quantity":"7.44602451"},{"side":"bid","event_time":"2025-10-27T17:39:42.08025Z","price_level":"4217.76","new_quantity":"0"},{"side":"bid","event_time":"2025-10-27T17:39:42.08025Z","price_level":"4217.7","new_quantity":"10"},{"side":"bid","event_time":"2025-10-27T17:39:42.08025Z","price_level":"4217.61","new_quantity":"30.80189537"},{"side":"bid","event_time":"2025-10-27T17:39:42.08025Z","price_level":"4217.6","new_quantity":"30"},{"side":"bid","event_time":"2025-10-27T17:39:42.08025Z","price_level":"4217.5","new_quantity":"10.001"},{"side":"bid","event_time":"2025-10-27T17:39:42.08025Z","price_level":"4217.44","new_quantity":"5.77961676"},{"side":"bid","event_time":"2025-10-27T17:39:42.08025Z","price_level":"4217.4","new_quantity":"20"},{"side":"bid","event_time":"2025-10-27T17:39:42.08025Z","price_level":"4213.16","new_quantity":"0.1536"},{"side":"offer","event_time":"2025-10-27T17:39:42.08025Z","price_level":"4219.15","new_quantity":"1.24485882"},{"side":"offer","event_time":"2025-10-27T17:39:42.08025Z","price_level":"4219.51","new_quantity":"0"},{"side":"offer","event_time":"2025-10-27T17:39:42.08025Z","price_level":"4220","new_quantity":"12.20517286"},{"side":"offer","event_time":"2025-10-27T17:39:42.08025Z","price_level":"4220.1","new_quantity":"0"},{"side":"offer","event_time":"2025-10-27T17:39:42.08025Z","price_level":"4220.4","new_quantity":"0"},{"side":"offer","event_time":"2025-10-27T17:39:42.08025Z","price_level":"4220.67","new_quantity":"8.5438493"},{"side":"offer","event_time":"2025-10-27T17:39:42.08025Z","price_level":"4221.1","new_quantity":"0"}]}]}
{"channel":"l2_data","client_id":"","timestamp":"2025-10-27T17:39:42.149746543Z","sequence_num":137670,"events":[{"type":"update","product_id":"BTC-USD","updates":[{"side":"bid","event_time":"2025-10-27T17:39:42.090247Z","price_level":"115647.48","new_quantity":"0"},{"side":"bid","event_time":"2025-10-27T17:39:42.090247Z","price_level":"115646.09","new_quantity":"0.00864707"},{"side":"bid","event_time":"2025-10-27T17:39:42.090247Z","price_level":"115623","new_quantity":"2"},{"side":"bid","event_time":"2025-10-27T17:39:42.090247Z","price_level":"115587.7","new_quantity":"0"},{"side":"bid","event_time":"2025-10-27T17:39:42.090247Z","price_level":"115581.6","new_quantity":"1.5"},{"side":"bid","event_time":"2025-10-27T17:39:42.090247Z","price_level":"115580","new_quantity":"5"},{"side":"bid","event_time":"2025-10-27T17:39:42.090247Z","price_level":"114911.22","new_quantity":"0"},{"side":"offer","event_time":"2025-10-27T17:39:42.090247Z","price_level":"115657.19","new_quantity":"0.04770849"},{"side":"offer","event_time":"2025-10-27T17:39:42.090247Z","price_level":"115700","new_quantity":"5"},{"side":"offer","event_time":"2025-10-27T17:39:42.090247Z","price_level":"115905.24","new_quantity":"0.07007"},{"side":"offer","event_time":"2025-10-27T17:39:42.090247Z","price_level":"115907.17","new_quantity":"0"},{"side":"offer","event_time":"2025-10-27T17:39:42.090247Z","price_level":"116978.81","new_quantity":"0"}]}]}
