{"channel":"l2_data","client_id":"","timestamp":"2025-10-27T17:39:42.183319042Z","sequence_num":137671,"events":[{"type":"update","product_id":"ETH-USD","updates":[{"side":"bid","event_time":"2025-10-27T17:39:42.133411Z","price_level":"4218.47","new_quantity":"0"},{"side":"bid","event_time":"2025-10-27T17:39:42.133411Z","price_level":"4218.32","new_quantity":"0"},{"side":"bid","event_time":"2025-10-27T17:39:42.133411Z","price_level":"4218.31","new_quantity":"0"},{"side":"bid","event_time":"2025-10-27T17:39:42.133411Z","price_level":"4218.3","new_quantity":"0"},{"side":"bid","event_time":"2025-10-27T17:39:42.133411Z","price_level":"4218.29","new_quantity":"0"},{"side":"bid","event_time":"2025-10-27T17:39:42.133411Z","price_level":"4218.23","new_quantity":"0.00237067"},{"side":"bid","event_time":"2025-10-27T17:39:42.133411Z","price_level":"4218.22","new_quantity":"0.01777675"},{"side":"bid","event_time":"2025-10-27T17:39:42.133411Z","price_level":"4218.21","new_quantity":"0"},{"side":"bid","event_time":"2025-10-27T17:39:42.133411Z","price_level":"4218.2","new_quantity":"0"},{"side":"bid","event_time":"2025-10-27T17:39:42.133411Z","price_level":"4218.19","new_quantity":"0"},{"side":"bid","event_time":"2025-10-27T17:39:42.133411Z","price_level":"4218.18","new_quantity":"0"},{"side":"bid","event_time":"2025-10-27T17:39:42.133411Z","price_level":"4218.11","new_quantity":"0"},{"side":"bid","event_time":"2025-10-27T17:39:42.133411Z","price_level":"4218.02","new_quantity":"0"},{"side":"bid","event_time":"2025-10-27T17:39:42.133411Z","price_level":"4218.01","new_quantity":"3.34479286"},{"side":"bid","event_time":"2025-10-27T17:39:42.133411Z","price_level":"4217.97","new_quantity":"0"},{"side":"bid","event_time":"2025-10-27T17:39:42.133411Z","price_level":"4217.94","new_quantity":"0.002"},{"side":"bid","event_time":"2025-10-27T17:39:42.133411Z","price_level":"4217.9","new_quantity":"0.519"},{"side":"bid","event_time":"2025-10-27T17:39:42.133411Z","price_level":"4217.87","new_quantity":"0"},{"side":"bid","event_time":"2025-10-27T17:39:42.133411Z","price_level":"4217.79","new_quantity":"0"},{"side":"bid","event_time":"2025-10-27T17:39:42.133411Z","price_level":"4217.71","new_quantity":"0"},{"side":"bid","event_time":"2025-10-27T17:39:42.133411Z","price_level":"4217.49","new_quantity":"0"},{"side":"bid","event_time":"2025-10-27T17:39:42.133411Z","price_level":"4217.41","new_quantity":"13.43517699"},{"side":"bid","event_time":"2025-10-27T17:39:42.133411Z","price_level":"4217.4","new_quantity":"20.146962"},{"side":"bid","event_time":"2025-10-27T17:39:42.133411Z","price_level":"4217.37","new_quantity":"0"},{"side":"bid","event_time":"2025-10-27T17:39:42.133411Z","price_level":"4217.26","new_quantity":"0"},{"side":"bid","event_time":"2025-10-27T17:39:42.133411Z","price_level":"4217.09","new_quantity":"0.21565049"},{"side":"bid","event_time":"2025-10-27T17:39:42.133411Z","price_level":"4216.93","new_quantity":"0.47427868"},{"side":"bid","event_time":"2025-10-27T17:39:42.133411Z","price_level":"4216.33","new_quantity":"0"},{"side":"bid","event_time":"2025-10-27T17:39:42.133411Z","price_level":"4215.8","new_quantity":"0"},{"side":"bid","event_time":"2025-10-27T17:39:42.133411Z","price_level":"4214.85","new_quantity":"0"},{"side":"bid","event_time":"2025-10-27T17:39:42.133411Z","price_level":"4214.27","new_quantity":"0"},{"side":"bid","event_time":"2025-10-27T17:39:42.133411Z","price_level":"4214.03","new_quantity":"12.86441698"},{"side":"bid","event_time":"2025-10-27T17:39:42.133411Z","price_level":"4213.16","new_quantity":"0"},{"side":"bid","event_time":"2025-10-27T17:39:42.133411Z","price_level":"4192.06","new_quantity":"0.1536"},{"side":"offer","event_time":"2025-10-27T17:39:42.133411Z","price_level":"4218.48","new_quantity":"1.62597623"},{"side":"offer","event_time":"2025-10-27T17:39:42.133411Z","price_level":"4218.5","new_quantity":"0.572"},{"side":"offer","event_time":"2025-10-27T17:39:42.133411Z","price_level":"4218.69","new_quantity":"1.35818258"},{"side":"offer","event_time":"2025-10-27T17:39:42.133411Z","price_level":"4218.74","new_quantity":"0"},{"side":"offer","event_time":"2025-10-27T17:39:42.133411Z","price_level":"4218.81","new_quantity":"0.4578293"},{"side":"offer","event_time":"2025-10-27T17:39:42.133411Z","price_level":"4218.9","new_quantity":"1.501065"},{"side":"offer","event_time":"2025-10-27T17:39:42.133411Z","price_level":"4218.99","new_quantity":"0"},{"side":"offer","event_time":"2025-10-27T17:39:42.133411Z","price_level":"4219.13","new_quantity":"0"},{"side":"offer","event_time":"2025-10-27T17:39:42.133411Z","price_level":"4219.2","new_quantity":"0"},{"side":"offer","event_time":"2025-10-27T17:39:42.133411Z","price_level":"4219.56","new_quantity":"0"},{"side":"offer","event_time":"2025-10-27T17:39:42.133411Z","price_level":"4219.59","new_quantity":"0"},{"side":"offer","event_time":"2025-10-27T17:39:42.133411Z","price_level":"4220","new_quantity":"22.20517286"},{"side":"offer","event_time":"2025-10-27T17:39:42.133411Z","price_level":"4220.37","new_quantity":"4.389288"},{"side":"offer","event_time":"2025-10-27T17:39:42.133411Z","price_level":"4221.84","new_quantity":"15.24461157"},{"side":"offer","event_time":"2025-10-27T17:39:42.133411Z","price_level":"4221.96","new_quantity":"0"},{"side":"offer","event_time":"2025-10-27T17:39:42.133411Z","price_level":"4223.02","new_quantity":"9.52628055"},{"side":"offer","event_time":"2025-10-27T17:39:42.133411Z","price_level":"4223.22","new_quantity":"0"},{"side":"offer","event_time":"2025-10-27T17:39:42.133411Z","price_level":"4232.29","new_quantity":"0"}]}]}
{"channel":"l2_data","client_id":"","timestamp":"2025-10-27T17:39:42.199000526Z","sequence_num":137672,"events":[{"type":"update","product_id":"BTC-USD","updates":[{"side":"bid","event_time":"2025-10-27T17:39:42.148928Z","price_level":"115657.18","new_quantity":"0"},{"side":"bid","event_time":"2025-10-27T17:39:42.148928Z","price_level":"115657.17","new_quantity":"0"},{"side":"bid","event_time":"2025-10-27T17:39:42.148928Z","price_level":"115657.16","new_quantity":"0"},{"side":"bid","event_time":"2025-10-27T17:39:42.148928Z","price_level":"115656.38","new_quantity":"0"},{"side":"bid","event_time":"2025-10-27T17:39:42.148928Z","price_level":"115654.77","new_quantity":"0"},{"side":"bid","event_time":"2025-10-27T17:39:42.148928Z","price_level":"115650","new_quantity":"0"},{"side":"bid","event_time":"2025-10-27T17:39:42.148928Z","price_level":"115648.36","new_quantity":"0"},{"side":"bid","event_time":"2025-10-27T17:39:42.148928Z","price_level":"115648.35","new_quantity":"0"},{"side":"bid","event_time":"2025-10-27T17:39:42.148928Z","price_level":"115646.6","new_quantity":"0"},{"side":"bid","event_time":"2025-10-27T17:39:42.148928Z","price_level":"115646.39","new_quantity":"0"},{"side":"bid","event_time":"2025-10-27T17:39:42.148928Z","price_level":"115646.09","new_quantity":"0"},{"side":"bid","event_time":"2025-10-27T17:39:42.148928Z","price_level":"115645.62","new_quantity":"0"},{"side":"bid","event_time":"2025-10-27T17:39:42.148928Z","price_level":"115645.58","new_quantity":"0"},{"side":"bid","event_time":"2025-10-27T17:39:42.148928Z","price_level":"115643.51","new_quantity":"0"},{"side":"bid","event_time":"2025-10-27T17:39:42.148928Z","price_level":"115643.36","new_quantity":"0"},{"side":"bid","event_time":"2025-10-27T17:39:42.148928Z","price_level":"115641.38","new_quantity":"0"},{"side":"bid","event_time":"2025-10-27T17:39:42.148928Z","price_level":"115640.43","new_quantity":"0"},{"side":"bid","event_time":"2025-10-27T17:39:42.148928Z","price_level":"115640.31","new_quantity":"0"},{"side":"bid","event_time":"2025-10-27T17:39:42.148928Z","price_level":"115639.25","new_quantity":"0"},{"side":"bid","event_time":"2025-10-27T17:39:42.148928Z","price_level":"115637.97","new_quantity":"0"},{"side":"bid","event_time":"2025-10-27T17:39:42.148928Z","price_level":"115636","new_quantity":"0.0224"},{"side":"bid","event_time":"2025-10-27T17:39:42.148928Z","price_level":"115633.01","new_quantity":"0"},{"side":"bid","event_time":"2025-10-27T17:39:42.148928Z","price_level":"115632.61","new_quantity":"0"},{"side":"bid","event_time":"2025-10-27T17:39:42.148928Z","price_level":"115632.28","new_quantity":"0"},{"side":"bid","event_time":"2025-10-27T17:39:42.148928Z","price_level":"115630.71","new_quantity":"0"},{"side":"bid","event_time":"2025-10-27T17:39:42.148928Z","price_level":"115628.93","new_quantity":"0"},{"side":"bid","event_time":"2025-10-27T17:39:42.148928Z","price_level":"115628.53","new_quantity":"0"},{"side":"bid","event_time":"2025-10-27T17:39:42.148928Z","price_level":"115628.23","new_quantity":"0"},{"side":"bid","event_time":"2025-10-27T17:39:42.148928Z","price_level":"115624.93","new_quantity":"0"},{"side":"bid","event_time":"2025-10-27T17:39:42.148928Z","price_level":"115624.92","new_quantity":"0"},{"side":"bid","event_time":"2025-10-27T17:39:42.148928Z","price_level":"115623.96","new_quantity":"0"},{"side":"bid","event_time":"2025-10-27T17:39:42.148928Z","price_level":"115623.82","new_quantity":"0.307095"},{"side":"bid","event_time":"2025-10-27T17:39:42.148928Z","price_level":"115623.12","new_quantity":"0.00084895"},{"side":"bid","event_time":"2025-10-27T17:39:42.148928Z","price_level":"115623.11","new_quantity":"0.08648789"},{"side":"bid","event_time":"2025-10-27T17:39:42.148928Z","price_level":"115623.01","new_quantity":"0.3312283"},{"side":"bid","event_time":"2025-10-27T17:39:42.148928Z","price_level":"115623","new_quantity":"0"},{"side":"bid","event_time":"2025-10-27T17:39:42.148928Z","price_level":"115620.65","new_quantity":"0"},{"side":"bid","event_time":"2025-10-27T17:39:42.148928Z","price_level":"115620.59","new_quantity":"0.16604"},{"side":"bid","event_time":"2025-10-27T17:39:42.148928Z","price_level":"115619.83","new_quantity":"0"},{"side":"bid","event_time":"2025-10-27T17:39:42.148928Z","price_level":"115614","new_quantity":"0.36970468"},{"side":"bid","event_time":"2025-10-27T17:39:42.148928Z","price_level":"115613.99","new_quantity":"0"},{"side":"bid","event_time":"2025-10-27T17:39:42.148928Z","price_level":"115613.97","new_quantity":"0"},{"side":"bid","event_time":"2025-10-27T17:39:42.148928Z","price_level":"115612.8","new_quantity":"0.15713924"},{"side":"bid","event_time":"2025-10-27T17:39:42.148928Z","price_level":"115612.79","new_quantity":"0"},{"side":"bid","event_time":"2025-10-27T17:39:42.148928Z","price_level":"115609.08","new_quantity":"0.52633782"},{"side":"bid","event_time":"2025-10-27T17:39:42.148928Z","price_level":"115608.69","new_quantity":"0.01124"},{"side":"bid","event_time":"2025-10-27T17:39:42.148928Z","price_level":"115604.94","new_quantity":"0"},{"side":"bid","event_time":"2025-10-27T17:39:42.148928Z","price_level":"115601.41","new_quantity":"0"},{"side":"bid","event_time":"2025-10-27T17:39:42.148928Z","price_level":"115601.23","new_quantity":"0.07007"},{"side":"bid","event_time":"2025-10-27T17:39:42.148928Z","price_level":"115596.71","new_quantity":"0.08512499"},{"side":"bid","event_time":"2025-10-27T17:39:42.148928Z","price_level":"115595.85","new_quantity":"0.87978"},{"side":"bid","event_time":"2025-10-27T17:39:42.148928Z","price_level":"115594.51","new_quantity":"0.0648264"},{"side":"bid","event_time":"2025-10-27T17:39:42.148928Z","price_level":"115592.49","new_quantity":"0"},{"side":"bid","event_time":"2025-10-27T17:39:42.148928Z","price_level":"115590.77","new_quantity":"0.874543"},{"side":"bid","event_time":"2025-10-27T17:39:42.148928Z","price_level":"115588.24","new_quantity":"0.76380839"},{"side":"bid","event_time":"2025-10-27T17:39:42.148928Z","price_level":"115584.47","new_quantity":"0"},{"side":"bid","event_time":"2025-10-27T17:39:42.148928Z","price_level":"115581.6","new_quantity":"0"},{"side":"bid","event_time":"2025-10-27T17:39:42.148928Z","price_level":"115581.4","new_quantity":"1.5"},{"side":"bid","event_time":"2025-10-27T17:39:42.148928Z","price_level":"115580.01","new_quantity":"0"},{"side":"bid","event_time":"2025-10-27T17:39:42.148928Z","price_level":"115579.28","new_quantity":"0"},{"side":"bid","event_time":"2025-10-27T17:39:42.148928Z","price_level":"115578.8","new_quantity":"0"},{"side":"bid","event_time":"2025-10-27T17:39:42.148928Z","price_level":"115576.69","new_quantity":"0.01268155"},{"side":"bid","event_time":"2025-10-27T17:39:42.148928Z","price_level":"115567.29","new_quantity":"0"},{"side":"bid","event_time":"2025-10-27T17:39:42.148928Z","price_level":"115552.04","new_quantity":"1.20638796"},{"side":"bid","event_time":"2025-10-27T17:39:42.148928Z","price_level":"115552.03","new_quantity":"0"},{"side":"bid","event_time":"2025-10-27T17:39:42.148928Z","price_level":"115546.6","new_quantity":"0.01033349"},{"side":"bid","event_time":"2025-10-27T17:39:42.148928Z","price_level":"115541.28","new_quantity":"0"},{"side":"bid","event_time":"2025-10-27T17:39:42.148928Z","price_level":"115528.01","new_quantity":"0"},{"side":"bid","event_time":"2025-10-27T17:39:42.148928Z","price_level":"115528","new_quantity":"0"},{"side":"bid","event_time":"2025-10-27T17:39:42.148928Z","price_level":"115511.8","new_quantity":"0.04128788"},{"side":"bid","event_time":"2025-10-27T17:39:42.148928Z","price_level":"115511.79","new_quantity":"0"},{"side":"bid","event_time":"2025-10-27T17:39:42.148928Z","price_level":"115507.9","new_quantity":"0"},{"side":"bid","event_time":"2025-10-27T17:39:42.148928Z","price_level":"115493","new_quantity":"0.2372"},{"side":"bid","event_time":"2025-10-27T17:39:42.148928Z","price_level":"115405.16","new_quantity":"0"},{"side":"bid","event_time":"2025-10-27T17:39:42.148928Z","price_level":"115338.37","new_quantity":"0"},{"side":"bid","event_time":"2025-10-27T17:39:42.148928Z","price_level":"115281.72","new_quantity":"0.00001"},{"side":"bid","event_time":"2025-10-27T17:39:42.148928Z","price_level":"115280.51","new_quantity":"5.844618"},{"side":"bid","event_time":"2025-10-27T17:39:42.148928Z","price_level":"115104.28","new_quantity":"0.1425"},{"side":"bid","event_time":"2025-10-27T17:39:42.148928Z","price_level":"114912.48","new_quantity":"0"},{"side":"offer","event_time":"2025-10-27T17:39:42.148928Z","price_level":"115640.93","new_quantity":"0.0030632"},{"side":"offer","event_time":"2025-10-27T17:39:42.148928Z","price_level":"115643.37","new_quantity":"0"},{"side":"offer","event_time":"2025-10-27T17:39:42.148928Z","price_level":"115644.77","new_quantity":"0.02913"},{"side":"offer","event_time":"2025-10-27T17:39:42.148928Z","price_level":"115645.59","new_quantity":"0"},{"side":"offer","event_time":"2025-10-27T17:39:42.148928Z","price_level":"115646.6","new_quantity":"0"},{"side":"offer","event_time":"2025-10-27T17:39:42.148928Z","price_level":"115647.11","new_quantity":"0"},{"side":"offer","event_time":"2025-10-27T17:39:42.148928Z","price_level":"115649.09","new_quantity":"0.25940542"},{"side":"offer","event_time":"2025-10-27T17:39:42.148928Z","price_level":"115650","new_quantity":"0"},{"side":"offer","event_time":"2025-10-27T17:39:42.148928Z","price_level":"115650.01","new_quantity":"0"},{"side":"offer","event_time":"2025-10-27T17:39:42.148928Z","price_level":"115654.77","new_quantity":"0"},{"side":"offer","event_time":"2025-10-27T17:39:42.148928Z","price_level":"115656.39","new_quantity":"0.04369"},{"side":"offer","event_time":"2025-10-27T17:39:42.148928Z","price_level":"115656.75","new_quantity":"0.25938823"},{"side":"offer","event_time":"2025-10-27T17:39:42.148928Z","price_level":"115657.18","new_quantity":"0"},{"side":"offer","event_time":"2025-10-27T17:39:42.148928Z","price_level":"115657.19","new_quantity":"0"},{"side":"offer","event_time":"2025-10-27T17:39:42.148928Z","price_level":"115658.48","new_quantity":"0"},{"side":"offer","event_time":"2025-10-27T17:39:42.148928Z","price_level":"115661.58","new_quantity":"0.1425"},{"side":"offer","event_time":"2025-10-27T17:39:42.148928Z","price_level":"115662","new_quantity":"0.00608281"},{"side":"offer","event_time":"2025-10-27T17:39:42.148928Z","price_level":"115662.01","new_quantity":"0.00006753"},{"side":"offer","event_time":"2025-10-27T17:39:42.148928Z","price_level":"115662.02","new_quantity":"0"},{"side":"offer","event_time":"2025-10-27T17:39:42.148928Z","price_level":"115662.03","new_quantity":"0"},{"side":"offer","event_time":"2025-10-27T17:39:42.148928Z","price_level":"115664.88","new_quantity":"0.00001"},{"side":"offer","event_time":"2025-10-27T17:39:42.148928Z","price_level":"115666.37","new_quantity":"0"},{"side":"offer","event_time":"2025-10-27T17:39:42.148928Z","price_level":"115666.38","new_quantity":"0"},{"side":"offer","event_time":"2025-10-27T17:39:42.148928Z","price_level":"115666.43","new_quantity":"0"},{"side":"offer","event_time":"2025-10-27T17:39:42.148928Z","price_level":"115667.55","new_quantity":"0.67443"},{"side":"offer","event_time":"2025-10-27T17:39:42.148928Z","price_level":"115668","new_quantity":"0"},{"side":"offer","event_time":"2025-10-27T17:39:42.148928Z","price_level":"115669","new_quantity":"0"},{"side":"offer","event_time":"2025-10-27T17:39:42.148928Z","price_level":"115672.34","new_quantity":"0"},{"side":"offer","event_time":"2025-10-27T17:39:42.148928Z","price_level":"115672.35","new_quantity":"0"},{"side":"offer","event_time":"2025-10-27T17:39:42.148928Z","price_level":"115674.6","new_quantity":"0"},{"side":"offer","event_time":"2025-10-27T17:39:42.148928Z","price_level":"115674.61","new_quantity":"0"},{"side":"offer","event_time":"2025-10-27T17:39:42.148928Z","price_level":"115675.6","new_quantity":"0.737886"},{"side":"offer","event_time":"2025-10-27T17:39:42.148928Z","price_level":"115677.9","new_quantity":"0.13833938"},{"side":"offer","event_time":"2025-10-27T17:39:42.148928Z","price_level":"115681.99","new_quantity":"0.38908572"},{"side":"offer","event_time":"2025-10-27T17:39:42.148928Z","price_level":"115683.91","new_quantity":"0"},{"side":"offer","event_time":"2025-10-27T17:39:42.148928Z","price_level":"115683.92","new_quantity":"0"},{"side":"offer","event_time":"2025-10-27T17:39:42.148928Z","price_level":"115686.73","new_quantity":"0"},{"side":"offer","event_time":"2025-10-27T17:39:42.148928Z","price_level":"115686.74","new_quantity":"0"},{"side":"offer","event_time":"2025-10-27T17:39:42.148928Z","price_level":"115687.55","new_quantity":"0.29226"},{"side":"offer","event_time":"2025-10-27T17:39:42.148928Z","price_level":"115687.98","new_quantity":"0"},{"side":"offer","event_time":"2025-10-27T17:39:42.148928Z","price_level":"115689.6","new_quantity":"0.00001"},{"side":"offer","event_time":"2025-10-27T17:39:42.148928Z","price_level":"115693.99","new_quantity":"0.24461981"},{"side":"offer","event_time":"2025-10-27T17:39:42.148928Z","price_level":"115698.57","new_quantity":"0"},{"side":"offer","event_time":"2025-10-27T17:39:42.148928Z","price_level":"115698.58","new_quantity":"0.00803968"},{"side":"offer","event_time":"2025-10-27T17:39:42.148928Z","price_level":"115699.8","new_quantity":"0.01728611"},{"side":"offer","event_time":"2025-10-27T17:39:42.148928Z","price_level":"115700.05","new_quantity":"0"},{"side":"offer","event_time":"2025-10-27T17:39:42.148928Z","price_level":"115702.2","new_quantity":"0.16811142"},{"side":"offer","event_time":"2025-10-27T17:39:42.148928Z","price_level":"115704.66","new_quantity":"0"},{"side":"offer","event_time":"2025-10-27T17:39:42.148928Z","price_level":"115706.38","new_quantity":"0"},{"side":"offer","event_time":"2025-10-27T17:39:42.148928Z","price_level":"115709.99","new_quantity":"0"},{"side":"offer","event_time":"2025-10-27T17:39:42.148928Z","price_level":"115710","new_quantity":"0.4000267"},{"side":"offer","event_time":"2025-10-27T17:39:42.148928Z","price_level":"115714.35","new_quantity":"0"},{"side":"offer","event_time":"2025-10-27T17:39:42.148928Z","price_level":"115715.05","new_quantity":"0"},{"side":"offer","event_time":"2025-10-27T17:39:42.148928Z","price_level":"115719.94","new_quantity":"0.25114682"},{"side":"offer","event_time":"2025-10-27T17:39:42.148928Z","price_level":"115720.5","new_quantity":"0"},{"side":"offer","event_time":"2025-10-27T17:39:42.148928Z","price_level":"115726.65","new_quantity":"0"},{"side":"offer","event_time":"2025-10-27T17:39:42.148928Z","price_level":"115726.68","new_quantity":"0"},{"side":"offer","event_time":"2025-10-27T17:39:42.148928Z","price_level":"115731.22","new_quantity":"0.37932208"},{"side":"offer","event_time":"2025-10-27T17:39:42.148928Z","price_level":"115735.1","new_quantity":"0.57787321"},{"side":"offer","event_time":"2025-10-27T17:39:42.148928Z","price_level":"115735.11","new_quantity":"0"},{"side":"offer","event_time":"2025-10-27T17:39:42.148928Z","price_level":"115739.99","new_quantity":"0"},{"side":"offer","event_time":"2025-10-27T17:39:42.148928Z","price_level":"115754.99","new_quantity":"0"},{"side":"offer","event_time":"2025-10-27T17:39:42.148928Z","price_level":"115800.84","new_quantity":"0"},{"side":"offer","event_time":"2025-10-27T17:39:42.148928Z","price_level":"115906.66","new_quantity":"0"},{"side":"offer","event_time":"2025-10-27T17:39:42.148928Z","price_level":"116053.62","new_quantity":"0"}]}]}
{"channel":"l2_data","client_id":"","timestamp":"2025-10-27T17:39:42.230970801Z","sequence_num":137673,"events":[{"type":"update","product_id":"ETH-USD","updates":[{"side":"bid","event_time":"2025-10-27T17:39:42.177399Z","price_level":"4218.29","new_quantity":"0.00237063"},{"side":"bid","event_time":"2025-10-27T17:39:42.177399Z","price_level":"4218.23","new_quantity":"0"},{"side":"bid","event_time":"2025-10-27T17:39:42.177399Z","price_level":"4218.1","new_quantity":"0.572"},{"side":"bid","event_time":"2025-10-27T17:39:42.177399Z","price_level":"4218.09","new_quantity":"0"},{"side":"bid","event_time":"2025-10-27T17:39:42.177399Z","price_level":"4218.01","new_quantity":"0"},{"side":"bid","event_time":"2025-10-27T17:39:42.177399Z","price_level":"4217.98","new_quantity":"0"},{"side":"bid","event_time":"2025-10-27T17:39:42.177399Z","price_level":"4217.91","new_quantity":"3.407744"},{"side":"bid","event_time":"2025-10-27T17:39:42.177399Z","price_level":"4217.85","new_quantity":"0"},{"side":"bid","event_time":"2025-10-27T17:39:42.177399Z","price_level":"4217.74","new_quantity":"1.125"},{"side":"bid","event_time":"2025-10-27T17:39:42.177399Z","price_level":"4217.51","new_quantity":"1.65638"},{"side":"bid","event_time":"2025-10-27T17:39:42.177399Z","price_level":"4217.44","new_quantity":"0"},{"side":"bid","event_time":"2025-10-27T17:39:42.177399Z","price_level":"4217.37","new_quantity":"0.59278592"},{"side":"bid","event_time":"2025-10-27T17:39:42.177399Z","price_level":"4217.31","new_quantity":"1.65694"},{"side":"bid","event_time":"2025-10-27T17:39:42.177399Z","price_level":"4217.25","new_quantity":"5.78087715"},{"side":"bid","event_time":"2025-10-27T17:39:42.177399Z","price_level":"4217.09","new_quantity":"0"},{"side":"bid","event_time":"2025-10-27T17:39:42.177399Z","price_level":"4216.75","new_quantity":"0.601"},{"side":"bid","event_time":"2025-10-27T17:39:42.177399Z","price_level":"4216.41","new_quantity":"0"},{"side":"bid","event_time":"2025-10-27T17:39:42.177399Z","price_level":"4216.17","new_quantity":"0"},{"side":"bid","event_time":"2025-10-27T17:39:42.177399Z","price_level":"4216.02","new_quantity":"3.2715266"},{"side":"bid","event_time":"2025-10-27T17:39:42.177399Z","price_level":"4215.75","new_quantity":"0.001"},{"side":"bid","event_time":"2025-10-27T17:39:42.177399Z","price_level":"4215.61","new_quantity":"0.37635091"},{"side":"bid","event_time":"2025-10-27T17:39:42.177399Z","price_level":"4215.13","new_quantity":"0.64798652"},{"side":"bid","event_time":"2025-10-27T17:39:42.177399Z","price_level":"4215.01","new_quantity":"0"},{"side":"bid","event_time":"2025-10-27T17:39:42.177399Z","price_level":"4214.78","new_quantity":"8.84640563"},{"side":"bid","event_time":"2025-10-27T17:39:42.177399Z","price_level":"4214.02","new_quantity":"0"},{"side":"bid","event_time":"2025-10-27T17:39:42.177399Z","price_level":"4213.67","new_quantity":"12.14508374"},{"side":"bid","event_time":"2025-10-27T17:39:42.177399Z","price_level":"4213.66","new_quantity":"19.62537831"},{"side":"offer","event_time":"2025-10-27T17:39:42.177399Z","price_level":"4218.3","new_quantity":"0"},{"side":"offer","event_time":"2025-10-27T17:39:42.177399Z","price_level":"4218.39","new_quantity":"0.341484"},{"side":"offer","event_time":"2025-10-27T17:39:42.177399Z","price_level":"4218.4","new_quantity":"0.572"},{"side":"offer","event_time":"2025-10-27T17:39:42.177399Z","price_level":"4218.46","new_quantity":"0"},{"side":"offer","event_time":"2025-10-27T17:39:42.177399Z","price_level":"4218.47","new_quantity":"0"},{"side":"offer","event_time":"2025-10-27T17:39:42.177399Z","price_level":"4218.48","new_quantity":"0"},{"side":"offer","event_time":"2025-10-27T17:39:42.177399Z","price_level":"4218.49","new_quantity":"1.03817892"},{"side":"offer","event_time":"2025-10-27T17:39:42.177399Z","price_level":"4218.53","new_quantity":"0.00237053"},{"side":"offer","event_time":"2025-10-27T17:39:42.177399Z","price_level":"4218.54","new_quantity":"0.59262264"},{"side":"offer","event_time":"2025-10-27T17:39:42.177399Z","price_level":"4218.59","new_quantity":"0"},{"side":"offer","event_time":"2025-10-27T17:39:42.177399Z","price_level":"4218.69","new_quantity":"0.93365721"},{"side":"offer","event_time":"2025-10-27T17:39:42.177399Z","price_level":"4218.85","new_quantity":"0"},{"side":"offer","event_time":"2025-10-27T17:39:42.177399Z","price_level":"4219.53","new_quantity":"4.461187"},{"side":"offer","event_time":"2025-10-27T17:39:42.177399Z","price_level":"4219.64","new_quantity":"0.0003556"},{"side":"offer","event_time":"2025-10-27T17:39:42.177399Z","price_level":"4220.44","new_quantity":"8.63510821"},{"side":"offer","event_time":"2025-10-27T17:39:42.177399Z","price_level":"4220.67","new_quantity":"0.00886424"}]}]}
39:41.826716Z","price_level":"4218.37","new_quantity":"0"},{"side":"offer","event_time":"2025-10-27T17:39:41.826716Z","price_level":"4218.4","new_quantity":"0"},{"side":"offer","event_time":"2025-10-27T17:39:41.826716Z","price_level":"4218.48","new_quantity":"0.02511404"},{"side":"offer","event_time":"2025-10-27T17:39:41.826716Z","price_level":"4218.49","new_quantity":"0"},{"side":"offer","event_time":"2025-10-27T17:39:41.826716Z","price_level":"4218.5","new_quantity":"0"},{"side":"offer","event_time":"2025-10-27T17:39:41.826716Z","price_level":"4218.6","new_quantity":"0"},{"side":"offer","event_time":"2025-10-27T17:39:41.826716Z","price_level":"4218.66","new_quantity":"0"},{"side":"offer","event_time":"2025-10-27T17:39:41.826716Z","price_level":"4218.67","new_quantity":"0"},{"side":"offer","event_time":"2025-10-27T17:39:41.826716Z","price_level":"4218.69","new_quantity":"0"},{"side":"offer","event_time":"2025-10-27T17:39:41.826716Z","price_level":"4218.7","new_quantity":"0"},{"side":"offer","event_time":"2025-10-27T17:39:41.826716Z","price_level":"4218.77","new_quantity":"0"},{"side":"offer","event_time":"2025-10-27T17:39:41.826716Z","price_level":"4218.78","new_quantity":"0"},{"side":"offer","event_time":"2025-10-27T17:39:41.826716Z","price_level":"4218.79","new_quantity":"0.00237053"},{"side":"offer","event_time":"2025-10-27T17:39:41.826716Z","price_level":"4218.85","new_quantity":"0"},{"side":"offer","event_time":"2025-10-27T17:39:41.826716Z","price_level":"4218.9","new_quantity":"0.519"},{"side":"offer","event_time":"2025-10-27T17:39:41.826716Z","price_level":"4218.91","new_quantity":"0"},{"side":"offer","event_time":"2025-10-27T17:39:41.826716Z","price_level":"4218.99","new_quantity":"0.31044"},{"side":"offer","event_time":"2025-10-27T17:39:41.826716Z","price_level":"4219.13","new_quantity":"0"},{"side":"offer","event_time":"2025-10-27T17:39:41.826716Z","price_level":"4219.14","new_quantity":"0.72474249"},{"side":"offer","event_time":"2025-10-27T17:39:41.826716Z","price_level":"4219.21","new_quantity":"0.59252908"},{"side":"offer","event_time":"2025-10-27T17:39:41.826716Z","price_level":"4219.22","new_quantity":"0"},{"side":"offer","event_time":"2025-10-27T17:39:41.826716Z","price_level":"4219.26","new_quantity":"0"},{"side":"offer","event_time":"2025-10-27T17:39:41.826716Z","price_level":"4219.32","new_quantity":"0.01508562"},{"side":"offer","event_time":"2025-10-27T17:39:41.826716Z","price_level":"4219.33","new_quantity":"0.78813074"},{"side":"offer","event_time":"2025-10-27T17:39:41.826716Z","price_level":"4219.4","new_quantity":"0"},{"side":"offer","event_time":"2025-10-27T17:39:41.826716Z","price_level":"4219.56","new_quantity":"1.96862549"},{"side":"offer","event_time":"2025-10-27T17:39:41.826716Z","price_level":"4219.59","new_quantity":"1.64484"},{"side":"offer","event_time":"2025-10-27T17:39:41.826716Z","price_level":"4219.61","new_quantity":"0"},{"side":"offer","event_time":"2025-10-27T17:39:41.826716Z","price_level":"4219.69","new_quantity":"0"},{"side":"offer","event_time":"2025-10-27T17:39:41.826716Z","price_level":"4219.76","new_quantity":"0"},{"side":"offer","event_time":"2025-10-27T17:39:41.826716Z","price_level":"4219.77","new_quantity":"0.2"},{"side":"offer","event_time":"2025-10-27T17:39:41.826716Z","price_level":"4219.78","new_quantity":"0"},{"side":"offer","event_time":"2025-10-27T17:39:41.826716Z","price_level":"4219.8","new_quantity":"0"},{"side":"offer","event_time":"2025-10-27T17:39:41.826716Z","price_level":"4220","new_quantity":"12.20517286"},{"side":"offer","event_time":"2025-10-27T17:39:41.826716Z","price_level":"4220.15","new_quantity":"0"},{"side":"offer","event_time":"2025-10-27T17:39:41.826716Z","price_level":"4220.39","new_quantity":"0.102886"},{"side":"offer","event_time":"2025-10-27T17:39:41.826716Z","price_level":"4220.67","new_quantity":"0.00886424"},{"side":"offer","event_time":"2025-10-27T17:39:41.826716Z","price_level":"4220.82","new_quantity":"0.47580589"},{"side":"offer","event_time":"2025-10-27T17:39:41.826716Z","price_level":"4220.84","new_quantity":"0.00816482"},{"side":"offer","event_time":"2025-10-27T17:39:41.826716Z","price_level":"4220.89","new_quantity":"8.66981972"},{"side":"offer","event_time":"2025-10-27T17:39:41.826716Z","price_level":"4222.87","new_quantity":"24.57"},{"side":"offer","event_time":"2025-10-27T17:39:41.826716Z","price_level":"4223.73","new_quantity":"0"},{"side":"offer","event_time":"2025-10-27T17:39:41.826716Z","price_level":"4224.96","new_quantity":"37.2125"},{"side":"offer","event_time":"2025-10-27T17:39:41.826716Z","price_level":"4227.09","new_quantity":"48.6975"},{"side":"offer","event_time":"2025-10-27T17:39:41.826716Z","price_level":"4228.24","new_quantity":"73.47500385"},{"side":"offer","event_time":"2025-10-27T17:39:41.826716Z","price_level":"4231.43","new_quantity":"74.9775"},{"side":"offer","event_time":"2025-10-27T17:39:41.826716Z","price_level":"4244.82","new_quantity":"0"}]}]}
{"channel":"l2_data","client_id":"","timestamp":"2025-10-27T17:39:42.300329887Z","sequence_num":137676,"events":[{"type":"update","product_id":"BTC-USD","updates":[{"side":"bid","event_time":"2025-10-27T17:39:42.262294Z","price_level":"115640.91","new_quantity":"0.04535304"},{"side":"bid","event_time":"2025-10-27T17:39:42.262294Z","price_level":"115638.01","new_quantity":"0.07790692"},{"side":"bid","event_time":"2025-10-27T17:39:42.262294Z","price_level":"115633.87","new_quantity":"0.01859003"},{"side":"bid","event_time":"2025-10-27T17:39:42.262294Z","price_level":"115633.86","new_quantity":"0.00864798"},{"side":"bid","event_time":"2025-10-27T17:39:42.262294Z","price_level":"115632.45","new_quantity":"0"},{"side":"bid","event_time":"2025-10-27T17:39:42.262294Z","price_level":"115631.92","new_quantity":"0.012556"},{"side":"bid","event_time":"2025-10-27T17:39:42.262294Z","price_level":"115627.3","new_quantity":"0.23832201"},{"side":"bid","event_time":"2025-10-27T17:39:42.262294Z","price_level":"115627.29","new_quantity":"0.08648476"},{"side":"bid","event_time":"2025-10-27T17:39:42.262294Z","price_level":"115623.01","new_quantity":"0"},{"side":"bid","event_time":"2025-10-27T17:39:42.262294Z","price_level":"115622.87","new_quantity":"0.68273703"},{"side":"bid","event_time":"2025-10-27T17:39:42.262294Z","price_level":"115619.96","new_quantity":"0.628382"},{"side":"bid","event_time":"2025-10-27T17:39:42.262294Z","price_level":"115618.11","new_quantity":"0.08"},{"side":"bid","event_time":"2025-10-27T17:39:42.262294Z","price_level":"115612.97","new_quantity":"0.15839129"},{"side":"bid","event_time":"2025-10-27T17:39:42.262294Z","price_level":"115612.96","new_quantity":"0.28"},{"side":"bid","event_time":"2025-10-27T17:39:42.262294Z","price_level":"115611.01","new_quantity":"2.13704992"},{"side":"bid","event_time":"2025-10-27T17:39:42.262294Z","price_level":"115611","new_quantity":"2"},{"side":"bid","event_time":"2025-10-27T17:39:42.262294Z","price_level":"115609.09","new_quantity":"0"},{"side":"bid","event_time":"2025-10-27T17:39:42.262294Z","price_level":"115609.08","new_quantity":"0"},{"side":"bid","event_time":"2025-10-27T17:39:42.262294Z","price_level":"115609","new_quantity":"0.01039232"},{"side":"bid","event_time":"2025-10-27T17:39:42.262294Z","price_level":"115608.69","new_quantity":"0"},{"side":"bid","event_time":"2025-10-27T17:39:42.262294Z","price_level":"115603.4","new_quantity":"0.04184849"},{"side":"bid","event_time":"2025-10-27T17:39:42.262294Z","price_level":"115602.89","new_quantity":"0"},{"side":"bid","event_time":"2025-10-27T17:39:42.262294Z","price_level":"115598.07","new_quantity":"0.011241"},{"side":"bid","event_time":"2025-10-27T17:39:42.262294Z","price_level":"115596.73","new_quantity":"1.14560808"},{"side":"bid","event_time":"2025-10-27T17:39:42.262294Z","price_level":"115596.72","new_quantity":"0.5263941"},{"side":"bid","event_time":"2025-10-27T17:39:42.262294Z","price_level":"115596.71","new_quantity":"0.37017948"},{"side":"bid","event_time":"2025-10-27T17:39:42.262294Z","price_level":"115592.48","new_quantity":"0"},{"side":"bid","event_time":"2025-10-27T17:39:42.262294Z","price_level":"115588.24","new_quantity":"0.17344305"},{"side":"bid","event_time":"2025-10-27T17:39:42.262294Z","price_level":"115580.01","new_quantity":"3.74886875"},{"side":"bid","event_time":"2025-10-27T17:39:42.262294Z","price_level":"115571.4","new_quantity":"0.01389285"},{"side":"bid","event_time":"2025-10-27T17:39:42.262294Z","price_level":"115570.71","new_quantity":"1.05828102"},{"side":"bid","event_time":"2025-10-27T17:39:42.262294Z","price_level":"115570.7","new_quantity":"1.5"},{"side":"bid","event_time":"2025-10-27T17:39:42.262294Z","price_level":"115567.3","new_quantity":"0"},{"side":"bid","event_time":"2025-10-27T17:39:42.262294Z","price_level":"115565.1","new_quantity":"0"},{"side":"bid","event_time":"2025-10-27T17:39:42.262294Z","price_level":"115564.89","new_quantity":"0.02764829"},{"side":"bid","event_time":"2025-10-27T17:39:42.262294Z","price_level":"115561","new_quantity":"0.02778569"},{"side":"bid","event_time":"2025-10-27T17:39:42.262294Z","price_level":"115552.29","new_quantity":"0.00043228"},{"side":"bid","event_time":"2025-10-27T17:39:42.262294Z","price_level":"115552.28","new_quantity":"0"},{"side":"bid","event_time":"2025-10-27T17:39:42.262294Z","price_level":"115552.07","new_quantity":"0.83846985"},{"side":"bid","event_time":"2025-10-27T17:39:42.262294Z","price_level":"115552.06","new_quantity":"1.20638775"},{"side":"bid","event_time":"2025-10-27T17:39:42.262294Z","price_level":"115552.04","new_quantity":"0"},{"side":"bid","event_time":"2025-10-27T17:39:42.262294Z","price_level":"115546.6","new_quantity":"0.00043228"},{"side":"bid","event_time":"2025-10-27T17:39:42.262294Z","price_level":"115546.59","new_quantity":"0"},{"side":"bid","event_time":"2025-10-27T17:39:42.262294Z","price_level":"115538.2","new_quantity":"0"},{"side":"bid","event_time":"2025-10-27T17:39:42.262294Z","price_level":"115534.44","new_quantity":"0.02755262"},{"side":"bid","event_time":"2025-10-27T17:39:42.262294Z","price_level":"115534.43","new_quantity":"0.01731085"},{"side":"bid","event_time":"2025-10-27T17:39:42.262294Z","price_level":"115528.03","new_quantity":"0.01806514"},{"side":"bid","event_time":"2025-10-27T17:39:42.262294Z","price_level":"115509.85","new_quantity":"0.03102107"},{"side":"bid","event_time":"2025-10-27T17:39:42.262294Z","price_level":"115506.73","new_quantity":"0.11114277"},{"side":"bid","event_time":"2025-10-27T17:39:42.262294Z","price_level":"115499.01","new_quantity":"0.49734822"},{"side":"bid","event_time":"2025-10-27T17:39:42.262294Z","price_level":"115493.02","new_quantity":"0.1829005"},{"side":"bid","event_time":"2025-10-27T17:39:42.262294Z","price_level":"115481.98","new_quantity":"0"},{"side":"bid","event_time":"2025-10-27T17:39:42.262294Z","price_level":"115465.43","new_quantity":"0"},{"side":"bid","event_time":"2025-10-27T17:39:42.262294Z","price_level":"115438.73","new_quantity":"0.06495199"},{"side":"offer","event_time":"2025-10-27T17:39:42.262294Z","price_level":"115646.15","new_quantity":"0"},{"side":"offer","event_time":"2025-10-27T17:39:42.262294Z","price_level":"115647.57","new_quantity":"0.02594088"},{"side":"offer","event_time":"2025-10-27T17:39:42.262294Z","price_level":"115671.01","new_quantity":"0.12"},{"side":"offer","event_time":"2025-10-27T17:39:42.262294Z","price_level":"115672","new_quantity":"2"},{"side":"offer","event_time":"2025-10-27T17:39:42.262294Z","price_level":"115673","new_quantity":"2"},{"side":"offer","event_time":"2025-10-27T17:39:42.262294Z","price_level":"115693.98","new_quantity":"0.16812337"},{"side":"offer","event_time":"2025-10-27T17:39:42.262294Z","price_level":"115693.99","new_quantity":"0.38263575"},{"side":"offer","event_time":"2025-10-27T17:39:42.262294Z","price_level":"115699.99","new_quantity":"2.45947262"},{"side":"offer","event_time":"2025-10-27T17:39:42.262294Z","price_level":"115702.2","new_quantity":"0"},{"side":"offer","event_time":"2025-10-27T17:39:42.262294Z","price_level":"115703.11","new_quantity":"0.28"},{"side":"offer","event_time":"2025-10-27T17:39:42.262294Z","price_level":"115711.99","new_quantity":"0.25116407"},{"side":"offer","event_time":"2025-10-27T17:39:42.262294Z","price_level":"115719.94","new_quantity":"0.00043228"},{"side":"offer","event_time":"2025-10-27T17:39:42.262294Z","price_level":"115720.99","new_quantity":"0.37935561"},{"side":"offer","event_time":"2025-10-27T17:39:42.262294Z","price_level":"115723.72","new_quantity":"0.00086461"},{"side":"offer","event_time":"2025-10-27T17:39:42.262294Z","price_level":"115723.73","new_quantity":"0"},{"side":"offer","event_time":"2025-10-27T17:39:42.262294Z","price_level":"115726.66","new_quantity":"0"},{"side":"offer","event_time":"2025-10-27T17:39:42.262294Z","price_level":"115727.15","new_quantity":"0.57748064"},{"side":"offer","event_time":"2025-10-27T17:39:42.262294Z","price_level":"115731.22","new_quantity":"0"},{"side":"offer","event_time":"2025-10-27T17:39:42.262294Z","price_level":"115735.1","new_quantity":"0"},{"side":"offer","event_time":"2025-10-27T17:39:42.262294Z","price_level":"115885.38","new_quantity":"0.06029762"}]}]}
{"channel":"l2_data","client_id":"","timestamp":"2025-10-27T17:39:42.321377781Z","sequence_num":137677,"events":[{"type":"update","product_id":"ETH-USD","updates":[{"side":"bid","event_time":"2025-10-27T17:39:42.286847Z","price_level":"4218.17","new_quantity":"0"},{"side":"bid","event_time":"2025-10-27T17:39:42.286847Z","price_level":"4218.16","new_quantity":"0"},{"side":"bid","event_time":"2025-10-27T17:39:42.286847Z","price_level":"4218.15","new_quantity":"0.00237071"},{"side":"bid","event_time":"2025-10-27T17:39:42.286847Z","price_level":"4218.14","new_quantity":"0.01777675"},{"side":"bid","event_time":"2025-10-27T17:39:42.286847Z","price_level":"4218.13","new_quantity":"0"},{"side":"bid","event_time":"2025-10-27T17:39:42.286847Z","price_level":"4218.12","new_quantity":"0"},{"side":"bid","event_time":"2025-10-27T17:39:42.286847Z","price_level":"4218.11","new_quantity":"0"},{"side":"bid","event_time":"2025-10-27T17:39:42.286847Z","price_level":"4218.01","new_quantity":"0.621477"},{"side":"bid","event_time":"2025-10-27T17:39:42.286847Z","price_level":"4217.84","new_quantity":"0"},{"side":"bid","event_time":"2025-10-27T17:39:42.286847Z","price_level":"4217.81","new_quantity":"11.21916212"},{"side":"bid","event_time":"2025-10-27T17:39:42.286847Z","price_level":"4217.8","new_quantity":"4.229609"},{"side":"bid","event_time":"2025-10-27T17:39:42.286847Z","price_level":"4217.74","new_quantity":"2.78138"},{"side":"bid","event_time":"2025-10-27T17:39:42.286847Z","price_level":"4217.53","new_quantity":"0.02370513"},{"side":"bid","event_time":"2025-10-27T17:39:42.286847Z","price_level":"4217.51","new_quantity":"0"},{"side":"bid","event_time":"2025-10-27T17:39:42.286847Z","price_level":"4217.32","new_quantity":"5.77978122"},{"side":"bid","event_time":"2025-10-27T17:39:42.286847Z","price_level":"4217.25","new_quantity":"0.001"},{"side":"bid","event_time":"2025-10-27T17:39:42.286847Z","price_level":"4217.22","new_quantity":"0.94611933"},{"side":"bid","event_time":"2025-10-27T17:39:42.286847Z","price_level":"4217.21","new_quantity":"0.54350992"},{"side":"bid","event_time":"2025-10-27T17:39:42.286847Z","price_level":"4217.08","new_quantity":"0"},{"side":"bid","event_time":"2025-10-27T17:39:42.286847Z","price_level":"4216.82","new_quantity":"0.8"},{"side":"bid","event_time":"2025-10-27T17:39:42.286847Z","price_level":"4214.2","new_quantity":"12.86389803"},{"side":"bid","event_time":"2025-10-27T17:39:42.286847Z","price_level":"4214.03","new_quantity":"0"},{"side":"bid","event_time":"2025-10-27T17:39:42.286847Z","price_level":"4213.68","new_quantity":"19.62528516"},{"side":"bid","event_time":"2025-10-27T17:39:42.286847Z","price_level":"4213.67","new_quantity":"0"},{"side":"bid","event_time":"2025-10-27T17:39:42.286847Z","price_level":"4213.66","new_quantity":"0"},{"side":"offer","event_time":"2025-10-27T17:39:42.286847Z","price_level":"4218.39","new_quantity":"0.00237053"},{"side":"offer","event_time":"2025-10-27T17:39:42.286847Z","price_level":"4218.4","new_quantity":"0.572"},{"side":"offer","event_time":"2025-10-27T17:39:42.286847Z","price_level":"4218.89","new_quantity":"0"},{"side":"offer","event_time":"2025-10-27T17:39:42.286847Z","price_level":"4219.1","new_quantity":"0.01508562"},{"side":"offer","event_time":"2025-10-27T17:39:42.286847Z","price_level":"4220.07","new_quantity":"0.102886"},{"side":"offer","event_time":"2025-10-27T17:39:42.286847Z","price_level":"4220.39","new_quantity":"0"}]}]}
{"channel":"l2_data","client_id":"","timestamp":"2025-10-27T17:39:42.3475291Z","sequence_num":137679,"events":[{"type":"update","product_id":"BTC-USD","updates":[{"side":"bid","event_time":"2025-10-27T17:39:42.289994Z","price_level":"115640.91","new_quantity":"0.03533261"},{"side":"bid","event_time":"2025-10-27T17:39:42.289994Z","price_level":"115633.86","new_quantity":"0"},{"side":"bid","event_time":"2025-10-27T17:39:42.289994Z","price_level":"115619.29","new_quantity":"0"},{"side":"bid","event_time":"2025-10-27T17:39:42.289994Z","price_level":"115546.6","new_quantity":"0"},{"side":"bid","event_time":"2025-10-27T17:39:42.289994Z","price_level":"114901.59","new_quantity":"0.00216153"},{"side":"offer","event_time":"2025-10-27T17:39:42.289994Z","price_level":"115645.92","new_quantity":"0.02594125"},{"side":"offer","event_time":"2025-10-27T17:39:42.289994Z","price_level":"115647.57","new_quantity":"0"},{"side":"offer","event_time":"2025-10-27T17:39:42.289994Z","price_level":"115719.94","new_quantity":"0"},{"side":"offer","event_time":"2025-10-27T17:39:42.289994Z","price_level":"115723.72","new_quantity":"0.00043228"}]}]}
{"channel":"l2_data","client_id":"","timestamp":"2025-10-27T17:39:42.372044144Z","sequence_num":137680,"events":[{"type":"update","product_id":"ETH-USD","updates":[{"side":"bid","event_time":"2025-10-27T17:39:42.336889Z","price_level":"4218.28","new_quantity":"0.00237064"},{"side":"bid","event_time":"2025-10-27T17:39:42.336889Z","price_level":"4218.27","new_quantity":"0.07109366"},{"side":"bid","event_time":"2025-10-27T17:39:42.336889Z","price_level":"4218.26","new_quantity":"1"},{"side":"bid","event_time":"2025-10-27T17:39:42.336889Z","price_level":"4218.24","new_quantity":"1"},{"side":"bid","event_time":"2025-10-27T17:39:42.336889Z","price_level":"4218.15","new_quantity":"0"},{"side":"bid","event_time":"2025-10-27T17:39:42.336889Z","price_level":"4217.61","new_quantity":"31.30634237"},{"side":"bid","event_time":"2025-10-27T17:39:42.336889Z","price_level":"4217.31","new_quantity":"0"},{"side":"bid","event_time":"2025-10-27T17:39:42.336889Z","price_level":"4217.22","new_quantity":"0.62164391"},{"side":"bid","event_time":"2025-10-27T17:39:42.336889Z","price_level":"4217.21","new_quantity":"0"},{"side":"bid","event_time":"2025-10-27T17:39:42.336889Z","price_level":"4214.92","new_quantity":"8.84611179"},{"side":"bid","event_time":"2025-10-27T17:39:42.336889Z","price_level":"4214.78","new_quantity":"0"},{"side":"offer","event_time":"2025-10-27T17:39:42.336889Z","price_level":"4218.38","new_quantity":"0.02031657"},{"side":"offer","event_time":"2025-10-27T17:39:42.336889Z","price_level":"4220.44","new_quantity":"0.09965802"},{"side":"offer","event_time":"2025-10-27T17:39:42.336889Z","price_level":"4220.67","new_quantity":"8.5438493"},{"side":"offer","event_time":"2025-10-27T17:39:42.336889Z","price_level":"4220.87","new_quantity":"0.47506793"},{"side":"offer","event_time":"2025-10-27T17:39:42.336889Z","price_level":"4221.5","new_quantity":"0.001"},{"side":"offer","event_time":"2025-10-27T17:39:42.336889Z","price_level":"4221.82","new_quantity":"15.34260145"},{"side":"offer","event_time":"2025-10-27T17:39:42.336889Z","price_level":"4222.86","new_quantity":"0"},{"side":"offer","event_time":"2025-10-27T17:39:42.336889Z","price_level":"4223.22","new_quantity":"9.52582941"},{"side":"offer","event_time":"2025-10-27T17:39:42.336889Z","price_level":"4224.07","new_quantity":"0.1536"},{"side":"offer","event_time":"2025-10-27T17:39:42.336889Z","price_level":"4267.21","new_quantity":"0"},{"side":"offer","event_time":"2025-10-27T17:39:42.336889Z","price_level":"4267.23","new_quantity":"0.59880912"},{"side":"offer","event_time":"2025-10-27T17:39:42.336889Z","price_level":"4272.99","new_quantity":"7.08630634"},{"side":"offer","event_time":"2025-10-27T17:39:42.336889Z","price_level":"4273.22","new_quantity":"0"}]}]}
{"channel":"l2_data","client_id":"","timestamp":"2025-10-27T17:39:42.398834827Z","sequence_num":137682,"events":[{"type":"update","product_id":"BTC-USD","updates":[{"side":"bid","event_time":"2025-10-27T17:39:42.340805Z","price_level":"115638.01","new_quantity":"0"},{"side":"bid","event_time":"2025-10-27T17:39:42.340805Z","price_level":"115635.66","new_quantity":"0.00864785"},{"side":"bid","event_time":"2025-10-27T17:39:42.340805Z","price_level":"115633.87","new_quantity":"0.07017565"},{"side":"bid","event_time":"2025-10-27T17:39:42.340805Z","price_level":"115632.16","new_quantity":"0.08648112"},{"side":"bid","event_time":"2025-10-27T17:39:42.340805Z","price_level":"115627.47","new_quantity":"0.16604"},{"side":"bid","event_time":"2025-10-27T17:39:42.340805Z","price_level":"115623.83","new_quantity":"0"},{"side":"bid","event_time":"2025-10-27T17:39:42.340805Z","price_level":"115612.99","new_quantity":"0.36492045"},{"side":"bid","event_time":"2025-10-27T17:39:42.340805Z","price_level":"115612.98","new_quantity":"0.33125703"},{"side":"bid","event_time":"2025-10-27T17:39:42.340805Z","price_level":"115612.97","new_quantity":"0"},{"side":"bid","event_time":"2025-10-27T17:39:42.340805Z","price_level":"115611.02","new_quantity":"0.5216247"},{"side":"bid","event_time":"2025-10-27T17:39:42.340805Z","price_level":"115611.01","new_quantity":"0"},{"side":"bid","event_time":"2025-10-27T17:39:42.340805Z","price_level":"115611","new_quantity":"0"},{"side":"bid","event_time":"2025-10-27T17:39:42.340805Z","price_level":"115608.68","new_quantity":"0"},{"side":"bid","event_time":"2025-10-27T17:39:42.340805Z","price_level":"115606.37","new_quantity":"0.0069609"},{"side":"bid","event_time":"2025-10-27T17:39:42.340805Z","price_level":"115603.82","new_quantity":"0.04184849"},{"side":"bid","event_time":"2025-10-27T17:39:42.340805Z","price_level":"115603.81","new_quantity":"0.07007"},{"side":"bid","event_time":"2025-10-27T17:39:42.340805Z","price_level":"115603.4","new_quantity":"0"},{"side":"bid","event_time":"2025-10-27T17:39:42.340805Z","price_level":"115603.39","new_quantity":"0"},{"side":"bid","event_time":"2025-10-27T17:39:42.340805Z","price_level":"115596.75","new_quantity":"0.92461088"},{"side":"bid","event_time":"2025-10-27T17:39:42.340805Z","price_level":"115596.74","new_quantity":"0.52639401"},{"side":"bid","event_time":"2025-10-27T17:39:42.340805Z","price_level":"115596.73","new_quantity":"0"},{"side":"bid","event_time":"2025-10-27T17:39:42.340805Z","price_level":"115596.72","new_quantity":"0.37011406"},{"side":"bid","event_time":"2025-10-27T17:39:42.340805Z","price_level":"115596.71","new_quantity":"0"},{"side":"bid","event_time":"2025-10-27T17:39:42.340805Z","price_level":"115571.41","new_quantity":"0"},{"side":"bid","event_time":"2025-10-27T17:39:42.340805Z","price_level":"115571.4","new_quantity":"0.01389285"},{"side":"bid","event_time":"2025-10-27T17:39:42.340805Z","price_level":"115570.71","new_quantity":"0"},{"side":"bid","event_time":"2025-10-27T17:39:42.340805Z","price_level":"115570.7","new_quantity":"0"},{"side":"bid","event_time":"2025-10-27T17:39:42.340805Z","price_level":"115570.01","new_quantity":"1.05802298"},{"side":"bid","event_time":"2025-10-27T17:39:42.340805Z","price_level":"115570","new_quantity":"1.5"},{"side":"bid","event_time":"2025-10-27T17:39:42.340805Z","price_level":"115567.27","new_quantity":"0"},{"side":"bid","event_time":"2025-10-27T17:39:42.340805Z","price_level":"115552.09","new_quantity":"0.83846972"},{"side":"bid","event_time":"2025-10-27T17:39:42.340805Z","price_level":"115552.08","new_quantity":"1.20638754"},{"side":"bid","event_time":"2025-10-27T17:39:42.340805Z","price_level":"115552.07","new_quantity":"0"},{"side":"bid","event_time":"2025-10-27T17:39:42.340805Z","price_level":"115552.06","new_quantity":"0"},{"side":"bid","event_time":"2025-10-27T17:39:42.340805Z","price_level":"115497.85","new_quantity":"0"},{"side":"bid","event_time":"2025-10-27T17:39:42.340805Z","price_level":"115489.65","new_quantity":"0.0850725"},{"side":"bid","event_time":"2025-10-27T17:39:42.340805Z","price_level":"115460.61","new_quantity":"0.03295856"},{"side":"bid","event_time":"2025-10-27T17:39:42.340805Z","price_level":"115386.6","new_quantity":"0"},{"side":"bid","event_time":"2025-10-27T17:39:42.340805Z","price_level":"115016.56","new_quantity":"0.02504652"},{"side":"bid","event_time":"2025-10-27T17:39:42.340805Z","price_level":"114969.7","new_quantity":"0.02750323"},{"side":"bid","event_time":"2025-10-27T17:39:42.340805Z","price_level":"114116.12","new_quantity":"0"},{"side":"offer","event_time":"2025-10-27T17:39:42.340805Z","price_level":"115666.99","new_quantity":"0.00006753"},{"side":"offer","event_time":"2025-10-27T17:39:42.340805Z","price_level":"115667","new_quantity":"2"},{"side":"offer","event_time":"2025-10-27T17:39:42.340805Z","price_level":"115667.54","new_quantity":"0"},{"side":"offer","event_time":"2025-10-27T17:39:42.340805Z","price_level":"115668","new_quantity":"2"},{"side":"offer","event_time":"2025-10-27T17:39:42.340805Z","price_level":"115672","new_quantity":"0"},{"side":"offer","event_time":"2025-10-27T17:39:42.340805Z","price_level":"115672.33","new_quantity":"0"},{"side":"offer","event_time":"2025-10-27T17:39:42.340805Z","price_level":"115674.74","new_quantity":"0.008993"},{"side":"offer","event_time":"2025-10-27T17:39:42.340805Z","price_level":"115675.59","new_quantity":"0.03458745"},{"side":"offer","event_time":"2025-10-27T17:39:42.340805Z","price_level":"115683.7","new_quantity":"0"},{"side":"offer","event_time":"2025-10-27T17:39:42.340805Z","price_level":"115718.7","new_quantity":"1"},{"side":"offer","event_time":"2025-10-27T17:39:42.340805Z","price_level":"115718.9","new_quantity":"0"},{"side":"offer","event_time":"2025-10-27T17:39:42.340805Z","price_level":"115720.99","new_quantity":"0"},{"side":"offer","event_time":"2025-10-27T17:39:42.340805Z","price_level":"115721","new_quantity":"0"},{"side":"offer","event_time":"2025-10-27T17:39:42.340805Z","price_level":"115723.72","new_quantity":"0"},{"side":"offer","event_time":"2025-10-27T17:39:42.340805Z","price_level":"115727.13","new_quantity":"0.57748074"},{"side":"offer","event_time":"2025-10-27T17:39:42.340805Z","price_level":"115727.14","new_quantity":"0.37933545"},{"side":"offer","event_time":"2025-10-27T17:39:42.340805Z","price_level":"115727.15","new_quantity":"0"},{"side":"offer","event_time":"2025-10-27T17:39:42.340805Z","price_level":"115732.6","new_quantity":"0.01215308"},{"side":"offer","event_time":"2025-10-27T17:39:42.340805Z","price_level":"115755.47","new_quantity":"0"},{"side":"offer","event_time":"2025-10-27T17:39:42.340805Z","price_level":"115893.89","new_quantity":"0.07007"},{"side":"offer","event_time":"2025-10-27T17:39:42.340805Z","price_level":"115905.24","new_quantity":"0"}]}]}
{"channel":"l2_data","client_id":"","timestamp":"2025-10-27T17:39:42.419358456Z","sequence_num":137683,"events":[{"type":"update","product_id":"ETH-USD","updates":[{"side":"bid","event_time":"2025-10-27T17:39:42.379253Z","price_level":"4218.32","new_quantity":"1.07972366"},{"side":"bid","event_time":"2025-10-27T17:39:42.379253Z","price_level":"4218.28","new_quantity":"0"},{"side":"bid","event_time":"2025-10-27T17:39:42.379253Z","price_level":"4218.27","new_quantity":"0.00237065"},{"side":"bid","event_time":"2025-10-27T17:39:42.379253Z","price_level":"4217.55","new_quantity":"0.53357955"},{"side":"bid","event_time":"2025-10-27T17:39:42.379253Z","price_level":"4217.44","new_quantity":"5.77961676"},{"side":"bid","event_time":"2025-10-27T17:39:42.379253Z","price_level":"4217.32","new_quantity":"0"},{"side":"bid","event_time":"2025-10-27T17:39:42.379253Z","price_level":"4216.19","new_quantity":"4.2003366"},{"side":"bid","event_time":"2025-10-27T17:39:42.379253Z","price_level":"4214.71","new_quantity":"8.76126369"},{"side":"bid","event_time":"2025-10-27T17:39:42.379253Z","price_level":"4214.26","new_quantity":"12.86371489"},{"side":"bid","event_time":"2025-10-27T17:39:42.379253Z","price_level":"4214.2","new_quantity":"0"},{"side":"bid","event_time":"2025-10-27T17:39:42.379253Z","price_level":"4213.97","new_quantity":"19.62393457"},{"side":"bid","event_time":"2025-10-27T17:39:42.379253Z","price_level":"4213.68","new_quantity":"0"}]}]}
{"channel":"l2_data","client_id":"","timestamp":"2025-10-27T17:39:42.447893737Z","sequence_num":137685,"events":[{"type":"update","product_id":"BTC-USD","updates":[{"side":"bid","event_time":"2025-10-27T17:39:42.398681Z","price_level":"115631.91","new_quantity":"0.02161115"},{"side":"bid","event_time":"2025-10-27T17:39:42.398681Z","price_level":"115625.95","new_quantity":"0.00432"},{"side":"bid","event_time":"2025-10-27T17:39:42.398681Z","price_level":"115625.92","new_quantity":"0.00432"},{"side":"bid","event_time":"2025-10-27T17:39:42.398681Z","price_level":"115621.69","new_quantity":"0"},{"side":"bid","event_time":"2025-10-27T17:39:42.398681Z","price_level":"115620.91","new_quantity":"0.04"},{"side":"bid","event_time":"2025-10-27T17:39:42.398681Z","price_level":"115612.99","new_quantity":"1.51226609"},{"side":"bid","event_time":"2025-10-27T17:39:42.398681Z","price_level":"115612","new_quantity":"2"},{"side":"bid","event_time":"2025-10-27T17:39:42.398681Z","price_level":"115608.68","new_quantity":"0.37009203"},{"side":"bid","event_time":"2025-10-27T17:39:42.398681Z","price_level":"115596.72","new_quantity":"0"},{"side":"bid","event_time":"2025-10-27T17:39:42.398681Z","price_level":"115590.36","new_quantity":"0.63998037"},{"side":"bid","event_time":"2025-10-27T17:39:42.398681Z","price_level":"115555.69","new_quantity":"0.72264632"},{"side":"bid","event_time":"2025-10-27T17:39:42.398681Z","price_level":"115555.68","new_quantity":"1.21046285"},{"side":"bid","event_time":"2025-10-27T17:39:42.398681Z","price_level":"101185.8","new_quantity":"0.0049568"},{"side":"offer","event_time":"2025-10-27T17:39:42.398681Z","price_level":"115718.7","new_quantity":"0"},{"side":"offer","event_time":"2025-10-27T17:39:42.398681Z","price_level":"115718.8","new_quantity":"1"}]}]}
{"channel":"l2_data","client_id":"","timestamp":"2025-10-27T17:39:42.47052437Z","sequence_num":137686,"events":[{"type":"update","product_id":"ETH-USD","updates":[{"side":"bid","event_time":"2025-10-27T17:39:42.437647Z","price_level":"4218.33","new_quantity":"0.00237061"},{"side":"bid","event_time":"2025-10-27T17:39:42.437647Z","price_level":"4218.27","new_quantity":"0"},{"side":"bid","event_time":"2025-10-27T17:39:42.437647Z","price_level":"4217.53","new_quantity":"0"},{"side":"bid","event_time":"2025-10-27T17:39:42.437647Z","price_level":"4217.27","new_quantity":"0.02370538"},{"side":"bid","event_time":"2025-10-27T17:39:42.437647Z","price_level":"4215.84","new_quantity":"0"},{"side":"bid","event_time":"2025-10-27T17:39:42.437647Z","price_level":"4215.58","new_quantity":"0.11852695"},{"side":"bid","event_time":"2025-10-27T17:39:42.437647Z","price_level":"4215.01","new_quantity":"8.84592291"},{"side":"bid","event_time":"2025-10-27T17:39:42.437647Z","price_level":"4214.92","new_quantity":"0"},{"side":"bid","event_time":"2025-10-27T17:39:42.437647Z","price_level":"4213.07","new_quantity":"0.1536"},{"side":"offer","event_time":"2025-10-27T17:39:42.437647Z","price_level":"4218.39","new_quantity":"0"},{"side":"offer","event_time":"2025-10-27T17:39:42.437647Z","price_level":"4218.4","new_quantity":"0"},{"side":"offer","event_time":"2025-10-27T17:39:42.437647Z","price_level":"4218.46","new_quantity":"0.00237053"},{"side":"offer","event_time":"2025-10-27T17:39:42.437647Z","price_level":"4219.1","new_quantity":"0"},{"side":"offer","event_time":"2025-10-27T17:39:42.437647Z","price_level":"4219.32","new_quantity":"0.01508562"}]}]}
{"channel":"l2_data","client_id":"","timestamp":"2025-10-27T17:39:42.248065254Z","sequence_num":137674,"events":[{"type":"update","product_id":"BTC-USD","updates":[{"side":"bid","event_time":"2025-10-27T17:39:42.204035Z","price_level":"115640.91","new_quantity":"0.02142542"},{"side":"bid","event_time":"2025-10-27T17:39:42.204035Z","price_level":"115640","new_quantity":"0.0224"},{"side":"bid","event_time":"2025-10-27T17:39:42.204035Z","price_level":"115638","new_quantity":"0.0224"},{"side":"bid","event_time":"2025-10-27T17:39:42.204035Z","price_level":"115632.65","new_quantity":"0"},{"side":"bid","event_time":"2025-10-27T17:39:42.204035Z","price_level":"115632.45","new_quantity":"0.00864809"},{"side":"bid","event_time":"2025-10-27T17:39:42.204035Z","price_level":"115630.79","new_quantity":"0"},{"side":"bid","event_time":"2025-10-27T17:39:42.204035Z","price_level":"115628.52","new_quantity":"0"},{"side":"bid","event_time":"2025-10-27T17:39:42.204035Z","price_level":"115623.83","new_quantity":"0.00129649"},{"side":"bid","event_time":"2025-10-27T17:39:42.204035Z","price_level":"115623.12","new_quantity":"0"},{"side":"bid","event_time":"2025-10-27T17:39:42.204035Z","price_level":"115621.69","new_quantity":"0.16604"},{"side":"bid","event_time":"2025-10-27T17:39:42.204035Z","price_level":"115620.59","new_quantity":"0"},{"side":"bid","event_time":"2025-10-27T17:39:42.204035Z","price_level":"115619.29","new_quantity":"0.08649075"},{"side":"bid","event_time":"2025-10-27T17:39:42.204035Z","price_level":"115617.36","new_quantity":"0"},{"side":"bid","event_time":"2025-10-27T17:39:42.204035Z","price_level":"115614","new_quantity":"0"},{"side":"bid","event_time":"2025-10-27T17:39:42.204035Z","price_level":"115612.8","new_quantity":"0"},{"side":"bid","event_time":"2025-10-27T17:39:42.204035Z","price_level":"115609.09","new_quantity":"0.15713924"},{"side":"bid","event_time":"2025-10-27T17:39:42.204035Z","price_level":"115609.08","new_quantity":"0.52633782"},{"side":"bid","event_time":"2025-10-27T17:39:42.204035Z","price_level":"115608.67","new_quantity":"0.71389"},{"side":"bid","event_time":"2025-10-27T17:39:42.204035Z","price_level":"115603.39","new_quantity":"0.07007"},{"side":"bid","event_time":"2025-10-27T17:39:42.204035Z","price_level":"115601.23","new_quantity":"0"},{"side":"bid","event_time":"2025-10-27T17:39:42.204035Z","price_level":"115596.71","new_quantity":"0.45530447"},{"side":"bid","event_time":"2025-10-27T17:39:42.204035Z","price_level":"115594.51","new_quantity":"0"},{"side":"bid","event_time":"2025-10-27T17:39:42.204035Z","price_level":"115585.62","new_quantity":"0.0648264"},{"side":"bid","event_time":"2025-10-27T17:39:42.204035Z","price_level":"115581.4","new_quantity":"0"},{"side":"bid","event_time":"2025-10-27T17:39:42.204035Z","price_level":"115576.69","new_quantity":"0"},{"side":"bid","event_time":"2025-10-27T17:39:42.204035Z","price_level":"115576.68","new_quantity":"0"},{"side":"bid","event_time":"2025-10-27T17:39:42.204035Z","price_level":"115565.1","new_quantity":"1.5"},{"side":"bid","event_time":"2025-10-27T17:39:42.204035Z","price_level":"115564.88","new_quantity":"0.02123212"},{"side":"bid","event_time":"2025-10-27T17:39:42.204035Z","price_level":"115535.81","new_quantity":"0"},{"side":"bid","event_time":"2025-10-27T17:39:42.204035Z","price_level":"115535.8","new_quantity":"0"},{"side":"bid","event_time":"2025-10-27T17:39:42.204035Z","price_level":"115511.8","new_quantity":"0"},{"side":"bid","event_time":"2025-10-27T17:39:42.204035Z","price_level":"115509.84","new_quantity":"0.05196159"},{"side":"bid","event_time":"2025-10-27T17:39:42.204035Z","price_level":"115493.01","new_quantity":"0.069166"},{"side":"offer","event_time":"2025-10-27T17:39:42.204035Z","price_level":"115640.92","new_quantity":"0.0024948"},{"side":"offer","event_time":"2025-10-27T17:39:42.204035Z","price_level":"115640.93","new_quantity":"0"},{"side":"offer","event_time":"2025-10-27T17:39:42.204035Z","price_level":"115643.37","new_quantity":"0.00002568"},{"side":"offer","event_time":"2025-10-27T17:39:42.204035Z","price_level":"115644.77","new_quantity":"0"},{"side":"offer","event_time":"2025-10-27T17:39:42.204035Z","price_level":"115646.15","new_quantity":"0.0259412"},{"side":"offer","event_time":"2025-10-27T17:39:42.204035Z","price_level":"115649.08","new_quantity":"0.00328513"},{"side":"offer","event_time":"2025-10-27T17:39:42.204035Z","price_level":"115651.83","new_quantity":"0.25939928"},{"side":"offer","event_time":"2025-10-27T17:39:42.204035Z","price_level":"115655.74","new_quantity":"0.2593905"},{"side":"offer","event_time":"2025-10-27T17:39:42.204035Z","price_level":"115656.75","new_quantity":"0"},{"side":"offer","event_time":"2025-10-27T17:39:42.204035Z","price_level":"115662","new_quantity":"0"},{"side":"offer","event_time":"2025-10-27T17:39:42.204035Z","price_level":"115662.01","new_quantity":"0"},{"side":"offer","event_time":"2025-10-27T17:39:42.204035Z","price_level":"115667.54","new_quantity":"0.00006753"},{"side":"offer","event_time":"2025-10-27T17:39:42.204035Z","price_level":"115672.33","new_quantity":"0.03458777"},{"side":"offer","event_time":"2025-10-27T17:39:42.204035Z","price_level":"115674.59","new_quantity":"0.13834141"},{"side":"offer","event_time":"2025-10-27T17:39:42.204035Z","price_level":"115675.78","new_quantity":"0.38910516"},{"side":"offer","event_time":"2025-10-27T17:39:42.204035Z","price_level":"115677.9","new_quantity":"0"},{"side":"offer","event_time":"2025-10-27T17:39:42.204035Z","price_level":"115679.09","new_quantity":"0.07007"},{"side":"offer","event_time":"2025-10-27T17:39:42.204035Z","price_level":"115681.99","new_quantity":"0"},{"side":"offer","event_time":"2025-10-27T17:39:42.204035Z","price_level":"115686.06","new_quantity":"0"},{"side":"offer","event_time":"2025-10-27T17:39:42.204035Z","price_level":"115687.55","new_quantity":"0"},{"side":"offer","event_time":"2025-10-27T17:39:42.204035Z","price_level":"115690.32","new_quantity":"0"},{"side":"offer","event_time":"2025-10-27T17:39:42.204035Z","price_level":"115697.35","new_quantity":"0.283568"},{"side":"offer","event_time":"2025-10-27T17:39:42.204035Z","price_level":"115705.95","new_quantity":"0.00702643"},{"side":"offer","event_time":"2025-10-27T17:39:42.204035Z","price_level":"115710","new_quantity":"5.4000267"},{"side":"offer","event_time":"2025-10-27T17:39:42.204035Z","price_level":"115713.39","new_quantity":"0.02204637"},{"side":"offer","event_time":"2025-10-27T17:39:42.204035Z","price_level":"115714.62","new_quantity":"0"},{"side":"offer","event_time":"2025-10-27T17:39:42.204035Z","price_level":"115720.9","new_quantity":"0"},{"side":"offer","event_time":"2025-10-27T17:39:42.204035Z","price_level":"115721","new_quantity":"1"},{"side":"offer","event_time":"2025-10-27T17:39:42.204035Z","price_level":"115723.74","new_quantity":"0"},{"side":"offer","event_time":"2025-10-27T17:39:42.204035Z","price_level":"115731.23","new_quantity":"0"},{"side":"offer","event_time":"2025-10-27T17:39:42.204035Z","price_level":"115731.6","new_quantity":"0"},{"side":"offer","event_time":"2025-10-27T17:39:42.204035Z","price_level":"115762.08","new_quantity":"0.069166"},{"side":"offer","event_time":"2025-10-27T17:39:42.204035Z","price_level":"115772.51","new_quantity":"0.04019841"},{"side":"offer","event_time":"2025-10-27T17:39:42.204035Z","price_level":"115774.22","new_quantity":"0"},{"side":"offer","event_time":"2025-10-27T17:39:42.204035Z","price_level":"115798.76","new_quantity":"0"},{"side":"offer","event_time":"2025-10-27T17:39:42.204035Z","price_level":"115824.46","new_quantity":"0.05024801"},{"side":"offer","event_time":"2025-10-27T17:39:42.204035Z","price_level":"115850.74","new_quantity":"0"},{"side":"offer","event_time":"2025-10-27T17:39:42.204035Z","price_level":"115913.12","new_quantity":"0"}]}]}
{"channel":"l2_data","client_id":"","timestamp":"2025-10-27T17:39:42.49766159Z","sequence_num":137687,"events":[{"type":"update","product_id":"BTC-USD","updates":[{"side":"bid","event_time":"2025-10-27T17:39:42.453429Z","price_level":"115640.91","new_quantity":"0.06196916"},{"side":"bid","event_time":"2025-10-27T17:39:42.453429Z","price_level":"115637.72","new_quantity":"0"},{"side":"bid","event_time":"2025-10-27T17:39:42.453429Z","price_level":"115635.66","new_quantity":"0"},{"side":"bid","event_time":"2025-10-27T17:39:42.453429Z","price_level":"115628.57","new_quantity":"0.00086469"},{"side":"bid","event_time":"2025-10-27T17:39:42.453429Z","price_level":"115627.48","new_quantity":"0.00077661"},{"side":"bid","event_time":"2025-10-27T17:39:42.453429Z","price_level":"115626.16","new_quantity":"0"},{"side":"bid","event_time":"2025-10-27T17:39:42.453429Z","price_level":"115618","new_quantity":"2"},{"side":"bid","event_time":"2025-10-27T17:39:42.453429Z","price_level":"115617.01","new_quantity":"0.00432345"},{"side":"bid","event_time":"2025-10-27T17:39:42.453429Z","price_level":"115613.01","new_quantity":"0.36492041"},{"side":"bid","event_time":"2025-10-27T17:39:42.453429Z","price_level":"115613","new_quantity":"0.33125697"},{"side":"bid","event_time":"2025-10-27T17:39:42.453429Z","price_level":"115612.99","new_quantity":"0"},{"side":"bid","event_time":"2025-10-27T17:39:42.453429Z","price_level":"115612.98","new_quantity":"0"},{"side":"bid","event_time":"2025-10-27T17:39:42.453429Z","price_level":"115612","new_quantity":"0"},{"side":"bid","event_time":"2025-10-27T17:39:42.453429Z","price_level":"115606.8","new_quantity":"0.011241"},{"side":"bid","event_time":"2025-10-27T17:39:42.453429Z","price_level":"115598.07","new_quantity":"0"},{"side":"bid","event_time":"2025-10-27T17:39:42.453429Z","price_level":"115596.77","new_quantity":"0.92461082"},{"side":"bid","event_time":"2025-10-27T17:39:42.453429Z","price_level":"115596.76","new_quantity":"0.52639392"},{"side":"bid","event_time":"2025-10-27T17:39:42.453429Z","price_level":"115596.75","new_quantity":"0"},{"side":"bid","event_time":"2025-10-27T17:39:42.453429Z","price_level":"115596.74","new_quantity":"0"},{"side":"bid","event_time":"2025-10-27T17:39:42.453429Z","price_level":"115555.7","new_quantity":"1.20634975"},{"side":"bid","event_time":"2025-10-27T17:39:42.453429Z","price_level":"115552.08","new_quantity":"0"},{"side":"bid","event_time":"2025-10-27T17:39:42.453429Z","price_level":"115534.45","new_quantity":"0.00043228"},{"side":"bid","event_time":"2025-10-27T17:39:42.453429Z","price_level":"115423.72","new_quantity":"0"},{"side":"bid","event_time":"2025-10-27T17:39:42.453429Z","price_level":"114969.7","new_quantity":"0.05291289"},{"side":"bid","event_time":"2025-10-27T17:39:42.453429Z","price_level":"114692.23","new_quantity":"0.03199536"},{"side":"offer","event_time":"2025-10-27T17:39:42.453429Z","price_level":"115666.99","new_quantity":"0"},{"side":"offer","event_time":"2025-10-27T17:39:42.453429Z","price_level":"115667","new_quantity":"0"},{"side":"offer","event_time":"2025-10-27T17:39:42.453429Z","price_level":"115667.54","new_quantity":"0.0000748"},{"side":"offer","event_time":"2025-10-27T17:39:42.453429Z","price_level":"115668","new_quantity":"0"},{"side":"offer","event_time":"2025-10-27T17:39:42.453429Z","price_level":"115673","new_quantity":"0"},{"side":"offer","event_time":"2025-10-27T17:39:42.453429Z","price_level":"115678","new_quantity":"0"},{"side":"offer","event_time":"2025-10-27T17:39:42.453429Z","price_level":"115705.94","new_quantity":"0.00043228"},{"side":"offer","event_time":"2025-10-27T17:39:42.453429Z","price_level":"115711.98","new_quantity":"0.00043234"},{"side":"offer","event_time":"2025-10-27T17:39:42.453429Z","price_level":"115715.59","new_quantity":"0.00043228"},{"side":"offer","event_time":"2025-10-27T17:39:42.453429Z","price_level":"115727.11","new_quantity":"0.57748084"},{"side":"offer","event_time":"2025-10-27T17:39:42.453429Z","price_level":"115727.12","new_quantity":"0.37933552"},{"side":"offer","event_time":"2025-10-27T17:39:42.453429Z","price_level":"115727.13","new_quantity":"0"},{"side":"offer","event_time":"2025-10-27T17:39:42.453429Z","price_level":"115727.14","new_quantity":"0"}]}]}
{"channel":"l2_data","client_id":"","timestamp":"2025-10-27T17:39:42.522268816Z","sequence_num":137688,"events":[{"type":"update","product_id":"ETH-USD","updates":[{"side":"bid","event_time":"2025-10-27T17:39:42.482152Z","price_level":"4218.33","new_quantity":"0"},{"side":"bid","event_time":"2025-10-27T17:39:42.482152Z","price_level":"4218.32","new_quantity":"1.00863"},{"side":"bid","event_time":"2025-10-27T17:39:42.482152Z","price_level":"4218.27","new_quantity":"0.00237065"},{"side":"bid","event_time":"2025-10-27T17:39:42.482152Z","price_level":"4218.19","new_quantity":"0.07109366"},{"side":"bid","event_time":"2025-10-27T17:39:42.482152Z","price_level":"4218.01","new_quantity":"0"},{"side":"bid","event_time":"2025-10-27T17:39:42.482152Z","price_level":"4217.87","new_quantity":"0.11854317"},{"side":"bid","event_time":"2025-10-27T17:39:42.482152Z","price_level":"4217.74","new_quantity":"1.125"},{"side":"bid","event_time":"2025-10-27T17:39:42.482152Z","price_level":"4217.52","new_quantity":"0"},{"side":"bid","event_time":"2025-10-27T17:39:42.482152Z","price_level":"4216.19","new_quantity":"0"},{"side":"bid","event_time":"2025-10-27T17:39:42.482152Z","price_level":"4214.02","new_quantity":"19.62370173"},{"side":"bid","event_time":"2025-10-27T17:39:42.482152Z","price_level":"4213.97","new_quantity":"0"},{"side":"bid","event_time":"2025-10-27T17:39:42.482152Z","price_level":"4210.48","new_quantity":"3.54755548"},{"side":"bid","event_time":"2025-10-27T17:39:42.482152Z","price_level":"4206.71","new_quantity":"0"},{"side":"offer","event_time":"2025-10-27T17:39:42.482152Z","price_level":"4218.39","new_quantity":"0.00237053"},{"side":"offer","event_time":"2025-10-27T17:39:42.482152Z","price_level":"4218.4","new_quantity":"0.572"},{"side":"offer","event_time":"2025-10-27T17:39:42.482152Z","price_level":"4218.46","new_quantity":"0"},{"side":"offer","event_time":"2025-10-27T17:39:42.482152Z","price_level":"4219.77","new_quantity":"0.302886"},{"side":"offer","event_time":"2025-10-27T17:39:42.482152Z","price_level":"4220.07","new_quantity":"0"},{"side":"offer","event_time":"2025-10-27T17:39:42.482152Z","price_level":"4229.27","new_quantity":"0"}]}]}
{"channel":"l2_data","client_id":"","timestamp":"2025-10-27T17:39:42.271160288Z","sequence_num":137675,"events":[{"type":"update","product_id":"ETH-USD","updates":[{"side":"bid","event_time":"2025-10-27T17:39:42.233372Z","price_level":"4218.39","new_quantity":"0"},{"side":"bid","event_time":"2025-10-27T17:39:42.233372Z","price_level":"4218.38","new_quantity":"0"},{"side":"bid","event_time":"2025-10-27T17:39:42.233372Z","price_level":"4218.29","new_quantity":"0"},{"side":"bid","event_time":"2025-10-27T17:39:42.233372Z","price_level":"4218.22","new_quantity":"0"},{"side":"bid","event_time":"2025-10-27T17:39:42.233372Z","price_level":"4218.13","new_quantity":"0.17151798"},{"side":"bid","event_time":"2025-10-27T17:39:42.233372Z","price_level":"4218.12","new_quantity":"0.17388871"},{"side":"bid","event_time":"2025-10-27T17:39:42.233372Z","price_level":"4218.11","new_quantity":"0.01777675"},{"side":"bid","event_time":"2025-10-27T17:39:42.233372Z","price_level":"4217.91","new_quantity":"0"},{"side":"bid","event_time":"2025-10-27T17:39:42.233372Z","price_level":"4217.74","new_quantity":"9.10643789"},{"side":"bid","event_time":"2025-10-27T17:39:42.233372Z","price_level":"4217.69","new_quantity":"0"},{"side":"bid","event_time":"2025-10-27T17:39:42.233372Z","price_level":"4217.65","new_quantity":"0.59274703"},{"side":"bid","event_time":"2025-10-27T17:39:42.233372Z","price_level":"4217.53","new_quantity":"0.55120024"},{"side":"bid","event_time":"2025-10-27T17:39:42.233372Z","price_level":"4217.52","new_quantity":"1.65694"},{"side":"bid","event_time":"2025-10-27T17:39:42.233372Z","price_level":"4216.99","new_quantity":"0.21565049"},{"side":"offer","event_time":"2025-10-27T17:39:42.233372Z","price_level":"4218.39","new_quantity":"0"},{"side":"offer","event_time":"2025-10-27T17:39:42.233372Z","price_level":"4218.4","new_quantity":"0.57437053"},{"side":"offer","event_time":"2025-10-27T17:39:42.233372Z","price_level":"4218.47","new_quantity":"0.59263192"},{"side":"offer","event_time":"2025-10-27T17:39:42.233372Z","price_level":"4218.53","new_quantity":"0"},{"side":"offer","event_time":"2025-10-27T17:39:42.233372Z","price_level":"4218.68","new_quantity":"0"},{"side":"offer","event_time":"2025-10-27T17:39:42.233372Z","price_level":"4219.53","new_quantity":"0"},{"side":"offer","event_time":"2025-10-27T17:39:42.233372Z","price_level":"4219.62","new_quantity":"4.040424"},{"side":"offer","event_time":"2025-10-27T17:39:42.233372Z","price_level":"4219.9","new_quantity":"10"},{"side":"offer","event_time":"2025-10-27T17:39:42.233372Z","price_level":"4220","new_quantity":"22.20517286"},{"side":"offer","event_time":"2025-10-27T17:39:42.233372Z","price_level":"4221.5","new_quantity":"15.24668281"},{"side":"offer","event_time":"2025-10-27T17:39:42.233372Z","price_level":"4221.84","new_quantity":"0"},{"side":"offer","event_time":"2025-10-27T17:39:42.233372Z","price_level":"4222.86","new_quantity":"9.52664149"},{"side":"offer","event_time":"2025-10-27T17:39:42.233372Z","price_level":"4223.02","new_quantity":"0"},{"side":"offer","event_time":"2025-10-27T17:39:42.233372Z","price_level":"4272.72","new_quantity":"0.0946876"}]}]}
{"channel":"l2_data","client_id":"","timestamp":"2025-10-27T17:39:42.645153885Z","sequence_num":137690,"events":[{"type":"update","product_id":"ETH-USD","updates":[{"side":"bid","event_time":"2025-10-27T17:39:42.534776Z","price_level":"4218.29","new_quantity":"0.07109366"},{"side":"bid","event_time":"2025-10-27T17:39:42.534776Z","price_level":"4218.25","new_quantity":"0"},{"side":"bid","event_time":"2025-10-27T17:39:42.534776Z","price_level":"4218.19","new_quantity":"0"},{"side":"bid","event_time":"2025-10-27T17:39:42.534776Z","price_level":"4218.15","new_quantity":"0"},{"side":"bid","event_time":"2025-10-27T17:39:42.534776Z","price_level":"4218.14","new_quantity":"0"},{"side":"bid","event_time":"2025-10-27T17:39:42.534776Z","price_level":"4218.1","new_quantity":"0"},{"side":"bid","event_time":"2025-10-27T17:39:42.534776Z","price_level":"4217.87","new_quantity":"0"},{"side":"bid","event_time":"2025-10-27T17:39:42.534776Z","price_level":"4217.82","new_quantity":"0.02070633"},{"side":"bid","event_time":"2025-10-27T17:39:42.534776Z","price_level":"4217.73","new_quantity":"0"},{"side":"bid","event_time":"2025-10-27T17:39:42.534776Z","price_level":"4217.6","new_quantity":"31.65696"},{"side":"bid","event_time":"2025-10-27T17:39:42.534776Z","price_level":"4217.4","new_quantity":"21.803902"},{"side":"bid","event_time":"2025-10-27T17:39:42.534776Z","price_level":"4216.82","new_quantity":"0"},{"side":"bid","event_time":"2025-10-27T17:39:42.534776Z","price_level":"4216.6","new_quantity":"0.00050522"},{"side":"bid","event_time":"2025-10-27T17:39:42.534776Z","price_level":"4216.02","new_quantity":"0"},{"side":"bid","event_time":"2025-10-27T17:39:42.534776Z","price_level":"4215.86","new_quantity":"3.27163228"},{"side":"bid","event_time":"2025-10-27T17:39:42.534776Z","price_level":"4192.06","new_quantity":"0"},{"side":"offer","event_time":"2025-10-27T17:39:42.534776Z","price_level":"4218.33","new_quantity":"0.2909368"},{"side":"offer","event_time":"2025-10-27T17:39:42.534776Z","price_level":"4218.34","new_quantity":"0"},{"side":"offer","event_time":"2025-10-27T17:39:42.534776Z","price_level":"4218.38","new_quantity":"0.02031657"},{"side":"offer","event_time":"2025-10-27T17:39:42.534776Z","price_level":"4218.39","new_quantity":"0"},{"side":"offer","event_time":"2025-10-27T17:39:42.534776Z","price_level":"4218.81","new_quantity":"0.97621181"},{"side":"offer","event_time":"2025-10-27T17:39:42.534776Z","price_level":"4219.1","new_quantity":"0.01508562"},{"side":"offer","event_time":"2025-10-27T17:39:42.534776Z","price_level":"4219.11","new_quantity":"1.58017136"},{"side":"offer","event_time":"2025-10-27T17:39:42.534776Z","price_level":"4219.15","new_quantity":"0.71154204"},{"side":"offer","event_time":"2025-10-27T17:39:42.534776Z","price_level":"4219.26","new_quantity":"1.64515"},{"side":"offer","event_time":"2025-10-27T17:39:42.534776Z","price_level":"4219.32","new_quantity":"0"},{"side":"offer","event_time":"2025-10-27T17:39:42.534776Z","price_level":"4219.44","new_quantity":"0.102887"},{"side":"offer","event_time":"2025-10-27T17:39:42.534776Z","price_level":"4219.77","new_quantity":"0.2"},{"side":"offer","event_time":"2025-10-27T17:39:42.534776Z","price_level":"4219.8","new_quantity":"10"},{"side":"offer","event_time":"2025-10-27T17:39:42.534776Z","price_level":"4219.9","new_quantity":"0"},{"side":"offer","event_time":"2025-10-27T17:39:42.534776Z","price_level":"4223.95","new_quantity":"0.1536"},{"side":"offer","event_time":"2025-10-27T17:39:42.534776Z","price_level":"4224.07","new_quantity":"0"},{"side":"offer","event_time":"2025-10-27T17:39:42.534776Z","price_level":"4245.04","new_quantity":"0.1536"},{"side":"offer","event_time":"2025-10-27T17:39:42.534776Z","price_level":"4272.5","new_quantity":"0"},{"side":"offer","event_time":"2025-10-27T17:39:42.534776Z","price_level":"4272.72","new_quantity":"0.1893752"},{"side":"offer","event_time":"2025-10-27T17:39:42.534776Z","price_level":"4272.99","new_quantity":"6.9074273"}]}]}
{"channel":"l2_data","client_id":"","timestamp":"2025-10-27T17:39:42.687461895Z","sequence_num":137692,"events":[{"type":"update","product_id":"BTC-USD","updates":[{"side":"bid","event_time":"2025-10-27T17:39:42.534022Z","price_level":"115633.53","new_quantity":"0.02161115"},{"side":"bid","event_time":"2025-10-27T17:39:42.534022Z","price_level":"115632.69","new_quantity":"0"},{"side":"bid","event_time":"2025-10-27T17:39:42.534022Z","price_level":"115631.91","new_quantity":"0"},{"side":"bid","event_time":"2025-10-27T17:39:42.534022Z","price_level":"115621.69","new_quantity":"0.16604"},{"side":"bid","event_time":"2025-10-27T17:39:42.534022Z","price_level":"115613.03","new_quantity":"0.36492038"},{"side":"bid","event_time":"2025-10-27T17:39:42.534022Z","price_level":"115613.02","new_quantity":"0.33125692"},{"side":"bid","event_time":"2025-10-27T17:39:42.534022Z","price_level":"115613.01","new_quantity":"0"},{"side":"bid","event_time":"2025-10-27T17:39:42.534022Z","price_level":"115613","new_quantity":"0"},{"side":"bid","event_time":"2025-10-27T17:39:42.534022Z","price_level":"115596.79","new_quantity":"0.92461077"},{"side":"bid","event_time":"2025-10-27T17:39:42.534022Z","price_level":"115596.78","new_quantity":"0.52639383"},{"side":"bid","event_time":"2025-10-27T17:39:42.534022Z","price_level":"115596.77","new_quantity":"0"},{"side":"bid","event_time":"2025-10-27T17:39:42.534022Z","price_level":"115596.76","new_quantity":"0"},{"side":"bid","event_time":"2025-10-27T17:39:42.534022Z","price_level":"115575.3","new_quantity":"0"},{"side":"bid","event_time":"2025-10-27T17:39:42.534022Z","price_level":"115573","new_quantity":"1.5"},{"side":"offer","event_time":"2025-10-27T17:39:42.534022Z","price_level":"115640.92","new_quantity":"0.0316248"},{"side":"offer","event_time":"2025-10-27T17:39:42.534022Z","price_level":"115719.94","new_quantity":"0.37935906"},{"side":"offer","event_time":"2025-10-27T17:39:42.534022Z","price_level":"115727.12","new_quantity":"0"}]}]}
{"channel":"l2_data","client_id":"","timestamp":"2025-10-27T17:39:42.702456368Z","sequence_num":137696,"events":[{"type":"update","product_id":"ETH-USD","updates":[{"side":"bid","event_time":"2025-10-27T17:39:42.583399Z","price_level":"4218.29","new_quantity":"0"},{"side":"bid","event_time":"2025-10-27T17:39:42.583399Z","price_level":"4217.82","new_quantity":"1.67766633"},{"side":"offer","event_time":"2025-10-27T17:39:42.583399Z","price_level":"4218.33","new_quantity":"0.12090084"},{"side":"offer","event_time":"2025-10-27T17:39:42.583399Z","price_level":"4218.81","new_quantity":"0.4578293"},{"side":"offer","event_time":"2025-10-27T17:39:42.583399Z","price_level":"4219.62","new_quantity":"0"},{"side":"offer","event_time":"2025-10-27T17:39:42.583399Z","price_level":"4219.8","new_quantity":"0"}]}]}
{"channel":"l2_data","client_id":"","timestamp":"2025-10-27T17:39:42.703095863Z","sequence_num":137697,"events":[{"type":"update","product_id":"ETH-USD","updates":[{"side":"bid","event_time":"2025-10-27T17:39:42.627162Z","price_level":"4217.83","new_quantity":"0.02270633"},{"side":"bid","event_time":"2025-10-27T17:39:42.627162Z","price_level":"4217.82","new_quantity":"1.65696"},{"side":"offer","event_time":"2025-10-27T17:39:42.627162Z","price_level":"4218.33","new_quantity":"0.2439368"},{"side":"offer","event_time":"2025-10-27T17:39:42.627162Z","price_level":"4219.33","new_quantity":"0"},{"side":"offer","event_time":"2025-10-27T17:39:42.627162Z","price_level":"4219.39","new_quantity":"0"},{"side":"offer","event_time":"2025-10-27T17:39:42.627162Z","price_level":"4219.7","new_quantity":"10.49495661"},{"side":"offer","event_time":"2025-10-27T17:39:42.627162Z","price_level":"4245.04","new_quantity":"0"}]}]}
{"channel":"l2_data","client_id":"","timestamp":"2025-10-27T17:39:42.720958695Z","sequence_num":137700,"events":[{"type":"update","product_id":"ETH-USD","updates":[{"side":"bid","event_time":"2025-10-27T17:39:42.674711Z","price_level":"4217.6","new_quantity":"30"},{"side":"bid","event_time":"2025-10-27T17:39:42.674711Z","price_level":"4216.78","new_quantity":"1.09078474"},{"side":"offer","event_time":"2025-10-27T17:39:42.674711Z","price_level":"4218.33","new_quantity":"0.10428682"}]}]}
{"channel":"l2_data","client_id":"","timestamp":"2025-10-27T17:39:42.749032709Z","sequence_num":137701,"events":[{"type":"update","product_id":"BTC-USD","updates":[{"side":"bid","event_time":"2025-10-27T17:39:42.682656Z","price_level":"115615.91","new_quantity":"0"},{"side":"bid","event_time":"2025-10-27T17:39:42.682656Z","price_level":"115555.74","new_quantity":"1.20634933"},{"side":"bid","event_time":"2025-10-27T17:39:42.682656Z","price_level":"115555.73","new_quantity":"0"},{"side":"bid","event_time":"2025-10-27T17:39:42.682656Z","price_level":"115555.72","new_quantity":"0"},{"side":"offer","event_time":"2025-10-27T17:39:42.682656Z","price_level":"115667","new_quantity":"2"},{"side":"offer","event_time":"2025-10-27T17:39:42.682656Z","price_level":"115667.99","new_quantity":"0.0000748"},{"side":"offer","event_time":"2025-10-27T17:39:42.682656Z","price_level":"115668","new_quantity":"2"},{"side":"offer","event_time":"2025-10-27T17:39:42.682656Z","price_level":"115670.98","new_quantity":"0"},{"side":"offer","event_time":"2025-10-27T17:39:42.682656Z","price_level":"115670.99","new_quantity":"0"}]}]}
{"channel":"l2_data","client_id":"","timestamp":"2025-10-27T17:39:42.771795418Z","sequence_num":137702,"events":[{"type":"update","product_id":"ETH-USD","updates":[{"side":"bid","event_time":"2025-10-27T17:39:42.740065Z","price_level":"4218.33","new_quantity":"0.07109422"},{"side":"bid","event_time":"2025-10-27T17:39:42.740065Z","price_level":"4218.27","new_quantity":"0.00237065"},{"side":"bid","event_time":"2025-10-27T17:39:42.740065Z","price_level":"4217.91","new_quantity":"0"},{"side":"bid","event_time":"2025-10-27T17:39:42.740065Z","price_level":"4217.71","new_quantity":"0.11854769"},{"side":"bid","event_time":"2025-10-27T17:39:42.740065Z","price_level":"4217.61","new_quantity":"32.96328237"},{"side":"bid","event_time":"2025-10-27T17:39:42.740065Z","price_level":"4217.22","new_quantity":"0.62164391"},{"side":"bid","event_time":"2025-10-27T17:39:42.740065Z","price_level":"4217.14","new_quantity":"0"},{"side":"bid","event_time":"2025-10-27T17:39:42.740065Z","price_level":"4216.79","new_quantity":"1.2283386"},{"side":"bid","event_time":"2025-10-27T17:39:42.740065Z","price_level":"4216.78","new_quantity":"0.8"},{"side":"bid","event_time":"2025-10-27T17:39:42.740065Z","price_level":"4215.46","new_quantity":"4.32574919"},{"side":"bid","event_time":"2025-10-27T17:39:42.740065Z","price_level":"4215.02","new_quantity":"6.75475715"},{"side":"bid","event_time":"2025-10-27T17:39:42.740065Z","price_level":"4212.01","new_quantity":"29.850597"},{"side":"offer","event_time":"2025-10-27T17:39:42.740065Z","price_level":"4218.33","new_quantity":"0"},{"side":"offer","event_time":"2025-10-27T17:39:42.740065Z","price_level":"4218.37","new_quantity":"0.17051798"},{"side":"offer","event_time":"2025-10-27T17:39:42.740065Z","price_level":"4218.38","new_quantity":"0.02031657"},{"side":"offer","event_time":"2025-10-27T17:39:42.740065Z","price_level":"4219.59","new_quantity":"5.15940469"},{"side":"offer","event_time":"2025-10-27T17:39:42.740065Z","price_level":"4219.6","new_quantity":"4.206428"}]}]}
{"channel":"l2_data","client_id":"","timestamp":"2025-10-27T17:39:42.799598028Z","sequence_num":137703,"events":[{"type":"update","product_id":"BTC-USD","updates":[{"side":"bid","event_time":"2025-10-27T17:39:42.754733Z","price_level":"115640.91","new_quantity":"0.08792272"},{"side":"bid","event_time":"2025-10-27T17:39:42.754733Z","price_level":"115640.01","new_quantity":"0.0017295"},{"side":"bid","event_time":"2025-10-27T17:39:42.754733Z","price_level":"115632.43","new_quantity":"0.02161064"},{"side":"bid","event_time":"2025-10-27T17:39:42.754733Z","price_level":"115628.27","new_quantity":"0.00432"},{"side":"bid","event_time":"2025-10-27T17:39:42.754733Z","price_level":"115625.92","new_quantity":"0.00432"},{"side":"bid","event_time":"2025-10-27T17:39:42.754733Z","price_level":"115624.61","new_quantity":"0"},{"side":"bid","event_time":"2025-10-27T17:39:42.754733Z","price_level":"115612.98","new_quantity":"0.33125703"},{"side":"bid","event_time":"2025-10-27T17:39:42.754733Z","price_level":"115612.97","new_quantity":"0"},{"side":"bid","event_time":"2025-10-27T17:39:42.754733Z","price_level":"115611.03","new_quantity":"0"},{"side":"bid","event_time":"2025-10-27T17:39:42.754733Z","price_level":"115575.7","new_quantity":"1.5"},{"side":"bid","event_time":"2025-10-27T17:39:42.754733Z","price_level":"115575.51","new_quantity":"0.76389252"},{"side":"bid","event_time":"2025-10-27T17:39:42.754733Z","price_level":"115575.5","new_quantity":"0"},{"side":"bid","event_time":"2025-10-27T17:39:42.754733Z","price_level":"115575.34","new_quantity":"0"},{"side":"bid","event_time":"2025-10-27T17:39:42.754733Z","price_level":"115573","new_quantity":"0"},{"side":"bid","event_time":"2025-10-27T17:39:42.754733Z","price_level":"115555.75","new_quantity":"1.44283687"},{"side":"bid","event_time":"2025-10-27T17:39:42.754733Z","price_level":"115552.29","new_quantity":"0"},{"side":"bid","event_time":"2025-10-27T17:39:42.754733Z","price_level":"115550.44","new_quantity":"0.00043229"},{"side":"bid","event_time":"2025-10-27T17:39:42.754733Z","price_level":"115500.25","new_quantity":"0.045"},{"side":"bid","event_time":"2025-10-27T17:39:42.754733Z","price_level":"101185.8","new_quantity":"0"},{"side":"offer","event_time":"2025-10-27T17:39:42.754733Z","price_level":"115666.99","new_quantity":"0"},{"side":"offer","event_time":"2025-10-27T17:39:42.754733Z","price_level":"115667","new_quantity":"0"},{"side":"offer","event_time":"2025-10-27T17:39:42.754733Z","price_level":"115667.98","new_quantity":"0.0000748"},{"side":"offer","event_time":"2025-10-27T17:39:42.754733Z","price_level":"115667.99","new_quantity":"0.00515008"},{"side":"offer","event_time":"2025-10-27T17:39:42.754733Z","price_level":"115700","new_quantity":"5.00001798"},{"side":"offer","event_time":"2025-10-27T17:39:42.754733Z","price_level":"115718.7","new_quantity":"0"},{"side":"offer","event_time":"2025-10-27T17:39:42.754733Z","price_level":"115718.9","new_quantity":"1"},{"side":"offer","event_time":"2025-10-27T17:39:42.754733Z","price_level":"115730","new_quantity":"0"}]}]}
{"channel":"l2_data","client_id":"","timestamp":"2025-10-27T17:39:42.82051383Z","sequence_num":137704,"events":[{"type":"update","product_id":"ETH-USD","updates":[{"side":"bid","event_time":"2025-10-27T17:39:42.769862Z","price_level":"4206.56","new_quantity":"33.14793088"},{"side":"offer","event_time":"2025-10-27T17:39:42.769862Z","price_level":"4218.83","new_quantity":"0.52674378"},{"side":"offer","event_time":"2025-10-27T17:39:42.769862Z","price_level":"4229.22","new_quantity":"32.63477181"}]}]}
{"channel":"l2_data","client_id":"","timestamp":"2025-10-27T17:39:42.847193451Z","sequence_num":137706,"events":[{"type":"update","product_id":"BTC-USD","updates":[{"side":"bid","event_time":"2025-10-27T17:39:42.802475Z","price_level":"115627.31","new_quantity":"0"},{"side":"bid","event_time":"2025-10-27T17:39:42.802475Z","price_level":"115555.76","new_quantity":"1.20634912"},{"side":"bid","event_time":"2025-10-27T17:39:42.802475Z","price_level":"115555.75","new_quantity":"0"},{"side":"bid","event_time":"2025-10-27T17:39:42.802475Z","price_level":"115555.74","new_quantity":"0"},{"side":"bid","event_time":"2025-10-27T17:39:42.802475Z","price_level":"115541.28","new_quantity":"0.00001"},{"side":"offer","event_time":"2025-10-27T17:39:42.802475Z","price_level":"115649.08","new_quantity":"0.00181541"},{"side":"offer","event_time":"2025-10-27T17:39:42.802475Z","price_level":"115663","new_quantity":"0.00432"},{"side":"offer","event_time":"2025-10-27T17:39:42.802475Z","price_level":"115663.01","new_quantity":"0.00432"},{"side":"offer","event_time":"2025-10-27T17:39:42.802475Z","price_level":"115666.99","new_quantity":"0.0000748"},{"side":"offer","event_time":"2025-10-27T17:39:42.802475Z","price_level":"115667.98","new_quantity":"0"},{"side":"offer","event_time":"2025-10-27T17:39:42.802475Z","price_level":"115667.99","new_quantity":"0"},{"side":"offer","event_time":"2025-10-27T17:39:42.802475Z","price_level":"115726.68","new_quantity":"0.00001"}]}]}
{"channel":"l2_data","client_id":"","timestamp":"2025-10-27T17:39:42.869190767Z","sequence_num":137707,"events":[{"type":"update","product_id":"ETH-USD","updates":[{"side":"bid","event_time":"2025-10-27T17:39:42.810325Z","price_level":"4218.01","new_quantity":"0.621477"},{"side":"bid","event_time":"2025-10-27T17:39:42.810325Z","price_level":"4217.4","new_quantity":"20.146962"}]}]}
{"channel":"l2_data","client_id":"","timestamp":"2025-10-27T17:39:42.898279817Z","sequence_num":137709,"events":[{"type":"update","product_id":"BTC-USD","updates":[{"side":"bid","event_time":"2025-10-27T17:39:42.851801Z","price_level":"115627.31","new_quantity":"0.00052662"},{"side":"bid","event_time":"2025-10-27T17:39:42.851801Z","price_level":"115613.01","new_quantity":"0.36492041"},{"side":"bid","event_time":"2025-10-27T17:39:42.851801Z","price_level":"115613","new_quantity":"0.33125697"},{"side":"bid","event_time":"2025-10-27T17:39:42.851801Z","price_level":"115612.98","new_quantity":"0"},{"side":"bid","event_time":"2025-10-27T17:39:42.851801Z","price_level":"115575.72","new_quantity":"1.35984305"},{"side":"bid","event_time":"2025-10-27T17:39:42.851801Z","price_level":"115575.71","new_quantity":"0.7638912"},{"side":"bid","event_time":"2025-10-27T17:39:42.851801Z","price_level":"115575.51","new_quantity":"0"},{"side":"offer","event_time":"2025-10-27T17:39:42.851801Z","price_level":"115666.99","new_quantity":"0.0000748"},{"side":"offer","event_time":"2025-10-27T17:39:42.851801Z","price_level":"115667.99","new_quantity":"0"}]}]}
{"channel":"l2_data","client_id":"","timestamp":"2025-10-27T17:39:42.91909858Z","sequence_num":137710,"events":[{"type":"update","product_id":"ETH-USD","updates":[{"side":"bid","event_time":"2025-10-27T17:39:42.886808Z","price_level":"4218.33","new_quantity":"0"}]}]}
{"channel":"l2_data","client_id":"","timestamp":"2025-10-27T17:39:42.947193163Z","sequence_num":137711,"events":[{"type":"update","product_id":"BTC-USD","updates":[{"side":"bid","event_time":"2025-10-27T17:39:42.886349Z","price_level":"115620.61","new_quantity":"0.08"},{"side":"offer","event_time":"2025-10-27T17:39:42.886349Z","price_level":"115649.08","new_quantity":"0.30972641"},{"side":"offer","event_time":"2025-10-27T17:39:42.886349Z","price_level":"115655.73","new_quantity":"0.18093906"},{"side":"offer","event_time":"2025-10-27T17:39:42.886349Z","price_level":"115661.57","new_quantity":"0.09023058"},{"side":"offer","event_time":"2025-10-27T17:39:42.886349Z","price_level":"115666.99","new_quantity":"2.20827485"},{"side":"offer","event_time":"2025-10-27T17:39:42.886349Z","price_level":"115667","new_quantity":"2"},{"side":"offer","event_time":"2025-10-27T17:39:42.886349Z","price_level":"115667.99","new_quantity":"0.0050854"}]}]}
{"channel":"l2_data","client_id":"","timestamp":"2025-10-27T17:39:42.971256605Z","sequence_num":137712,"events":[{"type":"update","product_id":"ETH-USD","updates":[{"side":"bid","event_time":"2025-10-27T17:39:42.935449Z","price_level":"4218.36","new_quantity":"0.07109422"},{"side":"bid","event_time":"2025-10-27T17:39:42.935449Z","price_level":"4218.27","new_quantity":"0"},{"side":"bid","event_time":"2025-10-27T17:39:42.935449Z","price_level":"4218.02","new_quantity":"0.00237079"},{"side":"bid","event_time":"2025-10-27T17:39:42.935449Z","price_level":"4217.88","new_quantity":"0.11854279"},{"side":"bid","event_time":"2025-10-27T17:39:42.935449Z","price_level":"4217.71","new_quantity":"0"},{"side":"bid","event_time":"2025-10-27T17:39:42.935449Z","price_level":"4215.46","new_quantity":"0"},{"side":"bid","event_time":"2025-10-27T17:39:42.935449Z","price_level":"4214.71","new_quantity":"0"},{"side":"offer","event_time":"2025-10-27T17:39:42.935449Z","price_level":"4218.37","new_quantity":"0.28904717"},{"side":"offer","event_time":"2025-10-27T17:39:42.935449Z","price_level":"4219.6","new_quantity":"0"}]}]}
{"channel":"l2_data","client_id":"","timestamp":"2025-10-27T17:39:42.998237709Z","sequence_num":137713,"events":[{"type":"update","product_id":"BTC-USD","updates":[{"side":"bid","event_time":"2025-10-27T17:39:42.940692Z","price_level":"115627.31","new_quantity":"0"},{"side":"bid","event_time":"2025-10-27T17:39:42.940692Z","price_level":"115605.26","new_quantity":"0.08368028"},{"side":"bid","event_time":"2025-10-27T17:39:42.940692Z","price_level":"115605.25","new_quantity":"0.07007"},{"side":"bid","event_time":"2025-10-27T17:39:42.940692Z","price_level":"115604.85","new_quantity":"0.07007"},{"side":"bid","event_time":"2025-10-27T17:39:42.940692Z","price_level":"115603.82","new_quantity":"0"},{"side":"bid","event_time":"2025-10-27T17:39:42.940692Z","price_level":"115603.81","new_quantity":"0"},{"side":"bid","event_time":"2025-10-27T17:39:42.940692Z","price_level":"115575.74","new_quantity":"1.35984297"},{"side":"bid","event_time":"2025-10-27T17:39:42.940692Z","price_level":"115575.73","new_quantity":"0.76389107"},{"side":"bid","event_time":"2025-10-27T17:39:42.940692Z","price_level":"115575.72","new_quantity":"0"},{"side":"bid","event_time":"2025-10-27T17:39:42.940692Z","price_level":"115575.71","new_quantity":"0"},{"side":"bid","event_time":"2025-10-27T17:39:42.940692Z","price_level":"114102.58","new_quantity":"0"},{"side":"offer","event_time":"2025-10-27T17:39:42.940692Z","price_level":"115649.07","new_quantity":"0.00231588"},{"side":"offer","event_time":"2025-10-27T17:39:42.940692Z","price_level":"115655.72","new_quantity":"0.0000748"},{"side":"offer","event_time":"2025-10-27T17:39:42.940692Z","price_level":"115666.99","new_quantity":"0"},{"side":"offer","event_time":"2025-10-27T17:39:42.940692Z","price_level":"115667","new_quantity":"0"},{"side":"offer","event_time":"2025-10-27T17:39:42.940692Z","price_level":"115667.99","new_quantity":"0"},{"side":"offer","event_time":"2025-10-27T17:39:42.940692Z","price_level":"116324.01","new_quantity":"0.07007"},{"side":"offer","event_time":"2025-10-27T17:39:42.940692Z","price_level":"116967.3","new_quantity":"0.07007"}]}]}
{"channel":"l2_data","client_id":"","timestamp":"2025-10-27T17:39:43.018677254Z","sequence_num":137714,"events":[{"type":"update","product_id":"ETH-USD","updates":[{"side":"offer","event_time":"2025-10-27T17:39:42.972648Z","price_level":"4218.37","new_quantity":"0.2914177"},{"side":"offer","event_time":"2025-10-27T17:39:42.972648Z","price_level":"4221.97","new_quantity":"1.125"}]}]}
{"channel":"l2_data","client_id":"","timestamp":"2025-10-27T17:39:43.046539859Z","sequence_num":137715,"events":[{"type":"update","product_id":"BTC-USD","updates":[{"side":"bid","event_time":"2025-10-27T17:39:42.988733Z","price_level":"115613.03","new_quantity":"0.36492038"},{"side":"bid","event_time":"2025-10-27T17:39:42.988733Z","price_level":"115613.02","new_quantity":"0.33125692"},{"side":"bid","event_time":"2025-10-27T17:39:42.988733Z","price_level":"115613.01","new_quantity":"0"},{"side":"bid","event_time":"2025-10-27T17:39:42.988733Z","price_level":"115613","new_quantity":"0"}]}]}
{"channel":"l2_data","client_id":"","timestamp":"2025-10-27T17:39:43.070663673Z","sequence_num":137716,"events":[{"type":"update","product_id":"ETH-USD","updates":[{"side":"bid","event_time":"2025-10-27T17:39:43.031147Z","price_level":"4217.91","new_quantity":"0.02070633"},{"side":"bid","event_time":"2025-10-27T17:39:43.031147Z","price_level":"4217.83","new_quantity":"0.002"},{"side":"bid","event_time":"2025-10-27T17:39:43.031147Z","price_level":"4169.88","new_quantity":"0"},{"side":"bid","event_time":"2025-10-27T17:39:43.031147Z","price_level":"4149.61","new_quantity":"0"},{"side":"bid","event_time":"2025-10-27T17:39:43.031147Z","price_level":"4129.34","new_quantity":"0"},{"side":"offer","event_time":"2025-10-27T17:39:43.031147Z","price_level":"4220.49","new_quantity":"5.92349217"}]}]}
{"channel":"l2_data","client_id":"","timestamp":"2025-10-27T17:39:43.170912784Z","sequence_num":137719,"events":[{"type":"update","product_id":"ETH-USD","updates":[{"side":"bid","event_time":"2025-10-27T17:39:43.13199Z","price_level":"4216","new_quantity":"54.33492686"},{"side":"bid","event_time":"2025-10-27T17:39:43.13199Z","price_level":"4215.03","new_quantity":"8.84588093"},{"side":"bid","event_time":"2025-10-27T17:39:43.13199Z","price_level":"4215.02","new_quantity":"0"},{"side":"bid","event_time":"2025-10-27T17:39:43.13199Z","price_level":"4215.01","new_quantity":"0"},{"side":"bid","event_time":"2025-10-27T17:39:43.13199Z","price_level":"4214.53","new_quantity":"9.33715171"},{"side":"offer","event_time":"2025-10-27T17:39:43.13199Z","price_level":"4221.85","new_quantity":"9.07707839"}]}]}
{"channel":"l2_data","client_id":"","timestamp":"2025-10-27T17:39:43.269234515Z","sequence_num":137720,"events":[{"type":"update","product_id":"ETH-USD","updates":[{"side":"bid","event_time":"2025-10-27T17:39:43.228366Z","price_level":"4218.01","new_quantity":"0"}]}]}
{"channel":"l2_data","client_id":"","timestamp":"2025-10-27T17:39:43.294255632Z","sequence_num":137721,"events":[{"type":"update","product_id":"BTC-USD","updates":[{"side":"offer","event_time":"2025-10-27T17:39:43.251941Z","price_level":"115666.54","new_quantity":"0.008993"},{"side":"offer","event_time":"2025-10-27T17:39:43.251941Z","price_level":"115674.74","new_quantity":"0"}]}]}
{"channel":"l2_data","client_id":"","timestamp":"2025-10-27T17:39:43.321813316Z","sequence_num":137722,"events":[{"type":"update","product_id":"ETH-USD","updates":[{"side":"bid","event_time":"2025-10-27T17:39:43.284565Z","price_level":"4218.36","new_quantity":"0"},{"side":"bid","event_time":"2025-10-27T17:39:43.284565Z","price_level":"4218.33","new_quantity":"0.01373161"},{"side":"bid","event_time":"2025-10-27T17:39:43.284565Z","price_level":"4218.3","new_quantity":"0.572"},{"side":"bid","event_time":"2025-10-27T17:39:43.284565Z","price_level":"4218.11","new_quantity":"0"},{"side":"bid","event_time":"2025-10-27T17:39:43.284565Z","price_level":"4218.1","new_quantity":"0.572"},{"side":"bid","event_time":"2025-10-27T17:39:43.284565Z","price_level":"4218.02","new_quantity":"0.00237079"},{"side":"bid","event_time":"2025-10-27T17:39:43.284565Z","price_level":"4218.01","new_quantity":"0.70602412"},{"side":"bid","event_time":"2025-10-27T17:39:43.284565Z","price_level":"4217.91","new_quantity":"0"},{"side":"bid","event_time":"2025-10-27T17:39:43.284565Z","price_level":"4217.75","new_quantity":"1.30537337"},{"side":"bid","event_time":"2025-10-27T17:39:43.284565Z","price_level":"4217.37","new_quantity":"0"},{"side":"bid","event_time":"2025-10-27T17:39:43.284565Z","price_level":"4212","new_quantity":"50.02500093"},{"side":"offer","event_time":"2025-10-27T17:39:43.284565Z","price_level":"4218.34","new_quantity":"0.0023705"},{"side":"offer","event_time":"2025-10-27T17:39:43.284565Z","price_level":"4218.37","new_quantity":"0.11852919"},{"side":"offer","event_time":"2025-10-27T17:39:43.284565Z","price_level":"4218.4","new_quantity":"0"},{"side":"offer","event_time":"2025-10-27T17:39:43.284565Z","price_level":"4218.49","new_quantity":"0"},{"side":"offer","event_time":"2025-10-27T17:39:43.284565Z","price_level":"4218.5","new_quantity":"0"},{"side":"offer","event_time":"2025-10-27T17:39:43.284565Z","price_level":"4218.6","new_quantity":"0"},{"side":"offer","event_time":"2025-10-27T17:39:43.284565Z","price_level":"4218.69","new_quantity":"0"},{"side":"offer","event_time":"2025-10-27T17:39:43.284565Z","price_level":"4218.89","new_quantity":"0.01300628"},{"side":"offer","event_time":"2025-10-27T17:39:43.284565Z","price_level":"4219.1","new_quantity":"0"},{"side":"offer","event_time":"2025-10-27T17:39:43.284565Z","price_level":"4219.33","new_quantity":"0.84955428"},{"side":"offer","event_time":"2025-10-27T17:39:43.284565Z","price_level":"4220.37","new_quantity":"8.58814995"},{"side":"offer","event_time":"2025-10-27T17:39:43.284565Z","price_level":"4223.95","new_quantity":"0"},{"side":"offer","event_time":"2025-10-27T17:39:43.284565Z","price_level":"4244.91","new_quantity":"0.1536"}]}]}
62.31","new_quantity":"0"},{"side":"offer","event_time":"2025-10-27T17:39:42.505129Z","price_level":"115667.53","new_quantity":"0.0000748"},{"side":"offer","event_time":"2025-10-27T17:39:42.505129Z","price_level":"115667.54","new_quantity":"0.00507069"},{"side":"offer","event_time":"2025-10-27T17:39:42.505129Z","price_level":"115671","new_quantity":"0"},{"side":"offer","event_time":"2025-10-27T17:39:42.505129Z","price_level":"115693.98","new_quantity":"0"},{"side":"offer","event_time":"2025-10-27T17:39:42.505129Z","price_level":"115697.34","new_quantity":"0.16811848"},{"side":"offer","event_time":"2025-10-27T17:39:42.505129Z","price_level":"115709.99","new_quantity":"0.25116841"},{"side":"offer","event_time":"2025-10-27T17:39:42.505129Z","price_level":"115711.99","new_quantity":"0"},{"side":"offer","event_time":"2025-10-27T17:39:42.505129Z","price_level":"115718.8","new_quantity":"0"},{"side":"offer","event_time":"2025-10-27T17:39:42.505129Z","price_level":"115718.9","new_quantity":"1"}]}]}
{"channel":"l2_data","client_id":"","timestamp":"2025-10-27T17:39:42.691469251Z","sequence_num":137693,"events":[{"type":"update","product_id":"BTC-USD","updates":[{"side":"bid","event_time":"2025-10-27T17:39:42.593514Z","price_level":"115638.01","new_quantity":"0.07739074"},{"side":"bid","event_time":"2025-10-27T17:39:42.593514Z","price_level":"115634.38","new_quantity":"0.00864794"},{"side":"bid","event_time":"2025-10-27T17:39:42.593514Z","price_level":"115633.53","new_quantity":"0"},{"side":"bid","event_time":"2025-10-27T17:39:42.593514Z","price_level":"115621.69","new_quantity":"0"},{"side":"bid","event_time":"2025-10-27T17:39:42.593514Z","price_level":"115618.11","new_quantity":"0"},{"side":"bid","event_time":"2025-10-27T17:39:42.593514Z","price_level":"115615.91","new_quantity":"0.16604"},{"side":"bid","event_time":"2025-10-27T17:39:42.593514Z","price_level":"115608.68","new_quantity":"0"},{"side":"bid","event_time":"2025-10-27T17:39:42.593514Z","price_level":"115596.76","new_quantity":"0.3701011"},{"side":"bid","event_time":"2025-10-27T17:39:42.593514Z","price_level":"115575.34","new_quantity":"0.76389364"},{"side":"bid","event_time":"2025-10-27T17:39:42.593514Z","price_level":"115575.33","new_quantity":"0"},{"side":"bid","event_time":"2025-10-27T17:39:42.593514Z","price_level":"115575.32","new_quantity":"0"},{"side":"bid","event_time":"2025-10-27T17:39:42.593514Z","price_level":"115555.73","new_quantity":"1.442837"},{"side":"bid","event_time":"2025-10-27T17:39:42.593514Z","price_level":"115555.72","new_quantity":"1.20634954"},{"side":"bid","event_time":"2025-10-27T17:39:42.593514Z","price_level":"115555.71","new_quantity":"0"},{"side":"bid","event_time":"2025-10-27T17:39:42.593514Z","price_level":"115555.7","new_quantity":"0"},{"side":"offer","event_time":"2025-10-27T17:39:42.593514Z","price_level":"115667.53","new_quantity":"0"},{"side":"offer","event_time":"2025-10-27T17:39:42.593514Z","price_level":"115667.54","new_quantity":"0"},{"side":"offer","event_time":"2025-10-27T17:39:42.593514Z","price_level":"115667.55","new_quantity":"0"},{"side":"offer","event_time":"2025-10-27T17:39:42.593514Z","price_level":"115670.99","new_quantity":"0.0000748"},{"side":"offer","event_time":"2025-10-27T17:39:42.593514Z","price_level":"115671","new_quantity":"0"},{"side":"offer","event_time":"2025-10-27T17:39:42.593514Z","price_level":"115674.58","new_quantity":"0"},{"side":"offer","event_time":"2025-10-27T17:39:42.593514Z","price_level":"115678.8","new_quantity":"0.01728925"},{"side":"offer","event_time":"2025-10-27T17:39:42.593514Z","price_level":"115687.1","new_quantity":"0.01728801"},{"side":"offer","event_time":"2025-10-27T17:39:42.593514Z","price_level":"115693.98","new_quantity":"0.16812337"},{"side":"offer","event_time":"2025-10-27T17:39:42.593514Z","price_level":"115697.34","new_quantity":"0"},{"side":"offer","event_time":"2025-10-27T17:39:42.593514Z","price_level":"115699.8","new_quantity":"0"},{"side":"offer","event_time":"2025-10-27T17:39:42.593514Z","price_level":"115702.21","new_quantity":"0"},{"side":"offer","event_time":"2025-10-27T17:39:42.593514Z","price_level":"115705.1","new_quantity":"0"},{"side":"offer","event_time":"2025-10-27T17:39:42.593514Z","price_level":"115718.7","new_quantity":"1"},{"side":"offer","event_time":"2025-10-27T17:39:42.593514Z","price_level":"115718.9","new_quantity":"0"}]}]}
{"channel":"l2_data","client_id":"","timestamp":"2025-10-27T17:39:42.697190436Z","sequence_num":137695,"events":[{"type":"update","product_id":"BTC-USD","updates":[{"side":"bid","event_time":"2025-10-27T17:39:42.653908Z","price_level":"115621.69","new_quantity":"0.16604"},{"side":"bid","event_time":"2025-10-27T17:39:42.653908Z","price_level":"115619.06","new_quantity":"0.05"},{"side":"bid","event_time":"2025-10-27T17:39:42.653908Z","price_level":"115613.03","new_quantity":"0"},{"side":"bid","event_time":"2025-10-27T17:39:42.653908Z","price_level":"115613.02","new_quantity":"0"},{"side":"bid","event_time":"2025-10-27T17:39:42.653908Z","price_level":"115611.03","new_quantity":"0.33126262"},{"side":"bid","event_time":"2025-10-27T17:39:42.653908Z","price_level":"115596.8","new_quantity":"0.52639374"},{"side":"bid","event_time":"2025-10-27T17:39:42.653908Z","price_level":"115596.78","new_quantity":"0"},{"side":"bid","event_time":"2025-10-27T17:39:42.653908Z","price_level":"115389.16","new_quantity":"0.07007"},{"side":"bid","event_time":"2025-10-27T17:39:42.653908Z","price_level":"115190.35","new_quantity":"0"},{"side":"bid","event_time":"2025-10-27T17:39:42.653908Z","price_level":"114102.58","new_quantity":"0.07007"},{"side":"offer","event_time":"2025-10-27T17:39:42.653908Z","price_level":"115640.92","new_quantity":"0.0024948"},{"side":"offer","event_time":"2025-10-27T17:39:42.653908Z","price_level":"115670.98","new_quantity":"0.0000748"},{"side":"offer","event_time":"2025-10-27T17:39:42.653908Z","price_level":"115670.99","new_quantity":"0.00615339"},{"side":"offer","event_time":"2025-10-27T17:39:42.653908Z","price_level":"115671","new_quantity":"0"},{"side":"offer","event_time":"2025-10-27T17:39:42.653908Z","price_level":"115674.58","new_quantity":"0"},{"side":"offer","event_time":"2025-10-27T17:39:42.653908Z","price_level":"115718.69","new_quantity":"0.37936315"},{"side":"offer","event_time":"2025-10-27T17:39:42.653908Z","price_level":"115719.94","new_quantity":"0"},{"side":"offer","event_time":"2025-10-27T17:39:42.653908Z","price_level":"116108.32","new_quantity":"0.07007"},{"side":"offer","event_time":"2025-10-27T17:39:42.653908Z","price_level":"116121.72","new_quantity":"0"}]}]}
{"channel":"l2_data","client_id":"","timestamp":"2025-10-27T17:39:43.370361763Z","sequence_num":137725,"events":[{"type":"update","product_id":"ETH-USD","updates":[{"side":"bid","event_time":"2025-10-27T17:39:43.335252Z","price_level":"4218.33","new_quantity":"0.08482478"},{"side":"bid","event_time":"2025-10-27T17:39:43.335252Z","price_level":"4218.27","new_quantity":"0"},{"side":"bid","event_time":"2025-10-27T17:39:43.335252Z","price_level":"4218.02","new_quantity":"0"},{"side":"bid","event_time":"2025-10-27T17:39:43.335252Z","price_level":"4217.84","new_quantity":"0.00237089"},{"side":"bid","event_time":"2025-10-27T17:39:43.335252Z","price_level":"4217.83","new_quantity":"1.65933"},{"side":"bid","event_time":"2025-10-27T17:39:43.335252Z","price_level":"4217.1","new_quantity":"4.485936"},{"side":"offer","event_time":"2025-10-27T17:39:43.335252Z","price_level":"4267.23","new_quantity":"0"},{"side":"offer","event_time":"2025-10-27T17:39:43.335252Z","price_level":"4272.99","new_quantity":"7.23402058"}]}]}
{"channel":"l2_data","client_id":"","timestamp":"2025-10-27T17:39:43.39697352Z","sequence_num":137727,"events":[{"type":"update","product_id":"BTC-USD","updates":[{"side":"bid","event_time":"2025-10-27T17:39:43.337985Z","price_level":"115556.63","new_quantity":"0.00907341"},{"side":"bid","event_time":"2025-10-27T17:39:43.337985Z","price_level":"115556.62","new_quantity":"0.01519835"},{"side":"bid","event_time":"2025-10-27T17:39:43.337985Z","price_level":"115555.69","new_quantity":"0"},{"side":"bid","event_time":"2025-10-27T17:39:43.337985Z","price_level":"115555.68","new_quantity":"0"},{"side":"bid","event_time":"2025-10-27T17:39:43.337985Z","price_level":"115552.27","new_quantity":"0"},{"side":"offer","event_time":"2025-10-27T17:39:43.337985Z","price_level":"115649.04","new_quantity":"0"},{"side":"offer","event_time":"2025-10-27T17:39:43.337985Z","price_level":"115655.72","new_quantity":"0"},{"side":"offer","event_time":"2025-10-27T17:39:43.337985Z","price_level":"115661.56","new_quantity":"0.00007464"},{"side":"offer","event_time":"2025-10-27T17:39:43.337985Z","price_level":"115667","new_quantity":"2"},{"side":"offer","event_time":"2025-10-27T17:39:43.337985Z","price_level":"115693.99","new_quantity":"0.24461981"},{"side":"offer","event_time":"2025-10-27T17:39:43.337985Z","price_level":"115704.99","new_quantity":"0"},{"side":"offer","event_time":"2025-10-27T17:39:43.337985Z","price_level":"115798.75","new_quantity":"0"}]}]}
{"channel":"l2_data","client_id":"","timestamp":"2025-10-27T17:39:43.418711099Z","sequence_num":137728,"events":[{"type":"update","product_id":"ETH-USD","updates":[{"side":"offer","event_time":"2025-10-27T17:39:43.373158Z","price_level":"4218.37","new_quantity":"0"}]}]}
{"channel":"l2_data","client_id":"","timestamp":"2025-10-27T17:39:43.352480978Z","sequence_num":137724,"events":[{"type":"update","product_id":"BTC-USD","updates":[{"side":"bid","event_time":"2025-10-27T17:39:43.311091Z","price_level":"115649.02","new_quantity":"0.06012247"},{"side":"bid","event_time":"2025-10-27T17:39:43.311091Z","price_level":"115646","new_quantity":"0"},{"side":"bid","event_time":"2025-10-27T17:39:43.311091Z","price_level":"115644.49","new_quantity":"0"},{"side":"bid","event_time":"2025-10-27T17:39:43.311091Z","price_level":"115644","new_quantity":"0.0224"},{"side":"bid","event_time":"2025-10-27T17:39:43.311091Z","price_level":"115642","new_quantity":"0.0224"},{"side":"bid","event_time":"2025-10-27T17:39:43.311091Z","price_level":"115640.92","new_quantity":"0"},{"side":"bid","event_time":"2025-10-27T17:39:43.311091Z","price_level":"115640.91","new_quantity":"0.02595589"},{"side":"bid","event_time":"2025-10-27T17:39:43.311091Z","price_level":"115640.01","new_quantity":"0"},{"side":"bid","event_time":"2025-10-27T17:39:43.311091Z","price_level":"115638.61","new_quantity":"0.00172952"},{"side":"bid","event_time":"2025-10-27T17:39:43.311091Z","price_level":"115638.6","new_quantity":"0.0097207"},{"side":"bid","event_time":"2025-10-27T17:39:43.311091Z","price_level":"115638.11","new_quantity":"0.00259725"},{"side":"bid","event_time":"2025-10-27T17:39:43.311091Z","price_level":"115637.37","new_quantity":"0.00864772"},{"side":"bid","event_time":"2025-10-27T17:39:43.311091Z","price_level":"115635.9","new_quantity":"0"},{"side":"bid","event_time":"2025-10-27T17:39:43.311091Z","price_level":"115634.38","new_quantity":"0"},{"side":"bid","event_time":"2025-10-27T17:39:43.311091Z","price_level":"115633.87","new_quantity":"0.24890232"},{"side":"bid","event_time":"2025-10-27T17:39:43.311091Z","price_level":"115632.92","new_quantity":"0.1425"},{"side":"bid","event_time":"2025-10-27T17:39:43.311091Z","price_level":"115631.05","new_quantity":"0.16588"},{"side":"bid","event_time":"2025-10-27T17:39:43.311091Z","price_level":"115628.24","new_quantity":"0.00432"},{"side":"bid","event_time":"2025-10-27T17:39:43.311091Z","price_level":"115624.74","new_quantity":"0.01005257"},{"side":"bid","event_time":"2025-10-27T17:39:43.311091Z","price_level":"115615.3","new_quantity":"0.011241"},{"side":"bid","event_time":"2025-10-27T17:39:43.311091Z","price_level":"115613.09","new_quantity":"0.36492028"},{"side":"bid","event_time":"2025-10-27T17:39:43.311091Z","price_level":"115613.08","new_quantity":"0.33125675"},{"side":"bid","event_time":"2025-10-27T17:39:43.311091Z","price_level":"115613.03","new_quantity":"0"},{"side":"bid","event_time":"2025-10-27T17:39:43.311091Z","price_level":"115613.02","new_quantity":"0"},{"side":"bid","event_time":"2025-10-27T17:39:43.311091Z","price_level":"115609.08","new_quantity":"0.37002703"},{"side":"bid","event_time":"2025-10-27T17:39:43.311091Z","price_level":"115606.8","new_quantity":"0"},{"side":"bid","event_time":"2025-10-27T17:39:43.311091Z","price_level":"115605.45","new_quantity":"0.04184849"},{"side":"bid","event_time":"2025-10-27T17:39:43.311091Z","price_level":"115605.44","new_quantity":"0.07007"},{"side":"bid","event_time":"2025-10-27T17:39:43.311091Z","price_level":"115605.26","new_quantity":"0"},{"side":"bid","event_time":"2025-10-27T17:39:43.311091Z","price_level":"115605.25","new_quantity":"0"},{"side":"bid","event_time":"2025-10-27T17:39:43.311091Z","price_level":"115604.85","new_quantity":"0"},{"side":"bid","event_time":"2025-10-27T17:39:43.311091Z","price_level":"115596.85","new_quantity":"0.9246106"},{"side":"bid","event_time":"2025-10-27T17:39:43.311091Z","price_level":"115596.84","new_quantity":"0.52639355"},{"side":"bid","event_time":"2025-10-27T17:39:43.311091Z","price_level":"115596.8","new_quantity":"0"},{"side":"bid","event_time":"2025-10-27T17:39:43.311091Z","price_level":"115596.79","new_quantity":"0"},{"side":"bid","event_time":"2025-10-27T17:39:43.311091Z","price_level":"115596.76","new_quantity":"0"},{"side":"bid","event_time":"2025-10-27T17:39:43.311091Z","price_level":"115575.8","new_quantity":"1.35984273"},{"side":"bid","event_time":"2025-10-27T17:39:43.311091Z","price_level":"115575.79","new_quantity":"0.76389067"},{"side":"bid","event_time":"2025-10-27T17:39:43.311091Z","price_level":"115575.74","new_quantity":"0"},{"side":"bid","event_time":"2025-10-27T17:39:43.311091Z","price_level":"115575.73","new_quantity":"0"},{"side":"bid","event_time":"2025-10-27T17:39:43.311091Z","price_level":"115564.89","new_quantity":"0.74589253"},{"side":"bid","event_time":"2025-10-27T17:39:43.311091Z","price_level":"115561.01","new_quantity":"1.20629431"},{"side":"bid","event_time":"2025-10-27T17:39:43.311091Z","price_level":"115555.76","new_quantity":"0"},{"side":"bid","event_time":"2025-10-27T17:39:43.311091Z","price_level":"115555.69","new_quantity":"0.72264632"},{"side":"bid","event_time":"2025-10-27T17:39:43.311091Z","price_level":"115538.63","new_quantity":"0.09539642"},{"side":"bid","event_time":"2025-10-27T17:39:43.311091Z","price_level":"115538.62","new_quantity":"0"},{"side":"bid","event_time":"2025-10-27T17:39:43.311091Z","price_level":"115507","new_quantity":"0.506348"},{"side":"bid","event_time":"2025-10-27T17:39:43.311091Z","price_level":"115504.63","new_quantity":"1.29326402"},{"side":"bid","event_time":"2025-10-27T17:39:43.311091Z","price_level":"115500.25","new_quantity":"0.045"},{"side":"bid","event_time":"2025-10-27T17:39:43.311091Z","price_level":"115499.01","new_quantity":"0"},{"side":"bid","event_time":"2025-10-27T17:39:43.311091Z","price_level":"115493.02","new_quantity":"0"},{"side":"bid","event_time":"2025-10-27T17:39:43.311091Z","price_level":"115489.65","new_quantity":"0"},{"side":"bid","event_time":"2025-10-27T17:39:43.311091Z","price_level":"115481.97","new_quantity":"0"},{"side":"bid","event_time":"2025-10-27T17:39:43.311091Z","price_level":"115439.77","new_quantity":"4.956685"},{"side":"bid","event_time":"2025-10-27T17:39:43.311091Z","price_level":"115390.45","new_quantity":"0.07007"},{"side":"bid","event_time":"2025-10-27T17:39:43.311091Z","price_level":"115389.16","new_quantity":"0"},{"side":"bid","event_time":"2025-10-27T17:39:43.311091Z","price_level":"115223.76","new_quantity":"0"},{"side":"bid","event_time":"2025-10-27T17:39:43.311091Z","price_level":"115154.1","new_quantity":"6.92125"},{"side":"bid","event_time":"2025-10-27T17:39:43.311091Z","price_level":"114921.99","new_quantity":"0.045"},{"side":"offer","event_time":"2025-10-27T17:39:43.311091Z","price_level":"115640.92","new_quantity":"0"},{"side":"offer","event_time":"2025-10-27T17:39:43.311091Z","price_level":"115643.37","new_quantity":"0"},{"side":"offer","event_time":"2025-10-27T17:39:43.311091Z","price_level":"115644.5","new_quantity":"0"},{"side":"offer","event_time":"2025-10-27T17:39:43.311091Z","price_level":"115646.23","new_quantity":"0"},{"side":"offer","event_time":"2025-10-27T17:39:43.311091Z","price_level":"115649.03","new_quantity":"0.23730852"},{"side":"offer","event_time":"2025-10-27T17:39:43.311091Z","price_level":"115649.04","new_quantity":"0.0031836"},{"side":"offer","event_time":"2025-10-27T17:39:43.311091Z","price_level":"115649.06","new_quantity":"0"},{"side":"offer","event_time":"2025-10-27T17:39:43.311091Z","price_level":"115649.07","new_quantity":"0"},{"side":"offer","event_time":"2025-10-27T17:39:43.311091Z","price_level":"115655.72","new_quantity":"0.00007464"},{"side":"offer","event_time":"2025-10-27T17:39:43.311091Z","price_level":"115663","new_quantity":"0.00432"},{"side":"offer","event_time":"2025-10-27T17:39:43.311091Z","price_level":"115663.01","new_quantity":"0.00432"},{"side":"offer","event_time":"2025-10-27T17:39:43.311091Z","price_level":"115665.32","new_quantity":"0.00432"},{"side":"offer","event_time":"2025-10-27T17:39:43.311091Z","price_level":"115667","new_quantity":"0"},{"side":"offer","event_time":"2025-10-27T17:39:43.311091Z","price_level":"115667.99","new_quantity":"1.20837367"},{"side":"offer","event_time":"2025-10-27T17:39:43.311091Z","price_level":"115671","new_quantity":"0.07164597"},{"side":"offer","event_time":"2025-10-27T17:39:43.311091Z","price_level":"115674.59","new_quantity":"0"},{"side":"offer","event_time":"2025-10-27T17:39:43.311091Z","price_level":"115675.58","new_quantity":"0.13835219"},{"side":"offer","event_time":"2025-10-27T17:39:43.311091Z","price_level":"115675.59","new_quantity":"0.40411517"},{"side":"offer","event_time":"2025-10-27T17:39:43.311091Z","price_level":"115675.6","new_quantity":"0"},{"side":"offer","event_time":"2025-10-27T17:39:43.311091Z","price_level":"115675.79","new_quantity":"0"},{"side":"offer","event_time":"2025-10-27T17:39:43.311091Z","price_level":"115680","new_quantity":"0.0069609"},{"side":"offer","event_time":"2025-10-27T17:39:43.311091Z","price_level":"115681.3","new_quantity":"0.50155403"},{"side":"offer","event_time":"2025-10-27T17:39:43.311091Z","price_level":"115681.31","new_quantity":"0.840114"},{"side":"offer","event_time":"2025-10-27T17:39:43.311091Z","price_level":"115686.99","new_quantity":"0.1176713"},{"side":"offer","event_time":"2025-10-27T17:39:43.311091Z","price_level":"115693.98","new_quantity":"0"},{"side":"offer","event_time":"2025-10-27T17:39:43.311091Z","price_level":"115697.34","new_quantity":"0.16811848"},{"side":"offer","event_time":"2025-10-27T17:39:43.311091Z","price_level":"115699.99","new_quantity":"0"},{"side":"offer","event_time":"2025-10-27T17:39:43.311091Z","price_level":"115709.99","new_quantity":"0"},{"side":"offer","event_time":"2025-10-27T17:39:43.311091Z","price_level":"115713.38","new_quantity":"0.25116106"},{"side":"offer","event_time":"2025-10-27T17:39:43.311091Z","price_level":"115718.69","new_quantity":"0"},{"side":"offer","event_time":"2025-10-27T17:39:43.311091Z","price_level":"115727.1","new_quantity":"0.37933559"},{"side":"offer","event_time":"2025-10-27T17:39:43.311091Z","price_level":"115727.11","new_quantity":"0"},{"side":"offer","event_time":"2025-10-27T17:39:43.311091Z","price_level":"115735.11","new_quantity":"0.57744092"},{"side":"offer","event_time":"2025-10-27T17:39:43.311091Z","price_level":"116323.56","new_quantity":"0.07007"},{"side":"offer","event_time":"2025-10-27T17:39:43.311091Z","price_level":"116324.01","new_quantity":"0"},{"side":"offer","event_time":"2025-10-27T17:39:43.311091Z","price_level":"116336.3","new_quantity":"0"},{"side":"offer","event_time":"2025-10-27T17:39:43.311091Z","price_level":"116538.23","new_quantity":"0.07007"},{"side":"offer","event_time":"2025-10-27T17:39:43.311091Z","price_level":"116551.18","new_quantity":"0"},{"side":"offer","event_time":"2025-10-27T17:39:43.311091Z","price_level":"116752.66","new_quantity":"0.07007"},{"side":"offer","event_time":"2025-10-27T17:39:43.311091Z","price_level":"116967.14","new_quantity":"0.07007"},{"side":"offer","event_time":"2025-10-27T17:39:43.311091Z","price_level":"116967.3","new_quantity":"0"}]}]}
{"channel":"l2_data","client_id":"","timestamp":"2025-10-27T17:39:43.447713957Z","sequence_num":137730,"events":[{"type":"update","product_id":"BTC-USD","updates":[{"side":"bid","event_time":"2025-10-27T17:39:43.393902Z","price_level":"115621.69","new_quantity":"0"},{"side":"bid","event_time":"2025-10-27T17:39:43.393902Z","price_level":"115619.97","new_quantity":"0.33123701"},{"side":"bid","event_time":"2025-10-27T17:39:43.393902Z","price_level":"115613.09","new_quantity":"0"},{"side":"bid","event_time":"2025-10-27T17:39:43.393902Z","price_level":"115613.08","new_quantity":"0"},{"side":"bid","event_time":"2025-10-27T17:39:43.393902Z","price_level":"115611.02","new_quantity":"0"},{"side":"bid","event_time":"2025-10-27T17:39:43.393902Z","price_level":"115607.76","new_quantity":"0.07007"},{"side":"bid","event_time":"2025-10-27T17:39:43.393902Z","price_level":"115607.74","new_quantity":"0"},{"side":"bid","event_time":"2025-10-27T17:39:43.393902Z","price_level":"115605.46","new_quantity":"0.5263543"},{"side":"bid","event_time":"2025-10-27T17:39:43.393902Z","price_level":"115605.45","new_quantity":"0"},{"side":"bid","event_time":"2025-10-27T17:39:43.393902Z","price_level":"115605.44","new_quantity":"0"},{"side":"bid","event_time":"2025-10-27T17:39:43.393902Z","price_level":"115596.85","new_quantity":"0.61035365"},{"side":"bid","event_time":"2025-10-27T17:39:43.393902Z","price_level":"115596.84","new_quantity":"0"},{"side":"bid","event_time":"2025-10-27T17:39:43.393902Z","price_level":"115588.24","new_quantity":"0.60727261"},{"side":"bid","event_time":"2025-10-27T17:39:43.393902Z","price_level":"115585.63","new_quantity":"0.76382564"},{"side":"bid","event_time":"2025-10-27T17:39:43.393902Z","price_level":"115575.8","new_quantity":"0.9038"},{"side":"bid","event_time":"2025-10-27T17:39:43.393902Z","price_level":"115575.79","new_quantity":"0"},{"side":"bid","event_time":"2025-10-27T17:39:43.393902Z","price_level":"115564.9","new_quantity":"1.20625371"},{"side":"bid","event_time":"2025-10-27T17:39:43.393902Z","price_level":"115564.89","new_quantity":"0"},{"side":"bid","event_time":"2025-10-27T17:39:43.393902Z","price_level":"115561.01","new_quantity":"0"},{"side":"bid","event_time":"2025-10-27T17:39:43.393902Z","price_level":"114921.99","new_quantity":"0"},{"side":"bid","event_time":"2025-10-27T17:39:43.393902Z","price_level":"114106.73","new_quantity":"0"},{"side":"offer","event_time":"2025-10-27T17:39:43.393902Z","price_level":"115667","new_quantity":"0"},{"side":"offer","event_time":"2025-10-27T17:39:43.393902Z","price_level":"115680","new_quantity":"0"},{"side":"offer","event_time":"2025-10-27T17:39:43.393902Z","price_level":"115697.34","new_quantity":"0"},{"side":"offer","event_time":"2025-10-27T17:39:43.393902Z","price_level":"115699.99","new_quantity":"0.16811463"},{"side":"offer","event_time":"2025-10-27T17:39:43.393902Z","price_level":"115718.9","new_quantity":"0"},{"side":"offer","event_time":"2025-10-27T17:39:43.393902Z","price_level":"115719","new_quantity":"1"},{"side":"offer","event_time":"2025-10-27T17:39:43.393902Z","price_level":"115834.3","new_quantity":"0"},{"side":"offer","event_time":"2025-10-27T17:39:43.393902Z","price_level":"115956.53","new_quantity":"0"},{"side":"offer","event_time":"2025-10-27T17:39:43.393902Z","price_level":"116049.28","new_quantity":"0"}]}]}
{"channel":"l2_data","client_id":"","timestamp":"2025-10-27T17:39:43.47093355Z","sequence_num":137731,"events":[{"type":"update","product_id":"ETH-USD","updates":[{"side":"bid","event_time":"2025-10-27T17:39:43.409138Z","price_level":"4218.11","new_quantity":"0.00237074"},{"side":"bid","event_time":"2025-10-27T17:39:43.409138Z","price_level":"4218.05","new_quantity":"0.11853817"},{"side":"bid","event_time":"2025-10-27T17:39:43.409138Z","price_level":"4218.02","new_quantity":"0"},{"side":"bid","event_time":"2025-10-27T17:39:43.409138Z","price_level":"4217.88","new_quantity":"0"},{"side":"bid","event_time":"2025-10-27T17:39:43.409138Z","price_level":"4217.84","new_quantity":"0"},{"side":"bid","event_time":"2025-10-27T17:39:43.409138Z","price_level":"4217.61","new_quantity":"31.30634237"},{"side":"bid","event_time":"2025-10-27T17:39:43.409138Z","price_level":"4217.51","new_quantity":"5.77952084"},{"side":"bid","event_time":"2025-10-27T17:39:43.409138Z","price_level":"4217.44","new_quantity":"0"},{"side":"bid","event_time":"2025-10-27T17:39:43.409138Z","price_level":"4217.1","new_quantity":"0"},{"side":"bid","event_time":"2025-10-27T17:39:43.409138Z","price_level":"4215.14","new_quantity":"8.12983895"},{"side":"bid","event_time":"2025-10-27T17:39:43.409138Z","price_level":"4215.03","new_quantity":"0"},{"side":"offer","event_time":"2025-10-27T17:39:43.409138Z","price_level":"4218.53","new_quantity":"0.11852481"}]}]}
{"channel":"l2_data","client_id":"","timestamp":"2025-10-27T17:39:43.497651267Z","sequence_num":137732,"events":[{"type":"update","product_id":"BTC-USD","updates":[{"side":"bid","event_time":"2025-10-27T17:39:43.442476Z","price_level":"115555.82","new_quantity":"0.00043229"},{"side":"bid","event_time":"2025-10-27T17:39:43.442476Z","price_level":"115550.44","new_quantity":"0"},{"side":"bid","event_time":"2025-10-27T17:39:43.442476Z","price_level":"115538.64","new_quantity":"0.00043229"},{"side":"bid","event_time":"2025-10-27T17:39:43.442476Z","price_level":"115534.45","new_quantity":"0"},{"side":"bid","event_time":"2025-10-27T17:39:43.442476Z","price_level":"115528.92","new_quantity":"0.00001"},{"side":"bid","event_time":"2025-10-27T17:39:43.442476Z","price_level":"101192.9","new_quantity":"0.0049568"},{"side":"offer","event_time":"2025-10-27T17:39:43.442476Z","price_level":"115649.03","new_quantity":"0.24036052"},{"side":"offer","event_time":"2025-10-27T17:39:43.442476Z","price_level":"115705.94","new_quantity":"0"},{"side":"offer","event_time":"2025-10-27T17:39:43.442476Z","price_level":"115711.98","new_quantity":"0"},{"side":"offer","event_time":"2025-10-27T17:39:43.442476Z","price_level":"115715.59","new_quantity":"0"},{"side":"offer","event_time":"2025-10-27T17:39:43.442476Z","price_level":"116132.57","new_quantity":"0"},{"side":"offer","event_time":"2025-10-27T17:39:43.442476Z","price_level":"116223.96","new_quantity":"0"},{"side":"offer","event_time":"2025-10-27T17:39:43.442476Z","price_level":"116323.46","new_quantity":"0"},{"side":"offer","event_time":"2025-10-27T17:39:43.442476Z","price_level":"116546.87","new_quantity":"0"}]}]}
{"channel":"l2_data","client_id":"","timestamp":"2025-10-27T17:39:43.52070434Z","sequence_num":137733,"events":[{"type":"update","product_id":"ETH-USD","updates":[{"side":"bid","event_time":"2025-10-27T17:39:43.488473Z","price_level":"4217.51","new_quantity":"0"},{"side":"bid","event_time":"2025-10-27T17:39:43.488473Z","price_level":"4217.44","new_quantity":"5.77961676"},{"side":"bid","event_time":"2025-10-27T17:39:43.488473Z","price_level":"4216.35","new_quantity":"2.37064754"},{"side":"offer","event_time":"2025-10-27T17:39:43.488473Z","price_level":"4218.6","new_quantity":"0.572"},{"side":"offer","event_time":"2025-10-27T17:39:43.488473Z","price_level":"4218.62","new_quantity":"0.06413341"},{"side":"offer","event_time":"2025-10-27T17:39:43.488473Z","price_level":"4219.83","new_quantity":"1.19960242"},{"side":"offer","event_time":"2025-10-27T17:39:43.488473Z","price_level":"4261.97","new_quantity":"0"},{"side":"offer","event_time":"2025-10-27T17:39:43.488473Z","price_level":"4272.15","new_quantity":"0.03583719"}]}]}
{"channel":"l2_data","client_id":"","timestamp":"2025-10-27T17:39:43.547737882Z","sequence_num":137734,"events":[{"type":"update","product_id":"BTC-USD","updates":[{"side":"bid","event_time":"2025-10-27T17:39:43.49435Z","price_level":"115605.46","new_quantity":"0"},{"side":"bid","event_time":"2025-10-27T17:39:43.49435Z","price_level":"115596.86","new_quantity":"0.52639346"},{"side":"bid","event_time":"2025-10-27T17:39:43.49435Z","price_level":"115596.85","new_quantity":"0"},{"side":"offer","event_time":"2025-10-27T17:39:43.49435Z","price_level":"115649.03","new_quantity":"0.2393103"},{"side":"offer","event_time":"2025-10-27T17:39:43.49435Z","price_level":"115667","new_quantity":"2"},{"side":"offer","event_time":"2025-10-27T17:39:43.49435Z","price_level":"115668.52","new_quantity":"0"},{"side":"offer","event_time":"2025-10-27T17:39:43.49435Z","price_level":"115681.3","new_quantity":"0"},{"side":"offer","event_time":"2025-10-27T17:39:43.49435Z","price_level":"115681.31","new_quantity":"0"},{"side":"offer","event_time":"2025-10-27T17:39:43.49435Z","price_level":"115800.84","new_quantity":"0.00001"},{"side":"offer","event_time":"2025-10-27T17:39:43.49435Z","price_level":"116101.27","new_quantity":"0.0310153"},{"side":"offer","event_time":"2025-10-27T17:39:43.49435Z","price_level":"116223.96","new_quantity":"0.06589319"},{"side":"offer","event_time":"2025-10-27T17:39:43.49435Z","price_level":"116313.71","new_quantity":"0.08308435"},{"side":"offer","event_time":"2025-10-27T17:39:43.49435Z","price_level":"116421.33","new_quantity":"0.06362757"},{"side":"offer","event_time":"2025-10-27T17:39:43.49435Z","price_level":"116431.09","new_quantity":"0"},{"side":"offer","event_time":"2025-10-27T17:39:43.49435Z","price_level":"116537.11","new_quantity":"0.08449232"},{"side":"offer","event_time":"2025-10-27T17:39:43.49435Z","price_level":"116639.09","new_quantity":"0"},{"side":"offer","event_time":"2025-10-27T17:39:43.49435Z","price_level":"116735.92","new_quantity":"0"},{"side":"offer","event_time":"2025-10-27T17:39:43.49435Z","price_level":"116827.58","new_quantity":"0.04827968"},{"side":"offer","event_time":"2025-10-27T17:39:43.49435Z","price_level":"116834.25","new_quantity":"0"},{"side":"offer","event_time":"2025-10-27T17:39:43.49435Z","price_level":"116998.99","new_quantity":"0"},{"side":"offer","event_time":"2025-10-27T17:39:43.49435Z","price_level":"117135.45","new_quantity":"0.00130703"}]}]}
{"channel":"l2_data","client_id":"","timestamp":"2025-10-27T17:39:43.569235926Z","sequence_num":137735,"events":[{"type":"update","product_id":"ETH-USD","updates":[{"side":"bid","event_time":"2025-10-27T17:39:43.53543Z","price_level":"4216.74","new_quantity":"0.46150581"},{"side":"bid","event_time":"2025-10-27T17:39:43.53543Z","price_level":"4216.35","new_quantity":"0"}]}]}
{"channel":"l2_data","client_id":"","timestamp":"2025-10-27T17:39:43.599120268Z","sequence_num":137737,"events":[{"type":"update","product_id":"BTC-USD","updates":[{"side":"bid","event_time":"2025-10-27T17:39:43.541505Z","price_level":"115646","new_quantity":"0.0224"},{"side":"offer","event_time":"2025-10-27T17:39:43.541505Z","price_level":"115661.56","new_quantity":"0"},{"side":"offer","event_time":"2025-10-27T17:39:43.541505Z","price_level":"115663","new_quantity":"0"},{"side":"offer","event_time":"2025-10-27T17:39:43.541505Z","price_level":"115663.01","new_quantity":"0"},{"side":"offer","event_time":"2025-10-27T17:39:43.541505Z","price_level":"115665.31","new_quantity":"0.00007468"},{"side":"offer","event_time":"2025-10-27T17:39:43.541505Z","price_level":"115665.33","new_quantity":"0.00432"},{"side":"offer","event_time":"2025-10-27T17:39:43.541505Z","price_level":"115667","new_quantity":"2"},{"side":"offer","event_time":"2025-10-27T17:39:43.541505Z","price_level":"115686.99","new_quantity":"0.34235747"},{"side":"offer","event_time":"2025-10-27T17:39:43.541505Z","price_level":"115799.09","new_quantity":"0.0310153"},{"side":"offer","event_time":"2025-10-27T17:39:43.541505Z","price_level":"115838.14","new_quantity":"0.06589319"},{"side":"offer","event_time":"2025-10-27T17:39:43.541505Z","price_level":"115929.79","new_quantity":"0.08308435"},{"side":"offer","event_time":"2025-10-27T17:39:43.541505Z","price_level":"116039.57","new_quantity":"0.06362757"},{"side":"offer","event_time":"2025-10-27T17:39:43.541505Z","price_level":"116101.27","new_quantity":"0"},{"side":"offer","event_time":"2025-10-27T17:39:43.541505Z","price_level":"116223.96","new_quantity":"0.08449232"},{"side":"offer","event_time":"2025-10-27T17:39:43.541505Z","price_level":"116313.71","new_quantity":"0"},{"side":"offer","event_time":"2025-10-27T17:39:43.541505Z","price_level":"116421.33","new_quantity":"0"},{"side":"offer","event_time":"2025-10-27T17:39:43.541505Z","price_level":"116537.11","new_quantity":"0"},{"side":"offer","event_time":"2025-10-27T17:39:43.541505Z","price_level":"116693.35","new_quantity":"0.07081819"}]}]}
{"channel":"l2_data","client_id":"","timestamp":"2025-10-27T17:39:43.621328681Z","sequence_num":137738,"events":[{"type":"update","product_id":"ETH-USD","updates":[{"side":"bid","event_time":"2025-10-27T17:39:43.57741Z","price_level":"4218.33","new_quantity":"0.01373161"},{"side":"bid","event_time":"2025-10-27T17:39:43.57741Z","price_level":"4218.3","new_quantity":"0"},{"side":"bid","event_time":"2025-10-27T17:39:43.57741Z","price_level":"4218.11","new_quantity":"0"},{"side":"bid","event_time":"2025-10-27T17:39:43.57741Z","price_level":"4218.1","new_quantity":"0"},{"side":"bid","event_time":"2025-10-27T17:39:43.57741Z","price_level":"4218.02","new_quantity":"0.00237079"},{"side":"bid","event_time":"2025-10-27T17:39:43.57741Z","price_level":"4218.01","new_quantity":"0"},{"side":"bid","event_time":"2025-10-27T17:39:43.57741Z","price_level":"4218","new_quantity":"0.001"},{"side":"bid","event_time":"2025-10-27T17:39:43.57741Z","price_level":"4217.83","new_quantity":"0.002"},{"side":"bid","event_time":"2025-10-27T17:39:43.57741Z","price_level":"4216.74","new_quantity":"2.8321481"},{"side":"offer","event_time":"2025-10-27T17:39:43.57741Z","price_level":"4218.34","new_quantity":"0.17188848"},{"side":"offer","event_time":"2025-10-27T17:39:43.57741Z","price_level":"4218.4","new_quantity":"0.572"},{"side":"offer","event_time":"2025-10-27T17:39:43.57741Z","price_level":"4218.5","new_quantity":"0.572"},{"side":"offer","event_time":"2025-10-27T17:39:43.57741Z","price_level":"4219.1","new_quantity":"0.01508562"}]}]}
ffer","event_time":"2025-10-27T17:39:43.638988Z","price_level":"115719","new_quantity":"0"}]}]}
{"channel":"l2_data","client_id":"","timestamp":"2025-10-27T17:39:43.720620362Z","sequence_num":137744,"events":[{"type":"update","product_id":"ETH-USD","updates":[{"side":"bid","event_time":"2025-10-27T17:39:43.687757Z","price_level":"4218.32","new_quantity":"1.07972241"},{"side":"bid","event_time":"2025-10-27T17:39:43.687757Z","price_level":"4218.1","new_quantity":"0.572"},{"side":"bid","event_time":"2025-10-27T17:39:43.687757Z","price_level":"4217.6","new_quantity":"31.65733"},{"side":"bid","event_time":"2025-10-27T17:39:43.687757Z","price_level":"4216.79","new_quantity":"0"},{"side":"offer","event_time":"2025-10-27T17:39:43.687757Z","price_level":"4218.33","new_quantity":"0.50634758"}]}]}
{"channel":"l2_data","client_id":"","timestamp":"2025-10-27T17:39:43.749344275Z","sequence_num":137745,"events":[{"type":"update","product_id":"BTC-USD","updates":[{"side":"bid","event_time":"2025-10-27T17:39:43.696849Z","price_level":"115640.91","new_quantity":"0.02176268"},{"side":"bid","event_time":"2025-10-27T17:39:43.696849Z","price_level":"115640","new_quantity":"0.0224"},{"side":"bid","event_time":"2025-10-27T17:39:43.696849Z","price_level":"115633.06","new_quantity":"0.01232665"},{"side":"bid","event_time":"2025-10-27T17:39:43.696849Z","price_level":"115630.23","new_quantity":"0"},{"side":"bid","event_time":"2025-10-27T17:39:43.696849Z","price_level":"115628.37","new_quantity":"0.02161063"},{"side":"bid","event_time":"2025-10-27T17:39:43.696849Z","price_level":"115627.31","new_quantity":"0.00066371"},{"side":"bid","event_time":"2025-10-27T17:39:43.696849Z","price_level":"115621.7","new_quantity":"0.16588"},{"side":"bid","event_time":"2025-10-27T17:39:43.696849Z","price_level":"115616.01","new_quantity":"0"},{"side":"bid","event_time":"2025-10-27T17:39:43.696849Z","price_level":"115612.97","new_quantity":"0"},{"side":"bid","event_time":"2025-10-27T17:39:43.696849Z","price_level":"115611.02","new_quantity":"0.33126265"},{"side":"bid","event_time":"2025-10-27T17:39:43.696849Z","price_level":"115611.01","new_quantity":"0"},{"side":"bid","event_time":"2025-10-27T17:39:43.696849Z","price_level":"115611","new_quantity":"0"},{"side":"bid","event_time":"2025-10-27T17:39:43.696849Z","price_level":"115609.09","new_quantity":"0"},{"side":"bid","event_time":"2025-10-27T17:39:43.696849Z","price_level":"115596.9","new_quantity":"0.52640328"},{"side":"bid","event_time":"2025-10-27T17:39:43.696849Z","price_level":"115596.88","new_quantity":"0"},{"side":"bid","event_time":"2025-10-27T17:39:43.696849Z","price_level":"115580.02","new_quantity":"0"},{"side":"bid","event_time":"2025-10-27T17:39:43.696849Z","price_level":"115575.81","new_quantity":"0.76389054"},{"side":"bid","event_time":"2025-10-27T17:39:43.696849Z","price_level":"115575.8","new_quantity":"0"},{"side":"bid","event_time":"2025-10-27T17:39:43.696849Z","price_level":"115408.99","new_quantity":"0.02770943"},{"side":"bid","event_time":"2025-10-27T17:39:43.696849Z","price_level":"115330.94","new_quantity":"0"},{"side":"offer","event_time":"2025-10-27T17:39:43.696849Z","price_level":"115640.92","new_quantity":"0.003066"},{"side":"offer","event_time":"2025-10-27T17:39:43.696849Z","price_level":"115642.02","new_quantity":"0"},{"side":"offer","event_time":"2025-10-27T17:39:43.696849Z","price_level":"115647.51","new_quantity":"0.00355991"},{"side":"offer","event_time":"2025-10-27T17:39:43.696849Z","price_level":"115654.65","new_quantity":"0.02595356"},{"side":"offer","event_time":"2025-10-27T17:39:43.696849Z","price_level":"115661.57","new_quantity":"0.09023058"},{"side":"offer","event_time":"2025-10-27T17:39:43.696849Z","price_level":"115661.87","new_quantity":"0"},{"side":"offer","event_time":"2025-10-27T17:39:43.696849Z","price_level":"115667","new_quantity":"0"},{"side":"offer","event_time":"2025-10-27T17:39:43.696849Z","price_level":"115686.99","new_quantity":"0.1176713"},{"side":"offer","event_time":"2025-10-27T17:39:43.696849Z","price_level":"115689.73","new_quantity":"0.16812954"},{"side":"offer","event_time":"2025-10-27T17:39:43.696849Z","price_level":"115697.34","new_quantity":"0"},{"side":"offer","event_time":"2025-10-27T17:39:43.696849Z","price_level":"115707.06","new_quantity":"0.25117477"},{"side":"offer","event_time":"2025-10-27T17:39:43.696849Z","price_level":"115710","new_quantity":"5.4000267"},{"side":"offer","event_time":"2025-10-27T17:39:43.696849Z","price_level":"115711.99","new_quantity":"0"},{"side":"offer","event_time":"2025-10-27T17:39:43.696849Z","price_level":"115776.43","new_quantity":"0.1425"},{"side":"offer","event_time":"2025-10-27T17:39:43.696849Z","price_level":"115787.58","new_quantity":"0"},{"side":"offer","event_time":"2025-10-27T17:39:43.696849Z","price_level":"115811.19","new_quantity":"0"},{"side":"offer","event_time":"2025-10-27T17:39:43.696849Z","price_level":"116786.22","new_quantity":"0.05968016"},{"side":"offer","event_time":"2025-10-27T17:39:43.696849Z","price_level":"116793.25","new_quantity":"0.06539271"}]}]}
{"channel":"l2_data","client_id":"","timestamp":"2025-10-27T17:39:43.772198773Z","sequence_num":137746,"events":[{"type":"update","product_id":"ETH-USD","updates":[{"side":"bid","event_time":"2025-10-27T17:39:43.725005Z","price_level":"4217.4","new_quantity":"20.146962"},{"side":"bid","event_time":"2025-10-27T17:39:43.725005Z","price_level":"4216","new_quantity":"50.001"},{"side":"bid","event_time":"2025-10-27T17:39:43.725005Z","price_level":"4215.01","new_quantity":"8.13008969"},{"side":"bid","event_time":"2025-10-27T17:39:43.725005Z","price_level":"4214.92","new_quantity":"0"},{"side":"bid","event_time":"2025-10-27T17:39:43.725005Z","price_level":"4214.53","new_quantity":"0"},{"side":"offer","event_time":"2025-10-27T17:39:43.725005Z","price_level":"4218.33","new_quantity":"0.0023705"},{"side":"offer","event_time":"2025-10-27T17:39:43.725005Z","price_level":"4219.56","new_quantity":"0"},{"side":"offer","event_time":"2025-10-27T17:39:43.725005Z","price_level":"4220.37","new_quantity":"4.389288"},{"side":"offer","event_time":"2025-10-27T17:39:43.725005Z","price_level":"4221.51","new_quantity":"0.671625"},{"side":"offer","event_time":"2025-10-27T17:39:43.725005Z","price_level":"4221.8","new_quantity":"13.30082152"},{"side":"offer","event_time":"2025-10-27T17:39:43.725005Z","price_level":"4221.81","new_quantity":"2.08818968"},{"side":"offer","event_time":"2025-10-27T17:39:43.725005Z","price_level":"4221.82","new_quantity":"0.09792687"},{"side":"offer","event_time":"2025-10-27T17:39:43.725005Z","price_level":"4221.85","new_quantity":"0.30652551"},{"side":"offer","event_time":"2025-10-27T17:39:43.725005Z","price_level":"4244.91","new_quantity":"0"}]}]}
{"channel":"l2_data","client_id":"","timestamp":"2025-10-27T17:39:43.798403284Z","sequence_num":137747,"events":[{"type":"update","product_id":"BTC-USD","updates":[{"side":"bid","event_time":"2025-10-27T17:39:43.755441Z","price_level":"115632.57","new_quantity":"0.00864808"},{"side":"bid","event_time":"2025-10-27T17:39:43.755441Z","price_level":"115611","new_quantity":"2"},{"side":"bid","event_time":"2025-10-27T17:39:43.755441Z","price_level":"115610","new_quantity":"1"},{"side":"bid","event_time":"2025-10-27T17:39:43.755441Z","price_level":"115606.99","new_quantity":"0.0069609"},{"side":"bid","event_time":"2025-10-27T17:39:43.755441Z","price_level":"115601.28","new_quantity":"0.011242"},{"side":"bid","event_time":"2025-10-27T17:39:43.755441Z","price_level":"115592.02","new_quantity":"0"},{"side":"bid","event_time":"2025-10-27T17:39:43.755441Z","price_level":"115574.3","new_quantity":"0"},{"side":"bid","event_time":"2025-10-27T17:39:43.755441Z","price_level":"115570.8","new_quantity":"1.5"},{"side":"bid","event_time":"2025-10-27T17:39:43.755441Z","price_level":"115567.8","new_quantity":"0"},{"side":"bid","event_time":"2025-10-27T17:39:43.755441Z","price_level":"115567.27","new_quantity":"0"},{"side":"bid","event_time":"2025-10-27T17:39:43.755441Z","price_level":"115555.82","new_quantity":"0"},{"side":"bid","event_time":"2025-10-27T17:39:43.755441Z","price_level":"115553.15","new_quantity":"0.00043232"},{"side":"bid","event_time":"2025-10-27T17:39:43.755441Z","price_level":"115552.06","new_quantity":"1.20638775"},{"side":"bid","event_time":"2025-10-27T17:39:43.755441Z","price_level":"115552.05","new_quantity":"0"},{"side":"bid","event_time":"2025-10-27T17:39:43.755441Z","price_level":"115552.04","new_quantity":"0"},{"side":"bid","event_time":"2025-10-27T17:39:43.755441Z","price_level":"115538.64","new_quantity":"0"},{"side":"bid","event_time":"2025-10-27T17:39:43.755441Z","price_level":"115536.92","new_quantity":"0.00043232"},{"side":"bid","event_time":"2025-10-27T17:39:43.755441Z","price_level":"115500.68","new_quantity":"0"},{"side":"offer","event_time":"2025-10-27T17:39:43.755441Z","price_level":"115643.6","new_quantity":"0.02594177"},{"side":"offer","event_time":"2025-10-27T17:39:43.755441Z","price_level":"115649.03","new_quantity":"0"},{"side":"offer","event_time":"2025-10-27T17:39:43.755441Z","price_level":"115651.82","new_quantity":"0.00007462"},{"side":"offer","event_time":"2025-10-27T17:39:43.755441Z","price_level":"115655.3","new_quantity":"0.16514"},{"side":"offer","event_time":"2025-10-27T17:39:43.755441Z","price_level":"115655.72","new_quantity":"0"},{"side":"offer","event_time":"2025-10-27T17:39:43.755441Z","price_level":"115670.99","new_quantity":"0"},{"side":"offer","event_time":"2025-10-27T17:39:43.755441Z","price_level":"115675.57","new_quantity":"0.82067294"},{"side":"offer","event_time":"2025-10-27T17:39:43.755441Z","price_level":"115680","new_quantity":"1"},{"side":"offer","event_time":"2025-10-27T17:39:43.755441Z","price_level":"115686.99","new_quantity":"0"},{"side":"offer","event_time":"2025-10-27T17:39:43.755441Z","price_level":"115707.06","new_quantity":"0.25160709"},{"side":"offer","event_time":"2025-10-27T17:39:43.755441Z","price_level":"115711.98","new_quantity":"0.00043236"},{"side":"offer","event_time":"2025-10-27T17:39:43.755441Z","price_level":"115714.82","new_quantity":"0"},{"side":"offer","event_time":"2025-10-27T17:39:43.755441Z","price_level":"115717.21","new_quantity":"0.00043232"},{"side":"offer","event_time":"2025-10-27T17:39:43.755441Z","price_level":"115718.1","new_quantity":"1"},{"side":"offer","event_time":"2025-10-27T17:39:43.755441Z","price_level":"115718.79","new_quantity":"0.37936283"},{"side":"offer","event_time":"2025-10-27T17:39:43.755441Z","price_level":"115718.8","new_quantity":"0"},{"side":"offer","event_time":"2025-10-27T17:39:43.755441Z","price_level":"115718.99","new_quantity":"0"},{"side":"offer","event_time":"2025-10-27T17:39:43.755441Z","price_level":"115725.94","new_quantity":"0"},{"side":"offer","event_time":"2025-10-27T17:39:43.755441Z","price_level":"115744.23","new_quantity":"0.01168442"},{"side":"offer","event_time":"2025-10-27T17:39:43.755441Z","price_level":"115755.37","new_quantity":"0.02336884"},{"side":"offer","event_time":"2025-10-27T17:39:43.755441Z","price_level":"115778.98","new_quantity":"0.04673768"}]}]}
{"channel":"l2_data","client_id":"","timestamp":"2025-10-27T17:39:43.820731137Z","sequence_num":137748,"events":[{"type":"update","product_id":"ETH-USD","updates":[{"side":"bid","event_time":"2025-10-27T17:39:43.777119Z","price_level":"4216.82","new_quantity":"0.8"},{"side":"bid","event_time":"2025-10-27T17:39:43.777119Z","price_level":"4216.36","new_quantity":"1.49927433"},{"side":"bid","event_time":"2025-10-27T17:39:43.777119Z","price_level":"4215.02","new_quantity":"6.32740472"},{"side":"bid","event_time":"2025-10-27T17:39:43.777119Z","price_level":"4213.66","new_quantity":"0.42873289"},{"side":"bid","event_time":"2025-10-27T17:39:43.777119Z","price_level":"4211.48","new_quantity":"1.57055927"},{"side":"bid","event_time":"2025-10-27T17:39:43.777119Z","price_level":"4210.48","new_quantity":"0"},{"side":"offer","event_time":"2025-10-27T17:39:43.777119Z","price_level":"4218.33","new_quantity":"0.02413099"},{"side":"offer","event_time":"2025-10-27T17:39:43.777119Z","price_level":"4218.38","new_quantity":"0"},{"side":"offer","event_time":"2025-10-27T17:39:43.777119Z","price_level":"4218.46","new_quantity":"0.07111599"},{"side":"offer","event_time":"2025-10-27T17:39:43.777119Z","price_level":"4218.61","new_quantity":"0.00197218"},{"side":"offer","event_time":"2025-10-27T17:39:43.777119Z","price_level":"4244.91","new_quantity":"0.1536"}]}]}
{"channel":"l2_data","client_id":"","timestamp":"2025-10-27T17:39:43.846575189Z","sequence_num":137750,"events":[{"type":"update","product_id":"BTC-USD","updates":[{"side":"bid","event_time":"2025-10-27T17:39:43.785156Z","price_level":"115625.95","new_quantity":"0.00432"},{"side":"bid","event_time":"2025-10-27T17:39:43.785156Z","price_level":"115623.6","new_quantity":"0.00432"},{"side":"bid","event_time":"2025-10-27T17:39:43.785156Z","price_level":"115618.25","new_quantity":"0"},{"side":"bid","event_time":"2025-10-27T17:39:43.785156Z","price_level":"115616","new_quantity":"0.4"},{"side":"bid","event_time":"2025-10-27T17:39:43.785156Z","price_level":"115614","new_quantity":"0.4"},{"side":"offer","event_time":"2025-10-27T17:39:43.785156Z","price_level":"115667","new_quantity":"2"},{"side":"offer","event_time":"2025-10-27T17:39:43.785156Z","price_level":"115668","new_quantity":"2.4"},{"side":"offer","event_time":"2025-10-27T17:39:43.785156Z","price_level":"115671","new_quantity":"0.30128617"},{"side":"offer","event_time":"2025-10-27T17:39:43.785156Z","price_level":"115674","new_quantity":"0.4"},{"side":"offer","event_time":"2025-10-27T17:39:43.785156Z","price_level":"116450.77","new_quantity":"0.00017293"}]}]}
{"channel":"l2_data","client_id":"","timestamp":"2025-10-27T17:39:43.871264965Z","sequence_num":137751,"events":[{"type":"update","product_id":"ETH-USD","updates":[{"side":"bid","event_time":"2025-10-27T17:39:43.828262Z","price_level":"4218.32","new_quantity":"1.00863"},{"side":"bid","event_time":"2025-10-27T17:39:43.828262Z","price_level":"4218.1","new_quantity":"0"},{"side":"bid","event_time":"2025-10-27T17:39:43.828262Z","price_level":"4215.03","new_quantity":"8.13005111"},{"side":"bid","event_time":"2025-10-27T17:39:43.828262Z","price_level":"4215.02","new_quantity":"0"},{"side":"bid","event_time":"2025-10-27T17:39:43.828262Z","price_level":"4215.01","new_quantity":"0"},{"side":"offer","event_time":"2025-10-27T17:39:43.828262Z","price_level":"4218.33","new_quantity":"0.19364897"},{"side":"offer","event_time":"2025-10-27T17:39:43.828262Z","price_level":"4221.78","new_quantity":"13.31002127"},{"side":"offer","event_time":"2025-10-27T17:39:43.828262Z","price_level":"4221.79","new_quantity":"2.04179073"},{"side":"offer","event_time":"2025-10-27T17:39:43.828262Z","price_level":"4221.8","new_quantity":"0"},{"side":"offer","event_time":"2025-10-27T17:39:43.828262Z","price_level":"4221.81","new_quantity":"0.14427361"}]}]}
{"channel":"l2_data","client_id":"","timestamp":"2025-10-27T17:39:43.899070603Z","sequence_num":137753,"events":[{"type":"update","product_id":"BTC-USD","updates":[{"side":"bid","event_time":"2025-10-27T17:39:43.844637Z","price_level":"115640","new_quantity":"0"},{"side":"bid","event_time":"2025-10-27T17:39:43.844637Z","price_level":"115632.57","new_quantity":"0"},{"side":"bid","event_time":"2025-10-27T17:39:43.844637Z","price_level":"115628.37","new_quantity":"0"},{"side":"bid","event_time":"2025-10-27T17:39:43.844637Z","price_level":"115625.95","new_quantity":"0"},{"side":"bid","event_time":"2025-10-27T17:39:43.844637Z","price_level":"115623.6","new_quantity":"0"},{"side":"bid","event_time":"2025-10-27T17:39:43.844637Z","price_level":"115621.7","new_quantity":"0"},{"side":"bid","event_time":"2025-10-27T17:39:43.844637Z","price_level":"115620.61","new_quantity":"0"},{"side":"bid","event_time":"2025-10-27T17:39:43.844637Z","price_level":"115619","new_quantity":"0.4"},{"side":"bid","event_time":"2025-10-27T17:39:43.844637Z","price_level":"115616.01","new_quantity":"0.65509343"},{"side":"bid","event_time":"2025-10-27T17:39:43.844637Z","price_level":"115612.97","new_quantity":"0.33125706"},{"side":"bid","event_time":"2025-10-27T17:39:43.844637Z","price_level":"115611.02","new_quantity":"0"},{"side":"bid","event_time":"2025-10-27T17:39:43.844637Z","price_level":"115611.01","new_quantity":"1.16045649"},{"side":"bid","event_time":"2025-10-27T17:39:43.844637Z","price_level":"115611","new_quantity":"0"},{"side":"bid","event_time":"2025-10-27T17:39:43.844637Z","price_level":"115575.81","new_quantity":"0"},{"side":"bid","event_time":"2025-10-27T17:39:43.844637Z","price_level":"115570.82","new_quantity":"1.43500044"},{"side":"bid","event_time":"2025-10-27T17:39:43.844637Z","price_level":"115570.81","new_quantity":"0.76392359"},{"side":"bid","event_time":"2025-10-27T17:39:43.844637Z","price_level":"115570.8","new_quantity":"0"},{"side":"bid","event_time":"2025-10-27T17:39:43.844637Z","price_level":"115566.6","new_quantity":"1.5"},{"side":"bid","event_time":"2025-10-27T17:39:43.844637Z","price_level":"115564.89","new_quantity":"0"},{"side":"bid","event_time":"2025-10-27T17:39:43.844637Z","price_level":"115562.5","new_quantity":"0.71616657"},{"side":"bid","event_time":"2025-10-27T17:39:43.844637Z","price_level":"115552.09","new_quantity":"0.83846972"},{"side":"bid","event_time":"2025-10-27T17:39:43.844637Z","price_level":"115552.08","new_quantity":"1.20638754"},{"side":"bid","event_time":"2025-10-27T17:39:43.844637Z","price_level":"115552.07","new_quantity":"0"},{"side":"bid","event_time":"2025-10-27T17:39:43.844637Z","price_level":"115552.06","new_quantity":"0"},{"side":"bid","event_time":"2025-10-27T17:39:43.844637Z","price_level":"115504.63","new_quantity":"0.36043329"},{"side":"bid","event_time":"2025-10-27T17:39:43.844637Z","price_level":"115500.25","new_quantity":"0"},{"side":"bid","event_time":"2025-10-27T17:39:43.844637Z","price_level":"114918.53","new_quantity":"0.045"},{"side":"offer","event_time":"2025-10-27T17:39:43.844637Z","price_level":"115640.92","new_quantity":"0.032196"},{"side":"offer","event_time":"2025-10-27T17:39:43.844637Z","price_level":"115641.96","new_quantity":"0.02594214"},{"side":"offer","event_time":"2025-10-27T17:39:43.844637Z","price_level":"115643.6","new_quantity":"0"},{"side":"offer","event_time":"2025-10-27T17:39:43.844637Z","price_level":"115667","new_quantity":"2"},{"side":"offer","event_time":"2025-10-27T17:39:43.844637Z","price_level":"115668","new_quantity":"2.4"},{"side":"offer","event_time":"2025-10-27T17:39:43.844637Z","price_level":"115670.99","new_quantity":"0.03458906"},{"side":"offer","event_time":"2025-10-27T17:39:43.844637Z","price_level":"115675.57","new_quantity":"0.7860837"},{"side":"offer","event_time":"2025-10-27T17:39:43.844637Z","price_level":"115680","new_quantity":"0"},{"side":"offer","event_time":"2025-10-27T17:39:43.844637Z","price_level":"115681.26","new_quantity":"0"},{"side":"offer","event_time":"2025-10-27T17:39:43.844637Z","price_level":"115689.73","new_quantity":"0"},{"side":"offer","event_time":"2025-10-27T17:39:43.844637Z","price_level":"115693.99","new_quantity":"0.16812335"},{"side":"offer","event_time":"2025-10-27T17:39:43.844637Z","price_level":"115706.38","new_quantity":"0.25117625"},{"side":"offer","event_time":"2025-10-27T17:39:43.844637Z","price_level":"115707.06","new_quantity":"0.00043232"},{"side":"offer","event_time":"2025-10-27T17:39:43.844637Z","price_level":"115718.09","new_quantity":"0.37936512"},{"side":"offer","event_time":"2025-10-27T17:39:43.844637Z","price_level":"115718.1","new_quantity":"0"},{"side":"offer","event_time":"2025-10-27T17:39:43.844637Z","price_level":"115718.3","new_quantity":"1"},{"side":"offer","event_time":"2025-10-27T17:39:43.844637Z","price_level":"115718.79","new_quantity":"0"},{"side":"offer","event_time":"2025-10-27T17:39:43.844637Z","price_level":"115727.09","new_quantity":"0"},{"side":"offer","event_time":"2025-10-27T17:39:43.844637Z","price_level":"115727.16","new_quantity":"0"},{"side":"offer","event_time":"2025-10-27T17:39:43.844637Z","price_level":"115735.11","new_quantity":"0.57744092"}]}]}
{"channel":"l2_data","client_id":"","timestamp":"2025-10-27T17:39:43.921125476Z","sequence_num":137754,"events":[{"type":"update","product_id":"ETH-USD","updates":[{"side":"bid","event_time":"2025-10-27T17:39:43.88191Z","price_level":"4218.32","new_quantity":"1.07962715"},{"side":"offer","event_time":"2025-10-27T17:39:43.88191Z","price_level":"4218.33","new_quantity":"0.36240897"}]}]}
{"channel":"l2_data","client_id":"","timestamp":"2025-10-27T17:39:43.947335682Z","sequence_num":137756,"events":[{"type":"update","product_id":"BTC-USD","updates":[{"side":"bid","event_time":"2025-10-27T17:39:43.906299Z","price_level":"115640.91","new_quantity":"0.08333268"},{"side":"bid","event_time":"2025-10-27T17:39:43.906299Z","price_level":"115615.92","new_quantity":"0.16588"},{"side":"bid","event_time":"2025-10-27T17:39:43.906299Z","price_level":"115611.01","new_quantity":"2.20609442"},{"side":"bid","event_time":"2025-10-27T17:39:43.906299Z","price_level":"115610","new_quantity":"3"},{"side":"bid","event_time":"2025-10-27T17:39:43.906299Z","price_level":"115566.9","new_quantity":"1.5"},{"side":"bid","event_time":"2025-10-27T17:39:43.906299Z","price_level":"115566.6","new_quantity":"0"},{"side":"bid","event_time":"2025-10-27T17:39:43.906299Z","price_level":"115504.63","new_quantity":"1.43680045"},{"side":"bid","event_time":"2025-10-27T17:39:43.906299Z","price_level":"115496.77","new_quantity":"0.045"},{"side":"offer","event_time":"2025-10-27T17:39:43.906299Z","price_level":"115667","new_quantity":"0"},{"side":"offer","event_time":"2025-10-27T17:39:43.906299Z","price_level":"115668","new_quantity":"2"},{"side":"offer","event_time":"2025-10-27T17:39:43.906299Z","price_level":"115670.99","new_quantity":"0"},{"side":"offer","event_time":"2025-10-27T17:39:43.906299Z","price_level":"115675.56","new_quantity":"0.0345897"},{"side":"offer","event_time":"2025-10-27T17:39:43.906299Z","price_level":"115675.57","new_quantity":"0.24047691"},{"side":"offer","event_time":"2025-10-27T17:39:43.906299Z","price_level":"115681.26","new_quantity":"0.38146486"},{"side":"offer","event_time":"2025-10-27T17:39:43.906299Z","price_level":"115710","new_quantity":"5.4000267"},{"side":"offer","event_time":"2025-10-27T17:39:43.906299Z","price_level":"115718.3","new_quantity":"0"},{"side":"offer","event_time":"2025-10-27T17:39:43.906299Z","price_level":"115718.4","new_quantity":"1"}]}]}
{"channel":"l2_data","client_id":"","timestamp":"2025-10-27T17:39:43.649408258Z","sequence_num":137740,"events":[{"type":"update","product_id":"BTC-USD","updates":[{"side":"bid","event_time":"2025-10-27T17:39:43.613189Z","price_level":"115649.02","new_quantity":"0"},{"side":"bid","event_time":"2025-10-27T17:39:43.613189Z","price_level":"115646","new_quantity":"0"},{"side":"bid","event_time":"2025-10-27T17:39:43.613189Z","price_level":"115644","new_quantity":"0"},{"side":"bid","event_time":"2025-10-27T17:39:43.613189Z","price_level":"115642.02","new_quantity":"0.00008648"},{"side":"bid","event_time":"2025-10-27T17:39:43.613189Z","price_level":"115642.01","new_quantity":"0"},{"side":"bid","event_time":"2025-10-27T17:39:43.613189Z","price_level":"115642","new_quantity":"0"},{"side":"bid","event_time":"2025-10-27T17:39:43.613189Z","price_level":"115640","new_quantity":"0"},{"side":"bid","event_time":"2025-10-27T17:39:43.613189Z","price_level":"115638.61","new_quantity":"0"},{"side":"bid","event_time":"2025-10-27T17:39:43.613189Z","price_level":"115638.6","new_quantity":"0.0097207"},{"side":"bid","event_time":"2025-10-27T17:39:43.613189Z","price_level":"115638.11","new_quantity":"0.00259725"},{"side":"bid","event_time":"2025-10-27T17:39:43.613189Z","price_level":"115638.01","new_quantity":"0"},{"side":"bid","event_time":"2025-10-27T17:39:43.613189Z","price_level":"115637.37","new_quantity":"0"},{"side":"bid","event_time":"2025-10-27T17:39:43.613189Z","price_level":"115636","new_quantity":"0.0224"},{"side":"bid","event_time":"2025-10-27T17:39:43.613189Z","price_level":"115634.69","new_quantity":"0.00172958"},{"side":"bid","event_time":"2025-10-27T17:39:43.613189Z","price_level":"115634.68","new_quantity":"0.08483273"},{"side":"bid","event_time":"2025-10-27T17:39:43.613189Z","price_level":"115633.87","new_quantity":"0"},{"side":"bid","event_time":"2025-10-27T17:39:43.613189Z","price_level":"115632.43","new_quantity":"0"},{"side":"bid","event_time":"2025-10-27T17:39:43.613189Z","price_level":"115632.16","new_quantity":"0"},{"side":"bid","event_time":"2025-10-27T17:39:43.613189Z","price_level":"115631.05","new_quantity":"0"},{"side":"bid","event_time":"2025-10-27T17:39:43.613189Z","price_level":"115629.64","new_quantity":"0"},{"side":"bid","event_time":"2025-10-27T17:39:43.613189Z","price_level":"115628.27","new_quantity":"0"},{"side":"bid","event_time":"2025-10-27T17:39:43.613189Z","price_level":"115628.24","new_quantity":"0"},{"side":"bid","event_time":"2025-10-27T17:39:43.613189Z","price_level":"115625.92","new_quantity":"0"},{"side":"bid","event_time":"2025-10-27T17:39:43.613189Z","price_level":"115622.87","new_quantity":"0.79416282"},{"side":"bid","event_time":"2025-10-27T17:39:43.613189Z","price_level":"115622.86","new_quantity":"0"},{"side":"bid","event_time":"2025-10-27T17:39:43.613189Z","price_level":"115621.54","new_quantity":"0.08648906"},{"side":"bid","event_time":"2025-10-27T17:39:43.613189Z","price_level":"115619.97","new_quantity":"0"},{"side":"bid","event_time":"2025-10-27T17:39:43.613189Z","price_level":"115618.25","new_quantity":"0.16588"},{"side":"bid","event_time":"2025-10-27T17:39:43.613189Z","price_level":"115618","new_quantity":"0"},{"side":"bid","event_time":"2025-10-27T17:39:43.613189Z","price_level":"115616.01","new_quantity":"1.56925389"},{"side":"bid","event_time":"2025-10-27T17:39:43.613189Z","price_level":"115616","new_quantity":"2"},{"side":"bid","event_time":"2025-10-27T17:39:43.613189Z","price_level":"115615.3","new_quantity":"0"},{"side":"bid","event_time":"2025-10-27T17:39:43.613189Z","price_level":"115614.11","new_quantity":"0.01729892"},{"side":"bid","event_time":"2025-10-27T17:39:43.613189Z","price_level":"115612.98","new_quantity":"0"},{"side":"bid","event_time":"2025-10-27T17:39:43.613189Z","price_level":"115612.97","new_quantity":"0.33125706"},{"side":"bid","event_time":"2025-10-27T17:39:43.613189Z","price_level":"115609.09","new_quantity":"0.56345649"},{"side":"bid","event_time":"2025-10-27T17:39:43.613189Z","price_level":"115609.08","new_quantity":"0"},{"side":"bid","event_time":"2025-10-27T17:39:43.613189Z","price_level":"115606.37","new_quantity":"0"},{"side":"bid","event_time":"2025-10-27T17:39:43.613189Z","price_level":"115596.89","new_quantity":"0.9246105"},{"side":"bid","event_time":"2025-10-27T17:39:43.613189Z","price_level":"115596.88","new_quantity":"0.52639337"},{"side":"bid","event_time":"2025-10-27T17:39:43.613189Z","price_level":"115596.87","new_quantity":"0"},{"side":"bid","event_time":"2025-10-27T17:39:43.613189Z","price_level":"115596.86","new_quantity":"0.37060245"},{"side":"bid","event_time":"2025-10-27T17:39:43.613189Z","price_level":"115592.02","new_quantity":"0.011241"},{"side":"bid","event_time":"2025-10-27T17:39:43.613189Z","price_level":"115588.24","new_quantity":"0.17344305"},{"side":"bid","event_time":"2025-10-27T17:39:43.613189Z","price_level":"115585.63","new_quantity":"0"},{"side":"bid","event_time":"2025-10-27T17:39:43.613189Z","price_level":"115585.62","new_quantity":"0"},{"side":"bid","event_time":"2025-10-27T17:39:43.613189Z","price_level":"115580.07","new_quantity":"0.058099"},{"side":"bid","event_time":"2025-10-27T17:39:43.613189Z","price_level":"115580.02","new_quantity":"0.76386271"},{"side":"bid","event_time":"2025-10-27T17:39:43.613189Z","price_level":"115579.83","new_quantity":"0.0648319"},{"side":"bid","event_time":"2025-10-27T17:39:43.613189Z","price_level":"115564.91","new_quantity":"0"},{"side":"bid","event_time":"2025-10-27T17:39:43.613189Z","price_level":"115564.9","new_quantity":"0"},{"side":"bid","event_time":"2025-10-27T17:39:43.613189Z","price_level":"115564.89","new_quantity":"0.0292696"},{"side":"bid","event_time":"2025-10-27T17:39:43.613189Z","price_level":"115556.63","new_quantity":"0"},{"side":"bid","event_time":"2025-10-27T17:39:43.613189Z","price_level":"115556.62","new_quantity":"0"},{"side":"bid","event_time":"2025-10-27T17:39:43.613189Z","price_level":"115553.14","new_quantity":"0.01909826"},{"side":"bid","event_time":"2025-10-27T17:39:43.613189Z","price_level":"115552.05","new_quantity":"0.83846998"},{"side":"bid","event_time":"2025-10-27T17:39:43.613189Z","price_level":"115552.04","new_quantity":"1.20638796"},{"side":"bid","event_time":"2025-10-27T17:39:43.613189Z","price_level":"115552.03","new_quantity":"0"},{"side":"bid","event_time":"2025-10-27T17:39:43.613189Z","price_level":"115536.49","new_quantity":"0"},{"side":"bid","event_time":"2025-10-27T17:39:43.613189Z","price_level":"115507.2","new_quantity":"0.017294"},{"side":"bid","event_time":"2025-10-27T17:39:43.613189Z","price_level":"115406.8","new_quantity":"0"},{"side":"bid","event_time":"2025-10-27T17:39:43.613189Z","price_level":"101192.9","new_quantity":"0"},{"side":"offer","event_time":"2025-10-27T17:39:43.613189Z","price_level":"115642.03","new_quantity":"0.2665198"},{"side":"offer","event_time":"2025-10-27T17:39:43.613189Z","price_level":"115647.52","new_quantity":"0.3858614"},{"side":"offer","event_time":"2025-10-27T17:39:43.613189Z","price_level":"115647.53","new_quantity":"0.25940892"},{"side":"offer","event_time":"2025-10-27T17:39:43.613189Z","price_level":"115649.02","new_quantity":"0.02"},{"side":"offer","event_time":"2025-10-27T17:39:43.613189Z","price_level":"115649.03","new_quantity":"0.032182"},{"side":"offer","event_time":"2025-10-27T17:39:43.613189Z","price_level":"115649.08","new_quantity":"0"},{"side":"offer","event_time":"2025-10-27T17:39:43.613189Z","price_level":"115649.09","new_quantity":"0"},{"side":"offer","event_time":"2025-10-27T17:39:43.613189Z","price_level":"115665.31","new_quantity":"0"},{"side":"offer","event_time":"2025-10-27T17:39:43.613189Z","price_level":"115665.32","new_quantity":"0"},{"side":"offer","event_time":"2025-10-27T17:39:43.613189Z","price_level":"115665.33","new_quantity":"0"},{"side":"offer","event_time":"2025-10-27T17:39:43.613189Z","price_level":"115666.53","new_quantity":"0.00007468"},{"side":"offer","event_time":"2025-10-27T17:39:43.613189Z","price_level":"115666.99","new_quantity":"0.38913622"},{"side":"offer","event_time":"2025-10-27T17:39:43.613189Z","price_level":"115667","new_quantity":"0"},{"side":"offer","event_time":"2025-10-27T17:39:43.613189Z","price_level":"115670.99","new_quantity":"0.03458625"},{"side":"offer","event_time":"2025-10-27T17:39:43.613189Z","price_level":"115675.57","new_quantity":"0.24047691"},{"side":"offer","event_time":"2025-10-27T17:39:43.613189Z","price_level":"115675.59","new_quantity":"0"},{"side":"offer","event_time":"2025-10-27T17:39:43.613189Z","price_level":"115675.78","new_quantity":"0"},{"side":"offer","event_time":"2025-10-27T17:39:43.613189Z","price_level":"115681.26","new_quantity":"0.50906369"},{"side":"offer","event_time":"2025-10-27T17:39:43.613189Z","price_level":"115681.27","new_quantity":"0.852693"},{"side":"offer","event_time":"2025-10-27T17:39:43.613189Z","price_level":"115693.99","new_quantity":"0"},{"side":"offer","event_time":"2025-10-27T17:39:43.613189Z","price_level":"115697.34","new_quantity":"0.16811848"},{"side":"offer","event_time":"2025-10-27T17:39:43.613189Z","price_level":"115699.99","new_quantity":"0"},{"side":"offer","event_time":"2025-10-27T17:39:43.613189Z","price_level":"115709.25","new_quantity":"0.01993432"},{"side":"offer","event_time":"2025-10-27T17:39:43.613189Z","price_level":"115711.99","new_quantity":"0.25116407"},{"side":"offer","event_time":"2025-10-27T17:39:43.613189Z","price_level":"115713.38","new_quantity":"0"},{"side":"offer","event_time":"2025-10-27T17:39:43.613189Z","price_level":"115714.82","new_quantity":"0.0004323"},{"side":"offer","event_time":"2025-10-27T17:39:43.613189Z","price_level":"115718.99","new_quantity":"0.37979451"},{"side":"offer","event_time":"2025-10-27T17:39:43.613189Z","price_level":"115725.94","new_quantity":"0.0004323"},{"side":"offer","event_time":"2025-10-27T17:39:43.613189Z","price_level":"115725.95","new_quantity":"0"},{"side":"offer","event_time":"2025-10-27T17:39:43.613189Z","price_level":"115727.09","new_quantity":"0.57748094"},{"side":"offer","event_time":"2025-10-27T17:39:43.613189Z","price_level":"115727.1","new_quantity":"0"},{"side":"offer","event_time":"2025-10-27T17:39:43.613189Z","price_level":"115735.11","new_quantity":"0"},{"side":"offer","event_time":"2025-10-27T17:39:43.613189Z","price_level":"116339.85","new_quantity":"0.04827968"},{"side":"offer","event_time":"2025-10-27T17:39:43.613189Z","price_level":"116393.66","new_quantity":"0.13558402"},{"side":"offer","event_time":"2025-10-27T17:39:43.613189Z","price_level":"116567.33","new_quantity":"0.06360397"},{"side":"offer","event_time":"2025-10-27T17:39:43.613189Z","price_level":"116693.35","new_quantity":"0.08381669"},{"side":"offer","event_time":"2025-10-27T17:39:43.613189Z","price_level":"116827.58","new_quantity":"0"}]}]}
{"channel":"l2_data","client_id":"","timestamp":"2025-10-27T17:39:43.97050324Z","sequence_num":137757,"events":[{"type":"update","product_id":"ETH-USD","updates":[{"side":"bid","event_time":"2025-10-27T17:39:43.932842Z","price_level":"4216.76","new_quantity":"2.37079003"},{"side":"bid","event_time":"2025-10-27T17:39:43.932842Z","price_level":"4216.36","new_quantity":"0"},{"side":"bid","event_time":"2025-10-27T17:39:43.932842Z","price_level":"4216.35","new_quantity":"0"},{"side":"bid","event_time":"2025-10-27T17:39:43.932842Z","price_level":"4216.02","new_quantity":"4.30162367"},{"side":"bid","event_time":"2025-10-27T17:39:43.932842Z","price_level":"4214.54","new_quantity":"9.16091595"},{"side":"offer","event_time":"2025-10-27T17:39:43.932842Z","price_level":"4218.33","new_quantity":"0.19364897"},{"side":"offer","event_time":"2025-10-27T17:39:43.932842Z","price_level":"4218.62","new_quantity":"0.15395789"},{"side":"offer","event_time":"2025-10-27T17:39:43.932842Z","price_level":"4220","new_quantity":"42.20517286"},{"side":"offer","event_time":"2025-10-27T17:39:43.932842Z","price_level":"4220.37","new_quantity":"8.63199701"},{"side":"offer","event_time":"2025-10-27T17:39:43.932842Z","price_level":"4221.85","new_quantity":"9.04704419"}]}]}
{"channel":"l2_data","client_id":"","timestamp":"2025-10-27T17:39:43.999310417Z","sequence_num":137758,"events":[{"type":"update","product_id":"BTC-USD","updates":[{"side":"bid","event_time":"2025-10-27T17:39:43.963681Z","price_level":"115622.87","new_quantity":"0"},{"side":"bid","event_time":"2025-10-27T17:39:43.963681Z","price_level":"115621.7","new_quantity":"0"},{"side":"bid","event_time":"2025-10-27T17:39:43.963681Z","price_level":"115620.91","new_quantity":"0"},{"side":"bid","event_time":"2025-10-27T17:39:43.963681Z","price_level":"115619","new_quantity":"0"},{"side":"bid","event_time":"2025-10-27T17:39:43.963681Z","price_level":"115612.97","new_quantity":"0"},{"side":"bid","event_time":"2025-10-27T17:39:43.963681Z","price_level":"115611.02","new_quantity":"0.33126265"},{"side":"bid","event_time":"2025-10-27T17:39:43.963681Z","price_level":"115570.84","new_quantity":"1.51408528"},{"side":"bid","event_time":"2025-10-27T17:39:43.963681Z","price_level":"115570.83","new_quantity":"0.76392345"},{"side":"bid","event_time":"2025-10-27T17:39:43.963681Z","price_level":"115570.82","new_quantity":"0"},{"side":"bid","event_time":"2025-10-27T17:39:43.963681Z","price_level":"115570.81","new_quantity":"0"},{"side":"bid","event_time":"2025-10-27T17:39:43.963681Z","price_level":"115552.11","new_quantity":"0.813891"},{"side":"bid","event_time":"2025-10-27T17:39:43.963681Z","price_level":"115552.1","new_quantity":"1.16521715"},{"side":"bid","event_time":"2025-10-27T17:39:43.963681Z","price_level":"115552.09","new_quantity":"0"},{"side":"bid","event_time":"2025-10-27T17:39:43.963681Z","price_level":"115552.08","new_quantity":"0"},{"side":"bid","event_time":"2025-10-27T17:39:43.963681Z","price_level":"115171.16","new_quantity":"0.07007"},{"side":"bid","event_time":"2025-10-27T17:39:43.963681Z","price_level":"115170.35","new_quantity":"0"},{"side":"bid","event_time":"2025-10-27T17:39:43.963681Z","price_level":"114918.53","new_quantity":"0"},{"side":"bid","event_time":"2025-10-27T17:39:43.963681Z","price_level":"114569.29","new_quantity":"0.00034914"},{"side":"offer","event_time":"2025-10-27T17:39:43.963681Z","price_level":"115640.92","new_quantity":"0.05739023"},{"side":"offer","event_time":"2025-10-27T17:39:43.963681Z","price_level":"115647.5","new_quantity":"0.00007601"},{"side":"offer","event_time":"2025-10-27T17:39:43.963681Z","price_level":"115651.82","new_quantity":"0"},{"side":"offer","event_time":"2025-10-27T17:39:43.963681Z","price_level":"115668","new_quantity":"2"},{"side":"offer","event_time":"2025-10-27T17:39:43.963681Z","price_level":"115675.45","new_quantity":"0.07007"},{"side":"offer","event_time":"2025-10-27T17:39:43.963681Z","price_level":"115675.57","new_quantity":"0.21983076"},{"side":"offer","event_time":"2025-10-27T17:39:43.963681Z","price_level":"115675.58","new_quantity":"0"},{"side":"offer","event_time":"2025-10-27T17:39:43.963681Z","price_level":"115677.9","new_quantity":"0.13835648"},{"side":"offer","event_time":"2025-10-27T17:39:43.963681Z","price_level":"115679.09","new_quantity":"0"},{"side":"offer","event_time":"2025-10-27T17:39:43.963681Z","price_level":"115686.99","new_quantity":"0.03819098"},{"side":"offer","event_time":"2025-10-27T17:39:43.963681Z","price_level":"115706.38","new_quantity":"0"},{"side":"offer","event_time":"2025-10-27T17:39:43.963681Z","price_level":"115709.99","new_quantity":"0.25116841"},{"side":"offer","event_time":"2025-10-27T17:39:43.963681Z","price_level":"115829.33","new_quantity":"0.09347537"},{"side":"offer","event_time":"2025-10-27T17:39:43.963681Z","price_level":"115862.68","new_quantity":"0"},{"side":"offer","event_time":"2025-10-27T17:39:43.963681Z","price_level":"116967.14","new_quantity":"0"}]}]}
{"channel":"l2_data","client_id":"","timestamp":"2025-10-27T17:39:44.020400969Z","sequence_num":137759,"events":[{"type":"update","product_id":"ETH-USD","updates":[{"side":"bid","event_time":"2025-10-27T17:39:43.985653Z","price_level":"4218.32","new_quantity":"1.00853407"},{"side":"bid","event_time":"2025-10-27T17:39:43.985653Z","price_level":"4216.76","new_quantity":"0"},{"side":"offer","event_time":"2025-10-27T17:39:43.985653Z","price_level":"4221.51","new_quantity":"2.61554107"},{"side":"offer","event_time":"2025-10-27T17:39:43.985653Z","price_level":"4221.79","new_quantity":"0.09787466"}]}]}
{"channel":"l2_data","client_id":"","timestamp":"2025-10-27T17:39:44.046415667Z","sequence_num":137760,"events":[{"type":"update","product_id":"BTC-USD","updates":[{"side":"bid","event_time":"2025-10-27T17:39:43.988868Z","price_level":"115616.81","new_quantity":"0.08"},{"side":"bid","event_time":"2025-10-27T17:39:43.988868Z","price_level":"115570.5","new_quantity":"1.5"},{"side":"bid","event_time":"2025-10-27T17:39:43.988868Z","price_level":"115566.9","new_quantity":"0"},{"side":"bid","event_time":"2025-10-27T17:39:43.988868Z","price_level":"115534.44","new_quantity":"0"},{"side":"bid","event_time":"2025-10-27T17:39:43.988868Z","price_level":"115532.4","new_quantity":"0"},{"side":"bid","event_time":"2025-10-27T17:39:43.988868Z","price_level":"115286.37","new_quantity":"0"},{"side":"bid","event_time":"2025-10-27T17:39:43.988868Z","price_level":"115239.39","new_quantity":"0"},{"side":"bid","event_time":"2025-10-27T17:39:43.988868Z","price_level":"115046.55","new_quantity":"0"},{"side":"bid","event_time":"2025-10-27T17:39:43.988868Z","price_level":"113820.53","new_quantity":"0.01054291"},{"side":"bid","event_time":"2025-10-27T17:39:43.988868Z","price_level":"113268.87","new_quantity":"0.01412568"},{"side":"offer","event_time":"2025-10-27T17:39:43.988868Z","price_level":"115667","new_quantity":"2"},{"side":"offer","event_time":"2025-10-27T17:39:43.988868Z","price_level":"115670.99","new_quantity":"0.03458987"},{"side":"offer","event_time":"2025-10-27T17:39:43.988868Z","price_level":"115675.56","new_quantity":"0"},{"side":"offer","event_time":"2025-10-27T17:39:43.988868Z","price_level":"115680","new_quantity":"1"}]}]}
{"channel":"l2_data","client_id":"","timestamp":"2025-10-27T17:39:44.070668078Z","sequence_num":137761,"events":[{"type":"update","product_id":"ETH-USD","updates":[{"side":"bid","event_time":"2025-10-27T17:39:44.03028Z","price_level":"4216.37","new_quantity":"2.3708124"},{"side":"offer","event_time":"2025-10-27T17:39:44.03028Z","price_level":"4261.22","new_quantity":"0.06544858"},{"side":"offer","event_time":"2025-10-27T17:39:44.03028Z","price_level":"4272.15","new_quantity":"0"},{"side":"offer","event_time":"2025-10-27T17:39:44.03028Z","price_level":"4272.24","new_quantity":"0.03583549"},{"side":"offer","event_time":"2025-10-27T17:39:44.03028Z","price_level":"4272.72","new_quantity":"0.0946876"}]}]}
{"channel":"l2_data","client_id":"","timestamp":"2025-10-27T17:39:44.098226459Z","sequence_num":137763,"events":[{"type":"update","product_id":"BTC-USD","updates":[{"side":"bid","event_time":"2025-10-27T17:39:44.043984Z","price_level":"115638.61","new_quantity":"0.00172952"},{"side":"bid","event_time":"2025-10-27T17:39:44.043984Z","price_level":"115633.06","new_quantity":"0.01059705"},{"side":"bid","event_time":"2025-10-27T17:39:44.043984Z","price_level":"115618","new_quantity":"0.4"},{"side":"bid","event_time":"2025-10-27T17:39:44.043984Z","price_level":"115610.53","new_quantity":"0.011242"},{"side":"bid","event_time":"2025-10-27T17:39:44.043984Z","price_level":"115601.28","new_quantity":"0"},{"side":"bid","event_time":"2025-10-27T17:39:44.043984Z","price_level":"115552.12","new_quantity":"1.16521695"},{"side":"bid","event_time":"2025-10-27T17:39:44.043984Z","price_level":"115552.11","new_quantity":"0"},{"side":"bid","event_time":"2025-10-27T17:39:44.043984Z","price_level":"115552.1","new_quantity":"0"},{"side":"bid","event_time":"2025-10-27T17:39:44.043984Z","price_level":"115396.53","new_quantity":"0.02741408"},{"side":"bid","event_time":"2025-10-27T17:39:44.043984Z","price_level":"115360.86","new_quantity":"0.03521415"},{"side":"bid","event_time":"2025-10-27T17:39:44.043984Z","price_level":"115209.36","new_quantity":"0.02411837"},{"side":"bid","event_time":"2025-10-27T17:39:44.043984Z","price_level":"115190.01","new_quantity":"0"},{"side":"bid","event_time":"2025-10-27T17:39:44.043984Z","price_level":"115155.75","new_quantity":"0"},{"side":"bid","event_time":"2025-10-27T17:39:44.043984Z","price_level":"114969.7","new_quantity":"0.07807063"},{"side":"bid","event_time":"2025-10-27T17:39:44.043984Z","price_level":"114931.19","new_quantity":"0.02013648"},{"side":"bid","event_time":"2025-10-27T17:39:44.043984Z","price_level":"114381.78","new_quantity":"0"},{"side":"bid","event_time":"2025-10-27T17:39:44.043984Z","price_level":"113834.9","new_quantity":"0"},{"side":"bid","event_time":"2025-10-27T17:39:44.043984Z","price_level":"113288.02","new_quantity":"0"},{"side":"offer","event_time":"2025-10-27T17:39:44.043984Z","price_level":"115667","new_quantity":"2"},{"side":"offer","event_time":"2025-10-27T17:39:44.043984Z","price_level":"115668","new_quantity":"2.4"},{"side":"offer","event_time":"2025-10-27T17:39:44.043984Z","price_level":"115675.57","new_quantity":"0.62194177"},{"side":"offer","event_time":"2025-10-27T17:39:44.043984Z","price_level":"115680","new_quantity":"1"},{"side":"offer","event_time":"2025-10-27T17:39:44.043984Z","price_level":"115704.69","new_quantity":"0"}]}]}
{"channel":"l2_data","client_id":"","timestamp":"2025-10-27T17:39:44.119694636Z","sequence_num":137764,"events":[{"type":"update","product_id":"ETH-USD","updates":[{"side":"bid","event_time":"2025-10-27T17:39:44.085398Z","price_level":"4218.28","new_quantity":"0.07109311"},{"side":"bid","event_time":"2025-10-27T17:39:44.085398Z","price_level":"4217.32","new_quantity":"0"}]}]}
{"channel":"l2_data","client_id":"","timestamp":"2025-10-27T17:39:44.147885267Z","sequence_num":137766,"events":[{"type":"update","product_id":"BTC-USD","updates":[{"side":"bid","event_time":"2025-10-27T17:39:44.095672Z","price_level":"115628.57","new_quantity":"0"},{"side":"bid","event_time":"2025-10-27T17:39:44.095672Z","price_level":"115626.86","new_quantity":"0.02161157"},{"side":"bid","event_time":"2025-10-27T17:39:44.095672Z","price_level":"115620.65","new_quantity":"0.4900743"},{"side":"bid","event_time":"2025-10-27T17:39:44.095672Z","price_level":"115619","new_quantity":"0.4"},{"side":"bid","event_time":"2025-10-27T17:39:44.095672Z","price_level":"115618.61","new_quantity":"0.04"},{"side":"bid","event_time":"2025-10-27T17:39:44.095672Z","price_level":"115618","new_quantity":"0"},{"side":"bid","event_time":"2025-10-27T17:39:44.095672Z","price_level":"115617.01","new_quantity":"0"},{"side":"bid","event_time":"2025-10-27T17:39:44.095672Z","price_level":"115570.85","new_quantity":"0.76392332"},{"side":"bid","event_time":"2025-10-27T17:39:44.095672Z","price_level":"115570.84","new_quantity":"0"},{"side":"bid","event_time":"2025-10-27T17:39:44.095672Z","price_level":"115570.83","new_quantity":"0"},{"side":"bid","event_time":"2025-10-27T17:39:44.095672Z","price_level":"115209.36","new_quantity":"0.05074681"},{"side":"bid","event_time":"2025-10-27T17:39:44.095672Z","price_level":"115172.19","new_quantity":"0.07007"},{"side":"bid","event_time":"2025-10-27T17:39:44.095672Z","price_level":"115172.15","new_quantity":"0.07007"},{"side":"bid","event_time":"2025-10-27T17:39:44.095672Z","price_level":"115172.14","new_quantity":"0"},{"side":"bid","event_time":"2025-10-27T17:39:44.095672Z","price_level":"115171.16","new_quantity":"0"},{"side":"bid","event_time":"2025-10-27T17:39:44.095672Z","price_level":"115037","new_quantity":"0"},{"side":"bid","event_time":"2025-10-27T17:39:44.095672Z","price_level":"115016.56","new_quantity":"0"},{"side":"bid","event_time":"2025-10-27T17:39:44.095672Z","price_level":"114931.19","new_quantity":"0.04615692"},{"side":"bid","event_time":"2025-10-27T17:39:44.095672Z","price_level":"114100","new_quantity":"0.03338652"},{"side":"bid","event_time":"2025-10-27T17:39:44.095672Z","price_level":"114099.99","new_quantity":"0.00622573"},{"side":"offer","event_time":"2025-10-27T17:39:44.095672Z","price_level":"115667","new_quantity":"2"},{"side":"offer","event_time":"2025-10-27T17:39:44.095672Z","price_level":"115668","new_quantity":"2.4"},{"side":"offer","event_time":"2025-10-27T17:39:44.095672Z","price_level":"115675.57","new_quantity":"0.62194177"},{"side":"offer","event_time":"2025-10-27T17:39:44.095672Z","price_level":"115680","new_quantity":"1"},{"side":"offer","event_time":"2025-10-27T17:39:44.095672Z","price_level":"115890.83","new_quantity":"0.07007"},{"side":"offer","event_time":"2025-10-27T17:39:44.095672Z","price_level":"115891.3","new_quantity":"0"},{"side":"offer","event_time":"2025-10-27T17:39:44.095672Z","price_level":"115893.89","new_quantity":"0"},{"side":"offer","event_time":"2025-10-27T17:39:44.095672Z","price_level":"116105.74","new_quantity":"0.07007"},{"side":"offer","event_time":"2025-10-27T17:39:44.095672Z","price_level":"116752.66","new_quantity":"0"},{"side":"offer","event_time":"2025-10-27T17:39:44.095672Z","price_level":"116963.49","new_quantity":"0.07007"}]}]}
{"channel":"l2_data","client_id":"","timestamp":"2025-10-27T17:39:44.169056212Z","sequence_num":137767,"events":[{"type":"update","product_id":"ETH-USD","updates":[{"side":"bid","event_time":"2025-10-27T17:39:44.091204Z","price_level":"4217.94","new_quantity":"0.00437083"},{"side":"bid","event_time":"2025-10-27T17:39:44.091204Z","price_level":"4217.93","new_quantity":"0.11854153"},{"side":"bid","event_time":"2025-10-27T17:39:44.091204Z","price_level":"4217.92","new_quantity":"0"},{"side":"bid","event_time":"2025-10-27T17:39:44.091204Z","price_level":"4217.71","new_quantity":"0.59273862"}]}]}
{"channel":"l2_data","client_id":"","timestamp":"2025-10-27T17:39:44.199248035Z","sequence_num":137768,"events":[{"type":"update","product_id":"BTC-USD","updates":[{"side":"bid","event_time":"2025-10-27T17:39:44.141223Z","price_level":"115630.86","new_quantity":"0.00864821"},{"side":"bid","event_time":"2025-10-27T17:39:44.141223Z","price_level":"115622.55","new_quantity":"0.00086476"},{"side":"bid","event_time":"2025-10-27T17:39:44.141223Z","price_level":"115621.7","new_quantity":"0.16578"},{"side":"bid","event_time":"2025-10-27T17:39:44.141223Z","price_level":"115621.62","new_quantity":"0.00001"},{"side":"bid","event_time":"2025-10-27T17:39:44.141223Z","price_level":"115620.65","new_quantity":"0.69009926"},{"side":"bid","event_time":"2025-10-27T17:39:44.141223Z","price_level":"115610.99","new_quantity":"0.00432381"},{"side":"bid","event_time":"2025-10-27T17:39:44.141223Z","price_level":"115570.86","new_quantity":"1.5140852"},{"side":"bid","event_time":"2025-10-27T17:39:44.141223Z","price_level":"115553.64","new_quantity":"0"},{"side":"bid","event_time":"2025-10-27T17:39:44.141223Z","price_level":"115552.13","new_quantity":"0.81389088"},{"side":"bid","event_time":"2025-10-27T17:39:44.141223Z","price_level":"115547.46","new_quantity":"0"},{"side":"bid","event_time":"2025-10-27T17:39:44.141223Z","price_level":"115178.33","new_quantity":"0.02504652"},{"side":"bid","event_time":"2025-10-27T17:39:44.141223Z","price_level":"115172.27","new_quantity":"0.07007"},{"side":"bid","event_time":"2025-10-27T17:39:44.141223Z","price_level":"115172.19","new_quantity":"0"},{"side":"bid","event_time":"2025-10-27T17:39:44.141223Z","price_level":"115172.15","new_quantity":"0"},{"side":"bid","event_time":"2025-10-27T17:39:44.141223Z","price_level":"114957.82","new_quantity":"0.07007"},{"side":"bid","event_time":"2025-10-27T17:39:44.141223Z","price_level":"114099.95","new_quantity":"0.07007"},{"side":"offer","event_time":"2025-10-27T17:39:44.141223Z","price_level":"115667","new_quantity":"2"},{"side":"offer","event_time":"2025-10-27T17:39:44.141223Z","price_level":"115668","new_quantity":"2.4"},{"side":"offer","event_time":"2025-10-27T17:39:44.141223Z","price_level":"115675.57","new_quantity":"0.21983076"},{"side":"offer","event_time":"2025-10-27T17:39:44.141223Z","price_level":"115680","new_quantity":"1"},{"side":"offer","event_time":"2025-10-27T17:39:44.141223Z","price_level":"116105.26","new_quantity":"0.07007"},{"side":"offer","event_time":"2025-10-27T17:39:44.141223Z","price_level":"116108.32","new_quantity":"0"},{"side":"offer","event_time":"2025-10-27T17:39:44.141223Z","price_level":"116963.49","new_quantity":"0"}]}]}
{"channel":"l2_data","client_id":"","timestamp":"2025-10-27T17:39:44.218757038Z","sequence_num":137769,"events":[{"type":"update","product_id":"ETH-USD","updates":[{"side":"bid","event_time":"2025-10-27T17:39:44.162787Z","price_level":"4218.32","new_quantity":"1.07962826"},{"side":"bid","event_time":"2025-10-27T17:39:44.162787Z","price_level":"4218.28","new_quantity":"0"}]}]}
{"channel":"l2_data","client_id":"","timestamp":"2025-10-27T17:39:44.24836872Z","sequence_num":137770,"events":[{"type":"update","product_id":"BTC-USD","updates":[{"side":"bid","event_time":"2025-10-27T17:39:44.190826Z","price_level":"115615.92","new_quantity":"0"},{"side":"bid","event_time":"2025-10-27T17:39:44.190826Z","price_level":"115570.87","new_quantity":"0.76392319"},{"side":"bid","event_time":"2025-10-27T17:39:44.190826Z","price_level":"115570.86","new_quantity":"1.05802298"},{"side":"bid","event_time":"2025-10-27T17:39:44.190826Z","price_level":"115570.85","new_quantity":"0"},{"side":"bid","event_time":"2025-10-27T17:39:44.190826Z","price_level":"115552.15","new_quantity":"0.81389076"},{"side":"bid","event_time":"2025-10-27T17:39:44.190826Z","price_level":"115552.14","new_quantity":"1.16521675"},{"side":"bid","event_time":"2025-10-27T17:39:44.190826Z","price_level":"115552.13","new_quantity":"0"},{"side":"bid","event_time":"2025-10-27T17:39:44.190826Z","price_level":"115552.12","new_quantity":"0"},{"side":"bid","event_time":"2025-10-27T17:39:44.190826Z","price_level":"115178.33","new_quantity":"0.04719654"},{"side":"bid","event_time":"2025-10-27T17:39:44.190826Z","price_level":"115146.23","new_quantity":"0.02515774"},{"side":"bid","event_time":"2025-10-27T17:39:44.190826Z","price_level":"114981.53","new_quantity":"0"},{"side":"bid","event_time":"2025-10-27T17:39:44.190826Z","price_level":"114969.7","new_quantity":"0.05291289"},{"side":"bid","event_time":"2025-10-27T17:39:44.190826Z","price_level":"114950.58","new_quantity":"0.02593077"},{"side":"bid","event_time":"2025-10-27T17:39:44.190826Z","price_level":"114100.01","new_quantity":"0.07007"},{"side":"bid","event_time":"2025-10-27T17:39:44.190826Z","price_level":"114100","new_quantity":"0.03338652"},{"side":"bid","event_time":"2025-10-27T17:39:44.190826Z","price_level":"114099.95","new_quantity":"0"},{"side":"offer","event_time":"2025-10-27T17:39:44.190826Z","price_level":"115667","new_quantity":"0"},{"side":"offer","event_time":"2025-10-27T17:39:44.190826Z","price_level":"115668","new_quantity":"2"},{"side":"offer","event_time":"2025-10-27T17:39:44.190826Z","price_level":"115675.57","new_quantity":"0.21983076"},{"side":"offer","event_time":"2025-10-27T17:39:44.190826Z","price_level":"115680","new_quantity":"0"},{"side":"offer","event_time":"2025-10-27T17:39:44.190826Z","price_level":"116105.74","new_quantity":"0"}]}]}
{"channel":"l2_data","client_id":"","timestamp":"2025-10-27T17:39:44.270809753Z","sequence_num":137771,"events":[{"type":"update","product_id":"ETH-USD","updates":[{"side":"bid","event_time":"2025-10-27T17:39:44.215825Z","price_level":"4218.27","new_quantity":"0.00237065"},{"side":"bid","event_time":"2025-10-27T17:39:44.215825Z","price_level":"4218.1","new_quantity":"0.572"},{"side":"bid","event_time":"2025-10-27T17:39:44.215825Z","price_level":"4217.94","new_quantity":"0.002"},{"side":"offer","event_time":"2025-10-27T17:39:44.215825Z","price_level":"4218.36","new_quantity":"0"},{"side":"offer","event_time":"2025-10-27T17:39:44.215825Z","price_level":"4218.6","new_quantity":"0.69052295"},{"side":"offer","event_time":"2025-10-27T17:39:44.215825Z","price_level":"4223.82","new_quantity":"0.15388609"},{"side":"offer","event_time":"2025-10-27T17:39:44.215825Z","price_level":"4272.72","new_quantity":"0"},{"side":"offer","event_time":"2025-10-27T17:39:44.215825Z","price_level":"4272.99","new_quantity":"7.24649293"}]}]}
{"channel":"l2_data","client_id":"","timestamp":"2025-10-27T17:39:44.29753551Z","sequence_num":137772,"events":[{"type":"update","product_id":"BTC-USD","updates":[{"side":"bid","event_time":"2025-10-27T17:39:44.240204Z","price_level":"115570.5","new_quantity":"0"},{"side":"bid","event_time":"2025-10-27T17:39:44.240204Z","price_level":"115569","new_quantity":"1.5"},{"side":"offer","event_time":"2025-10-27T17:39:44.240204Z","price_level":"115667","new_quantity":"2"},{"side":"offer","event_time":"2025-10-27T17:39:44.240204Z","price_level":"115668","new_quantity":"2.4"},{"side":"offer","event_time":"2025-10-27T17:39:44.240204Z","price_level":"115675.57","new_quantity":"0.21983076"},{"side":"offer","event_time":"2025-10-27T17:39:44.240204Z","price_level":"115680","new_quantity":"1"},{"side":"offer","event_time":"2025-10-27T17:39:44.240204Z","price_level":"115718.3","new_quantity":"1"},{"side":"offer","event_time":"2025-10-27T17:39:44.240204Z","price_level":"115718.4","new_quantity":"0"},{"side":"offer","event_time":"2025-10-27T17:39:44.240204Z","price_level":"116320.06","new_quantity":"0.07007"},{"side":"offer","event_time":"2025-10-27T17:39:44.240204Z","price_level":"116323.56","new_quantity":"0"}]}]}
{"channel":"l2_data","client_id":"","timestamp":"2025-10-27T17:39:44.521085411Z","sequence_num":137784,"events":[{"type":"update","product_id":"ETH-USD","updates":[{"side":"bid","event_time":"2025-10-27T17:39:44.487681Z","price_level":"4217.6","new_quantity":"30"},{"side":"bid","event_time":"2025-10-27T17:39:44.487681Z","price_level":"4216.02","new_quantity":"0"},{"side":"bid","event_time":"2025-10-27T17:39:44.487681Z","price_level":"4214.54","new_quantity":"0"},{"side":"offer","event_time":"2025-10-27T17:39:44.487681Z","price_level":"4218.49","new_quantity":"1.12985397"},{"side":"offer","event_time":"2025-10-27T17:39:44.487681Z","price_level":"4220","new_quantity":"22.20517286"},{"side":"offer","event_time":"2025-10-27T17:39:44.487681Z","price_level":"4220.37","new_quantity":"4.389288"},{"side":"offer","event_time":"2025-10-27T17:39:44.487681Z","price_level":"4221.51","new_quantity":"1.94391607"},{"side":"offer","event_time":"2025-10-27T17:39:44.487681Z","price_level":"4221.85","new_quantity":"0.30652551"}]}]}
{"channel":"l2_data","client_id":"","timestamp":"2025-10-27T17:39:44.547049821Z","sequence_num":137785,"events":[{"type":"update","product_id":"BTC-USD","updates":[{"side":"bid","event_time":"2025-10-27T17:39:44.49331Z","price_level":"115620.65","new_quantity":"0.69009926"},{"side":"bid","event_time":"2025-10-27T17:39:44.49331Z","price_level":"115618","new_quantity":"0.4"},{"side":"bid","event_time":"2025-10-27T17:39:44.49331Z","price_level":"115616.01","new_quantity":"0.17749343"},{"side":"bid","event_time":"2025-10-27T17:39:44.49331Z","price_level":"115616","new_quantity":"0"},{"side":"bid","event_time":"2025-10-27T17:39:44.49331Z","price_level":"115614","new_quantity":"0"},{"side":"bid","event_time":"2025-10-27T17:39:44.49331Z","price_level":"115552.21","new_quantity":"0.81414849"},{"side":"bid","event_time":"2025-10-27T17:39:44.49331Z","price_level":"115552.2","new_quantity":"1.16521614"},{"side":"bid","event_time":"2025-10-27T17:39:44.49331Z","price_level":"115552.19","new_quantity":"0"},{"side":"bid","event_time":"2025-10-27T17:39:44.49331Z","price_level":"115552.18","new_quantity":"0"},{"side":"offer","event_time":"2025-10-27T17:39:44.49331Z","price_level":"115667","new_quantity":"2"},{"side":"offer","event_time":"2025-10-27T17:39:44.49331Z","price_level":"115668","new_quantity":"2.4"},{"side":"offer","event_time":"2025-10-27T17:39:44.49331Z","price_level":"115671","new_quantity":"0.30128617"},{"side":"offer","event_time":"2025-10-27T17:39:44.49331Z","price_level":"115673","new_quantity":"0.4"},{"side":"offer","event_time":"2025-10-27T17:39:44.49331Z","price_level":"115675.57","new_quantity":"0.21983076"},{"side":"offer","event_time":"2025-10-27T17:39:44.49331Z","price_level":"115680","new_quantity":"1"}]}]}
{"channel":"l2_data","client_id":"","timestamp":"2025-10-27T17:39:44.57043472Z","sequence_num":137786,"events":[{"type":"update","product_id":"ETH-USD","updates":[{"side":"bid","event_time":"2025-10-27T17:39:44.536933Z","price_level":"4217.6","new_quantity":"31.65784"},{"side":"offer","event_time":"2025-10-27T17:39:44.536933Z","price_level":"4218.33","new_quantity":"0.20234807"},{"side":"offer","event_time":"2025-10-27T17:39:44.536933Z","price_level":"4219.8","new_quantity":"20"}]}]}
{"channel":"l2_data","client_id":"","timestamp":"2025-10-27T17:39:44.59713939Z","sequence_num":137788,"events":[{"type":"update","product_id":"BTC-USD","updates":[{"side":"bid","event_time":"2025-10-27T17:39:44.542549Z","price_level":"115620.65","new_quantity":"0.4900743"},{"side":"bid","event_time":"2025-10-27T17:39:44.542549Z","price_level":"115618","new_quantity":"0"},{"side":"bid","event_time":"2025-10-27T17:39:44.542549Z","price_level":"115616.01","new_quantity":"1.55997228"},{"side":"bid","event_time":"2025-10-27T17:39:44.542549Z","price_level":"115616","new_quantity":"0.4"},{"side":"bid","event_time":"2025-10-27T17:39:44.542549Z","price_level":"114742.85","new_quantity":"0.07007"},{"side":"bid","event_time":"2025-10-27T17:39:44.542549Z","price_level":"114546.03","new_quantity":"0"},{"side":"bid","event_time":"2025-10-27T17:39:44.542549Z","price_level":"114099.56","new_quantity":"0.07007"},{"side":"offer","event_time":"2025-10-27T17:39:44.542549Z","price_level":"115667","new_quantity":"0"},{"side":"offer","event_time":"2025-10-27T17:39:44.542549Z","price_level":"115668","new_quantity":"2"},{"side":"offer","event_time":"2025-10-27T17:39:44.542549Z","price_level":"115671","new_quantity":"0.07164597"},{"side":"offer","event_time":"2025-10-27T17:39:44.542549Z","price_level":"115673","new_quantity":"0"},{"side":"offer","event_time":"2025-10-27T17:39:44.542549Z","price_level":"115675.57","new_quantity":"0.21983076"},{"side":"offer","event_time":"2025-10-27T17:39:44.542549Z","price_level":"115680","new_quantity":"1"},{"side":"offer","event_time":"2025-10-27T17:39:44.542549Z","price_level":"116319.73","new_quantity":"0.07007"},{"side":"offer","event_time":"2025-10-27T17:39:44.542549Z","price_level":"116963.02","new_quantity":"0.07007"},{"side":"offer","event_time":"2025-10-27T17:39:44.542549Z","price_level":"116963.3","new_quantity":"0"}]}]}
{"channel":"l2_data","client_id":"","timestamp":"2025-10-27T17:39:44.620957036Z","sequence_num":137789,"events":[{"type":"update","product_id":"ETH-USD","updates":[{"side":"bid","event_time":"2025-10-27T17:39:44.58387Z","price_level":"4218.1","new_quantity":"0.572"},{"side":"bid","event_time":"2025-10-27T17:39:44.58387Z","price_level":"4217.8","new_quantity":"14.229609"},{"side":"offer","event_time":"2025-10-27T17:39:44.58387Z","price_level":"4218.33","new_quantity":"0.03283009"},{"side":"offer","event_time":"2025-10-27T17:39:44.58387Z","price_level":"4221.53","new_quantity":"13.30167221"},{"side":"offer","event_time":"2025-10-27T17:39:44.58387Z","price_level":"4221.78","new_quantity":"0.00913674"}]}]}
