{"channel":"l2_data","client_id":"","timestamp":"2025-10-27T17:39:47.84755644Z","sequence_num":137935,"events":[{"type":"update","product_id":"BTC-USD","updates":[{"side":"bid","event_time":"2025-10-27T17:39:47.789878Z","price_level":"115638.62","new_quantity":"0"},{"side":"bid","event_time":"2025-10-27T17:39:47.789878Z","price_level":"115636.95","new_quantity":"0"},{"side":"bid","event_time":"2025-10-27T17:39:47.789878Z","price_level":"115636.29","new_quantity":"0.00973418"},{"side":"bid","event_time":"2025-10-27T17:39:47.789878Z","price_level":"115628.91","new_quantity":"0.0013972"},{"side":"bid","event_time":"2025-10-27T17:39:47.789878Z","price_level":"115627.46","new_quantity":"0"},{"side":"bid","event_time":"2025-10-27T17:39:47.789878Z","price_level":"115619.39","new_quantity":"0"},{"side":"bid","event_time":"2025-10-27T17:39:47.789878Z","price_level":"115612.62","new_quantity":"0.33125806"},{"side":"bid","event_time":"2025-10-27T17:39:47.789878Z","price_level":"115612.01","new_quantity":"0"},{"side":"bid","event_time":"2025-10-27T17:39:47.789878Z","price_level":"115600","new_quantity":"0.00001798"},{"side":"bid","event_time":"2025-10-27T17:39:47.789878Z","price_level":"115597.75","new_quantity":"0.53831232"},{"side":"bid","event_time":"2025-10-27T17:39:47.789878Z","price_level":"115597.73","new_quantity":"0"},{"side":"bid","event_time":"2025-10-27T17:39:47.789878Z","price_level":"115580.02","new_quantity":"0"},{"side":"bid","event_time":"2025-10-27T17:39:47.789878Z","price_level":"115570.51","new_quantity":"0.76392557"},{"side":"bid","event_time":"2025-10-27T17:39:47.789878Z","price_level":"115552.36","new_quantity":"1.16521453"},{"side":"bid","event_time":"2025-10-27T17:39:47.789878Z","price_level":"115552.35","new_quantity":"0"},{"side":"bid","event_time":"2025-10-27T17:39:47.789878Z","price_level":"115552.34","new_quantity":"0"},{"side":"bid","event_time":"2025-10-27T17:39:47.789878Z","price_level":"115552.03","new_quantity":"0.00043233"},{"side":"bid","event_time":"2025-10-27T17:39:47.789878Z","price_level":"115538.64","new_quantity":"0"},{"side":"bid","event_time":"2025-10-27T17:39:47.789878Z","price_level":"115534.45","new_quantity":"0.00043233"},{"side":"bid","event_time":"2025-10-27T17:39:47.789878Z","price_level":"115528.04","new_quantity":"0"},{"side":"offer","event_time":"2025-10-27T17:39:47.789878Z","price_level":"115643.53","new_quantity":"0.25863009"},{"side":"offer","event_time":"2025-10-27T17:39:47.789878Z","price_level":"115656.03","new_quantity":"0.00007786"},{"side":"offer","event_time":"2025-10-27T17:39:47.789878Z","price_level":"115656.04","new_quantity":"0.00432"},{"side":"offer","event_time":"2025-10-27T17:39:47.789878Z","price_level":"115656.05","new_quantity":"0.00432"},{"side":"offer","event_time":"2025-10-27T17:39:47.789878Z","price_level":"115656.32","new_quantity":"0"},{"side":"offer","event_time":"2025-10-27T17:39:47.789878Z","price_level":"115660.68","new_quantity":"0"},{"side":"offer","event_time":"2025-10-27T17:39:47.789878Z","price_level":"115660.69","new_quantity":"0"},{"side":"offer","event_time":"2025-10-27T17:39:47.789878Z","price_level":"115662","new_quantity":"2"},{"side":"offer","event_time":"2025-10-27T17:39:47.789878Z","price_level":"115666","new_quantity":"0.4"},{"side":"offer","event_time":"2025-10-27T17:39:47.789878Z","price_level":"115703.27","new_quantity":"0"},{"side":"offer","event_time":"2025-10-27T17:39:47.789878Z","price_level":"115705.94","new_quantity":"0.00043233"},{"side":"offer","event_time":"2025-10-27T17:39:47.789878Z","price_level":"115713.38","new_quantity":"0"},{"side":"offer","event_time":"2025-10-27T17:39:47.789878Z","price_level":"115715.59","new_quantity":"0.00043233"}]}]}
{"channel":"l2_data","client_id":"","timestamp":"2025-10-27T17:39:47.87298349Z","sequence_num":137937,"events":[{"type":"update","product_id":"ETH-USD","updates":[{"side":"bid","event_time":"2025-10-27T17:39:47.829236Z","price_level":"4218.13","new_quantity":"0"},{"side":"bid","event_time":"2025-10-27T17:39:47.829236Z","price_level":"4218.11","new_quantity":"0"},{"side":"bid","event_time":"2025-10-27T17:39:47.829236Z","price_level":"4218.1","new_quantity":"0"},{"side":"bid","event_time":"2025-10-27T17:39:47.829236Z","price_level":"4218.08","new_quantity":"0"},{"side":"bid","event_time":"2025-10-27T17:39:47.829236Z","price_level":"4217.82","new_quantity":"0"},{"side":"bid","event_time":"2025-10-27T17:39:47.829236Z","price_level":"4217.81","new_quantity":"0.02070633"},{"side":"bid","event_time":"2025-10-27T17:39:47.829236Z","price_level":"4217.67","new_quantity":"0"},{"side":"bid","event_time":"2025-10-27T17:39:47.829236Z","price_level":"4217.63","new_quantity":"1.65853"},{"side":"bid","event_time":"2025-10-27T17:39:47.829236Z","price_level":"4217.57","new_quantity":"0"},{"side":"bid","event_time":"2025-10-27T17:39:47.829236Z","price_level":"4217.45","new_quantity":"0.11855482"},{"side":"bid","event_time":"2025-10-27T17:39:47.829236Z","price_level":"4217.43","new_quantity":"10"},{"side":"bid","event_time":"2025-10-27T17:39:47.829236Z","price_level":"4217.08","new_quantity":"0"},{"side":"bid","event_time":"2025-10-27T17:39:47.829236Z","price_level":"4217.01","new_quantity":"5.92259026"},{"side":"bid","event_time":"2025-10-27T17:39:47.829236Z","price_level":"4216.99","new_quantity":"0.59283878"},{"side":"bid","event_time":"2025-10-27T17:39:47.829236Z","price_level":"4216.36","new_quantity":"4.77355712"},{"side":"bid","event_time":"2025-10-27T17:39:47.829236Z","price_level":"4215.01","new_quantity":"3.9449227"},{"side":"bid","event_time":"2025-10-27T17:39:47.829236Z","price_level":"4214.78","new_quantity":"0"},{"side":"bid","event_time":"2025-10-27T17:39:47.829236Z","price_level":"4214.51","new_quantity":"8.13105423"},{"side":"bid","event_time":"2025-10-27T17:39:47.829236Z","price_level":"4212.69","new_quantity":"0"},{"side":"bid","event_time":"2025-10-27T17:39:47.829236Z","price_level":"4212.01","new_quantity":"18.00613775"},{"side":"bid","event_time":"2025-10-27T17:39:47.829236Z","price_level":"4210.77","new_quantity":"0"},{"side":"offer","event_time":"2025-10-27T17:39:47.829236Z","price_level":"4218.07","new_quantity":"0.59268895"},{"side":"offer","event_time":"2025-10-27T17:39:47.829236Z","price_level":"4218.08","new_quantity":"0.178"},{"side":"offer","event_time":"2025-10-27T17:39:47.829236Z","price_level":"4218.09","new_quantity":"0.3364591"},{"side":"offer","event_time":"2025-10-27T17:39:47.829236Z","price_level":"4218.1","new_quantity":"0.9196991"},{"side":"offer","event_time":"2025-10-27T17:39:47.829236Z","price_level":"4218.11","new_quantity":"0.3456991"},{"side":"offer","event_time":"2025-10-27T17:39:47.829236Z","price_level":"4218.13","new_quantity":"0.1696991"},{"side":"offer","event_time":"2025-10-27T17:39:47.829236Z","price_level":"4218.14","new_quantity":"0"},{"side":"offer","event_time":"2025-10-27T17:39:47.829236Z","price_level":"4218.24","new_quantity":"0.66378393"},{"side":"offer","event_time":"2025-10-27T17:39:47.829236Z","price_level":"4219.33","new_quantity":"2.9270726"},{"side":"offer","event_time":"2025-10-27T17:39:47.829236Z","price_level":"4219.37","new_quantity":"3.846613"},{"side":"offer","event_time":"2025-10-27T17:39:47.829236Z","price_level":"4220.15","new_quantity":"8.12664674"},{"side":"offer","event_time":"2025-10-27T17:39:47.829236Z","price_level":"4220.35","new_quantity":"0"},{"side":"offer","event_time":"2025-10-27T17:39:47.829236Z","price_level":"4221.33","new_quantity":"1.98177908"},{"side":"offer","event_time":"2025-10-27T17:39:47.829236Z","price_level":"4221.34","new_quantity":"0"},{"side":"offer","event_time":"2025-10-27T17:39:47.829236Z","price_level":"4221.35","new_quantity":"0"},{"side":"offer","event_time":"2025-10-27T17:39:47.829236Z","price_level":"4221.51","new_quantity":"13.30173523"}]}]}
{"channel":"l2_data","client_id":"","timestamp":"2025-10-27T17:39:47.898215278Z","sequence_num":137939,"events":[{"type":"update","product_id":"BTC-USD","updates":[{"side":"bid","event_time":"2025-10-27T17:39:47.843048Z","price_level":"115618.61","new_quantity":"0.04"},{"side":"bid","event_time":"2025-10-27T17:39:47.843048Z","price_level":"115534.45","new_quantity":"0"},{"side":"offer","event_time":"2025-10-27T17:39:47.843048Z","price_level":"115661","new_quantity":"2"},{"side":"offer","event_time":"2025-10-27T17:39:47.843048Z","price_level":"115662","new_quantity":"0"},{"side":"offer","event_time":"2025-10-27T17:39:47.843048Z","price_level":"115665","new_quantity":"0.4"},{"side":"offer","event_time":"2025-10-27T17:39:47.843048Z","price_level":"115666","new_quantity":"0"},{"side":"offer","event_time":"2025-10-27T17:39:47.843048Z","price_level":"115705.94","new_quantity":"0"},{"side":"offer","event_time":"2025-10-27T17:39:47.843048Z","price_level":"115709.23","new_quantity":"0"},{"side":"offer","event_time":"2025-10-27T17:39:47.843048Z","price_level":"115713.37","new_quantity":"0.00043237"},{"side":"offer","event_time":"2025-10-27T17:39:47.843048Z","price_level":"115715.59","new_quantity":"0"}]}]}
{"channel":"l2_data","client_id":"","timestamp":"2025-10-27T17:39:47.920994183Z","sequence_num":137940,"events":[{"type":"update","product_id":"ETH-USD","updates":[{"side":"bid","event_time":"2025-10-27T17:39:47.86284Z","price_level":"4218","new_quantity":"0.0033708"},{"side":"bid","event_time":"2025-10-27T17:39:47.86284Z","price_level":"4216.36","new_quantity":"1.49939179"},{"side":"bid","event_time":"2025-10-27T17:39:47.86284Z","price_level":"4216.26","new_quantity":"0"},{"side":"bid","event_time":"2025-10-27T17:39:47.86284Z","price_level":"4191.59","new_quantity":"0.1536"},{"side":"offer","event_time":"2025-10-27T17:39:47.86284Z","price_level":"4218.01","new_quantity":"0.46623841"},{"side":"offer","event_time":"2025-10-27T17:39:47.86284Z","price_level":"4218.08","new_quantity":"0"},{"side":"offer","event_time":"2025-10-27T17:39:47.86284Z","price_level":"4218.09","new_quantity":"0.16876"},{"side":"offer","event_time":"2025-10-27T17:39:47.86284Z","price_level":"4218.1","new_quantity":"0.572"},{"side":"offer","event_time":"2025-10-27T17:39:47.86284Z","price_level":"4218.11","new_quantity":"0"},{"side":"offer","event_time":"2025-10-27T17:39:47.86284Z","price_level":"4218.13","new_quantity":"0"},{"side":"offer","event_time":"2025-10-27T17:39:47.86284Z","price_level":"4218.19","new_quantity":"0.00237066"},{"side":"offer","event_time":"2025-10-27T17:39:47.86284Z","price_level":"4218.23","new_quantity":"0"},{"side":"offer","event_time":"2025-10-27T17:39:47.86284Z","price_level":"4218.44","new_quantity":"1.66237578"},{"side":"offer","event_time":"2025-10-27T17:39:47.86284Z","price_level":"4218.63","new_quantity":"0.01508562"},{"side":"offer","event_time":"2025-10-27T17:39:47.86284Z","price_level":"4218.68","new_quantity":"0"},{"side":"offer","event_time":"2025-10-27T17:39:47.86284Z","price_level":"4218.98","new_quantity":"1.6466"},{"side":"offer","event_time":"2025-10-27T17:39:47.86284Z","price_level":"4222.53","new_quantity":"9.20532832"},{"side":"offer","event_time":"2025-10-27T17:39:47.86284Z","price_level":"4222.59","new_quantity":"0"}]}]}
{"channel":"l2_data","client_id":"","timestamp":"2025-10-27T17:39:47.94456024Z","sequence_num":137942,"events":[{"type":"update","product_id":"BTC-USD","updates":[{"side":"offer","event_time":"2025-10-27T17:39:47.899043Z","price_level":"115656.32","new_quantity":"0"},{"side":"offer","event_time":"2025-10-27T17:39:47.899043Z","price_level":"115661","new_quantity":"0"},{"side":"offer","event_time":"2025-10-27T17:39:47.899043Z","price_level":"115661.57","new_quantity":"0.00303376"},{"side":"offer","event_time":"2025-10-27T17:39:47.899043Z","price_level":"115665","new_quantity":"0"},{"side":"offer","event_time":"2025-10-27T17:39:47.899043Z","price_level":"115718.3","new_quantity":"0"},{"side":"offer","event_time":"2025-10-27T17:39:47.899043Z","price_level":"115718.9","new_quantity":"1"}]}]}
{"channel":"l2_data","client_id":"","timestamp":"2025-10-27T17:39:47.971737049Z","sequence_num":137943,"events":[{"type":"update","product_id":"ETH-USD","updates":[{"side":"bid","event_time":"2025-10-27T17:39:47.927782Z","price_level":"4217.59","new_quantity":"0.11855087"},{"side":"bid","event_time":"2025-10-27T17:39:47.927782Z","price_level":"4217.45","new_quantity":"0"},{"side":"bid","event_time":"2025-10-27T17:39:47.927782Z","price_level":"4217.42","new_quantity":"0"},{"side":"bid","event_time":"2025-10-27T17:39:47.927782Z","price_level":"4217.36","new_quantity":"0.59278673"},{"side":"bid","event_time":"2025-10-27T17:39:47.927782Z","price_level":"4217.28","new_quantity":"0.59279786"},{"side":"bid","event_time":"2025-10-27T17:39:47.927782Z","price_level":"4216.99","new_quantity":"0"},{"side":"offer","event_time":"2025-10-27T17:39:47.927782Z","price_level":"4218.09","new_quantity":"0"},{"side":"offer","event_time":"2025-10-27T17:39:47.927782Z","price_level":"4221.1","new_quantity":"1.94391607"},{"side":"offer","event_time":"2025-10-27T17:39:47.927782Z","price_level":"4221.32","new_quantity":"13.30233394"},{"side":"offer","event_time":"2025-10-27T17:39:47.927782Z","price_level":"4221.33","new_quantity":"0.03786301"},{"side":"offer","event_time":"2025-10-27T17:39:47.927782Z","price_level":"4221.51","new_quantity":"0"}]}]}
{"channel":"l2_data","client_id":"","timestamp":"2025-10-27T17:39:47.997514016Z","sequence_num":137944,"events":[{"type":"update","product_id":"BTC-USD","updates":[{"side":"bid","event_time":"2025-10-27T17:39:47.954708Z","price_level":"115643.52","new_quantity":"0"},{"side":"bid","event_time":"2025-10-27T17:39:47.954708Z","price_level":"115638.6","new_quantity":"0"},{"side":"bid","event_time":"2025-10-27T17:39:47.954708Z","price_level":"115638","new_quantity":"0.10833279"},{"side":"bid","event_time":"2025-10-27T17:39:47.954708Z","price_level":"115636.74","new_quantity":"0.0203"},{"side":"bid","event_time":"2025-10-27T17:39:47.954708Z","price_level":"115627.46","new_quantity":"0.00097312"},{"side":"bid","event_time":"2025-10-27T17:39:47.954708Z","price_level":"115626.4","new_quantity":"0"},{"side":"bid","event_time":"2025-10-27T17:39:47.954708Z","price_level":"115538.65","new_quantity":"0.00043233"},{"side":"offer","event_time":"2025-10-27T17:39:47.954708Z","price_level":"115638.01","new_quantity":"0.005"},{"side":"offer","event_time":"2025-10-27T17:39:47.954708Z","price_level":"115643.52","new_quantity":"0.04919308"},{"side":"offer","event_time":"2025-10-27T17:39:47.954708Z","price_level":"115656.03","new_quantity":"0.02007786"},{"side":"offer","event_time":"2025-10-27T17:39:47.954708Z","price_level":"115656.32","new_quantity":"0.02"},{"side":"offer","event_time":"2025-10-27T17:39:47.954708Z","price_level":"115675.77","new_quantity":"0.83207"},{"side":"offer","event_time":"2025-10-27T17:39:47.954708Z","price_level":"115709.22","new_quantity":"0.00043233"},{"side":"offer","event_time":"2025-10-27T17:39:47.954708Z","price_level":"115718.29","new_quantity":"0.00043233"}]}]}
{"channel":"l2_data","client_id":"","timestamp":"2025-10-27T17:39:48.020649082Z","sequence_num":137945,"events":[{"type":"update","product_id":"ETH-USD","updates":[{"side":"bid","event_time":"2025-10-27T17:39:47.947793Z","price_level":"4217.22","new_quantity":"0.62305959"},{"side":"bid","event_time":"2025-10-27T17:39:47.947793Z","price_level":"4217.01","new_quantity":"0"},{"side":"bid","event_time":"2025-10-27T17:39:47.947793Z","price_level":"4217","new_quantity":"5.39010512"},{"side":"bid","event_time":"2025-10-27T17:39:47.947793Z","price_level":"4216.93","new_quantity":"6.3969813"},{"side":"offer","event_time":"2025-10-27T17:39:47.947793Z","price_level":"4218.63","new_quantity":"0"},{"side":"offer","event_time":"2025-10-27T17:39:47.947793Z","price_level":"4218.68","new_quantity":"0.01508562"},{"side":"offer","event_time":"2025-10-27T17:39:47.947793Z","price_level":"4219.09","new_quantity":"1.4"}]}]}
{"channel":"l2_data","client_id":"","timestamp":"2025-10-27T17:39:48.047545453Z","sequence_num":137946,"events":[{"type":"update","product_id":"BTC-USD","updates":[{"side":"bid","event_time":"2025-10-27T17:39:48.004537Z","price_level":"115638.16","new_quantity":"0.00745029"},{"side":"bid","event_time":"2025-10-27T17:39:48.004537Z","price_level":"115638","new_quantity":"0"},{"side":"bid","event_time":"2025-10-27T17:39:48.004537Z","price_level":"115634.02","new_quantity":"0"},{"side":"bid","event_time":"2025-10-27T17:39:48.004537Z","price_level":"115634.01","new_quantity":"0.07321915"},{"side":"bid","event_time":"2025-10-27T17:39:48.004537Z","price_level":"115631.93","new_quantity":"0"},{"side":"bid","event_time":"2025-10-27T17:39:48.004537Z","price_level":"115631.92","new_quantity":"0.012556"},{"side":"bid","event_time":"2025-10-27T17:39:48.004537Z","price_level":"115629.7","new_quantity":"0"},{"side":"bid","event_time":"2025-10-27T17:39:48.004537Z","price_level":"115628.91","new_quantity":"0.00172967"},{"side":"bid","event_time":"2025-10-27T17:39:48.004537Z","price_level":"115628.34","new_quantity":"0.02161105"},{"side":"bid","event_time":"2025-10-27T17:39:48.004537Z","price_level":"115627.46","new_quantity":"0"},{"side":"bid","event_time":"2025-10-27T17:39:48.004537Z","price_level":"115620.65","new_quantity":"0.48603951"},{"side":"bid","event_time":"2025-10-27T17:39:48.004537Z","price_level":"115618.95","new_quantity":"0.16524"},{"side":"bid","event_time":"2025-10-27T17:39:48.004537Z","price_level":"115617.65","new_quantity":"0"},{"side":"bid","event_time":"2025-10-27T17:39:48.004537Z","price_level":"115617.07","new_quantity":"0.96282465"},{"side":"bid","event_time":"2025-10-27T17:39:48.004537Z","price_level":"115617.06","new_quantity":"0.635384"},{"side":"bid","event_time":"2025-10-27T17:39:48.004537Z","price_level":"115616.82","new_quantity":"0"},{"side":"bid","event_time":"2025-10-27T17:39:48.004537Z","price_level":"115612.62","new_quantity":"0"},{"side":"bid","event_time":"2025-10-27T17:39:48.004537Z","price_level":"115612","new_quantity":"0"},{"side":"bid","event_time":"2025-10-27T17:39:48.004537Z","price_level":"115610.02","new_quantity":"0.33126551"},{"side":"bid","event_time":"2025-10-27T17:39:48.004537Z","price_level":"115597.75","new_quantity":"0"},{"side":"bid","event_time":"2025-10-27T17:39:48.004537Z","price_level":"115590.78","new_quantity":"0.53834478"},{"side":"offer","event_time":"2025-10-27T17:39:48.004537Z","price_level":"115638.01","new_quantity":"0"},{"side":"offer","event_time":"2025-10-27T17:39:48.004537Z","price_level":"115638.17","new_quantity":"0.02832579"},{"side":"offer","event_time":"2025-10-27T17:39:48.004537Z","price_level":"115643.47","new_quantity":"0.25941803"},{"side":"offer","event_time":"2025-10-27T17:39:48.004537Z","price_level":"115643.51","new_quantity":"0.005"},{"side":"offer","event_time":"2025-10-27T17:39:48.004537Z","price_level":"115643.52","new_quantity":"0.02"},{"side":"offer","event_time":"2025-10-27T17:39:48.004537Z","price_level":"115643.53","new_quantity":"0.25296929"},{"side":"offer","event_time":"2025-10-27T17:39:48.004537Z","price_level":"115649.58","new_quantity":"0.1425"},{"side":"offer","event_time":"2025-10-27T17:39:48.004537Z","price_level":"115652.18","new_quantity":"0.16456"},{"side":"offer","event_time":"2025-10-27T17:39:48.004537Z","price_level":"115654.64","new_quantity":"0.02"},{"side":"offer","event_time":"2025-10-27T17:39:48.004537Z","price_level":"115656.02","new_quantity":"0.00007808"},{"side":"offer","event_time":"2025-10-27T17:39:48.004537Z","price_level":"115656.03","new_quantity":"0.02"},{"side":"offer","event_time":"2025-10-27T17:39:48.004537Z","price_level":"115656.32","new_quantity":"0.02"},{"side":"offer","event_time":"2025-10-27T17:39:48.004537Z","price_level":"115661.57","new_quantity":"0"},{"side":"offer","event_time":"2025-10-27T17:39:48.004537Z","price_level":"115664.48","new_quantity":"0.627668"},{"side":"offer","event_time":"2025-10-27T17:39:48.004537Z","price_level":"115664.99","new_quantity":"0.38913456"},{"side":"offer","event_time":"2025-10-27T17:39:48.004537Z","price_level":"115666","new_quantity":"0"},{"side":"offer","event_time":"2025-10-27T17:39:48.004537Z","price_level":"115669.98","new_quantity":"0"},{"side":"offer","event_time":"2025-10-27T17:39:48.004537Z","price_level":"115689.73","new_quantity":"0.16812954"},{"side":"offer","event_time":"2025-10-27T17:39:48.004537Z","price_level":"115694.05","new_quantity":"0"},{"side":"offer","event_time":"2025-10-27T17:39:48.004537Z","price_level":"115705.5","new_quantity":"0.25575097"},{"side":"offer","event_time":"2025-10-27T17:39:48.004537Z","price_level":"115709.99","new_quantity":"0"},{"side":"offer","event_time":"2025-10-27T17:39:48.004537Z","price_level":"115719.94","new_quantity":"0.56831292"},{"side":"offer","event_time":"2025-10-27T17:39:48.004537Z","price_level":"115727.15","new_quantity":"0"}]}]}
{"channel":"l2_data","client_id":"","timestamp":"2025-10-27T17:39:48.07073569Z","sequence_num":137947,"events":[{"type":"update","product_id":"ETH-USD","updates":[{"side":"bid","event_time":"2025-10-27T17:39:48.027383Z","price_level":"4218","new_quantity":"0.07446747"},{"side":"bid","event_time":"2025-10-27T17:39:48.027383Z","price_level":"4169.88","new_quantity":"0"},{"side":"offer","event_time":"2025-10-27T17:39:48.027383Z","price_level":"4221.01","new_quantity":"0.05926418"},{"side":"offer","event_time":"2025-10-27T17:39:48.027383Z","price_level":"4221.32","new_quantity":"0"},{"side":"offer","event_time":"2025-10-27T17:39:48.027383Z","price_level":"4221.44","new_quantity":"0.05926418"},{"side":"offer","event_time":"2025-10-27T17:39:48.027383Z","price_level":"4221.51","new_quantity":"13.30173523"},{"side":"offer","event_time":"2025-10-27T17:39:48.027383Z","price_level":"4221.86","new_quantity":"0.15760455"}]}]}
{"channel":"l2_data","client_id":"","timestamp":"2025-10-27T17:39:48.098022297Z","sequence_num":137949,"events":[{"type":"update","product_id":"BTC-USD","updates":[{"side":"bid","event_time":"2025-10-27T17:39:48.030377Z","price_level":"115617.06","new_quantity":"0"},{"side":"bid","event_time":"2025-10-27T17:39:48.030377Z","price_level":"115611","new_quantity":"2"},{"side":"bid","event_time":"2025-10-27T17:39:48.030377Z","price_level":"114361.76","new_quantity":"0"},{"side":"bid","event_time":"2025-10-27T17:39:48.030377Z","price_level":"113804.88","new_quantity":"0"},{"side":"bid","event_time":"2025-10-27T17:39:48.030377Z","price_level":"113247.99","new_quantity":"0"},{"side":"offer","event_time":"2025-10-27T17:39:48.030377Z","price_level":"115656.03","new_quantity":"0"},{"side":"offer","event_time":"2025-10-27T17:39:48.030377Z","price_level":"115656.32","new_quantity":"0"},{"side":"offer","event_time":"2025-10-27T17:39:48.030377Z","price_level":"115664.48","new_quantity":"0"},{"side":"offer","event_time":"2025-10-27T17:39:48.030377Z","price_level":"115664.99","new_quantity":"0"},{"side":"offer","event_time":"2025-10-27T17:39:48.030377Z","price_level":"115669.98","new_quantity":"0.38913447"}]}]}
{"channel":"l2_data","client_id":"","timestamp":"2025-10-27T17:39:48.121116109Z","sequence_num":137951,"events":[{"type":"update","product_id":"ETH-USD","updates":[{"side":"bid","event_time":"2025-10-27T17:39:48.069555Z","price_level":"4217.24","new_quantity":"2.12367593"},{"side":"bid","event_time":"2025-10-27T17:39:48.069555Z","price_level":"4216.88","new_quantity":"0"},{"side":"bid","event_time":"2025-10-27T17:39:48.069555Z","price_level":"4170.16","new_quantity":"0"},{"side":"bid","event_time":"2025-10-27T17:39:48.069555Z","price_level":"4150.03","new_quantity":"0"},{"side":"bid","event_time":"2025-10-27T17:39:48.069555Z","price_level":"4149.61","new_quantity":"0"},{"side":"bid","event_time":"2025-10-27T17:39:48.069555Z","price_level":"4129.91","new_quantity":"0"},{"side":"bid","event_time":"2025-10-27T17:39:48.069555Z","price_level":"4129.34","new_quantity":"0"},{"side":"offer","event_time":"2025-10-27T17:39:48.069555Z","price_level":"4218.01","new_quantity":"0.11853931"}]}]}
{"channel":"l2_data","client_id":"","timestamp":"2025-10-27T17:39:46.64799206Z","sequence_num":137882,"events":[{"type":"update","product_id":"BTC-USD","updates":[{"side":"bid","event_time":"2025-10-27T17:39:46.579183Z","price_level":"115638.6","new_quantity":"0.11156606"},{"side":"bid","event_time":"2025-10-27T17:39:46.579183Z","price_level":"115627.31","new_quantity":"0"},{"side":"bid","event_time":"2025-10-27T17:39:46.579183Z","price_level":"115623.63","new_quantity":"0"},{"side":"bid","event_time":"2025-10-27T17:39:46.579183Z","price_level":"115623.6","new_quantity":"0"},{"side":"bid","event_time":"2025-10-27T17:39:46.579183Z","price_level":"115621.31","new_quantity":"0.00432"},{"side":"bid","event_time":"2025-10-27T17:39:46.579183Z","price_level":"115617","new_quantity":"0"},{"side":"bid","event_time":"2025-10-27T17:39:46.579183Z","price_level":"115613.01","new_quantity":"0.33125695"},{"side":"bid","event_time":"2025-10-27T17:39:46.579183Z","price_level":"115610.02","new_quantity":"0"},{"side":"bid","event_time":"2025-10-27T17:39:46.579183Z","price_level":"115580.02","new_quantity":"0.76386271"},{"side":"bid","event_time":"2025-10-27T17:39:46.579183Z","price_level":"115569.21","new_quantity":"0"},{"side":"bid","event_time":"2025-10-27T17:39:46.579183Z","price_level":"114532.04","new_quantity":"0.07007"},{"side":"bid","event_time":"2025-10-27T17:39:46.579183Z","price_level":"114531.99","new_quantity":"0"},{"side":"bid","event_time":"2025-10-27T17:39:46.579183Z","price_level":"114319.77","new_quantity":"0.00004591"},{"side":"offer","event_time":"2025-10-27T17:39:46.579183Z","price_level":"115641.81","new_quantity":"0.02594217"},{"side":"offer","event_time":"2025-10-27T17:39:46.579183Z","price_level":"115644.2","new_quantity":"0"},{"side":"offer","event_time":"2025-10-27T17:39:46.579183Z","price_level":"115647.51","new_quantity":"0.00112836"},{"side":"offer","event_time":"2025-10-27T17:39:46.579183Z","price_level":"115660.68","new_quantity":"0.00432"},{"side":"offer","event_time":"2025-10-27T17:39:46.579183Z","price_level":"115660.69","new_quantity":"0"},{"side":"offer","event_time":"2025-10-27T17:39:46.579183Z","price_level":"115663","new_quantity":"2"},{"side":"offer","event_time":"2025-10-27T17:39:46.579183Z","price_level":"115663.01","new_quantity":"0"},{"side":"offer","event_time":"2025-10-27T17:39:46.579183Z","price_level":"115673.75","new_quantity":"0.13835478"},{"side":"offer","event_time":"2025-10-27T17:39:46.579183Z","price_level":"115677.9","new_quantity":"0"},{"side":"offer","event_time":"2025-10-27T17:39:46.579183Z","price_level":"115689.73","new_quantity":"0.16812954"},{"side":"offer","event_time":"2025-10-27T17:39:46.579183Z","price_level":"115694.05","new_quantity":"0"},{"side":"offer","event_time":"2025-10-27T17:39:46.579183Z","price_level":"115706.38","new_quantity":"0.25574902"},{"side":"offer","event_time":"2025-10-27T17:39:46.579183Z","price_level":"115709.99","new_quantity":"0"},{"side":"offer","event_time":"2025-10-27T17:39:46.579183Z","price_level":"116752.16","new_quantity":"0.07007"},{"side":"offer","event_time":"2025-10-27T17:39:46.579183Z","price_level":"116753.93","new_quantity":"0"},{"side":"offer","event_time":"2025-10-27T17:39:46.579183Z","price_level":"116968.56","new_quantity":"0"}]}]}
{"channel":"l2_data","client_id":"","timestamp":"2025-10-27T17:39:46.821146009Z","sequence_num":137889,"events":[{"type":"update","product_id":"ETH-USD","updates":[{"side":"bid","event_time":"2025-10-27T17:39:46.775915Z","price_level":"4217.82","new_quantity":"0.02307723"},{"side":"bid","event_time":"2025-10-27T17:39:46.775915Z","price_level":"4217.55","new_quantity":"0"},{"side":"bid","event_time":"2025-10-27T17:39:46.775915Z","price_level":"4216.6","new_quantity":"0.80050522"},{"side":"offer","event_time":"2025-10-27T17:39:46.775915Z","price_level":"4221.45","new_quantity":"1.94391607"},{"side":"offer","event_time":"2025-10-27T17:39:46.775915Z","price_level":"4221.46","new_quantity":"13.30189278"},{"side":"offer","event_time":"2025-10-27T17:39:46.775915Z","price_level":"4221.47","new_quantity":"0"},{"side":"offer","event_time":"2025-10-27T17:39:46.775915Z","price_level":"4221.48","new_quantity":"0"},{"side":"offer","event_time":"2025-10-27T17:39:46.775915Z","price_level":"4244.82","new_quantity":"0"}]}]}
{"channel":"l2_data","client_id":"","timestamp":"2025-10-27T17:39:46.846695346Z","sequence_num":137891,"events":[{"type":"update","product_id":"BTC-USD","updates":[{"side":"bid","event_time":"2025-10-27T17:39:46.789575Z","price_level":"115616.82","new_quantity":"1.72601295"},{"side":"bid","event_time":"2025-10-27T17:39:46.789575Z","price_level":"115612","new_quantity":"2"},{"side":"bid","event_time":"2025-10-27T17:39:46.789575Z","price_level":"115573.11","new_quantity":"0.76390838"},{"side":"bid","event_time":"2025-10-27T17:39:46.789575Z","price_level":"115573.1","new_quantity":"1.5"},{"side":"bid","event_time":"2025-10-27T17:39:46.789575Z","price_level":"115572.61","new_quantity":"0"},{"side":"bid","event_time":"2025-10-27T17:39:46.789575Z","price_level":"115572.6","new_quantity":"0"},{"side":"offer","event_time":"2025-10-27T17:39:46.789575Z","price_level":"115647.51","new_quantity":"0"},{"side":"offer","event_time":"2025-10-27T17:39:46.789575Z","price_level":"115647.52","new_quantity":"0.00186746"}]}]}
{"channel":"l2_data","client_id":"","timestamp":"2025-10-27T17:39:46.870896984Z","sequence_num":137892,"events":[{"type":"update","product_id":"ETH-USD","updates":[{"side":"bid","event_time":"2025-10-27T17:39:46.827132Z","price_level":"4218.21","new_quantity":"0"},{"side":"bid","event_time":"2025-10-27T17:39:46.827132Z","price_level":"4218.16","new_quantity":"0.07109662"},{"side":"bid","event_time":"2025-10-27T17:39:46.827132Z","price_level":"4217.82","new_quantity":"0.02070633"},{"side":"bid","event_time":"2025-10-27T17:39:46.827132Z","price_level":"4217.81","new_quantity":"0.0023709"},{"side":"bid","event_time":"2025-10-27T17:39:46.827132Z","price_level":"4216.36","new_quantity":"1.49939179"},{"side":"bid","event_time":"2025-10-27T17:39:46.827132Z","price_level":"4215.06","new_quantity":"6.43493519"},{"side":"bid","event_time":"2025-10-27T17:39:46.827132Z","price_level":"4212.01","new_quantity":"7.10500994"},{"side":"offer","event_time":"2025-10-27T17:39:46.827132Z","price_level":"4219.33","new_quantity":"1.5153169"},{"side":"offer","event_time":"2025-10-27T17:39:46.827132Z","price_level":"4223.2","new_quantity":"0.47357454"},{"side":"offer","event_time":"2025-10-27T17:39:46.827132Z","price_level":"4223.33","new_quantity":"0"},{"side":"offer","event_time":"2025-10-27T17:39:46.827132Z","price_level":"4225.94","new_quantity":"0.82857379"},{"side":"offer","event_time":"2025-10-27T17:39:46.827132Z","price_level":"4226.08","new_quantity":"0"}]}]}
{"channel":"l2_data","client_id":"","timestamp":"2025-10-27T17:39:46.897865691Z","sequence_num":137893,"events":[{"type":"update","product_id":"BTC-USD","updates":[{"side":"bid","event_time":"2025-10-27T17:39:46.842888Z","price_level":"115638.01","new_quantity":"0"},{"side":"bid","event_time":"2025-10-27T17:39:46.842888Z","price_level":"115634.02","new_quantity":"0.00172959"},{"side":"bid","event_time":"2025-10-27T17:39:46.842888Z","price_level":"115627.31","new_quantity":"0"},{"side":"bid","event_time":"2025-10-27T17:39:46.842888Z","price_level":"115625.17","new_quantity":"0"},{"side":"bid","event_time":"2025-10-27T17:39:46.842888Z","price_level":"115619.39","new_quantity":"0.16549"},{"side":"bid","event_time":"2025-10-27T17:39:46.842888Z","price_level":"115606.16","new_quantity":"0"},{"side":"offer","event_time":"2025-10-27T17:39:46.842888Z","price_level":"115643.53","new_quantity":"0.2594179"},{"side":"offer","event_time":"2025-10-27T17:39:46.842888Z","price_level":"115647.5","new_quantity":"0"},{"side":"offer","event_time":"2025-10-27T17:39:46.842888Z","price_level":"115647.52","new_quantity":"0"},{"side":"offer","event_time":"2025-10-27T17:39:46.842888Z","price_level":"115651.82","new_quantity":"0.00007649"},{"side":"offer","event_time":"2025-10-27T17:39:46.842888Z","price_level":"115653.59","new_quantity":"0"},{"side":"offer","event_time":"2025-10-27T17:39:46.842888Z","price_level":"115662","new_quantity":"0"},{"side":"offer","event_time":"2025-10-27T17:39:46.842888Z","price_level":"115666","new_quantity":"0"},{"side":"offer","event_time":"2025-10-27T17:39:46.842888Z","price_level":"115689.73","new_quantity":"0.16812954"},{"side":"offer","event_time":"2025-10-27T17:39:46.842888Z","price_level":"115694.05","new_quantity":"0"},{"side":"offer","event_time":"2025-10-27T17:39:46.842888Z","price_level":"115709.99","new_quantity":"0"}]}]}
{"channel":"l2_data","client_id":"","timestamp":"2025-10-27T17:39:48.373949157Z","sequence_num":137961,"events":[{"type":"update","product_id":"ETH-USD","updates":[{"side":"bid","event_time":"2025-10-27T17:39:48.327255Z","price_level":"4217.9","new_quantity":"0"},{"side":"bid","event_time":"2025-10-27T17:39:48.327255Z","price_level":"4216.79","new_quantity":"0.21565049"},{"side":"offer","event_time":"2025-10-27T17:39:48.327255Z","price_level":"4218.1","new_quantity":"0.543"},{"side":"offer","event_time":"2025-10-27T17:39:48.327255Z","price_level":"4218.19","new_quantity":"0.00237072"},{"side":"offer","event_time":"2025-10-27T17:39:48.327255Z","price_level":"4218.2","new_quantity":"0.543"},{"side":"offer","event_time":"2025-10-27T17:39:48.327255Z","price_level":"4218.23","new_quantity":"0"},{"side":"offer","event_time":"2025-10-27T17:39:48.327255Z","price_level":"4221.47","new_quantity":"13.30186127"},{"side":"offer","event_time":"2025-10-27T17:39:48.327255Z","price_level":"4221.48","new_quantity":"1.94391607"},{"side":"offer","event_time":"2025-10-27T17:39:48.327255Z","price_level":"4221.49","new_quantity":"0"},{"side":"offer","event_time":"2025-10-27T17:39:48.327255Z","price_level":"4221.5","new_quantity":"0.001"}]}]}
{"channel":"l2_data","client_id":"","timestamp":"2025-10-27T17:39:48.398298804Z","sequence_num":137963,"events":[{"type":"update","product_id":"BTC-USD","updates":[{"side":"bid","event_time":"2025-10-27T17:39:48.347146Z","price_level":"115636","new_quantity":"0.06188771"},{"side":"bid","event_time":"2025-10-27T17:39:48.347146Z","price_level":"115634.01","new_quantity":"0"},{"side":"bid","event_time":"2025-10-27T17:39:48.347146Z","price_level":"115632","new_quantity":"0.0203"},{"side":"bid","event_time":"2025-10-27T17:39:48.347146Z","price_level":"115630.16","new_quantity":"0"},{"side":"bid","event_time":"2025-10-27T17:39:48.347146Z","price_level":"115628.75","new_quantity":"0"},{"side":"bid","event_time":"2025-10-27T17:39:48.347146Z","price_level":"115628.34","new_quantity":"0"},{"side":"bid","event_time":"2025-10-27T17:39:48.347146Z","price_level":"115623.63","new_quantity":"0"},{"side":"bid","event_time":"2025-10-27T17:39:48.347146Z","price_level":"115622.57","new_quantity":"0"},{"side":"bid","event_time":"2025-10-27T17:39:48.347146Z","price_level":"115621.31","new_quantity":"0"},{"side":"bid","event_time":"2025-10-27T17:39:48.347146Z","price_level":"115621.28","new_quantity":"0"},{"side":"bid","event_time":"2025-10-27T17:39:48.347146Z","price_level":"115618.99","new_quantity":"0.00432"},{"side":"bid","event_time":"2025-10-27T17:39:48.347146Z","price_level":"115618.95","new_quantity":"0"},{"side":"bid","event_time":"2025-10-27T17:39:48.347146Z","price_level":"115618.61","new_quantity":"0"},{"side":"bid","event_time":"2025-10-27T17:39:48.347146Z","price_level":"115617.07","new_quantity":"0.5835004"},{"side":"bid","event_time":"2025-10-27T17:39:48.347146Z","price_level":"115615","new_quantity":"0.4"},{"side":"bid","event_time":"2025-10-27T17:39:48.347146Z","price_level":"115614","new_quantity":"0"},{"side":"bid","event_time":"2025-10-27T17:39:48.347146Z","price_level":"115613","new_quantity":"0"},{"side":"bid","event_time":"2025-10-27T17:39:48.347146Z","price_level":"115611.01","new_quantity":"1.10296291"},{"side":"bid","event_time":"2025-10-27T17:39:48.347146Z","price_level":"115610.01","new_quantity":"0.33126554"},{"side":"bid","event_time":"2025-10-27T17:39:48.347146Z","price_level":"115607.77","new_quantity":"0"},{"side":"bid","event_time":"2025-10-27T17:39:48.347146Z","price_level":"115604.27","new_quantity":"0.6517228"},{"side":"bid","event_time":"2025-10-27T17:39:48.347146Z","price_level":"115601.64","new_quantity":"0.0069609"},{"side":"bid","event_time":"2025-10-27T17:39:48.347146Z","price_level":"115595.86","new_quantity":"0.53832113"},{"side":"bid","event_time":"2025-10-27T17:39:48.347146Z","price_level":"115590.78","new_quantity":"0"},{"side":"offer","event_time":"2025-10-27T17:39:48.347146Z","price_level":"115638.17","new_quantity":"0"},{"side":"offer","event_time":"2025-10-27T17:39:48.347146Z","price_level":"115638.64","new_quantity":"0.02594288"},{"side":"offer","event_time":"2025-10-27T17:39:48.347146Z","price_level":"115643.44","new_quantity":"0.02"},{"side":"offer","event_time":"2025-10-27T17:39:48.347146Z","price_level":"115643.45","new_quantity":"0.00304906"},{"side":"offer","event_time":"2025-10-27T17:39:48.347146Z","price_level":"115643.46","new_quantity":"0.30589523"},{"side":"offer","event_time":"2025-10-27T17:39:48.347146Z","price_level":"115647.51","new_quantity":"0.00008061"},{"side":"offer","event_time":"2025-10-27T17:39:48.347146Z","price_level":"115653.72","new_quantity":"0.00432"},{"side":"offer","event_time":"2025-10-27T17:39:48.347146Z","price_level":"115653.73","new_quantity":"0.00432"},{"side":"offer","event_time":"2025-10-27T17:39:48.347146Z","price_level":"115656.04","new_quantity":"0.00432"},{"side":"offer","event_time":"2025-10-27T17:39:48.347146Z","price_level":"115656.05","new_quantity":"0.00432"},{"side":"offer","event_time":"2025-10-27T17:39:48.347146Z","price_level":"115658.36","new_quantity":"0"},{"side":"offer","event_time":"2025-10-27T17:39:48.347146Z","price_level":"115658.37","new_quantity":"0"},{"side":"offer","event_time":"2025-10-27T17:39:48.347146Z","price_level":"115661.57","new_quantity":"0"},{"side":"offer","event_time":"2025-10-27T17:39:48.347146Z","price_level":"115689.99","new_quantity":"0"},{"side":"offer","event_time":"2025-10-27T17:39:48.347146Z","price_level":"115706.38","new_quantity":"0.00043237"},{"side":"offer","event_time":"2025-10-27T17:39:48.347146Z","price_level":"115709.21","new_quantity":"0"},{"side":"offer","event_time":"2025-10-27T17:39:48.347146Z","price_level":"115718.89","new_quantity":"0"},{"side":"offer","event_time":"2025-10-27T17:39:48.347146Z","price_level":"115727.14","new_quantity":"0.56827756"},{"side":"offer","event_time":"2025-10-27T17:39:48.347146Z","price_level":"115886.44","new_quantity":"0.07007"},{"side":"offer","event_time":"2025-10-27T17:39:48.347146Z","price_level":"115887.15","new_quantity":"0"}]}]}
{"channel":"l2_data","client_id":"","timestamp":"2025-10-27T17:39:48.420730483Z","sequence_num":137964,"events":[{"type":"update","product_id":"ETH-USD","updates":[{"side":"bid","event_time":"2025-10-27T17:39:48.382845Z","price_level":"4217.63","new_quantity":"0"},{"side":"bid","event_time":"2025-10-27T17:39:48.382845Z","price_level":"4217.34","new_quantity":"1.65919"},{"side":"bid","event_time":"2025-10-27T17:39:48.382845Z","price_level":"4215.74","new_quantity":"0"},{"side":"bid","event_time":"2025-10-27T17:39:48.382845Z","price_level":"4215.62","new_quantity":"3.27177295"},{"side":"offer","event_time":"2025-10-27T17:39:48.382845Z","price_level":"4218.1","new_quantity":"0"},{"side":"offer","event_time":"2025-10-27T17:39:48.382845Z","price_level":"4218.57","new_quantity":"0.47386456"},{"side":"offer","event_time":"2025-10-27T17:39:48.382845Z","price_level":"4218.68","new_quantity":"0.02163212"},{"side":"offer","event_time":"2025-10-27T17:39:48.382845Z","price_level":"4218.74","new_quantity":"0"},{"side":"offer","event_time":"2025-10-27T17:39:48.382845Z","price_level":"4219.6","new_quantity":"0"},{"side":"offer","event_time":"2025-10-27T17:39:48.382845Z","price_level":"4219.8","new_quantity":"0"},{"side":"offer","event_time":"2025-10-27T17:39:48.382845Z","price_level":"4220","new_quantity":"12.20517286"}]}]}
{"channel":"l2_data","client_id":"","timestamp":"2025-10-27T17:39:48.448840845Z","sequence_num":137966,"events":[{"type":"update","product_id":"BTC-USD","updates":[{"side":"bid","event_time":"2025-10-27T17:39:48.400107Z","price_level":"115636","new_quantity":"0.13440671"},{"side":"bid","event_time":"2025-10-27T17:39:48.400107Z","price_level":"115632.01","new_quantity":"0.07756898"},{"side":"bid","event_time":"2025-10-27T17:39:48.400107Z","price_level":"115631.67","new_quantity":"0.00977062"},{"side":"bid","event_time":"2025-10-27T17:39:48.400107Z","price_level":"115627.39","new_quantity":"0.00864846"},{"side":"bid","event_time":"2025-10-27T17:39:48.400107Z","price_level":"115617.07","new_quantity":"1.94170103"},{"side":"bid","event_time":"2025-10-27T17:39:48.400107Z","price_level":"115613","new_quantity":"0.4"},{"side":"bid","event_time":"2025-10-27T17:39:48.400107Z","price_level":"115612","new_quantity":"2"},{"side":"bid","event_time":"2025-10-27T17:39:48.400107Z","price_level":"115570.51","new_quantity":"0"},{"side":"bid","event_time":"2025-10-27T17:39:48.400107Z","price_level":"115570.1","new_quantity":"0"},{"side":"bid","event_time":"2025-10-27T17:39:48.400107Z","price_level":"115569.2","new_quantity":"0"},{"side":"bid","event_time":"2025-10-27T17:39:48.400107Z","price_level":"115567.27","new_quantity":"0.76394699"},{"side":"bid","event_time":"2025-10-27T17:39:48.400107Z","price_level":"115551.6","new_quantity":"1.5"},{"side":"bid","event_time":"2025-10-27T17:39:48.400107Z","price_level":"101181.5","new_quantity":"0.00396544"},{"side":"offer","event_time":"2025-10-27T17:39:48.400107Z","price_level":"115637.16","new_quantity":"0.02594321"},{"side":"offer","event_time":"2025-10-27T17:39:48.400107Z","price_level":"115638.64","new_quantity":"0"},{"side":"offer","event_time":"2025-10-27T17:39:48.400107Z","price_level":"115643.44","new_quantity":"0"},{"side":"offer","event_time":"2025-10-27T17:39:48.400107Z","price_level":"115647.51","new_quantity":"0"},{"side":"offer","event_time":"2025-10-27T17:39:48.400107Z","price_level":"115653.72","new_quantity":"0"},{"side":"offer","event_time":"2025-10-27T17:39:48.400107Z","price_level":"115653.73","new_quantity":"0"},{"side":"offer","event_time":"2025-10-27T17:39:48.400107Z","price_level":"115656.03","new_quantity":"0"},{"side":"offer","event_time":"2025-10-27T17:39:48.400107Z","price_level":"115656.04","new_quantity":"0"},{"side":"offer","event_time":"2025-10-27T17:39:48.400107Z","price_level":"115656.05","new_quantity":"0"},{"side":"offer","event_time":"2025-10-27T17:39:48.400107Z","price_level":"115658.36","new_quantity":"0.00432"},{"side":"offer","event_time":"2025-10-27T17:39:48.400107Z","price_level":"115660.99","new_quantity":"0.00008061"},{"side":"offer","event_time":"2025-10-27T17:39:48.400107Z","price_level":"115661","new_quantity":"2"},{"side":"offer","event_time":"2025-10-27T17:39:48.400107Z","price_level":"115662.98","new_quantity":"0.38914251"},{"side":"offer","event_time":"2025-10-27T17:39:48.400107Z","price_level":"115669.98","new_quantity":"0"},{"side":"offer","event_time":"2025-10-27T17:39:48.400107Z","price_level":"115694.04","new_quantity":"0"},{"side":"offer","event_time":"2025-10-27T17:39:48.400107Z","price_level":"115703.28","new_quantity":"0"},{"side":"offer","event_time":"2025-10-27T17:39:48.400107Z","price_level":"115714.83","new_quantity":"0"},{"side":"offer","event_time":"2025-10-27T17:39:48.400107Z","price_level":"115718.5","new_quantity":"0"},{"side":"offer","event_time":"2025-10-27T17:39:48.400107Z","price_level":"115718.9","new_quantity":"0"},{"side":"offer","event_time":"2025-10-27T17:39:48.400107Z","price_level":"115722.7","new_quantity":"1"}]}]}
{"channel":"l2_data","client_id":"","timestamp":"2025-10-27T17:39:48.470783368Z","sequence_num":137967,"events":[{"type":"update","product_id":"ETH-USD","updates":[{"side":"bid","event_time":"2025-10-27T17:39:48.43049Z","price_level":"4217.56","new_quantity":"1.65919"},{"side":"offer","event_time":"2025-10-27T17:39:48.43049Z","price_level":"4218.07","new_quantity":"0.6197581"},{"side":"offer","event_time":"2025-10-27T17:39:48.43049Z","price_level":"4218.27","new_quantity":"0"},{"side":"offer","event_time":"2025-10-27T17:39:48.43049Z","price_level":"4219.8","new_quantity":"20"},{"side":"offer","event_time":"2025-10-27T17:39:48.43049Z","price_level":"4221.1","new_quantity":"1.94391607"},{"side":"offer","event_time":"2025-10-27T17:39:48.43049Z","price_level":"4221.48","new_quantity":"0"}]}]}
{"channel":"l2_data","client_id":"","timestamp":"2025-10-27T17:39:48.499492635Z","sequence_num":137968,"events":[{"type":"update","product_id":"BTC-USD","updates":[{"side":"bid","event_time":"2025-10-27T17:39:48.452805Z","price_level":"115636","new_quantity":"0.10116828"},{"side":"bid","event_time":"2025-10-27T17:39:48.452805Z","price_level":"115628.71","new_quantity":"0.00864837"},{"side":"bid","event_time":"2025-10-27T17:39:48.452805Z","price_level":"115627.49","new_quantity":"0.0216117"},{"side":"bid","event_time":"2025-10-27T17:39:48.452805Z","price_level":"115627.39","new_quantity":"0"},{"side":"bid","event_time":"2025-10-27T17:39:48.452805Z","price_level":"115621.28","new_quantity":"0.00432"},{"side":"bid","event_time":"2025-10-27T17:39:48.452805Z","price_level":"115617.07","new_quantity":"0.5835004"},{"side":"bid","event_time":"2025-10-27T17:39:48.452805Z","price_level":"115617","new_quantity":"0"},{"side":"bid","event_time":"2025-10-27T17:39:48.452805Z","price_level":"115612","new_quantity":"0"},{"side":"bid","event_time":"2025-10-27T17:39:48.452805Z","price_level":"115610.01","new_quantity":"0"},{"side":"bid","event_time":"2025-10-27T17:39:48.452805Z","price_level":"115604.28","new_quantity":"0.33128196"},{"side":"bid","event_time":"2025-10-27T17:39:48.452805Z","price_level":"115595.86","new_quantity":"0"},{"side":"bid","event_time":"2025-10-27T17:39:48.452805Z","price_level":"115590.78","new_quantity":"0.53834478"},{"side":"bid","event_time":"2025-10-27T17:39:48.452805Z","price_level":"115553.3","new_quantity":"1.5"},{"side":"bid","event_time":"2025-10-27T17:39:48.452805Z","price_level":"115552.51","new_quantity":"1.16521302"},{"side":"bid","event_time":"2025-10-27T17:39:48.452805Z","price_level":"115552.36","new_quantity":"0"},{"side":"bid","event_time":"2025-10-27T17:39:48.452805Z","price_level":"115551.6","new_quantity":"0"},{"side":"offer","event_time":"2025-10-27T17:39:48.452805Z","price_level":"115637.16","new_quantity":"0"},{"side":"offer","event_time":"2025-10-27T17:39:48.452805Z","price_level":"115638.48","new_quantity":"0.02594292"},{"side":"offer","event_time":"2025-10-27T17:39:48.452805Z","price_level":"115673.3","new_quantity":"0.01310098"},{"side":"offer","event_time":"2025-10-27T17:39:48.452805Z","price_level":"115722.7","new_quantity":"0"},{"side":"offer","event_time":"2025-10-27T17:39:48.452805Z","price_level":"115722.79","new_quantity":"0.56829892"},{"side":"offer","event_time":"2025-10-27T17:39:48.452805Z","price_level":"115722.8","new_quantity":"1"},{"side":"offer","event_time":"2025-10-27T17:39:48.452805Z","price_level":"115727.14","new_quantity":"0"},{"side":"offer","event_time":"2025-10-27T17:39:48.452805Z","price_level":"116052","new_quantity":"0.23368842"},{"side":"offer","event_time":"2025-10-27T17:39:48.452805Z","price_level":"116089.41","new_quantity":"0"}]}]}
{"channel":"l2_data","client_id":"","timestamp":"2025-10-27T17:39:48.518870211Z","sequence_num":137969,"events":[{"type":"update","product_id":"ETH-USD","updates":[{"side":"bid","event_time":"2025-10-27T17:39:48.472573Z","price_level":"4217.9","new_quantity":"0.543"}]}]}
{"channel":"l2_data","client_id":"","timestamp":"2025-10-27T17:39:48.546601766Z","sequence_num":137970,"events":[{"type":"update","product_id":"BTC-USD","updates":[{"side":"bid","event_time":"2025-10-27T17:39:48.502195Z","price_level":"115634.01","new_quantity":"0.00172959"},{"side":"bid","event_time":"2025-10-27T17:39:48.502195Z","price_level":"115628.91","new_quantity":"0"},{"side":"bid","event_time":"2025-10-27T17:39:48.502195Z","price_level":"115621.28","new_quantity":"0"},{"side":"bid","event_time":"2025-10-27T17:39:48.502195Z","price_level":"115621.11","new_quantity":"0.04"},{"side":"bid","event_time":"2025-10-27T17:39:48.502195Z","price_level":"115617.07","new_quantity":"0.84634931"},{"side":"bid","event_time":"2025-10-27T17:39:48.502195Z","price_level":"115616.79","new_quantity":"0.16524"},{"side":"bid","event_time":"2025-10-27T17:39:48.502195Z","price_level":"115616","new_quantity":"0.4"},{"side":"bid","event_time":"2025-10-27T17:39:48.502195Z","price_level":"115615","new_quantity":"0"},{"side":"bid","event_time":"2025-10-27T17:39:48.502195Z","price_level":"115611.01","new_quantity":"1.97515187"},{"side":"bid","event_time":"2025-10-27T17:39:48.502195Z","price_level":"115611","new_quantity":"2"},{"side":"bid","event_time":"2025-10-27T17:39:48.502195Z","price_level":"115567.41","new_quantity":"0.76394606"},{"side":"bid","event_time":"2025-10-27T17:39:48.502195Z","price_level":"115567.4","new_quantity":"1.5"},{"side":"bid","event_time":"2025-10-27T17:39:48.502195Z","price_level":"115567.27","new_quantity":"0"},{"side":"bid","event_time":"2025-10-27T17:39:48.502195Z","price_level":"115553.3","new_quantity":"0"},{"side":"offer","event_time":"2025-10-27T17:39:48.502195Z","price_level":"115662.98","new_quantity":"0"},{"side":"offer","event_time":"2025-10-27T17:39:48.502195Z","price_level":"115669.98","new_quantity":"0.38913789"},{"side":"offer","event_time":"2025-10-27T17:39:48.502195Z","price_level":"115711.5","new_quantity":"1"},{"side":"offer","event_time":"2025-10-27T17:39:48.502195Z","price_level":"115722.8","new_quantity":"0"}]}]}
{"channel":"l2_data","client_id":"","timestamp":"2025-10-27T17:39:48.574781772Z","sequence_num":137971,"events":[{"type":"update","product_id":"ETH-USD","updates":[{"side":"bid","event_time":"2025-10-27T17:39:48.527476Z","price_level":"4217.34","new_quantity":"0"},{"side":"offer","event_time":"2025-10-27T17:39:48.527476Z","price_level":"4218.07","new_quantity":"0.02706915"},{"side":"offer","event_time":"2025-10-27T17:39:48.527476Z","price_level":"4221.1","new_quantity":"0"},{"side":"offer","event_time":"2025-10-27T17:39:48.527476Z","price_level":"4221.45","new_quantity":"13.29998027"},{"side":"offer","event_time":"2025-10-27T17:39:48.527476Z","price_level":"4221.46","new_quantity":"1.94391607"},{"side":"offer","event_time":"2025-10-27T17:39:48.527476Z","price_level":"4221.47","new_quantity":"0"}]}]}
{"channel":"l2_data","client_id":"","timestamp":"2025-10-27T17:39:48.596617934Z","sequence_num":137973,"events":[{"type":"update","product_id":"BTC-USD","updates":[{"side":"bid","event_time":"2025-10-27T17:39:48.552904Z","price_level":"115617.07","new_quantity":"0.5835004"},{"side":"bid","event_time":"2025-10-27T17:39:48.552904Z","price_level":"115614","new_quantity":"0.4"},{"side":"bid","event_time":"2025-10-27T17:39:48.552904Z","price_level":"115613","new_quantity":"0"},{"side":"bid","event_time":"2025-10-27T17:39:48.552904Z","price_level":"115607.77","new_quantity":"0.33127196"},{"side":"bid","event_time":"2025-10-27T17:39:48.552904Z","price_level":"115604.28","new_quantity":"0"},{"side":"offer","event_time":"2025-10-27T17:39:48.552904Z","price_level":"115658.33","new_quantity":"0.008993"},{"side":"offer","event_time":"2025-10-27T17:39:48.552904Z","price_level":"115662.98","new_quantity":"0.38913916"},{"side":"offer","event_time":"2025-10-27T17:39:48.552904Z","price_level":"115666.54","new_quantity":"0"},{"side":"offer","event_time":"2025-10-27T17:39:48.552904Z","price_level":"115669.98","new_quantity":"0"},{"side":"offer","event_time":"2025-10-27T17:39:48.552904Z","price_level":"115719.94","new_quantity":"0.56831292"},{"side":"offer","event_time":"2025-10-27T17:39:48.552904Z","price_level":"115722.79","new_quantity":"0"}]}]}
{"channel":"l2_data","client_id":"","timestamp":"2025-10-27T17:39:48.619761468Z","sequence_num":137974,"events":[{"type":"update","product_id":"ETH-USD","updates":[{"side":"offer","event_time":"2025-10-27T17:39:48.544294Z","price_level":"4218.17","new_quantity":"0"},{"side":"offer","event_time":"2025-10-27T17:39:48.544294Z","price_level":"4218.21","new_quantity":"0.11853395"},{"side":"offer","event_time":"2025-10-27T17:39:48.544294Z","price_level":"4218.49","new_quantity":"1.37950157"},{"side":"offer","event_time":"2025-10-27T17:39:48.544294Z","price_level":"4218.59","new_quantity":"0.59261641"}]}]}
{"channel":"l2_data","client_id":"","timestamp":"2025-10-27T17:39:48.64903216Z","sequence_num":137976,"events":[{"type":"update","product_id":"BTC-USD","updates":[{"side":"bid","event_time":"2025-10-27T17:39:48.606922Z","price_level":"115611.01","new_quantity":"0.93772291"},{"side":"bid","event_time":"2025-10-27T17:39:48.606922Z","price_level":"115611","new_quantity":"0"},{"side":"bid","event_time":"2025-10-27T17:39:48.606922Z","price_level":"115601.64","new_quantity":"0"},{"side":"bid","event_time":"2025-10-27T17:39:48.606922Z","price_level":"115567.4","new_quantity":"0"},{"side":"bid","event_time":"2025-10-27T17:39:48.606922Z","price_level":"115561.8","new_quantity":"1.5"},{"side":"offer","event_time":"2025-10-27T17:39:48.606922Z","price_level":"115636.01","new_quantity":"0.00211527"},{"side":"offer","event_time":"2025-10-27T17:39:48.606922Z","price_level":"115711.5","new_quantity":"0"},{"side":"offer","event_time":"2025-10-27T17:39:48.606922Z","price_level":"115725.5","new_quantity":"1"}]}]}
{"channel":"l2_data","client_id":"","timestamp":"2025-10-27T17:39:48.699728429Z","sequence_num":137977,"events":[{"type":"update","product_id":"BTC-USD","updates":[{"side":"bid","event_time":"2025-10-27T17:39:48.657497Z","price_level":"115636","new_quantity":"0.10112461"},{"side":"bid","event_time":"2025-10-27T17:39:48.657497Z","price_level":"115621.11","new_quantity":"0"},{"side":"bid","event_time":"2025-10-27T17:39:48.657497Z","price_level":"115617.07","new_quantity":"0.5835004"},{"side":"bid","event_time":"2025-10-27T17:39:48.657497Z","price_level":"115601.52","new_quantity":"0.0069609"},{"side":"offer","event_time":"2025-10-27T17:39:48.657497Z","price_level":"115661","new_quantity":"2"}]}]}
{"channel":"l2_data","client_id":"","timestamp":"2025-10-27T17:39:48.721064761Z","sequence_num":137978,"events":[{"type":"update","product_id":"ETH-USD","updates":[{"side":"bid","event_time":"2025-10-27T17:39:48.653929Z","price_level":"4216.17","new_quantity":"0"},{"side":"offer","event_time":"2025-10-27T17:39:48.653929Z","price_level":"4218.07","new_quantity":"0.20306915"},{"side":"offer","event_time":"2025-10-27T17:39:48.653929Z","price_level":"4221.43","new_quantity":"13.30004328"},{"side":"offer","event_time":"2025-10-27T17:39:48.653929Z","price_level":"4221.44","new_quantity":"1.94391607"},{"side":"offer","event_time":"2025-10-27T17:39:48.653929Z","price_level":"4221.45","new_quantity":"0"},{"side":"offer","event_time":"2025-10-27T17:39:48.653929Z","price_level":"4221.46","new_quantity":"0"}]}]}
{"channel":"l2_data","client_id":"","timestamp":"2025-10-27T17:39:48.746411099Z","sequence_num":137979,"events":[{"type":"update","product_id":"BTC-USD","updates":[{"side":"bid","event_time":"2025-10-27T17:39:48.705082Z","price_level":"115636","new_quantity":"0.1271112"},{"side":"bid","event_time":"2025-10-27T17:39:48.705082Z","price_level":"115618.99","new_quantity":"0"},{"side":"bid","event_time":"2025-10-27T17:39:48.705082Z","price_level":"115611.01","new_quantity":"2.00768123"},{"side":"bid","event_time":"2025-10-27T17:39:48.705082Z","price_level":"115611","new_quantity":"0"},{"side":"offer","event_time":"2025-10-27T17:39:48.705082Z","price_level":"115661","new_quantity":"0"},{"side":"offer","event_time":"2025-10-27T17:39:48.705082Z","price_level":"116101.75","new_quantity":"0.07007"}]}]}
{"channel":"l2_data","client_id":"","timestamp":"2025-10-27T17:39:48.796693026Z","sequence_num":137980,"events":[{"type":"update","product_id":"BTC-USD","updates":[{"side":"bid","event_time":"2025-10-27T17:39:48.746509Z","price_level":"115611.01","new_quantity":"0.93772291"},{"side":"bid","event_time":"2025-10-27T17:39:48.746509Z","price_level":"115611","new_quantity":"2"},{"side":"bid","event_time":"2025-10-27T17:39:48.746509Z","price_level":"115570","new_quantity":"0.00001798"},{"side":"bid","event_time":"2025-10-27T17:39:48.746509Z","price_level":"115567.42","new_quantity":"1.51409877"},{"side":"bid","event_time":"2025-10-27T17:39:48.746509Z","price_level":"115566.5","new_quantity":"1.5"},{"side":"bid","event_time":"2025-10-27T17:39:48.746509Z","price_level":"115561.8","new_quantity":"0"},{"side":"bid","event_time":"2025-10-27T17:39:48.746509Z","price_level":"115496.72","new_quantity":"0.026865"},{"side":"bid","event_time":"2025-10-27T17:39:48.746509Z","price_level":"101181.5","new_quantity":"0"},{"side":"offer","event_time":"2025-10-27T17:39:48.746509Z","price_level":"115660.99","new_quantity":"0"},{"side":"offer","event_time":"2025-10-27T17:39:48.746509Z","price_level":"115661","new_quantity":"2"},{"side":"offer","event_time":"2025-10-27T17:39:48.746509Z","price_level":"115661.57","new_quantity":"0.00008408"},{"side":"offer","event_time":"2025-10-27T17:39:48.746509Z","price_level":"115666","new_quantity":"0.4"},{"side":"offer","event_time":"2025-10-27T17:39:48.746509Z","price_level":"115669.96","new_quantity":"0.13835701"},{"side":"offer","event_time":"2025-10-27T17:39:48.746509Z","price_level":"115671","new_quantity":"0"},{"side":"offer","event_time":"2025-10-27T17:39:48.746509Z","price_level":"115675.76","new_quantity":"0.24959132"},{"side":"offer","event_time":"2025-10-27T17:39:48.746509Z","price_level":"115710.2","new_quantity":"1"},{"side":"offer","event_time":"2025-10-27T17:39:48.746509Z","price_level":"115725.5","new_quantity":"0"},{"side":"offer","event_time":"2025-10-27T17:39:48.746509Z","price_level":"115834.12","new_quantity":"0"}]}]}
{"channel":"l2_data","client_id":"","timestamp":"2025-10-27T17:39:48.818588428Z","sequence_num":137981,"events":[{"type":"update","product_id":"ETH-USD","updates":[{"side":"offer","event_time":"2025-10-27T17:39:48.769512Z","price_level":"4218.07","new_quantity":"0.02706915"},{"side":"offer","event_time":"2025-10-27T17:39:48.769512Z","price_level":"4221.41","new_quantity":"13.30010629"},{"side":"offer","event_time":"2025-10-27T17:39:48.769512Z","price_level":"4221.42","new_quantity":"1.94391607"},{"side":"offer","event_time":"2025-10-27T17:39:48.769512Z","price_level":"4221.43","new_quantity":"0"},{"side":"offer","event_time":"2025-10-27T17:39:48.769512Z","price_level":"4221.44","new_quantity":"0"}]}]}
{"channel":"l2_data","client_id":"","timestamp":"2025-10-27T17:39:48.846841909Z","sequence_num":137983,"events":[{"type":"update","product_id":"BTC-USD","updates":[{"side":"bid","event_time":"2025-10-27T17:39:48.786416Z","price_level":"115636","new_quantity":"0.1474112"},{"side":"bid","event_time":"2025-10-27T17:39:48.786416Z","price_level":"115623.63","new_quantity":"0.00432"},{"side":"bid","event_time":"2025-10-27T17:39:48.786416Z","price_level":"115621.28","new_quantity":"0.00432"},{"side":"bid","event_time":"2025-10-27T17:39:48.786416Z","price_level":"115621.11","new_quantity":"0.04"},{"side":"bid","event_time":"2025-10-27T17:39:48.786416Z","price_level":"115611.01","new_quantity":"2.00768123"},{"side":"bid","event_time":"2025-10-27T17:39:48.786416Z","price_level":"115567.43","new_quantity":"0.81377648"},{"side":"bid","event_time":"2025-10-27T17:39:48.786416Z","price_level":"115567.42","new_quantity":"0"},{"side":"bid","event_time":"2025-10-27T17:39:48.786416Z","price_level":"115567.41","new_quantity":"0"},{"side":"offer","event_time":"2025-10-27T17:39:48.786416Z","price_level":"115660.99","new_quantity":"0.00008408"},{"side":"offer","event_time":"2025-10-27T17:39:48.786416Z","price_level":"115661.57","new_quantity":"0"},{"side":"offer","event_time":"2025-10-27T17:39:48.786416Z","price_level":"115666","new_quantity":"0"},{"side":"offer","event_time":"2025-10-27T17:39:48.786416Z","price_level":"116102.1","new_quantity":"0"},{"side":"offer","event_time":"2025-10-27T17:39:48.786416Z","price_level":"116316.91","new_quantity":"0.07007"},{"side":"offer","event_time":"2025-10-27T17:39:48.786416Z","price_level":"116747.15","new_quantity":"0"}]}]}
{"channel":"l2_data","client_id":"","timestamp":"2025-10-27T17:39:48.897929244Z","sequence_num":137985,"events":[{"type":"update","product_id":"BTC-USD","updates":[{"side":"bid","event_time":"2025-10-27T17:39:48.835027Z","price_level":"115601.52","new_quantity":"0"},{"side":"bid","event_time":"2025-10-27T17:39:48.835027Z","price_level":"115597.72","new_quantity":"0"},{"side":"bid","event_time":"2025-10-27T17:39:48.835027Z","price_level":"115563.04","new_quantity":"0"},{"side":"offer","event_time":"2025-10-27T17:39:48.835027Z","price_level":"115658.32","new_quantity":"0.00008408"},{"side":"offer","event_time":"2025-10-27T17:39:48.835027Z","price_level":"115658.37","new_quantity":"0.00432"},{"side":"offer","event_time":"2025-10-27T17:39:48.835027Z","price_level":"115660.99","new_quantity":"0"},{"side":"offer","event_time":"2025-10-27T17:39:48.835027Z","price_level":"115688.91","new_quantity":"0"}]}]}
{"channel":"l2_data","client_id":"","timestamp":"2025-10-27T17:39:48.918552908Z","sequence_num":137986,"events":[{"type":"update","product_id":"ETH-USD","updates":[{"side":"offer","event_time":"2025-10-27T17:39:48.876365Z","price_level":"4218.2","new_quantity":"0"}]}]}
{"channel":"l2_data","client_id":"","timestamp":"2025-10-27T17:39:48.949855011Z","sequence_num":137987,"events":[{"type":"update","product_id":"BTC-USD","updates":[{"side":"bid","event_time":"2025-10-27T17:39:48.896083Z","price_level":"115636","new_quantity":"0.31473261"},{"side":"bid","event_time":"2025-10-27T17:39:48.896083Z","price_level":"115628.71","new_quantity":"0"},{"side":"bid","event_time":"2025-10-27T17:39:48.896083Z","price_level":"115628.45","new_quantity":"0.0864839"},{"side":"bid","event_time":"2025-10-27T17:39:48.896083Z","price_level":"115625.92","new_quantity":"0.00432"},{"side":"bid","event_time":"2025-10-27T17:39:48.896083Z","price_level":"115621.28","new_quantity":"0"},{"side":"bid","event_time":"2025-10-27T17:39:48.896083Z","price_level":"115618.96","new_quantity":"0"},{"side":"bid","event_time":"2025-10-27T17:39:48.896083Z","price_level":"115617.58","new_quantity":"0"},{"side":"bid","event_time":"2025-10-27T17:39:48.896083Z","price_level":"115611.01","new_quantity":"0.93772291"},{"side":"bid","event_time":"2025-10-27T17:39:48.896083Z","price_level":"115611","new_quantity":"0"},{"side":"bid","event_time":"2025-10-27T17:39:48.896083Z","price_level":"115610.01","new_quantity":"0.34898244"},{"side":"bid","event_time":"2025-10-27T17:39:48.896083Z","price_level":"115607.77","new_quantity":"0"},{"side":"bid","event_time":"2025-10-27T17:39:48.896083Z","price_level":"115601.55","new_quantity":"0.0069609"},{"side":"bid","event_time":"2025-10-27T17:39:48.896083Z","price_level":"115597.74","new_quantity":"0"},{"side":"bid","event_time":"2025-10-27T17:39:48.896083Z","price_level":"115595.86","new_quantity":"0.53832113"},{"side":"bid","event_time":"2025-10-27T17:39:48.896083Z","price_level":"115590.78","new_quantity":"0"},{"side":"bid","event_time":"2025-10-27T17:39:48.896083Z","price_level":"114101.27","new_quantity":"0.07007"},{"side":"bid","event_time":"2025-10-27T17:39:48.896083Z","price_level":"114098.75","new_quantity":"0"},{"side":"offer","event_time":"2025-10-27T17:39:48.896083Z","price_level":"115638.48","new_quantity":"0"},{"side":"offer","event_time":"2025-10-27T17:39:48.896083Z","price_level":"115643.45","new_quantity":"0"},{"side":"offer","event_time":"2025-10-27T17:39:48.896083Z","price_level":"115643.46","new_quantity":"0"},{"side":"offer","event_time":"2025-10-27T17:39:48.896083Z","price_level":"115643.47","new_quantity":"0"},{"side":"offer","event_time":"2025-10-27T17:39:48.896083Z","price_level":"115643.53","new_quantity":"0.00000514"},{"side":"offer","event_time":"2025-10-27T17:39:48.896083Z","price_level":"115647.52","new_quantity":"0"},{"side":"offer","event_time":"2025-10-27T17:39:48.896083Z","price_level":"115649.58","new_quantity":"0"},{"side":"offer","event_time":"2025-10-27T17:39:48.896083Z","price_level":"115651.01","new_quantity":"0.25940111"},{"side":"offer","event_time":"2025-10-27T17:39:48.896083Z","price_level":"115652.17","new_quantity":"0"},{"side":"offer","event_time":"2025-10-27T17:39:48.896083Z","price_level":"115653.92","new_quantity":"0.25939458"},{"side":"offer","event_time":"2025-10-27T17:39:48.896083Z","price_level":"115658.32","new_quantity":"0"},{"side":"offer","event_time":"2025-10-27T17:39:48.896083Z","price_level":"115658.36","new_quantity":"0"},{"side":"offer","event_time":"2025-10-27T17:39:48.896083Z","price_level":"115658.37","new_quantity":"0"},{"side":"offer","event_time":"2025-10-27T17:39:48.896083Z","price_level":"115660.99","new_quantity":"0.00354674"},{"side":"offer","event_time":"2025-10-27T17:39:48.896083Z","price_level":"115666","new_quantity":"0.4"},{"side":"offer","event_time":"2025-10-27T17:39:48.896083Z","price_level":"115669.96","new_quantity":"0"},{"side":"offer","event_time":"2025-10-27T17:39:48.896083Z","price_level":"115671.72","new_quantity":"0.13835701"},{"side":"offer","event_time":"2025-10-27T17:39:48.896083Z","price_level":"115675.76","new_quantity":"0.56023618"},{"side":"offer","event_time":"2025-10-27T17:39:48.896083Z","price_level":"115689.59","new_quantity":"0"},{"side":"offer","event_time":"2025-10-27T17:39:48.896083Z","price_level":"115694.05","new_quantity":"0.16687655"},{"side":"offer","event_time":"2025-10-27T17:39:48.896083Z","price_level":"115705.5","new_quantity":"0"},{"side":"offer","event_time":"2025-10-27T17:39:48.896083Z","price_level":"115709.99","new_quantity":"0.25574104"},{"side":"offer","event_time":"2025-10-27T17:39:48.896083Z","price_level":"115712.77","new_quantity":"0.00043233"},{"side":"offer","event_time":"2025-10-27T17:39:48.896083Z","price_level":"115719.94","new_quantity":"0.39305719"},{"side":"offer","event_time":"2025-10-27T17:39:48.896083Z","price_level":"115727.14","new_quantity":"0.56827756"},{"side":"offer","event_time":"2025-10-27T17:39:48.896083Z","price_level":"116317.54","new_quantity":"0"},{"side":"offer","event_time":"2025-10-27T17:39:48.896083Z","price_level":"116746.94","new_quantity":"0.07007"},{"side":"offer","event_time":"2025-10-27T17:39:48.896083Z","price_level":"116961.42","new_quantity":"0.07007"}]}]}
{"channel":"l2_data","client_id":"","timestamp":"2025-10-27T17:39:48.971718857Z","sequence_num":137988,"events":[{"type":"update","product_id":"ETH-USD","updates":[{"side":"bid","event_time":"2025-10-27T17:39:48.900662Z","price_level":"4218.06","new_quantity":"0.3084274"},{"side":"bid","event_time":"2025-10-27T17:39:48.900662Z","price_level":"4218","new_quantity":"2.29267"},{"side":"bid","event_time":"2025-10-27T17:39:48.900662Z","price_level":"4216.36","new_quantity":"2.25940624"},{"side":"bid","event_time":"2025-10-27T17:39:48.900662Z","price_level":"4214.91","new_quantity":"8.83923518"},{"side":"bid","event_time":"2025-10-27T17:39:48.900662Z","price_level":"4213.64","new_quantity":"3.5535708"},{"side":"bid","event_time":"2025-10-27T17:39:48.900662Z","price_level":"4212.01","new_quantity":"0.74271589"},{"side":"offer","event_time":"2025-10-27T17:39:48.900662Z","price_level":"4218.19","new_quantity":"0"},{"side":"offer","event_time":"2025-10-27T17:39:48.900662Z","price_level":"4218.2","new_quantity":"0.00237076"},{"side":"offer","event_time":"2025-10-27T17:39:48.900662Z","price_level":"4218.68","new_quantity":"0"},{"side":"offer","event_time":"2025-10-27T17:39:48.900662Z","price_level":"4221.39","new_quantity":"13.3001693"},{"side":"offer","event_time":"2025-10-27T17:39:48.900662Z","price_level":"4221.4","new_quantity":"1.94391607"},{"side":"offer","event_time":"2025-10-27T17:39:48.900662Z","price_level":"4221.41","new_quantity":"0"},{"side":"offer","event_time":"2025-10-27T17:39:48.900662Z","price_level":"4221.42","new_quantity":"0"}]}]}
{"channel":"l2_data","client_id":"","timestamp":"2025-10-27T17:39:48.998112986Z","sequence_num":137989,"events":[{"type":"update","product_id":"BTC-USD","updates":[{"side":"bid","event_time":"2025-10-27T17:39:48.950402Z","price_level":"115636","new_quantity":"0.40938261"},{"side":"bid","event_time":"2025-10-27T17:39:48.950402Z","price_level":"115632.82","new_quantity":"0.00864806"},{"side":"bid","event_time":"2025-10-27T17:39:48.950402Z","price_level":"115622.58","new_quantity":"0.2896162"},{"side":"bid","event_time":"2025-10-27T17:39:48.950402Z","price_level":"115622.57","new_quantity":"0.16524"},{"side":"bid","event_time":"2025-10-27T17:39:48.950402Z","price_level":"115620.65","new_quantity":"0"},{"side":"bid","event_time":"2025-10-27T17:39:48.950402Z","price_level":"115619","new_quantity":"0"},{"side":"bid","event_time":"2025-10-27T17:39:48.950402Z","price_level":"115617.07","new_quantity":"0.5835004"},{"side":"bid","event_time":"2025-10-27T17:39:48.950402Z","price_level":"115617","new_quantity":"0.4"},{"side":"bid","event_time":"2025-10-27T17:39:48.950402Z","price_level":"115616","new_quantity":"0"},{"side":"bid","event_time":"2025-10-27T17:39:48.950402Z","price_level":"115612","new_quantity":"0"},{"side":"bid","event_time":"2025-10-27T17:39:48.950402Z","price_level":"115568.51","new_quantity":"0.81376887"},{"side":"bid","event_time":"2025-10-27T17:39:48.950402Z","price_level":"115568.5","new_quantity":"0"},{"side":"bid","event_time":"2025-10-27T17:39:48.950402Z","price_level":"115567.43","new_quantity":"0"},{"side":"bid","event_time":"2025-10-27T17:39:48.950402Z","price_level":"115566.5","new_quantity":"0"},{"side":"bid","event_time":"2025-10-27T17:39:48.950402Z","price_level":"115563.3","new_quantity":"1.5"},{"side":"offer","event_time":"2025-10-27T17:39:48.950402Z","price_level":"115643.7","new_quantity":"0"},{"side":"offer","event_time":"2025-10-27T17:39:48.950402Z","price_level":"115645.78","new_quantity":"0.02594128"},{"side":"offer","event_time":"2025-10-27T17:39:48.950402Z","price_level":"115647.51","new_quantity":"0.00008408"},{"side":"offer","event_time":"2025-10-27T17:39:48.950402Z","price_level":"115647.52","new_quantity":"0.00302493"},{"side":"offer","event_time":"2025-10-27T17:39:48.950402Z","price_level":"115660.99","new_quantity":"0"},{"side":"offer","event_time":"2025-10-27T17:39:48.950402Z","price_level":"115661","new_quantity":"0"},{"side":"offer","event_time":"2025-10-27T17:39:48.950402Z","price_level":"115662","new_quantity":"2"},{"side":"offer","event_time":"2025-10-27T17:39:48.950402Z","price_level":"115666","new_quantity":"0.4"},{"side":"offer","event_time":"2025-10-27T17:39:48.950402Z","price_level":"115710.2","new_quantity":"0"},{"side":"offer","event_time":"2025-10-27T17:39:48.950402Z","price_level":"115725.6","new_quantity":"1"},{"side":"offer","event_time":"2025-10-27T17:39:48.950402Z","price_level":"115797.83","new_quantity":"0.045"},{"side":"offer","event_time":"2025-10-27T17:39:48.950402Z","price_level":"115797.89","new_quantity":"0"},{"side":"offer","event_time":"2025-10-27T17:39:48.950402Z","price_level":"116376.07","new_quantity":"0.045"}]}]}
{"channel":"l2_data","client_id":"","timestamp":"2025-10-27T17:39:49.046588334Z","sequence_num":137990,"events":[{"type":"update","product_id":"BTC-USD","updates":[{"side":"bid","event_time":"2025-10-27T17:39:49.007816Z","price_level":"115636","new_quantity":"0.29724751"},{"side":"bid","event_time":"2025-10-27T17:39:49.007816Z","price_level":"115632.01","new_quantity":"0.30541933"},{"side":"bid","event_time":"2025-10-27T17:39:49.007816Z","price_level":"115629","new_quantity":"0.4"},{"side":"bid","event_time":"2025-10-27T17:39:49.007816Z","price_level":"115617.07","new_quantity":"1.80154931"},{"side":"bid","event_time":"2025-10-27T17:39:49.007816Z","price_level":"115616.79","new_quantity":"0"},{"side":"bid","event_time":"2025-10-27T17:39:49.007816Z","price_level":"115616","new_quantity":"2"},{"side":"bid","event_time":"2025-10-27T17:39:49.007816Z","price_level":"115611.02","new_quantity":"0.34897939"},{"side":"bid","event_time":"2025-10-27T17:39:49.007816Z","price_level":"115610.01","new_quantity":"0"},{"side":"bid","event_time":"2025-10-27T17:39:49.007816Z","price_level":"115596.72","new_quantity":"0.53831712"},{"side":"bid","event_time":"2025-10-27T17:39:49.007816Z","price_level":"115595.86","new_quantity":"0"},{"side":"offer","event_time":"2025-10-27T17:39:49.007816Z","price_level":"115662","new_quantity":"0"},{"side":"offer","event_time":"2025-10-27T17:39:49.007816Z","price_level":"115662.98","new_quantity":"0"},{"side":"offer","event_time":"2025-10-27T17:39:49.007816Z","price_level":"115666","new_quantity":"0"},{"side":"offer","event_time":"2025-10-27T17:39:49.007816Z","price_level":"115669.95","new_quantity":"0.38913852"},{"side":"offer","event_time":"2025-10-27T17:39:49.007816Z","price_level":"115669.97","new_quantity":"0"},{"side":"offer","event_time":"2025-10-27T17:39:49.007816Z","price_level":"115671","new_quantity":"0.03459026"},{"side":"offer","event_time":"2025-10-27T17:39:49.007816Z","price_level":"115671.72","new_quantity":"0"},{"side":"offer","event_time":"2025-10-27T17:39:49.007816Z","price_level":"115673.29","new_quantity":"0.1383577"},{"side":"offer","event_time":"2025-10-27T17:39:49.007816Z","price_level":"115725.59","new_quantity":"0.56828517"},{"side":"offer","event_time":"2025-10-27T17:39:49.007816Z","price_level":"115727.14","new_quantity":"0"},{"side":"offer","event_time":"2025-10-27T17:39:49.007816Z","price_level":"115797.83","new_quantity":"0"}]}]}
{"channel":"l2_data","client_id":"","timestamp":"2025-10-27T17:39:49.121016286Z","sequence_num":137992,"events":[{"type":"update","product_id":"ETH-USD","updates":[{"side":"bid","event_time":"2025-10-27T17:39:49.082711Z","price_level":"4206.7","new_quantity":"0"},{"side":"offer","event_time":"2025-10-27T17:39:49.082711Z","price_level":"4221.1","new_quantity":"1.94391607"},{"side":"offer","event_time":"2025-10-27T17:39:49.082711Z","price_level":"4221.4","new_quantity":"0"},{"side":"offer","event_time":"2025-10-27T17:39:49.082711Z","price_level":"4229.15","new_quantity":"0"}]}]}
{"channel":"l2_data","client_id":"","timestamp":"2025-10-27T17:39:49.168568157Z","sequence_num":137994,"events":[{"type":"update","product_id":"ETH-USD","updates":[{"side":"offer","event_time":"2025-10-27T17:39:49.121874Z","price_level":"4219.35","new_quantity":"0.05926418"},{"side":"offer","event_time":"2025-10-27T17:39:49.121874Z","price_level":"4219.78","new_quantity":"0.05926418"},{"side":"offer","event_time":"2025-10-27T17:39:49.121874Z","price_level":"4220.2","new_quantity":"0.05926418"}]}]}
{"channel":"l2_data","client_id":"","timestamp":"2025-10-27T17:39:49.220659722Z","sequence_num":137995,"events":[{"type":"update","product_id":"ETH-USD","updates":[{"side":"bid","event_time":"2025-10-27T17:39:49.174623Z","price_level":"4216.79","new_quantity":"0"},{"side":"offer","event_time":"2025-10-27T17:39:49.174623Z","price_level":"4218.19","new_quantity":"0.00237076"},{"side":"offer","event_time":"2025-10-27T17:39:49.174623Z","price_level":"4218.2","new_quantity":"0"},{"side":"offer","event_time":"2025-10-27T17:39:49.174623Z","price_level":"4218.23","new_quantity":"0.07111987"},{"side":"offer","event_time":"2025-10-27T17:39:49.174623Z","price_level":"4218.24","new_quantity":"0.59266423"},{"side":"offer","event_time":"2025-10-27T17:39:49.174623Z","price_level":"4219.11","new_quantity":"0.6856796"},{"side":"offer","event_time":"2025-10-27T17:39:49.174623Z","price_level":"4219.15","new_quantity":"0"},{"side":"offer","event_time":"2025-10-27T17:39:49.174623Z","price_level":"4219.33","new_quantity":"3.18809597"},{"side":"offer","event_time":"2025-10-27T17:39:49.174623Z","price_level":"4221.1","new_quantity":"0"},{"side":"offer","event_time":"2025-10-27T17:39:49.174623Z","price_level":"4221.37","new_quantity":"13.30023232"},{"side":"offer","event_time":"2025-10-27T17:39:49.174623Z","price_level":"4221.38","new_quantity":"1.94391607"},{"side":"offer","event_time":"2025-10-27T17:39:49.174623Z","price_level":"4221.39","new_quantity":"0"}]}]}
{"channel":"l2_data","client_id":"","timestamp":"2025-10-27T17:39:49.270678097Z","sequence_num":137996,"events":[{"type":"update","product_id":"ETH-USD","updates":[{"side":"bid","event_time":"2025-10-27T17:39:49.227383Z","price_level":"4218.06","new_quantity":"0.0734674"},{"side":"bid","event_time":"2025-10-27T17:39:49.227383Z","price_level":"4216.79","new_quantity":"0.21565049"},{"side":"offer","event_time":"2025-10-27T17:39:49.227383Z","price_level":"4218.19","new_quantity":"0"},{"side":"offer","event_time":"2025-10-27T17:39:49.227383Z","price_level":"4218.2","new_quantity":"0.00237076"},{"side":"offer","event_time":"2025-10-27T17:39:49.227383Z","price_level":"4220.62","new_quantity":"0.03569201"},{"side":"offer","event_time":"2025-10-27T17:39:49.227383Z","price_level":"4221.3","new_quantity":"0"}]}]}
{"channel":"l2_data","client_id":"","timestamp":"2025-10-27T17:39:49.296080508Z","sequence_num":137997,"events":[{"type":"update","product_id":"BTC-USD","updates":[{"side":"bid","event_time":"2025-10-27T17:39:49.242683Z","price_level":"114101.27","new_quantity":"0"}]}]}
{"channel":"l2_data","client_id":"","timestamp":"2025-10-27T17:39:49.319020164Z","sequence_num":137998,"events":[{"type":"update","product_id":"ETH-USD","updates":[{"side":"offer","event_time":"2025-10-27T17:39:49.254841Z","price_level":"4220.16","new_quantity":"0.47391568"}]}]}
{"channel":"l2_data","client_id":"","timestamp":"2025-10-27T17:39:49.347581455Z","sequence_num":137999,"events":[{"type":"update","product_id":"BTC-USD","updates":[{"side":"bid","event_time":"2025-10-27T17:39:49.304554Z","price_level":"115629.84","new_quantity":"0.02161175"},{"side":"bid","event_time":"2025-10-27T17:39:49.304554Z","price_level":"115627.49","new_quantity":"0"},{"side":"bid","event_time":"2025-10-27T17:39:49.304554Z","price_level":"115625.92","new_quantity":"0"},{"side":"bid","event_time":"2025-10-27T17:39:49.304554Z","price_level":"115625.51","new_quantity":"0.08"},{"side":"bid","event_time":"2025-10-27T17:39:49.304554Z","price_level":"115624.45","new_quantity":"0.011242"},{"side":"bid","event_time":"2025-10-27T17:39:49.304554Z","price_level":"115623.63","new_quantity":"0"},{"side":"bid","event_time":"2025-10-27T17:39:49.304554Z","price_level":"115615.85","new_quantity":"0"},{"side":"bid","event_time":"2025-10-27T17:39:49.304554Z","price_level":"115612.61","new_quantity":"0"},{"side":"bid","event_time":"2025-10-27T17:39:49.304554Z","price_level":"115599.34","new_quantity":"0.6522095"},{"side":"bid","event_time":"2025-10-27T17:39:49.304554Z","price_level":"115570.31","new_quantity":"0.8137562"},{"side":"bid","event_time":"2025-10-27T17:39:49.304554Z","price_level":"115570.3","new_quantity":"1.5"},{"side":"bid","event_time":"2025-10-27T17:39:49.304554Z","price_level":"115568.51","new_quantity":"0"},{"side":"bid","event_time":"2025-10-27T17:39:49.304554Z","price_level":"115567.26","new_quantity":"0"},{"side":"bid","event_time":"2025-10-27T17:39:49.304554Z","price_level":"115564.66","new_quantity":"1.24988861"},{"side":"bid","event_time":"2025-10-27T17:39:49.304554Z","price_level":"115563.3","new_quantity":"0"},{"side":"bid","event_time":"2025-10-27T17:39:49.304554Z","price_level":"115542.58","new_quantity":"0.00043234"},{"side":"bid","event_time":"2025-10-27T17:39:49.304554Z","price_level":"115542.57","new_quantity":"0.103753"},{"side":"bid","event_time":"2025-10-27T17:39:49.304554Z","price_level":"115538.66","new_quantity":"0"},{"side":"bid","event_time":"2025-10-27T17:39:49.304554Z","price_level":"114532.34","new_quantity":"0.07007"},{"side":"bid","event_time":"2025-10-27T17:39:49.304554Z","price_level":"114532.04","new_quantity":"0"},{"side":"bid","event_time":"2025-10-27T17:39:49.304554Z","price_level":"114317.84","new_quantity":"0.07007"},{"side":"bid","event_time":"2025-10-27T17:39:49.304554Z","price_level":"114316.97","new_quantity":"0"},{"side":"bid","event_time":"2025-10-27T17:39:49.304554Z","price_level":"114103.33","new_quantity":"0.07007"},{"side":"bid","event_time":"2025-10-27T17:39:49.304554Z","price_level":"101181.5","new_quantity":"0.00049568"},{"side":"offer","event_time":"2025-10-27T17:39:49.304554Z","price_level":"115644.4","new_quantity":"0.02594159"},{"side":"offer","event_time":"2025-10-27T17:39:49.304554Z","price_level":"115645.78","new_quantity":"0"},{"side":"offer","event_time":"2025-10-27T17:39:49.304554Z","price_level":"115647.51","new_quantity":"0.00008408"},{"side":"offer","event_time":"2025-10-27T17:39:49.304554Z","price_level":"115647.52","new_quantity":"0.00203294"},{"side":"offer","event_time":"2025-10-27T17:39:49.304554Z","price_level":"115652.18","new_quantity":"0"},{"side":"offer","event_time":"2025-10-27T17:39:49.304554Z","price_level":"115655.06","new_quantity":"0.16447"},{"side":"offer","event_time":"2025-10-27T17:39:49.304554Z","price_level":"115673.29","new_quantity":"0.13836062"},{"side":"offer","event_time":"2025-10-27T17:39:49.304554Z","price_level":"115686.68","new_quantity":"0.02014916"},{"side":"offer","event_time":"2025-10-27T17:39:49.304554Z","price_level":"115689.73","new_quantity":"0.16688278"},{"side":"offer","event_time":"2025-10-27T17:39:49.304554Z","price_level":"115694.05","new_quantity":"0"},{"side":"offer","event_time":"2025-10-27T17:39:49.304554Z","price_level":"115700.99","new_quantity":"0.00043234"},{"side":"offer","event_time":"2025-10-27T17:39:49.304554Z","price_level":"115703.27","new_quantity":"0"},{"side":"offer","event_time":"2025-10-27T17:39:49.304554Z","price_level":"115706.38","new_quantity":"0.25618139"},{"side":"offer","event_time":"2025-10-27T17:39:49.304554Z","price_level":"115709.99","new_quantity":"0"},{"side":"offer","event_time":"2025-10-27T17:39:49.304554Z","price_level":"115711.99","new_quantity":"0.00043234"},{"side":"offer","event_time":"2025-10-27T17:39:49.304554Z","price_level":"115712.77","new_quantity":"0"},{"side":"offer","event_time":"2025-10-27T17:39:49.304554Z","price_level":"115797.83","new_quantity":"0.045"},{"side":"offer","event_time":"2025-10-27T17:39:49.304554Z","price_level":"116376.07","new_quantity":"0"}]}]}
{"channel":"l2_data","client_id":"","timestamp":"2025-10-27T17:39:49.36931462Z","sequence_num":138000,"events":[{"type":"update","product_id":"ETH-USD","updates":[{"side":"offer","event_time":"2025-10-27T17:39:49.326959Z","price_level":"4218.54","new_quantity":"0.11853395"},{"side":"offer","event_time":"2025-10-27T17:39:49.326959Z","price_level":"4221.35","new_quantity":"13.30029533"},{"side":"offer","event_time":"2025-10-27T17:39:49.326959Z","price_level":"4221.36","new_quantity":"1.94391607"},{"side":"offer","event_time":"2025-10-27T17:39:49.326959Z","price_level":"4221.37","new_quantity":"0"},{"side":"offer","event_time":"2025-10-27T17:39:49.326959Z","price_level":"4221.38","new_quantity":"0"}]}]}
{"channel":"l2_data","client_id":"","timestamp":"2025-10-27T17:39:49.398488059Z","sequence_num":138002,"events":[{"type":"update","product_id":"BTC-USD","updates":[{"side":"bid","event_time":"2025-10-27T17:39:49.358312Z","price_level":"115632.01","new_quantity":"0.07756898"},{"side":"bid","event_time":"2025-10-27T17:39:49.358312Z","price_level":"115629","new_quantity":"0"},{"side":"bid","event_time":"2025-10-27T17:39:49.358312Z","price_level":"115625.95","new_quantity":"0.00432"},{"side":"bid","event_time":"2025-10-27T17:39:49.358312Z","price_level":"115617.07","new_quantity":"0.5835004"},{"side":"bid","event_time":"2025-10-27T17:39:49.358312Z","price_level":"115616","new_quantity":"0"},{"side":"bid","event_time":"2025-10-27T17:39:49.358312Z","price_level":"115603.77","new_quantity":"0.37038312"},{"side":"bid","event_time":"2025-10-27T17:39:49.358312Z","price_level":"115596.71","new_quantity":"0"},{"side":"offer","event_time":"2025-10-27T17:39:49.358312Z","price_level":"115705.5","new_quantity":"0.00043238"},{"side":"offer","event_time":"2025-10-27T17:39:49.358312Z","price_level":"115706.38","new_quantity":"0.25574902"}]}]}
{"channel":"l2_data","client_id":"","timestamp":"2025-10-27T17:39:49.420609581Z","sequence_num":138003,"events":[{"type":"update","product_id":"ETH-USD","updates":[{"side":"bid","event_time":"2025-10-27T17:39:49.342499Z","price_level":"4206.6","new_quantity":"32.95536557"},{"side":"offer","event_time":"2025-10-27T17:39:49.342499Z","price_level":"4229.15","new_quantity":"32.62567048"}]}]}
{"channel":"l2_data","client_id":"","timestamp":"2025-10-27T17:39:49.447454508Z","sequence_num":138004,"events":[{"type":"update","product_id":"BTC-USD","updates":[{"side":"bid","event_time":"2025-10-27T17:39:49.385821Z","price_level":"115626","new_quantity":"0.4"},{"side":"bid","event_time":"2025-10-27T17:39:49.385821Z","price_level":"115625.92","new_quantity":"0.00432"},{"side":"bid","event_time":"2025-10-27T17:39:49.385821Z","price_level":"115617.07","new_quantity":"1.64842955"},{"side":"bid","event_time":"2025-10-27T17:39:49.385821Z","price_level":"115616","new_quantity":"2"},{"side":"bid","event_time":"2025-10-27T17:39:49.385821Z","price_level":"115575.01","new_quantity":"0.8137231"},{"side":"bid","event_time":"2025-10-27T17:39:49.385821Z","price_level":"115575","new_quantity":"1.5"},{"side":"bid","event_time":"2025-10-27T17:39:49.385821Z","price_level":"115570.31","new_quantity":"0"},{"side":"bid","event_time":"2025-10-27T17:39:49.385821Z","price_level":"115570.3","new_quantity":"0"},{"side":"offer","event_time":"2025-10-27T17:39:49.385821Z","price_level":"115665.32","new_quantity":"0.00432"},{"side":"offer","event_time":"2025-10-27T17:39:49.385821Z","price_level":"115665.33","new_quantity":"0.00432"},{"side":"offer","event_time":"2025-10-27T17:39:49.385821Z","price_level":"115723.69","new_quantity":"0.5682945"},{"side":"offer","event_time":"2025-10-27T17:39:49.385821Z","price_level":"115723.7","new_quantity":"1"},{"side":"offer","event_time":"2025-10-27T17:39:49.385821Z","price_level":"115725.59","new_quantity":"0"},{"side":"offer","event_time":"2025-10-27T17:39:49.385821Z","price_level":"115725.6","new_quantity":"0"}]}]}
{"channel":"l2_data","client_id":"","timestamp":"2025-10-27T17:39:49.496906543Z","sequence_num":138005,"events":[{"type":"update","product_id":"BTC-USD","updates":[{"side":"bid","event_time":"2025-10-27T17:39:49.449923Z","price_level":"115628.27","new_quantity":"0.00432"},{"side":"bid","event_time":"2025-10-27T17:39:49.449923Z","price_level":"115627.3","new_quantity":"0.50893064"},{"side":"bid","event_time":"2025-10-27T17:39:49.449923Z","price_level":"115575","new_quantity":"0"},{"side":"bid","event_time":"2025-10-27T17:39:49.449923Z","price_level":"115573.4","new_quantity":"1.5"},{"side":"bid","event_time":"2025-10-27T17:39:49.449923Z","price_level":"101181.5","new_quantity":"0.00446112"},{"side":"offer","event_time":"2025-10-27T17:39:49.449923Z","price_level":"115663","new_quantity":"2.00432"},{"side":"offer","event_time":"2025-10-27T17:39:49.449923Z","price_level":"115666","new_quantity":"0.4"},{"side":"offer","event_time":"2025-10-27T17:39:49.449923Z","price_level":"115723.5","new_quantity":"1"},{"side":"offer","event_time":"2025-10-27T17:39:49.449923Z","price_level":"115723.7","new_quantity":"0"}]}]}
{"channel":"l2_data","client_id":"","timestamp":"2025-10-27T17:39:49.52145251Z","sequence_num":138006,"events":[{"type":"update","product_id":"ETH-USD","updates":[{"side":"bid","event_time":"2025-10-27T17:39:49.482519Z","price_level":"4217.4","new_quantity":"0"},{"side":"bid","event_time":"2025-10-27T17:39:49.482519Z","price_level":"4216.79","new_quantity":"0"},{"side":"offer","event_time":"2025-10-27T17:39:49.482519Z","price_level":"4221.1","new_quantity":"1.94391607"},{"side":"offer","event_time":"2025-10-27T17:39:49.482519Z","price_level":"4221.35","new_quantity":"0"},{"side":"offer","event_time":"2025-10-27T17:39:49.482519Z","price_level":"4221.36","new_quantity":"0"},{"side":"offer","event_time":"2025-10-27T17:39:49.482519Z","price_level":"4221.51","new_quantity":"13.29979124"}]}]}
{"channel":"l2_data","client_id":"","timestamp":"2025-10-27T17:39:49.5478955Z","sequence_num":138007,"events":[{"type":"update","product_id":"BTC-USD","updates":[{"side":"bid","event_time":"2025-10-27T17:39:49.504268Z","price_level":"115627.3","new_quantity":"0.23832201"},{"side":"bid","event_time":"2025-10-27T17:39:49.504268Z","price_level":"115626","new_quantity":"0"},{"side":"bid","event_time":"2025-10-27T17:39:49.504268Z","price_level":"115617.07","new_quantity":"0.5835004"},{"side":"bid","event_time":"2025-10-27T17:39:49.504268Z","price_level":"115616","new_quantity":"0"},{"side":"offer","event_time":"2025-10-27T17:39:49.504268Z","price_level":"115662","new_quantity":"2"},{"side":"offer","event_time":"2025-10-27T17:39:49.504268Z","price_level":"115666","new_quantity":"0.4"},{"side":"offer","event_time":"2025-10-27T17:39:49.504268Z","price_level":"115706.38","new_quantity":"0"},{"side":"offer","event_time":"2025-10-27T17:39:49.504268Z","price_level":"115709.99","new_quantity":"0.25574104"},{"side":"offer","event_time":"2025-10-27T17:39:49.504268Z","price_level":"115723.49","new_quantity":"0.56829549"},{"side":"offer","event_time":"2025-10-27T17:39:49.504268Z","price_level":"115723.69","new_quantity":"0"}]}]}
{"channel":"l2_data","client_id":"","timestamp":"2025-10-27T17:39:49.572319279Z","sequence_num":138008,"events":[{"type":"update","product_id":"ETH-USD","updates":[{"side":"bid","event_time":"2025-10-27T17:39:49.520818Z","price_level":"4218.01","new_quantity":"0"},{"side":"bid","event_time":"2025-10-27T17:39:49.520818Z","price_level":"4218","new_quantity":"1.74967"},{"side":"bid","event_time":"2025-10-27T17:39:49.520818Z","price_level":"4217.81","new_quantity":"1.32243039"},{"side":"bid","event_time":"2025-10-27T17:39:49.520818Z","price_level":"4217.8","new_quantity":"0.543"},{"side":"bid","event_time":"2025-10-27T17:39:49.520818Z","price_level":"4217.7","new_quantity":"0"},{"side":"bid","event_time":"2025-10-27T17:39:49.520818Z","price_level":"4217.66","new_quantity":"0.01570132"},{"side":"bid","event_time":"2025-10-27T17:39:49.520818Z","price_level":"4217.61","new_quantity":"11.04995419"},{"side":"bid","event_time":"2025-10-27T17:39:49.520818Z","price_level":"4217.6","new_quantity":"3.790973"},{"side":"bid","event_time":"2025-10-27T17:39:49.520818Z","price_level":"4217.41","new_quantity":"3.14195908"},{"side":"bid","event_time":"2025-10-27T17:39:49.520818Z","price_level":"4216.87","new_quantity":"0.21565049"},{"side":"offer","event_time":"2025-10-27T17:39:49.520818Z","price_level":"4218.07","new_quantity":"0.20206915"},{"side":"offer","event_time":"2025-10-27T17:39:49.520818Z","price_level":"4218.19","new_quantity":"0.01611952"},{"side":"offer","event_time":"2025-10-27T17:39:49.520818Z","price_level":"4218.2","new_quantity":"0.543"}]}]}
{"channel":"l2_data","client_id":"","timestamp":"2025-10-27T17:39:49.597986973Z","sequence_num":138009,"events":[{"type":"update","product_id":"BTC-USD","updates":[{"side":"bid","event_time":"2025-10-27T17:39:49.535067Z","price_level":"115622.58","new_quantity":"0.49138934"},{"side":"bid","event_time":"2025-10-27T17:39:49.535067Z","price_level":"115619","new_quantity":"0.4"},{"side":"bid","event_time":"2025-10-27T17:39:49.535067Z","price_level":"115617.07","new_quantity":"1.44712373"},{"side":"bid","event_time":"2025-10-27T17:39:49.535067Z","price_level":"115615","new_quantity":"2.4"},{"side":"bid","event_time":"2025-10-27T17:39:49.535067Z","price_level":"115614","new_quantity":"0"},{"side":"bid","event_time":"2025-10-27T17:39:49.535067Z","price_level":"115603.77","new_quantity":"0"},{"side":"bid","event_time":"2025-10-27T17:39:49.535067Z","price_level":"115599.35","new_quantity":"0.37040303"},{"side":"offer","event_time":"2025-10-27T17:39:49.535067Z","price_level":"115662","new_quantity":"0"},{"side":"offer","event_time":"2025-10-27T17:39:49.535067Z","price_level":"115666","new_quantity":"0"},{"side":"offer","event_time":"2025-10-27T17:39:49.535067Z","price_level":"115689.73","new_quantity":"0"},{"side":"offer","event_time":"2025-10-27T17:39:49.535067Z","price_level":"115694.05","new_quantity":"0.16687655"}]}]}
{"channel":"l2_data","client_id":"","timestamp":"2025-10-27T17:39:49.619824177Z","sequence_num":138010,"events":[{"type":"update","product_id":"ETH-USD","updates":[{"side":"bid","event_time":"2025-10-27T17:39:49.565395Z","price_level":"4217.61","new_quantity":"20.42016316"},{"side":"bid","event_time":"2025-10-27T17:39:49.565395Z","price_level":"4217.6","new_quantity":"13.790973"},{"side":"bid","event_time":"2025-10-27T17:39:49.565395Z","price_level":"4217.5","new_quantity":"20.001"},{"side":"bid","event_time":"2025-10-27T17:39:49.565395Z","price_level":"4217.41","new_quantity":"13.94238604"},{"side":"bid","event_time":"2025-10-27T17:39:49.565395Z","price_level":"4217.4","new_quantity":"20"},{"side":"bid","event_time":"2025-10-27T17:39:49.565395Z","price_level":"4216.87","new_quantity":"0"}]}]}
{"channel":"l2_data","client_id":"","timestamp":"2025-10-27T17:39:49.64706976Z","sequence_num":138012,"events":[{"type":"update","product_id":"BTC-USD","updates":[{"side":"bid","event_time":"2025-10-27T17:39:49.583255Z","price_level":"115613","new_quantity":"0.4"},{"side":"offer","event_time":"2025-10-27T17:39:49.583255Z","price_level":"115636.01","new_quantity":"0.00196866"},{"side":"offer","event_time":"2025-10-27T17:39:49.583255Z","price_level":"115653.91","new_quantity":"0.26854143"},{"side":"offer","event_time":"2025-10-27T17:39:49.583255Z","price_level":"115663.01","new_quantity":"0.00432"},{"side":"offer","event_time":"2025-10-27T17:39:49.583255Z","price_level":"115673.29","new_quantity":"0"},{"side":"offer","event_time":"2025-10-27T17:39:49.583255Z","price_level":"115675.75","new_quantity":"0.13836062"},{"side":"offer","event_time":"2025-10-27T17:39:49.583255Z","price_level":"115797.83","new_quantity":"0"},{"side":"offer","event_time":"2025-10-27T17:39:49.583255Z","price_level":"116376.07","new_quantity":"0.045"}]}]}
{"channel":"l2_data","client_id":"","timestamp":"2025-10-27T17:39:49.6689856Z","sequence_num":138013,"events":[{"type":"update","product_id":"ETH-USD","updates":[{"side":"bid","event_time":"2025-10-27T17:39:49.612215Z","price_level":"4216.83","new_quantity":"0.21565049"}]}]}
{"channel":"l2_data","client_id":"","timestamp":"2025-10-27T17:39:49.694818247Z","sequence_num":138014,"events":[{"type":"update","product_id":"BTC-USD","updates":[{"side":"offer","event_time":"2025-10-27T17:39:49.634893Z","price_level":"115642.9","new_quantity":"0.02594193"},{"side":"offer","event_time":"2025-10-27T17:39:49.634893Z","price_level":"115644.4","new_quantity":"0"},{"side":"offer","event_time":"2025-10-27T17:39:49.634893Z","price_level":"115665.99","new_quantity":"0"},{"side":"offer","event_time":"2025-10-27T17:39:49.634893Z","price_level":"115681.26","new_quantity":"0"}]}]}
{"channel":"l2_data","client_id":"","timestamp":"2025-10-27T17:39:49.722548817Z","sequence_num":138015,"events":[{"type":"update","product_id":"ETH-USD","updates":[{"side":"bid","event_time":"2025-10-27T17:39:49.676832Z","price_level":"4217.9","new_quantity":"0"},{"side":"bid","event_time":"2025-10-27T17:39:49.676832Z","price_level":"4217.65","new_quantity":"0"},{"side":"offer","event_time":"2025-10-27T17:39:49.676832Z","price_level":"4218.1","new_quantity":"0.543"},{"side":"offer","event_time":"2025-10-27T17:39:49.676832Z","price_level":"4218.19","new_quantity":"0.00237076"}]}]}
{"channel":"l2_data","client_id":"","timestamp":"2025-10-27T17:39:49.743935585Z","sequence_num":138016,"events":[{"type":"update","product_id":"BTC-USD","updates":[{"side":"offer","event_time":"2025-10-27T17:39:49.701299Z","price_level":"115666","new_quantity":"0.4"}]}]}
{"channel":"l2_data","client_id":"","timestamp":"2025-10-27T17:39:49.771115298Z","sequence_num":138017,"events":[{"type":"update","product_id":"ETH-USD","updates":[{"side":"bid","event_time":"2025-10-27T17:39:49.703902Z","price_level":"4217.81","new_quantity":"0.66520582"},{"side":"bid","event_time":"2025-10-27T17:39:49.703902Z","price_level":"4217.66","new_quantity":"0.002"},{"side":"bid","event_time":"2025-10-27T17:39:49.703902Z","price_level":"4217.62","new_quantity":"0.02009744"},{"side":"bid","event_time":"2025-10-27T17:39:49.703902Z","price_level":"4217.34","new_quantity":"1.66121"},{"side":"offer","event_time":"2025-10-27T17:39:49.703902Z","price_level":"4218.48","new_quantity":"0.01521293"}]}]}
{"channel":"l2_data","client_id":"","timestamp":"2025-10-27T17:39:49.797120134Z","sequence_num":138018,"events":[{"type":"update","product_id":"BTC-USD","updates":[{"side":"bid","event_time":"2025-10-27T17:39:49.72995Z","price_level":"101181.5","new_quantity":"0"},{"side":"offer","event_time":"2025-10-27T17:39:49.72995Z","price_level":"115666","new_quantity":"0"},{"side":"offer","event_time":"2025-10-27T17:39:49.72995Z","price_level":"116376.07","new_quantity":"0"}]}]}
{"channel":"l2_data","client_id":"","timestamp":"2025-10-27T17:39:49.821219989Z","sequence_num":138019,"events":[{"type":"update","product_id":"ETH-USD","updates":[{"side":"bid","event_time":"2025-10-27T17:39:49.776925Z","price_level":"4217.56","new_quantity":"3.3204"},{"side":"offer","event_time":"2025-10-27T17:39:49.776925Z","price_level":"4218.07","new_quantity":"0.02706915"}]}]}
{"channel":"l2_data","client_id":"","timestamp":"2025-10-27T17:39:49.847364359Z","sequence_num":138021,"events":[{"type":"update","product_id":"BTC-USD","updates":[{"side":"bid","event_time":"2025-10-27T17:39:49.782047Z","price_level":"115599.35","new_quantity":"1.69570572"},{"side":"bid","event_time":"2025-10-27T17:39:49.782047Z","price_level":"115552.53","new_quantity":"1.16521281"},{"side":"bid","event_time":"2025-10-27T17:39:49.782047Z","price_level":"115552.51","new_quantity":"0"},{"side":"bid","event_time":"2025-10-27T17:39:49.782047Z","price_level":"115489.65","new_quantity":"0.0850725"},{"side":"offer","event_time":"2025-10-27T17:39:49.782047Z","price_level":"115662","new_quantity":"0"},{"side":"offer","event_time":"2025-10-27T17:39:49.782047Z","price_level":"115666","new_quantity":"0"},{"side":"offer","event_time":"2025-10-27T17:39:49.782047Z","price_level":"115683.66","new_quantity":"0.08762622"}]}]}
{"channel":"l2_data","client_id":"","timestamp":"2025-10-27T17:39:49.894326153Z","sequence_num":138023,"events":[{"type":"update","product_id":"BTC-USD","updates":[{"side":"offer","event_time":"2025-10-27T17:39:49.840949Z","price_level":"115638.02","new_quantity":"0.00864767"},{"side":"offer","event_time":"2025-10-27T17:39:49.840949Z","price_level":"115661","new_quantity":"0"},{"side":"offer","event_time":"2025-10-27T17:39:49.840949Z","price_level":"115665","new_quantity":"0"},{"side":"offer","event_time":"2025-10-27T17:39:49.840949Z","price_level":"116376.07","new_quantity":"0.045"}]}]}
{"channel":"l2_data","client_id":"","timestamp":"2025-10-27T17:39:49.922351143Z","sequence_num":138024,"events":[{"type":"update","product_id":"ETH-USD","updates":[{"side":"bid","event_time":"2025-10-27T17:39:49.85972Z","price_level":"4217.34","new_quantity":"0"},{"side":"offer","event_time":"2025-10-27T17:39:49.85972Z","price_level":"4218.07","new_quantity":"0.02706915"}]}]}
{"channel":"l2_data","client_id":"","timestamp":"2025-10-27T17:39:49.949108768Z","sequence_num":138026,"events":[{"type":"update","product_id":"BTC-USD","updates":[{"side":"bid","event_time":"2025-10-27T17:39:49.901912Z","price_level":"115622.58","new_quantity":"0.2896162"},{"side":"bid","event_time":"2025-10-27T17:39:49.901912Z","price_level":"115622","new_quantity":"0.4"},{"side":"bid","event_time":"2025-10-27T17:39:49.901912Z","price_level":"115619","new_quantity":"0"},{"side":"bid","event_time":"2025-10-27T17:39:49.901912Z","price_level":"115601.55","new_quantity":"0"},{"side":"bid","event_time":"2025-10-27T17:39:49.901912Z","price_level":"115599.35","new_quantity":"0.37040303"},{"side":"bid","event_time":"2025-10-27T17:39:49.901912Z","price_level":"115599.34","new_quantity":"0"},{"side":"bid","event_time":"2025-10-27T17:39:49.901912Z","price_level":"115574.5","new_quantity":"1.5"},{"side":"bid","event_time":"2025-10-27T17:39:49.901912Z","price_level":"115573.4","new_quantity":"0"},{"side":"bid","event_time":"2025-10-27T17:39:49.901912Z","price_level":"115564.66","new_quantity":"0"},{"side":"offer","event_time":"2025-10-27T17:39:49.901912Z","price_level":"115671","new_quantity":"0"},{"side":"offer","event_time":"2025-10-27T17:39:49.901912Z","price_level":"115686.68","new_quantity":"0"},{"side":"offer","event_time":"2025-10-27T17:39:49.901912Z","price_level":"115723.49","new_quantity":"0"},{"side":"offer","event_time":"2025-10-27T17:39:49.901912Z","price_level":"115723.5","new_quantity":"0"},{"side":"offer","event_time":"2025-10-27T17:39:49.901912Z","price_level":"115723.6","new_quantity":"1"},{"side":"offer","event_time":"2025-10-27T17:39:49.901912Z","price_level":"115727.15","new_quantity":"0"},{"side":"offer","event_time":"2025-10-27T17:39:49.901912Z","price_level":"115727.16","new_quantity":"0"},{"side":"offer","event_time":"2025-10-27T17:39:49.901912Z","price_level":"115735.57","new_quantity":"0.56823617"}]}]}
{"channel":"l2_data","client_id":"","timestamp":"2025-10-27T17:39:49.970703245Z","sequence_num":138027,"events":[{"type":"update","product_id":"ETH-USD","updates":[{"side":"bid","event_time":"2025-10-27T17:39:49.933487Z","price_level":"4217.56","new_quantity":"1.66121"},{"side":"bid","event_time":"2025-10-27T17:39:49.933487Z","price_level":"4215.46","new_quantity":"2.99642811"},{"side":"bid","event_time":"2025-10-27T17:39:49.933487Z","price_level":"4213.72","new_quantity":"19.7523407"},{"side":"bid","event_time":"2025-10-27T17:39:49.933487Z","price_level":"4213.7","new_quantity":"0"},{"side":"bid","event_time":"2025-10-27T17:39:49.933487Z","price_level":"4213.69","new_quantity":"0"},{"side":"bid","event_time":"2025-10-27T17:39:49.933487Z","price_level":"4212.01","new_quantity":"11.18513425"},{"side":"offer","event_time":"2025-10-27T17:39:49.933487Z","price_level":"4218.07","new_quantity":"0.34482915"},{"side":"offer","event_time":"2025-10-27T17:39:49.933487Z","price_level":"4218.1","new_quantity":"0.543"}]}]}
{"channel":"l2_data","client_id":"","timestamp":"2025-10-27T17:39:49.998472124Z","sequence_num":138028,"events":[{"type":"update","product_id":"BTC-USD","updates":[{"side":"bid","event_time":"2025-10-27T17:39:49.955802Z","price_level":"115636","new_quantity":"0.1474112"},{"side":"bid","event_time":"2025-10-27T17:39:49.955802Z","price_level":"115632.82","new_quantity":"0"},{"side":"bid","event_time":"2025-10-27T17:39:49.955802Z","price_level":"115629.84","new_quantity":"0"},{"side":"bid","event_time":"2025-10-27T17:39:49.955802Z","price_level":"115628.42","new_quantity":"0.00864839"},{"side":"bid","event_time":"2025-10-27T17:39:49.955802Z","price_level":"115628.27","new_quantity":"0"},{"side":"bid","event_time":"2025-10-27T17:39:49.955802Z","price_level":"115625.95","new_quantity":"0"},{"side":"bid","event_time":"2025-10-27T17:39:49.955802Z","price_level":"115625.92","new_quantity":"0"},{"side":"bid","event_time":"2025-10-27T17:39:49.955802Z","price_level":"115625.51","new_quantity":"0"},{"side":"bid","event_time":"2025-10-27T17:39:49.955802Z","price_level":"115622.58","new_quantity":"0.20177314"},{"side":"bid","event_time":"2025-10-27T17:39:49.955802Z","price_level":"115622.57","new_quantity":"0"},{"side":"bid","event_time":"2025-10-27T17:39:49.955802Z","price_level":"115622","new_quantity":"0"},{"side":"bid","event_time":"2025-10-27T17:39:49.955802Z","price_level":"115621.28","new_quantity":"0.00432"},{"side":"bid","event_time":"2025-10-27T17:39:49.955802Z","price_level":"115619","new_quantity":"0.4"},{"side":"bid","event_time":"2025-10-27T17:39:49.955802Z","price_level":"115617.07","new_quantity":"0.73072373"},{"side":"bid","event_time":"2025-10-27T17:39:49.955802Z","price_level":"115617","new_quantity":"0"},{"side":"bid","event_time":"2025-10-27T17:39:49.955802Z","price_level":"115615","new_quantity":"0.4"},{"side":"bid","event_time":"2025-10-27T17:39:49.955802Z","price_level":"115611.01","new_quantity":"1.10293291"},{"side":"bid","event_time":"2025-10-27T17:39:49.955802Z","price_level":"115574.5","new_quantity":"0"},{"side":"bid","event_time":"2025-10-27T17:39:49.955802Z","price_level":"115573.4","new_quantity":"1.5"},{"side":"offer","event_time":"2025-10-27T17:39:49.955802Z","price_level":"115641.43","new_quantity":"0.02594226"},{"side":"offer","event_time":"2025-10-27T17:39:49.955802Z","price_level":"115642.9","new_quantity":"0"},{"side":"offer","event_time":"2025-10-27T17:39:49.955802Z","price_level":"115647.49","new_quantity":"0.00008451"},{"side":"offer","event_time":"2025-10-27T17:39:49.955802Z","price_level":"115647.5","new_quantity":"0.00362124"},{"side":"offer","event_time":"2025-10-27T17:39:49.955802Z","price_level":"115647.51","new_quantity":"0"},{"side":"offer","event_time":"2025-10-27T17:39:49.955802Z","price_level":"115647.52","new_quantity":"0.30972959"},{"side":"offer","event_time":"2025-10-27T17:39:49.955802Z","price_level":"115647.58","new_quantity":"0.1425"},{"side":"offer","event_time":"2025-10-27T17:39:49.955802Z","price_level":"115658.36","new_quantity":"0.00432"},{"side":"offer","event_time":"2025-10-27T17:39:49.955802Z","price_level":"115658.37","new_quantity":"0.00432"},{"side":"offer","event_time":"2025-10-27T17:39:49.955802Z","price_level":"115662","new_quantity":"2"},{"side":"offer","event_time":"2025-10-27T17:39:49.955802Z","price_level":"115663","new_quantity":"2"},{"side":"offer","event_time":"2025-10-27T17:39:49.955802Z","price_level":"115663.01","new_quantity":"0"},{"side":"offer","event_time":"2025-10-27T17:39:49.955802Z","price_level":"115665.32","new_quantity":"0"},{"side":"offer","event_time":"2025-10-27T17:39:49.955802Z","price_level":"115665.33","new_quantity":"0"},{"side":"offer","event_time":"2025-10-27T17:39:49.955802Z","price_level":"115666","new_quantity":"0.4"},{"side":"offer","event_time":"2025-10-27T17:39:49.955802Z","price_level":"115673.29","new_quantity":"0.13836062"},{"side":"offer","event_time":"2025-10-27T17:39:49.955802Z","price_level":"115675.75","new_quantity":"0"},{"side":"offer","event_time":"2025-10-27T17:39:49.955802Z","price_level":"115689.73","new_quantity":"0.16688278"},{"side":"offer","event_time":"2025-10-27T17:39:49.955802Z","price_level":"115694.05","new_quantity":"0"},{"side":"offer","event_time":"2025-10-27T17:39:49.955802Z","price_level":"115705.5","new_quantity":"0.25618335"},{"side":"offer","event_time":"2025-10-27T17:39:49.955802Z","price_level":"115709.99","new_quantity":"0"},{"side":"offer","event_time":"2025-10-27T17:39:49.955802Z","price_level":"115716.36","new_quantity":"0.39306935"},{"side":"offer","event_time":"2025-10-27T17:39:49.955802Z","price_level":"115719.94","new_quantity":"0"}]}]}
{"channel":"l2_data","client_id":"","timestamp":"2025-10-27T17:39:50.019267207Z","sequence_num":138029,"events":[{"type":"update","product_id":"ETH-USD","updates":[{"side":"bid","event_time":"2025-10-27T17:39:49.972989Z","price_level":"4217.34","new_quantity":"1.66097"}]}]}
{"channel":"l2_data","client_id":"","timestamp":"2025-10-27T17:39:50.047642228Z","sequence_num":138030,"events":[{"type":"update","product_id":"BTC-USD","updates":[{"side":"bid","event_time":"2025-10-27T17:39:49.984051Z","price_level":"115630.09","new_quantity":"0.00864826"},{"side":"bid","event_time":"2025-10-27T17:39:49.984051Z","price_level":"115628.42","new_quantity":"0"},{"side":"bid","event_time":"2025-10-27T17:39:49.984051Z","price_level":"115622.58","new_quantity":"0.40655067"},{"side":"bid","event_time":"2025-10-27T17:39:49.984051Z","price_level":"115617.07","new_quantity":"1.65539362"},{"side":"bid","event_time":"2025-10-27T17:39:49.984051Z","price_level":"115612.01","new_quantity":"0.34897641"},{"side":"bid","event_time":"2025-10-27T17:39:49.984051Z","price_level":"115612","new_quantity":"2"},{"side":"bid","event_time":"2025-10-27T17:39:49.984051Z","price_level":"115611.02","new_quantity":"0"},{"side":"bid","event_time":"2025-10-27T17:39:49.984051Z","price_level":"115575.01","new_quantity":"0"},{"side":"bid","event_time":"2025-10-27T17:39:49.984051Z","price_level":"115573.4","new_quantity":"0"},{"side":"bid","event_time":"2025-10-27T17:39:49.984051Z","price_level":"115566.8","new_quantity":"0.81378091"},{"side":"bid","event_time":"2025-10-27T17:39:49.984051Z","price_level":"115565.5","new_quantity":"1.5"},{"side":"offer","event_time":"2025-10-27T17:39:49.984051Z","price_level":"115640.09","new_quantity":"0.02594256"},{"side":"offer","event_time":"2025-10-27T17:39:49.984051Z","price_level":"115641.43","new_quantity":"0"},{"side":"offer","event_time":"2025-10-27T17:39:49.984051Z","price_level":"115643.38","new_quantity":"0.25941824"},{"side":"offer","event_time":"2025-10-27T17:39:49.984051Z","price_level":"115647.49","new_quantity":"0"},{"side":"offer","event_time":"2025-10-27T17:39:49.984051Z","price_level":"115647.5","new_quantity":"0.00008451"},{"side":"offer","event_time":"2025-10-27T17:39:49.984051Z","price_level":"115647.51","new_quantity":"0.00415751"},{"side":"offer","event_time":"2025-10-27T17:39:49.984051Z","price_level":"115653.91","new_quantity":"0.11368287"},{"side":"offer","event_time":"2025-10-27T17:39:49.984051Z","price_level":"115653.92","new_quantity":"0"},{"side":"offer","event_time":"2025-10-27T17:39:49.984051Z","price_level":"115662","new_quantity":"0"},{"side":"offer","event_time":"2025-10-27T17:39:49.984051Z","price_level":"115666","new_quantity":"0"},{"side":"offer","event_time":"2025-10-27T17:39:49.984051Z","price_level":"115683.66","new_quantity":"0"},{"side":"offer","event_time":"2025-10-27T17:39:49.984051Z","price_level":"115722","new_quantity":"1"},{"side":"offer","event_time":"2025-10-27T17:39:49.984051Z","price_level":"115723.6","new_quantity":"0"},{"side":"offer","event_time":"2025-10-27T17:39:49.984051Z","price_level":"115797.83","new_quantity":"0.045"}]}]}
{"channel":"l2_data","client_id":"","timestamp":"2025-10-27T17:39:50.072405636Z","sequence_num":138031,"events":[{"type":"update","product_id":"ETH-USD","updates":[{"side":"bid","event_time":"2025-10-27T17:39:50.029531Z","price_level":"4217.81","new_quantity":"0"},{"side":"bid","event_time":"2025-10-27T17:39:50.029531Z","price_level":"4217.74","new_quantity":"0.01815979"},{"side":"bid","event_time":"2025-10-27T17:39:50.029531Z","price_level":"4217.71","new_quantity":"5.971194"},{"side":"bid","event_time":"2025-10-27T17:39:50.029531Z","price_level":"4217.7","new_quantity":"10"},{"side":"bid","event_time":"2025-10-27T17:39:50.029531Z","price_level":"4217.62","new_quantity":"0"},{"side":"bid","event_time":"2025-10-27T17:39:50.029531Z","price_level":"4217.61","new_quantity":"0.59275159"},{"side":"bid","event_time":"2025-10-27T17:39:50.029531Z","price_level":"4217.6","new_quantity":"33.790973"},{"side":"bid","event_time":"2025-10-27T17:39:50.029531Z","price_level":"4216.83","new_quantity":"0"},{"side":"offer","event_time":"2025-10-27T17:39:50.029531Z","price_level":"4218.07","new_quantity":"0.34147696"},{"side":"offer","event_time":"2025-10-27T17:39:50.029531Z","price_level":"4218.48","new_quantity":"0"}]}]}
{"channel":"l2_data","client_id":"","timestamp":"2025-10-27T17:39:50.097976536Z","sequence_num":138033,"events":[{"type":"update","product_id":"BTC-USD","updates":[{"side":"bid","event_time":"2025-10-27T17:39:50.035299Z","price_level":"115636","new_quantity":"0.14735083"},{"side":"bid","event_time":"2025-10-27T17:39:50.035299Z","price_level":"115616","new_quantity":"0.4"},{"side":"bid","event_time":"2025-10-27T17:39:50.035299Z","price_level":"115615","new_quantity":"0"},{"side":"bid","event_time":"2025-10-27T17:39:50.035299Z","price_level":"115601.51","new_quantity":"0.0069609"},{"side":"bid","event_time":"2025-10-27T17:39:50.035299Z","price_level":"115599.35","new_quantity":"0"},{"side":"bid","event_time":"2025-10-27T17:39:50.035299Z","price_level":"115596.73","new_quantity":"0.37042036"},{"side":"offer","event_time":"2025-10-27T17:39:50.035299Z","price_level":"115721.99","new_quantity":"0.56830285"},{"side":"offer","event_time":"2025-10-27T17:39:50.035299Z","price_level":"115722","new_quantity":"0"},{"side":"offer","event_time":"2025-10-27T17:39:50.035299Z","price_level":"115725.8","new_quantity":"1"},{"side":"offer","event_time":"2025-10-27T17:39:50.035299Z","price_level":"115735.57","new_quantity":"0"},{"side":"offer","event_time":"2025-10-27T17:39:50.035299Z","price_level":"116961.39","new_quantity":"0.07007"},{"side":"offer","event_time":"2025-10-27T17:39:50.035299Z","price_level":"116961.42","new_quantity":"0"}]}]}
{"channel":"l2_data","client_id":"","timestamp":"2025-10-27T17:39:50.121095126Z","sequence_num":138034,"events":[{"type":"update","product_id":"ETH-USD","updates":[{"side":"bid","event_time":"2025-10-27T17:39:50.075376Z","price_level":"4216.8","new_quantity":"0.21565049"},{"side":"bid","event_time":"2025-10-27T17:39:50.075376Z","price_level":"4216.17","new_quantity":"4.238814"},{"side":"offer","event_time":"2025-10-27T17:39:50.075376Z","price_level":"4218.07","new_quantity":"0.32110764"}]}]}
{"channel":"l2_data","client_id":"","timestamp":"2025-10-27T17:39:50.14656357Z","sequence_num":138036,"events":[{"type":"update","product_id":"BTC-USD","updates":[{"side":"bid","event_time":"2025-10-27T17:39:50.088076Z","price_level":"115636","new_quantity":"0.14904291"},{"side":"bid","event_time":"2025-10-27T17:39:50.088076Z","price_level":"115629.76","new_quantity":"0.0216113"},{"side":"bid","event_time":"2025-10-27T17:39:50.088076Z","price_level":"115622.61","new_quantity":"0.08"},{"side":"bid","event_time":"2025-10-27T17:39:50.088076Z","price_level":"115617.07","new_quantity":"0.52902893"},{"side":"bid","event_time":"2025-10-27T17:39:50.088076Z","price_level":"115617","new_quantity":"0.4"},{"side":"bid","event_time":"2025-10-27T17:39:50.088076Z","price_level":"115616","new_quantity":"0"},{"side":"bid","event_time":"2025-10-27T17:39:50.088076Z","price_level":"115615","new_quantity":"0.4"},{"side":"bid","event_time":"2025-10-27T17:39:50.088076Z","price_level":"115612.01","new_quantity":"0"},{"side":"bid","event_time":"2025-10-27T17:39:50.088076Z","price_level":"115612","new_quantity":"0"},{"side":"bid","event_time":"2025-10-27T17:39:50.088076Z","price_level":"115610.01","new_quantity":"0.34898244"},{"side":"offer","event_time":"2025-10-27T17:39:50.088076Z","price_level":"115662.07","new_quantity":"0.00001729"},{"side":"offer","event_time":"2025-10-27T17:39:50.088076Z","price_level":"115665.99","new_quantity":"0"},{"side":"offer","event_time":"2025-10-27T17:39:50.088076Z","price_level":"116376.07","new_quantity":"0"}]}]}
{"channel":"l2_data","client_id":"","timestamp":"2025-10-27T17:39:50.168938101Z","sequence_num":138037,"events":[{"type":"update","product_id":"ETH-USD","updates":[{"side":"offer","event_time":"2025-10-27T17:39:50.116679Z","price_level":"4218.07","new_quantity":"0.0148337"},{"side":"offer","event_time":"2025-10-27T17:39:50.116679Z","price_level":"4219.21","new_quantity":"0.05926418"}]}]}
{"channel":"l2_data","client_id":"","timestamp":"2025-10-27T17:39:50.19831353Z","sequence_num":138038,"events":[{"type":"update","product_id":"BTC-USD","updates":[{"side":"bid","event_time":"2025-10-27T17:39:50.138978Z","price_level":"115617.07","new_quantity":"1.89419362"},{"side":"bid","event_time":"2025-10-27T17:39:50.138978Z","price_level":"115614","new_quantity":"2"},{"side":"bid","event_time":"2025-10-27T17:39:50.138978Z","price_level":"114895.94","new_quantity":"0.00216163"},{"side":"bid","event_time":"2025-10-27T17:39:50.138978Z","price_level":"114894.76","new_quantity":"0"},{"side":"offer","event_time":"2025-10-27T17:39:50.138978Z","price_level":"115665.99","new_quantity":"0"}]}]}
{"channel":"l2_data","client_id":"","timestamp":"2025-10-27T17:39:50.218894578Z","sequence_num":138039,"events":[{"type":"update","product_id":"ETH-USD","updates":[{"side":"bid","event_time":"2025-10-27T17:39:50.173258Z","price_level":"4217.56","new_quantity":"3.32231"}]}]}
{"channel":"l2_data","client_id":"","timestamp":"2025-10-27T17:39:50.24871959Z","sequence_num":138040,"events":[{"type":"update","product_id":"BTC-USD","updates":[{"side":"bid","event_time":"2025-10-27T17:39:50.195512Z","price_level":"115636","new_quantity":"0.17639139"},{"side":"bid","event_time":"2025-10-27T17:39:50.195512Z","price_level":"115617.07","new_quantity":"0.79876429"},{"side":"bid","event_time":"2025-10-27T17:39:50.195512Z","price_level":"115616.79","new_quantity":"0.16511"},{"side":"bid","event_time":"2025-10-27T17:39:50.195512Z","price_level":"115614","new_quantity":"0"},{"side":"bid","event_time":"2025-10-27T17:39:50.195512Z","price_level":"115601.51","new_quantity":"0"},{"side":"bid","event_time":"2025-10-27T17:39:50.195512Z","price_level":"115599.25","new_quantity":"0.6512488"},{"side":"bid","event_time":"2025-10-27T17:39:50.195512Z","price_level":"115564.57","new_quantity":"1.25073489"},{"side":"offer","event_time":"2025-10-27T17:39:50.195512Z","price_level":"115658.36","new_quantity":"0"},{"side":"offer","event_time":"2025-10-27T17:39:50.195512Z","price_level":"115658.37","new_quantity":"0"},{"side":"offer","event_time":"2025-10-27T17:39:50.195512Z","price_level":"115662","new_quantity":"0"},{"side":"offer","event_time":"2025-10-27T17:39:50.195512Z","price_level":"115665.99","new_quantity":"0"},{"side":"offer","event_time":"2025-10-27T17:39:50.195512Z","price_level":"115666","new_quantity":"0"},{"side":"offer","event_time":"2025-10-27T17:39:50.195512Z","price_level":"115673.29","new_quantity":"0"},{"side":"offer","event_time":"2025-10-27T17:39:50.195512Z","price_level":"115675.75","new_quantity":"0.13836062"},{"side":"offer","event_time":"2025-10-27T17:39:50.195512Z","price_level":"115687.44","new_quantity":"0.02014916"},{"side":"offer","event_time":"2025-10-27T17:39:50.195512Z","price_level":"116531.91","new_quantity":"0.07007"},{"side":"offer","event_time":"2025-10-27T17:39:50.195512Z","price_level":"116532.23","new_quantity":"0"},{"side":"offer","event_time":"2025-10-27T17:39:50.195512Z","price_level":"116532.25","new_quantity":"0"},{"side":"offer","event_time":"2025-10-27T17:39:50.195512Z","price_level":"116746.67","new_quantity":"0.07007"},{"side":"offer","event_time":"2025-10-27T17:39:50.195512Z","price_level":"116746.71","new_quantity":"0.07007"},{"side":"offer","event_time":"2025-10-27T17:39:50.195512Z","price_level":"116746.9","new_quantity":"0"},{"side":"offer","event_time":"2025-10-27T17:39:50.195512Z","price_level":"116746.94","new_quantity":"0"},{"side":"offer","event_time":"2025-10-27T17:39:50.195512Z","price_level":"116961.39","new_quantity":"0"}]}]}
{"channel":"l2_data","client_id":"","timestamp":"2025-10-27T17:39:50.271409717Z","sequence_num":138041,"events":[{"type":"update","product_id":"ETH-USD","updates":[{"side":"bid","event_time":"2025-10-27T17:39:50.223539Z","price_level":"4218.01","new_quantity":"0.01644372"},{"side":"bid","event_time":"2025-10-27T17:39:50.223539Z","price_level":"4217.74","new_quantity":"0"},{"side":"bid","event_time":"2025-10-27T17:39:50.223539Z","price_level":"4217.61","new_quantity":"40.65997854"},{"side":"bid","event_time":"2025-10-27T17:39:50.223539Z","price_level":"4217.34","new_quantity":"0"},{"side":"bid","event_time":"2025-10-27T17:39:50.223539Z","price_level":"4216.17","new_quantity":"0"},{"side":"offer","event_time":"2025-10-27T17:39:50.223539Z","price_level":"4218.1","new_quantity":"0"}]}]}
{"channel":"l2_data","client_id":"","timestamp":"2025-10-27T17:39:50.297691495Z","sequence_num":138042,"events":[{"type":"update","product_id":"BTC-USD","updates":[{"side":"bid","event_time":"2025-10-27T17:39:50.243776Z","price_level":"115617.07","new_quantity":"1.95827916"},{"side":"bid","event_time":"2025-10-27T17:39:50.243776Z","price_level":"115615","new_quantity":"2.4"},{"side":"bid","event_time":"2025-10-27T17:39:50.243776Z","price_level":"115570.51","new_quantity":"0.81375479"},{"side":"bid","event_time":"2025-10-27T17:39:50.243776Z","price_level":"115570.5","new_quantity":"1.5"},{"side":"bid","event_time":"2025-10-27T17:39:50.243776Z","price_level":"115566.8","new_quantity":"0"},{"side":"bid","event_time":"2025-10-27T17:39:50.243776Z","price_level":"115565.5","new_quantity":"0"},{"side":"bid","event_time":"2025-10-27T17:39:50.243776Z","price_level":"101181.5","new_quantity":"0.00049568"},{"side":"offer","event_time":"2025-10-27T17:39:50.243776Z","price_level":"115647.5","new_quantity":"0"},{"side":"offer","event_time":"2025-10-27T17:39:50.243776Z","price_level":"115647.51","new_quantity":"0.00008441"},{"side":"offer","event_time":"2025-10-27T17:39:50.243776Z","price_level":"115665.99","new_quantity":"0"},{"side":"offer","event_time":"2025-10-27T17:39:50.243776Z","price_level":"115721.99","new_quantity":"0"},{"side":"offer","event_time":"2025-10-27T17:39:50.243776Z","price_level":"115725.8","new_quantity":"0"},{"side":"offer","event_time":"2025-10-27T17:39:50.243776Z","price_level":"115726.29","new_quantity":"0.56828174"},{"side":"offer","event_time":"2025-10-27T17:39:50.243776Z","price_level":"115726.3","new_quantity":"1"},{"side":"offer","event_time":"2025-10-27T17:39:50.243776Z","price_level":"116746.71","new_quantity":"0"},{"side":"offer","event_time":"2025-10-27T17:39:50.243776Z","price_level":"116961.63","new_quantity":"0.07007"}]}]}
{"channel":"l2_data","client_id":"","timestamp":"2025-10-27T17:39:50.32106462Z","sequence_num":138043,"events":[{"type":"update","product_id":"ETH-USD","updates":[{"side":"bid","event_time":"2025-10-27T17:39:50.278886Z","price_level":"4218","new_quantity":"2.29267"},{"side":"bid","event_time":"2025-10-27T17:39:50.278886Z","price_level":"4214.2","new_quantity":"13.23906732"},{"side":"bid","event_time":"2025-10-27T17:39:50.278886Z","price_level":"4214.04","new_quantity":"0"},{"side":"offer","event_time":"2025-10-27T17:39:50.278886Z","price_level":"4218.19","new_quantity":"0"},{"side":"offer","event_time":"2025-10-27T17:39:50.278886Z","price_level":"4218.2","new_quantity":"0.00237076"},{"side":"offer","event_time":"2025-10-27T17:39:50.278886Z","price_level":"4218.23","new_quantity":"0"},{"side":"offer","event_time":"2025-10-27T17:39:50.278886Z","price_level":"4218.26","new_quantity":"0"},{"side":"offer","event_time":"2025-10-27T17:39:50.278886Z","price_level":"4218.29","new_quantity":"0"},{"side":"offer","event_time":"2025-10-27T17:39:50.278886Z","price_level":"4218.45","new_quantity":"0"},{"side":"offer","event_time":"2025-10-27T17:39:50.278886Z","price_level":"4218.57","new_quantity":"0"},{"side":"offer","event_time":"2025-10-27T17:39:50.278886Z","price_level":"4218.68","new_quantity":"0.01398581"}]}]}
{"channel":"l2_data","client_id":"","timestamp":"2025-10-27T17:39:50.347289398Z","sequence_num":138045,"events":[{"type":"update","product_id":"BTC-USD","updates":[{"side":"bid","event_time":"2025-10-27T17:39:50.296838Z","price_level":"115636","new_quantity":"0.29586875"},{"side":"bid","event_time":"2025-10-27T17:39:50.296838Z","price_level":"115630.09","new_quantity":"0"},{"side":"bid","event_time":"2025-10-27T17:39:50.296838Z","price_level":"115623.63","new_quantity":"0.00432"},{"side":"bid","event_time":"2025-10-27T17:39:50.296838Z","price_level":"115622.58","new_quantity":"0.20177314"},{"side":"bid","event_time":"2025-10-27T17:39:50.296838Z","price_level":"115621.28","new_quantity":"0"},{"side":"bid","event_time":"2025-10-27T17:39:50.296838Z","price_level":"115619","new_quantity":"0"},{"side":"bid","event_time":"2025-10-27T17:39:50.296838Z","price_level":"115617.07","new_quantity":"0.8663996"},{"side":"bid","event_time":"2025-10-27T17:39:50.296838Z","price_level":"115615","new_quantity":"0.4"},{"side":"bid","event_time":"2025-10-27T17:39:50.296838Z","price_level":"115611.01","new_quantity":"0.93772291"},{"side":"bid","event_time":"2025-10-27T17:39:50.296838Z","price_level":"115601.42","new_quantity":"0.0069609"},{"side":"bid","event_time":"2025-10-27T17:39:50.296838Z","price_level":"115380","new_quantity":"0.00086802"},{"side":"offer","event_time":"2025-10-27T17:39:50.296838Z","price_level":"115640.09","new_quantity":"0"},{"side":"offer","event_time":"2025-10-27T17:39:50.296838Z","price_level":"115647.58","new_quantity":"0"},{"side":"offer","event_time":"2025-10-27T17:39:50.296838Z","price_level":"115660.68","new_quantity":"0"},{"side":"offer","event_time":"2025-10-27T17:39:50.296838Z","price_level":"116987.31","new_quantity":"0.02184214"},{"side":"offer","event_time":"2025-10-27T17:39:50.296838Z","price_level":"117136.64","new_quantity":"0.18235661"},{"side":"offer","event_time":"2025-10-27T17:39:50.296838Z","price_level":"117140.72","new_quantity":"0"}]}]}
{"channel":"l2_data","client_id":"","timestamp":"2025-10-27T17:39:50.370985585Z","sequence_num":138046,"events":[{"type":"update","product_id":"ETH-USD","updates":[{"side":"bid","event_time":"2025-10-27T17:39:50.323984Z","price_level":"4218.06","new_quantity":"1.3704674"},{"side":"bid","event_time":"2025-10-27T17:39:50.323984Z","price_level":"4217.25","new_quantity":"5.92325321"},{"side":"bid","event_time":"2025-10-27T17:39:50.323984Z","price_level":"4217.22","new_quantity":"0.62305959"},{"side":"bid","event_time":"2025-10-27T17:39:50.323984Z","price_level":"4217.07","new_quantity":"0.2677885"},{"side":"bid","event_time":"2025-10-27T17:39:50.323984Z","price_level":"4214.92","new_quantity":"8.13026329"},{"side":"bid","event_time":"2025-10-27T17:39:50.323984Z","price_level":"4214.91","new_quantity":"5.13229668"},{"side":"bid","event_time":"2025-10-27T17:39:50.323984Z","price_level":"4214.78","new_quantity":"0"},{"side":"bid","event_time":"2025-10-27T17:39:50.323984Z","price_level":"4213.87","new_quantity":"19.75163758"},{"side":"bid","event_time":"2025-10-27T17:39:50.323984Z","price_level":"4213.72","new_quantity":"0"},{"side":"offer","event_time":"2025-10-27T17:39:50.323984Z","price_level":"4218.3","new_quantity":"0"},{"side":"offer","event_time":"2025-10-27T17:39:50.323984Z","price_level":"4218.39","new_quantity":"0.341484"},{"side":"offer","event_time":"2025-10-27T17:39:50.323984Z","price_level":"4218.68","new_quantity":"0"},{"side":"offer","event_time":"2025-10-27T17:39:50.323984Z","price_level":"4218.89","new_quantity":"0.0149999"},{"side":"offer","event_time":"2025-10-27T17:39:50.323984Z","price_level":"4219.4","new_quantity":"0"},{"side":"offer","event_time":"2025-10-27T17:39:50.323984Z","price_level":"4220.67","new_quantity":"0.81827936"},{"side":"offer","event_time":"2025-10-27T17:39:50.323984Z","price_level":"4221.1","new_quantity":"0"},{"side":"offer","event_time":"2025-10-27T17:39:50.323984Z","price_level":"4221.49","new_quantity":"13.29985425"},{"side":"offer","event_time":"2025-10-27T17:39:50.323984Z","price_level":"4221.5","new_quantity":"1.94491607"},{"side":"offer","event_time":"2025-10-27T17:39:50.323984Z","price_level":"4221.51","new_quantity":"0"},{"side":"offer","event_time":"2025-10-27T17:39:50.323984Z","price_level":"4222.53","new_quantity":"0"},{"side":"offer","event_time":"2025-10-27T17:39:50.323984Z","price_level":"4222.8","new_quantity":"9.20473974"}]}]}
{"channel":"l2_data","client_id":"","timestamp":"2025-10-27T17:39:50.398665112Z","sequence_num":138048,"events":[{"type":"update","product_id":"BTC-USD","updates":[{"side":"bid","event_time":"2025-10-27T17:39:50.353608Z","price_level":"115627.3","new_quantity":"0.46117064"},{"side":"bid","event_time":"2025-10-27T17:39:50.353608Z","price_level":"115626","new_quantity":"0.4"},{"side":"bid","event_time":"2025-10-27T17:39:50.353608Z","price_level":"115625.95","new_quantity":"0.00432"},{"side":"bid","event_time":"2025-10-27T17:39:50.353608Z","price_level":"115623.63","new_quantity":"0"},{"side":"bid","event_time":"2025-10-27T17:39:50.353608Z","price_level":"115617.07","new_quantity":"1.94963212"},{"side":"bid","event_time":"2025-10-27T17:39:50.353608Z","price_level":"115616","new_quantity":"2"},{"side":"bid","event_time":"2025-10-27T17:39:50.353608Z","price_level":"115603.77","new_quantity":"0.37037596"},{"side":"bid","event_time":"2025-10-27T17:39:50.353608Z","price_level":"115596.73","new_quantity":"0"},{"side":"bid","event_time":"2025-10-27T17:39:50.353608Z","price_level":"115570.5","new_quantity":"0"},{"side":"bid","event_time":"2025-10-27T17:39:50.353608Z","price_level":"115568.6","new_quantity":"1.5"},{"side":"offer","event_time":"2025-10-27T17:39:50.353608Z","price_level":"115665.99","new_quantity":"0"},{"side":"offer","event_time":"2025-10-27T17:39:50.353608Z","price_level":"115666","new_quantity":"0"},{"side":"offer","event_time":"2025-10-27T17:39:50.353608Z","price_level":"115705.49","new_quantity":"0.00043237"},{"side":"offer","event_time":"2025-10-27T17:39:50.353608Z","price_level":"115705.5","new_quantity":"0.25575097"}]}]}
{"channel":"l2_data","client_id":"","timestamp":"2025-10-27T17:39:50.420755661Z","sequence_num":138049,"events":[{"type":"update","product_id":"ETH-USD","updates":[{"side":"bid","event_time":"2025-10-27T17:39:50.376609Z","price_level":"4216.8","new_quantity":"0"},{"side":"offer","event_time":"2025-10-27T17:39:50.376609Z","price_level":"4219.33","new_quantity":"0"},{"side":"offer","event_time":"2025-10-27T17:39:50.376609Z","price_level":"4219.5","new_quantity":"10.001"},{"side":"offer","event_time":"2025-10-27T17:39:50.376609Z","price_level":"4219.96","new_quantity":"0.95585794"},{"side":"offer","event_time":"2025-10-27T17:39:50.376609Z","price_level":"4220","new_quantity":"22.20517286"}]}]}
{"channel":"l2_data","client_id":"","timestamp":"2025-10-27T17:39:50.447930608Z","sequence_num":138051,"events":[{"type":"update","product_id":"BTC-USD","updates":[{"side":"bid","event_time":"2025-10-27T17:39:50.38277Z","price_level":"115628.27","new_quantity":"0.00432"},{"side":"bid","event_time":"2025-10-27T17:39:50.38277Z","price_level":"115625.92","new_quantity":"0.00432"},{"side":"offer","event_time":"2025-10-27T17:39:50.38277Z","price_level":"115663","new_quantity":"2.00432"}]}]}
{"channel":"l2_data","client_id":"","timestamp":"2025-10-27T17:39:50.471380424Z","sequence_num":138052,"events":[{"type":"update","product_id":"ETH-USD","updates":[{"side":"bid","event_time":"2025-10-27T17:39:50.423725Z","price_level":"4217.75","new_quantity":"0.5672135"},{"side":"bid","event_time":"2025-10-27T17:39:50.423725Z","price_level":"4217.59","new_quantity":"0.51985955"},{"side":"bid","event_time":"2025-10-27T17:39:50.423725Z","price_level":"4217.38","new_quantity":"0"},{"side":"bid","event_time":"2025-10-27T17:39:50.423725Z","price_level":"4217.24","new_quantity":"1.62084789"},{"side":"bid","event_time":"2025-10-27T17:39:50.423725Z","price_level":"4216.81","new_quantity":"1.34065049"},{"side":"bid","event_time":"2025-10-27T17:39:50.423725Z","price_level":"4214.26","new_quantity":"13.23887883"},{"side":"bid","event_time":"2025-10-27T17:39:50.423725Z","price_level":"4214.2","new_quantity":"0"},{"side":"offer","event_time":"2025-10-27T17:39:50.423725Z","price_level":"4218.69","new_quantity":"1.1089704"},{"side":"offer","event_time":"2025-10-27T17:39:50.423725Z","price_level":"4218.86","new_quantity":"0.02349922"},{"side":"offer","event_time":"2025-10-27T17:39:50.423725Z","price_level":"4218.87","new_quantity":"0.47409209"},{"side":"offer","event_time":"2025-10-27T17:39:50.423725Z","price_level":"4218.89","new_quantity":"0"},{"side":"offer","event_time":"2025-10-27T17:39:50.423725Z","price_level":"4219.02","new_quantity":"0.49999377"},{"side":"offer","event_time":"2025-10-27T17:39:50.423725Z","price_level":"4221.47","new_quantity":"13.29991726"},{"side":"offer","event_time":"2025-10-27T17:39:50.423725Z","price_level":"4221.48","new_quantity":"1.94391607"},{"side":"offer","event_time":"2025-10-27T17:39:50.423725Z","price_level":"4221.49","new_quantity":"0"},{"side":"offer","event_time":"2025-10-27T17:39:50.423725Z","price_level":"4221.5","new_quantity":"0.001"}]}]}
{"channel":"l2_data","client_id":"","timestamp":"2025-10-27T17:39:50.498254084Z","sequence_num":138053,"events":[{"type":"update","product_id":"BTC-USD","updates":[{"side":"bid","event_time":"2025-10-27T17:39:50.439372Z","price_level":"115627.3","new_quantity":"0.23832201"},{"side":"bid","event_time":"2025-10-27T17:39:50.439372Z","price_level":"115626","new_quantity":"0"},{"side":"bid","event_time":"2025-10-27T17:39:50.439372Z","price_level":"115617.07","new_quantity":"0.8663996"},{"side":"bid","event_time":"2025-10-27T17:39:50.439372Z","price_level":"115616","new_quantity":"0"},{"side":"bid","event_time":"2025-10-27T17:39:50.439372Z","price_level":"115611.02","new_quantity":"0.34897939"},{"side":"bid","event_time":"2025-10-27T17:39:50.439372Z","price_level":"115610.01","new_quantity":"0"},{"side":"bid","event_time":"2025-10-27T17:39:50.439372Z","price_level":"101181.5","new_quantity":"0.0049568"},{"side":"offer","event_time":"2025-10-27T17:39:50.439372Z","price_level":"115643.38","new_quantity":"0"},{"side":"offer","event_time":"2025-10-27T17:39:50.439372Z","price_level":"115644.96","new_quantity":"0.02594146"},{"side":"offer","event_time":"2025-10-27T17:39:50.439372Z","price_level":"115647.49","new_quantity":"0.00008441"},{"side":"offer","event_time":"2025-10-27T17:39:50.439372Z","price_level":"115647.5","new_quantity":"0.00282904"},{"side":"offer","event_time":"2025-10-27T17:39:50.439372Z","price_level":"115647.51","new_quantity":"0"},{"side":"offer","event_time":"2025-10-27T17:39:50.439372Z","price_level":"115653.91","new_quantity":"0.25400708"},{"side":"offer","event_time":"2025-10-27T17:39:50.439372Z","price_level":"115654.08","new_quantity":"0.25939422"},{"side":"offer","event_time":"2025-10-27T17:39:50.439372Z","price_level":"115662","new_quantity":"0"},{"side":"offer","event_time":"2025-10-27T17:39:50.439372Z","price_level":"115663","new_quantity":"2"},{"side":"offer","event_time":"2025-10-27T17:39:50.439372Z","price_level":"115665.32","new_quantity":"0.00432"},{"side":"offer","event_time":"2025-10-27T17:39:50.439372Z","price_level":"115665.99","new_quantity":"0"},{"side":"offer","event_time":"2025-10-27T17:39:50.439372Z","price_level":"115666","new_quantity":"0"},{"side":"offer","event_time":"2025-10-27T17:39:50.439372Z","price_level":"115675.14","new_quantity":"0.08467134"},{"side":"offer","event_time":"2025-10-27T17:39:50.439372Z","price_level":"115689.73","new_quantity":"0"},{"side":"offer","event_time":"2025-10-27T17:39:50.439372Z","price_level":"115694.05","new_quantity":"0.16687655"},{"side":"offer","event_time":"2025-10-27T17:39:50.439372Z","price_level":"115705.5","new_quantity":"0"},{"side":"offer","event_time":"2025-10-27T17:39:50.439372Z","price_level":"115709.99","new_quantity":"0.25574104"},{"side":"offer","event_time":"2025-10-27T17:39:50.439372Z","price_level":"115797.83","new_quantity":"0"},{"side":"offer","event_time":"2025-10-27T17:39:50.439372Z","price_level":"116376.07","new_quantity":"0.045"}]}]}
{"channel":"l2_data","client_id":"","timestamp":"2025-10-27T17:39:50.521239344Z","sequence_num":138054,"events":[{"type":"update","product_id":"ETH-USD","updates":[{"side":"bid","event_time":"2025-10-27T17:39:50.474024Z","price_level":"4218.06","new_quantity":"1.35605036"},{"side":"bid","event_time":"2025-10-27T17:39:50.474024Z","price_level":"4217.25","new_quantity":"0.001"},{"side":"bid","event_time":"2025-10-27T17:39:50.474024Z","price_level":"4217.22","new_quantity":"4.07913873"},{"side":"bid","event_time":"2025-10-27T17:39:50.474024Z","price_level":"4217.07","new_quantity":"6.1902945"},{"side":"bid","event_time":"2025-10-27T17:39:50.474024Z","price_level":"3842.77","new_quantity":"0"},{"side":"offer","event_time":"2025-10-27T17:39:50.474024Z","price_level":"4219.3","new_quantity":"4.562653"},{"side":"offer","event_time":"2025-10-27T17:39:50.474024Z","price_level":"4219.96","new_quantity":"5.12056594"},{"side":"offer","event_time":"2025-10-27T17:39:50.474024Z","price_level":"4221.99","new_quantity":"1.47254017"},{"side":"offer","event_time":"2025-10-27T17:39:50.474024Z","price_level":"4222.74","new_quantity":"9.20487053"},{"side":"offer","event_time":"2025-10-27T17:39:50.474024Z","price_level":"4222.8","new_quantity":"0"}]}]}
{"channel":"l2_data","client_id":"","timestamp":"2025-10-27T17:39:50.548014216Z","sequence_num":138055,"events":[{"type":"update","product_id":"BTC-USD","updates":[{"side":"bid","event_time":"2025-10-27T17:39:50.500078Z","price_level":"115632.01","new_quantity":"0.31832127"},{"side":"bid","event_time":"2025-10-27T17:39:50.500078Z","price_level":"115629","new_quantity":"0.4"},{"side":"bid","event_time":"2025-10-27T17:39:50.500078Z","price_level":"115627.3","new_quantity":"0.23832201"},{"side":"bid","event_time":"2025-10-27T17:39:50.500078Z","price_level":"115626","new_quantity":"0"},{"side":"bid","event_time":"2025-10-27T17:39:50.500078Z","price_level":"115625.95","new_quantity":"0"},{"side":"bid","event_time":"2025-10-27T17:39:50.500078Z","price_level":"115622.58","new_quantity":"0.20177314"},{"side":"bid","event_time":"2025-10-27T17:39:50.500078Z","price_level":"115618","new_quantity":"0"},{"side":"bid","event_time":"2025-10-27T17:39:50.500078Z","price_level":"115574.5","new_quantity":"1.5"},{"side":"bid","event_time":"2025-10-27T17:39:50.500078Z","price_level":"115571.31","new_quantity":"0.81374916"},{"side":"bid","event_time":"2025-10-27T17:39:50.500078Z","price_level":"115571.3","new_quantity":"0"},{"side":"bid","event_time":"2025-10-27T17:39:50.500078Z","price_level":"115570.51","new_quantity":"0"},{"side":"bid","event_time":"2025-10-27T17:39:50.500078Z","price_level":"115568.6","new_quantity":"0"},{"side":"bid","event_time":"2025-10-27T17:39:50.500078Z","price_level":"114317.86","new_quantity":"0.07007"},{"side":"bid","event_time":"2025-10-27T17:39:50.500078Z","price_level":"114317.84","new_quantity":"0"},{"side":"bid","event_time":"2025-10-27T17:39:50.500078Z","price_level":"114103.33","new_quantity":"0"},{"side":"bid","event_time":"2025-10-27T17:39:50.500078Z","price_level":"114103.08","new_quantity":"0.07007"},{"side":"offer","event_time":"2025-10-27T17:39:50.500078Z","price_level":"115647.49","new_quantity":"0"},{"side":"offer","event_time":"2025-10-27T17:39:50.500078Z","price_level":"115647.5","new_quantity":"0.00008441"},{"side":"offer","event_time":"2025-10-27T17:39:50.500078Z","price_level":"115647.51","new_quantity":"0.0034612"},{"side":"offer","event_time":"2025-10-27T17:39:50.500078Z","price_level":"115724.09","new_quantity":"0.56829254"},{"side":"offer","event_time":"2025-10-27T17:39:50.500078Z","price_level":"115724.1","new_quantity":"1"},{"side":"offer","event_time":"2025-10-27T17:39:50.500078Z","price_level":"115726.29","new_quantity":"0"},{"side":"offer","event_time":"2025-10-27T17:39:50.500078Z","price_level":"115726.3","new_quantity":"0"}]}]}
{"channel":"l2_data","client_id":"","timestamp":"2025-10-27T17:39:50.568718618Z","sequence_num":138056,"events":[{"type":"update","product_id":"ETH-USD","updates":[{"side":"offer","event_time":"2025-10-27T17:39:50.523017Z","price_level":"4219.3","new_quantity":"4.068847"},{"side":"offer","event_time":"2025-10-27T17:39:50.523017Z","price_level":"4219.5","new_quantity":"10.001"},{"side":"offer","event_time":"2025-10-27T17:39:50.523017Z","price_level":"4219.96","new_quantity":"0.95585794"},{"side":"offer","event_time":"2025-10-27T17:39:50.523017Z","price_level":"4221.45","new_quantity":"13.29998027"},{"side":"offer","event_time":"2025-10-27T17:39:50.523017Z","price_level":"4221.46","new_quantity":"1.94391607"},{"side":"offer","event_time":"2025-10-27T17:39:50.523017Z","price_level":"4221.47","new_quantity":"0"},{"side":"offer","event_time":"2025-10-27T17:39:50.523017Z","price_level":"4221.48","new_quantity":"0"}]}]}
{"channel":"l2_data","client_id":"","timestamp":"2025-10-27T17:39:50.596937277Z","sequence_num":138057,"events":[{"type":"update","product_id":"BTC-USD","updates":[{"side":"bid","event_time":"2025-10-27T17:39:50.52895Z","price_level":"115627.3","new_quantity":"0.4585916"},{"side":"bid","event_time":"2025-10-27T17:39:50.52895Z","price_level":"115625","new_quantity":"0.4"},{"side":"bid","event_time":"2025-10-27T17:39:50.52895Z","price_level":"115617.07","new_quantity":"1.94963212"},{"side":"bid","event_time":"2025-10-27T17:39:50.52895Z","price_level":"115616","new_quantity":"2"},{"side":"bid","event_time":"2025-10-27T17:39:50.52895Z","price_level":"114103.39","new_quantity":"0.07007"},{"side":"bid","event_time":"2025-10-27T17:39:50.52895Z","price_level":"114103.08","new_quantity":"0"}]}]}
{"channel":"l2_data","client_id":"","timestamp":"2025-10-27T17:39:50.621941296Z","sequence_num":138058,"events":[{"type":"update","product_id":"ETH-USD","updates":[{"side":"bid","event_time":"2025-10-27T17:39:50.581991Z","price_level":"4218.06","new_quantity":"0.24309615"},{"side":"bid","event_time":"2025-10-27T17:39:50.581991Z","price_level":"4218.02","new_quantity":"0.02070633"},{"side":"bid","event_time":"2025-10-27T17:39:50.581991Z","price_level":"4218.01","new_quantity":"2.0235656"},{"side":"bid","event_time":"2025-10-27T17:39:50.581991Z","price_level":"4217.23","new_quantity":"6.5222813"},{"side":"bid","event_time":"2025-10-27T17:39:50.581991Z","price_level":"4217.22","new_quantity":"0.62305959"},{"side":"bid","event_time":"2025-10-27T17:39:50.581991Z","price_level":"4217.07","new_quantity":"0.2677885"},{"side":"offer","event_time":"2025-10-27T17:39:50.581991Z","price_level":"4219.3","new_quantity":"0"},{"side":"offer","event_time":"2025-10-27T17:39:50.581991Z","price_level":"4219.4","new_quantity":"10"}]}]}
{"channel":"l2_data","client_id":"","timestamp":"2025-10-27T17:39:50.649318995Z","sequence_num":138060,"events":[{"type":"update","product_id":"BTC-USD","updates":[{"side":"bid","event_time":"2025-10-27T17:39:50.581481Z","price_level":"115630.91","new_quantity":"0.02161131"},{"side":"bid","event_time":"2025-10-27T17:39:50.581481Z","price_level":"115630.59","new_quantity":"0.00432"},{"side":"bid","event_time":"2025-10-27T17:39:50.581481Z","price_level":"115629.76","new_quantity":"0"},{"side":"bid","event_time":"2025-10-27T17:39:50.581481Z","price_level":"115622.57","new_quantity":"0.16511"},{"side":"bid","event_time":"2025-10-27T17:39:50.581481Z","price_level":"115574.51","new_quantity":"0.81372662"},{"side":"bid","event_time":"2025-10-27T17:39:50.581481Z","price_level":"115571.31","new_quantity":"0"},{"side":"bid","event_time":"2025-10-27T17:39:50.581481Z","price_level":"114532.65","new_quantity":"0.07007"},{"side":"bid","event_time":"2025-10-27T17:39:50.581481Z","price_level":"114532.34","new_quantity":"0"},{"side":"bid","event_time":"2025-10-27T17:39:50.581481Z","price_level":"114317.88","new_quantity":"0.07007"},{"side":"bid","event_time":"2025-10-27T17:39:50.581481Z","price_level":"114317.86","new_quantity":"0"},{"side":"bid","event_time":"2025-10-27T17:39:50.581481Z","price_level":"114103.39","new_quantity":"0"},{"side":"offer","event_time":"2025-10-27T17:39:50.581481Z","price_level":"115647.52","new_quantity":"0"},{"side":"offer","event_time":"2025-10-27T17:39:50.581481Z","price_level":"115689.99","new_quantity":"0.16688241"},{"side":"offer","event_time":"2025-10-27T17:39:50.581481Z","price_level":"115694.05","new_quantity":"0"},{"side":"offer","event_time":"2025-10-27T17:39:50.581481Z","price_level":"115706.38","new_quantity":"0.25574902"},{"side":"offer","event_time":"2025-10-27T17:39:50.581481Z","price_level":"115709.99","new_quantity":"0"}]}]}
{"channel":"l2_data","client_id":"","timestamp":"2025-10-27T17:39:50.668769874Z","sequence_num":138061,"events":[{"type":"update","product_id":"ETH-USD","updates":[{"side":"offer","event_time":"2025-10-27T17:39:50.604464Z","price_level":"4219.4","new_quantity":"0"},{"side":"offer","event_time":"2025-10-27T17:39:50.604464Z","price_level":"4219.5","new_quantity":"0.001"},{"side":"offer","event_time":"2025-10-27T17:39:50.604464Z","price_level":"4221.44","new_quantity":"1.94391607"},{"side":"offer","event_time":"2025-10-27T17:39:50.604464Z","price_level":"4221.46","new_quantity":"0"}]}]}
{"channel":"l2_data","client_id":"","timestamp":"2025-10-27T17:39:50.698274654Z","sequence_num":138062,"events":[{"type":"update","product_id":"BTC-USD","updates":[{"side":"bid","event_time":"2025-10-27T17:39:50.635865Z","price_level":"115630.59","new_quantity":"0"},{"side":"bid","event_time":"2025-10-27T17:39:50.635865Z","price_level":"115380","new_quantity":"0"},{"side":"bid","event_time":"2025-10-27T17:39:50.635865Z","price_level":"114103.24","new_quantity":"0.07007"},{"side":"offer","event_time":"2025-10-27T17:39:50.635865Z","price_level":"115647.5","new_quantity":"0"},{"side":"offer","event_time":"2025-10-27T17:39:50.635865Z","price_level":"115647.51","new_quantity":"0"},{"side":"offer","event_time":"2025-10-27T17:39:50.635865Z","price_level":"115647.52","new_quantity":"0.00008427"},{"side":"offer","event_time":"2025-10-27T17:39:50.635865Z","price_level":"115658.33","new_quantity":"0"},{"side":"offer","event_time":"2025-10-27T17:39:50.635865Z","price_level":"115666.69","new_quantity":"0.011241"},{"side":"offer","event_time":"2025-10-27T17:39:50.635865Z","price_level":"115675.13","new_quantity":"0.03458857"}]}]}
{"channel":"l2_data","client_id":"","timestamp":"2025-10-27T17:39:50.72098211Z","sequence_num":138063,"events":[{"type":"update","product_id":"ETH-USD","updates":[{"side":"bid","event_time":"2025-10-27T17:39:50.641638Z","price_level":"4218.01","new_quantity":"0"},{"side":"offer","event_time":"2025-10-27T17:39:50.641638Z","price_level":"4219.5","new_quantity":"10.001"},{"side":"offer","event_time":"2025-10-27T17:39:50.641638Z","price_level":"4221.43","new_quantity":"13.30004328"},{"side":"offer","event_time":"2025-10-27T17:39:50.641638Z","price_level":"4221.45","new_quantity":"0"}]}]}
{"channel":"l2_data","client_id":"","timestamp":"2025-10-27T17:39:50.747452816Z","sequence_num":138064,"events":[{"type":"update","product_id":"BTC-USD","updates":[{"side":"bid","event_time":"2025-10-27T17:39:50.690136Z","price_level":"115616.79","new_quantity":"0"},{"side":"offer","event_time":"2025-10-27T17:39:50.690136Z","price_level":"115647.5","new_quantity":"0.00008427"},{"side":"offer","event_time":"2025-10-27T17:39:50.690136Z","price_level":"115647.51","new_quantity":"0.00149767"},{"side":"offer","event_time":"2025-10-27T17:39:50.690136Z","price_level":"115647.52","new_quantity":"0"},{"side":"offer","event_time":"2025-10-27T17:39:50.690136Z","price_level":"115662","new_quantity":"0"},{"side":"offer","event_time":"2025-10-27T17:39:50.690136Z","price_level":"115665.31","new_quantity":"0.00928992"},{"side":"offer","event_time":"2025-10-27T17:39:50.690136Z","price_level":"115666","new_quantity":"0"}]}]}
{"channel":"l2_data","client_id":"","timestamp":"2025-10-27T17:39:50.771083749Z","sequence_num":138065,"events":[{"type":"update","product_id":"ETH-USD","updates":[{"side":"bid","event_time":"2025-10-27T17:39:50.730486Z","price_level":"4218.06","new_quantity":"0.24544795"},{"side":"bid","event_time":"2025-10-27T17:39:50.730486Z","price_level":"4217.23","new_quantity":"0.6"},{"side":"bid","event_time":"2025-10-27T17:39:50.730486Z","price_level":"4217.22","new_quantity":"4.07913873"},{"side":"bid","event_time":"2025-10-27T17:39:50.730486Z","price_level":"4217.07","new_quantity":"6.1902945"},{"side":"bid","event_time":"2025-10-27T17:39:50.730486Z","price_level":"4216.81","new_quantity":"1.125"},{"side":"bid","event_time":"2025-10-27T17:39:50.730486Z","price_level":"4215.91","new_quantity":"0.99421868"},{"side":"bid","event_time":"2025-10-27T17:39:50.730486Z","price_level":"4215.83","new_quantity":"0.53935792"},{"side":"bid","event_time":"2025-10-27T17:39:50.730486Z","price_level":"4215.23","new_quantity":"7.3425"},{"side":"offer","event_time":"2025-10-27T17:39:50.730486Z","price_level":"4221.42","new_quantity":"1.94391607"},{"side":"offer","event_time":"2025-10-27T17:39:50.730486Z","price_level":"4221.44","new_quantity":"0"}]}]}
{"channel":"l2_data","client_id":"","timestamp":"2025-10-27T17:39:50.796807811Z","sequence_num":138066,"events":[{"type":"update","product_id":"BTC-USD","updates":[{"side":"bid","event_time":"2025-10-27T17:39:50.743637Z","price_level":"114103.34","new_quantity":"0.07007"},{"side":"bid","event_time":"2025-10-27T17:39:50.743637Z","price_level":"114103.24","new_quantity":"0"},{"side":"bid","event_time":"2025-10-27T17:39:50.743637Z","price_level":"101181.5","new_quantity":"0"},{"side":"offer","event_time":"2025-10-27T17:39:50.743637Z","price_level":"115636.01","new_quantity":"0.00183744"},{"side":"offer","event_time":"2025-10-27T17:39:50.743637Z","price_level":"115647.5","new_quantity":"0"},{"side":"offer","event_time":"2025-10-27T17:39:50.743637Z","price_level":"115647.51","new_quantity":"0.00008427"},{"side":"offer","event_time":"2025-10-27T17:39:50.743637Z","price_level":"115647.52","new_quantity":"0.00177535"},{"side":"offer","event_time":"2025-10-27T17:39:50.743637Z","price_level":"115662","new_quantity":"0"},{"side":"offer","event_time":"2025-10-27T17:39:50.743637Z","price_level":"115665.31","new_quantity":"0.00928992"},{"side":"offer","event_time":"2025-10-27T17:39:50.743637Z","price_level":"115666","new_quantity":"0"}]}]}
{"channel":"l2_data","client_id":"","timestamp":"2025-10-27T17:39:50.820470448Z","sequence_num":138067,"events":[{"type":"update","product_id":"ETH-USD","updates":[{"side":"bid","event_time":"2025-10-27T17:39:50.778623Z","price_level":"4216.86","new_quantity":"0"},{"side":"offer","event_time":"2025-10-27T17:39:50.778623Z","price_level":"4218.3","new_quantity":"0.543"},{"side":"offer","event_time":"2025-10-27T17:39:50.778623Z","price_level":"4218.8","new_quantity":"0.01296997"},{"side":"offer","event_time":"2025-10-27T17:39:50.778623Z","price_level":"4218.86","new_quantity":"0"},{"side":"offer","event_time":"2025-10-27T17:39:50.778623Z","price_level":"4221.41","new_quantity":"13.30010629"},{"side":"offer","event_time":"2025-10-27T17:39:50.778623Z","price_level":"4221.43","new_quantity":"0"}]}]}
{"channel":"l2_data","client_id":"","timestamp":"2025-10-27T17:39:50.847882083Z","sequence_num":138070,"events":[{"type":"update","product_id":"BTC-USD","updates":[{"side":"bid","event_time":"2025-10-27T17:39:50.789261Z","price_level":"115632.01","new_quantity":"0.07756898"},{"side":"bid","event_time":"2025-10-27T17:39:50.789261Z","price_level":"115629","new_quantity":"0"},{"side":"bid","event_time":"2025-10-27T17:39:50.789261Z","price_level":"115599.26","new_quantity":"1.32472916"},{"side":"bid","event_time":"2025-10-27T17:39:50.789261Z","price_level":"115552.55","new_quantity":"1.16521261"},{"side":"bid","event_time":"2025-10-27T17:39:50.789261Z","price_level":"115552.54","new_quantity":"0"},{"side":"bid","event_time":"2025-10-27T17:39:50.789261Z","price_level":"115552.53","new_quantity":"0"},{"side":"bid","event_time":"2025-10-27T17:39:50.789261Z","price_level":"115481.7","new_quantity":"0.02312787"},{"side":"offer","event_time":"2025-10-27T17:39:50.789261Z","price_level":"115662","new_quantity":"0"},{"side":"offer","event_time":"2025-10-27T17:39:50.789261Z","price_level":"115665.31","new_quantity":"0.00928992"},{"side":"offer","event_time":"2025-10-27T17:39:50.789261Z","price_level":"115666","new_quantity":"0"}]}]}
{"channel":"l2_data","client_id":"","timestamp":"2025-10-27T17:39:50.870686874Z","sequence_num":138071,"events":[{"type":"update","product_id":"ETH-USD","updates":[{"side":"bid","event_time":"2025-10-27T17:39:50.822756Z","price_level":"4214.26","new_quantity":"0"},{"side":"bid","event_time":"2025-10-27T17:39:50.822756Z","price_level":"4214.04","new_quantity":"13.23956999"},{"side":"offer","event_time":"2025-10-27T17:39:50.822756Z","price_level":"4218.19","new_quantity":"0.00237076"},{"side":"offer","event_time":"2025-10-27T17:39:50.822756Z","price_level":"4218.2","new_quantity":"0.543"},{"side":"offer","event_time":"2025-10-27T17:39:50.822756Z","price_level":"4219.4","new_quantity":"10"},{"side":"offer","event_time":"2025-10-27T17:39:50.822756Z","price_level":"4219.5","new_quantity":"10.001"}]}]}
{"channel":"l2_data","client_id":"","timestamp":"2025-10-27T17:39:50.897194429Z","sequence_num":138073,"events":[{"type":"update","product_id":"BTC-USD","updates":[{"side":"bid","event_time":"2025-10-27T17:39:50.840905Z","price_level":"115636","new_quantity":"0.30711075"},{"side":"bid","event_time":"2025-10-27T17:39:50.840905Z","price_level":"115627.3","new_quantity":"0.4585916"},{"side":"bid","event_time":"2025-10-27T17:39:50.840905Z","price_level":"115626","new_quantity":"0.4"},{"side":"bid","event_time":"2025-10-27T17:39:50.840905Z","price_level":"115625","new_quantity":"0"},{"side":"bid","event_time":"2025-10-27T17:39:50.840905Z","price_level":"115624.45","new_quantity":"0"},{"side":"bid","event_time":"2025-10-27T17:39:50.840905Z","price_level":"115575.51","new_quantity":"0.81371958"},{"side":"bid","event_time":"2025-10-27T17:39:50.840905Z","price_level":"115575.5","new_quantity":"1.5"},{"side":"bid","event_time":"2025-10-27T17:39:50.840905Z","price_level":"115574.51","new_quantity":"0"},{"side":"bid","event_time":"2025-10-27T17:39:50.840905Z","price_level":"115574.5","new_quantity":"0"},{"side":"offer","event_time":"2025-10-27T17:39:50.840905Z","price_level":"115636.01","new_quantity":"0.00142744"},{"side":"offer","event_time":"2025-10-27T17:39:50.840905Z","price_level":"115665.31","new_quantity":"0.00928992"},{"side":"offer","event_time":"2025-10-27T17:39:50.840905Z","price_level":"115683.66","new_quantity":"0.09287065"},{"side":"offer","event_time":"2025-10-27T17:39:50.840905Z","price_level":"115723.99","new_quantity":"0.56829303"},{"side":"offer","event_time":"2025-10-27T17:39:50.840905Z","price_level":"115724","new_quantity":"1"},{"side":"offer","event_time":"2025-10-27T17:39:50.840905Z","price_level":"115724.09","new_quantity":"0"},{"side":"offer","event_time":"2025-10-27T17:39:50.840905Z","price_level":"115724.1","new_quantity":"0"}]}]}
{"channel":"l2_data","client_id":"","timestamp":"2025-10-27T17:39:50.920519989Z","sequence_num":138074,"events":[{"type":"update","product_id":"ETH-USD","updates":[{"side":"bid","event_time":"2025-10-27T17:39:50.889444Z","price_level":"4218","new_quantity":"1.74967"},{"side":"bid","event_time":"2025-10-27T17:39:50.889444Z","price_level":"4216.79","new_quantity":"0.21565049"},{"side":"offer","event_time":"2025-10-27T17:39:50.889444Z","price_level":"4218.1","new_quantity":"0.543"},{"side":"offer","event_time":"2025-10-27T17:39:50.889444Z","price_level":"4218.68","new_quantity":"0.02110671"},{"side":"offer","event_time":"2025-10-27T17:39:50.889444Z","price_level":"4218.8","new_quantity":"0"},{"side":"offer","event_time":"2025-10-27T17:39:50.889444Z","price_level":"4221.1","new_quantity":"1.94391607"},{"side":"offer","event_time":"2025-10-27T17:39:50.889444Z","price_level":"4221.42","new_quantity":"0"}]}]}
{"channel":"l2_data","client_id":"","timestamp":"2025-10-27T17:39:50.947779447Z","sequence_num":138075,"events":[{"type":"update","product_id":"BTC-USD","updates":[{"side":"bid","event_time":"2025-10-27T17:39:50.911019Z","price_level":"115634.63","new_quantity":"0.00172958"},{"side":"bid","event_time":"2025-10-27T17:39:50.911019Z","price_level":"115634.62","new_quantity":"0.00864792"},{"side":"bid","event_time":"2025-10-27T17:39:50.911019Z","price_level":"115634.01","new_quantity":"0"},{"side":"bid","event_time":"2025-10-27T17:39:50.911019Z","price_level":"115627.3","new_quantity":"0.23832201"},{"side":"bid","event_time":"2025-10-27T17:39:50.911019Z","price_level":"115626","new_quantity":"0"},{"side":"bid","event_time":"2025-10-27T17:39:50.911019Z","price_level":"115622.58","new_quantity":"0.5025423"},{"side":"bid","event_time":"2025-10-27T17:39:50.911019Z","price_level":"115620","new_quantity":"0.4"},{"side":"bid","event_time":"2025-10-27T17:39:50.911019Z","price_level":"115617.07","new_quantity":"0.52902893"},{"side":"bid","event_time":"2025-10-27T17:39:50.911019Z","price_level":"115617","new_quantity":"0"},{"side":"bid","event_time":"2025-10-27T17:39:50.911019Z","price_level":"115616","new_quantity":"0"},{"side":"offer","event_time":"2025-10-27T17:39:50.911019Z","price_level":"115643.05","new_quantity":"0.02594189"},{"side":"offer","event_time":"2025-10-27T17:39:50.911019Z","price_level":"115644.96","new_quantity":"0"},{"side":"offer","event_time":"2025-10-27T17:39:50.911019Z","price_level":"115662","new_quantity":"0"},{"side":"offer","event_time":"2025-10-27T17:39:50.911019Z","price_level":"115665.31","new_quantity":"0.00928992"},{"side":"offer","event_time":"2025-10-27T17:39:50.911019Z","price_level":"115666","new_quantity":"0"},{"side":"offer","event_time":"2025-10-27T17:39:50.911019Z","price_level":"115671.72","new_quantity":"0.03458844"},{"side":"offer","event_time":"2025-10-27T17:39:50.911019Z","price_level":"115675.13","new_quantity":"0"},{"side":"offer","event_time":"2025-10-27T17:39:50.911019Z","price_level":"115689.99","new_quantity":"0"},{"side":"offer","event_time":"2025-10-27T17:39:50.911019Z","price_level":"115694.05","new_quantity":"0.16687655"},{"side":"offer","event_time":"2025-10-27T17:39:50.911019Z","price_level":"115706.38","new_quantity":"0"},{"side":"offer","event_time":"2025-10-27T17:39:50.911019Z","price_level":"115709.99","new_quantity":"0.25574104"}]}]}
{"channel":"l2_data","client_id":"","timestamp":"2025-10-27T17:39:50.968801134Z","sequence_num":138076,"events":[{"type":"update","product_id":"ETH-USD","updates":[{"side":"bid","event_time":"2025-10-27T17:39:50.934328Z","price_level":"4216.79","new_quantity":"0"}]}]}
{"channel":"l2_data","client_id":"","timestamp":"2025-10-27T17:39:50.997133433Z","sequence_num":138077,"events":[{"type":"update","product_id":"BTC-USD","updates":[{"side":"bid","event_time":"2025-10-27T17:39:50.958551Z","price_level":"115628.24","new_quantity":"0"},{"side":"bid","event_time":"2025-10-27T17:39:50.958551Z","price_level":"115623.01","new_quantity":"0.57609859"},{"side":"bid","event_time":"2025-10-27T17:39:50.958551Z","price_level":"115623","new_quantity":"0.4"},{"side":"bid","event_time":"2025-10-27T17:39:50.958551Z","price_level":"115622.58","new_quantity":"0"},{"side":"bid","event_time":"2025-10-27T17:39:50.958551Z","price_level":"115620","new_quantity":"0"},{"side":"bid","event_time":"2025-10-27T17:39:50.958551Z","price_level":"115617.07","new_quantity":"1.65539362"},{"side":"bid","event_time":"2025-10-27T17:39:50.958551Z","price_level":"115615","new_quantity":"2.4"},{"side":"bid","event_time":"2025-10-27T17:39:50.958551Z","price_level":"115601.42","new_quantity":"0"},{"side":"bid","event_time":"2025-10-27T17:39:50.958551Z","price_level":"115599.26","new_quantity":"0"},{"side":"bid","event_time":"2025-10-27T17:39:50.958551Z","price_level":"115599.25","new_quantity":"0"},{"side":"bid","event_time":"2025-10-27T17:39:50.958551Z","price_level":"115564.57","new_quantity":"0"},{"side":"offer","event_time":"2025-10-27T17:39:50.958551Z","price_level":"115665.31","new_quantity":"0.00928992"},{"side":"offer","event_time":"2025-10-27T17:39:50.958551Z","price_level":"115665.33","new_quantity":"0.00432"},{"side":"offer","event_time":"2025-10-27T17:39:50.958551Z","price_level":"115670.26","new_quantity":"0.0069609"},{"side":"offer","event_time":"2025-10-27T17:39:50.958551Z","price_level":"115675.12","new_quantity":"0.13835547"},{"side":"offer","event_time":"2025-10-27T17:39:50.958551Z","price_level":"115675.75","new_quantity":"0"},{"side":"offer","event_time":"2025-10-27T17:39:50.958551Z","price_level":"115687.44","new_quantity":"0"}]}]}
{"channel":"l2_data","client_id":"","timestamp":"2025-10-27T17:39:51.021289919Z","sequence_num":138078,"events":[{"type":"update","product_id":"ETH-USD","updates":[{"side":"bid","event_time":"2025-10-27T17:39:50.980594Z","price_level":"4218.06","new_quantity":"0.07344795"},{"side":"bid","event_time":"2025-10-27T17:39:50.980594Z","price_level":"4215.01","new_quantity":"8.29433929"},{"side":"bid","event_time":"2025-10-27T17:39:50.980594Z","price_level":"4213.69","new_quantity":"0.71209565"},{"side":"bid","event_time":"2025-10-27T17:39:50.980594Z","price_level":"4212.01","new_quantity":"1.79226656"},{"side":"bid","event_time":"2025-10-27T17:39:50.980594Z","price_level":"4210","new_quantity":"50.10457551"},{"side":"offer","event_time":"2025-10-27T17:39:50.980594Z","price_level":"4218.1","new_quantity":"0"},{"side":"offer","event_time":"2025-10-27T17:39:50.980594Z","price_level":"4219.39","new_quantity":"3.69053856"},{"side":"offer","event_time":"2025-10-27T17:39:50.980594Z","price_level":"4221.32","new_quantity":"0.10628207"}]}]}
{"channel":"l2_data","client_id":"","timestamp":"2025-10-27T17:39:51.047842272Z","sequence_num":138079,"events":[{"type":"update","product_id":"BTC-USD","updates":[{"side":"bid","event_time":"2025-10-27T17:39:51.004661Z","price_level":"115618","new_quantity":"0.4"},{"side":"offer","event_time":"2025-10-27T17:39:51.004661Z","price_level":"115636.01","new_quantity":"0.00134184"},{"side":"offer","event_time":"2025-10-27T17:39:51.004661Z","price_level":"115665.31","new_quantity":"0.00928992"},{"side":"offer","event_time":"2025-10-27T17:39:51.004661Z","price_level":"115670.26","new_quantity":"0"},{"side":"offer","event_time":"2025-10-27T17:39:51.004661Z","price_level":"115689.73","new_quantity":"0.16688278"},{"side":"offer","event_time":"2025-10-27T17:39:51.004661Z","price_level":"115694.05","new_quantity":"0"}]}]}
{"channel":"l2_data","client_id":"","timestamp":"2025-10-27T17:39:51.069065728Z","sequence_num":138080,"events":[{"type":"update","product_id":"ETH-USD","updates":[{"side":"offer","event_time":"2025-10-27T17:39:51.026439Z","price_level":"4218.39","new_quantity":"0"},{"side":"offer","event_time":"2025-10-27T17:39:51.026439Z","price_level":"4218.48","new_quantity":"0.01707481"},{"side":"offer","event_time":"2025-10-27T17:39:51.026439Z","price_level":"4218.68","new_quantity":"0"}]}]}
{"channel":"l2_data","client_id":"","timestamp":"2025-10-27T17:39:51.097914734Z","sequence_num":138082,"events":[{"type":"update","product_id":"BTC-USD","updates":[{"side":"bid","event_time":"2025-10-27T17:39:51.060395Z","price_level":"115619","new_quantity":"0.4"},{"side":"bid","event_time":"2025-10-27T17:39:51.060395Z","price_level":"115618","new_quantity":"0"},{"side":"bid","event_time":"2025-10-27T17:39:51.060395Z","price_level":"115617.07","new_quantity":"0.52902893"},{"side":"bid","event_time":"2025-10-27T17:39:51.060395Z","price_level":"115615","new_quantity":"0.4"},{"side":"bid","event_time":"2025-10-27T17:39:51.060395Z","price_level":"115575.71","new_quantity":"0.81371818"},{"side":"bid","event_time":"2025-10-27T17:39:51.060395Z","price_level":"115575.7","new_quantity":"1.5"},{"side":"bid","event_time":"2025-10-27T17:39:51.060395Z","price_level":"115575.51","new_quantity":"0"},{"side":"bid","event_time":"2025-10-27T17:39:51.060395Z","price_level":"115575.5","new_quantity":"0"},{"side":"bid","event_time":"2025-10-27T17:39:51.060395Z","price_level":"114533.03","new_quantity":"0.07007"},{"side":"bid","event_time":"2025-10-27T17:39:51.060395Z","price_level":"114532.65","new_quantity":"0"},{"side":"bid","event_time":"2025-10-27T17:39:51.060395Z","price_level":"114318.21","new_quantity":"0.07007"},{"side":"bid","event_time":"2025-10-27T17:39:51.060395Z","price_level":"114317.88","new_quantity":"0"},{"side":"bid","event_time":"2025-10-27T17:39:51.060395Z","price_level":"114103.61","new_quantity":"0.07007"},{"side":"bid","event_time":"2025-10-27T17:39:51.060395Z","price_level":"114103.44","new_quantity":"0"},{"side":"bid","event_time":"2025-10-27T17:39:51.060395Z","price_level":"114103.4","new_quantity":"0"},{"side":"bid","event_time":"2025-10-27T17:39:51.060395Z","price_level":"114103.34","new_quantity":"0"},{"side":"offer","event_time":"2025-10-27T17:39:51.060395Z","price_level":"115643.05","new_quantity":"0"},{"side":"offer","event_time":"2025-10-27T17:39:51.060395Z","price_level":"115644.39","new_quantity":"0.02594159"},{"side":"offer","event_time":"2025-10-27T17:39:51.060395Z","price_level":"115665.31","new_quantity":"0"},{"side":"offer","event_time":"2025-10-27T17:39:51.060395Z","price_level":"115671.72","new_quantity":"0"},{"side":"offer","event_time":"2025-10-27T17:39:51.060395Z","price_level":"115675.13","new_quantity":"0.03458862"},{"side":"offer","event_time":"2025-10-27T17:39:51.060395Z","price_level":"115705.5","new_quantity":"0.25575097"},{"side":"offer","event_time":"2025-10-27T17:39:51.060395Z","price_level":"115709.99","new_quantity":"0"},{"side":"offer","event_time":"2025-10-27T17:39:51.060395Z","price_level":"115716.35","new_quantity":"0.00928992"},{"side":"offer","event_time":"2025-10-27T17:39:51.060395Z","price_level":"115724","new_quantity":"0"},{"side":"offer","event_time":"2025-10-27T17:39:51.060395Z","price_level":"115724.1","new_quantity":"1"}]}]}
{"channel":"l2_data","client_id":"","timestamp":"2025-10-27T17:39:51.124959033Z","sequence_num":138083,"events":[{"type":"update","product_id":"ETH-USD","updates":[{"side":"bid","event_time":"2025-10-27T17:39:51.083404Z","price_level":"4218.06","new_quantity":"0.41184615"},{"side":"bid","event_time":"2025-10-27T17:39:51.083404Z","price_level":"4218.01","new_quantity":"1.6993946"},{"side":"bid","event_time":"2025-10-27T17:39:51.083404Z","price_level":"4218","new_quantity":"2.29267"},{"side":"bid","event_time":"2025-10-27T17:39:51.083404Z","price_level":"4217.76","new_quantity":"0"},{"side":"bid","event_time":"2025-10-27T17:39:51.083404Z","price_level":"4217.59","new_quantity":"0"},{"side":"bid","event_time":"2025-10-27T17:39:51.083404Z","price_level":"4217.23","new_quantity":"6.5222813"},{"side":"bid","event_time":"2025-10-27T17:39:51.083404Z","price_level":"4217.22","new_quantity":"0.62305959"},{"side":"bid","event_time":"2025-10-27T17:39:51.083404Z","price_level":"4217.17","new_quantity":"0.21565049"},{"side":"bid","event_time":"2025-10-27T17:39:51.083404Z","price_level":"4217.07","new_quantity":"0.2677885"},{"side":"bid","event_time":"2025-10-27T17:39:51.083404Z","price_level":"4216.36","new_quantity":"1.49939179"},{"side":"bid","event_time":"2025-10-27T17:39:51.083404Z","price_level":"4216.24","new_quantity":"0"},{"side":"bid","event_time":"2025-10-27T17:39:51.083404Z","price_level":"4215.9","new_quantity":"0"},{"side":"bid","event_time":"2025-10-27T17:39:51.083404Z","price_level":"4215.74","new_quantity":"3.27171131"},{"side":"bid","event_time":"2025-10-27T17:39:51.083404Z","price_level":"4215.62","new_quantity":"0"},{"side":"bid","event_time":"2025-10-27T17:39:51.083404Z","price_level":"4215.02","new_quantity":"8.1300704"},{"side":"bid","event_time":"2025-10-27T17:39:51.083404Z","price_level":"4215.01","new_quantity":"3.9449227"},{"side":"bid","event_time":"2025-10-27T17:39:51.083404Z","price_level":"4214.92","new_quantity":"0"},{"side":"bid","event_time":"2025-10-27T17:39:51.083404Z","price_level":"4214.2","new_quantity":"13.23906732"},{"side":"bid","event_time":"2025-10-27T17:39:51.083404Z","price_level":"4214.12","new_quantity":"0.47459493"},{"side":"bid","event_time":"2025-10-27T17:39:51.083404Z","price_level":"4214.04","new_quantity":"0"},{"side":"bid","event_time":"2025-10-27T17:39:51.083404Z","price_level":"4213.97","new_quantity":"19.75116886"},{"side":"bid","event_time":"2025-10-27T17:39:51.083404Z","price_level":"4213.87","new_quantity":"0"},{"side":"bid","event_time":"2025-10-27T17:39:51.083404Z","price_level":"4213.69","new_quantity":"0"},{"side":"bid","event_time":"2025-10-27T17:39:51.083404Z","price_level":"4213.68","new_quantity":"0"},{"side":"bid","event_time":"2025-10-27T17:39:51.083404Z","price_level":"4211.38","new_quantity":"0.83108149"},{"side":"bid","event_time":"2025-10-27T17:39:51.083404Z","price_level":"4210.94","new_quantity":"0"},{"side":"offer","event_time":"2025-10-27T17:39:51.083404Z","price_level":"4218.19","new_quantity":"0"},{"side":"offer","event_time":"2025-10-27T17:39:51.083404Z","price_level":"4218.2","new_quantity":"0.00237076"},{"side":"offer","event_time":"2025-10-27T17:39:51.083404Z","price_level":"4218.3","new_quantity":"0"},{"side":"offer","event_time":"2025-10-27T17:39:51.083404Z","price_level":"4218.4","new_quantity":"0"},{"side":"offer","event_time":"2025-10-27T17:39:51.083404Z","price_level":"4218.48","new_quantity":"0"},{"side":"offer","event_time":"2025-10-27T17:39:51.083404Z","price_level":"4218.49","new_quantity":"0"},{"side":"offer","event_time":"2025-10-27T17:39:51.083404Z","price_level":"4218.54","new_quantity":"0"},{"side":"offer","event_time":"2025-10-27T17:39:51.083404Z","price_level":"4218.68","new_quantity":"0"},{"side":"offer","event_time":"2025-10-27T17:39:51.083404Z","price_level":"4218.86","new_quantity":"0.01470383"},{"side":"offer","event_time":"2025-10-27T17:39:51.083404Z","price_level":"4218.9","new_quantity":"1.79956128"},{"side":"offer","event_time":"2025-10-27T17:39:51.083404Z","price_level":"4218.98","new_quantity":"0"},{"side":"offer","event_time":"2025-10-27T17:39:51.083404Z","price_level":"4219.09","new_quantity":"0"},{"side":"offer","event_time":"2025-10-27T17:39:51.083404Z","price_level":"4219.11","new_quantity":"1.29660303"},{"side":"offer","event_time":"2025-10-27T17:39:51.083404Z","price_level":"4219.15","new_quantity":"1.64931"},{"side":"offer","event_time":"2025-10-27T17:39:51.083404Z","price_level":"4219.31","new_quantity":"0"},{"side":"offer","event_time":"2025-10-27T17:39:51.083404Z","price_level":"4219.39","new_quantity":"0"},{"side":"offer","event_time":"2025-10-27T17:39:51.083404Z","price_level":"4219.4","new_quantity":"0"},{"side":"offer","event_time":"2025-10-27T17:39:51.083404Z","price_level":"4219.5","new_quantity":"0.001"},{"side":"offer","event_time":"2025-10-27T17:39:51.083404Z","price_level":"4219.8","new_quantity":"0"},{"side":"offer","event_time":"2025-10-27T17:39:51.083404Z","price_level":"4219.9","new_quantity":"10"},{"side":"offer","event_time":"2025-10-27T17:39:51.083404Z","price_level":"4219.96","new_quantity":"5.34656494"},{"side":"offer","event_time":"2025-10-27T17:39:51.083404Z","price_level":"4221.1","new_quantity":"0"},{"side":"offer","event_time":"2025-10-27T17:39:51.083404Z","price_level":"4221.39","new_quantity":"13.3001693"},{"side":"offer","event_time":"2025-10-27T17:39:51.083404Z","price_level":"4221.4","new_quantity":"1.94391607"},{"side":"offer","event_time":"2025-10-27T17:39:51.083404Z","price_level":"4221.41","new_quantity":"0"},{"side":"offer","event_time":"2025-10-27T17:39:51.083404Z","price_level":"4221.62","new_quantity":"0"},{"side":"offer","event_time":"2025-10-27T17:39:51.083404Z","price_level":"4221.82","new_quantity":"4.02476687"}]}]}
{"channel":"l2_data","client_id":"","timestamp":"2025-10-27T17:39:51.147520982Z","sequence_num":138085,"events":[{"type":"update","product_id":"BTC-USD","updates":[{"side":"bid","event_time":"2025-10-27T17:39:51.08537Z","price_level":"115632.01","new_quantity":"0.31832128"},{"side":"bid","event_time":"2025-10-27T17:39:51.08537Z","price_level":"115630.91","new_quantity":"0"},{"side":"bid","event_time":"2025-10-27T17:39:51.08537Z","price_level":"115629.17","new_quantity":"0.0216111"},{"side":"bid","event_time":"2025-10-27T17:39:51.08537Z","price_level":"115629","new_quantity":"0.4"},{"side":"bid","event_time":"2025-10-27T17:39:51.08537Z","price_level":"115617.07","new_quantity":"1.65539362"},{"side":"bid","event_time":"2025-10-27T17:39:51.08537Z","price_level":"115616","new_quantity":"2"},{"side":"offer","event_time":"2025-10-27T17:39:51.08537Z","price_level":"115671.72","new_quantity":"0.03458852"},{"side":"offer","event_time":"2025-10-27T17:39:51.08537Z","price_level":"115675.13","new_quantity":"0"}]}]}
{"channel":"l2_data","client_id":"","timestamp":"2025-10-27T17:39:51.170692683Z","sequence_num":138086,"events":[{"type":"update","product_id":"ETH-USD","updates":[{"side":"bid","event_time":"2025-10-27T17:39:51.138891Z","price_level":"4218.06","new_quantity":"0.07344795"},{"side":"bid","event_time":"2025-10-27T17:39:51.138891Z","price_level":"4218.02","new_quantity":"0"},{"side":"bid","event_time":"2025-10-27T17:39:51.138891Z","price_level":"4218.01","new_quantity":"0.02059569"},{"side":"bid","event_time":"2025-10-27T17:39:51.138891Z","price_level":"4218","new_quantity":"1.74967"},{"side":"bid","event_time":"2025-10-27T17:39:51.138891Z","price_level":"4217.56","new_quantity":"1.66121"},{"side":"bid","event_time":"2025-10-27T17:39:51.138891Z","price_level":"4217.17","new_quantity":"0"},{"side":"offer","event_time":"2025-10-27T17:39:51.138891Z","price_level":"4218.07","new_quantity":"0.1848337"},{"side":"offer","event_time":"2025-10-27T17:39:51.138891Z","price_level":"4218.1","new_quantity":"0.543"},{"side":"offer","event_time":"2025-10-27T17:39:51.138891Z","price_level":"4218.19","new_quantity":"0.00237076"},{"side":"offer","event_time":"2025-10-27T17:39:51.138891Z","price_level":"4218.2","new_quantity":"0.543"},{"side":"offer","event_time":"2025-10-27T17:39:51.138891Z","price_level":"4218.3","new_quantity":"0.543"},{"side":"offer","event_time":"2025-10-27T17:39:51.138891Z","price_level":"4218.49","new_quantity":"1.19204398"},{"side":"offer","event_time":"2025-10-27T17:39:51.138891Z","price_level":"4219.96","new_quantity":"0.95585794"},{"side":"offer","event_time":"2025-10-27T17:39:51.138891Z","price_level":"4220","new_quantity":"42.20517286"}]}]}
{"channel":"l2_data","client_id":"","timestamp":"2025-10-27T17:39:51.198248397Z","sequence_num":138088,"events":[{"type":"update","product_id":"BTC-USD","updates":[{"side":"bid","event_time":"2025-10-27T17:39:51.140159Z","price_level":"115636","new_quantity":"0.29586875"},{"side":"bid","event_time":"2025-10-27T17:39:51.140159Z","price_level":"115634.63","new_quantity":"0"},{"side":"bid","event_time":"2025-10-27T17:39:51.140159Z","price_level":"115634.62","new_quantity":"0"},{"side":"bid","event_time":"2025-10-27T17:39:51.140159Z","price_level":"115634.02","new_quantity":"0"},{"side":"bid","event_time":"2025-10-27T17:39:51.140159Z","price_level":"115634.01","new_quantity":"0.00172959"},{"side":"bid","event_time":"2025-10-27T17:39:51.140159Z","price_level":"115634","new_quantity":"0.0213"},{"side":"bid","event_time":"2025-10-27T17:39:51.140159Z","price_level":"115632.01","new_quantity":"0.07756898"},{"side":"bid","event_time":"2025-10-27T17:39:51.140159Z","price_level":"115631.51","new_quantity":"0.00864816"},{"side":"bid","event_time":"2025-10-27T17:39:51.140159Z","price_level":"115630.22","new_quantity":"0"},{"side":"bid","event_time":"2025-10-27T17:39:51.140159Z","price_level":"115629.17","new_quantity":"0"},{"side":"bid","event_time":"2025-10-27T17:39:51.140159Z","price_level":"115629","new_quantity":"0"},{"side":"bid","event_time":"2025-10-27T17:39:51.140159Z","price_level":"115628.27","new_quantity":"0"},{"side":"bid","event_time":"2025-10-27T17:39:51.140159Z","price_level":"115626.18","new_quantity":"0.011241"},{"side":"bid","event_time":"2025-10-27T17:39:51.140159Z","price_level":"115625.92","new_quantity":"0"},{"side":"bid","event_time":"2025-10-27T17:39:51.140159Z","price_level":"115623.01","new_quantity":"0.40588792"},{"side":"bid","event_time":"2025-10-27T17:39:51.140159Z","price_level":"115622.61","new_quantity":"0"},{"side":"bid","event_time":"2025-10-27T17:39:51.140159Z","price_level":"115622.57","new_quantity":"0"},{"side":"bid","event_time":"2025-10-27T17:39:51.140159Z","price_level":"115621.11","new_quantity":"0"},{"side":"bid","event_time":"2025-10-27T17:39:51.140159Z","price_level":"115619","new_quantity":"0"},{"side":"bid","event_time":"2025-10-27T17:39:51.140159Z","price_level":"115617.07","new_quantity":"1.75391653"},{"side":"bid","event_time":"2025-10-27T17:39:51.140159Z","price_level":"115616.79","new_quantity":"0.16503"},{"side":"bid","event_time":"2025-10-27T17:39:51.140159Z","price_level":"115616","new_quantity":"0"},{"side":"bid","event_time":"2025-10-27T17:39:51.140159Z","price_level":"115615","new_quantity":"2.4"},{"side":"bid","event_time":"2025-10-27T17:39:51.140159Z","price_level":"115601.68","new_quantity":"0.0069609"},{"side":"bid","event_time":"2025-10-27T17:39:51.140159Z","price_level":"115575.7","new_quantity":"0"},{"side":"bid","event_time":"2025-10-27T17:39:51.140159Z","price_level":"115570.5","new_quantity":"1.5"},{"side":"offer","event_time":"2025-10-27T17:39:51.140159Z","price_level":"115642.7","new_quantity":"0.02594197"},{"side":"offer","event_time":"2025-10-27T17:39:51.140159Z","price_level":"115644.39","new_quantity":"0"},{"side":"offer","event_time":"2025-10-27T17:39:51.140159Z","price_level":"115647.58","new_quantity":"0.1425"},{"side":"offer","event_time":"2025-10-27T17:39:51.140159Z","price_level":"115658.36","new_quantity":"0.00432"},{"side":"offer","event_time":"2025-10-27T17:39:51.140159Z","price_level":"115663","new_quantity":"2"},{"side":"offer","event_time":"2025-10-27T17:39:51.140159Z","price_level":"115665.32","new_quantity":"0"},{"side":"offer","event_time":"2025-10-27T17:39:51.140159Z","price_level":"115665.33","new_quantity":"0"},{"side":"offer","event_time":"2025-10-27T17:39:51.140159Z","price_level":"115673.29","new_quantity":"0.13835495"},{"side":"offer","event_time":"2025-10-27T17:39:51.140159Z","price_level":"115675.12","new_quantity":"0"},{"side":"offer","event_time":"2025-10-27T17:39:51.140159Z","price_level":"115689.73","new_quantity":"0"},{"side":"offer","event_time":"2025-10-27T17:39:51.140159Z","price_level":"115694.04","new_quantity":"0.01007052"},{"side":"offer","event_time":"2025-10-27T17:39:51.140159Z","price_level":"115694.05","new_quantity":"0.16687655"},{"side":"offer","event_time":"2025-10-27T17:39:51.140159Z","price_level":"115705.5","new_quantity":"0"},{"side":"offer","event_time":"2025-10-27T17:39:51.140159Z","price_level":"115707.9","new_quantity":"0.00974353"},{"side":"offer","event_time":"2025-10-27T17:39:51.140159Z","price_level":"115709.99","new_quantity":"0.25574104"},{"side":"offer","event_time":"2025-10-27T17:39:51.140159Z","price_level":"115723.5","new_quantity":"1"},{"side":"offer","event_time":"2025-10-27T17:39:51.140159Z","price_level":"115724.1","new_quantity":"0"}]}]}
{"channel":"l2_data","client_id":"","timestamp":"2025-10-27T17:39:51.221317684Z","sequence_num":138089,"events":[{"type":"update","product_id":"ETH-USD","updates":[{"side":"bid","event_time":"2025-10-27T17:39:51.177484Z","price_level":"4217.57","new_quantity":"0.11855151"},{"side":"bid","event_time":"2025-10-27T17:39:51.177484Z","price_level":"4217.34","new_quantity":"1.66208"},{"side":"bid","event_time":"2025-10-27T17:39:51.177484Z","price_level":"4217.3","new_quantity":"0"},{"side":"bid","event_time":"2025-10-27T17:39:51.177484Z","price_level":"4217.23","new_quantity":"0.6"},{"side":"bid","event_time":"2025-10-27T17:39:51.177484Z","price_level":"4217.22","new_quantity":"4.07913873"},{"side":"bid","event_time":"2025-10-27T17:39:51.177484Z","price_level":"4217.07","new_quantity":"6.1902945"},{"side":"bid","event_time":"2025-10-27T17:39:51.177484Z","price_level":"4216.98","new_quantity":"0.146982"},{"side":"bid","event_time":"2025-10-27T17:39:51.177484Z","price_level":"4216.49","new_quantity":"0.2388"},{"side":"bid","event_time":"2025-10-27T17:39:51.177484Z","price_level":"4216.48","new_quantity":"1.4"},{"side":"bid","event_time":"2025-10-27T17:39:51.177484Z","price_level":"4215.02","new_quantity":"0"},{"side":"bid","event_time":"2025-10-27T17:39:51.177484Z","price_level":"4214.78","new_quantity":"8.13053335"},{"side":"bid","event_time":"2025-10-27T17:39:51.177484Z","price_level":"4213.97","new_quantity":"0"},{"side":"bid","event_time":"2025-10-27T17:39:51.177484Z","price_level":"4213.66","new_quantity":"19.75262196"},{"side":"offer","event_time":"2025-10-27T17:39:51.177484Z","price_level":"4218.07","new_quantity":"0.47213132"},{"side":"offer","event_time":"2025-10-27T17:39:51.177484Z","price_level":"4218.19","new_quantity":"0.07349131"},{"side":"offer","event_time":"2025-10-27T17:39:51.177484Z","price_level":"4218.21","new_quantity":"0"},{"side":"offer","event_time":"2025-10-27T17:39:51.177484Z","price_level":"4218.9","new_quantity":"2.62048211"},{"side":"offer","event_time":"2025-10-27T17:39:51.177484Z","price_level":"4219","new_quantity":"2.16931"},{"side":"offer","event_time":"2025-10-27T17:39:51.177484Z","price_level":"4219.33","new_quantity":"1.4"},{"side":"offer","event_time":"2025-10-27T17:39:51.177484Z","price_level":"4219.35","new_quantity":"0.6"},{"side":"offer","event_time":"2025-10-27T17:39:51.177484Z","price_level":"4219.78","new_quantity":"0"},{"side":"offer","event_time":"2025-10-27T17:39:51.177484Z","price_level":"4219.8","new_quantity":"0"},{"side":"offer","event_time":"2025-10-27T17:39:51.177484Z","price_level":"4220","new_quantity":"22.20517286"},{"side":"offer","event_time":"2025-10-27T17:39:51.177484Z","price_level":"4221.1","new_quantity":"1.94391607"},{"side":"offer","event_time":"2025-10-27T17:39:51.177484Z","price_level":"4221.4","new_quantity":"0"}]}]}
{"channel":"l2_data","client_id":"","timestamp":"2025-10-27T17:39:51.256199746Z","sequence_num":138090,"events":[{"type":"update","product_id":"BTC-USD","updates":[{"side":"bid","event_time":"2025-10-27T17:39:51.197785Z","price_level":"115636","new_quantity":"0.20121875"},{"side":"bid","event_time":"2025-10-27T17:39:51.197785Z","price_level":"115629.16","new_quantity":"0.02161141"},{"side":"bid","event_time":"2025-10-27T17:39:51.197785Z","price_level":"115623.01","new_quantity":"0.59279595"},{"side":"bid","event_time":"2025-10-27T17:39:51.197785Z","price_level":"115618","new_quantity":"0.4"},{"side":"bid","event_time":"2025-10-27T17:39:51.197785Z","price_level":"115611.02","new_quantity":"0"},{"side":"bid","event_time":"2025-10-27T17:39:51.197785Z","price_level":"115609.08","new_quantity":"0.34898525"},{"side":"bid","event_time":"2025-10-27T17:39:51.197785Z","price_level":"115603.77","new_quantity":"0"},{"side":"bid","event_time":"2025-10-27T17:39:51.197785Z","price_level":"115601.68","new_quantity":"0"},{"side":"bid","event_time":"2025-10-27T17:39:51.197785Z","price_level":"115596.73","new_quantity":"0.37042475"},{"side":"bid","event_time":"2025-10-27T17:39:51.197785Z","price_level":"115596.72","new_quantity":"0"},{"side":"bid","event_time":"2025-10-27T17:39:51.197785Z","price_level":"115590.78","new_quantity":"0.53834478"},{"side":"bid","event_time":"2025-10-27T17:39:51.197785Z","price_level":"115575.71","new_quantity":"0"},{"side":"bid","event_time":"2025-10-27T17:39:51.197785Z","price_level":"115570.51","new_quantity":"0.81375479"},{"side":"offer","event_time":"2025-10-27T17:39:51.197785Z","price_level":"115641.31","new_quantity":"0.02594228"},{"side":"offer","event_time":"2025-10-27T17:39:51.197785Z","price_level":"115642.7","new_quantity":"0"},{"side":"offer","event_time":"2025-10-27T17:39:51.197785Z","price_level":"115662","new_quantity":"0"},{"side":"offer","event_time":"2025-10-27T17:39:51.197785Z","price_level":"115665.99","new_quantity":"0"},{"side":"offer","event_time":"2025-10-27T17:39:51.197785Z","price_level":"115666","new_quantity":"0"},{"side":"offer","event_time":"2025-10-27T17:39:51.197785Z","price_level":"115671.71","new_quantity":"0.13835547"},{"side":"offer","event_time":"2025-10-27T17:39:51.197785Z","price_level":"115673.29","new_quantity":"0"},{"side":"offer","event_time":"2025-10-27T17:39:51.197785Z","price_level":"115723.49","new_quantity":"0.56829549"},{"side":"offer","event_time":"2025-10-27T17:39:51.197785Z","price_level":"115723.99","new_quantity":"0"}]}]}
{"channel":"l2_data","client_id":"","timestamp":"2025-10-27T17:39:51.272138653Z","sequence_num":138091,"events":[{"type":"update","product_id":"ETH-USD","updates":[{"side":"bid","event_time":"2025-10-27T17:39:51.229236Z","price_level":"4217.3","new_quantity":"0.56367673"},{"side":"offer","event_time":"2025-10-27T17:39:51.229236Z","price_level":"4218.07","new_quantity":"0.13337132"},{"side":"offer","event_time":"2025-10-27T17:39:51.229236Z","price_level":"4218.18","new_quantity":"0.00237076"},{"side":"offer","event_time":"2025-10-27T17:39:51.229236Z","price_level":"4218.19","new_quantity":"0.07112055"},{"side":"offer","event_time":"2025-10-27T17:39:51.229236Z","price_level":"4218.72","new_quantity":"0.11853395"},{"side":"offer","event_time":"2025-10-27T17:39:51.229236Z","price_level":"4218.86","new_quantity":"0"},{"side":"offer","event_time":"2025-10-27T17:39:51.229236Z","price_level":"4218.89","new_quantity":"0.01508562"},{"side":"offer","event_time":"2025-10-27T17:39:51.229236Z","price_level":"4219.5","new_quantity":"10.001"},{"side":"offer","event_time":"2025-10-27T17:39:51.229236Z","price_level":"4219.7","new_quantity":"0.49495661"},{"side":"offer","event_time":"2025-10-27T17:39:51.229236Z","price_level":"4223.68","new_quantity":"0.1536"}]}]}
{"channel":"l2_data","client_id":"","timestamp":"2025-10-27T17:39:51.296971212Z","sequence_num":138092,"events":[{"type":"update","product_id":"BTC-USD","updates":[{"side":"bid","event_time":"2025-10-27T17:39:51.24955Z","price_level":"115627.3","new_quantity":"0.45601196"},{"side":"bid","event_time":"2025-10-27T17:39:51.24955Z","price_level":"115624","new_quantity":"0.4"},{"side":"bid","event_time":"2025-10-27T17:39:51.24955Z","price_level":"115623.01","new_quantity":"0.44700703"},{"side":"bid","event_time":"2025-10-27T17:39:51.24955Z","price_level":"115623","new_quantity":"0"},{"side":"bid","event_time":"2025-10-27T17:39:51.24955Z","price_level":"115621.61","new_quantity":"0.12"},{"side":"bid","event_time":"2025-10-27T17:39:51.24955Z","price_level":"115619","new_quantity":"0.4"},{"side":"bid","event_time":"2025-10-27T17:39:51.24955Z","price_level":"115618","new_quantity":"0"},{"side":"bid","event_time":"2025-10-27T17:39:51.24955Z","price_level":"115617.07","new_quantity":"1.75391653"},{"side":"bid","event_time":"2025-10-27T17:39:51.24955Z","price_level":"115615","new_quantity":"2.4"},{"side":"bid","event_time":"2025-10-27T17:39:51.24955Z","price_level":"115599.25","new_quantity":"0.65274295"},{"side":"bid","event_time":"2025-10-27T17:39:51.24955Z","price_level":"115564.57","new_quantity":"1.27066269"},{"side":"offer","event_time":"2025-10-27T17:39:51.24955Z","price_level":"115662","new_quantity":"0"},{"side":"offer","event_time":"2025-10-27T17:39:51.24955Z","price_level":"115665.99","new_quantity":"0"},{"side":"offer","event_time":"2025-10-27T17:39:51.24955Z","price_level":"115666","new_quantity":"0"},{"side":"offer","event_time":"2025-10-27T17:39:51.24955Z","price_level":"115670.7","new_quantity":"0.0069609"},{"side":"offer","event_time":"2025-10-27T17:39:51.24955Z","price_level":"115687.84","new_quantity":"0.02014916"},{"side":"offer","event_time":"2025-10-27T17:39:51.24955Z","price_level":"115689.73","new_quantity":"0.16688278"},{"side":"offer","event_time":"2025-10-27T17:39:51.24955Z","price_level":"115694.05","new_quantity":"0"},{"side":"offer","event_time":"2025-10-27T17:39:51.24955Z","price_level":"115705.5","new_quantity":"0.25575097"},{"side":"offer","event_time":"2025-10-27T17:39:51.24955Z","price_level":"115709.99","new_quantity":"0"}]}]}
{"channel":"l2_data","client_id":"","timestamp":"2025-10-27T17:39:51.318965082Z","sequence_num":138093,"events":[{"type":"update","product_id":"ETH-USD","updates":[{"side":"offer","event_time":"2025-10-27T17:39:51.28921Z","price_level":"4218.68","new_quantity":"0.01185319"},{"side":"offer","event_time":"2025-10-27T17:39:51.28921Z","price_level":"4218.89","new_quantity":"0"},{"side":"offer","event_time":"2025-10-27T17:39:51.28921Z","price_level":"4219.11","new_quantity":"0.35769564"},{"side":"offer","event_time":"2025-10-27T17:39:51.28921Z","price_level":"4219.15","new_quantity":"0"},{"side":"offer","event_time":"2025-10-27T17:39:51.28921Z","price_level":"4219.4","new_quantity":"10"},{"side":"offer","event_time":"2025-10-27T17:39:51.28921Z","price_level":"4219.8","new_quantity":"20"},{"side":"offer","event_time":"2025-10-27T17:39:51.28921Z","price_level":"4223.22","new_quantity":"0.6518384"},{"side":"offer","event_time":"2025-10-27T17:39:51.28921Z","price_level":"4223.68","new_quantity":"0"},{"side":"offer","event_time":"2025-10-27T17:39:51.28921Z","price_level":"4244.78","new_quantity":"0"}]}]}
{"channel":"l2_data","client_id":"","timestamp":"2025-10-27T17:39:51.347148648Z","sequence_num":138095,"events":[{"type":"update","product_id":"BTC-USD","updates":[{"side":"bid","event_time":"2025-10-27T17:39:51.308664Z","price_level":"115636","new_quantity":"0.17387027"},{"side":"bid","event_time":"2025-10-27T17:39:51.308664Z","price_level":"115570.5","new_quantity":"0"},{"side":"bid","event_time":"2025-10-27T17:39:51.308664Z","price_level":"115568.5","new_quantity":"1.5"},{"side":"offer","event_time":"2025-10-27T17:39:51.308664Z","price_level":"115721.8","new_quantity":"1"},{"side":"offer","event_time":"2025-10-27T17:39:51.308664Z","price_level":"115722.49","new_quantity":"0.5683004"},{"side":"offer","event_time":"2025-10-27T17:39:51.308664Z","price_level":"115723.49","new_quantity":"0"},{"side":"offer","event_time":"2025-10-27T17:39:51.308664Z","price_level":"115723.5","new_quantity":"0"}]}]}
{"channel":"l2_data","client_id":"","timestamp":"2025-10-27T17:39:51.371134619Z","sequence_num":138096,"events":[{"type":"update","product_id":"ETH-USD","updates":[{"side":"bid","event_time":"2025-10-27T17:39:51.310921Z","price_level":"4216.36","new_quantity":"0"},{"side":"bid","event_time":"2025-10-27T17:39:51.310921Z","price_level":"4216.35","new_quantity":"0"},{"side":"offer","event_time":"2025-10-27T17:39:51.310921Z","price_level":"4219.4","new_quantity":"0"},{"side":"offer","event_time":"2025-10-27T17:39:51.310921Z","price_level":"4219.5","new_quantity":"0.001"}]}]}
{"channel":"l2_data","client_id":"","timestamp":"2025-10-27T17:39:51.396974806Z","sequence_num":138098,"events":[{"type":"update","product_id":"BTC-USD","updates":[{"side":"bid","event_time":"2025-10-27T17:39:51.356318Z","price_level":"115603.77","new_quantity":"0"},{"side":"bid","event_time":"2025-10-27T17:39:51.356318Z","price_level":"115596.73","new_quantity":"0"},{"side":"bid","event_time":"2025-10-27T17:39:51.356318Z","price_level":"115596.71","new_quantity":"0.37038886"},{"side":"offer","event_time":"2025-10-27T17:39:51.356318Z","price_level":"115705.49","new_quantity":"0"},{"side":"offer","event_time":"2025-10-27T17:39:51.356318Z","price_level":"115705.5","new_quantity":"0.25618334"},{"side":"offer","event_time":"2025-10-27T17:39:51.356318Z","price_level":"115711.3","new_quantity":"1"},{"side":"offer","event_time":"2025-10-27T17:39:51.356318Z","price_level":"115721.8","new_quantity":"0"}]}]}
{"channel":"l2_data","client_id":"","timestamp":"2025-10-27T17:39:51.419358838Z","sequence_num":138099,"events":[{"type":"update","product_id":"ETH-USD","updates":[{"side":"offer","event_time":"2025-10-27T17:39:51.352978Z","price_level":"4219.4","new_quantity":"10"},{"side":"offer","event_time":"2025-10-27T17:39:51.352978Z","price_level":"4219.5","new_quantity":"10.001"}]}]}
{"channel":"l2_data","client_id":"","timestamp":"2025-10-27T17:39:51.444123066Z","sequence_num":138100,"events":[{"type":"update","product_id":"BTC-USD","updates":[{"side":"offer","event_time":"2025-10-27T17:39:51.381493Z","price_level":"115722.49","new_quantity":"0"},{"side":"offer","event_time":"2025-10-27T17:39:51.381493Z","price_level":"115735.11","new_quantity":"0.56823843"}]}]}
{"channel":"l2_data","client_id":"","timestamp":"2025-10-27T17:39:51.470579987Z","sequence_num":138101,"events":[{"type":"update","product_id":"ETH-USD","updates":[{"side":"bid","event_time":"2025-10-27T17:39:51.417963Z","price_level":"4217.03","new_quantity":"0.21565049"},{"side":"offer","event_time":"2025-10-27T17:39:51.417963Z","price_level":"4218.68","new_quantity":"0"},{"side":"offer","event_time":"2025-10-27T17:39:51.417963Z","price_level":"4218.8","new_quantity":"0.01508562"}]}]}
{"channel":"l2_data","client_id":"","timestamp":"2025-10-27T17:39:51.498215635Z","sequence_num":138102,"events":[{"type":"update","product_id":"BTC-USD","updates":[{"side":"bid","event_time":"2025-10-27T17:39:51.43922Z","price_level":"115636","new_quantity":"0.26852027"},{"side":"bid","event_time":"2025-10-27T17:39:51.43922Z","price_level":"115629","new_quantity":"0.4"},{"side":"bid","event_time":"2025-10-27T17:39:51.43922Z","price_level":"115627.3","new_quantity":"0.66698073"},{"side":"bid","event_time":"2025-10-27T17:39:51.43922Z","price_level":"115627","new_quantity":"0.4"},{"side":"bid","event_time":"2025-10-27T17:39:51.43922Z","price_level":"115625","new_quantity":"0.4"},{"side":"bid","event_time":"2025-10-27T17:39:51.43922Z","price_level":"115624","new_quantity":"0"},{"side":"bid","event_time":"2025-10-27T17:39:51.43922Z","price_level":"115623.01","new_quantity":"1.61437896"},{"side":"bid","event_time":"2025-10-27T17:39:51.43922Z","price_level":"115620","new_quantity":"1"},{"side":"bid","event_time":"2025-10-27T17:39:51.43922Z","price_level":"115618","new_quantity":"2"},{"side":"bid","event_time":"2025-10-27T17:39:51.43922Z","price_level":"115617.07","new_quantity":"0.52902893"},{"side":"bid","event_time":"2025-10-27T17:39:51.43922Z","price_level":"115615","new_quantity":"0.4"},{"side":"bid","event_time":"2025-10-27T17:39:51.43922Z","price_level":"115611.01","new_quantity":"0.34714209"},{"side":"bid","event_time":"2025-10-27T17:39:51.43922Z","price_level":"115610","new_quantity":"0"},{"side":"bid","event_time":"2025-10-27T17:39:51.43922Z","price_level":"115602.36","new_quantity":"0.0069609"},{"side":"bid","event_time":"2025-10-27T17:39:51.43922Z","price_level":"101181.5","new_quantity":"0.0049568"},{"side":"offer","event_time":"2025-10-27T17:39:51.43922Z","price_level":"115699.67","new_quantity":"0.5"}]}]}
{"channel":"l2_data","client_id":"","timestamp":"2025-10-27T17:39:51.547990913Z","sequence_num":138103,"events":[{"type":"update","product_id":"BTC-USD","updates":[{"side":"bid","event_time":"2025-10-27T17:39:51.498281Z","price_level":"115632.01","new_quantity":"0.32348429"},{"side":"bid","event_time":"2025-10-27T17:39:51.498281Z","price_level":"115630.29","new_quantity":"0.02161141"},{"side":"bid","event_time":"2025-10-27T17:39:51.498281Z","price_level":"115629.16","new_quantity":"0"},{"side":"bid","event_time":"2025-10-27T17:39:51.498281Z","price_level":"115623.01","new_quantity":"2.30093276"},{"side":"bid","event_time":"2025-10-27T17:39:51.498281Z","price_level":"115623","new_quantity":"0.4"},{"side":"bid","event_time":"2025-10-27T17:39:51.498281Z","price_level":"115617.07","new_quantity":"1.75391653"},{"side":"bid","event_time":"2025-10-27T17:39:51.498281Z","price_level":"115617","new_quantity":"2"},{"side":"bid","event_time":"2025-10-27T17:39:51.498281Z","price_level":"115572.51","new_quantity":"0.81374071"},{"side":"bid","event_time":"2025-10-27T17:39:51.498281Z","price_level":"115572.5","new_quantity":"1.5"},{"side":"bid","event_time":"2025-10-27T17:39:51.498281Z","price_level":"115570.51","new_quantity":"0"},{"side":"bid","event_time":"2025-10-27T17:39:51.498281Z","price_level":"115568.5","new_quantity":"0"},{"side":"offer","event_time":"2025-10-27T17:39:51.498281Z","price_level":"115647.51","new_quantity":"0"},{"side":"offer","event_time":"2025-10-27T17:39:51.498281Z","price_level":"115647.52","new_quantity":"0.00008564"},{"side":"offer","event_time":"2025-10-27T17:39:51.498281Z","price_level":"115711.29","new_quantity":"0.00043233"},{"side":"offer","event_time":"2025-10-27T17:39:51.498281Z","price_level":"115711.3","new_quantity":"0"},{"side":"offer","event_time":"2025-10-27T17:39:51.498281Z","price_level":"115711.99","new_quantity":"0"},{"side":"offer","event_time":"2025-10-27T17:39:51.498281Z","price_level":"115722.89","new_quantity":"0.56829843"},{"side":"offer","event_time":"2025-10-27T17:39:51.498281Z","price_level":"115722.9","new_quantity":"1"},{"side":"offer","event_time":"2025-10-27T17:39:51.498281Z","price_level":"115735.11","new_quantity":"0"}]}]}
{"channel":"l2_data","client_id":"","timestamp":"2025-10-27T17:39:51.568682432Z","sequence_num":138104,"events":[{"type":"update","product_id":"ETH-USD","updates":[{"side":"offer","event_time":"2025-10-27T17:39:51.534421Z","price_level":"4218.1","new_quantity":"0"},{"side":"offer","event_time":"2025-10-27T17:39:51.534421Z","price_level":"4218.16","new_quantity":"0.00237075"},{"side":"offer","event_time":"2025-10-27T17:39:51.534421Z","price_level":"4218.17","new_quantity":"0"},{"side":"offer","event_time":"2025-10-27T17:39:51.534421Z","price_level":"4218.18","new_quantity":"0"},{"side":"offer","event_time":"2025-10-27T17:39:51.534421Z","price_level":"4218.19","new_quantity":"0"},{"side":"offer","event_time":"2025-10-27T17:39:51.534421Z","price_level":"4218.47","new_quantity":"0"},{"side":"offer","event_time":"2025-10-27T17:39:51.534421Z","price_level":"4218.48","new_quantity":"0.01831983"},{"side":"offer","event_time":"2025-10-27T17:39:51.534421Z","price_level":"4218.8","new_quantity":"0"},{"side":"offer","event_time":"2025-10-27T17:39:51.534421Z","price_level":"4218.86","new_quantity":"0"},{"side":"offer","event_time":"2025-10-27T17:39:51.534421Z","price_level":"4244.78","new_quantity":"0.1536"}]}]}
{"channel":"l2_data","client_id":"","timestamp":"2025-10-27T17:39:51.597336562Z","sequence_num":138106,"events":[{"type":"update","product_id":"BTC-USD","updates":[{"side":"bid","event_time":"2025-10-27T17:39:51.551942Z","price_level":"115636","new_quantity":"0.29840656"},{"side":"bid","event_time":"2025-10-27T17:39:51.551942Z","price_level":"115623.63","new_quantity":"0"},{"side":"bid","event_time":"2025-10-27T17:39:51.551942Z","price_level":"115623.01","new_quantity":"3.50826016"},{"side":"bid","event_time":"2025-10-27T17:39:51.551942Z","price_level":"115622.57","new_quantity":"0.16503"},{"side":"bid","event_time":"2025-10-27T17:39:51.551942Z","price_level":"115621.28","new_quantity":"0"},{"side":"bid","event_time":"2025-10-27T17:39:51.551942Z","price_level":"115619","new_quantity":"2.4"},{"side":"bid","event_time":"2025-10-27T17:39:51.551942Z","price_level":"115617.07","new_quantity":"0.52902893"},{"side":"bid","event_time":"2025-10-27T17:39:51.551942Z","price_level":"115617","new_quantity":"0"},{"side":"offer","event_time":"2025-10-27T17:39:51.551942Z","price_level":"115647.51","new_quantity":"0.00008564"},{"side":"offer","event_time":"2025-10-27T17:39:51.551942Z","price_level":"115647.52","new_quantity":"0.00172364"},{"side":"offer","event_time":"2025-10-27T17:39:51.551942Z","price_level":"115647.58","new_quantity":"0"},{"side":"offer","event_time":"2025-10-27T17:39:51.551942Z","price_level":"115658.36","new_quantity":"0"},{"side":"offer","event_time":"2025-10-27T17:39:51.551942Z","price_level":"115658.37","new_quantity":"0"},{"side":"offer","event_time":"2025-10-27T17:39:51.551942Z","price_level":"115662","new_quantity":"0"},{"side":"offer","event_time":"2025-10-27T17:39:51.551942Z","price_level":"115663","new_quantity":"2.00432"},{"side":"offer","event_time":"2025-10-27T17:39:51.551942Z","price_level":"115663.01","new_quantity":"0.00432"},{"side":"offer","event_time":"2025-10-27T17:39:51.551942Z","price_level":"115665.99","new_quantity":"0"},{"side":"offer","event_time":"2025-10-27T17:39:51.551942Z","price_level":"115666","new_quantity":"0"},{"side":"offer","event_time":"2025-10-27T17:39:51.551942Z","price_level":"115670.7","new_quantity":"0"}]}]}
{"channel":"l2_data","client_id":"","timestamp":"2025-10-27T17:39:51.620798301Z","sequence_num":138107,"events":[{"type":"update","product_id":"ETH-USD","updates":[{"side":"bid","event_time":"2025-10-27T17:39:51.572878Z","price_level":"4212.98","new_quantity":"0"},{"side":"bid","event_time":"2025-10-27T17:39:51.572878Z","price_level":"4212.21","new_quantity":"1.043"},{"side":"offer","event_time":"2025-10-27T17:39:51.572878Z","price_level":"4218.16","new_quantity":"0"},{"side":"offer","event_time":"2025-10-27T17:39:51.572878Z","price_level":"4218.19","new_quantity":"0.00237075"},{"side":"offer","event_time":"2025-10-27T17:39:51.572878Z","price_level":"4218.48","new_quantity":"0.08943549"}]}]}
