{"channel":"l2_data","client_id":"","timestamp":"2025-10-27T17:39:36.398073373Z","sequence_num":137416,"events":[{"type":"update","product_id":"BTC-USD","updates":[{"side":"bid","event_time":"2025-10-27T17:39:36.361354Z","price_level":"115192.29","new_quantity":"0.07007"},{"side":"bid","event_time":"2025-10-27T17:39:36.361354Z","price_level":"115192.23","new_quantity":"0"},{"side":"bid","event_time":"2025-10-27T17:39:36.361354Z","price_level":"115191.97","new_quantity":"0"},{"side":"bid","event_time":"2025-10-27T17:39:36.361354Z","price_level":"114333.81","new_quantity":"0.07007"},{"side":"bid","event_time":"2025-10-27T17:39:36.361354Z","price_level":"114333.72","new_quantity":"0.07007"},{"side":"bid","event_time":"2025-10-27T17:39:36.361354Z","price_level":"114120.73","new_quantity":"0"},{"side":"offer","event_time":"2025-10-27T17:39:36.361354Z","price_level":"115689","new_quantity":"0.4"},{"side":"offer","event_time":"2025-10-27T17:39:36.361354Z","price_level":"115690","new_quantity":"2"},{"side":"offer","event_time":"2025-10-27T17:39:36.361354Z","price_level":"115700","new_quantity":"1"}]}]}
{"channel":"l2_data","client_id":"","timestamp":"2025-10-27T17:39:36.420970068Z","sequence_num":137417,"events":[{"type":"update","product_id":"ETH-USD","updates":[{"side":"bid","event_time":"2025-10-27T17:39:36.372087Z","price_level":"4215.48","new_quantity":"0"},{"side":"bid","event_time":"2025-10-27T17:39:36.372087Z","price_level":"4215.15","new_quantity":"0.37635091"},{"side":"offer","event_time":"2025-10-27T17:39:36.372087Z","price_level":"4218.49","new_quantity":"1.44539746"},{"side":"offer","event_time":"2025-10-27T17:39:36.372087Z","price_level":"4221.37","new_quantity":"13.41736584"},{"side":"offer","event_time":"2025-10-27T17:39:36.372087Z","price_level":"4221.38","new_quantity":"1.94391607"},{"side":"offer","event_time":"2025-10-27T17:39:36.372087Z","price_level":"4221.39","new_quantity":"0"},{"side":"offer","event_time":"2025-10-27T17:39:36.372087Z","price_level":"4221.4","new_quantity":"0"}]}]}
{"channel":"l2_data","client_id":"","timestamp":"2025-10-27T17:39:36.447017003Z","sequence_num":137418,"events":[{"type":"update","product_id":"BTC-USD","updates":[{"side":"bid","event_time":"2025-10-27T17:39:36.389806Z","price_level":"115631","new_quantity":"0"},{"side":"bid","event_time":"2025-10-27T17:39:36.389806Z","price_level":"115628.53","new_quantity":"1.51954644"},{"side":"bid","event_time":"2025-10-27T17:39:36.389806Z","price_level":"115628","new_quantity":"0"},{"side":"bid","event_time":"2025-10-27T17:39:36.389806Z","price_level":"115622.88","new_quantity":"0"},{"side":"bid","event_time":"2025-10-27T17:39:36.389806Z","price_level":"115621.81","new_quantity":"0.07007"},{"side":"bid","event_time":"2025-10-27T17:39:36.389806Z","price_level":"114333.72","new_quantity":"0"},{"side":"offer","event_time":"2025-10-27T17:39:36.389806Z","price_level":"115689","new_quantity":"0"},{"side":"offer","event_time":"2025-10-27T17:39:36.389806Z","price_level":"115689.72","new_quantity":"0"},{"side":"offer","event_time":"2025-10-27T17:39:36.389806Z","price_level":"115690","new_quantity":"0"},{"side":"offer","event_time":"2025-10-27T17:39:36.389806Z","price_level":"115692","new_quantity":"0"},{"side":"offer","event_time":"2025-10-27T17:39:36.389806Z","price_level":"115694","new_quantity":"0"},{"side":"offer","event_time":"2025-10-27T17:39:36.389806Z","price_level":"115700","new_quantity":"0"}]}]}
{"channel":"l2_data","client_id":"","timestamp":"2025-10-27T17:39:36.469461153Z","sequence_num":137419,"events":[{"type":"update","product_id":"ETH-USD","updates":[{"side":"bid","event_time":"2025-10-27T17:39:36.400842Z","price_level":"4214.2","new_quantity":"12.69723405"},{"side":"bid","event_time":"2025-10-27T17:39:36.400842Z","price_level":"4214.02","new_quantity":"0"},{"side":"bid","event_time":"2025-10-27T17:39:36.400842Z","price_level":"4169.84","new_quantity":"0"},{"side":"bid","event_time":"2025-10-27T17:39:36.400842Z","price_level":"4149.64","new_quantity":"0"}]}]}
{"channel":"l2_data","client_id":"","timestamp":"2025-10-27T17:39:36.498354064Z","sequence_num":137420,"events":[{"type":"update","product_id":"BTC-USD","updates":[{"side":"bid","event_time":"2025-10-27T17:39:36.448523Z","price_level":"115634","new_quantity":"0.4"},{"side":"bid","event_time":"2025-10-27T17:39:36.448523Z","price_level":"115632.98","new_quantity":"2.48166125"},{"side":"bid","event_time":"2025-10-27T17:39:36.448523Z","price_level":"115629","new_quantity":"2.4"},{"side":"bid","event_time":"2025-10-27T17:39:36.448523Z","price_level":"115621.9","new_quantity":"0.07007"},{"side":"bid","event_time":"2025-10-27T17:39:36.448523Z","price_level":"115621.84","new_quantity":"0.07007"},{"side":"bid","event_time":"2025-10-27T17:39:36.448523Z","price_level":"115621.81","new_quantity":"0"},{"side":"bid","event_time":"2025-10-27T17:39:36.448523Z","price_level":"115621.74","new_quantity":"0"},{"side":"bid","event_time":"2025-10-27T17:39:36.448523Z","price_level":"115589","new_quantity":"0"},{"side":"bid","event_time":"2025-10-27T17:39:36.448523Z","price_level":"115588.8","new_quantity":"1.5"},{"side":"bid","event_time":"2025-10-27T17:39:36.448523Z","price_level":"115407.24","new_quantity":"0.07007"},{"side":"bid","event_time":"2025-10-27T17:39:36.448523Z","price_level":"115407.14","new_quantity":"0"},{"side":"bid","event_time":"2025-10-27T17:39:36.448523Z","price_level":"114333.81","new_quantity":"0"},{"side":"bid","event_time":"2025-10-27T17:39:36.448523Z","price_level":"101200.02","new_quantity":"0.00446112"},{"side":"offer","event_time":"2025-10-27T17:39:36.448523Z","price_level":"115689","new_quantity":"0.4"},{"side":"offer","event_time":"2025-10-27T17:39:36.448523Z","price_level":"115693","new_quantity":"0.4"}]}]}
{"channel":"l2_data","client_id":"","timestamp":"2025-10-27T17:39:36.54735915Z","sequence_num":137421,"events":[{"type":"update","product_id":"BTC-USD","updates":[{"side":"bid","event_time":"2025-10-27T17:39:36.505386Z","price_level":"115652.01","new_quantity":"0"},{"side":"bid","event_time":"2025-10-27T17:39:36.505386Z","price_level":"115650.01","new_quantity":"0.00172935"},{"side":"bid","event_time":"2025-10-27T17:39:36.505386Z","price_level":"115634","new_quantity":"0"},{"side":"bid","event_time":"2025-10-27T17:39:36.505386Z","price_level":"115632.98","new_quantity":"1.50340755"},{"side":"bid","event_time":"2025-10-27T17:39:36.505386Z","price_level":"115629","new_quantity":"0.4"},{"side":"bid","event_time":"2025-10-27T17:39:36.505386Z","price_level":"115622.53","new_quantity":"0.0069609"},{"side":"bid","event_time":"2025-10-27T17:39:36.505386Z","price_level":"115621.84","new_quantity":"0"},{"side":"bid","event_time":"2025-10-27T17:39:36.505386Z","price_level":"115567.36","new_quantity":"0.00043225"},{"side":"bid","event_time":"2025-10-27T17:39:36.505386Z","price_level":"115567.34","new_quantity":"0"},{"side":"offer","event_time":"2025-10-27T17:39:36.505386Z","price_level":"115674.6","new_quantity":"0.00432"},{"side":"offer","event_time":"2025-10-27T17:39:36.505386Z","price_level":"115689","new_quantity":"0"}]}]}
{"channel":"l2_data","client_id":"","timestamp":"2025-10-27T17:39:36.596679086Z","sequence_num":137422,"events":[{"type":"update","product_id":"BTC-USD","updates":[{"side":"bid","event_time":"2025-10-27T17:39:36.555064Z","price_level":"115652.01","new_quantity":"0.03638422"},{"side":"bid","event_time":"2025-10-27T17:39:36.555064Z","price_level":"115633","new_quantity":"0.4"},{"side":"bid","event_time":"2025-10-27T17:39:36.555064Z","price_level":"115628.53","new_quantity":"2.20699334"},{"side":"bid","event_time":"2025-10-27T17:39:36.555064Z","price_level":"115628","new_quantity":"2"}]}]}
{"channel":"l2_data","client_id":"","timestamp":"2025-10-27T17:39:36.646683824Z","sequence_num":137424,"events":[{"type":"update","product_id":"BTC-USD","updates":[{"side":"bid","event_time":"2025-10-27T17:39:36.608942Z","price_level":"115633","new_quantity":"0"},{"side":"bid","event_time":"2025-10-27T17:39:36.608942Z","price_level":"115628.53","new_quantity":"1.51954644"},{"side":"bid","event_time":"2025-10-27T17:39:36.608942Z","price_level":"115628","new_quantity":"0"},{"side":"bid","event_time":"2025-10-27T17:39:36.608942Z","price_level":"115407.43","new_quantity":"0.07007"},{"side":"offer","event_time":"2025-10-27T17:39:36.608942Z","price_level":"115657.17","new_quantity":"0.00002696"},{"side":"offer","event_time":"2025-10-27T17:39:36.608942Z","price_level":"115708.71","new_quantity":"0.17930161"},{"side":"offer","event_time":"2025-10-27T17:39:36.608942Z","price_level":"115708.72","new_quantity":"0.5"},{"side":"offer","event_time":"2025-10-27T17:39:36.608942Z","price_level":"115709.99","new_quantity":"0"}]}]}
{"channel":"l2_data","client_id":"","timestamp":"2025-10-27T17:39:36.670957608Z","sequence_num":137425,"events":[{"type":"update","product_id":"ETH-USD","updates":[{"side":"bid","event_time":"2025-10-27T17:39:36.60057Z","price_level":"4218.05","new_quantity":"0.54800566"},{"side":"bid","event_time":"2025-10-27T17:39:36.60057Z","price_level":"4217.83","new_quantity":"0.002"},{"side":"bid","event_time":"2025-10-27T17:39:36.60057Z","price_level":"4216.11","new_quantity":"0"},{"side":"bid","event_time":"2025-10-27T17:39:36.60057Z","price_level":"4129.44","new_quantity":"0"},{"side":"offer","event_time":"2025-10-27T17:39:36.60057Z","price_level":"4218.06","new_quantity":"0.00237087"},{"side":"offer","event_time":"2025-10-27T17:39:36.60057Z","price_level":"4218.37","new_quantity":"0"},{"side":"offer","event_time":"2025-10-27T17:39:36.60057Z","price_level":"4218.68","new_quantity":"0.02003401"},{"side":"offer","event_time":"2025-10-27T17:39:36.60057Z","price_level":"4218.78","new_quantity":"0.55457476"},{"side":"offer","event_time":"2025-10-27T17:39:36.60057Z","price_level":"4220.67","new_quantity":"0.00886424"},{"side":"offer","event_time":"2025-10-27T17:39:36.60057Z","price_level":"4221.33","new_quantity":"13.41749298"},{"side":"offer","event_time":"2025-10-27T17:39:36.60057Z","price_level":"4221.34","new_quantity":"1.94391607"},{"side":"offer","event_time":"2025-10-27T17:39:36.60057Z","price_level":"4221.35","new_quantity":"0"},{"side":"offer","event_time":"2025-10-27T17:39:36.60057Z","price_level":"4221.36","new_quantity":"0.13633061"},{"side":"offer","event_time":"2025-10-27T17:39:36.60057Z","price_level":"4221.37","new_quantity":"0"},{"side":"offer","event_time":"2025-10-27T17:39:36.60057Z","price_level":"4221.38","new_quantity":"0"},{"side":"offer","event_time":"2025-10-27T17:39:36.60057Z","price_level":"4223.16","new_quantity":"0"},{"side":"offer","event_time":"2025-10-27T17:39:36.60057Z","price_level":"4244.24","new_quantity":"0.1536"}]}]}
{"channel":"l2_data","client_id":"","timestamp":"2025-10-27T17:39:36.696943269Z","sequence_num":137426,"events":[{"type":"update","product_id":"BTC-USD","updates":[{"side":"bid","event_time":"2025-10-27T17:39:36.637204Z","price_level":"115638.29","new_quantity":"0.33384801"},{"side":"bid","event_time":"2025-10-27T17:39:36.637204Z","price_level":"115635","new_quantity":"0.4"},{"side":"bid","event_time":"2025-10-27T17:39:36.637204Z","price_level":"115632.98","new_quantity":"2.50519986"},{"side":"bid","event_time":"2025-10-27T17:39:36.637204Z","price_level":"115631","new_quantity":"0.4"},{"side":"bid","event_time":"2025-10-27T17:39:36.637204Z","price_level":"115630","new_quantity":"2"},{"side":"bid","event_time":"2025-10-27T17:39:36.637204Z","price_level":"115407.24","new_quantity":"0"},{"side":"bid","event_time":"2025-10-27T17:39:36.637204Z","price_level":"114977.6","new_quantity":"0.07007"},{"side":"bid","event_time":"2025-10-27T17:39:36.637204Z","price_level":"114977.49","new_quantity":"0"},{"side":"offer","event_time":"2025-10-27T17:39:36.637204Z","price_level":"115693","new_quantity":"0"}]}]}
{"channel":"l2_data","client_id":"","timestamp":"2025-10-27T17:39:36.719054855Z","sequence_num":137427,"events":[{"type":"update","product_id":"ETH-USD","updates":[{"side":"offer","event_time":"2025-10-27T17:39:36.670834Z","price_level":"4218.82","new_quantity":"0"}]}]}
{"channel":"l2_data","client_id":"","timestamp":"2025-10-27T17:39:36.749834261Z","sequence_num":137428,"events":[{"type":"update","product_id":"BTC-USD","updates":[{"side":"bid","event_time":"2025-10-27T17:39:36.690212Z","price_level":"115645.36","new_quantity":"0"},{"side":"bid","event_time":"2025-10-27T17:39:36.690212Z","price_level":"115630.01","new_quantity":"0.33054521"},{"side":"bid","event_time":"2025-10-27T17:39:36.690212Z","price_level":"115629.01","new_quantity":"0"},{"side":"bid","event_time":"2025-10-27T17:39:36.690212Z","price_level":"115621.91","new_quantity":"0.07007"},{"side":"bid","event_time":"2025-10-27T17:39:36.690212Z","price_level":"115621.9","new_quantity":"0"},{"side":"bid","event_time":"2025-10-27T17:39:36.690212Z","price_level":"115612.94","new_quantity":"0.52632025"},{"side":"bid","event_time":"2025-10-27T17:39:36.690212Z","price_level":"115612.93","new_quantity":"0"},{"side":"bid","event_time":"2025-10-27T17:39:36.690212Z","price_level":"115612.92","new_quantity":"0"},{"side":"bid","event_time":"2025-10-27T17:39:36.690212Z","price_level":"115596.71","new_quantity":"0.78060617"},{"side":"bid","event_time":"2025-10-27T17:39:36.690212Z","price_level":"115593.59","new_quantity":"0"},{"side":"bid","event_time":"2025-10-27T17:39:36.690212Z","price_level":"115567.37","new_quantity":"1.20622793"},{"side":"bid","event_time":"2025-10-27T17:39:36.690212Z","price_level":"115567.36","new_quantity":"0.00043225"},{"side":"bid","event_time":"2025-10-27T17:39:36.690212Z","price_level":"115567.35","new_quantity":"0"},{"side":"offer","event_time":"2025-10-27T17:39:36.690212Z","price_level":"115659.74","new_quantity":"0"},{"side":"offer","event_time":"2025-10-27T17:39:36.690212Z","price_level":"115660.71","new_quantity":"0"},{"side":"offer","event_time":"2025-10-27T17:39:36.690212Z","price_level":"115660.72","new_quantity":"0"},{"side":"offer","event_time":"2025-10-27T17:39:36.690212Z","price_level":"115661.78","new_quantity":"0.02593769"},{"side":"offer","event_time":"2025-10-27T17:39:36.690212Z","price_level":"115670.6","new_quantity":"0"},{"side":"offer","event_time":"2025-10-27T17:39:36.690212Z","price_level":"115671.15","new_quantity":"0.25935594"},{"side":"offer","event_time":"2025-10-27T17:39:36.690212Z","price_level":"115674.6","new_quantity":"0"},{"side":"offer","event_time":"2025-10-27T17:39:36.690212Z","price_level":"115676.93","new_quantity":"0"},{"side":"offer","event_time":"2025-10-27T17:39:36.690212Z","price_level":"115679.25","new_quantity":"0.00432"},{"side":"offer","event_time":"2025-10-27T17:39:36.690212Z","price_level":"115690","new_quantity":"0"},{"side":"offer","event_time":"2025-10-27T17:39:36.690212Z","price_level":"115694","new_quantity":"0.4"},{"side":"offer","event_time":"2025-10-27T17:39:36.690212Z","price_level":"115696","new_quantity":"0.4"},{"side":"offer","event_time":"2025-10-27T17:39:36.690212Z","price_level":"115700","new_quantity":"0"},{"side":"offer","event_time":"2025-10-27T17:39:36.690212Z","price_level":"115704.99","new_quantity":"1.06116617"},{"side":"offer","event_time":"2025-10-27T17:39:36.690212Z","price_level":"115729.99","new_quantity":"0"},{"side":"offer","event_time":"2025-10-27T17:39:36.690212Z","price_level":"115743.9","new_quantity":"0.57739707"},{"side":"offer","event_time":"2025-10-27T17:39:36.690212Z","price_level":"115743.91","new_quantity":"0"},{"side":"offer","event_time":"2025-10-27T17:39:36.690212Z","price_level":"115743.92","new_quantity":"0"}]}]}
{"channel":"l2_data","client_id":"","timestamp":"2025-10-27T17:39:36.772696454Z","sequence_num":137429,"events":[{"type":"update","product_id":"ETH-USD","updates":[{"side":"bid","event_time":"2025-10-27T17:39:36.726328Z","price_level":"4218.05","new_quantity":"2.31525391"},{"side":"bid","event_time":"2025-10-27T17:39:36.726328Z","price_level":"4218.02","new_quantity":"0"},{"side":"bid","event_time":"2025-10-27T17:39:36.726328Z","price_level":"4218.01","new_quantity":"1.61680999"},{"side":"bid","event_time":"2025-10-27T17:39:36.726328Z","price_level":"4218","new_quantity":"0.519"},{"side":"bid","event_time":"2025-10-27T17:39:36.726328Z","price_level":"4217.88","new_quantity":"1.05084855"},{"side":"bid","event_time":"2025-10-27T17:39:36.726328Z","price_level":"4217.78","new_quantity":"1.59272776"},{"side":"bid","event_time":"2025-10-27T17:39:36.726328Z","price_level":"4217.55","new_quantity":"0"},{"side":"bid","event_time":"2025-10-27T17:39:36.726328Z","price_level":"4217.54","new_quantity":"0.56004815"},{"side":"bid","event_time":"2025-10-27T17:39:36.726328Z","price_level":"4217.49","new_quantity":"0"},{"side":"bid","event_time":"2025-10-27T17:39:36.726328Z","price_level":"4217.37","new_quantity":"0.437"},{"side":"bid","event_time":"2025-10-27T17:39:36.726328Z","price_level":"4217.23","new_quantity":"5.77990456"},{"side":"bid","event_time":"2025-10-27T17:39:36.726328Z","price_level":"4217.22","new_quantity":"0.23956391"},{"side":"bid","event_time":"2025-10-27T17:39:36.726328Z","price_level":"4217.12","new_quantity":"0"},{"side":"bid","event_time":"2025-10-27T17:39:36.726328Z","price_level":"4217.05","new_quantity":"0"},{"side":"bid","event_time":"2025-10-27T17:39:36.726328Z","price_level":"4216.79","new_quantity":"0.02370946"},{"side":"bid","event_time":"2025-10-27T17:39:36.726328Z","price_level":"4216.57","new_quantity":"0"},{"side":"bid","event_time":"2025-10-27T17:39:36.726328Z","price_level":"4216.4","new_quantity":"0"},{"side":"bid","event_time":"2025-10-27T17:39:36.726328Z","price_level":"4216.32","new_quantity":"0"},{"side":"bid","event_time":"2025-10-27T17:39:36.726328Z","price_level":"4216.31","new_quantity":"0"},{"side":"bid","event_time":"2025-10-27T17:39:36.726328Z","price_level":"4216.27","new_quantity":"0"},{"side":"bid","event_time":"2025-10-27T17:39:36.726328Z","price_level":"4216.23","new_quantity":"0"},{"side":"bid","event_time":"2025-10-27T17:39:36.726328Z","price_level":"4216.16","new_quantity":"4.436603"},{"side":"bid","event_time":"2025-10-27T17:39:36.726328Z","price_level":"4215.84","new_quantity":"3.64804295"},{"side":"bid","event_time":"2025-10-27T17:39:36.726328Z","price_level":"4215.54","new_quantity":"0"},{"side":"bid","event_time":"2025-10-27T17:39:36.726328Z","price_level":"4215.48","new_quantity":"0.64798652"},{"side":"bid","event_time":"2025-10-27T17:39:36.726328Z","price_level":"4215.15","new_quantity":"0"},{"side":"bid","event_time":"2025-10-27T17:39:36.726328Z","price_level":"4215.12","new_quantity":"7.05153691"},{"side":"bid","event_time":"2025-10-27T17:39:36.726328Z","price_level":"4215.1","new_quantity":"0.11854732"},{"side":"bid","event_time":"2025-10-27T17:39:36.726328Z","price_level":"4215.01","new_quantity":"8.84592291"},{"side":"bid","event_time":"2025-10-27T17:39:36.726328Z","price_level":"4214.92","new_quantity":"0"},{"side":"bid","event_time":"2025-10-27T17:39:36.726328Z","price_level":"4214.91","new_quantity":"5.13229668"},{"side":"bid","event_time":"2025-10-27T17:39:36.726328Z","price_level":"4214.72","new_quantity":"0.20004387"},{"side":"bid","event_time":"2025-10-27T17:39:36.726328Z","price_level":"4214.24","new_quantity":"12.69711353"},{"side":"bid","event_time":"2025-10-27T17:39:36.726328Z","price_level":"4214.2","new_quantity":"0"},{"side":"bid","event_time":"2025-10-27T17:39:36.726328Z","price_level":"4214.02","new_quantity":"19.62370173"},{"side":"bid","event_time":"2025-10-27T17:39:36.726328Z","price_level":"4213.87","new_quantity":"0"},{"side":"bid","event_time":"2025-10-27T17:39:36.726328Z","price_level":"4213.8","new_quantity":"6.05662855"},{"side":"bid","event_time":"2025-10-27T17:39:36.726328Z","price_level":"4211.14","new_quantity":"0"},{"side":"bid","event_time":"2025-10-27T17:39:36.726328Z","price_level":"4211.1","new_quantity":"0"},{"side":"offer","event_time":"2025-10-27T17:39:36.726328Z","price_level":"4218.06","new_quantity":"0"},{"side":"offer","event_time":"2025-10-27T17:39:36.726328Z","price_level":"4218.1","new_quantity":"0"},{"side":"offer","event_time":"2025-10-27T17:39:36.726328Z","price_level":"4218.11","new_quantity":"0"},{"side":"offer","event_time":"2025-10-27T17:39:36.726328Z","price_level":"4218.3","new_quantity":"0"},{"side":"offer","event_time":"2025-10-27T17:39:36.726328Z","price_level":"4218.38","new_quantity":"0"},{"side":"offer","event_time":"2025-10-27T17:39:36.726328Z","price_level":"4218.4","new_quantity":"0"},{"side":"offer","event_time":"2025-10-27T17:39:36.726328Z","price_level":"4218.41","new_quantity":"0"},{"side":"offer","event_time":"2025-10-27T17:39:36.726328Z","price_level":"4218.46","new_quantity":"0.09032329"},{"side":"offer","event_time":"2025-10-27T17:39:36.726328Z","price_level":"4218.49","new_quantity":"0"},{"side":"offer","event_time":"2025-10-27T17:39:36.726328Z","price_level":"4218.5","new_quantity":"0.001"},{"side":"offer","event_time":"2025-10-27T17:39:36.726328Z","price_level":"4218.51","new_quantity":"0"},{"side":"offer","event_time":"2025-10-27T17:39:36.726328Z","price_level":"4218.58","new_quantity":"0.69194408"},{"side":"offer","event_time":"2025-10-27T17:39:36.726328Z","price_level":"4218.68","new_quantity":"0"},{"side":"offer","event_time":"2025-10-27T17:39:36.726328Z","price_level":"4218.69","new_quantity":"0"},{"side":"offer","event_time":"2025-10-27T17:39:36.726328Z","price_level":"4218.75","new_quantity":"0.001"},{"side":"offer","event_time":"2025-10-27T17:39:36.726328Z","price_level":"4218.81","new_quantity":"0"},{"side":"offer","event_time":"2025-10-27T17:39:36.726328Z","price_level":"4218.84","new_quantity":"0"},{"side":"offer","event_time":"2025-10-27T17:39:36.726328Z","price_level":"4218.99","new_quantity":"0.01434418"},{"side":"offer","event_time":"2025-10-27T17:39:36.726328Z","price_level":"4219.12","new_quantity":"0.671625"},{"side":"offer","event_time":"2025-10-27T17:39:36.726328Z","price_level":"4219.16","new_quantity":"0"},{"side":"offer","event_time":"2025-10-27T17:39:36.726328Z","price_level":"4219.21","new_quantity":"0"},{"side":"offer","event_time":"2025-10-27T17:39:36.726328Z","price_level":"4219.28","new_quantity":"0"},{"side":"offer","event_time":"2025-10-27T17:39:36.726328Z","price_level":"4219.3","new_quantity":"0"},{"side":"offer","event_time":"2025-10-27T17:39:36.726328Z","price_level":"4219.4","new_quantity":"0"},{"side":"offer","event_time":"2025-10-27T17:39:36.726328Z","price_level":"4219.45","new_quantity":"0.49582781"},{"side":"offer","event_time":"2025-10-27T17:39:36.726328Z","price_level":"4219.46","new_quantity":"0"},{"side":"offer","event_time":"2025-10-27T17:39:36.726328Z","price_level":"4219.72","new_quantity":"0"},{"side":"offer","event_time":"2025-10-27T17:39:36.726328Z","price_level":"4219.98","new_quantity":"3.61603384"},{"side":"offer","event_time":"2025-10-27T17:39:36.726328Z","price_level":"4220","new_quantity":"12.20517286"},{"side":"offer","event_time":"2025-10-27T17:39:36.726328Z","price_level":"4220.26","new_quantity":"0"},{"side":"offer","event_time":"2025-10-27T17:39:36.726328Z","price_level":"4220.49","new_quantity":"5.92349217"},{"side":"offer","event_time":"2025-10-27T17:39:36.726328Z","price_level":"4221.32","new_quantity":"1.94391607"},{"side":"offer","event_time":"2025-10-27T17:39:36.726328Z","price_level":"4221.33","new_quantity":"0"},{"side":"offer","event_time":"2025-10-27T17:39:36.726328Z","price_level":"4221.34","new_quantity":"0"},{"side":"offer","event_time":"2025-10-27T17:39:36.726328Z","price_level":"4221.36","new_quantity":"0"},{"side":"offer","event_time":"2025-10-27T17:39:36.726328Z","price_level":"4221.51","new_quantity":"13.41692088"},{"side":"offer","event_time":"2025-10-27T17:39:36.726328Z","price_level":"4221.68","new_quantity":"0.09871233"},{"side":"offer","event_time":"2025-10-27T17:39:36.726328Z","price_level":"4222.43","new_quantity":"0"},{"side":"offer","event_time":"2025-10-27T17:39:36.726328Z","price_level":"4222.59","new_quantity":"0"},{"side":"offer","event_time":"2025-10-27T17:39:36.726328Z","price_level":"4222.82","new_quantity":"9.52673173"},{"side":"offer","event_time":"2025-10-27T17:39:36.726328Z","price_level":"4232.72","new_quantity":"1.125"}]}]}
{"channel":"l2_data","client_id":"","timestamp":"2025-10-27T17:39:36.821990716Z","sequence_num":137430,"events":[{"type":"update","product_id":"ETH-USD","updates":[{"side":"bid","event_time":"2025-10-27T17:39:36.761677Z","price_level":"4218.45","new_quantity":"1.43810728"},{"side":"bid","event_time":"2025-10-27T17:39:36.761677Z","price_level":"4218.42","new_quantity":"0.01376781"},{"side":"bid","event_time":"2025-10-27T17:39:36.761677Z","price_level":"4218.41","new_quantity":"0.619686"},{"side":"bid","event_time":"2025-10-27T17:39:36.761677Z","price_level":"4218.4","new_quantity":"0.519"},{"side":"bid","event_time":"2025-10-27T17:39:36.761677Z","price_level":"4218.3","new_quantity":"0.519"},{"side":"bid","event_time":"2025-10-27T17:39:36.761677Z","price_level":"4218.2","new_quantity":"20"},{"side":"bid","event_time":"2025-10-27T17:39:36.761677Z","price_level":"4218.06","new_quantity":"3.99981902"},{"side":"bid","event_time":"2025-10-27T17:39:36.761677Z","price_level":"4218.05","new_quantity":"1.60190614"},{"side":"bid","event_time":"2025-10-27T17:39:36.761677Z","price_level":"4218.01","new_quantity":"0"},{"side":"bid","event_time":"2025-10-27T17:39:36.761677Z","price_level":"4218","new_quantity":"10.519"},{"side":"bid","event_time":"2025-10-27T17:39:36.761677Z","price_level":"4217.98","new_quantity":"0"},{"side":"bid","event_time":"2025-10-27T17:39:36.761677Z","price_level":"4217.94","new_quantity":"3.30108"},{"side":"bid","event_time":"2025-10-27T17:39:36.761677Z","price_level":"4217.91","new_quantity":"0.00237085"},{"side":"bid","event_time":"2025-10-27T17:39:36.761677Z","price_level":"4217.82","new_quantity":"0.02218922"},{"side":"bid","event_time":"2025-10-27T17:39:36.761677Z","price_level":"4217.81","new_quantity":"14.22314852"},{"side":"bid","event_time":"2025-10-27T17:39:36.761677Z","price_level":"4217.8","new_quantity":"0.519"},{"side":"bid","event_time":"2025-10-27T17:39:36.761677Z","price_level":"4217.78","new_quantity":"0.59272776"},{"side":"bid","event_time":"2025-10-27T17:39:36.761677Z","price_level":"4217.76","new_quantity":"0"},{"side":"bid","event_time":"2025-10-27T17:39:36.761677Z","price_level":"4217.72","new_quantity":"0.437"},{"side":"bid","event_time":"2025-10-27T17:39:36.761677Z","price_level":"4217.37","new_quantity":"0"},{"side":"bid","event_time":"2025-10-27T17:39:36.761677Z","price_level":"4217.18","new_quantity":"0.21565049"},{"side":"bid","event_time":"2025-10-27T17:39:36.761677Z","price_level":"4216.82","new_quantity":"3.975"},{"side":"bid","event_time":"2025-10-27T17:39:36.761677Z","price_level":"4216.73","new_quantity":"0.194152"},{"side":"bid","event_time":"2025-10-27T17:39:36.761677Z","price_level":"4211.48","new_quantity":"0.0050201"},{"side":"bid","event_time":"2025-10-27T17:39:36.761677Z","price_level":"4210.77","new_quantity":"0"},{"side":"bid","event_time":"2025-10-27T17:39:36.761677Z","price_level":"4210.05","new_quantity":"0"},{"side":"offer","event_time":"2025-10-27T17:39:36.761677Z","price_level":"4218.58","new_quantity":"0.09932715"},{"side":"offer","event_time":"2025-10-27T17:39:36.761677Z","price_level":"4218.6","new_quantity":"0"},{"side":"offer","event_time":"2025-10-27T17:39:36.761677Z","price_level":"4218.67","new_quantity":"0.07309618"},{"side":"offer","event_time":"2025-10-27T17:39:36.761677Z","price_level":"4218.7","new_quantity":"0"},{"side":"offer","event_time":"2025-10-27T17:39:36.761677Z","price_level":"4218.74","new_quantity":"0.11851906"},{"side":"offer","event_time":"2025-10-27T17:39:36.761677Z","price_level":"4218.78","new_quantity":"0.59258934"},{"side":"offer","event_time":"2025-10-27T17:39:36.761677Z","price_level":"4218.99","new_quantity":"0"},{"side":"offer","event_time":"2025-10-27T17:39:36.761677Z","price_level":"4219.11","new_quantity":"0.01434418"},{"side":"offer","event_time":"2025-10-27T17:39:36.761677Z","price_level":"4219.32","new_quantity":"2.26214653"},{"side":"offer","event_time":"2025-10-27T17:39:36.761677Z","price_level":"4219.4","new_quantity":"0"},{"side":"offer","event_time":"2025-10-27T17:39:36.761677Z","price_level":"4219.42","new_quantity":"0"},{"side":"offer","event_time":"2025-10-27T17:39:36.761677Z","price_level":"4219.48","new_quantity":"1.63864"},{"side":"offer","event_time":"2025-10-27T17:39:36.761677Z","price_level":"4219.5","new_quantity":"0.001"},{"side":"offer","event_time":"2025-10-27T17:39:36.761677Z","price_level":"4219.8","new_quantity":"0"},{"side":"offer","event_time":"2025-10-27T17:39:36.761677Z","price_level":"4220.44","new_quantity":"0.09965802"},{"side":"offer","event_time":"2025-10-27T17:39:36.761677Z","price_level":"4220.67","new_quantity":"8.5438493"},{"side":"offer","event_time":"2025-10-27T17:39:36.761677Z","price_level":"4220.7","new_quantity":"0.00955168"},{"side":"offer","event_time":"2025-10-27T17:39:36.761677Z","price_level":"4220.79","new_quantity":"0.00221161"},{"side":"offer","event_time":"2025-10-27T17:39:36.761677Z","price_level":"4221.04","new_quantity":"0"},{"side":"offer","event_time":"2025-10-27T17:39:36.761677Z","price_level":"4221.97","new_quantity":"1.125"},{"side":"offer","event_time":"2025-10-27T17:39:36.761677Z","price_level":"4222.22","new_quantity":"3.384883"}]}]}
{"channel":"l2_data","client_id":"","timestamp":"2025-10-27T17:39:36.972272077Z","sequence_num":137436,"events":[{"type":"update","product_id":"ETH-USD","updates":[{"side":"bid","event_time":"2025-10-27T17:39:36.924933Z","price_level":"4218.45","new_quantity":"1.43810728"},{"side":"bid","event_time":"2025-10-27T17:39:36.924933Z","price_level":"4218.42","new_quantity":"0"},{"side":"bid","event_time":"2025-10-27T17:39:36.924933Z","price_level":"4218.41","new_quantity":"0"},{"side":"bid","event_time":"2025-10-27T17:39:36.924933Z","price_level":"4218.4","new_quantity":"30.519"},{"side":"bid","event_time":"2025-10-27T17:39:36.924933Z","price_level":"4218.2","new_quantity":"20"},{"side":"bid","event_time":"2025-10-27T17:39:36.924933Z","price_level":"4218.03","new_quantity":"0.00237078"},{"side":"bid","event_time":"2025-10-27T17:39:36.924933Z","price_level":"4218.02","new_quantity":"1.125"},{"side":"bid","event_time":"2025-10-27T17:39:36.924933Z","price_level":"4218.01","new_quantity":"9.51124677"},{"side":"bid","event_time":"2025-10-27T17:39:36.924933Z","price_level":"4218","new_quantity":"10.956"},{"side":"bid","event_time":"2025-10-27T17:39:36.924933Z","price_level":"4217.79","new_quantity":"0"},{"side":"bid","event_time":"2025-10-27T17:39:36.924933Z","price_level":"4217.72","new_quantity":"0"},{"side":"bid","event_time":"2025-10-27T17:39:36.924933Z","price_level":"4217.71","new_quantity":"6.3282"},{"side":"bid","event_time":"2025-10-27T17:39:36.924933Z","price_level":"4217.58","new_quantity":"0.147"},{"side":"bid","event_time":"2025-10-27T17:39:36.924933Z","price_level":"4217.24","new_quantity":"1.62084789"},{"side":"bid","event_time":"2025-10-27T17:39:36.924933Z","price_level":"4211.72","new_quantity":"0"},{"side":"bid","event_time":"2025-10-27T17:39:36.924933Z","price_level":"4201.38","new_quantity":"1.24877715"},{"side":"offer","event_time":"2025-10-27T17:39:36.924933Z","price_level":"4218.97","new_quantity":"0.69202947"},{"side":"offer","event_time":"2025-10-27T17:39:36.924933Z","price_level":"4219.11","new_quantity":"0.437"},{"side":"offer","event_time":"2025-10-27T17:39:36.924933Z","price_level":"4219.57","new_quantity":"1.65010537"},{"side":"offer","event_time":"2025-10-27T17:39:36.924933Z","price_level":"4219.59","new_quantity":"0"},{"side":"offer","event_time":"2025-10-27T17:39:36.924933Z","price_level":"4219.71","new_quantity":"0"},{"side":"offer","event_time":"2025-10-27T17:39:36.924933Z","price_level":"4220.1","new_quantity":"10"},{"side":"offer","event_time":"2025-10-27T17:39:36.924933Z","price_level":"4220.83","new_quantity":"8.37915125"},{"side":"offer","event_time":"2025-10-27T17:39:36.924933Z","price_level":"4221.85","new_quantity":"13.72236588"},{"side":"offer","event_time":"2025-10-27T17:39:36.924933Z","price_level":"4221.87","new_quantity":"0"}]}]}
{"channel":"l2_data","client_id":"","timestamp":"2025-10-27T17:39:37.057514013Z","sequence_num":137437,"events":[{"type":"update","product_id":"ETH-USD","updates":[{"side":"bid","event_time":"2025-10-27T17:39:36.97588Z","price_level":"4218.21","new_quantity":"0.00237068"},{"side":"bid","event_time":"2025-10-27T17:39:36.97588Z","price_level":"4218.03","new_quantity":"0"},{"side":"bid","event_time":"2025-10-27T17:39:36.97588Z","price_level":"4217.34","new_quantity":"0"},{"side":"bid","event_time":"2025-10-27T17:39:36.97588Z","price_level":"4216.82","new_quantity":"0"},{"side":"bid","event_time":"2025-10-27T17:39:36.97588Z","price_level":"4215.65","new_quantity":"0"},{"side":"offer","event_time":"2025-10-27T17:39:36.97588Z","price_level":"4218.46","new_quantity":"0.09269416"},{"side":"offer","event_time":"2025-10-27T17:39:36.97588Z","price_level":"4219.31","new_quantity":"0.01434418"},{"side":"offer","event_time":"2025-10-27T17:39:36.97588Z","price_level":"4219.48","new_quantity":"0"},{"side":"offer","event_time":"2025-10-27T17:39:36.97588Z","price_level":"4220","new_quantity":"12.80517286"},{"side":"offer","event_time":"2025-10-27T17:39:36.97588Z","price_level":"4220.1","new_quantity":"0"},{"side":"offer","event_time":"2025-10-27T17:39:36.97588Z","price_level":"4220.99","new_quantity":"0.13679195"},{"side":"offer","event_time":"2025-10-27T17:39:36.97588Z","price_level":"4718.97","new_quantity":"0.1381"}]}]}
{"channel":"l2_data","client_id":"","timestamp":"2025-10-27T17:39:37.077570386Z","sequence_num":137438,"events":[{"type":"update","product_id":"ETH-USD","updates":[{"side":"bid","event_time":"2025-10-27T17:39:37.023238Z","price_level":"4218.41","new_quantity":"24.499686"},{"side":"bid","event_time":"2025-10-27T17:39:37.023238Z","price_level":"4218.21","new_quantity":"3.12055387"},{"side":"bid","event_time":"2025-10-27T17:39:37.023238Z","price_level":"4218.02","new_quantity":"1.12737079"},{"side":"bid","event_time":"2025-10-27T17:39:37.023238Z","price_level":"4217.82","new_quantity":"0"},{"side":"bid","event_time":"2025-10-27T17:39:37.023238Z","price_level":"4217.11","new_quantity":"0.02370696"},{"side":"bid","event_time":"2025-10-27T17:39:37.023238Z","price_level":"4215.42","new_quantity":"0.11853481"},{"side":"bid","event_time":"2025-10-27T17:39:37.023238Z","price_level":"4212.01","new_quantity":"1.90398068"},{"side":"bid","event_time":"2025-10-27T17:39:37.023238Z","price_level":"4211.85","new_quantity":"0"},{"side":"offer","event_time":"2025-10-27T17:39:37.023238Z","price_level":"4220","new_quantity":"22.80517286"},{"side":"offer","event_time":"2025-10-27T17:39:37.023238Z","price_level":"4220.4","new_quantity":"0"}]}]}
{"channel":"l2_data","client_id":"","timestamp":"2025-10-27T17:39:37.12113534Z","sequence_num":137441,"events":[{"type":"update","product_id":"ETH-USD","updates":[{"side":"bid","event_time":"2025-10-27T17:39:37.061597Z","price_level":"4218.45","new_quantity":"1.12538728"},{"side":"bid","event_time":"2025-10-27T17:39:37.061597Z","price_level":"4217.66","new_quantity":"0.602"},{"side":"offer","event_time":"2025-10-27T17:39:37.061597Z","price_level":"4218.97","new_quantity":"0.59256183"},{"side":"offer","event_time":"2025-10-27T17:39:37.061597Z","price_level":"4219.32","new_quantity":"1.10018089"},{"side":"offer","event_time":"2025-10-27T17:39:37.061597Z","price_level":"4219.73","new_quantity":"0.102891"},{"side":"offer","event_time":"2025-10-27T17:39:37.061597Z","price_level":"4220.04","new_quantity":"0"},{"side":"offer","event_time":"2025-10-27T17:39:37.061597Z","price_level":"4220.14","new_quantity":"0"},{"side":"offer","event_time":"2025-10-27T17:39:37.061597Z","price_level":"4220.2","new_quantity":"20"}]}]}
{"channel":"l2_data","client_id":"","timestamp":"2025-10-27T17:39:37.171589751Z","sequence_num":137443,"events":[{"type":"update","product_id":"ETH-USD","updates":[{"side":"bid","event_time":"2025-10-27T17:39:37.094177Z","price_level":"4218.21","new_quantity":"0"},{"side":"bid","event_time":"2025-10-27T17:39:37.094177Z","price_level":"4218.2","new_quantity":"0"},{"side":"offer","event_time":"2025-10-27T17:39:37.094177Z","price_level":"4219.32","new_quantity":"0.52219159"},{"side":"offer","event_time":"2025-10-27T17:39:37.094177Z","price_level":"4219.52","new_quantity":"0.64"},{"side":"offer","event_time":"2025-10-27T17:39:37.094177Z","price_level":"4244.82","new_quantity":"0.1536"}]}]}
{"channel":"l2_data","client_id":"","timestamp":"2025-10-27T17:39:37.369966349Z","sequence_num":137445,"events":[{"type":"update","product_id":"ETH-USD","updates":[{"side":"offer","event_time":"2025-10-27T17:39:37.114136Z","price_level":"4219.83","new_quantity":"0.93111026"}]}]}
{"channel":"l2_data","client_id":"","timestamp":"2025-10-27T17:39:37.422466924Z","sequence_num":137446,"events":[{"type":"update","product_id":"ETH-USD","updates":[{"side":"bid","event_time":"2025-10-27T17:39:37.372073Z","price_level":"4218.45","new_quantity":"1.12537949"},{"side":"bid","event_time":"2025-10-27T17:39:37.372073Z","price_level":"4218.41","new_quantity":"0"},{"side":"bid","event_time":"2025-10-27T17:39:37.372073Z","price_level":"4218.24","new_quantity":"0"},{"side":"bid","event_time":"2025-10-27T17:39:37.372073Z","price_level":"4218.22","new_quantity":"0.00237067"},{"side":"bid","event_time":"2025-10-27T17:39:37.372073Z","price_level":"4218.21","new_quantity":"11.94"},{"side":"bid","event_time":"2025-10-27T17:39:37.372073Z","price_level":"4218.2","new_quantity":"20"},{"side":"bid","event_time":"2025-10-27T17:39:37.372073Z","price_level":"4218.11","new_quantity":"0.11853632"},{"side":"bid","event_time":"2025-10-27T17:39:37.372073Z","price_level":"4218.02","new_quantity":"1.125"},{"side":"bid","event_time":"2025-10-27T17:39:37.372073Z","price_level":"4217.94","new_quantity":"1.65158"},{"side":"bid","event_time":"2025-10-27T17:39:37.372073Z","price_level":"4217.74","new_quantity":"1.65371"},{"side":"bid","event_time":"2025-10-27T17:39:37.372073Z","price_level":"4216.94","new_quantity":"2.37061879"},{"side":"bid","event_time":"2025-10-27T17:39:37.372073Z","price_level":"4199.2","new_quantity":"0"},{"side":"bid","event_time":"2025-10-27T17:39:37.372073Z","price_level":"4170.52","new_quantity":"0.3836455"},{"side":"bid","event_time":"2025-10-27T17:39:37.372073Z","price_level":"4150.57","new_quantity":"0.57851942"},{"side":"bid","event_time":"2025-10-27T17:39:37.372073Z","price_level":"4130.63","new_quantity":"0.7747008"},{"side":"offer","event_time":"2025-10-27T17:39:37.372073Z","price_level":"4218.62","new_quantity":"0.09477157"},{"side":"offer","event_time":"2025-10-27T17:39:37.372073Z","price_level":"4218.7","new_quantity":"0.519"},{"side":"offer","event_time":"2025-10-27T17:39:37.372073Z","price_level":"4218.74","new_quantity":"0"},{"side":"offer","event_time":"2025-10-27T17:39:37.372073Z","price_level":"4218.95","new_quantity":"0.01922344"},{"side":"offer","event_time":"2025-10-27T17:39:37.372073Z","price_level":"4218.96","new_quantity":"0.88318511"},{"side":"offer","event_time":"2025-10-27T17:39:37.372073Z","price_level":"4218.98","new_quantity":"0.4632786"},{"side":"offer","event_time":"2025-10-27T17:39:37.372073Z","price_level":"4219","new_quantity":"0.50747003"},{"side":"offer","event_time":"2025-10-27T17:39:37.372073Z","price_level":"4219.04","new_quantity":"0.09932715"},{"side":"offer","event_time":"2025-10-27T17:39:37.372073Z","price_level":"4219.31","new_quantity":"0"},{"side":"offer","event_time":"2025-10-27T17:39:37.372073Z","price_level":"4219.32","new_quantity":"0"},{"side":"offer","event_time":"2025-10-27T17:39:37.372073Z","price_level":"4219.34","new_quantity":"0"},{"side":"offer","event_time":"2025-10-27T17:39:37.372073Z","price_level":"4219.39","new_quantity":"0.194152"},{"side":"offer","event_time":"2025-10-27T17:39:37.372073Z","price_level":"4219.45","new_quantity":"1.30108005"},{"side":"offer","event_time":"2025-10-27T17:39:37.372073Z","price_level":"4219.46","new_quantity":"1.63864"},{"side":"offer","event_time":"2025-10-27T17:39:37.372073Z","price_level":"4219.49","new_quantity":"0.53972356"},{"side":"offer","event_time":"2025-10-27T17:39:37.372073Z","price_level":"4219.52","new_quantity":"0"},{"side":"offer","event_time":"2025-10-27T17:39:37.372073Z","price_level":"4244.82","new_quantity":"0"},{"side":"offer","event_time":"2025-10-27T17:39:37.372073Z","price_level":"4272.99","new_quantity":"5.32322313"}]}]}
{"channel":"l2_data","client_id":"","timestamp":"2025-10-27T17:39:37.469199914Z","sequence_num":137448,"events":[{"type":"update","product_id":"ETH-USD","updates":[{"side":"offer","event_time":"2025-10-27T17:39:37.429592Z","price_level":"4218.7","new_quantity":"0"},{"side":"offer","event_time":"2025-10-27T17:39:37.429592Z","price_level":"4219.57","new_quantity":"0"},{"side":"offer","event_time":"2025-10-27T17:39:37.429592Z","price_level":"4219.58","new_quantity":"0"},{"side":"offer","event_time":"2025-10-27T17:39:37.429592Z","price_level":"4272.99","new_quantity":"5.27052545"}]}]}
r","event_time":"2025-10-27T17:39:36.814499Z","price_level":"4219.71","new_quantity":"1.63864"},{"side":"offer","event_time":"2025-10-27T17:39:36.814499Z","price_level":"4219.82","new_quantity":"1.4"},{"side":"offer","event_time":"2025-10-27T17:39:36.814499Z","price_level":"4219.88","new_quantity":"0.6"},{"side":"offer","event_time":"2025-10-27T17:39:36.814499Z","price_level":"4219.98","new_quantity":"4.15848684"},{"side":"offer","event_time":"2025-10-27T17:39:36.814499Z","price_level":"4220.04","new_quantity":"0.102891"},{"side":"offer","event_time":"2025-10-27T17:39:36.814499Z","price_level":"4220.5","new_quantity":"10.10081343"},{"side":"offer","event_time":"2025-10-27T17:39:36.814499Z","price_level":"4220.6","new_quantity":"0"},{"side":"offer","event_time":"2025-10-27T17:39:36.814499Z","price_level":"4220.84","new_quantity":"1.25916482"},{"side":"offer","event_time":"2025-10-27T17:39:36.814499Z","price_level":"4221.32","new_quantity":"0"},{"side":"offer","event_time":"2025-10-27T17:39:36.814499Z","price_level":"4221.37","new_quantity":"0.14427361"},{"side":"offer","event_time":"2025-10-27T17:39:36.814499Z","price_level":"4221.51","new_quantity":"0"},{"side":"offer","event_time":"2025-10-27T17:39:36.814499Z","price_level":"4221.68","new_quantity":"2.0426284"},{"side":"offer","event_time":"2025-10-27T17:39:36.814499Z","price_level":"4221.87","new_quantity":"13.41577681"},{"side":"offer","event_time":"2025-10-27T17:39:36.814499Z","price_level":"4222","new_quantity":"0.39505286"},{"side":"offer","event_time":"2025-10-27T17:39:36.814499Z","price_level":"4222.13","new_quantity":"4.00815796"},{"side":"offer","event_time":"2025-10-27T17:39:36.814499Z","price_level":"4222.22","new_quantity":"0"},{"side":"offer","event_time":"2025-10-27T17:39:36.814499Z","price_level":"4222.78","new_quantity":"0.47336439"},{"side":"offer","event_time":"2025-10-27T17:39:36.814499Z","price_level":"4222.82","new_quantity":"0"},{"side":"offer","event_time":"2025-10-27T17:39:36.814499Z","price_level":"4222.89","new_quantity":"1.35243588"},{"side":"offer","event_time":"2025-10-27T17:39:36.814499Z","price_level":"4223.22","new_quantity":"9.52582941"},{"side":"offer","event_time":"2025-10-27T17:39:36.814499Z","price_level":"4223.33","new_quantity":"0.47355996"},{"side":"offer","event_time":"2025-10-27T17:39:36.814499Z","price_level":"4223.47","new_quantity":"0.569123"},{"side":"offer","event_time":"2025-10-27T17:39:36.814499Z","price_level":"4224.53","new_quantity":"4.7337874"},{"side":"offer","event_time":"2025-10-27T17:39:36.814499Z","price_level":"4225.52","new_quantity":"0"},{"side":"offer","event_time":"2025-10-27T17:39:36.814499Z","price_level":"4225.69","new_quantity":"0.28155516"},{"side":"offer","event_time":"2025-10-27T17:39:36.814499Z","price_level":"4226.08","new_quantity":"0.82819066"},{"side":"offer","event_time":"2025-10-27T17:39:36.814499Z","price_level":"4244.24","new_quantity":"0"}]}]}
{"channel":"l2_data","client_id":"","timestamp":"2025-10-27T17:39:36.921415736Z","sequence_num":137435,"events":[{"type":"update","product_id":"ETH-USD","updates":[{"side":"bid","event_time":"2025-10-27T17:39:36.865105Z","price_level":"4218.45","new_quantity":"2.56310728"},{"side":"bid","event_time":"2025-10-27T17:39:36.865105Z","price_level":"4218.3","new_quantity":"10.519"},{"side":"bid","event_time":"2025-10-27T17:39:36.865105Z","price_level":"4218.2","new_quantity":"0"},{"side":"bid","event_time":"2025-10-27T17:39:36.865105Z","price_level":"4218.05","new_quantity":"0.47690614"},{"side":"bid","event_time":"2025-10-27T17:39:36.865105Z","price_level":"4217.94","new_quantity":"3.30308"},{"side":"bid","event_time":"2025-10-27T17:39:36.865105Z","price_level":"4217.66","new_quantity":"0.6"},{"side":"bid","event_time":"2025-10-27T17:39:36.865105Z","price_level":"4217.5","new_quantity":"10.001"},{"side":"offer","event_time":"2025-10-27T17:39:36.865105Z","price_level":"4218.8","new_quantity":"0"},{"side":"offer","event_time":"2025-10-27T17:39:36.865105Z","price_level":"4219.11","new_quantity":"0"},{"side":"offer","event_time":"2025-10-27T17:39:36.865105Z","price_level":"4219.32","new_quantity":"0.5779893"},{"side":"offer","event_time":"2025-10-27T17:39:36.865105Z","price_level":"4219.34","new_quantity":"0.48221898"},{"side":"offer","event_time":"2025-10-27T17:39:36.865105Z","price_level":"4219.45","new_quantity":"0"},{"side":"offer","event_time":"2025-10-27T17:39:36.865105Z","price_level":"4219.48","new_quantity":"0.01434418"},{"side":"offer","event_time":"2025-10-27T17:39:36.865105Z","price_level":"4219.58","new_quantity":"1.63864"},{"side":"offer","event_time":"2025-10-27T17:39:36.865105Z","price_level":"4219.6","new_quantity":"0"},{"side":"offer","event_time":"2025-10-27T17:39:36.865105Z","price_level":"4219.88","new_quantity":"0"},{"side":"offer","event_time":"2025-10-27T17:39:36.865105Z","price_level":"4219.98","new_quantity":"3.61603384"},{"side":"offer","event_time":"2025-10-27T17:39:36.865105Z","price_level":"4220","new_quantity":"12.20517286"},{"side":"offer","event_time":"2025-10-27T17:39:36.865105Z","price_level":"4220.14","new_quantity":"0.54649206"},{"side":"offer","event_time":"2025-10-27T17:39:36.865105Z","price_level":"4220.4","new_quantity":"20"},{"side":"offer","event_time":"2025-10-27T17:39:36.865105Z","price_level":"4220.42","new_quantity":"0"},{"side":"offer","event_time":"2025-10-27T17:39:36.865105Z","price_level":"4220.67","new_quantity":"0.00886424"},{"side":"offer","event_time":"2025-10-27T17:39:36.865105Z","price_level":"4221.37","new_quantity":"0"},{"side":"offer","event_time":"2025-10-27T17:39:36.865105Z","price_level":"4221.81","new_quantity":"0.14427361"}]}]}
{"channel":"l2_data","client_id":"","timestamp":"2025-10-27T17:39:37.503929159Z","sequence_num":137450,"events":[{"type":"update","product_id":"BTC-USD","updates":[{"side":"bid","event_time":"2025-10-27T17:39:36.782801Z","price_level":"115657.75","new_quantity":"0.00008647"},{"side":"bid","event_time":"2025-10-27T17:39:36.782801Z","price_level":"115657.17","new_quantity":"0.00190217"},{"side":"bid","event_time":"2025-10-27T17:39:36.782801Z","price_level":"115652.01","new_quantity":"0.19107453"},{"side":"bid","event_time":"2025-10-27T17:39:36.782801Z","price_level":"115650.63","new_quantity":"0.0216084"},{"side":"bid","event_time":"2025-10-27T17:39:36.782801Z","price_level":"115650.37","new_quantity":"0.16746"},{"side":"bid","event_time":"2025-10-27T17:39:36.782801Z","price_level":"115644.48","new_quantity":"0.00432"},{"side":"bid","event_time":"2025-10-27T17:39:36.782801Z","price_level":"115641.23","new_quantity":"0"},{"side":"bid","event_time":"2025-10-27T17:39:36.782801Z","price_level":"115638.29","new_quantity":"0.62104709"},{"side":"bid","event_time":"2025-10-27T17:39:36.782801Z","price_level":"115637","new_quantity":"0.4"},{"side":"bid","event_time":"2025-10-27T17:39:36.782801Z","price_level":"115633","new_quantity":"0.4"},{"side":"bid","event_time":"2025-10-27T17:39:36.782801Z","price_level":"115632.98","new_quantity":"2.50519815"},{"side":"bid","event_time":"2025-10-27T17:39:36.782801Z","price_level":"115625.01","new_quantity":"0.36901662"},{"side":"bid","event_time":"2025-10-27T17:39:36.782801Z","price_level":"115620.65","new_quantity":"0.52628515"},{"side":"bid","event_time":"2025-10-27T17:39:36.782801Z","price_level":"115620","new_quantity":"1"},{"side":"bid","event_time":"2025-10-27T17:39:36.782801Z","price_level":"115612.94","new_quantity":"0"},{"side":"bid","event_time":"2025-10-27T17:39:36.782801Z","price_level":"115601.41","new_quantity":"0.06482518"},{"side":"bid","event_time":"2025-10-27T17:39:36.782801Z","price_level":"115593.58","new_quantity":"0"},{"side":"bid","event_time":"2025-10-27T17:39:36.782801Z","price_level":"115589.4","new_quantity":"0"},{"side":"bid","event_time":"2025-10-27T17:39:36.782801Z","price_level":"115584.1","new_quantity":"1.5"},{"side":"bid","event_time":"2025-10-27T17:39:36.782801Z","price_level":"115576.69","new_quantity":"1.20613066"},{"side":"bid","event_time":"2025-10-27T17:39:36.782801Z","price_level":"115567.37","new_quantity":"0"},{"side":"offer","event_time":"2025-10-27T17:39:36.782801Z","price_level":"115689.72","new_quantity":"0.4620573"},{"side":"offer","event_time":"2025-10-27T17:39:36.782801Z","price_level":"115689.99","new_quantity":"0"},{"side":"offer","event_time":"2025-10-27T17:39:36.782801Z","price_level":"115696.99","new_quantity":"0.2388"},{"side":"offer","event_time":"2025-10-27T17:39:36.782801Z","price_level":"115697","new_quantity":"0.4"},{"side":"offer","event_time":"2025-10-27T17:39:36.782801Z","price_level":"115700","new_quantity":"1"},{"side":"offer","event_time":"2025-10-27T17:39:36.782801Z","price_level":"115742.1","new_quantity":"0"},{"side":"offer","event_time":"2025-10-27T17:39:36.782801Z","price_level":"115743.9","new_quantity":"0"},{"side":"offer","event_time":"2025-10-27T17:39:36.782801Z","price_level":"115748","new_quantity":"1"},{"side":"offer","event_time":"2025-10-27T17:39:36.782801Z","price_level":"115749.57","new_quantity":"0.57736879"}]}]}
{"channel":"l2_data","client_id":"","timestamp":"2025-10-27T17:39:37.503340247Z","sequence_num":137449,"events":[{"type":"update","product_id":"BTC-USD","updates":[{"side":"bid","event_time":"2025-10-27T17:39:36.754668Z","price_level":"115666","new_quantity":"0.0249"},{"side":"bid","event_time":"2025-10-27T17:39:36.754668Z","price_level":"115664","new_quantity":"0.0249"},{"side":"bid","event_time":"2025-10-27T17:39:36.754668Z","price_level":"115663.03","new_quantity":"0"},{"side":"bid","event_time":"2025-10-27T17:39:36.754668Z","price_level":"115663.02","new_quantity":"0.00664793"},{"side":"bid","event_time":"2025-10-27T17:39:36.754668Z","price_level":"115662.01","new_quantity":"0.01067084"},{"side":"bid","event_time":"2025-10-27T17:39:36.754668Z","price_level":"115662","new_quantity":"0.0249"},{"side":"bid","event_time":"2025-10-27T17:39:36.754668Z","price_level":"115660","new_quantity":"0.0249"},{"side":"bid","event_time":"2025-10-27T17:39:36.754668Z","price_level":"115657.75","new_quantity":"0"},{"side":"bid","event_time":"2025-10-27T17:39:36.754668Z","price_level":"115657.74","new_quantity":"0.05980929"},{"side":"bid","event_time":"2025-10-27T17:39:36.754668Z","price_level":"115657.17","new_quantity":"0.00181571"},{"side":"bid","event_time":"2025-10-27T17:39:36.754668Z","price_level":"115657.16","new_quantity":"0.01324363"},{"side":"bid","event_time":"2025-10-27T17:39:36.754668Z","price_level":"115652.01","new_quantity":"0.07715891"},{"side":"bid","event_time":"2025-10-27T17:39:36.754668Z","price_level":"115651.55","new_quantity":"0.00864666"},{"side":"bid","event_time":"2025-10-27T17:39:36.754668Z","price_level":"115650.7","new_quantity":"0.08646726"},{"side":"bid","event_time":"2025-10-27T17:39:36.754668Z","price_level":"115650.01","new_quantity":"0"},{"side":"bid","event_time":"2025-10-27T17:39:36.754668Z","price_level":"115648.49","new_quantity":"0"},{"side":"bid","event_time":"2025-10-27T17:39:36.754668Z","price_level":"115646.4","new_quantity":"0.00183031"},{"side":"bid","event_time":"2025-10-27T17:39:36.754668Z","price_level":"115645.66","new_quantity":"0"},{"side":"bid","event_time":"2025-10-27T17:39:36.754668Z","price_level":"115645.6","new_quantity":"0.47386655"},{"side":"bid","event_time":"2025-10-27T17:39:36.754668Z","price_level":"115644.51","new_quantity":"0.00432"},{"side":"bid","event_time":"2025-10-27T17:39:36.754668Z","price_level":"115644.48","new_quantity":"0.00432"},{"side":"bid","event_time":"2025-10-27T17:39:36.754668Z","price_level":"115644.3","new_quantity":"0.16746"},{"side":"bid","event_time":"2025-10-27T17:39:36.754668Z","price_level":"115642.19","new_quantity":"0.00432"},{"side":"bid","event_time":"2025-10-27T17:39:36.754668Z","price_level":"115642.16","new_quantity":"0.00432"},{"side":"bid","event_time":"2025-10-27T17:39:36.754668Z","price_level":"115639.87","new_quantity":"0"},{"side":"bid","event_time":"2025-10-27T17:39:36.754668Z","price_level":"115639.84","new_quantity":"0"},{"side":"bid","event_time":"2025-10-27T17:39:36.754668Z","price_level":"115638.29","new_quantity":"0.43828037"},{"side":"bid","event_time":"2025-10-27T17:39:36.754668Z","price_level":"115637.55","new_quantity":"0"},{"side":"bid","event_time":"2025-10-27T17:39:36.754668Z","price_level":"115637.52","new_quantity":"0"},{"side":"bid","event_time":"2025-10-27T17:39:36.754668Z","price_level":"115636.63","new_quantity":"0"},{"side":"bid","event_time":"2025-10-27T17:39:36.754668Z","price_level":"115636.21","new_quantity":"0.646708"},{"side":"bid","event_time":"2025-10-27T17:39:36.754668Z","price_level":"115635","new_quantity":"0"},{"side":"bid","event_time":"2025-10-27T17:39:36.754668Z","price_level":"115632.98","new_quantity":"1.50340755"},{"side":"bid","event_time":"2025-10-27T17:39:36.754668Z","price_level":"115631","new_quantity":"0"},{"side":"bid","event_time":"2025-10-27T17:39:36.754668Z","price_level":"115630","new_quantity":"2"},{"side":"bid","event_time":"2025-10-27T17:39:36.754668Z","price_level":"115625.38","new_quantity":"0.07007"},{"side":"bid","event_time":"2025-10-27T17:39:36.754668Z","price_level":"115623.01","new_quantity":"0"},{"side":"bid","event_time":"2025-10-27T17:39:36.754668Z","price_level":"115622.53","new_quantity":"0"},{"side":"bid","event_time":"2025-10-27T17:39:36.754668Z","price_level":"115621.91","new_quantity":"0"},{"side":"bid","event_time":"2025-10-27T17:39:36.754668Z","price_level":"115620.01","new_quantity":"0"},{"side":"bid","event_time":"2025-10-27T17:39:36.754668Z","price_level":"115620","new_quantity":"0"},{"side":"bid","event_time":"2025-10-27T17:39:36.754668Z","price_level":"115589.4","new_quantity":"1.5"},{"side":"bid","event_time":"2025-10-27T17:39:36.754668Z","price_level":"115588.8","new_quantity":"0"},{"side":"bid","event_time":"2025-10-27T17:39:36.754668Z","price_level":"115579.21","new_quantity":"0"},{"side":"bid","event_time":"2025-10-27T17:39:36.754668Z","price_level":"115511.8","new_quantity":"0.04128788"},{"side":"bid","event_time":"2025-10-27T17:39:36.754668Z","price_level":"115511.79","new_quantity":"0"},{"side":"bid","event_time":"2025-10-27T17:39:36.754668Z","price_level":"114933.48","new_quantity":"0.045"},{"side":"bid","event_time":"2025-10-27T17:39:36.754668Z","price_level":"101782.56","new_quantity":"0"},{"side":"bid","event_time":"2025-10-27T17:39:36.754668Z","price_level":"101200.02","new_quantity":"0"},{"side":"offer","event_time":"2025-10-27T17:39:36.754668Z","price_level":"115657.17","new_quantity":"0"},{"side":"offer","event_time":"2025-10-27T17:39:36.754668Z","price_level":"115661.78","new_quantity":"0"},{"side":"offer","event_time":"2025-10-27T17:39:36.754668Z","price_level":"115665.35","new_quantity":"0"},{"side":"offer","event_time":"2025-10-27T17:39:36.754668Z","price_level":"115665.36","new_quantity":"0"},{"side":"offer","event_time":"2025-10-27T17:39:36.754668Z","price_level":"115665.37","new_quantity":"0"},{"side":"offer","event_time":"2025-10-27T17:39:36.754668Z","price_level":"115665.42","new_quantity":"0"},{"side":"offer","event_time":"2025-10-27T17:39:36.754668Z","price_level":"115666.42","new_quantity":"0.0029176"},{"side":"offer","event_time":"2025-10-27T17:39:36.754668Z","price_level":"115666.43","new_quantity":"0.25936654"},{"side":"offer","event_time":"2025-10-27T17:39:36.754668Z","price_level":"115670.59","new_quantity":"0"},{"side":"offer","event_time":"2025-10-27T17:39:36.754668Z","price_level":"115671.14","new_quantity":"0.30966898"},{"side":"offer","event_time":"2025-10-27T17:39:36.754668Z","price_level":"115672.66","new_quantity":"0.25935257"},{"side":"offer","event_time":"2025-10-27T17:39:36.754668Z","price_level":"115677.55","new_quantity":"0.17266181"},{"side":"offer","event_time":"2025-10-27T17:39:36.754668Z","price_level":"115679.25","new_quantity":"0"},{"side":"offer","event_time":"2025-10-27T17:39:36.754668Z","price_level":"115679.86","new_quantity":"0.16654"},{"side":"offer","event_time":"2025-10-27T17:39:36.754668Z","price_level":"115681.56","new_quantity":"0.00432"},{"side":"offer","event_time":"2025-10-27T17:39:36.754668Z","price_level":"115681.57","new_quantity":"0.00432"},{"side":"offer","event_time":"2025-10-27T17:39:36.754668Z","price_level":"115681.99","new_quantity":"0.02927404"},{"side":"offer","event_time":"2025-10-27T17:39:36.754668Z","price_level":"115683.89","new_quantity":"0.00432"},{"side":"offer","event_time":"2025-10-27T17:39:36.754668Z","price_level":"115685.9","new_quantity":"0"},{"side":"offer","event_time":"2025-10-27T17:39:36.754668Z","price_level":"115685.91","new_quantity":"0"},{"side":"offer","event_time":"2025-10-27T17:39:36.754668Z","price_level":"115689.4","new_quantity":"0"},{"side":"offer","event_time":"2025-10-27T17:39:36.754668Z","price_level":"115689.42","new_quantity":"0"},{"side":"offer","event_time":"2025-10-27T17:39:36.754668Z","price_level":"115689.72","new_quantity":"0.4620573"},{"side":"offer","event_time":"2025-10-27T17:39:36.754668Z","price_level":"115689.99","new_quantity":"0.13833905"},{"side":"offer","event_time":"2025-10-27T17:39:36.754668Z","price_level":"115693.99","new_quantity":"0"},{"side":"offer","event_time":"2025-10-27T17:39:36.754668Z","price_level":"115694","new_quantity":"0"},{"side":"offer","event_time":"2025-10-27T17:39:36.754668Z","price_level":"115696","new_quantity":"0"},{"side":"offer","event_time":"2025-10-27T17:39:36.754668Z","price_level":"115698.56","new_quantity":"0.03025913"},{"side":"offer","event_time":"2025-10-27T17:39:36.754668Z","price_level":"115704.99","new_quantity":"0.09022428"},{"side":"offer","event_time":"2025-10-27T17:39:36.754668Z","price_level":"115708.71","new_quantity":"0"},{"side":"offer","event_time":"2025-10-27T17:39:36.754668Z","price_level":"115708.72","new_quantity":"0"},{"side":"offer","event_time":"2025-10-27T17:39:36.754668Z","price_level":"115711.99","new_quantity":"0.17929652"},{"side":"offer","event_time":"2025-10-27T17:39:36.754668Z","price_level":"115726.65","new_quantity":"0"},{"side":"offer","event_time":"2025-10-27T17:39:36.754668Z","price_level":"115734.69","new_quantity":"0"},{"side":"offer","event_time":"2025-10-27T17:39:36.754668Z","price_level":"115734.79","new_quantity":"0.25111459"},{"side":"offer","event_time":"2025-10-27T17:39:36.754668Z","price_level":"115734.8","new_quantity":"0"},{"side":"offer","event_time":"2025-10-27T17:39:36.754668Z","price_level":"115739.11","new_quantity":"0.38643"},{"side":"offer","event_time":"2025-10-27T17:39:36.754668Z","price_level":"115742.1","new_quantity":"1"}]}]}
{"channel":"l2_data","client_id":"","timestamp":"2025-10-27T17:39:37.505546957Z","sequence_num":137451,"events":[{"type":"update","product_id":"BTC-USD","updates":[{"side":"bid","event_time":"2025-10-27T17:39:36.833139Z","price_level":"115666","new_quantity":"0.0249"},{"side":"bid","event_time":"2025-10-27T17:39:36.833139Z","price_level":"115664.04","new_quantity":"0"},{"side":"bid","event_time":"2025-10-27T17:39:36.833139Z","price_level":"115664.03","new_quantity":"0.00664793"},{"side":"bid","event_time":"2025-10-27T17:39:36.833139Z","price_level":"115663.02","new_quantity":"0"},{"side":"bid","event_time":"2025-10-27T17:39:36.833139Z","price_level":"115652.96","new_quantity":"0"},{"side":"bid","event_time":"2025-10-27T17:39:36.833139Z","price_level":"115651.6","new_quantity":"0.00864665"},{"side":"bid","event_time":"2025-10-27T17:39:36.833139Z","price_level":"115651.55","new_quantity":"0"},{"side":"bid","event_time":"2025-10-27T17:39:36.833139Z","price_level":"115644.48","new_quantity":"0"},{"side":"bid","event_time":"2025-10-27T17:39:36.833139Z","price_level":"115638.29","new_quantity":"0.43828037"},{"side":"bid","event_time":"2025-10-27T17:39:36.833139Z","price_level":"115637.01","new_quantity":"0.3305252"},{"side":"bid","event_time":"2025-10-27T17:39:36.833139Z","price_level":"115637","new_quantity":"0"},{"side":"bid","event_time":"2025-10-27T17:39:36.833139Z","price_level":"115633","new_quantity":"0"},{"side":"bid","event_time":"2025-10-27T17:39:36.833139Z","price_level":"115632.98","new_quantity":"2.31201832"},{"side":"bid","event_time":"2025-10-27T17:39:36.833139Z","price_level":"115631.36","new_quantity":"0.0069609"},{"side":"bid","event_time":"2025-10-27T17:39:36.833139Z","price_level":"115631","new_quantity":"2"},{"side":"bid","event_time":"2025-10-27T17:39:36.833139Z","price_level":"115630.01","new_quantity":"0"},{"side":"bid","event_time":"2025-10-27T17:39:36.833139Z","price_level":"115630","new_quantity":"0"},{"side":"bid","event_time":"2025-10-27T17:39:36.833139Z","price_level":"115620","new_quantity":"1"},{"side":"bid","event_time":"2025-10-27T17:39:36.833139Z","price_level":"115601.42","new_quantity":"0.78057437"},{"side":"bid","event_time":"2025-10-27T17:39:36.833139Z","price_level":"115596.71","new_quantity":"0"},{"side":"bid","event_time":"2025-10-27T17:39:36.833139Z","price_level":"115511.79","new_quantity":"0.045"},{"side":"bid","event_time":"2025-10-27T17:39:36.833139Z","price_level":"114933.48","new_quantity":"0"},{"side":"offer","event_time":"2025-10-27T17:39:36.833139Z","price_level":"115666.42","new_quantity":"0.02885425"},{"side":"offer","event_time":"2025-10-27T17:39:36.833139Z","price_level":"115671.14","new_quantity":"0"},{"side":"offer","event_time":"2025-10-27T17:39:36.833139Z","price_level":"115691.85","new_quantity":"0.13833853"},{"side":"offer","event_time":"2025-10-27T17:39:36.833139Z","price_level":"115696.99","new_quantity":"0"},{"side":"offer","event_time":"2025-10-27T17:39:36.833139Z","price_level":"115697","new_quantity":"0"},{"side":"offer","event_time":"2025-10-27T17:39:36.833139Z","price_level":"115698.56","new_quantity":"0"},{"side":"offer","event_time":"2025-10-27T17:39:36.833139Z","price_level":"115702","new_quantity":"0"},{"side":"offer","event_time":"2025-10-27T17:39:36.833139Z","price_level":"115711.99","new_quantity":"0"},{"side":"offer","event_time":"2025-10-27T17:39:36.833139Z","price_level":"115716.39","new_quantity":"0.17928971"},{"side":"offer","event_time":"2025-10-27T17:39:36.833139Z","price_level":"115730.9","new_quantity":"0"},{"side":"offer","event_time":"2025-10-27T17:39:36.833139Z","price_level":"115739.11","new_quantity":"0"},{"side":"offer","event_time":"2025-10-27T17:39:36.833139Z","price_level":"115742.5","new_quantity":"0.01993432"},{"side":"offer","event_time":"2025-10-27T17:39:36.833139Z","price_level":"115743.92","new_quantity":"0.38641394"}]}]}
"2025-10-27T17:39:37.039535Z","price_level":"115622.87","new_quantity":"0"},{"side":"bid","event_time":"2025-10-27T17:39:37.039535Z","price_level":"115620","new_quantity":"1"},{"side":"bid","event_time":"2025-10-27T17:39:37.039535Z","price_level":"115612.8","new_quantity":"0.52632089"},{"side":"bid","event_time":"2025-10-27T17:39:37.039535Z","price_level":"115595","new_quantity":"1.5"},{"side":"bid","event_time":"2025-10-27T17:39:37.039535Z","price_level":"115593.4","new_quantity":"0"},{"side":"bid","event_time":"2025-10-27T17:39:37.039535Z","price_level":"115576.7","new_quantity":"0.00043224"},{"side":"offer","event_time":"2025-10-27T17:39:37.039535Z","price_level":"115668.52","new_quantity":"0.0240765"},{"side":"offer","event_time":"2025-10-27T17:39:37.039535Z","price_level":"115689.73","new_quantity":"0.14744478"},{"side":"offer","event_time":"2025-10-27T17:39:37.039535Z","price_level":"115690.89","new_quantity":"0"},{"side":"offer","event_time":"2025-10-27T17:39:37.039535Z","price_level":"115692.16","new_quantity":"0.03458133"},{"side":"offer","event_time":"2025-10-27T17:39:37.039535Z","price_level":"115693.98","new_quantity":"0.13833663"},{"side":"offer","event_time":"2025-10-27T17:39:37.039535Z","price_level":"115698","new_quantity":"0"},{"side":"offer","event_time":"2025-10-27T17:39:37.039535Z","price_level":"115698.56","new_quantity":"0.38904112"},{"side":"offer","event_time":"2025-10-27T17:39:37.039535Z","price_level":"115735.57","new_quantity":"0"},{"side":"offer","event_time":"2025-10-27T17:39:37.039535Z","price_level":"115738.38","new_quantity":"0.0004323"},{"side":"offer","event_time":"2025-10-27T17:39:37.039535Z","price_level":"115742.49","new_quantity":"0.00043224"},{"side":"offer","event_time":"2025-10-27T17:39:37.039535Z","price_level":"115746.5","new_quantity":"1"},{"side":"offer","event_time":"2025-10-27T17:39:37.039535Z","price_level":"115748.2","new_quantity":"0"}]}]}
{"channel":"l2_data","client_id":"","timestamp":"2025-10-27T17:39:37.515899478Z","sequence_num":137456,"events":[{"type":"update","product_id":"BTC-USD","updates":[{"side":"bid","event_time":"2025-10-27T17:39:37.070675Z","price_level":"115634","new_quantity":"0.4"},{"side":"bid","event_time":"2025-10-27T17:39:37.070675Z","price_level":"115632","new_quantity":"0.4"},{"side":"bid","event_time":"2025-10-27T17:39:37.070675Z","price_level":"115579.92","new_quantity":"1.26472512"},{"side":"bid","event_time":"2025-10-27T17:39:37.070675Z","price_level":"114981.77","new_quantity":"0.07007"},{"side":"bid","event_time":"2025-10-27T17:39:37.070675Z","price_level":"114124.05","new_quantity":"0.07007"},{"side":"offer","event_time":"2025-10-27T17:39:37.070675Z","price_level":"115698","new_quantity":"0.4"}]}]}
{"channel":"l2_data","client_id":"","timestamp":"2025-10-27T17:39:37.510721101Z","sequence_num":137452,"events":[{"type":"update","product_id":"BTC-USD","updates":[{"side":"bid","event_time":"2025-10-27T17:39:36.888587Z","price_level":"115666.41","new_quantity":"0.0240765"},{"side":"bid","event_time":"2025-10-27T17:39:36.888587Z","price_level":"115666.03","new_quantity":"0.0240765"},{"side":"bid","event_time":"2025-10-27T17:39:36.888587Z","price_level":"115666.02","new_quantity":"0.0240765"},{"side":"bid","event_time":"2025-10-27T17:39:36.888587Z","price_level":"115666","new_quantity":"0.0249"},{"side":"bid","event_time":"2025-10-27T17:39:36.888587Z","price_level":"115664.03","new_quantity":"0"},{"side":"bid","event_time":"2025-10-27T17:39:36.888587Z","price_level":"115662.01","new_quantity":"0"},{"side":"bid","event_time":"2025-10-27T17:39:36.888587Z","price_level":"115657.75","new_quantity":"0"},{"side":"bid","event_time":"2025-10-27T17:39:36.888587Z","price_level":"115657.74","new_quantity":"0"},{"side":"bid","event_time":"2025-10-27T17:39:36.888587Z","price_level":"115656.44","new_quantity":"0.00008647"},{"side":"bid","event_time":"2025-10-27T17:39:36.888587Z","price_level":"115656.43","new_quantity":"0.05217108"},{"side":"bid","event_time":"2025-10-27T17:39:36.888587Z","price_level":"115652.93","new_quantity":"0.00864655"},{"side":"bid","event_time":"2025-10-27T17:39:36.888587Z","price_level":"115652.03","new_quantity":"0"},{"side":"bid","event_time":"2025-10-27T17:39:36.888587Z","price_level":"115652.02","new_quantity":"0.00053579"},{"side":"bid","event_time":"2025-10-27T17:39:36.888587Z","price_level":"115651.6","new_quantity":"0"},{"side":"bid","event_time":"2025-10-27T17:39:36.888587Z","price_level":"115646.4","new_quantity":"0"},{"side":"bid","event_time":"2025-10-27T17:39:36.888587Z","price_level":"115645.6","new_quantity":"0.33937138"},{"side":"bid","event_time":"2025-10-27T17:39:36.888587Z","price_level":"115644.51","new_quantity":"0.00432"},{"side":"bid","event_time":"2025-10-27T17:39:36.888587Z","price_level":"115644.3","new_quantity":"0"},{"side":"bid","event_time":"2025-10-27T17:39:36.888587Z","price_level":"115640.01","new_quantity":"1.03194321"},{"side":"bid","event_time":"2025-10-27T17:39:36.888587Z","price_level":"115639","new_quantity":"0.4"},{"side":"bid","event_time":"2025-10-27T17:39:36.888587Z","price_level":"115638.29","new_quantity":"0"},{"side":"bid","event_time":"2025-10-27T17:39:36.888587Z","price_level":"115636","new_quantity":"0.4"},{"side":"bid","event_time":"2025-10-27T17:39:36.888587Z","price_level":"115634","new_quantity":"0.4"},{"side":"bid","event_time":"2025-10-27T17:39:36.888587Z","price_level":"115633.01","new_quantity":"2.5460578"},{"side":"bid","event_time":"2025-10-27T17:39:36.888587Z","price_level":"115633","new_quantity":"2"},{"side":"bid","event_time":"2025-10-27T17:39:36.888587Z","price_level":"115632.98","new_quantity":"0"},{"side":"bid","event_time":"2025-10-27T17:39:36.888587Z","price_level":"115631","new_quantity":"0"},{"side":"bid","event_time":"2025-10-27T17:39:36.888587Z","price_level":"115629.14","new_quantity":"0.07007"},{"side":"bid","event_time":"2025-10-27T17:39:36.888587Z","price_level":"115625.38","new_quantity":"0"},{"side":"bid","event_time":"2025-10-27T17:39:36.888587Z","price_level":"115622.87","new_quantity":"0.52627505"},{"side":"bid","event_time":"2025-10-27T17:39:36.888587Z","price_level":"115620.65","new_quantity":"0"},{"side":"bid","event_time":"2025-10-27T17:39:36.888587Z","price_level":"115620","new_quantity":"1"},{"side":"bid","event_time":"2025-10-27T17:39:36.888587Z","price_level":"115593.4","new_quantity":"1.5"},{"side":"bid","event_time":"2025-10-27T17:39:36.888587Z","price_level":"115584.1","new_quantity":"0"},{"side":"bid","event_time":"2025-10-27T17:39:36.888587Z","price_level":"115576.69","new_quantity":"1.20656291"},{"side":"bid","event_time":"2025-10-27T17:39:36.888587Z","price_level":"115567.36","new_quantity":"0"},{"side":"bid","event_time":"2025-10-27T17:39:36.888587Z","price_level":"115414.52","new_quantity":"0.07007"},{"side":"bid","event_time":"2025-10-27T17:39:36.888587Z","price_level":"115414.46","new_quantity":"0.07007"},{"side":"bid","event_time":"2025-10-27T17:39:36.888587Z","price_level":"115407.43","new_quantity":"0"},{"side":"bid","event_time":"2025-10-27T17:39:36.888587Z","price_level":"109320.4","new_quantity":"0.00047949"},{"side":"offer","event_time":"2025-10-27T17:39:36.888587Z","price_level":"115667.45","new_quantity":"0"},{"side":"offer","event_time":"2025-10-27T17:39:36.888587Z","price_level":"115668.32","new_quantity":"0"},{"side":"offer","event_time":"2025-10-27T17:39:36.888587Z","price_level":"115681.56","new_quantity":"0"},{"side":"offer","event_time":"2025-10-27T17:39:36.888587Z","price_level":"115681.57","new_quantity":"0"},{"side":"offer","event_time":"2025-10-27T17:39:36.888587Z","price_level":"115681.99","new_quantity":"0"},{"side":"offer","event_time":"2025-10-27T17:39:36.888587Z","price_level":"115686","new_quantity":"0"},{"side":"offer","event_time":"2025-10-27T17:39:36.888587Z","price_level":"115689.72","new_quantity":"0"},{"side":"offer","event_time":"2025-10-27T17:39:36.888587Z","price_level":"115689.73","new_quantity":"0.14744478"},{"side":"offer","event_time":"2025-10-27T17:39:36.888587Z","price_level":"115690.89","new_quantity":"0.03458213"},{"side":"offer","event_time":"2025-10-27T17:39:36.888587Z","price_level":"115690.9","new_quantity":"0"},{"side":"offer","event_time":"2025-10-27T17:39:36.888587Z","price_level":"115691.85","new_quantity":"0"},{"side":"offer","event_time":"2025-10-27T17:39:36.888587Z","price_level":"115693.99","new_quantity":"0"},{"side":"offer","event_time":"2025-10-27T17:39:36.888587Z","price_level":"115694.04","new_quantity":"0.00967245"},{"side":"offer","event_time":"2025-10-27T17:39:36.888587Z","price_level":"115698.56","new_quantity":"0.52738129"},{"side":"offer","event_time":"2025-10-27T17:39:36.888587Z","price_level":"115699","new_quantity":"0.4"},{"side":"offer","event_time":"2025-10-27T17:39:36.888587Z","price_level":"115701","new_quantity":"0.4"},{"side":"offer","event_time":"2025-10-27T17:39:36.888587Z","price_level":"115723.73","new_quantity":"0"},{"side":"offer","event_time":"2025-10-27T17:39:36.888587Z","price_level":"115726.63","new_quantity":"0"},{"side":"offer","event_time":"2025-10-27T17:39:36.888587Z","price_level":"115726.64","new_quantity":"0"},{"side":"offer","event_time":"2025-10-27T17:39:36.888587Z","price_level":"115734.67","new_quantity":"0.00043225"},{"side":"offer","event_time":"2025-10-27T17:39:36.888587Z","price_level":"115734.68","new_quantity":"0"},{"side":"offer","event_time":"2025-10-27T17:39:36.888587Z","price_level":"115737.6","new_quantity":"0"},{"side":"offer","event_time":"2025-10-27T17:39:36.888587Z","price_level":"115738.38","new_quantity":"0"},{"side":"offer","event_time":"2025-10-27T17:39:36.888587Z","price_level":"115739.12","new_quantity":"0"},{"side":"offer","event_time":"2025-10-27T17:39:36.888587Z","price_level":"115748","new_quantity":"0"},{"side":"offer","event_time":"2025-10-27T17:39:36.888587Z","price_level":"115749.1","new_quantity":"1"},{"side":"offer","event_time":"2025-10-27T17:39:36.888587Z","price_level":"115768.04","new_quantity":"0"}]}]}
{"channel":"l2_data","client_id":"","timestamp":"2025-10-27T17:39:37.512687323Z","sequence_num":137453,"events":[{"type":"update","product_id":"BTC-USD","updates":[{"side":"bid","event_time":"2025-10-27T17:39:36.946962Z","price_level":"115666.41","new_quantity":"0"},{"side":"bid","event_time":"2025-10-27T17:39:36.946962Z","price_level":"115666.03","new_quantity":"0"},{"side":"bid","event_time":"2025-10-27T17:39:36.946962Z","price_level":"115666.02","new_quantity":"0"},{"side":"bid","event_time":"2025-10-27T17:39:36.946962Z","price_level":"115666","new_quantity":"0"},{"side":"bid","event_time":"2025-10-27T17:39:36.946962Z","price_level":"115657.18","new_quantity":"0.00008647"},{"side":"bid","event_time":"2025-10-27T17:39:36.946962Z","price_level":"115656.44","new_quantity":"0"},{"side":"bid","event_time":"2025-10-27T17:39:36.946962Z","price_level":"115652.82","new_quantity":"0.0216084"},{"side":"bid","event_time":"2025-10-27T17:39:36.946962Z","price_level":"115650.63","new_quantity":"0"},{"side":"bid","event_time":"2025-10-27T17:39:36.946962Z","price_level":"115637","new_quantity":"0.4"},{"side":"bid","event_time":"2025-10-27T17:39:36.946962Z","price_level":"115636","new_quantity":"0"},{"side":"bid","event_time":"2025-10-27T17:39:36.946962Z","price_level":"115635","new_quantity":"0.4"},{"side":"bid","event_time":"2025-10-27T17:39:36.946962Z","price_level":"115634","new_quantity":"0"},{"side":"bid","event_time":"2025-10-27T17:39:36.946962Z","price_level":"115630","new_quantity":"1"},{"side":"bid","event_time":"2025-10-27T17:39:36.946962Z","price_level":"115620","new_quantity":"0"},{"side":"bid","event_time":"2025-10-27T17:39:36.946962Z","price_level":"115576.69","new_quantity":"1.20613066"},{"side":"bid","event_time":"2025-10-27T17:39:36.946962Z","price_level":"115414.46","new_quantity":"0"},{"side":"bid","event_time":"2025-10-27T17:39:36.946962Z","price_level":"115198.73","new_quantity":"0.07007"},{"side":"bid","event_time":"2025-10-27T17:39:36.946962Z","price_level":"115198.6","new_quantity":"0"},{"side":"bid","event_time":"2025-10-27T17:39:36.946962Z","price_level":"115192.29","new_quantity":"0"},{"side":"offer","event_time":"2025-10-27T17:39:36.946962Z","price_level":"115666.42","new_quantity":"0.04141325"},{"side":"offer","event_time":"2025-10-27T17:39:36.946962Z","price_level":"115681.57","new_quantity":"0.00432"},{"side":"offer","event_time":"2025-10-27T17:39:36.946962Z","price_level":"115689.73","new_quantity":"0.38150114"},{"side":"offer","event_time":"2025-10-27T17:39:36.946962Z","price_level":"115690.89","new_quantity":"0.42362962"},{"side":"offer","event_time":"2025-10-27T17:39:36.946962Z","price_level":"115693","new_quantity":"0.4"},{"side":"offer","event_time":"2025-10-27T17:39:36.946962Z","price_level":"115698.56","new_quantity":"0.13833767"},{"side":"offer","event_time":"2025-10-27T17:39:36.946962Z","price_level":"115716.3","new_quantity":"0.082996"},{"side":"offer","event_time":"2025-10-27T17:39:36.946962Z","price_level":"115725.83","new_quantity":"0"},{"side":"offer","event_time":"2025-10-27T17:39:36.946962Z","price_level":"115729.99","new_quantity":"0.00043224"},{"side":"offer","event_time":"2025-10-27T17:39:36.946962Z","price_level":"115734.67","new_quantity":"0"},{"side":"offer","event_time":"2025-10-27T17:39:36.946962Z","price_level":"115735.57","new_quantity":"0.0004323"},{"side":"offer","event_time":"2025-10-27T17:39:36.946962Z","price_level":"115745.21","new_quantity":"0.103745"},{"side":"offer","event_time":"2025-10-27T17:39:36.946962Z","price_level":"115747.6","new_quantity":"1"},{"side":"offer","event_time":"2025-10-27T17:39:36.946962Z","price_level":"115749.1","new_quantity":"0"}]}]}
{"channel":"l2_data","client_id":"","timestamp":"2025-10-27T17:39:37.518616849Z","sequence_num":137459,"events":[{"type":"update","product_id":"ETH-USD","updates":[{"side":"offer","event_time":"2025-10-27T17:39:37.479945Z","price_level":"4219.42","new_quantity":"0.102891"},{"side":"offer","event_time":"2025-10-27T17:39:37.479945Z","price_level":"4219.52","new_quantity":"0.64"},{"side":"offer","event_time":"2025-10-27T17:39:37.479945Z","price_level":"4219.73","new_quantity":"0"},{"side":"offer","event_time":"2025-10-27T17:39:37.479945Z","price_level":"4244.82","new_quantity":"0.1536"}]}]}
{"channel":"l2_data","client_id":"","timestamp":"2025-10-27T17:39:37.522010637Z","sequence_num":137460,"events":[{"type":"update","product_id":"BTC-USD","updates":[{"side":"bid","event_time":"2025-10-27T17:39:37.407472Z","price_level":"115656.43","new_quantity":"0"},{"side":"bid","event_time":"2025-10-27T17:39:37.407472Z","price_level":"115634.69","new_quantity":"0"},{"side":"bid","event_time":"2025-10-27T17:39:37.407472Z","price_level":"115633.02","new_quantity":"0.3305366"},{"side":"bid","event_time":"2025-10-27T17:39:37.407472Z","price_level":"115627.38","new_quantity":"0.0069609"},{"side":"bid","event_time":"2025-10-27T17:39:37.407472Z","price_level":"115595","new_quantity":"0"},{"side":"bid","event_time":"2025-10-27T17:39:37.407472Z","price_level":"115594.2","new_quantity":"1.5"},{"side":"bid","event_time":"2025-10-27T17:39:37.407472Z","price_level":"114933.48","new_quantity":"0"},{"side":"bid","event_time":"2025-10-27T17:39:37.407472Z","price_level":"114552.03","new_quantity":"0.07007"},{"side":"bid","event_time":"2025-10-27T17:39:37.407472Z","price_level":"114123.17","new_quantity":"0.07007"},{"side":"bid","event_time":"2025-10-27T17:39:37.407472Z","price_level":"101204.31","new_quantity":"0.0049568"},{"side":"offer","event_time":"2025-10-27T17:39:37.407472Z","price_level":"115689.73","new_quantity":"0.14744478"},{"side":"offer","event_time":"2025-10-27T17:39:37.407472Z","price_level":"115740.09","new_quantity":"0.38642673"},{"side":"offer","event_time":"2025-10-27T17:39:37.407472Z","price_level":"115740.1","new_quantity":"1"},{"side":"offer","event_time":"2025-10-27T17:39:37.407472Z","price_level":"115740.39","new_quantity":"0"},{"side":"offer","event_time":"2025-10-27T17:39:37.407472Z","price_level":"115740.4","new_quantity":"0"},{"side":"offer","event_time":"2025-10-27T17:39:37.407472Z","price_level":"116391.26","new_quantity":"0"}]}]}
{"channel":"l2_data","client_id":"","timestamp":"2025-10-27T17:39:37.523247995Z","sequence_num":137461,"events":[{"type":"update","product_id":"BTC-USD","updates":[{"side":"bid","event_time":"2025-10-27T17:39:37.435004Z","price_level":"115652.83","new_quantity":"0.02160763"},{"side":"bid","event_time":"2025-10-27T17:39:37.435004Z","price_level":"115645.6","new_quantity":"0.33937138"},{"side":"bid","event_time":"2025-10-27T17:39:37.435004Z","price_level":"115641.07","new_quantity":"0"},{"side":"bid","event_time":"2025-10-27T17:39:37.435004Z","price_level":"114552.32","new_quantity":"0.07007"},{"side":"bid","event_time":"2025-10-27T17:39:37.435004Z","price_level":"114338.08","new_quantity":"0"},{"side":"bid","event_time":"2025-10-27T17:39:37.435004Z","price_level":"114123.17","new_quantity":"0"},{"side":"offer","event_time":"2025-10-27T17:39:37.435004Z","price_level":"115677.55","new_quantity":"0.09257142"},{"side":"offer","event_time":"2025-10-27T17:39:37.435004Z","price_level":"115679.86","new_quantity":"0"},{"side":"offer","event_time":"2025-10-27T17:39:37.435004Z","price_level":"115681.57","new_quantity":"0"},{"side":"offer","event_time":"2025-10-27T17:39:37.435004Z","price_level":"115689.73","new_quantity":"0.14744478"}]}]}
{"channel":"l2_data","client_id":"","timestamp":"2025-10-27T17:39:37.547646003Z","sequence_num":137462,"events":[{"type":"update","product_id":"BTC-USD","updates":[{"side":"bid","event_time":"2025-10-27T17:39:37.488654Z","price_level":"115644.48","new_quantity":"0.00432"},{"side":"bid","event_time":"2025-10-27T17:39:37.488654Z","price_level":"115640.01","new_quantity":"0.2909957"},{"side":"bid","event_time":"2025-10-27T17:39:37.488654Z","price_level":"115639","new_quantity":"0.4"},{"side":"bid","event_time":"2025-10-27T17:39:37.488654Z","price_level":"115638","new_quantity":"0"},{"side":"bid","event_time":"2025-10-27T17:39:37.488654Z","price_level":"115620","new_quantity":"0"},{"side":"offer","event_time":"2025-10-27T17:39:37.488654Z","price_level":"115689.73","new_quantity":"0.14744478"},{"side":"offer","event_time":"2025-10-27T17:39:37.488654Z","price_level":"115693","new_quantity":"0"},{"side":"offer","event_time":"2025-10-27T17:39:37.488654Z","price_level":"115708.32","new_quantity":"0"},{"side":"offer","event_time":"2025-10-27T17:39:37.488654Z","price_level":"115710.92","new_quantity":"0.5"},{"side":"offer","event_time":"2025-10-27T17:39:37.488654Z","price_level":"115727.15","new_quantity":"0.00043223"},{"side":"offer","event_time":"2025-10-27T17:39:37.488654Z","price_level":"115734.67","new_quantity":"0"}]}]}
{"channel":"l2_data","client_id":"","timestamp":"2025-10-27T17:39:37.568974614Z","sequence_num":137463,"events":[{"type":"update","product_id":"ETH-USD","updates":[{"side":"bid","event_time":"2025-10-27T17:39:37.495186Z","price_level":"4217.94","new_quantity":"3.30529"},{"side":"bid","event_time":"2025-10-27T17:39:37.495186Z","price_level":"4214.01","new_quantity":"36.28204886"},{"side":"bid","event_time":"2025-10-27T17:39:37.495186Z","price_level":"4210.59","new_quantity":"0"}]}]}
{"channel":"l2_data","client_id":"","timestamp":"2025-10-27T17:39:37.596687018Z","sequence_num":137465,"events":[{"type":"update","product_id":"BTC-USD","updates":[{"side":"bid","event_time":"2025-10-27T17:39:37.550796Z","price_level":"115662.06","new_quantity":"0.02400515"},{"side":"bid","event_time":"2025-10-27T17:39:37.550796Z","price_level":"115640.01","new_quantity":"0.49259247"},{"side":"bid","event_time":"2025-10-27T17:39:37.550796Z","price_level":"115620","new_quantity":"1"},{"side":"bid","event_time":"2025-10-27T17:39:37.550796Z","price_level":"114933.48","new_quantity":"0.045"},{"side":"bid","event_time":"2025-10-27T17:39:37.550796Z","price_level":"114767.42","new_quantity":"0.07007"},{"side":"bid","event_time":"2025-10-27T17:39:37.550796Z","price_level":"114767.04","new_quantity":"0.07007"},{"side":"bid","event_time":"2025-10-27T17:39:37.550796Z","price_level":"114766.94","new_quantity":"0"},{"side":"bid","event_time":"2025-10-27T17:39:37.550796Z","price_level":"114552.03","new_quantity":"0"},{"side":"offer","event_time":"2025-10-27T17:39:37.550796Z","price_level":"115689.73","new_quantity":"0.14744478"},{"side":"offer","event_time":"2025-10-27T17:39:37.550796Z","price_level":"115692","new_quantity":"0"},{"side":"offer","event_time":"2025-10-27T17:39:37.550796Z","price_level":"115694","new_quantity":"0"},{"side":"offer","event_time":"2025-10-27T17:39:37.550796Z","price_level":"115698","new_quantity":"0"}]}]}
{"channel":"l2_data","client_id":"","timestamp":"2025-10-27T17:39:37.619720146Z","sequence_num":137466,"events":[{"type":"update","product_id":"ETH-USD","updates":[{"side":"offer","event_time":"2025-10-27T17:39:37.556272Z","price_level":"4219.14","new_quantity":"0.00592715"}]}]}
{"channel":"l2_data","client_id":"","timestamp":"2025-10-27T17:39:37.646860549Z","sequence_num":137468,"events":[{"type":"update","product_id":"BTC-USD","updates":[{"side":"bid","event_time":"2025-10-27T17:39:37.606497Z","price_level":"115656.43","new_quantity":"0.06475097"},{"side":"bid","event_time":"2025-10-27T17:39:37.606497Z","price_level":"115640.01","new_quantity":"0.2909957"},{"side":"bid","event_time":"2025-10-27T17:39:37.606497Z","price_level":"115639","new_quantity":"0"},{"side":"offer","event_time":"2025-10-27T17:39:37.606497Z","price_level":"115689.73","new_quantity":"0.14744478"},{"side":"offer","event_time":"2025-10-27T17:39:37.606497Z","price_level":"115692","new_quantity":"0"},{"side":"offer","event_time":"2025-10-27T17:39:37.606497Z","price_level":"115693","new_quantity":"0"},{"side":"offer","event_time":"2025-10-27T17:39:37.606497Z","price_level":"115698","new_quantity":"0.4"}]}]}
{"channel":"l2_data","client_id":"","timestamp":"2025-10-27T17:39:37.669279773Z","sequence_num":137469,"events":[{"type":"update","product_id":"ETH-USD","updates":[{"side":"bid","event_time":"2025-10-27T17:39:37.625617Z","price_level":"4217.74","new_quantity":"0"},{"side":"bid","event_time":"2025-10-27T17:39:37.625617Z","price_level":"4210.26","new_quantity":"2.39774646"},{"side":"bid","event_time":"2025-10-27T17:39:37.625617Z","price_level":"4208.75","new_quantity":"0"}]}]}
{"channel":"l2_data","client_id":"","timestamp":"2025-10-27T17:39:37.697628227Z","sequence_num":137470,"events":[{"type":"update","product_id":"BTC-USD","updates":[{"side":"bid","event_time":"2025-10-27T17:39:37.656191Z","price_level":"115640.01","new_quantity":"0.49259247"},{"side":"bid","event_time":"2025-10-27T17:39:37.656191Z","price_level":"115638","new_quantity":"0.4"},{"side":"bid","event_time":"2025-10-27T17:39:37.656191Z","price_level":"115528.01","new_quantity":"0"},{"side":"bid","event_time":"2025-10-27T17:39:37.656191Z","price_level":"115526.58","new_quantity":"0"},{"side":"bid","event_time":"2025-10-27T17:39:37.656191Z","price_level":"115520.82","new_quantity":"0.43214898"},{"side":"bid","event_time":"2025-10-27T17:39:37.656191Z","price_level":"115377.5","new_quantity":"1.29644694"},{"side":"bid","event_time":"2025-10-27T17:39:37.656191Z","price_level":"115311","new_quantity":"0.00017295"},{"side":"offer","event_time":"2025-10-27T17:39:37.656191Z","price_level":"115689.73","new_quantity":"0.14744478"},{"side":"offer","event_time":"2025-10-27T17:39:37.656191Z","price_level":"115807.96","new_quantity":"0.43214898"},{"side":"offer","event_time":"2025-10-27T17:39:37.656191Z","price_level":"115819.77","new_quantity":"0"},{"side":"offer","event_time":"2025-10-27T17:39:37.656191Z","price_level":"115843.58","new_quantity":"1.19073474"},{"side":"offer","event_time":"2025-10-27T17:39:37.656191Z","price_level":"115898","new_quantity":"1.46901247"},{"side":"offer","event_time":"2025-10-27T17:39:37.656191Z","price_level":"116004.6","new_quantity":"0.00017295"}]}]}
{"channel":"l2_data","client_id":"","timestamp":"2025-10-27T17:39:37.721526814Z","sequence_num":137471,"events":[{"type":"update","product_id":"ETH-USD","updates":[{"side":"bid","event_time":"2025-10-27T17:39:37.645594Z","price_level":"4203.12","new_quantity":"14.22162996"},{"side":"bid","event_time":"2025-10-27T17:39:37.645594Z","price_level":"4202.8","new_quantity":"0"},{"side":"offer","event_time":"2025-10-27T17:39:37.645594Z","price_level":"4227.62","new_quantity":"2.37027166"},{"side":"offer","event_time":"2025-10-27T17:39:37.645594Z","price_level":"4230.8","new_quantity":"0"},{"side":"offer","event_time":"2025-10-27T17:39:37.645594Z","price_level":"4234.4","new_quantity":"0.00028533"},{"side":"offer","event_time":"2025-10-27T17:39:37.645594Z","price_level":"4234.77","new_quantity":"14.22162996"}]}]}
{"channel":"l2_data","client_id":"","timestamp":"2025-10-27T17:39:37.746519001Z","sequence_num":137472,"events":[{"type":"update","product_id":"BTC-USD","updates":[{"side":"bid","event_time":"2025-10-27T17:39:37.683898Z","price_level":"115634.69","new_quantity":"0.33053183"},{"side":"bid","event_time":"2025-10-27T17:39:37.683898Z","price_level":"115633.02","new_quantity":"0"},{"side":"bid","event_time":"2025-10-27T17:39:37.683898Z","price_level":"115620.65","new_quantity":"0.52628515"},{"side":"bid","event_time":"2025-10-27T17:39:37.683898Z","price_level":"115612.8","new_quantity":"0"},{"side":"bid","event_time":"2025-10-27T17:39:37.683898Z","price_level":"115579.94","new_quantity":"1.47508669"},{"side":"bid","event_time":"2025-10-27T17:39:37.683898Z","price_level":"114982.21","new_quantity":"0.07007"},{"side":"bid","event_time":"2025-10-27T17:39:37.683898Z","price_level":"114767.04","new_quantity":"0"},{"side":"offer","event_time":"2025-10-27T17:39:37.683898Z","price_level":"115662.07","new_quantity":"0.02858367"},{"side":"offer","event_time":"2025-10-27T17:39:37.683898Z","price_level":"115689.73","new_quantity":"0.38803931"},{"side":"offer","event_time":"2025-10-27T17:39:37.683898Z","price_level":"115692","new_quantity":"0.4"},{"side":"offer","event_time":"2025-10-27T17:39:37.683898Z","price_level":"115693","new_quantity":"2"},{"side":"offer","event_time":"2025-10-27T17:39:37.683898Z","price_level":"115711.99","new_quantity":"0"},{"side":"offer","event_time":"2025-10-27T17:39:37.683898Z","price_level":"115715.04","new_quantity":"0.1792918"},{"side":"offer","event_time":"2025-10-27T17:39:37.683898Z","price_level":"115719.91","new_quantity":"1.7466115"},{"side":"offer","event_time":"2025-10-27T17:39:37.683898Z","price_level":"115729.99","new_quantity":"0"},{"side":"offer","event_time":"2025-10-27T17:39:37.683898Z","price_level":"115735.11","new_quantity":"0.2511139"},{"side":"offer","event_time":"2025-10-27T17:39:37.683898Z","price_level":"115740.09","new_quantity":"0"},{"side":"offer","event_time":"2025-10-27T17:39:37.683898Z","price_level":"115743.92","new_quantity":"0.38641394"},{"side":"offer","event_time":"2025-10-27T17:39:37.683898Z","price_level":"115745.2","new_quantity":"0"},{"side":"offer","event_time":"2025-10-27T17:39:37.683898Z","price_level":"115749.57","new_quantity":"0.57736879"},{"side":"offer","event_time":"2025-10-27T17:39:37.683898Z","price_level":"115809.57","new_quantity":"0"},{"side":"offer","event_time":"2025-10-27T17:39:37.683898Z","price_level":"115843.58","new_quantity":"0"}]}]}
{"channel":"l2_data","client_id":"","timestamp":"2025-10-27T17:39:37.797807423Z","sequence_num":137473,"events":[{"type":"update","product_id":"BTC-USD","updates":[{"side":"bid","event_time":"2025-10-27T17:39:37.759343Z","price_level":"115644.51","new_quantity":"0.00432"},{"side":"bid","event_time":"2025-10-27T17:39:37.759343Z","price_level":"115600.02","new_quantity":"0.78058382"},{"side":"bid","event_time":"2025-10-27T17:39:37.759343Z","price_level":"115596.71","new_quantity":"0"},{"side":"bid","event_time":"2025-10-27T17:39:37.759343Z","price_level":"114982.3","new_quantity":"0.07007"},{"side":"bid","event_time":"2025-10-27T17:39:37.759343Z","price_level":"114982.2","new_quantity":"0"},{"side":"bid","event_time":"2025-10-27T17:39:37.759343Z","price_level":"101204.31","new_quantity":"0"},{"side":"offer","event_time":"2025-10-27T17:39:37.759343Z","price_level":"115662.07","new_quantity":"0.02826696"},{"side":"offer","event_time":"2025-10-27T17:39:37.759343Z","price_level":"115679.24","new_quantity":"0.00432"},{"side":"offer","event_time":"2025-10-27T17:39:37.759343Z","price_level":"115679.25","new_quantity":"0.00432"},{"side":"offer","event_time":"2025-10-27T17:39:37.759343Z","price_level":"115689.73","new_quantity":"0.14744478"},{"side":"offer","event_time":"2025-10-27T17:39:37.759343Z","price_level":"115692","new_quantity":"0"},{"side":"offer","event_time":"2025-10-27T17:39:37.759343Z","price_level":"115693","new_quantity":"0"},{"side":"offer","event_time":"2025-10-27T17:39:37.759343Z","price_level":"115708.04","new_quantity":"0.5"},{"side":"offer","event_time":"2025-10-27T17:39:37.759343Z","price_level":"115710.32","new_quantity":"0"},{"side":"offer","event_time":"2025-10-27T17:39:37.759343Z","price_level":"115710.92","new_quantity":"0"}]}]}
{"channel":"l2_data","client_id":"","timestamp":"2025-10-27T17:39:37.846613219Z","sequence_num":137475,"events":[{"type":"update","product_id":"BTC-USD","updates":[{"side":"bid","event_time":"2025-10-27T17:39:37.785169Z","price_level":"115656.43","new_quantity":"0"},{"side":"bid","event_time":"2025-10-27T17:39:37.785169Z","price_level":"115521.01","new_quantity":"0"},{"side":"bid","event_time":"2025-10-27T17:39:37.785169Z","price_level":"115519.74","new_quantity":"0.00017286"},{"side":"bid","event_time":"2025-10-27T17:39:37.785169Z","price_level":"115311","new_quantity":"0"},{"side":"bid","event_time":"2025-10-27T17:39:37.785169Z","price_level":"114982.21","new_quantity":"0"},{"side":"bid","event_time":"2025-10-27T17:39:37.785169Z","price_level":"114767.64","new_quantity":"0.07007"},{"side":"offer","event_time":"2025-10-27T17:39:37.785169Z","price_level":"115677.55","new_quantity":"0"},{"side":"offer","event_time":"2025-10-27T17:39:37.785169Z","price_level":"115689.73","new_quantity":"1.34323931"},{"side":"offer","event_time":"2025-10-27T17:39:37.785169Z","price_level":"115691","new_quantity":"2"},{"side":"offer","event_time":"2025-10-27T17:39:37.785169Z","price_level":"115698","new_quantity":"0"},{"side":"offer","event_time":"2025-10-27T17:39:37.785169Z","price_level":"115821.89","new_quantity":"0"},{"side":"offer","event_time":"2025-10-27T17:39:37.785169Z","price_level":"116004.6","new_quantity":"0"}]}]}
{"channel":"l2_data","client_id":"","timestamp":"2025-10-27T17:39:37.897288426Z","sequence_num":137476,"events":[{"type":"update","product_id":"BTC-USD","updates":[{"side":"bid","event_time":"2025-10-27T17:39:37.833905Z","price_level":"115632.93","new_quantity":"0"},{"side":"bid","event_time":"2025-10-27T17:39:37.833905Z","price_level":"114767.65","new_quantity":"0.07007"},{"side":"bid","event_time":"2025-10-27T17:39:37.833905Z","price_level":"114767.42","new_quantity":"0"},{"side":"offer","event_time":"2025-10-27T17:39:37.833905Z","price_level":"115666.37","new_quantity":"0.3315551"},{"side":"offer","event_time":"2025-10-27T17:39:37.833905Z","price_level":"115671.14","new_quantity":"0.1548355"},{"side":"offer","event_time":"2025-10-27T17:39:37.833905Z","price_level":"115675.79","new_quantity":"0.18955944"},{"side":"offer","event_time":"2025-10-27T17:39:37.833905Z","price_level":"115683.24","new_quantity":"0.02927404"},{"side":"offer","event_time":"2025-10-27T17:39:37.833905Z","price_level":"115689.73","new_quantity":"1.55127977"},{"side":"offer","event_time":"2025-10-27T17:39:37.833905Z","price_level":"115691","new_quantity":"2"},{"side":"offer","event_time":"2025-10-27T17:39:37.833905Z","price_level":"115698","new_quantity":"0.4"},{"side":"offer","event_time":"2025-10-27T17:39:37.833905Z","price_level":"115706.59","new_quantity":"0"}]}]}
{"channel":"l2_data","client_id":"","timestamp":"2025-10-27T17:39:37.946991804Z","sequence_num":137478,"events":[{"type":"update","product_id":"BTC-USD","updates":[{"side":"bid","event_time":"2025-10-27T17:39:37.881451Z","price_level":"115662.06","new_quantity":"0.02396896"},{"side":"bid","event_time":"2025-10-27T17:39:37.881451Z","price_level":"115656.43","new_quantity":"0.06475097"},{"side":"bid","event_time":"2025-10-27T17:39:37.881451Z","price_level":"115652.83","new_quantity":"0"},{"side":"bid","event_time":"2025-10-27T17:39:37.881451Z","price_level":"115652.01","new_quantity":"0.04825113"},{"side":"bid","event_time":"2025-10-27T17:39:37.881451Z","price_level":"115651.12","new_quantity":"0.02160702"},{"side":"bid","event_time":"2025-10-27T17:39:37.881451Z","price_level":"115650.37","new_quantity":"0"},{"side":"bid","event_time":"2025-10-27T17:39:37.881451Z","price_level":"115638","new_quantity":"0"},{"side":"bid","event_time":"2025-10-27T17:39:37.881451Z","price_level":"115633","new_quantity":"0"},{"side":"bid","event_time":"2025-10-27T17:39:37.881451Z","price_level":"115620","new_quantity":"0"},{"side":"bid","event_time":"2025-10-27T17:39:37.881451Z","price_level":"115579.94","new_quantity":"0"},{"side":"bid","event_time":"2025-10-27T17:39:37.881451Z","price_level":"115579.92","new_quantity":"0"},{"side":"bid","event_time":"2025-10-27T17:39:37.881451Z","price_level":"114767.64","new_quantity":"0"},{"side":"bid","event_time":"2025-10-27T17:39:37.881451Z","price_level":"114337.49","new_quantity":"0.07007"},{"side":"offer","event_time":"2025-10-27T17:39:37.881451Z","price_level":"115683.02","new_quantity":"0.702859"},{"side":"offer","event_time":"2025-10-27T17:39:37.881451Z","price_level":"115689.73","new_quantity":"0.16808983"},{"side":"offer","event_time":"2025-10-27T17:39:37.881451Z","price_level":"115691","new_quantity":"0"},{"side":"offer","event_time":"2025-10-27T17:39:37.881451Z","price_level":"115692","new_quantity":"0.4"},{"side":"offer","event_time":"2025-10-27T17:39:37.881451Z","price_level":"115693","new_quantity":"2"},{"side":"offer","event_time":"2025-10-27T17:39:37.881451Z","price_level":"115708.04","new_quantity":"0"},{"side":"offer","event_time":"2025-10-27T17:39:37.881451Z","price_level":"115711.32","new_quantity":"0.5"}]}]}
{"channel":"l2_data","client_id":"","timestamp":"2025-10-27T17:39:37.998459472Z","sequence_num":137479,"events":[{"type":"update","product_id":"BTC-USD","updates":[{"side":"bid","event_time":"2025-10-27T17:39:37.942686Z","price_level":"115652.01","new_quantity":"0.1419484"},{"side":"bid","event_time":"2025-10-27T17:39:37.942686Z","price_level":"115651.37","new_quantity":"0.00864667"},{"side":"bid","event_time":"2025-10-27T17:39:37.942686Z","price_level":"115649.66","new_quantity":"0"},{"side":"bid","event_time":"2025-10-27T17:39:37.942686Z","price_level":"115648.63","new_quantity":"0.16728"},{"side":"bid","event_time":"2025-10-27T17:39:37.942686Z","price_level":"115645.66","new_quantity":"0.00054422"},{"side":"bid","event_time":"2025-10-27T17:39:37.942686Z","price_level":"115639","new_quantity":"0.4"},{"side":"bid","event_time":"2025-10-27T17:39:37.942686Z","price_level":"115633.01","new_quantity":"2.4550732"},{"side":"bid","event_time":"2025-10-27T17:39:37.942686Z","price_level":"115633","new_quantity":"2"},{"side":"bid","event_time":"2025-10-27T17:39:37.942686Z","price_level":"115630.72","new_quantity":"0.36875386"},{"side":"bid","event_time":"2025-10-27T17:39:37.942686Z","price_level":"115625.01","new_quantity":"0"},{"side":"bid","event_time":"2025-10-27T17:39:37.942686Z","price_level":"115620","new_quantity":"1"},{"side":"bid","event_time":"2025-10-27T17:39:37.942686Z","price_level":"114983.1","new_quantity":"0.07007"},{"side":"bid","event_time":"2025-10-27T17:39:37.942686Z","price_level":"114982.3","new_quantity":"0"},{"side":"bid","event_time":"2025-10-27T17:39:37.942686Z","price_level":"114767.71","new_quantity":"0.07007"},{"side":"bid","event_time":"2025-10-27T17:39:37.942686Z","price_level":"114767.65","new_quantity":"0"},{"side":"bid","event_time":"2025-10-27T17:39:37.942686Z","price_level":"114552.46","new_quantity":"0.07007"},{"side":"bid","event_time":"2025-10-27T17:39:37.942686Z","price_level":"114552.32","new_quantity":"0"},{"side":"bid","event_time":"2025-10-27T17:39:37.942686Z","price_level":"114338.03","new_quantity":"0.07007"},{"side":"bid","event_time":"2025-10-27T17:39:37.942686Z","price_level":"114337.49","new_quantity":"0"},{"side":"bid","event_time":"2025-10-27T17:39:37.942686Z","price_level":"114123.6","new_quantity":"0.07007"},{"side":"offer","event_time":"2025-10-27T17:39:37.942686Z","price_level":"115683.02","new_quantity":"0"},{"side":"offer","event_time":"2025-10-27T17:39:37.942686Z","price_level":"115683.24","new_quantity":"0"},{"side":"offer","event_time":"2025-10-27T17:39:37.942686Z","price_level":"115683.25","new_quantity":"0"},{"side":"offer","event_time":"2025-10-27T17:39:37.942686Z","price_level":"115689.72","new_quantity":"0"},{"side":"offer","event_time":"2025-10-27T17:39:37.942686Z","price_level":"115692","new_quantity":"0"},{"side":"offer","event_time":"2025-10-27T17:39:37.942686Z","price_level":"115693","new_quantity":"0"},{"side":"offer","event_time":"2025-10-27T17:39:37.942686Z","price_level":"115709.17","new_quantity":"0.5"},{"side":"offer","event_time":"2025-10-27T17:39:37.942686Z","price_level":"115711.32","new_quantity":"0"},{"side":"offer","event_time":"2025-10-27T17:39:37.942686Z","price_level":"115715.05","new_quantity":"0.12"},{"side":"offer","event_time":"2025-10-27T17:39:37.942686Z","price_level":"115719.91","new_quantity":"0"},{"side":"offer","event_time":"2025-10-27T17:39:37.942686Z","price_level":"115734.66","new_quantity":"0"},{"side":"offer","event_time":"2025-10-27T17:39:37.942686Z","price_level":"115738.38","new_quantity":"0.00043223"},{"side":"offer","event_time":"2025-10-27T17:39:37.942686Z","price_level":"115742.49","new_quantity":"0"},{"side":"offer","event_time":"2025-10-27T17:39:37.942686Z","price_level":"115754.99","new_quantity":"0.48017812"},{"side":"offer","event_time":"2025-10-27T17:39:37.942686Z","price_level":"115806.94","new_quantity":"0.00017286"}]}]}
{"channel":"l2_data","client_id":"","timestamp":"2025-10-27T17:39:38.027934468Z","sequence_num":137480,"events":[{"type":"update","product_id":"ETH-USD","updates":[{"side":"bid","event_time":"2025-10-27T17:39:37.721791Z","price_level":"4217","new_quantity":"3.97656773"},{"side":"bid","event_time":"2025-10-27T17:39:37.721791Z","price_level":"4215.53","new_quantity":"10.74148787"},{"side":"bid","event_time":"2025-10-27T17:39:37.721791Z","price_level":"4214.29","new_quantity":"19.62441285"},{"side":"bid","event_time":"2025-10-27T17:39:37.721791Z","price_level":"4214.28","new_quantity":"0.0019612"},{"side":"bid","event_time":"2025-10-27T17:39:37.721791Z","price_level":"4214.27","new_quantity":"0"},{"side":"bid","event_time":"2025-10-27T17:39:37.721791Z","price_level":"4214.26","new_quantity":"0"},{"side":"offer","event_time":"2025-10-27T17:39:37.721791Z","price_level":"4219.54","new_quantity":"0.4923825"},{"side":"offer","event_time":"2025-10-27T17:39:37.721791Z","price_level":"4219.98","new_quantity":"9.6600228"},{"side":"offer","event_time":"2025-10-27T17:39:37.721791Z","price_level":"4224.53","new_quantity":"0"}]}]}
{"channel":"l2_data","client_id":"","timestamp":"2025-10-27T17:39:38.028173011Z","sequence_num":137481,"events":[{"type":"update","product_id":"ETH-USD","updates":[{"side":"offer","event_time":"2025-10-27T17:39:37.733202Z","price_level":"4218.57","new_quantity":"0.0592698"},{"side":"offer","event_time":"2025-10-27T17:39:37.733202Z","price_level":"4219","new_quantity":"0.56673983"}]}]}
{"channel":"l2_data","client_id":"","timestamp":"2025-10-27T17:39:38.028326788Z","sequence_num":137482,"events":[{"type":"update","product_id":"ETH-USD","updates":[{"side":"bid","event_time":"2025-10-27T17:39:37.827466Z","price_level":"4201.74","new_quantity":"0.12377419"}]}]}
{"channel":"l2_data","client_id":"","timestamp":"2025-10-27T17:39:38.028572494Z","sequence_num":137483,"events":[{"type":"update","product_id":"ETH-USD","updates":[{"side":"offer","event_time":"2025-10-27T17:39:37.878042Z","price_level":"4219","new_quantity":"0.0602698"}]}]}
{"channel":"l2_data","client_id":"","timestamp":"2025-10-27T17:39:38.028803234Z","sequence_num":137484,"events":[{"type":"update","product_id":"ETH-USD","updates":[{"side":"bid","event_time":"2025-10-27T17:39:37.966614Z","price_level":"4206.4","new_quantity":"0"},{"side":"offer","event_time":"2025-10-27T17:39:37.966614Z","price_level":"4228.96","new_quantity":"0"}]}]}
{"channel":"l2_data","client_id":"","timestamp":"2025-10-27T17:39:38.046903239Z","sequence_num":137485,"events":[{"type":"update","product_id":"BTC-USD","updates":[{"side":"bid","event_time":"2025-10-27T17:39:37.998694Z","price_level":"115651.12","new_quantity":"0"},{"side":"offer","event_time":"2025-10-27T17:39:37.998694Z","price_level":"115662.07","new_quantity":"0.02822416"},{"side":"offer","event_time":"2025-10-27T17:39:37.998694Z","price_level":"115666.37","new_quantity":"0"},{"side":"offer","event_time":"2025-10-27T17:39:37.998694Z","price_level":"115689.72","new_quantity":"0.00085452"},{"side":"offer","event_time":"2025-10-27T17:39:37.998694Z","price_level":"115692","new_quantity":"0"},{"side":"offer","event_time":"2025-10-27T17:39:37.998694Z","price_level":"115693","new_quantity":"0"},{"side":"offer","event_time":"2025-10-27T17:39:37.998694Z","price_level":"115698","new_quantity":"0"},{"side":"offer","event_time":"2025-10-27T17:39:37.998694Z","price_level":"115708.32","new_quantity":"0.5"},{"side":"offer","event_time":"2025-10-27T17:39:37.998694Z","price_level":"115709.17","new_quantity":"0"},{"side":"offer","event_time":"2025-10-27T17:39:37.998694Z","price_level":"115735.1","new_quantity":"0.00043229"}]}]}
{"channel":"l2_data","client_id":"","timestamp":"2025-10-27T17:39:38.072577431Z","sequence_num":137486,"events":[{"type":"update","product_id":"ETH-USD","updates":[{"side":"bid","event_time":"2025-10-27T17:39:38.021816Z","price_level":"4218.84","new_quantity":"1.217662"},{"side":"bid","event_time":"2025-10-27T17:39:38.021816Z","price_level":"4218.65","new_quantity":"0.01373384"},{"side":"bid","event_time":"2025-10-27T17:39:38.021816Z","price_level":"4218.6","new_quantity":"0.519"},{"side":"bid","event_time":"2025-10-27T17:39:38.021816Z","price_level":"4218.5","new_quantity":"0.519"},{"side":"bid","event_time":"2025-10-27T17:39:38.021816Z","price_level":"4218.46","new_quantity":"0.02070633"},{"side":"bid","event_time":"2025-10-27T17:39:38.021816Z","price_level":"4218.45","new_quantity":"0"},{"side":"bid","event_time":"2025-10-27T17:39:38.021816Z","price_level":"4218.4","new_quantity":"10.519"},{"side":"bid","event_time":"2025-10-27T17:39:38.021816Z","price_level":"4218.3","new_quantity":"14.02696503"},{"side":"bid","event_time":"2025-10-27T17:39:38.021816Z","price_level":"4218.19","new_quantity":"0.59267055"},{"side":"bid","event_time":"2025-10-27T17:39:38.021816Z","price_level":"4218.11","new_quantity":"0"},{"side":"bid","event_time":"2025-10-27T17:39:38.021816Z","price_level":"4218","new_quantity":"10.957"},{"side":"bid","event_time":"2025-10-27T17:39:38.021816Z","price_level":"4217.78","new_quantity":"0"},{"side":"bid","event_time":"2025-10-27T17:39:38.021816Z","price_level":"4217.73","new_quantity":"3.80959614"},{"side":"bid","event_time":"2025-10-27T17:39:38.021816Z","price_level":"4217.72","new_quantity":"5.77923307"},{"side":"bid","event_time":"2025-10-27T17:39:38.021816Z","price_level":"4217.71","new_quantity":"0"},{"side":"bid","event_time":"2025-10-27T17:39:38.021816Z","price_level":"4217.7","new_quantity":"0"},{"side":"bid","event_time":"2025-10-27T17:39:38.021816Z","price_level":"4217.62","new_quantity":"0"},{"side":"bid","event_time":"2025-10-27T17:39:38.021816Z","price_level":"4217.61","new_quantity":"0"},{"side":"bid","event_time":"2025-10-27T17:39:38.021816Z","price_level":"4217.6","new_quantity":"20"},{"side":"bid","event_time":"2025-10-27T17:39:38.021816Z","price_level":"4217.5","new_quantity":"0.001"},{"side":"bid","event_time":"2025-10-27T17:39:38.021816Z","price_level":"4217.43","new_quantity":"10"},{"side":"bid","event_time":"2025-10-27T17:39:38.021816Z","price_level":"4217.41","new_quantity":"17.89802412"},{"side":"bid","event_time":"2025-10-27T17:39:38.021816Z","price_level":"4215.75","new_quantity":"0"},{"side":"bid","event_time":"2025-10-27T17:39:38.021816Z","price_level":"4215.5","new_quantity":"0"},{"side":"bid","event_time":"2025-10-27T17:39:38.021816Z","price_level":"4215.37","new_quantity":"8.84516745"},{"side":"bid","event_time":"2025-10-27T17:39:38.021816Z","price_level":"4215.34","new_quantity":"0"},{"side":"bid","event_time":"2025-10-27T17:39:38.021816Z","price_level":"4214.77","new_quantity":"17.63112789"},{"side":"bid","event_time":"2025-10-27T17:39:38.021816Z","price_level":"4214.59","new_quantity":"0"},{"side":"bid","event_time":"2025-10-27T17:39:38.021816Z","price_level":"4214.51","new_quantity":"19.62142018"},{"side":"bid","event_time":"2025-10-27T17:39:38.021816Z","price_level":"4214.29","new_quantity":"0.00196837"},{"side":"bid","event_time":"2025-10-27T17:39:38.021816Z","price_level":"4213.96","new_quantity":"25.35211295"},{"side":"bid","event_time":"2025-10-27T17:39:38.021816Z","price_level":"4212.73","new_quantity":"0.1536"},{"side":"bid","event_time":"2025-10-27T17:39:38.021816Z","price_level":"4212.19","new_quantity":"37.2225"},{"side":"bid","event_time":"2025-10-27T17:39:38.021816Z","price_level":"4212.16","new_quantity":"0"},{"side":"bid","event_time":"2025-10-27T17:39:38.021816Z","price_level":"4212.01","new_quantity":"0"},{"side":"bid","event_time":"2025-10-27T17:39:38.021816Z","price_level":"4210.06","new_quantity":"50.565"},{"side":"bid","event_time":"2025-10-27T17:39:38.021816Z","price_level":"4207.93","new_quantity":"73.0875"},{"side":"bid","event_time":"2025-10-27T17:39:38.021816Z","price_level":"4207.79","new_quantity":"0"},{"side":"bid","event_time":"2025-10-27T17:39:38.021816Z","price_level":"4203.86","new_quantity":"0"},{"side":"bid","event_time":"2025-10-27T17:39:38.021816Z","price_level":"4201.05","new_quantity":"0"},{"side":"bid","event_time":"2025-10-27T17:39:38.021816Z","price_level":"4199.99","new_quantity":"0"},{"side":"bid","event_time":"2025-10-27T17:39:38.021816Z","price_level":"4198.92","new_quantity":"0"},{"side":"bid","event_time":"2025-10-27T17:39:38.021816Z","price_level":"4196.66","new_quantity":"74.2875"},{"side":"bid","event_time":"2025-10-27T17:39:38.021816Z","price_level":"4191.63","new_quantity":"0.1536"},{"side":"bid","event_time":"2025-10-27T17:39:38.021816Z","price_level":"4189.41","new_quantity":"0"},{"side":"bid","event_time":"2025-10-27T17:39:38.021816Z","price_level":"4107.02","new_quantity":"0"},{"side":"offer","event_time":"2025-10-27T17:39:38.021816Z","price_level":"4218.46","new_quantity":"0"},{"side":"offer","event_time":"2025-10-27T17:39:38.021816Z","price_level":"4218.5","new_quantity":"0"},{"side":"offer","event_time":"2025-10-27T17:39:38.021816Z","price_level":"4218.57","new_quantity":"0"},{"side":"offer","event_time":"2025-10-27T17:39:38.021816Z","price_level":"4218.58","new_quantity":"0"},{"side":"offer","event_time":"2025-10-27T17:39:38.021816Z","price_level":"4218.61","new_quantity":"0"},{"side":"offer","event_time":"2025-10-27T17:39:38.021816Z","price_level":"4218.62","new_quantity":"0"},{"side":"offer","event_time":"2025-10-27T17:39:38.021816Z","price_level":"4218.63","new_quantity":"0"},{"side":"offer","event_time":"2025-10-27T17:39:38.021816Z","price_level":"4218.64","new_quantity":"0"},{"side":"offer","event_time":"2025-10-27T17:39:38.021816Z","price_level":"4218.67","new_quantity":"0"},{"side":"offer","event_time":"2025-10-27T17:39:38.021816Z","price_level":"4218.73","new_quantity":"0"},{"side":"offer","event_time":"2025-10-27T17:39:38.021816Z","price_level":"4218.75","new_quantity":"0"},{"side":"offer","event_time":"2025-10-27T17:39:38.021816Z","price_level":"4218.78","new_quantity":"0"},{"side":"offer","event_time":"2025-10-27T17:39:38.021816Z","price_level":"4218.79","new_quantity":"0"},{"side":"offer","event_time":"2025-10-27T17:39:38.021816Z","price_level":"4218.83","new_quantity":"0"},{"side":"offer","event_time":"2025-10-27T17:39:38.021816Z","price_level":"4218.85","new_quantity":"0.16876"},{"side":"offer","event_time":"2025-10-27T17:39:38.021816Z","price_level":"4218.89","new_quantity":"0.0643914"},{"side":"offer","event_time":"2025-10-27T17:39:38.021816Z","price_level":"4218.9","new_quantity":"0.519"},{"side":"offer","event_time":"2025-10-27T17:39:38.021816Z","price_level":"4218.95","new_quantity":"0"},{"side":"offer","event_time":"2025-10-27T17:39:38.021816Z","price_level":"4218.96","new_quantity":"0"},{"side":"offer","event_time":"2025-10-27T17:39:38.021816Z","price_level":"4218.97","new_quantity":"0"},{"side":"offer","event_time":"2025-10-27T17:39:38.021816Z","price_level":"4218.98","new_quantity":"0"},{"side":"offer","event_time":"2025-10-27T17:39:38.021816Z","price_level":"4219","new_quantity":"0.519"},{"side":"offer","event_time":"2025-10-27T17:39:38.021816Z","price_level":"4219.04","new_quantity":"0"},{"side":"offer","event_time":"2025-10-27T17:39:38.021816Z","price_level":"4219.11","new_quantity":"0"},{"side":"offer","event_time":"2025-10-27T17:39:38.021816Z","price_level":"4219.12","new_quantity":"0"},{"side":"offer","event_time":"2025-10-27T17:39:38.021816Z","price_level":"4219.14","new_quantity":"0"},{"side":"offer","event_time":"2025-10-27T17:39:38.021816Z","price_level":"4219.18","new_quantity":"0.1536"},{"side":"offer","event_time":"2025-10-27T17:39:38.021816Z","price_level":"4219.19","new_quantity":"1.125"},{"side":"offer","event_time":"2025-10-27T17:39:38.021816Z","price_level":"4219.22","new_quantity":"0.437"},{"side":"offer","event_time":"2025-10-27T17:39:38.021816Z","price_level":"4219.39","new_quantity":"0"},{"side":"offer","event_time":"2025-10-27T17:39:38.021816Z","price_level":"4219.42","new_quantity":"0"},{"side":"offer","event_time":"2025-10-27T17:39:38.021816Z","price_level":"4219.45","new_quantity":"0"},{"side":"offer","event_time":"2025-10-27T17:39:38.021816Z","price_level":"4219.46","new_quantity":"0"},{"side":"offer","event_time":"2025-10-27T17:39:38.021816Z","price_level":"4219.49","new_quantity":"0"},{"side":"offer","event_time":"2025-10-27T17:39:38.021816Z","price_level":"4219.5","new_quantity":"0.001"},{"side":"offer","event_time":"2025-10-27T17:39:38.021816Z","price_level":"4219.52","new_quantity":"0"},{"side":"offer","event_time":"2025-10-27T17:39:38.021816Z","price_level":"4219.54","new_quantity":"0"},{"side":"offer","event_time":"2025-10-27T17:39:38.021816Z","price_level":"4219.58","new_quantity":"0.2"},{"side":"offer","event_time":"2025-10-27T17:39:38.021816Z","price_level":"4219.59","new_quantity":"0.309843"},{"side":"offer","event_time":"2025-10-27T17:39:38.021816Z","price_level":"4219.6","new_quantity":"0.519"},{"side":"offer","event_time":"2025-10-27T17:39:38.021816Z","price_level":"4219.63","new_quantity":"0"},{"side":"offer","event_time":"2025-10-27T17:39:38.021816Z","price_level":"4219.64","new_quantity":"0"},{"side":"offer","event_time":"2025-10-27T17:39:38.021816Z","price_level":"4219.75","new_quantity":"0"},{"side":"offer","event_time":"2025-10-27T17:39:38.021816Z","price_level":"4219.82","new_quantity":"1.43531872"},{"side":"offer","event_time":"2025-10-27T17:39:38.021816Z","price_level":"4219.83","new_quantity":"1.88521896"},{"side":"offer","event_time":"2025-10-27T17:39:38.021816Z","price_level":"4219.85","new_quantity":"0.5"},{"side":"offer","event_time":"2025-10-27T17:39:38.021816Z","price_level":"4219.9","new_quantity":"0.519"},{"side":"offer","event_time":"2025-10-27T17:39:38.021816Z","price_level":"4220","new_quantity":"12.80517286"},{"side":"offer","event_time":"2025-10-27T17:39:38.021816Z","price_level":"4220.2","new_quantity":"0"},{"side":"offer","event_time":"2025-10-27T17:39:38.021816Z","price_level":"4220.23","new_quantity":"0"},{"side":"offer","event_time":"2025-10-27T17:39:38.021816Z","price_level":"4220.36","new_quantity":"0.19287692"},{"side":"offer","event_time":"2025-10-27T17:39:38.021816Z","price_level":"4220.46","new_quantity":"0.51743178"},{"side":"offer","event_time":"2025-10-27T17:39:38.021816Z","price_level":"4220.83","new_quantity":"0.00911344"},{"side":"offer","event_time":"2025-10-27T17:39:38.021816Z","price_level":"4221.1","new_quantity":"8.53411561"},{"side":"offer","event_time":"2025-10-27T17:39:38.021816Z","price_level":"4221.68","new_quantity":"0.09871233"},{"side":"offer","event_time":"2025-10-27T17:39:38.021816Z","price_level":"4221.84","new_quantity":"1.94391607"},{"side":"offer","event_time":"2025-10-27T17:39:38.021816Z","price_level":"4221.85","new_quantity":"0.30652551"},{"side":"offer","event_time":"2025-10-27T17:39:38.021816Z","price_level":"4222.12","new_quantity":"13.49296996"},{"side":"offer","event_time":"2025-10-27T17:39:38.021816Z","price_level":"4222.13","new_quantity":"0.07776196"},{"side":"offer","event_time":"2025-10-27T17:39:38.021816Z","price_level":"4222.16","new_quantity":"3.49907796"},{"side":"offer","event_time":"2025-10-27T17:39:38.021816Z","price_level":"4223.22","new_quantity":"0"},{"side":"offer","event_time":"2025-10-27T17:39:38.021816Z","price_level":"4223.45","new_quantity":"9.72530687"},{"side":"offer","event_time":"2025-10-27T17:39:38.021816Z","price_level":"4227.53","new_quantity":"0"},{"side":"offer","event_time":"2025-10-27T17:39:38.021816Z","price_level":"4232.12","new_quantity":"0"},{"side":"offer","event_time":"2025-10-27T17:39:38.021816Z","price_level":"4233.19","new_quantity":"0"},{"side":"offer","event_time":"2025-10-27T17:39:38.021816Z","price_level":"4235.28","new_quantity":"0"},{"side":"offer","event_time":"2025-10-27T17:39:38.021816Z","price_level":"4237.87","new_quantity":"0"},{"side":"offer","event_time":"2025-10-27T17:39:38.021816Z","price_level":"4244.82","new_quantity":"0"}]}]}
{"channel":"l2_data","client_id":"","timestamp":"2025-10-27T17:39:37.516648206Z","sequence_num":137457,"events":[{"type":"update","product_id":"BTC-USD","updates":[{"side":"bid","event_time":"2025-10-27T17:39:37.100555Z","price_level":"115650.85","new_quantity":"0"},{"side":"bid","event_time":"2025-10-27T17:39:37.100555Z","price_level":"115636.22","new_quantity":"0.33052746"},{"side":"bid","event_time":"2025-10-27T17:39:37.100555Z","price_level":"115635.01","new_quantity":"0"},{"side":"bid","event_time":"2025-10-27T17:39:37.100555Z","price_level":"115631.36","new_quantity":"0"},{"side":"bid","event_time":"2025-10-27T17:39:37.100555Z","price_level":"115620.65","new_quantity":"0.52628515"},{"side":"bid","event_time":"2025-10-27T17:39:37.100555Z","price_level":"115612.8","new_quantity":"0"},{"side":"bid","event_time":"2025-10-27T17:39:37.100555Z","price_level":"115579.93","new_quantity":"1.20609685"},{"side":"bid","event_time":"2025-10-27T17:39:37.100555Z","price_level":"115576.69","new_quantity":"0"},{"side":"bid","event_time":"2025-10-27T17:39:37.100555Z","price_level":"114982.2","new_quantity":"0.07007"},{"side":"bid","event_time":"2025-10-27T17:39:37.100555Z","price_level":"114981.77","new_quantity":"0"},{"side":"bid","event_time":"2025-10-27T17:39:37.100555Z","price_level":"114977.6","new_quantity":"0"},{"side":"bid","event_time":"2025-10-27T17:39:37.100555Z","price_level":"114766.93","new_quantity":"0.07007"},{"side":"bid","event_time":"2025-10-27T17:39:37.100555Z","price_level":"114548.59","new_quantity":"0"},{"side":"bid","event_time":"2025-10-27T17:39:37.100555Z","price_level":"114124.05","new_quantity":"0"},{"side":"offer","event_time":"2025-10-27T17:39:37.100555Z","price_level":"115664.01","new_quantity":"0.02876617"},{"side":"offer","event_time":"2025-10-27T17:39:37.100555Z","price_level":"115708.32","new_quantity":"0.5"},{"side":"offer","event_time":"2025-10-27T17:39:37.100555Z","price_level":"115708.82","new_quantity":"0"},{"side":"offer","event_time":"2025-10-27T17:39:37.100555Z","price_level":"115738.38","new_quantity":"0"}]}]}
{"channel":"l2_data","client_id":"","timestamp":"2025-10-27T17:39:37.517779154Z","sequence_num":137458,"events":[{"type":"update","product_id":"BTC-USD","updates":[{"side":"bid","event_time":"2025-10-27T17:39:37.325607Z","price_level":"115664","new_quantity":"0"},{"side":"bid","event_time":"2025-10-27T17:39:37.325607Z","price_level":"115662.06","new_quantity":"0.02409246"},{"side":"bid","event_time":"2025-10-27T17:39:37.325607Z","price_level":"115662.05","new_quantity":"0"},{"side":"bid","event_time":"2025-10-27T17:39:37.325607Z","price_level":"115662.03","new_quantity":"0"},{"side":"bid","event_time":"2025-10-27T17:39:37.325607Z","price_level":"115662.01","new_quantity":"0"},{"side":"bid","event_time":"2025-10-27T17:39:37.325607Z","price_level":"115652.02","new_quantity":"0"},{"side":"bid","event_time":"2025-10-27T17:39:37.325607Z","price_level":"115652.01","new_quantity":"0.13016322"},{"side":"bid","event_time":"2025-10-27T17:39:37.325607Z","price_level":"115651.51","new_quantity":"0"},{"side":"bid","event_time":"2025-10-27T17:39:37.325607Z","price_level":"115650.7","new_quantity":"0"},{"side":"bid","event_time":"2025-10-27T17:39:37.325607Z","price_level":"115649.66","new_quantity":"0.0086468"},{"side":"bid","event_time":"2025-10-27T17:39:37.325607Z","price_level":"115649.58","new_quantity":"0"},{"side":"bid","event_time":"2025-10-27T17:39:37.325607Z","price_level":"115645.66","new_quantity":"0.00121414"},{"side":"bid","event_time":"2025-10-27T17:39:37.325607Z","price_level":"115645.6","new_quantity":"0.69585981"},{"side":"bid","event_time":"2025-10-27T17:39:37.325607Z","price_level":"115644.51","new_quantity":"0"},{"side":"bid","event_time":"2025-10-27T17:39:37.325607Z","price_level":"115641.07","new_quantity":"0.712078"},{"side":"bid","event_time":"2025-10-27T17:39:37.325607Z","price_level":"115640.31","new_quantity":"0.08647503"},{"side":"bid","event_time":"2025-10-27T17:39:37.325607Z","price_level":"115640.01","new_quantity":"0.63560392"},{"side":"bid","event_time":"2025-10-27T17:39:37.325607Z","price_level":"115636.22","new_quantity":"0"},{"side":"bid","event_time":"2025-10-27T17:39:37.325607Z","price_level":"115636.21","new_quantity":"0"},{"side":"bid","event_time":"2025-10-27T17:39:37.325607Z","price_level":"115634.69","new_quantity":"0.33053183"},{"side":"bid","event_time":"2025-10-27T17:39:37.325607Z","price_level":"115620.65","new_quantity":"0"},{"side":"bid","event_time":"2025-10-27T17:39:37.325607Z","price_level":"115612.8","new_quantity":"0.52632089"},{"side":"bid","event_time":"2025-10-27T17:39:37.325607Z","price_level":"115601.42","new_quantity":"0"},{"side":"bid","event_time":"2025-10-27T17:39:37.325607Z","price_level":"115596.71","new_quantity":"0.78060617"},{"side":"bid","event_time":"2025-10-27T17:39:37.325607Z","price_level":"115576.7","new_quantity":"0"},{"side":"bid","event_time":"2025-10-27T17:39:37.325607Z","price_level":"115567.27","new_quantity":"0.00043224"},{"side":"bid","event_time":"2025-10-27T17:39:37.325607Z","price_level":"115511.79","new_quantity":"0"},{"side":"bid","event_time":"2025-10-27T17:39:37.325607Z","price_level":"114933.48","new_quantity":"0.045"},{"side":"bid","event_time":"2025-10-27T17:39:37.325607Z","price_level":"114766.94","new_quantity":"0.07007"},{"side":"bid","event_time":"2025-10-27T17:39:37.325607Z","price_level":"114766.93","new_quantity":"0"},{"side":"bid","event_time":"2025-10-27T17:39:37.325607Z","price_level":"114763.03","new_quantity":"0"},{"side":"bid","event_time":"2025-10-27T17:39:37.325607Z","price_level":"114338.08","new_quantity":"0.07007"},{"side":"offer","event_time":"2025-10-27T17:39:37.325607Z","price_level":"115662.07","new_quantity":"0.02901483"},{"side":"offer","event_time":"2025-10-27T17:39:37.325607Z","price_level":"115663.99","new_quantity":"0"},{"side":"offer","event_time":"2025-10-27T17:39:37.325607Z","price_level":"115664","new_quantity":"0"},{"side":"offer","event_time":"2025-10-27T17:39:37.325607Z","price_level":"115664.01","new_quantity":"0"},{"side":"offer","event_time":"2025-10-27T17:39:37.325607Z","price_level":"115666","new_quantity":"0"},{"side":"offer","event_time":"2025-10-27T17:39:37.325607Z","price_level":"115666.38","new_quantity":"0.25936664"},{"side":"offer","event_time":"2025-10-27T17:39:37.325607Z","price_level":"115666.41","new_quantity":"0"},{"side":"offer","event_time":"2025-10-27T17:39:37.325607Z","price_level":"115666.42","new_quantity":"0.012559"},{"side":"offer","event_time":"2025-10-27T17:39:37.325607Z","price_level":"115672.66","new_quantity":"0"},{"side":"offer","event_time":"2025-10-27T17:39:37.325607Z","price_level":"115675.8","new_quantity":"0.16637"},{"side":"offer","event_time":"2025-10-27T17:39:37.325607Z","price_level":"115683.25","new_quantity":"0.04"},{"side":"offer","event_time":"2025-10-27T17:39:37.325607Z","price_level":"115683.89","new_quantity":"0"},{"side":"offer","event_time":"2025-10-27T17:39:37.325607Z","price_level":"115689.59","new_quantity":"0"},{"side":"offer","event_time":"2025-10-27T17:39:37.325607Z","price_level":"115689.6","new_quantity":"0.00001"},{"side":"offer","event_time":"2025-10-27T17:39:37.325607Z","price_level":"115689.72","new_quantity":"0.00356272"},{"side":"offer","event_time":"2025-10-27T17:39:37.325607Z","price_level":"115689.73","new_quantity":"0.14744478"},{"side":"offer","event_time":"2025-10-27T17:39:37.325607Z","price_level":"115692","new_quantity":"0"},{"side":"offer","event_time":"2025-10-27T17:39:37.325607Z","price_level":"115694","new_quantity":"0"},{"side":"offer","event_time":"2025-10-27T17:39:37.325607Z","price_level":"115706.59","new_quantity":"0.02014916"},{"side":"offer","event_time":"2025-10-27T17:39:37.325607Z","price_level":"115711.99","new_quantity":"0.17929652"},{"side":"offer","event_time":"2025-10-27T17:39:37.325607Z","price_level":"115715.04","new_quantity":"0"},{"side":"offer","event_time":"2025-10-27T17:39:37.325607Z","price_level":"115729.99","new_quantity":"0.25112501"},{"side":"offer","event_time":"2025-10-27T17:39:37.325607Z","price_level":"115734.66","new_quantity":"0.0004323"},{"side":"offer","event_time":"2025-10-27T17:39:37.325607Z","price_level":"115734.79","new_quantity":"0"},{"side":"offer","event_time":"2025-10-27T17:39:37.325607Z","price_level":"115740.39","new_quantity":"0.38642573"},{"side":"offer","event_time":"2025-10-27T17:39:37.325607Z","price_level":"115740.4","new_quantity":"1"},{"side":"offer","event_time":"2025-10-27T17:39:37.325607Z","price_level":"115743.92","new_quantity":"0"},{"side":"offer","event_time":"2025-10-27T17:39:37.325607Z","price_level":"115745.2","new_quantity":"0.57739058"},{"side":"offer","event_time":"2025-10-27T17:39:37.325607Z","price_level":"115746.5","new_quantity":"0"},{"side":"offer","event_time":"2025-10-27T17:39:37.325607Z","price_level":"115747.59","new_quantity":"0"},{"side":"offer","event_time":"2025-10-27T17:39:37.325607Z","price_level":"115774.21","new_quantity":"0.13334184"},{"side":"offer","event_time":"2025-10-27T17:39:37.325607Z","price_level":"115809.57","new_quantity":"0.42253492"},{"side":"offer","event_time":"2025-10-27T17:39:37.325607Z","price_level":"115812.95","new_quantity":"0.045"},{"side":"offer","event_time":"2025-10-27T17:39:37.325607Z","price_level":"115812.96","new_quantity":"0"},{"side":"offer","event_time":"2025-10-27T17:39:37.325607Z","price_level":"116391.26","new_quantity":"0.045"},{"side":"offer","event_time":"2025-10-27T17:39:37.325607Z","price_level":"130121.98","new_quantity":"0.00005086"},{"side":"offer","event_time":"2025-10-27T17:39:37.325607Z","price_level":"130122.01","new_quantity":"0"}]}]}
{"channel":"l2_data","client_id":"","timestamp":"2025-10-27T17:39:38.32046235Z","sequence_num":137498,"events":[{"type":"update","product_id":"ETH-USD","updates":[{"side":"bid","event_time":"2025-10-27T17:39:38.280329Z","price_level":"4218.73","new_quantity":"0.03744095"},{"side":"bid","event_time":"2025-10-27T17:39:38.280329Z","price_level":"4218.72","new_quantity":"0.06811407"},{"side":"bid","event_time":"2025-10-27T17:39:38.280329Z","price_level":"4218.71","new_quantity":"0"},{"side":"bid","event_time":"2025-10-27T17:39:38.280329Z","price_level":"4218.01","new_quantity":"15.2900825"},{"side":"bid","event_time":"2025-10-27T17:39:38.280329Z","price_level":"4217.95","new_quantity":"0"},{"side":"bid","event_time":"2025-10-27T17:39:38.280329Z","price_level":"4216.17","new_quantity":"3.27139153"},{"side":"bid","event_time":"2025-10-27T17:39:38.280329Z","price_level":"4206.95","new_quantity":"33.67501599"},{"side":"offer","event_time":"2025-10-27T17:39:38.280329Z","price_level":"4219.18","new_quantity":"1.086114"},{"side":"offer","event_time":"2025-10-27T17:39:38.280329Z","price_level":"4219.35","new_quantity":"0.33903666"},{"side":"offer","event_time":"2025-10-27T17:39:38.280329Z","price_level":"4219.36","new_quantity":"0.56690061"},{"side":"offer","event_time":"2025-10-27T17:39:38.280329Z","price_level":"4219.76","new_quantity":"1.4"},{"side":"offer","event_time":"2025-10-27T17:39:38.280329Z","price_level":"4222.11","new_quantity":"0"},{"side":"offer","event_time":"2025-10-27T17:39:38.280329Z","price_level":"4222.37","new_quantity":"13.41418816"},{"side":"offer","event_time":"2025-10-27T17:39:38.280329Z","price_level":"4222.38","new_quantity":"1.94391607"},{"side":"offer","event_time":"2025-10-27T17:39:38.280329Z","price_level":"4222.39","new_quantity":"0.31351169"},{"side":"offer","event_time":"2025-10-27T17:39:38.280329Z","price_level":"4229.28","new_quantity":"33.97892917"}]}]}
{"channel":"l2_data","client_id":"","timestamp":"2025-10-27T17:39:38.347183668Z","sequence_num":137500,"events":[{"type":"update","product_id":"BTC-USD","updates":[{"side":"bid","event_time":"2025-10-27T17:39:38.300416Z","price_level":"115662.06","new_quantity":"0.03517277"},{"side":"bid","event_time":"2025-10-27T17:39:38.300416Z","price_level":"115657.16","new_quantity":"0.00200363"},{"side":"bid","event_time":"2025-10-27T17:39:38.300416Z","price_level":"115633.01","new_quantity":"1.99612714"},{"side":"bid","event_time":"2025-10-27T17:39:38.300416Z","price_level":"115633","new_quantity":"2"},{"side":"bid","event_time":"2025-10-27T17:39:38.300416Z","price_level":"115632","new_quantity":"0.4"},{"side":"bid","event_time":"2025-10-27T17:39:38.300416Z","price_level":"114552.8","new_quantity":"0.07007"},{"side":"bid","event_time":"2025-10-27T17:39:38.300416Z","price_level":"114552.79","new_quantity":"0.07007"},{"side":"bid","event_time":"2025-10-27T17:39:38.300416Z","price_level":"114552.76","new_quantity":"0"},{"side":"bid","event_time":"2025-10-27T17:39:38.300416Z","price_level":"114552.58","new_quantity":"0"},{"side":"bid","event_time":"2025-10-27T17:39:38.300416Z","price_level":"114338.03","new_quantity":"0"},{"side":"bid","event_time":"2025-10-27T17:39:38.300416Z","price_level":"114123.57","new_quantity":"0"},{"side":"offer","event_time":"2025-10-27T17:39:38.300416Z","price_level":"115689.59","new_quantity":"0"}]}]}
{"channel":"l2_data","client_id":"","timestamp":"2025-10-27T17:39:38.370618979Z","sequence_num":137502,"events":[{"type":"update","product_id":"ETH-USD","updates":[{"side":"bid","event_time":"2025-10-27T17:39:38.311197Z","price_level":"4218.84","new_quantity":"1.69374574"},{"side":"bid","event_time":"2025-10-27T17:39:38.311197Z","price_level":"4218.73","new_quantity":"0"},{"side":"bid","event_time":"2025-10-27T17:39:38.311197Z","price_level":"4218.72","new_quantity":"0.05814737"},{"side":"offer","event_time":"2025-10-27T17:39:38.311197Z","price_level":"4218.85","new_quantity":"0.19768138"},{"side":"offer","event_time":"2025-10-27T17:39:38.311197Z","price_level":"4222.39","new_quantity":"7.99675944"}]}]}
{"channel":"l2_data","client_id":"","timestamp":"2025-10-27T17:39:38.39443134Z","sequence_num":137504,"events":[{"type":"update","product_id":"BTC-USD","updates":[{"side":"offer","event_time":"2025-10-27T17:39:38.347945Z","price_level":"115692","new_quantity":"0"},{"side":"offer","event_time":"2025-10-27T17:39:38.347945Z","price_level":"115693","new_quantity":"0"}]}]}
{"channel":"l2_data","client_id":"","timestamp":"2025-10-27T17:39:38.418967167Z","sequence_num":137505,"events":[{"type":"update","product_id":"ETH-USD","updates":[{"side":"offer","event_time":"2025-10-27T17:39:38.341131Z","price_level":"4218.85","new_quantity":"0.19768138"},{"side":"offer","event_time":"2025-10-27T17:39:38.341131Z","price_level":"4222.36","new_quantity":"1.94391607"},{"side":"offer","event_time":"2025-10-27T17:39:38.341131Z","price_level":"4222.38","new_quantity":"0"}]}]}
{"channel":"l2_data","client_id":"","timestamp":"2025-10-27T17:39:38.447826076Z","sequence_num":137507,"events":[{"type":"update","product_id":"BTC-USD","updates":[{"side":"bid","event_time":"2025-10-27T17:39:38.404474Z","price_level":"115662.06","new_quantity":"0.02219027"},{"side":"bid","event_time":"2025-10-27T17:39:38.404474Z","price_level":"115627.38","new_quantity":"0"},{"side":"bid","event_time":"2025-10-27T17:39:38.404474Z","price_level":"114552.79","new_quantity":"0"},{"side":"bid","event_time":"2025-10-27T17:39:38.404474Z","price_level":"114337.59","new_quantity":"0.07007"},{"side":"bid","event_time":"2025-10-27T17:39:38.404474Z","price_level":"101204.31","new_quantity":"0.0049568"}]}]}
{"channel":"l2_data","client_id":"","timestamp":"2025-10-27T17:39:38.469490525Z","sequence_num":137508,"events":[{"type":"update","product_id":"ETH-USD","updates":[{"side":"bid","event_time":"2025-10-27T17:39:38.420935Z","price_level":"4217.9","new_quantity":"0.666"},{"side":"bid","event_time":"2025-10-27T17:39:38.420935Z","price_level":"4217.58","new_quantity":"0"}]}]}
{"channel":"l2_data","client_id":"","timestamp":"2025-10-27T17:39:38.497299108Z","sequence_num":137509,"events":[{"type":"update","product_id":"BTC-USD","updates":[{"side":"bid","event_time":"2025-10-27T17:39:38.455498Z","price_level":"114338.27","new_quantity":"0.07007"},{"side":"bid","event_time":"2025-10-27T17:39:38.455498Z","price_level":"114338.25","new_quantity":"0"},{"side":"bid","event_time":"2025-10-27T17:39:38.455498Z","price_level":"114337.59","new_quantity":"0"}]}]}
{"channel":"l2_data","client_id":"","timestamp":"2025-10-27T17:39:38.520757089Z","sequence_num":137510,"events":[{"type":"update","product_id":"ETH-USD","updates":[{"side":"bid","event_time":"2025-10-27T17:39:38.477115Z","price_level":"4218.72","new_quantity":"0"},{"side":"bid","event_time":"2025-10-27T17:39:38.477115Z","price_level":"4218.71","new_quantity":"0.06811418"},{"side":"bid","event_time":"2025-10-27T17:39:38.477115Z","price_level":"4218.58","new_quantity":"0"},{"side":"offer","event_time":"2025-10-27T17:39:38.477115Z","price_level":"4218.85","new_quantity":"0.20005212"},{"side":"offer","event_time":"2025-10-27T17:39:38.477115Z","price_level":"4219.56","new_quantity":"0.85332728"},{"side":"offer","event_time":"2025-10-27T17:39:38.477115Z","price_level":"4219.57","new_quantity":"0.51035893"},{"side":"offer","event_time":"2025-10-27T17:39:38.477115Z","price_level":"4222.34","new_quantity":"1.94391607"},{"side":"offer","event_time":"2025-10-27T17:39:38.477115Z","price_level":"4222.35","new_quantity":"13.4142517"},{"side":"offer","event_time":"2025-10-27T17:39:38.477115Z","price_level":"4222.36","new_quantity":"0"},{"side":"offer","event_time":"2025-10-27T17:39:38.477115Z","price_level":"4222.37","new_quantity":"0"}]}]}
{"channel":"l2_data","client_id":"","timestamp":"2025-10-27T17:39:38.548180974Z","sequence_num":137511,"events":[{"type":"update","product_id":"BTC-USD","updates":[{"side":"bid","event_time":"2025-10-27T17:39:38.481589Z","price_level":"115662.06","new_quantity":"0.01132646"},{"side":"bid","event_time":"2025-10-27T17:39:38.481589Z","price_level":"115633.01","new_quantity":"1.19351579"},{"side":"bid","event_time":"2025-10-27T17:39:38.481589Z","price_level":"115633","new_quantity":"0"},{"side":"bid","event_time":"2025-10-27T17:39:38.481589Z","price_level":"115632","new_quantity":"0"},{"side":"offer","event_time":"2025-10-27T17:39:38.481589Z","price_level":"115692","new_quantity":"0.4"},{"side":"offer","event_time":"2025-10-27T17:39:38.481589Z","price_level":"115693","new_quantity":"2"}]}]}
{"channel":"l2_data","client_id":"","timestamp":"2025-10-27T17:39:38.571220288Z","sequence_num":137512,"events":[{"type":"update","product_id":"ETH-USD","updates":[{"side":"bid","event_time":"2025-10-27T17:39:38.526794Z","price_level":"4218.7","new_quantity":"0"},{"side":"bid","event_time":"2025-10-27T17:39:38.526794Z","price_level":"4218.61","new_quantity":"0.07109033"},{"side":"bid","event_time":"2025-10-27T17:39:38.526794Z","price_level":"4218.6","new_quantity":"10.519"},{"side":"bid","event_time":"2025-10-27T17:39:38.526794Z","price_level":"4218.5","new_quantity":"20.519"},{"side":"bid","event_time":"2025-10-27T17:39:38.526794Z","price_level":"4218.41","new_quantity":"25.58016009"},{"side":"bid","event_time":"2025-10-27T17:39:38.526794Z","price_level":"4218.4","new_quantity":"30.519"},{"side":"bid","event_time":"2025-10-27T17:39:38.526794Z","price_level":"4218.22","new_quantity":"0"},{"side":"bid","event_time":"2025-10-27T17:39:38.526794Z","price_level":"4218.08","new_quantity":"0.5296026"},{"side":"bid","event_time":"2025-10-27T17:39:38.526794Z","price_level":"4218.04","new_quantity":"0.00237077"},{"side":"bid","event_time":"2025-10-27T17:39:38.526794Z","price_level":"4218.03","new_quantity":"5.77880833"},{"side":"bid","event_time":"2025-10-27T17:39:38.526794Z","price_level":"4218.02","new_quantity":"1.125"},{"side":"bid","event_time":"2025-10-27T17:39:38.526794Z","price_level":"4218.01","new_quantity":"9.51124677"},{"side":"bid","event_time":"2025-10-27T17:39:38.526794Z","price_level":"4217.41","new_quantity":"13.28851212"},{"side":"bid","event_time":"2025-10-27T17:39:38.526794Z","price_level":"4214.51","new_quantity":"19.62142018"},{"side":"bid","event_time":"2025-10-27T17:39:38.526794Z","price_level":"4214.26","new_quantity":"0"},{"side":"offer","event_time":"2025-10-27T17:39:38.526794Z","price_level":"4218.85","new_quantity":"0.03129212"},{"side":"offer","event_time":"2025-10-27T17:39:38.526794Z","price_level":"4219.18","new_quantity":"0.932514"},{"side":"offer","event_time":"2025-10-27T17:39:38.526794Z","price_level":"4219.34","new_quantity":"0.66834078"},{"side":"offer","event_time":"2025-10-27T17:39:38.526794Z","price_level":"4219.35","new_quantity":"0.55159819"},{"side":"offer","event_time":"2025-10-27T17:39:38.526794Z","price_level":"4221.1","new_quantity":"0"},{"side":"offer","event_time":"2025-10-27T17:39:38.526794Z","price_level":"4221.33","new_quantity":"0.03786301"},{"side":"offer","event_time":"2025-10-27T17:39:38.526794Z","price_level":"4221.51","new_quantity":"8.53328676"},{"side":"offer","event_time":"2025-10-27T17:39:38.526794Z","price_level":"4244.82","new_quantity":"0.1536"}]}]}
{"channel":"l2_data","client_id":"","timestamp":"2025-10-27T17:39:38.597257837Z","sequence_num":137514,"events":[{"type":"update","product_id":"BTC-USD","updates":[{"side":"bid","event_time":"2025-10-27T17:39:38.538166Z","price_level":"115633.01","new_quantity":"1.99612714"},{"side":"bid","event_time":"2025-10-27T17:39:38.538166Z","price_level":"115632","new_quantity":"2"},{"side":"bid","event_time":"2025-10-27T17:39:38.538166Z","price_level":"115627.52","new_quantity":"0.0069609"},{"side":"bid","event_time":"2025-10-27T17:39:38.538166Z","price_level":"114123.72","new_quantity":"0.07007"},{"side":"bid","event_time":"2025-10-27T17:39:38.538166Z","price_level":"114122.98","new_quantity":"0"},{"side":"offer","event_time":"2025-10-27T17:39:38.538166Z","price_level":"115662.07","new_quantity":"0.02807438"},{"side":"offer","event_time":"2025-10-27T17:39:38.538166Z","price_level":"115692","new_quantity":"0"},{"side":"offer","event_time":"2025-10-27T17:39:38.538166Z","price_level":"115693","new_quantity":"0"}]}]}
{"channel":"l2_data","client_id":"","timestamp":"2025-10-27T17:39:38.621159165Z","sequence_num":137515,"events":[{"type":"update","product_id":"ETH-USD","updates":[{"side":"bid","event_time":"2025-10-27T17:39:38.542735Z","price_level":"4218.71","new_quantity":"0"},{"side":"bid","event_time":"2025-10-27T17:39:38.542735Z","price_level":"4218.62","new_quantity":"0.05814826"},{"side":"offer","event_time":"2025-10-27T17:39:38.542735Z","price_level":"4222.33","new_quantity":"13.29915196"},{"side":"offer","event_time":"2025-10-27T17:39:38.542735Z","price_level":"4222.35","new_quantity":"0"}]}]}
{"channel":"l2_data","client_id":"","timestamp":"2025-10-27T17:39:38.647122459Z","sequence_num":137517,"events":[{"type":"update","product_id":"BTC-USD","updates":[{"side":"bid","event_time":"2025-10-27T17:39:38.591227Z","price_level":"115652.27","new_quantity":"0"},{"side":"bid","event_time":"2025-10-27T17:39:38.591227Z","price_level":"115650.59","new_quantity":"0.02160702"},{"side":"bid","event_time":"2025-10-27T17:39:38.591227Z","price_level":"115641.73","new_quantity":"0"},{"side":"bid","event_time":"2025-10-27T17:39:38.591227Z","price_level":"115638","new_quantity":"0"},{"side":"bid","event_time":"2025-10-27T17:39:38.591227Z","price_level":"115637.72","new_quantity":"0.00086462"},{"side":"bid","event_time":"2025-10-27T17:39:38.591227Z","price_level":"115634.25","new_quantity":"0"},{"side":"bid","event_time":"2025-10-27T17:39:38.591227Z","price_level":"115634","new_quantity":"0"},{"side":"bid","event_time":"2025-10-27T17:39:38.591227Z","price_level":"115633.01","new_quantity":"1.19351579"},{"side":"bid","event_time":"2025-10-27T17:39:38.591227Z","price_level":"115632","new_quantity":"0.4"},{"side":"bid","event_time":"2025-10-27T17:39:38.591227Z","price_level":"115626.16","new_quantity":"0.0043231"},{"side":"bid","event_time":"2025-10-27T17:39:38.591227Z","price_level":"115620","new_quantity":"0"},{"side":"offer","event_time":"2025-10-27T17:39:38.591227Z","price_level":"115708.32","new_quantity":"0"},{"side":"offer","event_time":"2025-10-27T17:39:38.591227Z","price_level":"115710.92","new_quantity":"0.5"}]}]}
{"channel":"l2_data","client_id":"","timestamp":"2025-10-27T17:39:38.671308598Z","sequence_num":137518,"events":[{"type":"update","product_id":"ETH-USD","updates":[{"side":"bid","event_time":"2025-10-27T17:39:38.601374Z","price_level":"4207.6","new_quantity":"0"},{"side":"offer","event_time":"2025-10-27T17:39:38.601374Z","price_level":"4222.32","new_quantity":"2.29851015"},{"side":"offer","event_time":"2025-10-27T17:39:38.601374Z","price_level":"4222.34","new_quantity":"0"}]}]}
{"channel":"l2_data","client_id":"","timestamp":"2025-10-27T17:39:38.697573047Z","sequence_num":137520,"events":[{"type":"update","product_id":"BTC-USD","updates":[{"side":"bid","event_time":"2025-10-27T17:39:38.642861Z","price_level":"115662.06","new_quantity":"0.03509027"},{"side":"bid","event_time":"2025-10-27T17:39:38.642861Z","price_level":"115645.66","new_quantity":"0.0008485"},{"side":"bid","event_time":"2025-10-27T17:39:38.642861Z","price_level":"115639","new_quantity":"0.4"},{"side":"bid","event_time":"2025-10-27T17:39:38.642861Z","price_level":"115637","new_quantity":"0.4"},{"side":"bid","event_time":"2025-10-27T17:39:38.642861Z","price_level":"115636","new_quantity":"0"},{"side":"bid","event_time":"2025-10-27T17:39:38.642861Z","price_level":"115633.01","new_quantity":"2.23492714"},{"side":"bid","event_time":"2025-10-27T17:39:38.642861Z","price_level":"115633","new_quantity":"2"},{"side":"bid","event_time":"2025-10-27T17:39:38.642861Z","price_level":"115630","new_quantity":"1"},{"side":"bid","event_time":"2025-10-27T17:39:38.642861Z","price_level":"115627.52","new_quantity":"0"},{"side":"bid","event_time":"2025-10-27T17:39:38.642861Z","price_level":"114338.34","new_quantity":"0.07007"},{"side":"bid","event_time":"2025-10-27T17:39:38.642861Z","price_level":"114338.27","new_quantity":"0"},{"side":"bid","event_time":"2025-10-27T17:39:38.642861Z","price_level":"114123.88","new_quantity":"0.07007"},{"side":"bid","event_time":"2025-10-27T17:39:38.642861Z","price_level":"114123.72","new_quantity":"0"}]}]}
{"channel":"l2_data","client_id":"","timestamp":"2025-10-27T17:39:38.7209316Z","sequence_num":137521,"events":[{"type":"update","product_id":"ETH-USD","updates":[{"side":"bid","event_time":"2025-10-27T17:39:38.680312Z","price_level":"4215.5","new_quantity":"0.001"},{"side":"bid","event_time":"2025-10-27T17:39:38.680312Z","price_level":"4214.51","new_quantity":"0"},{"side":"bid","event_time":"2025-10-27T17:39:38.680312Z","price_level":"4214.26","new_quantity":"19.62258417"},{"side":"offer","event_time":"2025-10-27T17:39:38.680312Z","price_level":"4218.85","new_quantity":"0.21107492"},{"side":"offer","event_time":"2025-10-27T17:39:38.680312Z","price_level":"4219.59","new_quantity":"0"},{"side":"offer","event_time":"2025-10-27T17:39:38.680312Z","price_level":"4219.75","new_quantity":"0.001"},{"side":"offer","event_time":"2025-10-27T17:39:38.680312Z","price_level":"4221.1","new_quantity":"8.53411561"},{"side":"offer","event_time":"2025-10-27T17:39:38.680312Z","price_level":"4221.51","new_quantity":"0"},{"side":"offer","event_time":"2025-10-27T17:39:38.680312Z","price_level":"4222.31","new_quantity":"13.29921496"},{"side":"offer","event_time":"2025-10-27T17:39:38.680312Z","price_level":"4222.33","new_quantity":"0"}]}]}
{"channel":"l2_data","client_id":"","timestamp":"2025-10-27T17:39:38.746637726Z","sequence_num":137522,"events":[{"type":"update","product_id":"BTC-USD","updates":[{"side":"bid","event_time":"2025-10-27T17:39:38.695195Z","price_level":"115651.83","new_quantity":"0.02160702"},{"side":"bid","event_time":"2025-10-27T17:39:38.695195Z","price_level":"115650.59","new_quantity":"0"},{"side":"bid","event_time":"2025-10-27T17:39:38.695195Z","price_level":"115640.01","new_quantity":"0.9034624"},{"side":"bid","event_time":"2025-10-27T17:39:38.695195Z","price_level":"115635.01","new_quantity":"0.33119392"},{"side":"bid","event_time":"2025-10-27T17:39:38.695195Z","price_level":"115635","new_quantity":"0.4"},{"side":"bid","event_time":"2025-10-27T17:39:38.695195Z","price_level":"115634.69","new_quantity":"0"},{"side":"bid","event_time":"2025-10-27T17:39:38.695195Z","price_level":"115633","new_quantity":"2.4"},{"side":"bid","event_time":"2025-10-27T17:39:38.695195Z","price_level":"115632","new_quantity":"0"},{"side":"bid","event_time":"2025-10-27T17:39:38.695195Z","price_level":"115613.95","new_quantity":"0.93995076"},{"side":"bid","event_time":"2025-10-27T17:39:38.695195Z","price_level":"115579.95","new_quantity":"1.20609664"},{"side":"bid","event_time":"2025-10-27T17:39:38.695195Z","price_level":"115579.93","new_quantity":"0"},{"side":"bid","event_time":"2025-10-27T17:39:38.695195Z","price_level":"115521.44","new_quantity":"0.32884445"},{"side":"offer","event_time":"2025-10-27T17:39:38.695195Z","price_level":"115754.99","new_quantity":"0"}]}]}
{"channel":"l2_data","client_id":"","timestamp":"2025-10-27T17:39:38.770580538Z","sequence_num":137523,"events":[{"type":"update","product_id":"ETH-USD","updates":[{"side":"bid","event_time":"2025-10-27T17:39:38.728023Z","price_level":"4217.22","new_quantity":"0"},{"side":"bid","event_time":"2025-10-27T17:39:38.728023Z","price_level":"4217.19","new_quantity":"0.38246031"},{"side":"bid","event_time":"2025-10-27T17:39:38.728023Z","price_level":"4215.46","new_quantity":"5.75285086"},{"side":"bid","event_time":"2025-10-27T17:39:38.728023Z","price_level":"4214.27","new_quantity":"13.59865225"},{"side":"bid","event_time":"2025-10-27T17:39:38.728023Z","price_level":"4212.2","new_quantity":"8.15810167"},{"side":"offer","event_time":"2025-10-27T17:39:38.728023Z","price_level":"4218.85","new_quantity":"0.2083171"},{"side":"offer","event_time":"2025-10-27T17:39:38.728023Z","price_level":"4219.56","new_quantity":"0.61452728"},{"side":"offer","event_time":"2025-10-27T17:39:38.728023Z","price_level":"4219.58","new_quantity":"0"},{"side":"offer","event_time":"2025-10-27T17:39:38.728023Z","price_level":"4222.3","new_quantity":"1.94391607"},{"side":"offer","event_time":"2025-10-27T17:39:38.728023Z","price_level":"4222.32","new_quantity":"0.35459408"},{"side":"offer","event_time":"2025-10-27T17:39:38.728023Z","price_level":"4222.89","new_quantity":"0.39981989"}]}]}
{"channel":"l2_data","client_id":"","timestamp":"2025-10-27T17:39:38.797284265Z","sequence_num":137524,"events":[{"type":"update","product_id":"BTC-USD","updates":[{"side":"bid","event_time":"2025-10-27T17:39:38.74871Z","price_level":"115627.77","new_quantity":"0.0069609"},{"side":"bid","event_time":"2025-10-27T17:39:38.74871Z","price_level":"114911.22","new_quantity":"0.00216134"},{"side":"bid","event_time":"2025-10-27T17:39:38.74871Z","price_level":"114910.05","new_quantity":"0"},{"side":"bid","event_time":"2025-10-27T17:39:38.74871Z","price_level":"114338.37","new_quantity":"0.07007"},{"side":"bid","event_time":"2025-10-27T17:39:38.74871Z","price_level":"114123.88","new_quantity":"0"},{"side":"bid","event_time":"2025-10-27T17:39:38.74871Z","price_level":"101204.31","new_quantity":"0"},{"side":"offer","event_time":"2025-10-27T17:39:38.74871Z","price_level":"115662.07","new_quantity":"0.02798878"}]}]}
{"channel":"l2_data","client_id":"","timestamp":"2025-10-27T17:39:38.820752288Z","sequence_num":137525,"events":[{"type":"update","product_id":"ETH-USD","updates":[{"side":"bid","event_time":"2025-10-27T17:39:38.776485Z","price_level":"4218.84","new_quantity":"1.45878574"},{"side":"bid","event_time":"2025-10-27T17:39:38.776485Z","price_level":"4218.13","new_quantity":"0"},{"side":"bid","event_time":"2025-10-27T17:39:38.776485Z","price_level":"4214.28","new_quantity":"19.62445224"},{"side":"bid","event_time":"2025-10-27T17:39:38.776485Z","price_level":"4214.27","new_quantity":"0"},{"side":"bid","event_time":"2025-10-27T17:39:38.776485Z","price_level":"4214.26","new_quantity":"0"},{"side":"offer","event_time":"2025-10-27T17:39:38.776485Z","price_level":"4218.85","new_quantity":"0.0922334"},{"side":"offer","event_time":"2025-10-27T17:39:38.776485Z","price_level":"4221.03","new_quantity":"0"},{"side":"offer","event_time":"2025-10-27T17:39:38.776485Z","price_level":"4221.1","new_quantity":"0"},{"side":"offer","event_time":"2025-10-27T17:39:38.776485Z","price_level":"4221.51","new_quantity":"8.53328676"},{"side":"offer","event_time":"2025-10-27T17:39:38.776485Z","price_level":"4222.29","new_quantity":"13.29927795"},{"side":"offer","event_time":"2025-10-27T17:39:38.776485Z","price_level":"4222.31","new_quantity":"0"}]}]}
{"channel":"l2_data","client_id":"","timestamp":"2025-10-27T17:39:38.848282329Z","sequence_num":137526,"events":[{"type":"update","product_id":"BTC-USD","updates":[{"side":"bid","event_time":"2025-10-27T17:39:38.802326Z","price_level":"115662.06","new_quantity":"0.06068335"},{"side":"bid","event_time":"2025-10-27T17:39:38.802326Z","price_level":"115651.83","new_quantity":"0"},{"side":"bid","event_time":"2025-10-27T17:39:38.802326Z","price_level":"115633","new_quantity":"0.4"},{"side":"bid","event_time":"2025-10-27T17:39:38.802326Z","price_level":"115511.79","new_quantity":"0.045"},{"side":"bid","event_time":"2025-10-27T17:39:38.802326Z","price_level":"114553.14","new_quantity":"0.07007"},{"side":"bid","event_time":"2025-10-27T17:39:38.802326Z","price_level":"114552.8","new_quantity":"0"},{"side":"bid","event_time":"2025-10-27T17:39:38.802326Z","price_level":"114338.37","new_quantity":"0"},{"side":"bid","event_time":"2025-10-27T17:39:38.802326Z","price_level":"114338.34","new_quantity":"0"}]}]}
{"channel":"l2_data","client_id":"","timestamp":"2025-10-27T17:39:38.871169737Z","sequence_num":137528,"events":[{"type":"update","product_id":"ETH-USD","updates":[{"side":"bid","event_time":"2025-10-27T17:39:38.826727Z","price_level":"4218.84","new_quantity":"0"},{"side":"bid","event_time":"2025-10-27T17:39:38.826727Z","price_level":"4218.62","new_quantity":"0.03744193"},{"side":"bid","event_time":"2025-10-27T17:39:38.826727Z","price_level":"4218.61","new_quantity":"0.0681153"},{"side":"bid","event_time":"2025-10-27T17:39:38.826727Z","price_level":"4218.3","new_quantity":"13.908434"},{"side":"bid","event_time":"2025-10-27T17:39:38.826727Z","price_level":"4217.91","new_quantity":"1.65596"},{"side":"offer","event_time":"2025-10-27T17:39:38.826727Z","price_level":"4218.85","new_quantity":"0.0285343"},{"side":"offer","event_time":"2025-10-27T17:39:38.826727Z","price_level":"4219.83","new_quantity":"2.07991193"}]}]}
{"channel":"l2_data","client_id":"","timestamp":"2025-10-27T17:39:38.898291408Z","sequence_num":137530,"events":[{"type":"update","product_id":"BTC-USD","updates":[{"side":"bid","event_time":"2025-10-27T17:39:38.862021Z","price_level":"115662.06","new_quantity":"0.15533335"},{"side":"bid","event_time":"2025-10-27T17:39:38.862021Z","price_level":"115645.66","new_quantity":"0"},{"side":"bid","event_time":"2025-10-27T17:39:38.862021Z","price_level":"115633","new_quantity":"2.4"},{"side":"bid","event_time":"2025-10-27T17:39:38.862021Z","price_level":"114124.35","new_quantity":"0.07007"},{"side":"offer","event_time":"2025-10-27T17:39:38.862021Z","price_level":"115687.07","new_quantity":"0.0024484"},{"side":"offer","event_time":"2025-10-27T17:39:38.862021Z","price_level":"115692","new_quantity":"0"},{"side":"offer","event_time":"2025-10-27T17:39:38.862021Z","price_level":"115693","new_quantity":"0"}]}]}
{"channel":"l2_data","client_id":"","timestamp":"2025-10-27T17:39:38.921204357Z","sequence_num":137532,"events":[{"type":"update","product_id":"ETH-USD","updates":[{"side":"bid","event_time":"2025-10-27T17:39:38.875799Z","price_level":"4218.67","new_quantity":"0.1793914"},{"side":"bid","event_time":"2025-10-27T17:39:38.875799Z","price_level":"4218.66","new_quantity":"0.02070633"},{"side":"bid","event_time":"2025-10-27T17:39:38.875799Z","price_level":"4218.65","new_quantity":"0"},{"side":"bid","event_time":"2025-10-27T17:39:38.875799Z","price_level":"4218.63","new_quantity":"0"},{"side":"bid","event_time":"2025-10-27T17:39:38.875799Z","price_level":"4218.62","new_quantity":"0.03744801"},{"side":"bid","event_time":"2025-10-27T17:39:38.875799Z","price_level":"4218.61","new_quantity":"0.07108888"},{"side":"bid","event_time":"2025-10-27T17:39:38.875799Z","price_level":"4218.41","new_quantity":"0"},{"side":"bid","event_time":"2025-10-27T17:39:38.875799Z","price_level":"4218.3","new_quantity":"10.519"},{"side":"bid","event_time":"2025-10-27T17:39:38.875799Z","price_level":"4218.12","new_quantity":"0.11853608"},{"side":"bid","event_time":"2025-10-27T17:39:38.875799Z","price_level":"4218.09","new_quantity":"3.8792"},{"side":"bid","event_time":"2025-10-27T17:39:38.875799Z","price_level":"4218.08","new_quantity":"0"},{"side":"bid","event_time":"2025-10-27T17:39:38.875799Z","price_level":"4218.05","new_quantity":"0"},{"side":"bid","event_time":"2025-10-27T17:39:38.875799Z","price_level":"4218.04","new_quantity":"0"},{"side":"bid","event_time":"2025-10-27T17:39:38.875799Z","price_level":"4218.03","new_quantity":"0"},{"side":"bid","event_time":"2025-10-27T17:39:38.875799Z","price_level":"4218.02","new_quantity":"1.12737079"},{"side":"bid","event_time":"2025-10-27T17:39:38.875799Z","price_level":"4217.92","new_quantity":"5.77895904"},{"side":"bid","event_time":"2025-10-27T17:39:38.875799Z","price_level":"4217.35","new_quantity":"0.06698569"},{"side":"bid","event_time":"2025-10-27T17:39:38.875799Z","price_level":"4215.54","new_quantity":"0"},{"side":"bid","event_time":"2025-10-27T17:39:38.875799Z","price_level":"4215.34","new_quantity":"8.8452304"},{"side":"bid","event_time":"2025-10-27T17:39:38.875799Z","price_level":"4214.77","new_quantity":"4.935611"},{"side":"bid","event_time":"2025-10-27T17:39:38.875799Z","price_level":"4214.51","new_quantity":"12.86295183"},{"side":"offer","event_time":"2025-10-27T17:39:38.875799Z","price_level":"4218.84","new_quantity":"0.59257995"},{"side":"offer","event_time":"2025-10-27T17:39:38.875799Z","price_level":"4218.96","new_quantity":"0.66213591"},{"side":"offer","event_time":"2025-10-27T17:39:38.875799Z","price_level":"4218.99","new_quantity":"0"},{"side":"offer","event_time":"2025-10-27T17:39:38.875799Z","price_level":"4219.34","new_quantity":"0"},{"side":"offer","event_time":"2025-10-27T17:39:38.875799Z","price_level":"4219.35","new_quantity":"0"},{"side":"offer","event_time":"2025-10-27T17:39:38.875799Z","price_level":"4220","new_quantity":"12.80517286"},{"side":"offer","event_time":"2025-10-27T17:39:38.875799Z","price_level":"4220.2","new_quantity":"0"},{"side":"offer","event_time":"2025-10-27T17:39:38.875799Z","price_level":"4221.1","new_quantity":"8.53411561"},{"side":"offer","event_time":"2025-10-27T17:39:38.875799Z","price_level":"4221.51","new_quantity":"0"},{"side":"offer","event_time":"2025-10-27T17:39:38.875799Z","price_level":"4222.27","new_quantity":"13.29934095"},{"side":"offer","event_time":"2025-10-27T17:39:38.875799Z","price_level":"4222.28","new_quantity":"1.94391607"},{"side":"offer","event_time":"2025-10-27T17:39:38.875799Z","price_level":"4222.29","new_quantity":"0"},{"side":"offer","event_time":"2025-10-27T17:39:38.875799Z","price_level":"4222.3","new_quantity":"0"},{"side":"offer","event_time":"2025-10-27T17:39:38.875799Z","price_level":"4223.45","new_quantity":"9.72530687"},{"side":"offer","event_time":"2025-10-27T17:39:38.875799Z","price_level":"4223.68","new_quantity":"0"}]}]}
{"channel":"l2_data","client_id":"","timestamp":"2025-10-27T17:39:38.94720523Z","sequence_num":137533,"events":[{"type":"update","product_id":"BTC-USD","updates":[{"side":"bid","event_time":"2025-10-27T17:39:38.888335Z","price_level":"115651.12","new_quantity":"0.00864669"},{"side":"bid","event_time":"2025-10-27T17:39:38.888335Z","price_level":"115649.71","new_quantity":"0"},{"side":"bid","event_time":"2025-10-27T17:39:38.888335Z","price_level":"115640.01","new_quantity":"0.48923465"},{"side":"bid","event_time":"2025-10-27T17:39:38.888335Z","price_level":"115639","new_quantity":"0"},{"side":"bid","event_time":"2025-10-27T17:39:38.888335Z","price_level":"115635","new_quantity":"0"},{"side":"bid","event_time":"2025-10-27T17:39:38.888335Z","price_level":"115630","new_quantity":"0"},{"side":"bid","event_time":"2025-10-27T17:39:38.888335Z","price_level":"115579.25","new_quantity":"0"},{"side":"bid","event_time":"2025-10-27T17:39:38.888335Z","price_level":"114933.48","new_quantity":"0"},{"side":"bid","event_time":"2025-10-27T17:39:38.888335Z","price_level":"114553.21","new_quantity":"0.07007"},{"side":"offer","event_time":"2025-10-27T17:39:38.888335Z","price_level":"115679.24","new_quantity":"0"},{"side":"offer","event_time":"2025-10-27T17:39:38.888335Z","price_level":"115679.25","new_quantity":"0"},{"side":"offer","event_time":"2025-10-27T17:39:38.888335Z","price_level":"115681.56","new_quantity":"0.00432"},{"side":"offer","event_time":"2025-10-27T17:39:38.888335Z","price_level":"115681.57","new_quantity":"0.00432"},{"side":"offer","event_time":"2025-10-27T17:39:38.888335Z","price_level":"115683.25","new_quantity":"0"},{"side":"offer","event_time":"2025-10-27T17:39:38.888335Z","price_level":"115689.73","new_quantity":"0.38539989"},{"side":"offer","event_time":"2025-10-27T17:39:38.888335Z","price_level":"115692","new_quantity":"0.4"},{"side":"offer","event_time":"2025-10-27T17:39:38.888335Z","price_level":"115693","new_quantity":"2"},{"side":"offer","event_time":"2025-10-27T17:39:38.888335Z","price_level":"115710.92","new_quantity":"0"},{"side":"offer","event_time":"2025-10-27T17:39:38.888335Z","price_level":"115711.32","new_quantity":"0.5"}]}]}
{"channel":"l2_data","client_id":"","timestamp":"2025-10-27T17:39:38.970489249Z","sequence_num":137534,"events":[{"type":"update","product_id":"ETH-USD","updates":[{"side":"bid","event_time":"2025-10-27T17:39:38.929853Z","price_level":"4218.67","new_quantity":"0.4143514"},{"side":"bid","event_time":"2025-10-27T17:39:38.929853Z","price_level":"4218.61","new_quantity":"0"},{"side":"bid","event_time":"2025-10-27T17:39:38.929853Z","price_level":"4218.41","new_quantity":"25.48540464"},{"side":"bid","event_time":"2025-10-27T17:39:38.929853Z","price_level":"4218.22","new_quantity":"0.00237067"},{"side":"bid","event_time":"2025-10-27T17:39:38.929853Z","price_level":"4218.19","new_quantity":"0"},{"side":"bid","event_time":"2025-10-27T17:39:38.929853Z","price_level":"4218.02","new_quantity":"1.125"},{"side":"bid","event_time":"2025-10-27T17:39:38.929853Z","price_level":"4215.36","new_quantity":"0"},{"side":"offer","event_time":"2025-10-27T17:39:38.929853Z","price_level":"4218.68","new_quantity":"0.12089101"},{"side":"offer","event_time":"2025-10-27T17:39:38.929853Z","price_level":"4218.83","new_quantity":"0.59258135"},{"side":"offer","event_time":"2025-10-27T17:39:38.929853Z","price_level":"4218.84","new_quantity":"0"},{"side":"offer","event_time":"2025-10-27T17:39:38.929853Z","price_level":"4218.85","new_quantity":"0"},{"side":"offer","event_time":"2025-10-27T17:39:38.929853Z","price_level":"4219.34","new_quantity":"0.33903666"},{"side":"offer","event_time":"2025-10-27T17:39:38.929853Z","price_level":"4219.56","new_quantity":"1.51597847"},{"side":"offer","event_time":"2025-10-27T17:39:38.929853Z","price_level":"4219.66","new_quantity":"1.64157"},{"side":"offer","event_time":"2025-10-27T17:39:38.929853Z","price_level":"4219.9","new_quantity":"0"},{"side":"offer","event_time":"2025-10-27T17:39:38.929853Z","price_level":"4219.98","new_quantity":"3.49696016"},{"side":"offer","event_time":"2025-10-27T17:39:38.929853Z","price_level":"4220.4","new_quantity":"0"},{"side":"offer","event_time":"2025-10-27T17:39:38.929853Z","price_level":"4221.69","new_quantity":"0"},{"side":"offer","event_time":"2025-10-27T17:39:38.929853Z","price_level":"4223.73","new_quantity":"0.1536"}]}]}
{"channel":"l2_data","client_id":"","timestamp":"2025-10-27T17:39:38.998753167Z","sequence_num":137535,"events":[{"type":"update","product_id":"BTC-USD","updates":[{"side":"bid","event_time":"2025-10-27T17:39:38.945624Z","price_level":"115651.12","new_quantity":"0"},{"side":"bid","event_time":"2025-10-27T17:39:38.945624Z","price_level":"115646.83","new_quantity":"0.00432"},{"side":"bid","event_time":"2025-10-27T17:39:38.945624Z","price_level":"115642.19","new_quantity":"0"},{"side":"bid","event_time":"2025-10-27T17:39:38.945624Z","price_level":"115640.01","new_quantity":"0.25043465"},{"side":"bid","event_time":"2025-10-27T17:39:38.945624Z","price_level":"115637","new_quantity":"0"},{"side":"bid","event_time":"2025-10-27T17:39:38.945624Z","price_level":"115633.01","new_quantity":"1.19351579"},{"side":"bid","event_time":"2025-10-27T17:39:38.945624Z","price_level":"115633","new_quantity":"0"},{"side":"bid","event_time":"2025-10-27T17:39:38.945624Z","price_level":"115613.95","new_quantity":"0"},{"side":"bid","event_time":"2025-10-27T17:39:38.945624Z","price_level":"115613.94","new_quantity":"0"},{"side":"bid","event_time":"2025-10-27T17:39:38.945624Z","price_level":"115590.01","new_quantity":"0"},{"side":"bid","event_time":"2025-10-27T17:39:38.945624Z","price_level":"115590","new_quantity":"0"},{"side":"bid","event_time":"2025-10-27T17:39:38.945624Z","price_level":"115199.12","new_quantity":"0.07007"},{"side":"bid","event_time":"2025-10-27T17:39:38.945624Z","price_level":"115198.73","new_quantity":"0"},{"side":"bid","event_time":"2025-10-27T17:39:38.945624Z","price_level":"114983.99","new_quantity":"0.07007"},{"side":"bid","event_time":"2025-10-27T17:39:38.945624Z","price_level":"114983.1","new_quantity":"0"},{"side":"bid","event_time":"2025-10-27T17:39:38.945624Z","price_level":"114768.59","new_quantity":"0"},{"side":"bid","event_time":"2025-10-27T17:39:38.945624Z","price_level":"114768.57","new_quantity":"0"},{"side":"bid","event_time":"2025-10-27T17:39:38.945624Z","price_level":"114767.71","new_quantity":"0"},{"side":"bid","event_time":"2025-10-27T17:39:38.945624Z","price_level":"114553.39","new_quantity":"0"},{"side":"bid","event_time":"2025-10-27T17:39:38.945624Z","price_level":"114553.21","new_quantity":"0"},{"side":"bid","event_time":"2025-10-27T17:39:38.945624Z","price_level":"114553.14","new_quantity":"0"},{"side":"bid","event_time":"2025-10-27T17:39:38.945624Z","price_level":"114124.35","new_quantity":"0"},{"side":"offer","event_time":"2025-10-27T17:39:38.945624Z","price_level":"115662.07","new_quantity":"0.0030772"},{"side":"offer","event_time":"2025-10-27T17:39:38.945624Z","price_level":"115666.42","new_quantity":"0"},{"side":"offer","event_time":"2025-10-27T17:39:38.945624Z","price_level":"115675.79","new_quantity":"0.08507847"},{"side":"offer","event_time":"2025-10-27T17:39:38.945624Z","price_level":"115675.8","new_quantity":"0"},{"side":"offer","event_time":"2025-10-27T17:39:38.945624Z","price_level":"115681.55","new_quantity":"0"},{"side":"offer","event_time":"2025-10-27T17:39:38.945624Z","price_level":"115681.56","new_quantity":"0"},{"side":"offer","event_time":"2025-10-27T17:39:38.945624Z","price_level":"115681.57","new_quantity":"0"},{"side":"offer","event_time":"2025-10-27T17:39:38.945624Z","price_level":"115689.73","new_quantity":"0.16808983"},{"side":"offer","event_time":"2025-10-27T17:39:38.945624Z","price_level":"115692","new_quantity":"0"},{"side":"offer","event_time":"2025-10-27T17:39:38.945624Z","price_level":"115693","new_quantity":"0"},{"side":"offer","event_time":"2025-10-27T17:39:38.945624Z","price_level":"115694.04","new_quantity":"0"},{"side":"offer","event_time":"2025-10-27T17:39:38.945624Z","price_level":"115706.54","new_quantity":"0"},{"side":"offer","event_time":"2025-10-27T17:39:38.945624Z","price_level":"115711.32","new_quantity":"0"},{"side":"offer","event_time":"2025-10-27T17:39:38.945624Z","price_level":"115712.53","new_quantity":"0"},{"side":"offer","event_time":"2025-10-27T17:39:38.945624Z","price_level":"115714.18","new_quantity":"0.16809402"},{"side":"offer","event_time":"2025-10-27T17:39:38.945624Z","price_level":"115714.46","new_quantity":"0"},{"side":"offer","event_time":"2025-10-27T17:39:38.945624Z","price_level":"115714.47","new_quantity":"0"},{"side":"offer","event_time":"2025-10-27T17:39:38.945624Z","price_level":"115715.05","new_quantity":"0.04"},{"side":"offer","event_time":"2025-10-27T17:39:38.945624Z","price_level":"115716.3","new_quantity":"0"},{"side":"offer","event_time":"2025-10-27T17:39:38.945624Z","price_level":"115729.99","new_quantity":"1.24628075"},{"side":"offer","event_time":"2025-10-27T17:39:38.945624Z","price_level":"115745.21","new_quantity":"0"}]}]}
{"channel":"l2_data","client_id":"","timestamp":"2025-10-27T17:39:38.098009462Z","sequence_num":137488,"events":[{"type":"update","product_id":"BTC-USD","updates":[{"side":"bid","event_time":"2025-10-27T17:39:38.053555Z","price_level":"115652.27","new_quantity":"0.02160702"},{"side":"bid","event_time":"2025-10-27T17:39:38.053555Z","price_level":"115651.37","new_quantity":"0"},{"side":"bid","event_time":"2025-10-27T17:39:38.053555Z","price_level":"115649.71","new_quantity":"0.0086468"},{"side":"bid","event_time":"2025-10-27T17:39:38.053555Z","price_level":"115639","new_quantity":"0"},{"side":"bid","event_time":"2025-10-27T17:39:38.053555Z","price_level":"115633.01","new_quantity":"1.19351579"},{"side":"bid","event_time":"2025-10-27T17:39:38.053555Z","price_level":"115633","new_quantity":"0"},{"side":"bid","event_time":"2025-10-27T17:39:38.053555Z","price_level":"115632","new_quantity":"0"},{"side":"bid","event_time":"2025-10-27T17:39:38.053555Z","price_level":"113816.29","new_quantity":"0"},{"side":"bid","event_time":"2025-10-27T17:39:38.053555Z","price_level":"113263.61","new_quantity":"0"},{"side":"offer","event_time":"2025-10-27T17:39:38.053555Z","price_level":"115683.25","new_quantity":"0.04"},{"side":"offer","event_time":"2025-10-27T17:39:38.053555Z","price_level":"115689.6","new_quantity":"0.00106969"},{"side":"offer","event_time":"2025-10-27T17:39:38.053555Z","price_level":"115689.72","new_quantity":"0.0345812"},{"side":"offer","event_time":"2025-10-27T17:39:38.053555Z","price_level":"115692.16","new_quantity":"0"},{"side":"offer","event_time":"2025-10-27T17:39:38.053555Z","price_level":"115693.05","new_quantity":"0.38903854"},{"side":"offer","event_time":"2025-10-27T17:39:38.053555Z","price_level":"115698","new_quantity":"0.4"},{"side":"offer","event_time":"2025-10-27T17:39:38.053555Z","price_level":"115698.56","new_quantity":"0"},{"side":"offer","event_time":"2025-10-27T17:39:38.053555Z","price_level":"115714.46","new_quantity":"0.1792927"},{"side":"offer","event_time":"2025-10-27T17:39:38.053555Z","price_level":"115714.47","new_quantity":"0.16"},{"side":"offer","event_time":"2025-10-27T17:39:38.053555Z","price_level":"115715.04","new_quantity":"0"}]}]}
{"channel":"l2_data","client_id":"","timestamp":"2025-10-27T17:39:38.121533353Z","sequence_num":137489,"events":[{"type":"update","product_id":"ETH-USD","updates":[{"side":"bid","event_time":"2025-10-27T17:39:38.072326Z","price_level":"4218.7","new_quantity":"10"},{"side":"bid","event_time":"2025-10-27T17:39:38.072326Z","price_level":"4218.65","new_quantity":"0"},{"side":"bid","event_time":"2025-10-27T17:39:38.072326Z","price_level":"4218.6","new_quantity":"30.519"},{"side":"bid","event_time":"2025-10-27T17:39:38.072326Z","price_level":"4218.58","new_quantity":"0.07109033"},{"side":"bid","event_time":"2025-10-27T17:39:38.072326Z","price_level":"4218.5","new_quantity":"10.519"},{"side":"bid","event_time":"2025-10-27T17:39:38.072326Z","price_level":"4218.33","new_quantity":"1.65112"},{"side":"bid","event_time":"2025-10-27T17:39:38.072326Z","price_level":"4218.31","new_quantity":"0"},{"side":"bid","event_time":"2025-10-27T17:39:38.072326Z","price_level":"4218.22","new_quantity":"0.00237067"},{"side":"bid","event_time":"2025-10-27T17:39:38.072326Z","price_level":"4081.22","new_quantity":"0"},{"side":"bid","event_time":"2025-10-27T17:39:38.072326Z","price_level":"4055.41","new_quantity":"0"},{"side":"offer","event_time":"2025-10-27T17:39:38.072326Z","price_level":"4218.85","new_quantity":"0.3481514"},{"side":"offer","event_time":"2025-10-27T17:39:38.072326Z","price_level":"4218.89","new_quantity":"0"},{"side":"offer","event_time":"2025-10-27T17:39:38.072326Z","price_level":"4219.17","new_quantity":"0.07110403"},{"side":"offer","event_time":"2025-10-27T17:39:38.072326Z","price_level":"4219.57","new_quantity":"0.548643"},{"side":"offer","event_time":"2025-10-27T17:39:38.072326Z","price_level":"4219.59","new_quantity":"0.2"},{"side":"offer","event_time":"2025-10-27T17:39:38.072326Z","price_level":"4219.78","new_quantity":"2.713042"},{"side":"offer","event_time":"2025-10-27T17:39:38.072326Z","price_level":"4219.79","new_quantity":"1.64024"},{"side":"offer","event_time":"2025-10-27T17:39:38.072326Z","price_level":"4219.82","new_quantity":"0"},{"side":"offer","event_time":"2025-10-27T17:39:38.072326Z","price_level":"4220.2","new_quantity":"10"},{"side":"offer","event_time":"2025-10-27T17:39:38.072326Z","price_level":"4220.4","new_quantity":"20"},{"side":"offer","event_time":"2025-10-27T17:39:38.072326Z","price_level":"4222.16","new_quantity":"0.00035596"},{"side":"offer","event_time":"2025-10-27T17:39:38.072326Z","price_level":"4222.43","new_quantity":"3.489542"}]}]}
{"channel":"l2_data","client_id":"","timestamp":"2025-10-27T17:39:38.146914488Z","sequence_num":137491,"events":[{"type":"update","product_id":"BTC-USD","updates":[{"side":"bid","event_time":"2025-10-27T17:39:38.08198Z","price_level":"115641.73","new_quantity":"0.00086462"},{"side":"bid","event_time":"2025-10-27T17:39:38.08198Z","price_level":"115638","new_quantity":"0.4"},{"side":"bid","event_time":"2025-10-27T17:39:38.08198Z","price_level":"115634.25","new_quantity":"0.00432314"},{"side":"bid","event_time":"2025-10-27T17:39:38.08198Z","price_level":"115634","new_quantity":"0"},{"side":"bid","event_time":"2025-10-27T17:39:38.08198Z","price_level":"115633.01","new_quantity":"2.2162732"},{"side":"bid","event_time":"2025-10-27T17:39:38.08198Z","price_level":"115632","new_quantity":"2"},{"side":"bid","event_time":"2025-10-27T17:39:38.08198Z","price_level":"115622.69","new_quantity":"0"},{"side":"bid","event_time":"2025-10-27T17:39:38.08198Z","price_level":"115377.5","new_quantity":"1.2966198"},{"side":"offer","event_time":"2025-10-27T17:39:38.08198Z","price_level":"115666.37","new_quantity":"0.00006598"},{"side":"offer","event_time":"2025-10-27T17:39:38.08198Z","price_level":"115692","new_quantity":"0.4"},{"side":"offer","event_time":"2025-10-27T17:39:38.08198Z","price_level":"115693","new_quantity":"2"},{"side":"offer","event_time":"2025-10-27T17:39:38.08198Z","price_level":"115898","new_quantity":"1.46918533"}]}]}
{"channel":"l2_data","client_id":"","timestamp":"2025-10-27T17:39:39.022460768Z","sequence_num":137536,"events":[{"type":"update","product_id":"ETH-USD","updates":[{"side":"bid","event_time":"2025-10-27T17:39:38.983484Z","price_level":"4218.67","new_quantity":"2.05522543"},{"side":"bid","event_time":"2025-10-27T17:39:38.983484Z","price_level":"4218.64","new_quantity":"0.07108939"},{"side":"bid","event_time":"2025-10-27T17:39:38.983484Z","price_level":"4218.61","new_quantity":"0"},{"side":"bid","event_time":"2025-10-27T17:39:38.983484Z","price_level":"4218.22","new_quantity":"0.00237067"},{"side":"bid","event_time":"2025-10-27T17:39:38.983484Z","price_level":"4218.21","new_quantity":"12.44663676"},{"side":"bid","event_time":"2025-10-27T17:39:38.983484Z","price_level":"4218.17","new_quantity":"1.65596"},{"side":"bid","event_time":"2025-10-27T17:39:38.983484Z","price_level":"4218.12","new_quantity":"0"},{"side":"bid","event_time":"2025-10-27T17:39:38.983484Z","price_level":"4218.11","new_quantity":"0.55445825"},{"side":"bid","event_time":"2025-10-27T17:39:38.983484Z","price_level":"4218.02","new_quantity":"1.125"},{"side":"bid","event_time":"2025-10-27T17:39:38.983484Z","price_level":"4217.92","new_quantity":"0"},{"side":"bid","event_time":"2025-10-27T17:39:38.983484Z","price_level":"4217.88","new_quantity":"0.59271358"},{"side":"bid","event_time":"2025-10-27T17:39:38.983484Z","price_level":"4217.83","new_quantity":"4.90066433"},{"side":"bid","event_time":"2025-10-27T17:39:38.983484Z","price_level":"4217.82","new_quantity":"5.77909605"},{"side":"bid","event_time":"2025-10-27T17:39:38.983484Z","price_level":"4217.81","new_quantity":"0"},{"side":"bid","event_time":"2025-10-27T17:39:38.983484Z","price_level":"4217.77","new_quantity":"0"},{"side":"bid","event_time":"2025-10-27T17:39:38.983484Z","price_level":"4217","new_quantity":"1.97593789"},{"side":"bid","event_time":"2025-10-27T17:39:38.983484Z","price_level":"4216.94","new_quantity":"0"},{"side":"bid","event_time":"2025-10-27T17:39:38.983484Z","price_level":"4213.8","new_quantity":"0"},{"side":"bid","event_time":"2025-10-27T17:39:38.983484Z","price_level":"4213.79","new_quantity":"0"},{"side":"offer","event_time":"2025-10-27T17:39:38.983484Z","price_level":"4218.68","new_quantity":"0.00237053"},{"side":"offer","event_time":"2025-10-27T17:39:38.983484Z","price_level":"4218.83","new_quantity":"1.1851627"},{"side":"offer","event_time":"2025-10-27T17:39:38.983484Z","price_level":"4218.85","new_quantity":"0.11851592"},{"side":"offer","event_time":"2025-10-27T17:39:38.983484Z","price_level":"4218.9","new_quantity":"0"},{"side":"offer","event_time":"2025-10-27T17:39:38.983484Z","price_level":"4218.96","new_quantity":"0"},{"side":"offer","event_time":"2025-10-27T17:39:38.983484Z","price_level":"4219.09","new_quantity":"0.07110538"},{"side":"offer","event_time":"2025-10-27T17:39:38.983484Z","price_level":"4219.18","new_quantity":"0.260889"},{"side":"offer","event_time":"2025-10-27T17:39:38.983484Z","price_level":"4219.19","new_quantity":"0"},{"side":"offer","event_time":"2025-10-27T17:39:38.983484Z","price_level":"4219.56","new_quantity":"2.00432418"},{"side":"offer","event_time":"2025-10-27T17:39:38.983484Z","price_level":"4219.57","new_quantity":"0"},{"side":"offer","event_time":"2025-10-27T17:39:38.983484Z","price_level":"4219.78","new_quantity":"0"},{"side":"offer","event_time":"2025-10-27T17:39:38.983484Z","price_level":"4219.83","new_quantity":"1.125"},{"side":"offer","event_time":"2025-10-27T17:39:38.983484Z","price_level":"4220","new_quantity":"22.20517286"},{"side":"offer","event_time":"2025-10-27T17:39:38.983484Z","price_level":"4220.11","new_quantity":"0"},{"side":"offer","event_time":"2025-10-27T17:39:38.983484Z","price_level":"4220.2","new_quantity":"20"},{"side":"offer","event_time":"2025-10-27T17:39:38.983484Z","price_level":"4220.36","new_quantity":"0.08999692"},{"side":"offer","event_time":"2025-10-27T17:39:38.983484Z","price_level":"4220.71","new_quantity":"0.28287083"},{"side":"offer","event_time":"2025-10-27T17:39:38.983484Z","price_level":"4221.51","new_quantity":"0.671625"},{"side":"offer","event_time":"2025-10-27T17:39:38.983484Z","price_level":"4222.25","new_quantity":"13.29940394"},{"side":"offer","event_time":"2025-10-27T17:39:38.983484Z","price_level":"4222.26","new_quantity":"1.94391607"},{"side":"offer","event_time":"2025-10-27T17:39:38.983484Z","price_level":"4222.27","new_quantity":"0"},{"side":"offer","event_time":"2025-10-27T17:39:38.983484Z","price_level":"4222.28","new_quantity":"0"},{"side":"offer","event_time":"2025-10-27T17:39:38.983484Z","price_level":"4222.74","new_quantity":"3.37517791"},{"side":"offer","event_time":"2025-10-27T17:39:38.983484Z","price_level":"4223.73","new_quantity":"0"},{"side":"offer","event_time":"2025-10-27T17:39:38.983484Z","price_level":"4224.42","new_quantity":"0"},{"side":"offer","event_time":"2025-10-27T17:39:38.983484Z","price_level":"4224.45","new_quantity":"10"},{"side":"offer","event_time":"2025-10-27T17:39:38.983484Z","price_level":"4244.82","new_quantity":"0.1536"}]}]}
{"channel":"l2_data","client_id":"","timestamp":"2025-10-27T17:39:39.04825604Z","sequence_num":137537,"events":[{"type":"update","product_id":"BTC-USD","updates":[{"side":"bid","event_time":"2025-10-27T17:39:39.00332Z","price_level":"115652.78","new_quantity":"0.00864657"},{"side":"bid","event_time":"2025-10-27T17:39:39.00332Z","price_level":"115646.8","new_quantity":"0.00432"},{"side":"bid","event_time":"2025-10-27T17:39:39.00332Z","price_level":"115642.16","new_quantity":"0"},{"side":"bid","event_time":"2025-10-27T17:39:39.00332Z","price_level":"115640.32","new_quantity":"0.7517285"},{"side":"bid","event_time":"2025-10-27T17:39:39.00332Z","price_level":"115640.01","new_quantity":"0"},{"side":"bid","event_time":"2025-10-27T17:39:39.00332Z","price_level":"115639","new_quantity":"0.4"},{"side":"bid","event_time":"2025-10-27T17:39:39.00332Z","price_level":"115637","new_quantity":"0.4"},{"side":"bid","event_time":"2025-10-27T17:39:39.00332Z","price_level":"115635.01","new_quantity":"0"},{"side":"bid","event_time":"2025-10-27T17:39:39.00332Z","price_level":"115635","new_quantity":"0.4"},{"side":"bid","event_time":"2025-10-27T17:39:39.00332Z","price_level":"115633.02","new_quantity":"0.33119962"},{"side":"bid","event_time":"2025-10-27T17:39:39.00332Z","price_level":"115633.01","new_quantity":"2.83192714"},{"side":"bid","event_time":"2025-10-27T17:39:39.00332Z","price_level":"115633","new_quantity":"2.4"},{"side":"bid","event_time":"2025-10-27T17:39:39.00332Z","price_level":"115630","new_quantity":"1"},{"side":"bid","event_time":"2025-10-27T17:39:39.00332Z","price_level":"115620.65","new_quantity":"0"},{"side":"bid","event_time":"2025-10-27T17:39:39.00332Z","price_level":"115612.8","new_quantity":"0.52632089"},{"side":"bid","event_time":"2025-10-27T17:39:39.00332Z","price_level":"115600.02","new_quantity":"0"},{"side":"bid","event_time":"2025-10-27T17:39:39.00332Z","price_level":"115596.71","new_quantity":"0.76375243"},{"side":"bid","event_time":"2025-10-27T17:39:39.00332Z","price_level":"115594.8","new_quantity":"1.5"},{"side":"bid","event_time":"2025-10-27T17:39:39.00332Z","price_level":"115594.2","new_quantity":"0"},{"side":"bid","event_time":"2025-10-27T17:39:39.00332Z","price_level":"115590","new_quantity":"5"},{"side":"offer","event_time":"2025-10-27T17:39:39.00332Z","price_level":"115662.07","new_quantity":"0.00303654"},{"side":"offer","event_time":"2025-10-27T17:39:39.00332Z","price_level":"115663.93","new_quantity":"0.00006605"},{"side":"offer","event_time":"2025-10-27T17:39:39.00332Z","price_level":"115663.94","new_quantity":"0.02593721"},{"side":"offer","event_time":"2025-10-27T17:39:39.00332Z","price_level":"115666.37","new_quantity":"0"},{"side":"offer","event_time":"2025-10-27T17:39:39.00332Z","price_level":"115683.17","new_quantity":"0.10971979"},{"side":"offer","event_time":"2025-10-27T17:39:39.00332Z","price_level":"115683.18","new_quantity":"0.16611"},{"side":"offer","event_time":"2025-10-27T17:39:39.00332Z","price_level":"115683.69","new_quantity":"0"},{"side":"offer","event_time":"2025-10-27T17:39:39.00332Z","price_level":"115683.88","new_quantity":"0.00432"},{"side":"offer","event_time":"2025-10-27T17:39:39.00332Z","price_level":"115683.89","new_quantity":"0.00432"},{"side":"offer","event_time":"2025-10-27T17:39:39.00332Z","price_level":"115689.72","new_quantity":"0.00185259"},{"side":"offer","event_time":"2025-10-27T17:39:39.00332Z","price_level":"115693","new_quantity":"0"},{"side":"offer","event_time":"2025-10-27T17:39:39.00332Z","price_level":"115693.05","new_quantity":"0"},{"side":"offer","event_time":"2025-10-27T17:39:39.00332Z","price_level":"115693.06","new_quantity":"0"},{"side":"offer","event_time":"2025-10-27T17:39:39.00332Z","price_level":"115693.98","new_quantity":"0"},{"side":"offer","event_time":"2025-10-27T17:39:39.00332Z","price_level":"115694.03","new_quantity":"0.13833559"},{"side":"offer","event_time":"2025-10-27T17:39:39.00332Z","price_level":"115697.99","new_quantity":"0.38903253"},{"side":"offer","event_time":"2025-10-27T17:39:39.00332Z","price_level":"115698","new_quantity":"0"},{"side":"offer","event_time":"2025-10-27T17:39:39.00332Z","price_level":"115712.39","new_quantity":"0.5"},{"side":"offer","event_time":"2025-10-27T17:39:39.00332Z","price_level":"115715.05","new_quantity":"0"},{"side":"offer","event_time":"2025-10-27T17:39:39.00332Z","price_level":"115729.98","new_quantity":"0.25112503"},{"side":"offer","event_time":"2025-10-27T17:39:39.00332Z","price_level":"115735.1","new_quantity":"0.00043229"},{"side":"offer","event_time":"2025-10-27T17:39:39.00332Z","price_level":"115735.11","new_quantity":"0"},{"side":"offer","event_time":"2025-10-27T17:39:39.00332Z","price_level":"115740.09","new_quantity":"0.37929301"},{"side":"offer","event_time":"2025-10-27T17:39:39.00332Z","price_level":"115740.1","new_quantity":"0"},{"side":"offer","event_time":"2025-10-27T17:39:39.00332Z","price_level":"115741.5","new_quantity":"1"},{"side":"offer","event_time":"2025-10-27T17:39:39.00332Z","price_level":"115743.92","new_quantity":"0"}]}]}
{"channel":"l2_data","client_id":"","timestamp":"2025-10-27T17:39:39.07095548Z","sequence_num":137538,"events":[{"type":"update","product_id":"ETH-USD","updates":[{"side":"bid","event_time":"2025-10-27T17:39:39.028141Z","price_level":"4218.67","new_quantity":"2.12631482"},{"side":"bid","event_time":"2025-10-27T17:39:39.028141Z","price_level":"4218.64","new_quantity":"0"},{"side":"bid","event_time":"2025-10-27T17:39:39.028141Z","price_level":"4218.28","new_quantity":"0.11853145"},{"side":"bid","event_time":"2025-10-27T17:39:39.028141Z","price_level":"4218.17","new_quantity":"2.24863306"},{"side":"bid","event_time":"2025-10-27T17:39:39.028141Z","price_level":"4217.91","new_quantity":"0"},{"side":"offer","event_time":"2025-10-27T17:39:39.028141Z","price_level":"4219.79","new_quantity":"0"}]}]}
{"channel":"l2_data","client_id":"","timestamp":"2025-10-27T17:39:39.099895963Z","sequence_num":137539,"events":[{"type":"update","product_id":"BTC-USD","updates":[{"side":"bid","event_time":"2025-10-27T17:39:39.056638Z","price_level":"115662.06","new_quantity":"0.06068335"},{"side":"bid","event_time":"2025-10-27T17:39:39.056638Z","price_level":"114381.77","new_quantity":"0"},{"side":"bid","event_time":"2025-10-27T17:39:39.056638Z","price_level":"113834.89","new_quantity":"0"},{"side":"bid","event_time":"2025-10-27T17:39:39.056638Z","price_level":"113288.01","new_quantity":"0"},{"side":"offer","event_time":"2025-10-27T17:39:39.056638Z","price_level":"115664.43","new_quantity":"0.012557"},{"side":"offer","event_time":"2025-10-27T17:39:39.056638Z","price_level":"115686.74","new_quantity":"0.04"},{"side":"offer","event_time":"2025-10-27T17:39:39.056638Z","price_level":"115694.03","new_quantity":"0"},{"side":"offer","event_time":"2025-10-27T17:39:39.056638Z","price_level":"115697.99","new_quantity":"0.52736795"},{"side":"offer","event_time":"2025-10-27T17:39:39.056638Z","price_level":"115699","new_quantity":"0.4"},{"side":"offer","event_time":"2025-10-27T17:39:39.056638Z","price_level":"115711.49","new_quantity":"0.5"},{"side":"offer","event_time":"2025-10-27T17:39:39.056638Z","price_level":"115712.39","new_quantity":"0"},{"side":"offer","event_time":"2025-10-27T17:39:39.056638Z","price_level":"115714.57","new_quantity":"0.058098"},{"side":"offer","event_time":"2025-10-27T17:39:39.056638Z","price_level":"115718.25","new_quantity":"0.082997"},{"side":"offer","event_time":"2025-10-27T17:39:39.056638Z","price_level":"115747.15","new_quantity":"0.57738086"},{"side":"offer","event_time":"2025-10-27T17:39:39.056638Z","price_level":"115747.16","new_quantity":"0.103746"},{"side":"offer","event_time":"2025-10-27T17:39:39.056638Z","price_level":"115749.57","new_quantity":"0"}]}]}
{"channel":"l2_data","client_id":"","timestamp":"2025-10-27T17:39:39.121589695Z","sequence_num":137542,"events":[{"type":"update","product_id":"ETH-USD","updates":[{"side":"bid","event_time":"2025-10-27T17:39:39.07323Z","price_level":"4217.85","new_quantity":"4.54598203"},{"side":"bid","event_time":"2025-10-27T17:39:39.07323Z","price_level":"4217.84","new_quantity":"5.77906865"},{"side":"bid","event_time":"2025-10-27T17:39:39.07323Z","price_level":"4217.83","new_quantity":"0.002"},{"side":"bid","event_time":"2025-10-27T17:39:39.07323Z","price_level":"4217.82","new_quantity":"0"},{"side":"offer","event_time":"2025-10-27T17:39:39.07323Z","price_level":"4218.68","new_quantity":"0.01919321"},{"side":"offer","event_time":"2025-10-27T17:39:39.07323Z","price_level":"4220.13","new_quantity":"0.6"},{"side":"offer","event_time":"2025-10-27T17:39:39.07323Z","price_level":"4222.24","new_quantity":"1.94391607"},{"side":"offer","event_time":"2025-10-27T17:39:39.07323Z","price_level":"4222.26","new_quantity":"0"}]}]}
{"channel":"l2_data","client_id":"","timestamp":"2025-10-27T17:39:39.149635074Z","sequence_num":137544,"events":[{"type":"update","product_id":"BTC-USD","updates":[{"side":"bid","event_time":"2025-10-27T17:39:39.085216Z","price_level":"115651.75","new_quantity":"0.02160751"},{"side":"offer","event_time":"2025-10-27T17:39:39.085216Z","price_level":"115694","new_quantity":"0.4"},{"side":"offer","event_time":"2025-10-27T17:39:39.085216Z","price_level":"115695","new_quantity":"2"},{"side":"offer","event_time":"2025-10-27T17:39:39.085216Z","price_level":"115717.86","new_quantity":"0.08"},{"side":"offer","event_time":"2025-10-27T17:39:39.085216Z","price_level":"115718.16","new_quantity":"0.16"},{"side":"offer","event_time":"2025-10-27T17:39:39.085216Z","price_level":"115740.09","new_quantity":"0"},{"side":"offer","event_time":"2025-10-27T17:39:39.085216Z","price_level":"115741.5","new_quantity":"0"},{"side":"offer","event_time":"2025-10-27T17:39:39.085216Z","price_level":"115743.92","new_quantity":"0.37928046"},{"side":"offer","event_time":"2025-10-27T17:39:39.085216Z","price_level":"115745.2","new_quantity":"1"}]}]}
{"channel":"l2_data","client_id":"","timestamp":"2025-10-27T17:39:39.170966737Z","sequence_num":137545,"events":[{"type":"update","product_id":"ETH-USD","updates":[{"side":"bid","event_time":"2025-10-27T17:39:39.135627Z","price_level":"4218.66","new_quantity":"0"},{"side":"bid","event_time":"2025-10-27T17:39:39.135627Z","price_level":"4218.62","new_quantity":"0"},{"side":"bid","event_time":"2025-10-27T17:39:39.135627Z","price_level":"4218.61","new_quantity":"0.02070633"},{"side":"bid","event_time":"2025-10-27T17:39:39.135627Z","price_level":"4216.33","new_quantity":"4.19049264"},{"side":"bid","event_time":"2025-10-27T17:39:39.135627Z","price_level":"4214.85","new_quantity":"8.81142411"},{"side":"offer","event_time":"2025-10-27T17:39:39.135627Z","price_level":"4219.09","new_quantity":"0"},{"side":"offer","event_time":"2025-10-27T17:39:39.135627Z","price_level":"4219.1","new_quantity":"0"},{"side":"offer","event_time":"2025-10-27T17:39:39.135627Z","price_level":"4219.17","new_quantity":"0"},{"side":"offer","event_time":"2025-10-27T17:39:39.135627Z","price_level":"4220.49","new_quantity":"10.11707578"},{"side":"offer","event_time":"2025-10-27T17:39:39.135627Z","price_level":"4221.97","new_quantity":"9.67760816"},{"side":"offer","event_time":"2025-10-27T17:39:39.135627Z","price_level":"4222.23","new_quantity":"13.29946694"},{"side":"offer","event_time":"2025-10-27T17:39:39.135627Z","price_level":"4222.25","new_quantity":"0"}]}]}
{"channel":"l2_data","client_id":"","timestamp":"2025-10-27T17:39:39.197744538Z","sequence_num":137546,"events":[{"type":"update","product_id":"BTC-USD","updates":[{"side":"bid","event_time":"2025-10-27T17:39:39.146152Z","price_level":"115640.32","new_quantity":"0.31603943"},{"side":"bid","event_time":"2025-10-27T17:39:39.146152Z","price_level":"115639","new_quantity":"0"},{"side":"bid","event_time":"2025-10-27T17:39:39.146152Z","price_level":"115635","new_quantity":"0"},{"side":"bid","event_time":"2025-10-27T17:39:39.146152Z","price_level":"115633.01","new_quantity":"1.19351579"},{"side":"bid","event_time":"2025-10-27T17:39:39.146152Z","price_level":"115633","new_quantity":"0.4"},{"side":"bid","event_time":"2025-10-27T17:39:39.146152Z","price_level":"115630","new_quantity":"0"},{"side":"offer","event_time":"2025-10-27T17:39:39.146152Z","price_level":"115681.56","new_quantity":"0.00432"},{"side":"offer","event_time":"2025-10-27T17:39:39.146152Z","price_level":"115681.57","new_quantity":"0.00432"},{"side":"offer","event_time":"2025-10-27T17:39:39.146152Z","price_level":"115690.04","new_quantity":"0.08"},{"side":"offer","event_time":"2025-10-27T17:39:39.146152Z","price_level":"115694","new_quantity":"0"},{"side":"offer","event_time":"2025-10-27T17:39:39.146152Z","price_level":"115695","new_quantity":"0"},{"side":"offer","event_time":"2025-10-27T17:39:39.146152Z","price_level":"115714.35","new_quantity":"0.04"},{"side":"offer","event_time":"2025-10-27T17:39:39.146152Z","price_level":"115718.16","new_quantity":"0"}]}]}
{"channel":"l2_data","client_id":"","timestamp":"2025-10-27T17:39:39.22093786Z","sequence_num":137547,"events":[{"type":"update","product_id":"ETH-USD","updates":[{"side":"bid","event_time":"2025-10-27T17:39:39.179269Z","price_level":"4218.67","new_quantity":"1.00131482"},{"side":"bid","event_time":"2025-10-27T17:39:39.179269Z","price_level":"4217.84","new_quantity":"0"},{"side":"bid","event_time":"2025-10-27T17:39:39.179269Z","price_level":"4217.76","new_quantity":"5.77917826"},{"side":"bid","event_time":"2025-10-27T17:39:39.179269Z","price_level":"4211.1","new_quantity":"6.641625"},{"side":"bid","event_time":"2025-10-27T17:39:39.179269Z","price_level":"4207.52","new_quantity":"1.043"},{"side":"bid","event_time":"2025-10-27T17:39:39.179269Z","price_level":"4203.35","new_quantity":"0"},{"side":"offer","event_time":"2025-10-27T17:39:39.179269Z","price_level":"4219.7","new_quantity":"0.49495661"},{"side":"offer","event_time":"2025-10-27T17:39:39.179269Z","price_level":"4222.22","new_quantity":"1.94391607"},{"side":"offer","event_time":"2025-10-27T17:39:39.179269Z","price_level":"4222.24","new_quantity":"0"}]}]}
{"channel":"l2_data","client_id":"","timestamp":"2025-10-27T17:39:39.245265616Z","sequence_num":137548,"events":[{"type":"update","product_id":"BTC-USD","updates":[{"side":"bid","event_time":"2025-10-27T17:39:39.174718Z","price_level":"115662.06","new_quantity":"0.07180501"},{"side":"bid","event_time":"2025-10-27T17:39:39.174718Z","price_level":"115640.32","new_quantity":"0.32979813"},{"side":"bid","event_time":"2025-10-27T17:39:39.174718Z","price_level":"115639","new_quantity":"0.4"},{"side":"bid","event_time":"2025-10-27T17:39:39.174718Z","price_level":"115637","new_quantity":"0"},{"side":"bid","event_time":"2025-10-27T17:39:39.174718Z","price_level":"115633.01","new_quantity":"2.23492714"},{"side":"bid","event_time":"2025-10-27T17:39:39.174718Z","price_level":"115632","new_quantity":"2"},{"side":"bid","event_time":"2025-10-27T17:39:39.174718Z","price_level":"115620","new_quantity":"1"},{"side":"bid","event_time":"2025-10-27T17:39:39.174718Z","price_level":"114769.28","new_quantity":"0.07007"},{"side":"bid","event_time":"2025-10-27T17:39:39.174718Z","price_level":"114554.85","new_quantity":"0.07007"},{"side":"bid","event_time":"2025-10-27T17:39:39.174718Z","price_level":"114340.42","new_quantity":"0.07007"}]}]}
{"channel":"l2_data","client_id":"","timestamp":"2025-10-27T17:39:39.269174673Z","sequence_num":137549,"events":[{"type":"update","product_id":"ETH-USD","updates":[{"side":"offer","event_time":"2025-10-27T17:39:39.18588Z","price_level":"4219.96","new_quantity":"0.95585794"}]}]}
{"channel":"l2_data","client_id":"","timestamp":"2025-10-27T17:39:38.171924931Z","sequence_num":137492,"events":[{"type":"update","product_id":"ETH-USD","updates":[{"side":"bid","event_time":"2025-10-27T17:39:38.126565Z","price_level":"4218.71","new_quantity":"0.01373526"},{"side":"bid","event_time":"2025-10-27T17:39:38.126565Z","price_level":"4217.95","new_quantity":"5.77891794"},{"side":"bid","event_time":"2025-10-27T17:39:38.126565Z","price_level":"4217.9","new_quantity":"0.519"},{"side":"bid","event_time":"2025-10-27T17:39:38.126565Z","price_level":"4217.81","new_quantity":"1.09468405"},{"side":"bid","event_time":"2025-10-27T17:39:38.126565Z","price_level":"4217.73","new_quantity":"0"},{"side":"bid","event_time":"2025-10-27T17:39:38.126565Z","price_level":"4217.72","new_quantity":"0"},{"side":"bid","event_time":"2025-10-27T17:39:38.126565Z","price_level":"4217.61","new_quantity":"17.998356"},{"side":"bid","event_time":"2025-10-27T17:39:38.126565Z","price_level":"4215.54","new_quantity":"8.84481075"},{"side":"bid","event_time":"2025-10-27T17:39:38.126565Z","price_level":"4215.53","new_quantity":"0"},{"side":"bid","event_time":"2025-10-27T17:39:38.126565Z","price_level":"4215.37","new_quantity":"0"},{"side":"bid","event_time":"2025-10-27T17:39:38.126565Z","price_level":"4214.58","new_quantity":"0"},{"side":"bid","event_time":"2025-10-27T17:39:38.126565Z","price_level":"4214.51","new_quantity":"0"},{"side":"bid","event_time":"2025-10-27T17:39:38.126565Z","price_level":"4214.34","new_quantity":"0.533362"},{"side":"bid","event_time":"2025-10-27T17:39:38.126565Z","price_level":"4214.26","new_quantity":"19.62258417"},{"side":"bid","event_time":"2025-10-27T17:39:38.126565Z","price_level":"4213.44","new_quantity":"0.0019946"},{"side":"bid","event_time":"2025-10-27T17:39:38.126565Z","price_level":"4213.28","new_quantity":"0.00401428"},{"side":"bid","event_time":"2025-10-27T17:39:38.126565Z","price_level":"4191.63","new_quantity":"0"},{"side":"offer","event_time":"2025-10-27T17:39:38.126565Z","price_level":"4218.85","new_quantity":"0.16876"},{"side":"offer","event_time":"2025-10-27T17:39:38.126565Z","price_level":"4219.76","new_quantity":"0.4"},{"side":"offer","event_time":"2025-10-27T17:39:38.126565Z","price_level":"4219.83","new_quantity":"1.88521896"},{"side":"offer","event_time":"2025-10-27T17:39:38.126565Z","price_level":"4220.09","new_quantity":"0.5080443"},{"side":"offer","event_time":"2025-10-27T17:39:38.126565Z","price_level":"4221.84","new_quantity":"0"},{"side":"offer","event_time":"2025-10-27T17:39:38.126565Z","price_level":"4222.11","new_quantity":"1.94391607"},{"side":"offer","event_time":"2025-10-27T17:39:38.126565Z","price_level":"4222.12","new_quantity":"0.07798752"},{"side":"offer","event_time":"2025-10-27T17:39:38.126565Z","price_level":"4222.39","new_quantity":"13.72763631"},{"side":"offer","event_time":"2025-10-27T17:39:38.126565Z","price_level":"4223.45","new_quantity":"0.19999622"},{"side":"offer","event_time":"2025-10-27T17:39:38.126565Z","price_level":"4223.68","new_quantity":"9.52479195"}]}]}
{"channel":"l2_data","client_id":"","timestamp":"2025-10-27T17:39:38.197110591Z","sequence_num":137493,"events":[{"type":"update","product_id":"BTC-USD","updates":[{"side":"bid","event_time":"2025-10-27T17:39:38.134183Z","price_level":"115662.06","new_quantity":"0.02196896"},{"side":"bid","event_time":"2025-10-27T17:39:38.134183Z","price_level":"115633","new_quantity":"0.4"},{"side":"bid","event_time":"2025-10-27T17:39:38.134183Z","price_level":"115630.72","new_quantity":"0"},{"side":"bid","event_time":"2025-10-27T17:39:38.134183Z","price_level":"115628.54","new_quantity":"0.3688877"},{"side":"bid","event_time":"2025-10-27T17:39:38.134183Z","price_level":"115613.94","new_quantity":"0.65828788"},{"side":"bid","event_time":"2025-10-27T17:39:38.134183Z","price_level":"115579.25","new_quantity":"1.21911792"},{"side":"offer","event_time":"2025-10-27T17:39:38.134183Z","price_level":"115689.59","new_quantity":"0.00227404"},{"side":"offer","event_time":"2025-10-27T17:39:38.134183Z","price_level":"115689.6","new_quantity":"0.00001"},{"side":"offer","event_time":"2025-10-27T17:39:38.134183Z","price_level":"115692","new_quantity":"0.4"},{"side":"offer","event_time":"2025-10-27T17:39:38.134183Z","price_level":"115693","new_quantity":"2"},{"side":"offer","event_time":"2025-10-27T17:39:38.134183Z","price_level":"115706.54","new_quantity":"0.02014916"}]}]}
{"channel":"l2_data","client_id":"","timestamp":"2025-10-27T17:39:38.221834869Z","sequence_num":137494,"events":[{"type":"update","product_id":"ETH-USD","updates":[{"side":"bid","event_time":"2025-10-27T17:39:38.157968Z","price_level":"4218.71","new_quantity":"0.03444159"},{"side":"bid","event_time":"2025-10-27T17:39:38.157968Z","price_level":"4218.46","new_quantity":"0"},{"side":"bid","event_time":"2025-10-27T17:39:38.157968Z","price_level":"4218.41","new_quantity":"15.63965976"},{"side":"bid","event_time":"2025-10-27T17:39:38.157968Z","price_level":"4218.22","new_quantity":"0"},{"side":"bid","event_time":"2025-10-27T17:39:38.157968Z","price_level":"4218.13","new_quantity":"1.65596"},{"side":"bid","event_time":"2025-10-27T17:39:38.157968Z","price_level":"4218.02","new_quantity":"1.12737079"},{"side":"bid","event_time":"2025-10-27T17:39:38.157968Z","price_level":"4217.94","new_quantity":"1.65571"},{"side":"offer","event_time":"2025-10-27T17:39:38.157968Z","price_level":"4219.09","new_quantity":"0.07110538"},{"side":"offer","event_time":"2025-10-27T17:39:38.157968Z","price_level":"4219.1","new_quantity":"0.519"},{"side":"offer","event_time":"2025-10-27T17:39:38.157968Z","price_level":"4219.83","new_quantity":"1.125"},{"side":"offer","event_time":"2025-10-27T17:39:38.157968Z","price_level":"4220.2","new_quantity":"0"},{"side":"offer","event_time":"2025-10-27T17:39:38.157968Z","price_level":"4220.4","new_quantity":"0"}]}]}
{"channel":"l2_data","client_id":"","timestamp":"2025-10-27T17:39:38.24809579Z","sequence_num":137495,"events":[{"type":"update","product_id":"BTC-USD","updates":[{"side":"bid","event_time":"2025-10-27T17:39:38.190078Z","price_level":"115662.06","new_quantity":"0.02393277"},{"side":"bid","event_time":"2025-10-27T17:39:38.190078Z","price_level":"114552.58","new_quantity":"0.07007"},{"side":"bid","event_time":"2025-10-27T17:39:38.190078Z","price_level":"114552.46","new_quantity":"0"},{"side":"bid","event_time":"2025-10-27T17:39:38.190078Z","price_level":"114123.6","new_quantity":"0"},{"side":"bid","event_time":"2025-10-27T17:39:38.190078Z","price_level":"114123.57","new_quantity":"0.07007"},{"side":"offer","event_time":"2025-10-27T17:39:38.190078Z","price_level":"115662.07","new_quantity":"0.02815783"},{"side":"offer","event_time":"2025-10-27T17:39:38.190078Z","price_level":"115689.59","new_quantity":"0"},{"side":"offer","event_time":"2025-10-27T17:39:38.190078Z","price_level":"115689.72","new_quantity":"0"},{"side":"offer","event_time":"2025-10-27T17:39:38.190078Z","price_level":"115692","new_quantity":"0"},{"side":"offer","event_time":"2025-10-27T17:39:38.190078Z","price_level":"115692.16","new_quantity":"0.03458134"},{"side":"offer","event_time":"2025-10-27T17:39:38.190078Z","price_level":"115693","new_quantity":"0"}]}]}
