{"channel":"l2_data","client_id":"","timestamp":"2025-10-27T17:39:44.321236349Z","sequence_num":137773,"events":[{"type":"update","product_id":"ETH-USD","updates":[{"side":"bid","event_time":"2025-10-27T17:39:44.278178Z","price_level":"4218.27","new_quantity":"0"},{"side":"bid","event_time":"2025-10-27T17:39:44.278178Z","price_level":"4217.92","new_quantity":"0.00237084"},{"side":"bid","event_time":"2025-10-27T17:39:44.278178Z","price_level":"4170.3","new_quantity":"0.38366567"},{"side":"bid","event_time":"2025-10-27T17:39:44.278178Z","price_level":"4150.24","new_quantity":"0.57827939"},{"side":"bid","event_time":"2025-10-27T17:39:44.278178Z","price_level":"4130.19","new_quantity":"0.77478305"},{"side":"offer","event_time":"2025-10-27T17:39:44.278178Z","price_level":"4218.44","new_quantity":"0.11852745"},{"side":"offer","event_time":"2025-10-27T17:39:44.278178Z","price_level":"4218.6","new_quantity":"0.572"},{"side":"offer","event_time":"2025-10-27T17:39:44.278178Z","price_level":"4223.82","new_quantity":"0.00028609"}]}]}
{"channel":"l2_data","client_id":"","timestamp":"2025-10-27T17:39:44.347805679Z","sequence_num":137775,"events":[{"type":"update","product_id":"BTC-USD","updates":[{"side":"bid","event_time":"2025-10-27T17:39:44.313666Z","price_level":"115626.86","new_quantity":"0"},{"side":"bid","event_time":"2025-10-27T17:39:44.313666Z","price_level":"115621.31","new_quantity":"0.00432"},{"side":"bid","event_time":"2025-10-27T17:39:44.313666Z","price_level":"115621.28","new_quantity":"0.00432"},{"side":"bid","event_time":"2025-10-27T17:39:44.313666Z","price_level":"115552.17","new_quantity":"0.81389064"},{"side":"bid","event_time":"2025-10-27T17:39:44.313666Z","price_level":"115552.16","new_quantity":"1.16521655"},{"side":"bid","event_time":"2025-10-27T17:39:44.313666Z","price_level":"115552.15","new_quantity":"0"},{"side":"bid","event_time":"2025-10-27T17:39:44.313666Z","price_level":"115552.14","new_quantity":"0"},{"side":"bid","event_time":"2025-10-27T17:39:44.313666Z","price_level":"115172.54","new_quantity":"0.07007"},{"side":"bid","event_time":"2025-10-27T17:39:44.313666Z","price_level":"115172.27","new_quantity":"0"},{"side":"bid","event_time":"2025-10-27T17:39:44.313666Z","price_level":"114761.25","new_quantity":"0"},{"side":"bid","event_time":"2025-10-27T17:39:44.313666Z","price_level":"114100.01","new_quantity":"0"},{"side":"offer","event_time":"2025-10-27T17:39:44.313666Z","price_level":"115640.92","new_quantity":"0.02382796"},{"side":"offer","event_time":"2025-10-27T17:39:44.313666Z","price_level":"115658.36","new_quantity":"0.00432"},{"side":"offer","event_time":"2025-10-27T17:39:44.313666Z","price_level":"115658.37","new_quantity":"0.00432"},{"side":"offer","event_time":"2025-10-27T17:39:44.313666Z","price_level":"115667","new_quantity":"0"},{"side":"offer","event_time":"2025-10-27T17:39:44.313666Z","price_level":"115668","new_quantity":"2"},{"side":"offer","event_time":"2025-10-27T17:39:44.313666Z","price_level":"115675.57","new_quantity":"0.21983076"},{"side":"offer","event_time":"2025-10-27T17:39:44.313666Z","price_level":"115680","new_quantity":"0"},{"side":"offer","event_time":"2025-10-27T17:39:44.313666Z","price_level":"116320.01","new_quantity":"0.07007"},{"side":"offer","event_time":"2025-10-27T17:39:44.313666Z","price_level":"116320.06","new_quantity":"0"},{"side":"offer","event_time":"2025-10-27T17:39:44.313666Z","price_level":"116963.3","new_quantity":"0.07007"}]}]}
{"channel":"l2_data","client_id":"","timestamp":"2025-10-27T17:39:44.368791297Z","sequence_num":137777,"events":[{"type":"update","product_id":"ETH-USD","updates":[{"side":"offer","event_time":"2025-10-27T17:39:44.30465Z","price_level":"4244.91","new_quantity":"0"}]}]}
{"channel":"l2_data","client_id":"","timestamp":"2025-10-27T17:39:44.394633798Z","sequence_num":137779,"events":[{"type":"update","product_id":"BTC-USD","updates":[{"side":"bid","event_time":"2025-10-27T17:39:44.338531Z","price_level":"115628.31","new_quantity":"0.02161184"},{"side":"bid","event_time":"2025-10-27T17:39:44.338531Z","price_level":"115623.63","new_quantity":"0.00432"},{"side":"bid","event_time":"2025-10-27T17:39:44.338531Z","price_level":"115623.6","new_quantity":"0.00432"}]}]}
{"channel":"l2_data","client_id":"","timestamp":"2025-10-27T17:39:44.420663585Z","sequence_num":137780,"events":[{"type":"update","product_id":"ETH-USD","updates":[{"side":"bid","event_time":"2025-10-27T17:39:44.376932Z","price_level":"4217.93","new_quantity":"0"},{"side":"bid","event_time":"2025-10-27T17:39:44.376932Z","price_level":"4217.74","new_quantity":"1.24354667"},{"side":"offer","event_time":"2025-10-27T17:39:44.376932Z","price_level":"4218.33","new_quantity":"0.37110807"},{"side":"offer","event_time":"2025-10-27T17:39:44.376932Z","price_level":"4218.39","new_quantity":"0.07111717"},{"side":"offer","event_time":"2025-10-27T17:39:44.376932Z","price_level":"4244.91","new_quantity":"0.1536"}]}]}
{"channel":"l2_data","client_id":"","timestamp":"2025-10-27T17:39:44.447306308Z","sequence_num":137781,"events":[{"type":"update","product_id":"BTC-USD","updates":[{"side":"bid","event_time":"2025-10-27T17:39:44.395065Z","price_level":"115552.19","new_quantity":"0.81389052"},{"side":"bid","event_time":"2025-10-27T17:39:44.395065Z","price_level":"115552.18","new_quantity":"1.16521634"},{"side":"bid","event_time":"2025-10-27T17:39:44.395065Z","price_level":"115552.17","new_quantity":"0"},{"side":"bid","event_time":"2025-10-27T17:39:44.395065Z","price_level":"115552.16","new_quantity":"0"},{"side":"bid","event_time":"2025-10-27T17:39:44.395065Z","price_level":"101185.8","new_quantity":"0.00049568"},{"side":"offer","event_time":"2025-10-27T17:39:44.395065Z","price_level":"115640.92","new_quantity":"0.02629756"},{"side":"offer","event_time":"2025-10-27T17:39:44.395065Z","price_level":"115667","new_quantity":"2"},{"side":"offer","event_time":"2025-10-27T17:39:44.395065Z","price_level":"115668","new_quantity":"2.4"},{"side":"offer","event_time":"2025-10-27T17:39:44.395065Z","price_level":"115675.57","new_quantity":"0.62194177"},{"side":"offer","event_time":"2025-10-27T17:39:44.395065Z","price_level":"115680","new_quantity":"1"},{"side":"offer","event_time":"2025-10-27T17:39:44.395065Z","price_level":"115688.91","new_quantity":"0.02014916"}]}]}
{"channel":"l2_data","client_id":"","timestamp":"2025-10-27T17:39:44.468871181Z","sequence_num":137782,"events":[{"type":"update","product_id":"ETH-USD","updates":[{"side":"bid","event_time":"2025-10-27T17:39:44.406783Z","price_level":"4218.1","new_quantity":"0"},{"side":"bid","event_time":"2025-10-27T17:39:44.406783Z","price_level":"4217.74","new_quantity":"1.125"},{"side":"bid","event_time":"2025-10-27T17:39:44.406783Z","price_level":"4217.71","new_quantity":"0"},{"side":"bid","event_time":"2025-10-27T17:39:44.406783Z","price_level":"4217.32","new_quantity":"0.59279352"}]}]}
{"channel":"l2_data","client_id":"","timestamp":"2025-10-27T17:39:44.496919259Z","sequence_num":137783,"events":[{"type":"update","product_id":"BTC-USD","updates":[{"side":"bid","event_time":"2025-10-27T17:39:44.440894Z","price_level":"115620.65","new_quantity":"0.4900743"},{"side":"bid","event_time":"2025-10-27T17:39:44.440894Z","price_level":"115619","new_quantity":"0"},{"side":"bid","event_time":"2025-10-27T17:39:44.440894Z","price_level":"115553.15","new_quantity":"0"},{"side":"bid","event_time":"2025-10-27T17:39:44.440894Z","price_level":"115550.44","new_quantity":"0.00043232"},{"side":"bid","event_time":"2025-10-27T17:39:44.440894Z","price_level":"115536.92","new_quantity":"0"},{"side":"bid","event_time":"2025-10-27T17:39:44.440894Z","price_level":"115534.44","new_quantity":"0.0107669"},{"side":"bid","event_time":"2025-10-27T17:39:44.440894Z","price_level":"101185.8","new_quantity":"0.0049568"},{"side":"offer","event_time":"2025-10-27T17:39:44.440894Z","price_level":"115667","new_quantity":"0"},{"side":"offer","event_time":"2025-10-27T17:39:44.440894Z","price_level":"115668","new_quantity":"2"},{"side":"offer","event_time":"2025-10-27T17:39:44.440894Z","price_level":"115674","new_quantity":"0"},{"side":"offer","event_time":"2025-10-27T17:39:44.440894Z","price_level":"115675.57","new_quantity":"0.21983076"},{"side":"offer","event_time":"2025-10-27T17:39:44.440894Z","price_level":"115680","new_quantity":"0"},{"side":"offer","event_time":"2025-10-27T17:39:44.440894Z","price_level":"117100.99","new_quantity":"0.00002466"},{"side":"offer","event_time":"2025-10-27T17:39:44.440894Z","price_level":"117135.45","new_quantity":"0"}]}]}
{"channel":"l2_data","client_id":"","timestamp":"2025-10-27T17:39:44.747847614Z","sequence_num":137796,"events":[{"type":"update","product_id":"BTC-USD","updates":[{"side":"bid","event_time":"2025-10-27T17:39:44.705743Z","price_level":"115640","new_quantity":"0.0213"},{"side":"bid","event_time":"2025-10-27T17:39:44.705743Z","price_level":"115638.61","new_quantity":"0"},{"side":"bid","event_time":"2025-10-27T17:39:44.705743Z","price_level":"115636.01","new_quantity":"0.00172956"},{"side":"bid","event_time":"2025-10-27T17:39:44.705743Z","price_level":"115635.86","new_quantity":"0.00864783"},{"side":"bid","event_time":"2025-10-27T17:39:44.705743Z","price_level":"115634.48","new_quantity":"0"},{"side":"bid","event_time":"2025-10-27T17:39:44.705743Z","price_level":"115632.21","new_quantity":"0"},{"side":"bid","event_time":"2025-10-27T17:39:44.705743Z","price_level":"115631.63","new_quantity":"0.08648152"},{"side":"bid","event_time":"2025-10-27T17:39:44.705743Z","price_level":"115627.31","new_quantity":"0"},{"side":"bid","event_time":"2025-10-27T17:39:44.705743Z","price_level":"115621.54","new_quantity":"0"},{"side":"bid","event_time":"2025-10-27T17:39:44.705743Z","price_level":"115621.31","new_quantity":"0"},{"side":"bid","event_time":"2025-10-27T17:39:44.705743Z","price_level":"115621","new_quantity":"0.4"},{"side":"bid","event_time":"2025-10-27T17:39:44.705743Z","price_level":"115618","new_quantity":"0"},{"side":"bid","event_time":"2025-10-27T17:39:44.705743Z","price_level":"115617","new_quantity":"0.4"},{"side":"bid","event_time":"2025-10-27T17:39:44.705743Z","price_level":"115616","new_quantity":"0"},{"side":"bid","event_time":"2025-10-27T17:39:44.705743Z","price_level":"115612.97","new_quantity":"1.51226753"},{"side":"bid","event_time":"2025-10-27T17:39:44.705743Z","price_level":"115612","new_quantity":"2"},{"side":"bid","event_time":"2025-10-27T17:39:44.705743Z","price_level":"115611.01","new_quantity":"1.16045649"},{"side":"bid","event_time":"2025-10-27T17:39:44.705743Z","price_level":"115552.25","new_quantity":"0.81414825"},{"side":"bid","event_time":"2025-10-27T17:39:44.705743Z","price_level":"115552.24","new_quantity":"1.16521574"},{"side":"bid","event_time":"2025-10-27T17:39:44.705743Z","price_level":"115552.23","new_quantity":"0"},{"side":"bid","event_time":"2025-10-27T17:39:44.705743Z","price_level":"115552.22","new_quantity":"0"},{"side":"bid","event_time":"2025-10-27T17:39:44.705743Z","price_level":"115172.54","new_quantity":"0"},{"side":"offer","event_time":"2025-10-27T17:39:44.705743Z","price_level":"115640.92","new_quantity":"0.00246318"},{"side":"offer","event_time":"2025-10-27T17:39:44.705743Z","price_level":"115644.72","new_quantity":"0"},{"side":"offer","event_time":"2025-10-27T17:39:44.705743Z","price_level":"115644.73","new_quantity":"0"},{"side":"offer","event_time":"2025-10-27T17:39:44.705743Z","price_level":"115646.11","new_quantity":"0.02594121"},{"side":"offer","event_time":"2025-10-27T17:39:44.705743Z","price_level":"115658.36","new_quantity":"0"},{"side":"offer","event_time":"2025-10-27T17:39:44.705743Z","price_level":"115658.37","new_quantity":"0"},{"side":"offer","event_time":"2025-10-27T17:39:44.705743Z","price_level":"115661.55","new_quantity":"0.0850725"},{"side":"offer","event_time":"2025-10-27T17:39:44.705743Z","price_level":"115661.56","new_quantity":"0"},{"side":"offer","event_time":"2025-10-27T17:39:44.705743Z","price_level":"115665.32","new_quantity":"0.00432"},{"side":"offer","event_time":"2025-10-27T17:39:44.705743Z","price_level":"115665.33","new_quantity":"0.00432"},{"side":"offer","event_time":"2025-10-27T17:39:44.705743Z","price_level":"115666.99","new_quantity":"0.3891421"},{"side":"offer","event_time":"2025-10-27T17:39:44.705743Z","price_level":"115667","new_quantity":"0"},{"side":"offer","event_time":"2025-10-27T17:39:44.705743Z","price_level":"115669.99","new_quantity":"0.09229612"},{"side":"offer","event_time":"2025-10-27T17:39:44.705743Z","price_level":"115670","new_quantity":"0"},{"side":"offer","event_time":"2025-10-27T17:39:44.705743Z","price_level":"115670.99","new_quantity":"0"},{"side":"offer","event_time":"2025-10-27T17:39:44.705743Z","price_level":"115673.99","new_quantity":"0"},{"side":"offer","event_time":"2025-10-27T17:39:44.705743Z","price_level":"115675.43","new_quantity":"0.37677057"},{"side":"offer","event_time":"2025-10-27T17:39:44.705743Z","price_level":"115675.44","new_quantity":"0.17294714"},{"side":"offer","event_time":"2025-10-27T17:39:44.705743Z","price_level":"115675.57","new_quantity":"0"},{"side":"offer","event_time":"2025-10-27T17:39:44.705743Z","price_level":"115676","new_quantity":"0"},{"side":"offer","event_time":"2025-10-27T17:39:44.705743Z","price_level":"115680","new_quantity":"0"},{"side":"offer","event_time":"2025-10-27T17:39:44.705743Z","price_level":"115692.19","new_quantity":"0.5"},{"side":"offer","event_time":"2025-10-27T17:39:44.705743Z","price_level":"115693.44","new_quantity":"0"},{"side":"offer","event_time":"2025-10-27T17:39:44.705743Z","price_level":"115797.89","new_quantity":"0.045"},{"side":"offer","event_time":"2025-10-27T17:39:44.705743Z","price_level":"115812.95","new_quantity":"0"},{"side":"offer","event_time":"2025-10-27T17:39:44.705743Z","price_level":"116376.13","new_quantity":"0.045"}]}]}
{"channel":"l2_data","client_id":"","timestamp":"2025-10-27T17:39:44.770913496Z","sequence_num":137797,"events":[{"type":"update","product_id":"ETH-USD","updates":[{"side":"bid","event_time":"2025-10-27T17:39:44.733898Z","price_level":"4218.3","new_quantity":"0"},{"side":"bid","event_time":"2025-10-27T17:39:44.733898Z","price_level":"4218.02","new_quantity":"0.00237079"},{"side":"bid","event_time":"2025-10-27T17:39:44.733898Z","price_level":"4218.01","new_quantity":"0.6668896"},{"side":"bid","event_time":"2025-10-27T17:39:44.733898Z","price_level":"4218","new_quantity":"0.59369717"},{"side":"bid","event_time":"2025-10-27T17:39:44.733898Z","price_level":"4217.94","new_quantity":"0.002"},{"side":"bid","event_time":"2025-10-27T17:39:44.733898Z","price_level":"4217.92","new_quantity":"0.02070633"},{"side":"bid","event_time":"2025-10-27T17:39:44.733898Z","price_level":"4217.91","new_quantity":"0"},{"side":"bid","event_time":"2025-10-27T17:39:44.733898Z","price_level":"4217.83","new_quantity":"0.002"},{"side":"bid","event_time":"2025-10-27T17:39:44.733898Z","price_level":"4217.65","new_quantity":"0"},{"side":"bid","event_time":"2025-10-27T17:39:44.733898Z","price_level":"4217.6","new_quantity":"30"},{"side":"offer","event_time":"2025-10-27T17:39:44.733898Z","price_level":"4218.4","new_quantity":"0.572"},{"side":"offer","event_time":"2025-10-27T17:39:44.733898Z","price_level":"4218.43","new_quantity":"0"},{"side":"offer","event_time":"2025-10-27T17:39:44.733898Z","price_level":"4218.44","new_quantity":"0"},{"side":"offer","event_time":"2025-10-27T17:39:44.733898Z","price_level":"4218.46","new_quantity":"0"},{"side":"offer","event_time":"2025-10-27T17:39:44.733898Z","price_level":"4218.47","new_quantity":"0"},{"side":"offer","event_time":"2025-10-27T17:39:44.733898Z","price_level":"4218.49","new_quantity":"0"},{"side":"offer","event_time":"2025-10-27T17:39:44.733898Z","price_level":"4218.5","new_quantity":"0.64311532"},{"side":"offer","event_time":"2025-10-27T17:39:44.733898Z","price_level":"4218.51","new_quantity":"0.11852551"},{"side":"offer","event_time":"2025-10-27T17:39:44.733898Z","price_level":"4218.53","new_quantity":"0.07111481"},{"side":"offer","event_time":"2025-10-27T17:39:44.733898Z","price_level":"4218.92","new_quantity":"0.59256973"},{"side":"offer","event_time":"2025-10-27T17:39:44.733898Z","price_level":"4219.1","new_quantity":"0"},{"side":"offer","event_time":"2025-10-27T17:39:44.733898Z","price_level":"4219.25","new_quantity":"0.01608562"},{"side":"offer","event_time":"2025-10-27T17:39:44.733898Z","price_level":"4219.8","new_quantity":"0"},{"side":"offer","event_time":"2025-10-27T17:39:44.733898Z","price_level":"4221.51","new_quantity":"0"},{"side":"offer","event_time":"2025-10-27T17:39:44.733898Z","price_level":"4221.81","new_quantity":"2.08818968"}]}]}
{"channel":"l2_data","client_id":"","timestamp":"2025-10-27T17:39:44.798247627Z","sequence_num":137798,"events":[{"type":"update","product_id":"BTC-USD","updates":[{"side":"bid","event_time":"2025-10-27T17:39:44.760072Z","price_level":"115627.49","new_quantity":"0.00054701"},{"side":"bid","event_time":"2025-10-27T17:39:44.760072Z","price_level":"115627.48","new_quantity":"0.16578"},{"side":"bid","event_time":"2025-10-27T17:39:44.760072Z","price_level":"115623.63","new_quantity":"0"},{"side":"bid","event_time":"2025-10-27T17:39:44.760072Z","price_level":"115621.28","new_quantity":"0"},{"side":"bid","event_time":"2025-10-27T17:39:44.760072Z","price_level":"115615","new_quantity":"0.4"},{"side":"bid","event_time":"2025-10-27T17:39:44.760072Z","price_level":"115612.98","new_quantity":"0.33125703"},{"side":"bid","event_time":"2025-10-27T17:39:44.760072Z","price_level":"115612.97","new_quantity":"0.16716"},{"side":"bid","event_time":"2025-10-27T17:39:44.760072Z","price_level":"115612.01","new_quantity":"0"},{"side":"bid","event_time":"2025-10-27T17:39:44.760072Z","price_level":"115612","new_quantity":"0"},{"side":"bid","event_time":"2025-10-27T17:39:44.760072Z","price_level":"115580.08","new_quantity":"0.76386232"},{"side":"bid","event_time":"2025-10-27T17:39:44.760072Z","price_level":"115571.12","new_quantity":"0"},{"side":"bid","event_time":"2025-10-27T17:39:44.760072Z","price_level":"115571.11","new_quantity":"0"},{"side":"bid","event_time":"2025-10-27T17:39:44.760072Z","price_level":"115571.1","new_quantity":"0"},{"side":"bid","event_time":"2025-10-27T17:39:44.760072Z","price_level":"115569.51","new_quantity":"1.05802298"},{"side":"bid","event_time":"2025-10-27T17:39:44.760072Z","price_level":"115569.5","new_quantity":"1.5"},{"side":"bid","event_time":"2025-10-27T17:39:44.760072Z","price_level":"115567.27","new_quantity":"0"},{"side":"bid","event_time":"2025-10-27T17:39:44.760072Z","price_level":"101185.8","new_quantity":"0"},{"side":"offer","event_time":"2025-10-27T17:39:44.760072Z","price_level":"115647.5","new_quantity":"0"},{"side":"offer","event_time":"2025-10-27T17:39:44.760072Z","price_level":"115647.51","new_quantity":"0"},{"side":"offer","event_time":"2025-10-27T17:39:44.760072Z","price_level":"115647.52","new_quantity":"0.00007597"},{"side":"offer","event_time":"2025-10-27T17:39:44.760072Z","price_level":"115651.82","new_quantity":"0.00113787"},{"side":"offer","event_time":"2025-10-27T17:39:44.760072Z","price_level":"115666.99","new_quantity":"0"},{"side":"offer","event_time":"2025-10-27T17:39:44.760072Z","price_level":"115669.97","new_quantity":"0.30395174"},{"side":"offer","event_time":"2025-10-27T17:39:44.760072Z","price_level":"115669.98","new_quantity":"0.3891219"},{"side":"offer","event_time":"2025-10-27T17:39:44.760072Z","price_level":"115669.99","new_quantity":"0"},{"side":"offer","event_time":"2025-10-27T17:39:44.760072Z","price_level":"115675.43","new_quantity":"0.21983075"},{"side":"offer","event_time":"2025-10-27T17:39:44.760072Z","price_level":"115686.99","new_quantity":"0.40900007"},{"side":"offer","event_time":"2025-10-27T17:39:44.760072Z","price_level":"115717.21","new_quantity":"0"},{"side":"offer","event_time":"2025-10-27T17:39:44.760072Z","price_level":"115718.1","new_quantity":"1"},{"side":"offer","event_time":"2025-10-27T17:39:44.760072Z","price_level":"115718.3","new_quantity":"0"},{"side":"offer","event_time":"2025-10-27T17:39:44.760072Z","price_level":"115727.14","new_quantity":"0.56827756"},{"side":"offer","event_time":"2025-10-27T17:39:44.760072Z","price_level":"115727.15","new_quantity":"0.37933542"},{"side":"offer","event_time":"2025-10-27T17:39:44.760072Z","price_level":"115735.09","new_quantity":"0"},{"side":"offer","event_time":"2025-10-27T17:39:44.760072Z","price_level":"115735.1","new_quantity":"0"}]}]}
{"channel":"l2_data","client_id":"","timestamp":"2025-10-27T17:39:44.820908207Z","sequence_num":137799,"events":[{"type":"update","product_id":"ETH-USD","updates":[{"side":"bid","event_time":"2025-10-27T17:39:44.772787Z","price_level":"4217.75","new_quantity":"0.001"},{"side":"offer","event_time":"2025-10-27T17:39:44.772787Z","price_level":"4219.1","new_quantity":"0.01466549"},{"side":"offer","event_time":"2025-10-27T17:39:44.772787Z","price_level":"4219.25","new_quantity":"0.001"},{"side":"offer","event_time":"2025-10-27T17:39:44.772787Z","price_level":"4219.8","new_quantity":"20"}]}]}
{"channel":"l2_data","client_id":"","timestamp":"2025-10-27T17:39:44.847611475Z","sequence_num":137801,"events":[{"type":"update","product_id":"BTC-USD","updates":[{"side":"bid","event_time":"2025-10-27T17:39:44.78798Z","price_level":"115625.95","new_quantity":"0.00432"},{"side":"bid","event_time":"2025-10-27T17:39:44.78798Z","price_level":"115625.92","new_quantity":"0.00432"},{"side":"bid","event_time":"2025-10-27T17:39:44.78798Z","price_level":"115621.7","new_quantity":"0"},{"side":"bid","event_time":"2025-10-27T17:39:44.78798Z","price_level":"115553.64","new_quantity":"0.00001"},{"side":"offer","event_time":"2025-10-27T17:39:44.78798Z","price_level":"115665.32","new_quantity":"0"},{"side":"offer","event_time":"2025-10-27T17:39:44.78798Z","price_level":"115665.33","new_quantity":"0"},{"side":"offer","event_time":"2025-10-27T17:39:44.78798Z","price_level":"115711.98","new_quantity":"0"},{"side":"offer","event_time":"2025-10-27T17:39:44.78798Z","price_level":"115711.99","new_quantity":"0.00043237"},{"side":"offer","event_time":"2025-10-27T17:39:44.78798Z","price_level":"115715.59","new_quantity":"0.00043232"},{"side":"offer","event_time":"2025-10-27T17:39:44.78798Z","price_level":"115718.1","new_quantity":"0"},{"side":"offer","event_time":"2025-10-27T17:39:44.78798Z","price_level":"115718.4","new_quantity":"1"}]}]}
{"channel":"l2_data","client_id":"","timestamp":"2025-10-27T17:39:44.870457283Z","sequence_num":137802,"events":[{"type":"update","product_id":"ETH-USD","updates":[{"side":"bid","event_time":"2025-10-27T17:39:44.804044Z","price_level":"4217.95","new_quantity":"0.11854079"},{"side":"bid","event_time":"2025-10-27T17:39:44.804044Z","price_level":"4216.38","new_quantity":"1.49937492"},{"side":"bid","event_time":"2025-10-27T17:39:44.804044Z","price_level":"4215.04","new_quantity":"6.50757688"},{"side":"bid","event_time":"2025-10-27T17:39:44.804044Z","price_level":"4211.72","new_quantity":"1.11831963"},{"side":"offer","event_time":"2025-10-27T17:39:44.804044Z","price_level":"4221.8","new_quantity":"13.30082152"},{"side":"offer","event_time":"2025-10-27T17:39:44.804044Z","price_level":"4221.82","new_quantity":"0.09792687"}]}]}
{"channel":"l2_data","client_id":"","timestamp":"2025-10-27T17:39:44.898265997Z","sequence_num":137804,"events":[{"type":"update","product_id":"BTC-USD","updates":[{"side":"bid","event_time":"2025-10-27T17:39:44.851826Z","price_level":"115640.91","new_quantity":"0.08335469"},{"side":"bid","event_time":"2025-10-27T17:39:44.851826Z","price_level":"115625.95","new_quantity":"0"},{"side":"bid","event_time":"2025-10-27T17:39:44.851826Z","price_level":"115625.92","new_quantity":"0"},{"side":"bid","event_time":"2025-10-27T17:39:44.851826Z","price_level":"115615.01","new_quantity":"1.8080479"},{"side":"bid","event_time":"2025-10-27T17:39:44.851826Z","price_level":"115614.01","new_quantity":"0.33125408"},{"side":"bid","event_time":"2025-10-27T17:39:44.851826Z","price_level":"115614","new_quantity":"2"},{"side":"bid","event_time":"2025-10-27T17:39:44.851826Z","price_level":"115612.98","new_quantity":"0"},{"side":"bid","event_time":"2025-10-27T17:39:44.851826Z","price_level":"115612.97","new_quantity":"0"},{"side":"bid","event_time":"2025-10-27T17:39:44.851826Z","price_level":"115552.27","new_quantity":"0.81414814"},{"side":"bid","event_time":"2025-10-27T17:39:44.851826Z","price_level":"115552.26","new_quantity":"1.16521554"},{"side":"bid","event_time":"2025-10-27T17:39:44.851826Z","price_level":"115552.25","new_quantity":"0"},{"side":"bid","event_time":"2025-10-27T17:39:44.851826Z","price_level":"115552.24","new_quantity":"0"},{"side":"offer","event_time":"2025-10-27T17:39:44.851826Z","price_level":"115651.82","new_quantity":"0"},{"side":"offer","event_time":"2025-10-27T17:39:44.851826Z","price_level":"115663","new_quantity":"0.00432"},{"side":"offer","event_time":"2025-10-27T17:39:44.851826Z","price_level":"115663.01","new_quantity":"0.00432"},{"side":"offer","event_time":"2025-10-27T17:39:44.851826Z","price_level":"115667","new_quantity":"2"},{"side":"offer","event_time":"2025-10-27T17:39:44.851826Z","price_level":"115667.98","new_quantity":"0"},{"side":"offer","event_time":"2025-10-27T17:39:44.851826Z","price_level":"115669.97","new_quantity":"0.30395174"},{"side":"offer","event_time":"2025-10-27T17:39:44.851826Z","price_level":"115669.98","new_quantity":"0"},{"side":"offer","event_time":"2025-10-27T17:39:44.851826Z","price_level":"115672","new_quantity":"0.4"},{"side":"offer","event_time":"2025-10-27T17:39:44.851826Z","price_level":"115675.42","new_quantity":"0.38911056"},{"side":"offer","event_time":"2025-10-27T17:39:44.851826Z","price_level":"115675.43","new_quantity":"0.80937646"},{"side":"offer","event_time":"2025-10-27T17:39:44.851826Z","price_level":"115680","new_quantity":"1"},{"side":"offer","event_time":"2025-10-27T17:39:44.851826Z","price_level":"115686.99","new_quantity":"0"},{"side":"offer","event_time":"2025-10-27T17:39:44.851826Z","price_level":"115727.13","new_quantity":"0.37933549"},{"side":"offer","event_time":"2025-10-27T17:39:44.851826Z","price_level":"115727.15","new_quantity":"0"},{"side":"offer","event_time":"2025-10-27T17:39:44.851826Z","price_level":"116376.13","new_quantity":"0"}]}]}
{"channel":"l2_data","client_id":"","timestamp":"2025-10-27T17:39:44.921009678Z","sequence_num":137805,"events":[{"type":"update","product_id":"ETH-USD","updates":[{"side":"bid","event_time":"2025-10-27T17:39:44.882603Z","price_level":"4217.06","new_quantity":"0.64237132"},{"side":"bid","event_time":"2025-10-27T17:39:44.882603Z","price_level":"4213.12","new_quantity":"0"},{"side":"offer","event_time":"2025-10-27T17:39:44.882603Z","price_level":"4218.33","new_quantity":"0.19364897"},{"side":"offer","event_time":"2025-10-27T17:39:44.882603Z","price_level":"4221.51","new_quantity":"1.94391607"},{"side":"offer","event_time":"2025-10-27T17:39:44.882603Z","price_level":"4221.81","new_quantity":"0.14427361"}]}]}
{"channel":"l2_data","client_id":"","timestamp":"2025-10-27T17:39:44.947681069Z","sequence_num":137806,"events":[{"type":"update","product_id":"BTC-USD","updates":[{"side":"bid","event_time":"2025-10-27T17:39:44.904698Z","price_level":"115629.77","new_quantity":"0.02161157"},{"side":"bid","event_time":"2025-10-27T17:39:44.904698Z","price_level":"115628.31","new_quantity":"0"},{"side":"bid","event_time":"2025-10-27T17:39:44.904698Z","price_level":"115608.68","new_quantity":"0.37009342"},{"side":"bid","event_time":"2025-10-27T17:39:44.904698Z","price_level":"115596.91","new_quantity":"0.92461641"},{"side":"bid","event_time":"2025-10-27T17:39:44.904698Z","price_level":"115596.89","new_quantity":"0"},{"side":"bid","event_time":"2025-10-27T17:39:44.904698Z","price_level":"115596.86","new_quantity":"0"},{"side":"bid","event_time":"2025-10-27T17:39:44.904698Z","price_level":"115552.29","new_quantity":"0.81414801"},{"side":"bid","event_time":"2025-10-27T17:39:44.904698Z","price_level":"115552.28","new_quantity":"1.16521533"},{"side":"bid","event_time":"2025-10-27T17:39:44.904698Z","price_level":"115552.27","new_quantity":"0"},{"side":"bid","event_time":"2025-10-27T17:39:44.904698Z","price_level":"115552.26","new_quantity":"0"},{"side":"offer","event_time":"2025-10-27T17:39:44.904698Z","price_level":"115651.82","new_quantity":"0.00170513"},{"side":"offer","event_time":"2025-10-27T17:39:44.904698Z","price_level":"115667","new_quantity":"2"},{"side":"offer","event_time":"2025-10-27T17:39:44.904698Z","price_level":"115669.97","new_quantity":"0"},{"side":"offer","event_time":"2025-10-27T17:39:44.904698Z","price_level":"115669.99","new_quantity":"0.31044597"},{"side":"offer","event_time":"2025-10-27T17:39:44.904698Z","price_level":"115670","new_quantity":"0.4"},{"side":"offer","event_time":"2025-10-27T17:39:44.904698Z","price_level":"115671","new_quantity":"0"},{"side":"offer","event_time":"2025-10-27T17:39:44.904698Z","price_level":"115672","new_quantity":"0"},{"side":"offer","event_time":"2025-10-27T17:39:44.904698Z","price_level":"115675.41","new_quantity":"1.00380145"},{"side":"offer","event_time":"2025-10-27T17:39:44.904698Z","price_level":"115675.43","new_quantity":"0"},{"side":"offer","event_time":"2025-10-27T17:39:44.904698Z","price_level":"115680","new_quantity":"1"},{"side":"offer","event_time":"2025-10-27T17:39:44.904698Z","price_level":"115727.12","new_quantity":"0.56827766"},{"side":"offer","event_time":"2025-10-27T17:39:44.904698Z","price_level":"115727.14","new_quantity":"0"}]}]}
{"channel":"l2_data","client_id":"","timestamp":"2025-10-27T17:39:44.968894605Z","sequence_num":137807,"events":[{"type":"update","product_id":"ETH-USD","updates":[{"side":"bid","event_time":"2025-10-27T17:39:44.936851Z","price_level":"4218.28","new_quantity":"0.64311532"},{"side":"bid","event_time":"2025-10-27T17:39:44.936851Z","price_level":"4218.02","new_quantity":"0"},{"side":"bid","event_time":"2025-10-27T17:39:44.936851Z","price_level":"4217.92","new_quantity":"0"},{"side":"bid","event_time":"2025-10-27T17:39:44.936851Z","price_level":"4217.83","new_quantity":"0.00437089"},{"side":"bid","event_time":"2025-10-27T17:39:44.936851Z","price_level":"4217.82","new_quantity":"1.65696"},{"side":"bid","event_time":"2025-10-27T17:39:44.936851Z","price_level":"4217.6","new_quantity":"31.65784"},{"side":"bid","event_time":"2025-10-27T17:39:44.936851Z","price_level":"4215.05","new_quantity":"8.13001254"},{"side":"bid","event_time":"2025-10-27T17:39:44.936851Z","price_level":"4215.04","new_quantity":"0.18019519"},{"side":"bid","event_time":"2025-10-27T17:39:44.936851Z","price_level":"4215.03","new_quantity":"0"}]}]}
{"channel":"l2_data","client_id":"","timestamp":"2025-10-27T17:39:44.998063039Z","sequence_num":137808,"events":[{"type":"update","product_id":"BTC-USD","updates":[{"side":"bid","event_time":"2025-10-27T17:39:44.952887Z","price_level":"115631.19","new_quantity":"0.02161157"},{"side":"bid","event_time":"2025-10-27T17:39:44.952887Z","price_level":"115629.77","new_quantity":"0"},{"side":"bid","event_time":"2025-10-27T17:39:44.952887Z","price_level":"115596.93","new_quantity":"0.92461636"},{"side":"bid","event_time":"2025-10-27T17:39:44.952887Z","price_level":"115596.92","new_quantity":"0.52639319"},{"side":"bid","event_time":"2025-10-27T17:39:44.952887Z","price_level":"115596.91","new_quantity":"0"},{"side":"bid","event_time":"2025-10-27T17:39:44.952887Z","price_level":"115596.9","new_quantity":"0.00001"},{"side":"bid","event_time":"2025-10-27T17:39:44.952887Z","price_level":"115390.87","new_quantity":"0.07007"},{"side":"bid","event_time":"2025-10-27T17:39:44.952887Z","price_level":"114104.29","new_quantity":"0.07007"},{"side":"bid","event_time":"2025-10-27T17:39:44.952887Z","price_level":"114099.56","new_quantity":"0"},{"side":"offer","event_time":"2025-10-27T17:39:44.952887Z","price_level":"115651.82","new_quantity":"0"},{"side":"offer","event_time":"2025-10-27T17:39:44.952887Z","price_level":"115663","new_quantity":"0"},{"side":"offer","event_time":"2025-10-27T17:39:44.952887Z","price_level":"115663.01","new_quantity":"0"},{"side":"offer","event_time":"2025-10-27T17:39:44.952887Z","price_level":"115667","new_quantity":"2"},{"side":"offer","event_time":"2025-10-27T17:39:44.952887Z","price_level":"115669.99","new_quantity":"0.30128617"},{"side":"offer","event_time":"2025-10-27T17:39:44.952887Z","price_level":"115670","new_quantity":"0.4"},{"side":"offer","event_time":"2025-10-27T17:39:44.952887Z","price_level":"115675.41","new_quantity":"1.00933635"},{"side":"offer","event_time":"2025-10-27T17:39:44.952887Z","price_level":"115680","new_quantity":"1"},{"side":"offer","event_time":"2025-10-27T17:39:44.952887Z","price_level":"115686.99","new_quantity":"0.3883562"},{"side":"offer","event_time":"2025-10-27T17:39:44.952887Z","price_level":"115691.37","new_quantity":"0.5"},{"side":"offer","event_time":"2025-10-27T17:39:44.952887Z","price_level":"115692.19","new_quantity":"0"},{"side":"offer","event_time":"2025-10-27T17:39:44.952887Z","price_level":"115727.11","new_quantity":"0.37933555"},{"side":"offer","event_time":"2025-10-27T17:39:44.952887Z","price_level":"115727.13","new_quantity":"0"},{"side":"offer","event_time":"2025-10-27T17:39:44.952887Z","price_level":"116753.32","new_quantity":"0.07007"}]}]}
{"channel":"l2_data","client_id":"","timestamp":"2025-10-27T17:39:45.01915666Z","sequence_num":137809,"events":[{"type":"update","product_id":"ETH-USD","updates":[{"side":"bid","event_time":"2025-10-27T17:39:44.977411Z","price_level":"4217.83","new_quantity":"0.02507722"},{"side":"bid","event_time":"2025-10-27T17:39:44.977411Z","price_level":"4169.88","new_quantity":"0.76740909"},{"side":"bid","event_time":"2025-10-27T17:39:44.977411Z","price_level":"4149.61","new_quantity":"1.15673543"},{"side":"bid","event_time":"2025-10-27T17:39:44.977411Z","price_level":"4129.34","new_quantity":"1.5498832"}]}]}
{"channel":"l2_data","client_id":"","timestamp":"2025-10-27T17:39:45.047653459Z","sequence_num":137810,"events":[{"type":"update","product_id":"BTC-USD","updates":[{"side":"bid","event_time":"2025-10-27T17:39:44.998822Z","price_level":"115640.01","new_quantity":"0.0017295"},{"side":"bid","event_time":"2025-10-27T17:39:44.998822Z","price_level":"115636.01","new_quantity":"0"},{"side":"bid","event_time":"2025-10-27T17:39:44.998822Z","price_level":"115635.86","new_quantity":"0"},{"side":"bid","event_time":"2025-10-27T17:39:44.998822Z","price_level":"115634.17","new_quantity":"0.00864796"},{"side":"bid","event_time":"2025-10-27T17:39:44.998822Z","price_level":"115618.91","new_quantity":"0.011242"},{"side":"bid","event_time":"2025-10-27T17:39:44.998822Z","price_level":"115615.02","new_quantity":"0.33125119"},{"side":"bid","event_time":"2025-10-27T17:39:44.998822Z","price_level":"115614.01","new_quantity":"0"},{"side":"bid","event_time":"2025-10-27T17:39:44.998822Z","price_level":"115610.53","new_quantity":"0"},{"side":"bid","event_time":"2025-10-27T17:39:44.998822Z","price_level":"115580.08","new_quantity":"0"},{"side":"bid","event_time":"2025-10-27T17:39:44.998822Z","price_level":"115569.52","new_quantity":"0.76393211"},{"side":"bid","event_time":"2025-10-27T17:39:44.998822Z","price_level":"115391.32","new_quantity":"0.07007"},{"side":"bid","event_time":"2025-10-27T17:39:44.998822Z","price_level":"115390.87","new_quantity":"0"},{"side":"bid","event_time":"2025-10-27T17:39:44.998822Z","price_level":"115390.45","new_quantity":"0"},{"side":"bid","event_time":"2025-10-27T17:39:44.998822Z","price_level":"114104.43","new_quantity":"0.07007"},{"side":"bid","event_time":"2025-10-27T17:39:44.998822Z","price_level":"114104.29","new_quantity":"0"},{"side":"offer","event_time":"2025-10-27T17:39:44.998822Z","price_level":"115644.33","new_quantity":"0.02594161"},{"side":"offer","event_time":"2025-10-27T17:39:44.998822Z","price_level":"115646.11","new_quantity":"0"},{"side":"offer","event_time":"2025-10-27T17:39:44.998822Z","price_level":"115667","new_quantity":"0"},{"side":"offer","event_time":"2025-10-27T17:39:44.998822Z","price_level":"115669.99","new_quantity":"0.07164597"},{"side":"offer","event_time":"2025-10-27T17:39:44.998822Z","price_level":"115670","new_quantity":"0"},{"side":"offer","event_time":"2025-10-27T17:39:44.998822Z","price_level":"115675.41","new_quantity":"0.47278039"},{"side":"offer","event_time":"2025-10-27T17:39:44.998822Z","price_level":"115675.44","new_quantity":"0.13835647"},{"side":"offer","event_time":"2025-10-27T17:39:44.998822Z","price_level":"115680","new_quantity":"0"},{"side":"offer","event_time":"2025-10-27T17:39:44.998822Z","price_level":"115686.99","new_quantity":"0.01892563"},{"side":"offer","event_time":"2025-10-27T17:39:44.998822Z","price_level":"115727.1","new_quantity":"0.56827776"},{"side":"offer","event_time":"2025-10-27T17:39:44.998822Z","price_level":"115727.12","new_quantity":"0"},{"side":"offer","event_time":"2025-10-27T17:39:44.998822Z","price_level":"116963.02","new_quantity":"0"}]}]}
{"channel":"l2_data","client_id":"","timestamp":"2025-10-27T17:39:45.068861178Z","sequence_num":137811,"events":[{"type":"update","product_id":"ETH-USD","updates":[{"side":"offer","event_time":"2025-10-27T17:39:45.038506Z","price_level":"4218.33","new_quantity":"0.27034807"},{"side":"offer","event_time":"2025-10-27T17:39:45.038506Z","price_level":"4218.69","new_quantity":"1.34512325"}]}]}
{"channel":"l2_data","client_id":"","timestamp":"2025-10-27T17:39:45.097065717Z","sequence_num":137813,"events":[{"type":"update","product_id":"BTC-USD","updates":[{"side":"bid","event_time":"2025-10-27T17:39:45.052302Z","price_level":"115596.95","new_quantity":"0.9246163"},{"side":"bid","event_time":"2025-10-27T17:39:45.052302Z","price_level":"115596.94","new_quantity":"0.5263931"},{"side":"bid","event_time":"2025-10-27T17:39:45.052302Z","price_level":"115596.93","new_quantity":"0"},{"side":"bid","event_time":"2025-10-27T17:39:45.052302Z","price_level":"115596.92","new_quantity":"0"},{"side":"bid","event_time":"2025-10-27T17:39:45.052302Z","price_level":"115574.71","new_quantity":"0.9038"},{"side":"bid","event_time":"2025-10-27T17:39:45.052302Z","price_level":"115574.7","new_quantity":"1.5"},{"side":"bid","event_time":"2025-10-27T17:39:45.052302Z","price_level":"115569.51","new_quantity":"0"},{"side":"bid","event_time":"2025-10-27T17:39:45.052302Z","price_level":"115569.5","new_quantity":"0"},{"side":"bid","event_time":"2025-10-27T17:39:45.052302Z","price_level":"115552.31","new_quantity":"0.81414789"},{"side":"bid","event_time":"2025-10-27T17:39:45.052302Z","price_level":"115552.3","new_quantity":"1.16521513"},{"side":"bid","event_time":"2025-10-27T17:39:45.052302Z","price_level":"115552.29","new_quantity":"0"},{"side":"bid","event_time":"2025-10-27T17:39:45.052302Z","price_level":"115552.28","new_quantity":"0"},{"side":"bid","event_time":"2025-10-27T17:39:45.052302Z","price_level":"114361.76","new_quantity":"0.02798138"},{"side":"bid","event_time":"2025-10-27T17:39:45.052302Z","price_level":"113804.88","new_quantity":"0.04217745"},{"side":"bid","event_time":"2025-10-27T17:39:45.052302Z","price_level":"113247.99","new_quantity":"0.05651314"},{"side":"offer","event_time":"2025-10-27T17:39:45.052302Z","price_level":"115651.82","new_quantity":"0"},{"side":"offer","event_time":"2025-10-27T17:39:45.052302Z","price_level":"115667","new_quantity":"2"},{"side":"offer","event_time":"2025-10-27T17:39:45.052302Z","price_level":"115669.99","new_quantity":"0.07164597"},{"side":"offer","event_time":"2025-10-27T17:39:45.052302Z","price_level":"115670","new_quantity":"0.4"},{"side":"offer","event_time":"2025-10-27T17:39:45.052302Z","price_level":"115675.4","new_quantity":"0.03458704"},{"side":"offer","event_time":"2025-10-27T17:39:45.052302Z","price_level":"115675.41","new_quantity":"0.47278039"},{"side":"offer","event_time":"2025-10-27T17:39:45.052302Z","price_level":"115680","new_quantity":"1"},{"side":"offer","event_time":"2025-10-27T17:39:45.052302Z","price_level":"115686.99","new_quantity":"0.3883562"},{"side":"offer","event_time":"2025-10-27T17:39:45.052302Z","price_level":"115691.37","new_quantity":"0"},{"side":"offer","event_time":"2025-10-27T17:39:45.052302Z","price_level":"115691.97","new_quantity":"0.5"},{"side":"offer","event_time":"2025-10-27T17:39:45.052302Z","price_level":"115718.4","new_quantity":"0"},{"side":"offer","event_time":"2025-10-27T17:39:45.052302Z","price_level":"115718.8","new_quantity":"1"}]}]}
{"channel":"l2_data","client_id":"","timestamp":"2025-10-27T17:39:45.121785573Z","sequence_num":137814,"events":[{"type":"update","product_id":"ETH-USD","updates":[{"side":"bid","event_time":"2025-10-27T17:39:45.083701Z","price_level":"4218.01","new_quantity":"0.38240285"},{"side":"bid","event_time":"2025-10-27T17:39:45.083701Z","price_level":"4218","new_quantity":"0.001"},{"side":"bid","event_time":"2025-10-27T17:39:45.083701Z","price_level":"4217.95","new_quantity":"0"},{"side":"bid","event_time":"2025-10-27T17:39:45.083701Z","price_level":"4217.91","new_quantity":"0.00237085"},{"side":"bid","event_time":"2025-10-27T17:39:45.083701Z","price_level":"4217.87","new_quantity":"0.11854322"},{"side":"bid","event_time":"2025-10-27T17:39:45.083701Z","price_level":"4217.83","new_quantity":"0.02270633"},{"side":"bid","event_time":"2025-10-27T17:39:45.083701Z","price_level":"4217.43","new_quantity":"10.59277777"},{"side":"offer","event_time":"2025-10-27T17:39:45.083701Z","price_level":"4218.33","new_quantity":"0.38887838"},{"side":"offer","event_time":"2025-10-27T17:39:45.083701Z","price_level":"4218.46","new_quantity":"0.07111599"},{"side":"offer","event_time":"2025-10-27T17:39:45.083701Z","price_level":"4218.47","new_quantity":"0.59263287"},{"side":"offer","event_time":"2025-10-27T17:39:45.083701Z","price_level":"4218.51","new_quantity":"0"},{"side":"offer","event_time":"2025-10-27T17:39:45.083701Z","price_level":"4218.92","new_quantity":"0"},{"side":"offer","event_time":"2025-10-27T17:39:45.083701Z","price_level":"4219.1","new_quantity":"0"},{"side":"offer","event_time":"2025-10-27T17:39:45.083701Z","price_level":"4219.24","new_quantity":"0.01498603"},{"side":"offer","event_time":"2025-10-27T17:39:45.083701Z","price_level":"4223.73","new_quantity":"0.1536"}]}]}
{"channel":"l2_data","client_id":"","timestamp":"2025-10-27T17:39:45.146910696Z","sequence_num":137816,"events":[{"type":"update","product_id":"BTC-USD","updates":[{"side":"bid","event_time":"2025-10-27T17:39:45.107828Z","price_level":"115615.02","new_quantity":"0"},{"side":"bid","event_time":"2025-10-27T17:39:45.107828Z","price_level":"115612.97","new_quantity":"0.33125706"},{"side":"bid","event_time":"2025-10-27T17:39:45.107828Z","price_level":"115574.72","new_quantity":"0.76389774"},{"side":"bid","event_time":"2025-10-27T17:39:45.107828Z","price_level":"115574.71","new_quantity":"0"},{"side":"bid","event_time":"2025-10-27T17:39:45.107828Z","price_level":"115569.52","new_quantity":"0"},{"side":"bid","event_time":"2025-10-27T17:39:45.107828Z","price_level":"115176.72","new_quantity":"0.07007"},{"side":"bid","event_time":"2025-10-27T17:39:45.107828Z","price_level":"115176.2","new_quantity":"0"},{"side":"bid","event_time":"2025-10-27T17:39:45.107828Z","price_level":"115173.04","new_quantity":"0"},{"side":"bid","event_time":"2025-10-27T17:39:45.107828Z","price_level":"114961.99","new_quantity":"0.07007"},{"side":"bid","event_time":"2025-10-27T17:39:45.107828Z","price_level":"114961.37","new_quantity":"0.07007"},{"side":"bid","event_time":"2025-10-27T17:39:45.107828Z","price_level":"114957.82","new_quantity":"0"},{"side":"bid","event_time":"2025-10-27T17:39:45.107828Z","price_level":"114104.43","new_quantity":"0"},{"side":"offer","event_time":"2025-10-27T17:39:45.107828Z","price_level":"115651.82","new_quantity":"0.00134308"},{"side":"offer","event_time":"2025-10-27T17:39:45.107828Z","price_level":"115667","new_quantity":"2"},{"side":"offer","event_time":"2025-10-27T17:39:45.107828Z","price_level":"115669.99","new_quantity":"0.30128617"},{"side":"offer","event_time":"2025-10-27T17:39:45.107828Z","price_level":"115670","new_quantity":"0.4"},{"side":"offer","event_time":"2025-10-27T17:39:45.107828Z","price_level":"115675.41","new_quantity":"0.47278039"},{"side":"offer","event_time":"2025-10-27T17:39:45.107828Z","price_level":"115680","new_quantity":"1"},{"side":"offer","event_time":"2025-10-27T17:39:45.107828Z","price_level":"115686.99","new_quantity":"0"},{"side":"offer","event_time":"2025-10-27T17:39:45.107828Z","price_level":"115719.94","new_quantity":"0.37935906"},{"side":"offer","event_time":"2025-10-27T17:39:45.107828Z","price_level":"115727.11","new_quantity":"0"},{"side":"offer","event_time":"2025-10-27T17:39:45.107828Z","price_level":"116537.81","new_quantity":"0.07007"},{"side":"offer","event_time":"2025-10-27T17:39:45.107828Z","price_level":"116538.16","new_quantity":"0"},{"side":"offer","event_time":"2025-10-27T17:39:45.107828Z","price_level":"116538.23","new_quantity":"0"},{"side":"offer","event_time":"2025-10-27T17:39:45.107828Z","price_level":"116752.68","new_quantity":"0.07007"},{"side":"offer","event_time":"2025-10-27T17:39:45.107828Z","price_level":"116753.08","new_quantity":"0"},{"side":"offer","event_time":"2025-10-27T17:39:45.107828Z","price_level":"116753.32","new_quantity":"0"}]}]}
{"channel":"l2_data","client_id":"","timestamp":"2025-10-27T17:39:45.16882817Z","sequence_num":137817,"events":[{"type":"update","product_id":"ETH-USD","updates":[{"side":"bid","event_time":"2025-10-27T17:39:45.131864Z","price_level":"4218.1","new_quantity":"0"}]}]}
{"channel":"l2_data","client_id":"","timestamp":"2025-10-27T17:39:45.197454329Z","sequence_num":137818,"events":[{"type":"update","product_id":"BTC-USD","updates":[{"side":"bid","event_time":"2025-10-27T17:39:45.133898Z","price_level":"115596.96","new_quantity":"0.52639301"},{"side":"bid","event_time":"2025-10-27T17:39:45.133898Z","price_level":"115596.95","new_quantity":"0"},{"side":"bid","event_time":"2025-10-27T17:39:45.133898Z","price_level":"115596.94","new_quantity":"0"},{"side":"bid","event_time":"2025-10-27T17:39:45.133898Z","price_level":"115552.32","new_quantity":"1.16521493"},{"side":"bid","event_time":"2025-10-27T17:39:45.133898Z","price_level":"115552.31","new_quantity":"0"},{"side":"bid","event_time":"2025-10-27T17:39:45.133898Z","price_level":"115552.3","new_quantity":"0"},{"side":"bid","event_time":"2025-10-27T17:39:45.133898Z","price_level":"115499.01","new_quantity":"0.50417844"},{"side":"bid","event_time":"2025-10-27T17:39:45.133898Z","price_level":"115391.76","new_quantity":"0.07007"},{"side":"bid","event_time":"2025-10-27T17:39:45.133898Z","price_level":"115176.75","new_quantity":"0.07007"},{"side":"bid","event_time":"2025-10-27T17:39:45.133898Z","price_level":"115176.72","new_quantity":"0"},{"side":"bid","event_time":"2025-10-27T17:39:45.133898Z","price_level":"114961.37","new_quantity":"0"},{"side":"bid","event_time":"2025-10-27T17:39:45.133898Z","price_level":"114746.88","new_quantity":"0.07007"},{"side":"bid","event_time":"2025-10-27T17:39:45.133898Z","price_level":"114742.85","new_quantity":"0"},{"side":"offer","event_time":"2025-10-27T17:39:45.133898Z","price_level":"115647.51","new_quantity":"0.000076"},{"side":"offer","event_time":"2025-10-27T17:39:45.133898Z","price_level":"115647.52","new_quantity":"0.02"},{"side":"offer","event_time":"2025-10-27T17:39:45.133898Z","price_level":"115651.82","new_quantity":"0.02"},{"side":"offer","event_time":"2025-10-27T17:39:45.133898Z","price_level":"115667","new_quantity":"0"},{"side":"offer","event_time":"2025-10-27T17:39:45.133898Z","price_level":"115669.99","new_quantity":"0.07164597"},{"side":"offer","event_time":"2025-10-27T17:39:45.133898Z","price_level":"115670","new_quantity":"0"},{"side":"offer","event_time":"2025-10-27T17:39:45.133898Z","price_level":"115680","new_quantity":"0"},{"side":"offer","event_time":"2025-10-27T17:39:45.133898Z","price_level":"116968.06","new_quantity":"0.07007"}]}]}
{"channel":"l2_data","client_id":"","timestamp":"2025-10-27T17:39:45.218627874Z","sequence_num":137819,"events":[{"type":"update","product_id":"ETH-USD","updates":[{"side":"offer","event_time":"2025-10-27T17:39:45.17109Z","price_level":"4219.1","new_quantity":"0.01336599"},{"side":"offer","event_time":"2025-10-27T17:39:45.17109Z","price_level":"4219.24","new_quantity":"0"},{"side":"offer","event_time":"2025-10-27T17:39:45.17109Z","price_level":"4244.91","new_quantity":"0"}]}]}
{"channel":"l2_data","client_id":"","timestamp":"2025-10-27T17:39:45.247151586Z","sequence_num":137820,"events":[{"type":"update","product_id":"BTC-USD","updates":[{"side":"bid","event_time":"2025-10-27T17:39:45.193011Z","price_level":"115618","new_quantity":"0.4"},{"side":"bid","event_time":"2025-10-27T17:39:45.193011Z","price_level":"115617","new_quantity":"0"},{"side":"bid","event_time":"2025-10-27T17:39:45.193011Z","price_level":"115615.01","new_quantity":"0.61404792"},{"side":"bid","event_time":"2025-10-27T17:39:45.193011Z","price_level":"115614","new_quantity":"0"},{"side":"bid","event_time":"2025-10-27T17:39:45.193011Z","price_level":"115391.32","new_quantity":"0"},{"side":"bid","event_time":"2025-10-27T17:39:45.193011Z","price_level":"115176.97","new_quantity":"0.07007"},{"side":"bid","event_time":"2025-10-27T17:39:45.193011Z","price_level":"115176.75","new_quantity":"0"},{"side":"bid","event_time":"2025-10-27T17:39:45.193011Z","price_level":"114747.25","new_quantity":"0.07007"},{"side":"bid","event_time":"2025-10-27T17:39:45.193011Z","price_level":"114746.88","new_quantity":"0"},{"side":"offer","event_time":"2025-10-27T17:39:45.193011Z","price_level":"115647.51","new_quantity":"0"},{"side":"offer","event_time":"2025-10-27T17:39:45.193011Z","price_level":"115647.52","new_quantity":"0.000076"},{"side":"offer","event_time":"2025-10-27T17:39:45.193011Z","price_level":"115651.82","new_quantity":"0"},{"side":"offer","event_time":"2025-10-27T17:39:45.193011Z","price_level":"115669.99","new_quantity":"0.07164597"},{"side":"offer","event_time":"2025-10-27T17:39:45.193011Z","price_level":"115670","new_quantity":"0"},{"side":"offer","event_time":"2025-10-27T17:39:45.193011Z","price_level":"115675.41","new_quantity":"0.47278039"},{"side":"offer","event_time":"2025-10-27T17:39:45.193011Z","price_level":"115680","new_quantity":"0"},{"side":"offer","event_time":"2025-10-27T17:39:45.193011Z","price_level":"115691.97","new_quantity":"0"},{"side":"offer","event_time":"2025-10-27T17:39:45.193011Z","price_level":"115692.79","new_quantity":"0.5"}]}]}
{"channel":"l2_data","client_id":"","timestamp":"2025-10-27T17:39:45.271389933Z","sequence_num":137821,"events":[{"type":"update","product_id":"ETH-USD","updates":[{"side":"bid","event_time":"2025-10-27T17:39:45.219371Z","price_level":"4218.01","new_quantity":"0"},{"side":"bid","event_time":"2025-10-27T17:39:45.219371Z","price_level":"4217.92","new_quantity":"0.00237084"},{"side":"bid","event_time":"2025-10-27T17:39:45.219371Z","price_level":"4217.91","new_quantity":"0.3806133"},{"side":"bid","event_time":"2025-10-27T17:39:45.219371Z","price_level":"4217.44","new_quantity":"0"},{"side":"bid","event_time":"2025-10-27T17:39:45.219371Z","price_level":"4217.28","new_quantity":"5.92221108"},{"side":"offer","event_time":"2025-10-27T17:39:45.219371Z","price_level":"4218.33","new_quantity":"0.55763838"},{"side":"offer","event_time":"2025-10-27T17:39:45.219371Z","price_level":"4218.39","new_quantity":"0.07111717"},{"side":"offer","event_time":"2025-10-27T17:39:45.219371Z","price_level":"4218.49","new_quantity":"1.23095991"},{"side":"offer","event_time":"2025-10-27T17:39:45.219371Z","price_level":"4218.53","new_quantity":"0"},{"side":"offer","event_time":"2025-10-27T17:39:45.219371Z","price_level":"4220.49","new_quantity":"14.04948423"},{"side":"offer","event_time":"2025-10-27T17:39:45.219371Z","price_level":"4220.67","new_quantity":"0.00886424"},{"side":"offer","event_time":"2025-10-27T17:39:45.219371Z","price_level":"4223.73","new_quantity":"0"},{"side":"offer","event_time":"2025-10-27T17:39:45.219371Z","price_level":"4244.82","new_quantity":"0.1536"}]}]}
{"channel":"l2_data","client_id":"","timestamp":"2025-10-27T17:39:45.298405613Z","sequence_num":137822,"events":[{"type":"update","product_id":"BTC-USD","updates":[{"side":"bid","event_time":"2025-10-27T17:39:45.249653Z","price_level":"115627.49","new_quantity":"0.00070263"},{"side":"bid","event_time":"2025-10-27T17:39:45.249653Z","price_level":"115616","new_quantity":"0.4"},{"side":"bid","event_time":"2025-10-27T17:39:45.249653Z","price_level":"115615.01","new_quantity":"0.37524792"},{"side":"bid","event_time":"2025-10-27T17:39:45.249653Z","price_level":"115615","new_quantity":"0"},{"side":"offer","event_time":"2025-10-27T17:39:45.249653Z","price_level":"115667.98","new_quantity":"0.00296543"},{"side":"offer","event_time":"2025-10-27T17:39:45.249653Z","price_level":"115669.99","new_quantity":"0.07164597"},{"side":"offer","event_time":"2025-10-27T17:39:45.249653Z","price_level":"115692.78","new_quantity":"0.16812511"},{"side":"offer","event_time":"2025-10-27T17:39:45.249653Z","price_level":"115692.79","new_quantity":"0"},{"side":"offer","event_time":"2025-10-27T17:39:45.249653Z","price_level":"115693.68","new_quantity":"0"},{"side":"offer","event_time":"2025-10-27T17:39:45.249653Z","price_level":"115693.92","new_quantity":"0.5"}]}]}
{"channel":"l2_data","client_id":"","timestamp":"2025-10-27T17:39:45.321739337Z","sequence_num":137823,"events":[{"type":"update","product_id":"ETH-USD","updates":[{"side":"bid","event_time":"2025-10-27T17:39:45.287384Z","price_level":"4170.16","new_quantity":"0.19183926"},{"side":"bid","event_time":"2025-10-27T17:39:45.287384Z","price_level":"4150.03","new_quantity":"0.28915429"},{"side":"bid","event_time":"2025-10-27T17:39:45.287384Z","price_level":"4129.91","new_quantity":"0.38741773"},{"side":"offer","event_time":"2025-10-27T17:39:45.287384Z","price_level":"4218.33","new_quantity":"0.38887838"},{"side":"offer","event_time":"2025-10-27T17:39:45.287384Z","price_level":"4220.37","new_quantity":"4.22506911"},{"side":"offer","event_time":"2025-10-27T17:39:45.287384Z","price_level":"4221.85","new_quantity":"0.30652551"}]}]}
{"channel":"l2_data","client_id":"","timestamp":"2025-10-27T17:39:45.346512222Z","sequence_num":137824,"events":[{"type":"update","product_id":"BTC-USD","updates":[{"side":"bid","event_time":"2025-10-27T17:39:45.300961Z","price_level":"115615.01","new_quantity":"0.37524792"},{"side":"bid","event_time":"2025-10-27T17:39:45.300961Z","price_level":"115614","new_quantity":"0"},{"side":"bid","event_time":"2025-10-27T17:39:45.300961Z","price_level":"115392.3","new_quantity":"0.07007"},{"side":"bid","event_time":"2025-10-27T17:39:45.300961Z","price_level":"115391.76","new_quantity":"0"},{"side":"bid","event_time":"2025-10-27T17:39:45.300961Z","price_level":"115177.25","new_quantity":"0.07007"},{"side":"bid","event_time":"2025-10-27T17:39:45.300961Z","price_level":"115176.97","new_quantity":"0"},{"side":"bid","event_time":"2025-10-27T17:39:45.300961Z","price_level":"114962.39","new_quantity":"0.07007"},{"side":"bid","event_time":"2025-10-27T17:39:45.300961Z","price_level":"114961.99","new_quantity":"0"},{"side":"bid","event_time":"2025-10-27T17:39:45.300961Z","price_level":"114747.77","new_quantity":"0.07007"},{"side":"bid","event_time":"2025-10-27T17:39:45.300961Z","price_level":"114747.25","new_quantity":"0"},{"side":"offer","event_time":"2025-10-27T17:39:45.300961Z","price_level":"115669.99","new_quantity":"0.07164597"}]}]}
{"channel":"l2_data","client_id":"","timestamp":"2025-10-27T17:39:45.370663473Z","sequence_num":137825,"events":[{"type":"update","product_id":"ETH-USD","updates":[{"side":"bid","event_time":"2025-10-27T17:39:45.335983Z","price_level":"4217.92","new_quantity":"0.02307717"},{"side":"bid","event_time":"2025-10-27T17:39:45.335983Z","price_level":"4217.83","new_quantity":"0.002"},{"side":"bid","event_time":"2025-10-27T17:39:45.335983Z","price_level":"4216","new_quantity":"50.001"},{"side":"offer","event_time":"2025-10-27T17:39:45.335983Z","price_level":"4219.8","new_quantity":"0"},{"side":"offer","event_time":"2025-10-27T17:39:45.335983Z","price_level":"4220.37","new_quantity":"0"}]}]}
{"channel":"l2_data","client_id":"","timestamp":"2025-10-27T17:39:44.64710888Z","sequence_num":137791,"events":[{"type":"update","product_id":"BTC-USD","updates":[{"side":"bid","event_time":"2025-10-27T17:39:44.594648Z","price_level":"115617","new_quantity":"0.4"},{"side":"bid","event_time":"2025-10-27T17:39:44.594648Z","price_level":"115616.01","new_quantity":"0.41629343"},{"side":"bid","event_time":"2025-10-27T17:39:44.594648Z","price_level":"115611.01","new_quantity":"1.16045649"},{"side":"bid","event_time":"2025-10-27T17:39:44.594648Z","price_level":"115610","new_quantity":"1"},{"side":"bid","event_time":"2025-10-27T17:39:44.594648Z","price_level":"115552.23","new_quantity":"0.81414837"},{"side":"bid","event_time":"2025-10-27T17:39:44.594648Z","price_level":"115552.22","new_quantity":"1.16521594"},{"side":"bid","event_time":"2025-10-27T17:39:44.594648Z","price_level":"115552.21","new_quantity":"0"},{"side":"bid","event_time":"2025-10-27T17:39:44.594648Z","price_level":"115552.2","new_quantity":"0"},{"side":"offer","event_time":"2025-10-27T17:39:44.594648Z","price_level":"115640.92","new_quantity":"0.02545737"},{"side":"offer","event_time":"2025-10-27T17:39:44.594648Z","price_level":"115661.55","new_quantity":"0.3173917"},{"side":"offer","event_time":"2025-10-27T17:39:44.594648Z","price_level":"115661.56","new_quantity":"0.38914439"},{"side":"offer","event_time":"2025-10-27T17:39:44.594648Z","price_level":"115661.57","new_quantity":"0"},{"side":"offer","event_time":"2025-10-27T17:39:44.594648Z","price_level":"115666.99","new_quantity":"0"},{"side":"offer","event_time":"2025-10-27T17:39:44.594648Z","price_level":"115667","new_quantity":"2"},{"side":"offer","event_time":"2025-10-27T17:39:44.594648Z","price_level":"115669.99","new_quantity":"0.33109612"},{"side":"offer","event_time":"2025-10-27T17:39:44.594648Z","price_level":"115670","new_quantity":"0.4"},{"side":"offer","event_time":"2025-10-27T17:39:44.594648Z","price_level":"115671","new_quantity":"0"},{"side":"offer","event_time":"2025-10-27T17:39:44.594648Z","price_level":"115673.99","new_quantity":"0.13835664"},{"side":"offer","event_time":"2025-10-27T17:39:44.594648Z","price_level":"115675.57","new_quantity":"0.38869404"},{"side":"offer","event_time":"2025-10-27T17:39:44.594648Z","price_level":"115676","new_quantity":"0.4"},{"side":"offer","event_time":"2025-10-27T17:39:44.594648Z","price_level":"115677.9","new_quantity":"0"},{"side":"offer","event_time":"2025-10-27T17:39:44.594648Z","price_level":"115680","new_quantity":"1"},{"side":"offer","event_time":"2025-10-27T17:39:44.594648Z","price_level":"115693.68","new_quantity":"0.1681238"},{"side":"offer","event_time":"2025-10-27T17:39:44.594648Z","price_level":"115693.69","new_quantity":"0.5"},{"side":"offer","event_time":"2025-10-27T17:39:44.594648Z","price_level":"115693.99","new_quantity":"0"},{"side":"offer","event_time":"2025-10-27T17:39:44.594648Z","price_level":"116320.01","new_quantity":"0"}]}]}
{"channel":"l2_data","client_id":"","timestamp":"2025-10-27T17:39:44.66885395Z","sequence_num":137792,"events":[{"type":"update","product_id":"ETH-USD","updates":[{"side":"offer","event_time":"2025-10-27T17:39:44.596405Z","price_level":"4218.71","new_quantity":"0.06365526"}]}]}
{"channel":"l2_data","client_id":"","timestamp":"2025-10-27T17:39:44.697731698Z","sequence_num":137794,"events":[{"type":"update","product_id":"BTC-USD","updates":[{"side":"bid","event_time":"2025-10-27T17:39:44.651464Z","price_level":"115632.21","new_quantity":"0.0086481"},{"side":"bid","event_time":"2025-10-27T17:39:44.651464Z","price_level":"115630.86","new_quantity":"0"},{"side":"bid","event_time":"2025-10-27T17:39:44.651464Z","price_level":"115627.31","new_quantity":"0.00065589"},{"side":"bid","event_time":"2025-10-27T17:39:44.651464Z","price_level":"115624","new_quantity":"0"},{"side":"bid","event_time":"2025-10-27T17:39:44.651464Z","price_level":"115618","new_quantity":"0.4"},{"side":"bid","event_time":"2025-10-27T17:39:44.651464Z","price_level":"115617","new_quantity":"0"},{"side":"bid","event_time":"2025-10-27T17:39:44.651464Z","price_level":"115616.01","new_quantity":"0"},{"side":"bid","event_time":"2025-10-27T17:39:44.651464Z","price_level":"115612.97","new_quantity":"0.36492211"},{"side":"bid","event_time":"2025-10-27T17:39:44.651464Z","price_level":"115612.01","new_quantity":"0.33125981"},{"side":"bid","event_time":"2025-10-27T17:39:44.651464Z","price_level":"115611.02","new_quantity":"0"},{"side":"bid","event_time":"2025-10-27T17:39:44.651464Z","price_level":"115571.12","new_quantity":"1.3515612"},{"side":"bid","event_time":"2025-10-27T17:39:44.651464Z","price_level":"115571.11","new_quantity":"0.7639216"},{"side":"bid","event_time":"2025-10-27T17:39:44.651464Z","price_level":"115571.1","new_quantity":"1.5"},{"side":"bid","event_time":"2025-10-27T17:39:44.651464Z","price_level":"115570.87","new_quantity":"0"},{"side":"bid","event_time":"2025-10-27T17:39:44.651464Z","price_level":"115570.86","new_quantity":"0"},{"side":"bid","event_time":"2025-10-27T17:39:44.651464Z","price_level":"115569","new_quantity":"0"},{"side":"bid","event_time":"2025-10-27T17:39:44.651464Z","price_level":"115567.27","new_quantity":"0.16252298"},{"side":"bid","event_time":"2025-10-27T17:39:44.651464Z","price_level":"115173.04","new_quantity":"0.07007"},{"side":"offer","event_time":"2025-10-27T17:39:44.651464Z","price_level":"115640.92","new_quantity":"0.00250384"},{"side":"offer","event_time":"2025-10-27T17:39:44.651464Z","price_level":"115641.96","new_quantity":"0"},{"side":"offer","event_time":"2025-10-27T17:39:44.651464Z","price_level":"115667","new_quantity":"2"},{"side":"offer","event_time":"2025-10-27T17:39:44.651464Z","price_level":"115669.99","new_quantity":"0.39133505"},{"side":"offer","event_time":"2025-10-27T17:39:44.651464Z","price_level":"115670","new_quantity":"0.4"},{"side":"offer","event_time":"2025-10-27T17:39:44.651464Z","price_level":"115680","new_quantity":"1"},{"side":"offer","event_time":"2025-10-27T17:39:44.651464Z","price_level":"115693.44","new_quantity":"0.5"},{"side":"offer","event_time":"2025-10-27T17:39:44.651464Z","price_level":"115693.69","new_quantity":"0"},{"side":"offer","event_time":"2025-10-27T17:39:44.651464Z","price_level":"115718.09","new_quantity":"0"},{"side":"offer","event_time":"2025-10-27T17:39:44.651464Z","price_level":"115727.16","new_quantity":"0.08681404"},{"side":"offer","event_time":"2025-10-27T17:39:44.651464Z","price_level":"115735.09","new_quantity":"0.56823853"},{"side":"offer","event_time":"2025-10-27T17:39:44.651464Z","price_level":"115735.1","new_quantity":"0.37930936"},{"side":"offer","event_time":"2025-10-27T17:39:44.651464Z","price_level":"115735.11","new_quantity":"0"}]}]}
{"channel":"l2_data","client_id":"","timestamp":"2025-10-27T17:39:44.720691235Z","sequence_num":137795,"events":[{"type":"update","product_id":"ETH-USD","updates":[{"side":"bid","event_time":"2025-10-27T17:39:44.68042Z","price_level":"4217.94","new_quantity":"0.12054126"},{"side":"bid","event_time":"2025-10-27T17:39:44.68042Z","price_level":"4217.82","new_quantity":"3.3148"},{"side":"bid","event_time":"2025-10-27T17:39:44.68042Z","price_level":"4217.72","new_quantity":"0.59273726"},{"side":"bid","event_time":"2025-10-27T17:39:44.68042Z","price_level":"4217.32","new_quantity":"0"},{"side":"bid","event_time":"2025-10-27T17:39:44.68042Z","price_level":"4216","new_quantity":"54.20745482"},{"side":"bid","event_time":"2025-10-27T17:39:44.68042Z","price_level":"4214.52","new_quantity":"8.97955653"},{"side":"offer","event_time":"2025-10-27T17:39:44.68042Z","price_level":"4218.33","new_quantity":"0.02413099"},{"side":"offer","event_time":"2025-10-27T17:39:44.68042Z","price_level":"4218.39","new_quantity":"0"},{"side":"offer","event_time":"2025-10-27T17:39:44.68042Z","price_level":"4218.4","new_quantity":"0"},{"side":"offer","event_time":"2025-10-27T17:39:44.68042Z","price_level":"4218.43","new_quantity":"0.0711165"},{"side":"offer","event_time":"2025-10-27T17:39:44.68042Z","price_level":"4218.44","new_quantity":"0.11852745"},{"side":"offer","event_time":"2025-10-27T17:39:44.68042Z","price_level":"4220.37","new_quantity":"8.61435711"},{"side":"offer","event_time":"2025-10-27T17:39:44.68042Z","price_level":"4221.53","new_quantity":"0"},{"side":"offer","event_time":"2025-10-27T17:39:44.68042Z","price_level":"4221.82","new_quantity":"13.39868538"},{"side":"offer","event_time":"2025-10-27T17:39:44.68042Z","price_level":"4221.85","new_quantity":"9.00326156"}]}]}
0-27T17:39:45.354823Z","price_level":"115693.92","new_quantity":"0"},{"side":"offer","event_time":"2025-10-27T17:39:45.354823Z","price_level":"115694","new_quantity":"0"},{"side":"offer","event_time":"2025-10-27T17:39:45.354823Z","price_level":"115696.12","new_quantity":"0.5"},{"side":"offer","event_time":"2025-10-27T17:39:45.354823Z","price_level":"115697.34","new_quantity":"0.16811848"}]}]}
{"channel":"l2_data","client_id":"","timestamp":"2025-10-27T17:39:45.420871489Z","sequence_num":137827,"events":[{"type":"update","product_id":"ETH-USD","updates":[{"side":"bid","event_time":"2025-10-27T17:39:45.380426Z","price_level":"4217.42","new_quantity":"5.92201449"},{"side":"bid","event_time":"2025-10-27T17:39:45.380426Z","price_level":"4217.28","new_quantity":"0"},{"side":"bid","event_time":"2025-10-27T17:39:45.380426Z","price_level":"4214.52","new_quantity":"0"},{"side":"offer","event_time":"2025-10-27T17:39:45.380426Z","price_level":"4220","new_quantity":"42.20517286"},{"side":"offer","event_time":"2025-10-27T17:39:45.380426Z","price_level":"4220.49","new_quantity":"5.92349217"},{"side":"offer","event_time":"2025-10-27T17:39:45.380426Z","price_level":"4220.67","new_quantity":"8.13450975"}]}]}
{"channel":"l2_data","client_id":"","timestamp":"2025-10-27T17:39:45.446894934Z","sequence_num":137828,"events":[{"type":"update","product_id":"BTC-USD","updates":[{"side":"bid","event_time":"2025-10-27T17:39:45.400363Z","price_level":"115632.3","new_quantity":"0.02161157"},{"side":"bid","event_time":"2025-10-27T17:39:45.400363Z","price_level":"115631.19","new_quantity":"0"},{"side":"bid","event_time":"2025-10-27T17:39:45.400363Z","price_level":"115629.01","new_quantity":"0.00066259"},{"side":"bid","event_time":"2025-10-27T17:39:45.400363Z","price_level":"115627.49","new_quantity":"0"},{"side":"bid","event_time":"2025-10-27T17:39:45.400363Z","price_level":"115625.95","new_quantity":"0.00432"},{"side":"bid","event_time":"2025-10-27T17:39:45.400363Z","price_level":"115620","new_quantity":"1"},{"side":"bid","event_time":"2025-10-27T17:39:45.400363Z","price_level":"115619.96","new_quantity":"0"},{"side":"bid","event_time":"2025-10-27T17:39:45.400363Z","price_level":"115618","new_quantity":"2.4"},{"side":"bid","event_time":"2025-10-27T17:39:45.400363Z","price_level":"115586.05","new_quantity":"0.06483472"},{"side":"bid","event_time":"2025-10-27T17:39:45.400363Z","price_level":"115579.83","new_quantity":"0"},{"side":"bid","event_time":"2025-10-27T17:39:45.400363Z","price_level":"101185.8","new_quantity":"0.0049568"},{"side":"offer","event_time":"2025-10-27T17:39:45.400363Z","price_level":"115663","new_quantity":"0.00432"},{"side":"offer","event_time":"2025-10-27T17:39:45.400363Z","price_level":"115663.01","new_quantity":"0.00432"},{"side":"offer","event_time":"2025-10-27T17:39:45.400363Z","price_level":"115667.98","new_quantity":"0"},{"side":"offer","event_time":"2025-10-27T17:39:45.400363Z","price_level":"115695.12","new_quantity":"0.5"},{"side":"offer","event_time":"2025-10-27T17:39:45.400363Z","price_level":"115696.12","new_quantity":"0"}]}]}
{"channel":"l2_data","client_id":"","timestamp":"2025-10-27T17:39:45.470602453Z","sequence_num":137829,"events":[{"type":"update","product_id":"ETH-USD","updates":[{"side":"bid","event_time":"2025-10-27T17:39:45.431754Z","price_level":"4217.55","new_quantity":"0"},{"side":"offer","event_time":"2025-10-27T17:39:45.431754Z","price_level":"4218.62","new_quantity":"0.15593277"},{"side":"offer","event_time":"2025-10-27T17:39:45.431754Z","price_level":"4225.69","new_quantity":"0"},{"side":"offer","event_time":"2025-10-27T17:39:45.431754Z","price_level":"4228.75","new_quantity":"7.68324775"}]}]}
{"channel":"l2_data","client_id":"","timestamp":"2025-10-27T17:39:45.498342385Z","sequence_num":137830,"events":[{"type":"update","product_id":"BTC-USD","updates":[{"side":"bid","event_time":"2025-10-27T17:39:45.448373Z","price_level":"115632.3","new_quantity":"0"},{"side":"bid","event_time":"2025-10-27T17:39:45.448373Z","price_level":"115631.13","new_quantity":"0"},{"side":"bid","event_time":"2025-10-27T17:39:45.448373Z","price_level":"115627.48","new_quantity":"0"},{"side":"bid","event_time":"2025-10-27T17:39:45.448373Z","price_level":"115609.26","new_quantity":"0.00001"},{"side":"bid","event_time":"2025-10-27T17:39:45.448373Z","price_level":"115566","new_quantity":"0"},{"side":"bid","event_time":"2025-10-27T17:39:45.448373Z","price_level":"115559.82","new_quantity":"0"},{"side":"bid","event_time":"2025-10-27T17:39:45.448373Z","price_level":"115534.45","new_quantity":"0.00043232"},{"side":"bid","event_time":"2025-10-27T17:39:45.448373Z","price_level":"115534.44","new_quantity":"0.01033458"},{"side":"offer","event_time":"2025-10-27T17:39:45.448373Z","price_level":"115668","new_quantity":"2"},{"side":"offer","event_time":"2025-10-27T17:39:45.448373Z","price_level":"115669.99","new_quantity":"0.07164597"},{"side":"offer","event_time":"2025-10-27T17:39:45.448373Z","price_level":"115675.39","new_quantity":"0.00301718"},{"side":"offer","event_time":"2025-10-27T17:39:45.448373Z","price_level":"115680","new_quantity":"1"},{"side":"offer","event_time":"2025-10-27T17:39:45.448373Z","price_level":"115692.38","new_quantity":"0.16812569"},{"side":"offer","event_time":"2025-10-27T17:39:45.448373Z","price_level":"115692.39","new_quantity":"0.5"},{"side":"offer","event_time":"2025-10-27T17:39:45.448373Z","price_level":"115695.12","new_quantity":"0"},{"side":"offer","event_time":"2025-10-27T17:39:45.448373Z","price_level":"115697.34","new_quantity":"0"},{"side":"offer","event_time":"2025-10-27T17:39:45.448373Z","price_level":"115705.94","new_quantity":"0.00043232"},{"side":"offer","event_time":"2025-10-27T17:39:45.448373Z","price_level":"115707.06","new_quantity":"0"}]}]}
{"channel":"l2_data","client_id":"","timestamp":"2025-10-27T17:39:45.550607231Z","sequence_num":137832,"events":[{"type":"update","product_id":"BTC-USD","updates":[{"side":"bid","event_time":"2025-10-27T17:39:45.498163Z","price_level":"115640.91","new_quantity":"0.06421293"},{"side":"bid","event_time":"2025-10-27T17:39:45.498163Z","price_level":"115640.01","new_quantity":"0"},{"side":"bid","event_time":"2025-10-27T17:39:45.498163Z","price_level":"115640","new_quantity":"0"},{"side":"bid","event_time":"2025-10-27T17:39:45.498163Z","price_level":"115638","new_quantity":"0"},{"side":"bid","event_time":"2025-10-27T17:39:45.498163Z","price_level":"115636.01","new_quantity":"0"},{"side":"bid","event_time":"2025-10-27T17:39:45.498163Z","price_level":"115636","new_quantity":"0.0213"},{"side":"bid","event_time":"2025-10-27T17:39:45.498163Z","price_level":"115634.69","new_quantity":"0"},{"side":"bid","event_time":"2025-10-27T17:39:45.498163Z","price_level":"115634.68","new_quantity":"0"},{"side":"bid","event_time":"2025-10-27T17:39:45.498163Z","price_level":"115634.17","new_quantity":"0"},{"side":"bid","event_time":"2025-10-27T17:39:45.498163Z","price_level":"115633.06","new_quantity":"0"},{"side":"bid","event_time":"2025-10-27T17:39:45.498163Z","price_level":"115633.05","new_quantity":"0.0051945"},{"side":"bid","event_time":"2025-10-27T17:39:45.498163Z","price_level":"115631.63","new_quantity":"0"},{"side":"bid","event_time":"2025-10-27T17:39:45.498163Z","price_level":"115629.01","new_quantity":"0"},{"side":"bid","event_time":"2025-10-27T17:39:45.498163Z","price_level":"115629","new_quantity":"0"},{"side":"bid","event_time":"2025-10-27T17:39:45.498163Z","price_level":"115627.31","new_quantity":"0.00043334"},{"side":"bid","event_time":"2025-10-27T17:39:45.498163Z","price_level":"115627.29","new_quantity":"0"},{"side":"bid","event_time":"2025-10-27T17:39:45.498163Z","price_level":"115627","new_quantity":"0"},{"side":"bid","event_time":"2025-10-27T17:39:45.498163Z","price_level":"115626.99","new_quantity":"0"},{"side":"bid","event_time":"2025-10-27T17:39:45.498163Z","price_level":"115625.95","new_quantity":"0"},{"side":"bid","event_time":"2025-10-27T17:39:45.498163Z","price_level":"115625","new_quantity":"0"},{"side":"bid","event_time":"2025-10-27T17:39:45.498163Z","price_level":"115623.76","new_quantity":"0.08648741"},{"side":"bid","event_time":"2025-10-27T17:39:45.498163Z","price_level":"115623.6","new_quantity":"0"},{"side":"bid","event_time":"2025-10-27T17:39:45.498163Z","price_level":"115623.11","new_quantity":"0"},{"side":"bid","event_time":"2025-10-27T17:39:45.498163Z","price_level":"115623","new_quantity":"0"},{"side":"bid","event_time":"2025-10-27T17:39:45.498163Z","price_level":"115621","new_quantity":"0"},{"side":"bid","event_time":"2025-10-27T17:39:45.498163Z","price_level":"115620","new_quantity":"0"},{"side":"bid","event_time":"2025-10-27T17:39:45.498163Z","price_level":"115618.91","new_quantity":"0"},{"side":"bid","event_time":"2025-10-27T17:39:45.498163Z","price_level":"115618.61","new_quantity":"0"},{"side":"bid","event_time":"2025-10-27T17:39:45.498163Z","price_level":"115618","new_quantity":"0.4"},{"side":"bid","event_time":"2025-10-27T17:39:45.498163Z","price_level":"115617.58","new_quantity":"0.08649202"},{"side":"bid","event_time":"2025-10-27T17:39:45.498163Z","price_level":"115616.81","new_quantity":"0"},{"side":"bid","event_time":"2025-10-27T17:39:45.498163Z","price_level":"115616","new_quantity":"0"},{"side":"bid","event_time":"2025-10-27T17:39:45.498163Z","price_level":"115615.01","new_quantity":"0.01032746"},{"side":"bid","event_time":"2025-10-27T17:39:45.498163Z","price_level":"115612.97","new_quantity":"0"},{"side":"bid","event_time":"2025-10-27T17:39:45.498163Z","price_level":"115612.96","new_quantity":"0"},{"side":"bid","event_time":"2025-10-27T17:39:45.498163Z","price_level":"115610.14","new_quantity":"0.16562"},{"side":"bid","event_time":"2025-10-27T17:39:45.498163Z","price_level":"115609.09","new_quantity":"0.76377883"},{"side":"bid","event_time":"2025-10-27T17:39:45.498163Z","price_level":"115609.08","new_quantity":"0.33126821"},{"side":"bid","event_time":"2025-10-27T17:39:45.498163Z","price_level":"115608.69","new_quantity":"0"},{"side":"bid","event_time":"2025-10-27T17:39:45.498163Z","price_level":"115608.68","new_quantity":"0"},{"side":"bid","event_time":"2025-10-27T17:39:45.498163Z","price_level":"115607.55","new_quantity":"0.011241"},{"side":"bid","event_time":"2025-10-27T17:39:45.498163Z","price_level":"115606.99","new_quantity":"0"},{"side":"bid","event_time":"2025-10-27T17:39:45.498163Z","price_level":"115596.98","new_quantity":"0.53831591"},{"side":"bid","event_time":"2025-10-27T17:39:45.498163Z","price_level":"115596.97","new_quantity":"0.37037536"},{"side":"bid","event_time":"2025-10-27T17:39:45.498163Z","price_level":"115596.96","new_quantity":"0"},{"side":"bid","event_time":"2025-10-27T17:39:45.498163Z","price_level":"115590.36","new_quantity":"0"},{"side":"bid","event_time":"2025-10-27T17:39:45.498163Z","price_level":"115574.7","new_quantity":"0"},{"side":"bid","event_time":"2025-10-27T17:39:45.498163Z","price_level":"115574.4","new_quantity":"1.5"},{"side":"bid","event_time":"2025-10-27T17:39:45.498163Z","price_level":"115562.5","new_quantity":"0"},{"side":"bid","event_time":"2025-10-27T17:39:45.498163Z","price_level":"115562.49","new_quantity":"0"},{"side":"bid","event_time":"2025-10-27T17:39:45.498163Z","price_level":"115504.63","new_quantity":"0"},{"side":"bid","event_time":"2025-10-27T17:39:45.498163Z","price_level":"115504.62","new_quantity":"0"},{"side":"bid","event_time":"2025-10-27T17:39:45.498163Z","price_level":"115499.01","new_quantity":"0"},{"side":"bid","event_time":"2025-10-27T17:39:45.498163Z","price_level":"115499","new_quantity":"0"},{"side":"bid","event_time":"2025-10-27T17:39:45.498163Z","price_level":"115496.77","new_quantity":"0.045"},{"side":"bid","event_time":"2025-10-27T17:39:45.498163Z","price_level":"115468.89","new_quantity":"2.500289"},{"side":"bid","event_time":"2025-10-27T17:39:45.498163Z","price_level":"115462.68","new_quantity":"0.0850725"},{"side":"bid","event_time":"2025-10-27T17:39:45.498163Z","price_level":"115409","new_quantity":"0.79952"},{"side":"bid","event_time":"2025-10-27T17:39:45.498163Z","price_level":"114901.59","new_quantity":"0"},{"side":"bid","event_time":"2025-10-27T17:39:45.498163Z","price_level":"114893.59","new_quantity":"0.00216168"},{"side":"offer","event_time":"2025-10-27T17:39:45.498163Z","price_level":"115640.92","new_quantity":"0.1003326"},{"side":"offer","event_time":"2025-10-27T17:39:45.498163Z","price_level":"115642.23","new_quantity":"0"},{"side":"offer","event_time":"2025-10-27T17:39:45.498163Z","price_level":"115644.33","new_quantity":"0"},{"side":"offer","event_time":"2025-10-27T17:39:45.498163Z","price_level":"115647.51","new_quantity":"0.02"},{"side":"offer","event_time":"2025-10-27T17:39:45.498163Z","price_level":"115647.52","new_quantity":"0"},{"side":"offer","event_time":"2025-10-27T17:39:45.498163Z","price_level":"115651.81","new_quantity":"0.00076184"},{"side":"offer","event_time":"2025-10-27T17:39:45.498163Z","price_level":"115651.82","new_quantity":"0.000076"},{"side":"offer","event_time":"2025-10-27T17:39:45.498163Z","price_level":"115656.04","new_quantity":"0.00432"},{"side":"offer","event_time":"2025-10-27T17:39:45.498163Z","price_level":"115658.36","new_quantity":"0.00432"},{"side":"offer","event_time":"2025-10-27T17:39:45.498163Z","price_level":"115658.37","new_quantity":"0.00432"},{"side":"offer","event_time":"2025-10-27T17:39:45.498163Z","price_level":"115663","new_quantity":"0"},{"side":"offer","event_time":"2025-10-27T17:39:45.498163Z","price_level":"115663.01","new_quantity":"0"},{"side":"offer","event_time":"2025-10-27T17:39:45.498163Z","price_level":"115668","new_quantity":"0"},{"side":"offer","event_time":"2025-10-27T17:39:45.498163Z","price_level":"115669.98","new_quantity":"0.1729413"},{"side":"offer","event_time":"2025-10-27T17:39:45.498163Z","price_level":"115669.99","new_quantity":"0.07164597"},{"side":"offer","event_time":"2025-10-27T17:39:45.498163Z","price_level":"115675.4","new_quantity":"0"},{"side":"offer","event_time":"2025-10-27T17:39:45.498163Z","price_level":"115675.44","new_quantity":"0"},{"side":"offer","event_time":"2025-10-27T17:39:45.498163Z","price_level":"115680","new_quantity":"0"},{"side":"offer","event_time":"2025-10-27T17:39:45.498163Z","price_level":"115692.39","new_quantity":"0"},{"side":"offer","event_time":"2025-10-27T17:39:45.498163Z","price_level":"115703.11","new_quantity":"0"},{"side":"offer","event_time":"2025-10-27T17:39:45.498163Z","price_level":"115710","new_quantity":"0.4000267"},{"side":"offer","event_time":"2025-10-27T17:39:45.498163Z","price_level":"115718.79","new_quantity":"0.37936283"},{"side":"offer","event_time":"2025-10-27T17:39:45.498163Z","price_level":"115719.94","new_quantity":"0"},{"side":"offer","event_time":"2025-10-27T17:39:45.498163Z","price_level":"115727.08","new_quantity":"0.56827786"},{"side":"offer","event_time":"2025-10-27T17:39:45.498163Z","price_level":"115727.1","new_quantity":"0"},{"side":"offer","event_time":"2025-10-27T17:39:45.498163Z","price_level":"115749.99","new_quantity":"0.06917379"},{"side":"offer","event_time":"2025-10-27T17:39:45.498163Z","price_level":"115762.08","new_quantity":"0"},{"side":"offer","event_time":"2025-10-27T17:39:45.498163Z","price_level":"115764.88","new_quantity":"0.12452357"}]}]}
{"channel":"l2_data","client_id":"","timestamp":"2025-10-27T17:39:45.59820066Z","sequence_num":137835,"events":[{"type":"update","product_id":"BTC-USD","updates":[{"side":"bid","event_time":"2025-10-27T17:39:45.554313Z","price_level":"115640.91","new_quantity":"0.00011082"},{"side":"bid","event_time":"2025-10-27T17:39:45.554313Z","price_level":"115638.11","new_quantity":"0"},{"side":"bid","event_time":"2025-10-27T17:39:45.554313Z","price_level":"115638","new_quantity":"0"},{"side":"bid","event_time":"2025-10-27T17:39:45.554313Z","price_level":"115633.05","new_quantity":"0"},{"side":"bid","event_time":"2025-10-27T17:39:45.554313Z","price_level":"115627.15","new_quantity":"0.00864848"},{"side":"bid","event_time":"2025-10-27T17:39:45.554313Z","price_level":"115616.55","new_quantity":"0.0864928"},{"side":"bid","event_time":"2025-10-27T17:39:45.554313Z","price_level":"115615.9","new_quantity":"0.00259808"},{"side":"bid","event_time":"2025-10-27T17:39:45.554313Z","price_level":"115610.84","new_quantity":"0.00519616"},{"side":"bid","event_time":"2025-10-27T17:39:45.554313Z","price_level":"115610.01","new_quantity":"1.9577848"},{"side":"bid","event_time":"2025-10-27T17:39:45.554313Z","price_level":"115610","new_quantity":"3"},{"side":"bid","event_time":"2025-10-27T17:39:45.554313Z","price_level":"115609.09","new_quantity":"0"},{"side":"bid","event_time":"2025-10-27T17:39:45.554313Z","price_level":"115586.05","new_quantity":"0"},{"side":"bid","event_time":"2025-10-27T17:39:45.554313Z","price_level":"115580","new_quantity":"5.06483415"},{"side":"bid","event_time":"2025-10-27T17:39:45.554313Z","price_level":"115496.77","new_quantity":"0"},{"side":"bid","event_time":"2025-10-27T17:39:45.554313Z","price_level":"114918.53","new_quantity":"0.045"},{"side":"bid","event_time":"2025-10-27T17:39:45.554313Z","price_level":"114526.63","new_quantity":"0.07007"},{"side":"bid","event_time":"2025-10-27T17:39:45.554313Z","price_level":"114097.77","new_quantity":"0.07007"},{"side":"offer","event_time":"2025-10-27T17:39:45.554313Z","price_level":"115640.92","new_quantity":"0.02329936"},{"side":"offer","event_time":"2025-10-27T17:39:45.554313Z","price_level":"115642.42","new_quantity":"0.02594203"},{"side":"offer","event_time":"2025-10-27T17:39:45.554313Z","price_level":"115647.5","new_quantity":"0.00412623"},{"side":"offer","event_time":"2025-10-27T17:39:45.554313Z","price_level":"115651.81","new_quantity":"0"},{"side":"offer","event_time":"2025-10-27T17:39:45.554313Z","price_level":"115656.04","new_quantity":"0"},{"side":"offer","event_time":"2025-10-27T17:39:45.554313Z","price_level":"115658.36","new_quantity":"0"},{"side":"offer","event_time":"2025-10-27T17:39:45.554313Z","price_level":"115658.37","new_quantity":"0"},{"side":"offer","event_time":"2025-10-27T17:39:45.554313Z","price_level":"115662","new_quantity":"2"},{"side":"offer","event_time":"2025-10-27T17:39:45.554313Z","price_level":"115663","new_quantity":"2"},{"side":"offer","event_time":"2025-10-27T17:39:45.554313Z","price_level":"115665","new_quantity":"0.4"},{"side":"offer","event_time":"2025-10-27T17:39:45.554313Z","price_level":"115669.98","new_quantity":"0.13835768"},{"side":"offer","event_time":"2025-10-27T17:39:45.554313Z","price_level":"115670","new_quantity":"1"},{"side":"offer","event_time":"2025-10-27T17:39:45.554313Z","price_level":"115671","new_quantity":"0"},{"side":"offer","event_time":"2025-10-27T17:39:45.554313Z","price_level":"115673.76","new_quantity":"0.07007"},{"side":"offer","event_time":"2025-10-27T17:39:45.554313Z","price_level":"115674.65","new_quantity":"0"},{"side":"offer","event_time":"2025-10-27T17:39:45.554313Z","price_level":"115675.39","new_quantity":"0"},{"side":"offer","event_time":"2025-10-27T17:39:45.554313Z","price_level":"115675.41","new_quantity":"0"},{"side":"offer","event_time":"2025-10-27T17:39:45.554313Z","price_level":"115675.45","new_quantity":"0"},{"side":"offer","event_time":"2025-10-27T17:39:45.554313Z","price_level":"115689.73","new_quantity":"0.16812954"},{"side":"offer","event_time":"2025-10-27T17:39:45.554313Z","price_level":"115690","new_quantity":"5"},{"side":"offer","event_time":"2025-10-27T17:39:45.554313Z","price_level":"115692.38","new_quantity":"0"},{"side":"offer","event_time":"2025-10-27T17:39:45.554313Z","price_level":"115706.38","new_quantity":"0.25574902"},{"side":"offer","event_time":"2025-10-27T17:39:45.554313Z","price_level":"115709.99","new_quantity":"0"},{"side":"offer","event_time":"2025-10-27T17:39:45.554313Z","price_level":"115718.6","new_quantity":"1"},{"side":"offer","event_time":"2025-10-27T17:39:45.554313Z","price_level":"115718.8","new_quantity":"0"},{"side":"offer","event_time":"2025-10-27T17:39:45.554313Z","price_level":"116752.68","new_quantity":"0"},{"side":"offer","event_time":"2025-10-27T17:39:45.554313Z","price_level":"116968.06","new_quantity":"0"}]}]}
{"channel":"l2_data","client_id":"","timestamp":"2025-10-27T17:39:45.621011901Z","sequence_num":137836,"events":[{"type":"update","product_id":"ETH-USD","updates":[{"side":"bid","event_time":"2025-10-27T17:39:45.581178Z","price_level":"4218.17","new_quantity":"0.0710956"},{"side":"bid","event_time":"2025-10-27T17:39:45.581178Z","price_level":"4217.81","new_quantity":"14.82310115"},{"side":"bid","event_time":"2025-10-27T17:39:45.581178Z","price_level":"4217.55","new_quantity":"1.65774"},{"side":"bid","event_time":"2025-10-27T17:39:45.581178Z","price_level":"4217.25","new_quantity":"0.47067485"},{"side":"bid","event_time":"2025-10-27T17:39:45.581178Z","price_level":"4217.23","new_quantity":"0.6"},{"side":"bid","event_time":"2025-10-27T17:39:45.581178Z","price_level":"4217.22","new_quantity":"0.88053657"},{"side":"bid","event_time":"2025-10-27T17:39:45.581178Z","price_level":"4217.2","new_quantity":"0.56441027"},{"side":"bid","event_time":"2025-10-27T17:39:45.581178Z","price_level":"4216.61","new_quantity":"1.4"},{"side":"offer","event_time":"2025-10-27T17:39:45.581178Z","price_level":"4218.27","new_quantity":"0.51034771"},{"side":"offer","event_time":"2025-10-27T17:39:45.581178Z","price_level":"4218.28","new_quantity":"0.18965075"},{"side":"offer","event_time":"2025-10-27T17:39:45.581178Z","price_level":"4218.29","new_quantity":"1.26308965"},{"side":"offer","event_time":"2025-10-27T17:39:45.581178Z","price_level":"4218.39","new_quantity":"0"},{"side":"offer","event_time":"2025-10-27T17:39:45.581178Z","price_level":"4219.46","new_quantity":"1.4"},{"side":"offer","event_time":"2025-10-27T17:39:45.581178Z","price_level":"4219.8","new_quantity":"30"},{"side":"offer","event_time":"2025-10-27T17:39:45.581178Z","price_level":"4220","new_quantity":"42.20517286"},{"side":"offer","event_time":"2025-10-27T17:39:45.581178Z","price_level":"4222","new_quantity":"50.39505286"},{"side":"offer","event_time":"2025-10-27T17:39:45.581178Z","price_level":"4222.86","new_quantity":"9.20460896"},{"side":"offer","event_time":"2025-10-27T17:39:45.581178Z","price_level":"4222.93","new_quantity":"0"},{"side":"offer","event_time":"2025-10-27T17:39:45.581178Z","price_level":"4244.82","new_quantity":"0"}]}]}
{"channel":"l2_data","client_id":"","timestamp":"2025-10-27T17:39:45.648479568Z","sequence_num":137838,"events":[{"type":"update","product_id":"BTC-USD","updates":[{"side":"bid","event_time":"2025-10-27T17:39:45.611705Z","price_level":"115640.91","new_quantity":"0"},{"side":"bid","event_time":"2025-10-27T17:39:45.611705Z","price_level":"115638.6","new_quantity":"0.00939491"},{"side":"bid","event_time":"2025-10-27T17:39:45.611705Z","price_level":"115634","new_quantity":"0.0213"},{"side":"bid","event_time":"2025-10-27T17:39:45.611705Z","price_level":"115624.85","new_quantity":"0.02161139"},{"side":"bid","event_time":"2025-10-27T17:39:45.611705Z","price_level":"115621.11","new_quantity":"0.12"},{"side":"bid","event_time":"2025-10-27T17:39:45.611705Z","price_level":"115618.5","new_quantity":"0.16562"},{"side":"bid","event_time":"2025-10-27T17:39:45.611705Z","price_level":"115616.56","new_quantity":"0.06352068"},{"side":"bid","event_time":"2025-10-27T17:39:45.611705Z","price_level":"115615.01","new_quantity":"0"},{"side":"bid","event_time":"2025-10-27T17:39:45.611705Z","price_level":"115610.15","new_quantity":"0.33126514"},{"side":"bid","event_time":"2025-10-27T17:39:45.611705Z","price_level":"115609.08","new_quantity":"0"},{"side":"bid","event_time":"2025-10-27T17:39:45.611705Z","price_level":"115606.36","new_quantity":"0.0069609"},{"side":"bid","event_time":"2025-10-27T17:39:45.611705Z","price_level":"115604.26","new_quantity":"0.28"},{"side":"bid","event_time":"2025-10-27T17:39:45.611705Z","price_level":"115598.41","new_quantity":"0.00703296"},{"side":"bid","event_time":"2025-10-27T17:39:45.611705Z","price_level":"115596.98","new_quantity":"0"},{"side":"bid","event_time":"2025-10-27T17:39:45.611705Z","price_level":"115590.78","new_quantity":"0.53834478"},{"side":"bid","event_time":"2025-10-27T17:39:45.611705Z","price_level":"115574.72","new_quantity":"0"},{"side":"bid","event_time":"2025-10-27T17:39:45.611705Z","price_level":"115574.4","new_quantity":"0"},{"side":"bid","event_time":"2025-10-27T17:39:45.611705Z","price_level":"115572.7","new_quantity":"0"},{"side":"bid","event_time":"2025-10-27T17:39:45.611705Z","price_level":"115567.27","new_quantity":"0.76394699"},{"side":"bid","event_time":"2025-10-27T17:39:45.611705Z","price_level":"115563.9","new_quantity":"1.5"},{"side":"bid","event_time":"2025-10-27T17:39:45.611705Z","price_level":"101185.8","new_quantity":"0"},{"side":"offer","event_time":"2025-10-27T17:39:45.611705Z","price_level":"115638.61","new_quantity":"0.005"},{"side":"offer","event_time":"2025-10-27T17:39:45.611705Z","price_level":"115640.92","new_quantity":"0.02841411"},{"side":"offer","event_time":"2025-10-27T17:39:45.611705Z","price_level":"115642.42","new_quantity":"0"},{"side":"offer","event_time":"2025-10-27T17:39:45.611705Z","price_level":"115647.47","new_quantity":"0.00420509"},{"side":"offer","event_time":"2025-10-27T17:39:45.611705Z","price_level":"115647.48","new_quantity":"0.00007599"},{"side":"offer","event_time":"2025-10-27T17:39:45.611705Z","price_level":"115647.49","new_quantity":"0.02"},{"side":"offer","event_time":"2025-10-27T17:39:45.611705Z","price_level":"115647.51","new_quantity":"0"},{"side":"offer","event_time":"2025-10-27T17:39:45.611705Z","price_level":"115647.52","new_quantity":"0.02"},{"side":"offer","event_time":"2025-10-27T17:39:45.611705Z","price_level":"115651.82","new_quantity":"0"},{"side":"offer","event_time":"2025-10-27T17:39:45.611705Z","price_level":"115661.87","new_quantity":"0.629328"},{"side":"offer","event_time":"2025-10-27T17:39:45.611705Z","price_level":"115665","new_quantity":"0"},{"side":"offer","event_time":"2025-10-27T17:39:45.611705Z","price_level":"115666.99","new_quantity":"0.38912936"},{"side":"offer","event_time":"2025-10-27T17:39:45.611705Z","price_level":"115667.99","new_quantity":"0.0345893"},{"side":"offer","event_time":"2025-10-27T17:39:45.611705Z","price_level":"115675.42","new_quantity":"0"},{"side":"offer","event_time":"2025-10-27T17:39:45.611705Z","price_level":"115694.06","new_quantity":"0.28"},{"side":"offer","event_time":"2025-10-27T17:39:45.611705Z","price_level":"115718.1","new_quantity":"1"},{"side":"offer","event_time":"2025-10-27T17:39:45.611705Z","price_level":"115718.59","new_quantity":"0.37936348"},{"side":"offer","event_time":"2025-10-27T17:39:45.611705Z","price_level":"115718.6","new_quantity":"0"},{"side":"offer","event_time":"2025-10-27T17:39:45.611705Z","price_level":"115718.79","new_quantity":"0"},{"side":"offer","event_time":"2025-10-27T17:39:45.611705Z","price_level":"115719.94","new_quantity":"0.56831292"},{"side":"offer","event_time":"2025-10-27T17:39:45.611705Z","price_level":"115727.08","new_quantity":"0"},{"side":"offer","event_time":"2025-10-27T17:39:45.611705Z","price_level":"115788.48","new_quantity":"0"},{"side":"offer","event_time":"2025-10-27T17:39:45.611705Z","price_level":"115797.89","new_quantity":"0"},{"side":"offer","event_time":"2025-10-27T17:39:45.611705Z","price_level":"115799.08","new_quantity":"0.10991073"},{"side":"offer","event_time":"2025-10-27T17:39:45.611705Z","price_level":"116376.13","new_quantity":"0.045"}]}]}
{"channel":"l2_data","client_id":"","timestamp":"2025-10-27T17:39:45.672079937Z","sequence_num":137839,"events":[{"type":"update","product_id":"ETH-USD","updates":[{"side":"bid","event_time":"2025-10-27T17:39:45.626448Z","price_level":"4218.21","new_quantity":"0.0710956"},{"side":"bid","event_time":"2025-10-27T17:39:45.626448Z","price_level":"4218.17","new_quantity":"0"},{"side":"bid","event_time":"2025-10-27T17:39:45.626448Z","price_level":"4217.82","new_quantity":"0.02307723"},{"side":"bid","event_time":"2025-10-27T17:39:45.626448Z","price_level":"4217.81","new_quantity":"14.82073025"},{"side":"bid","event_time":"2025-10-27T17:39:45.626448Z","price_level":"4217.64","new_quantity":"0.11854957"},{"side":"bid","event_time":"2025-10-27T17:39:45.626448Z","price_level":"4217.33","new_quantity":"3.31612"},{"side":"bid","event_time":"2025-10-27T17:39:45.626448Z","price_level":"4216.99","new_quantity":"0"},{"side":"bid","event_time":"2025-10-27T17:39:45.626448Z","price_level":"4214.51","new_quantity":"9.07318996"},{"side":"offer","event_time":"2025-10-27T17:39:45.626448Z","price_level":"4218.48","new_quantity":"0.48992646"},{"side":"offer","event_time":"2025-10-27T17:39:45.626448Z","price_level":"4218.75","new_quantity":"0.00198887"},{"side":"offer","event_time":"2025-10-27T17:39:45.626448Z","price_level":"4218.8","new_quantity":"0"},{"side":"offer","event_time":"2025-10-27T17:39:45.626448Z","price_level":"4218.83","new_quantity":"0"},{"side":"offer","event_time":"2025-10-27T17:39:45.626448Z","price_level":"4218.89","new_quantity":"0.01508562"},{"side":"offer","event_time":"2025-10-27T17:39:45.626448Z","price_level":"4219.31","new_quantity":"0.6"},{"side":"offer","event_time":"2025-10-27T17:39:45.626448Z","price_level":"4219.33","new_quantity":"0.84955428"},{"side":"offer","event_time":"2025-10-27T17:39:45.626448Z","price_level":"4219.5","new_quantity":"3.991953"},{"side":"offer","event_time":"2025-10-27T17:39:45.626448Z","price_level":"4219.52","new_quantity":"0"},{"side":"offer","event_time":"2025-10-27T17:39:45.626448Z","price_level":"4220","new_quantity":"22.20517286"}]}]}
{"channel":"l2_data","client_id":"","timestamp":"2025-10-27T17:39:45.847758072Z","sequence_num":137847,"events":[{"type":"update","product_id":"BTC-USD","updates":[{"side":"bid","event_time":"2025-10-27T17:39:45.790388Z","price_level":"115616.82","new_quantity":"0.11128068"},{"side":"bid","event_time":"2025-10-27T17:39:45.790388Z","price_level":"115616.81","new_quantity":"0.08"},{"side":"bid","event_time":"2025-10-27T17:39:45.790388Z","price_level":"115616.56","new_quantity":"0"},{"side":"bid","event_time":"2025-10-27T17:39:45.790388Z","price_level":"115603.49","new_quantity":"0.65420305"},{"side":"bid","event_time":"2025-10-27T17:39:45.790388Z","price_level":"115568.81","new_quantity":"1.23489786"},{"side":"bid","event_time":"2025-10-27T17:39:45.790388Z","price_level":"115550.44","new_quantity":"0"},{"side":"bid","event_time":"2025-10-27T17:39:45.790388Z","price_level":"115538.64","new_quantity":"0.00043233"},{"side":"bid","event_time":"2025-10-27T17:39:45.790388Z","price_level":"115534.45","new_quantity":"0"},{"side":"bid","event_time":"2025-10-27T17:39:45.790388Z","price_level":"115528.04","new_quantity":"0.00043233"},{"side":"bid","event_time":"2025-10-27T17:39:45.790388Z","price_level":"114918.53","new_quantity":"0"},{"side":"offer","event_time":"2025-10-27T17:39:45.790388Z","price_level":"115647.46","new_quantity":"0"},{"side":"offer","event_time":"2025-10-27T17:39:45.790388Z","price_level":"115647.47","new_quantity":"0"},{"side":"offer","event_time":"2025-10-27T17:39:45.790388Z","price_level":"115647.51","new_quantity":"0.00007599"},{"side":"offer","event_time":"2025-10-27T17:39:45.790388Z","price_level":"115647.52","new_quantity":"0.00288087"},{"side":"offer","event_time":"2025-10-27T17:39:45.790388Z","price_level":"115655.3","new_quantity":"0"},{"side":"offer","event_time":"2025-10-27T17:39:45.790388Z","price_level":"115661","new_quantity":"2"},{"side":"offer","event_time":"2025-10-27T17:39:45.790388Z","price_level":"115665","new_quantity":"0"},{"side":"offer","event_time":"2025-10-27T17:39:45.790388Z","price_level":"115703.27","new_quantity":"0.00043233"},{"side":"offer","event_time":"2025-10-27T17:39:45.790388Z","price_level":"115705.94","new_quantity":"0"},{"side":"offer","event_time":"2025-10-27T17:39:45.790388Z","price_level":"115709.23","new_quantity":"0.00043237"},{"side":"offer","event_time":"2025-10-27T17:39:45.790388Z","price_level":"115711.99","new_quantity":"0"},{"side":"offer","event_time":"2025-10-27T17:39:45.790388Z","price_level":"115713.38","new_quantity":"0.00043233"},{"side":"offer","event_time":"2025-10-27T17:39:45.790388Z","price_level":"115715.59","new_quantity":"0"},{"side":"offer","event_time":"2025-10-27T17:39:45.790388Z","price_level":"115797.89","new_quantity":"0"}]}]}
{"channel":"l2_data","client_id":"","timestamp":"2025-10-27T17:39:45.869110083Z","sequence_num":137849,"events":[{"type":"update","product_id":"ETH-USD","updates":[{"side":"bid","event_time":"2025-10-27T17:39:45.82908Z","price_level":"4218.21","new_quantity":"0"},{"side":"bid","event_time":"2025-10-27T17:39:45.82908Z","price_level":"4218.18","new_quantity":"0.0710956"},{"side":"bid","event_time":"2025-10-27T17:39:45.82908Z","price_level":"4218.11","new_quantity":"0"},{"side":"bid","event_time":"2025-10-27T17:39:45.82908Z","price_level":"4217.82","new_quantity":"0.02307723"},{"side":"bid","event_time":"2025-10-27T17:39:45.82908Z","price_level":"4217.81","new_quantity":"8.92150435"},{"side":"bid","event_time":"2025-10-27T17:39:45.82908Z","price_level":"4217.7","new_quantity":"0"},{"side":"bid","event_time":"2025-10-27T17:39:45.82908Z","price_level":"4217.55","new_quantity":"3.31612"},{"side":"bid","event_time":"2025-10-27T17:39:45.82908Z","price_level":"4217.22","new_quantity":"0.96001252"},{"side":"bid","event_time":"2025-10-27T17:39:45.82908Z","price_level":"4217.13","new_quantity":"0"},{"side":"bid","event_time":"2025-10-27T17:39:45.82908Z","price_level":"4215.91","new_quantity":"5.99742928"},{"side":"bid","event_time":"2025-10-27T17:39:45.82908Z","price_level":"4214.03","new_quantity":"49.72795022"},{"side":"bid","event_time":"2025-10-27T17:39:45.82908Z","price_level":"4214.01","new_quantity":"0.02283078"},{"side":"bid","event_time":"2025-10-27T17:39:45.82908Z","price_level":"4212.01","new_quantity":"16.54298415"},{"side":"bid","event_time":"2025-10-27T17:39:45.82908Z","price_level":"4211.1","new_quantity":"0"},{"side":"bid","event_time":"2025-10-27T17:39:45.82908Z","price_level":"4206.56","new_quantity":"0"}]}]}
{"channel":"l2_data","client_id":"","timestamp":"2025-10-27T17:39:45.919040525Z","sequence_num":137850,"events":[{"type":"update","product_id":"ETH-USD","updates":[{"side":"bid","event_time":"2025-10-27T17:39:45.850643Z","price_level":"4217.75","new_quantity":"1.65874"}]}]}
{"channel":"l2_data","client_id":"","timestamp":"2025-10-27T17:39:45.970731852Z","sequence_num":137852,"events":[{"type":"update","product_id":"ETH-USD","updates":[{"side":"bid","event_time":"2025-10-27T17:39:45.91962Z","price_level":"4217.33","new_quantity":"0"},{"side":"offer","event_time":"2025-10-27T17:39:45.91962Z","price_level":"4218.64","new_quantity":"0.00396085"}]}]}
{"channel":"l2_data","client_id":"","timestamp":"2025-10-27T17:39:46.022408411Z","sequence_num":137853,"events":[{"type":"update","product_id":"ETH-USD","updates":[{"side":"bid","event_time":"2025-10-27T17:39:45.987296Z","price_level":"4218.09","new_quantity":"0.71159267"},{"side":"bid","event_time":"2025-10-27T17:39:45.987296Z","price_level":"4217.55","new_quantity":"1.65838"},{"side":"offer","event_time":"2025-10-27T17:39:45.987296Z","price_level":"4223.4","new_quantity":"1.043"},{"side":"offer","event_time":"2025-10-27T17:39:45.987296Z","price_level":"4225.32","new_quantity":"0"}]}]}
{"channel":"l2_data","client_id":"","timestamp":"2025-10-27T17:39:46.121880749Z","sequence_num":137854,"events":[{"type":"update","product_id":"ETH-USD","updates":[{"side":"bid","event_time":"2025-10-27T17:39:46.079154Z","price_level":"4210.77","new_quantity":"0.89584139"},{"side":"bid","event_time":"2025-10-27T17:39:46.079154Z","price_level":"4206.7","new_quantity":"32.32614556"},{"side":"offer","event_time":"2025-10-27T17:39:46.079154Z","price_level":"4219.14","new_quantity":"0.102891"},{"side":"offer","event_time":"2025-10-27T17:39:46.079154Z","price_level":"4219.44","new_quantity":"0"},{"side":"offer","event_time":"2025-10-27T17:39:46.079154Z","price_level":"4229.15","new_quantity":"32.74802851"}]}]}
{"channel":"l2_data","client_id":"","timestamp":"2025-10-27T17:39:45.697456355Z","sequence_num":137840,"events":[{"type":"update","product_id":"BTC-USD","updates":[{"side":"bid","event_time":"2025-10-27T17:39:45.661537Z","price_level":"115638.6","new_quantity":"0.09167839"},{"side":"bid","event_time":"2025-10-27T17:39:45.661537Z","price_level":"115637.46","new_quantity":"0.0097207"},{"side":"bid","event_time":"2025-10-27T17:39:45.661537Z","price_level":"115627.31","new_quantity":"0"},{"side":"bid","event_time":"2025-10-27T17:39:45.661537Z","price_level":"115621.11","new_quantity":"0.04"},{"side":"bid","event_time":"2025-10-27T17:39:45.661537Z","price_level":"115565.2","new_quantity":"1.5"},{"side":"bid","event_time":"2025-10-27T17:39:45.661537Z","price_level":"115563.9","new_quantity":"0"},{"side":"bid","event_time":"2025-10-27T17:39:45.661537Z","price_level":"115496.77","new_quantity":"0.045"},{"side":"offer","event_time":"2025-10-27T17:39:45.661537Z","price_level":"115638.61","new_quantity":"0.0027692"},{"side":"offer","event_time":"2025-10-27T17:39:45.661537Z","price_level":"115640.91","new_quantity":"0.005"},{"side":"offer","event_time":"2025-10-27T17:39:45.661537Z","price_level":"115640.92","new_quantity":"0.02595093"},{"side":"offer","event_time":"2025-10-27T17:39:45.661537Z","price_level":"115647.46","new_quantity":"0.00007599"},{"side":"offer","event_time":"2025-10-27T17:39:45.661537Z","price_level":"115647.48","new_quantity":"0"},{"side":"offer","event_time":"2025-10-27T17:39:45.661537Z","price_level":"115647.5","new_quantity":"0"},{"side":"offer","event_time":"2025-10-27T17:39:45.661537Z","price_level":"115652.04","new_quantity":"0.16478"},{"side":"offer","event_time":"2025-10-27T17:39:45.661537Z","price_level":"115661.87","new_quantity":"0"},{"side":"offer","event_time":"2025-10-27T17:39:45.661537Z","price_level":"115665","new_quantity":"0.4"},{"side":"offer","event_time":"2025-10-27T17:39:45.661537Z","price_level":"115666.99","new_quantity":"0"},{"side":"offer","event_time":"2025-10-27T17:39:45.661537Z","price_level":"115671","new_quantity":"0.7891252"},{"side":"offer","event_time":"2025-10-27T17:39:45.661537Z","price_level":"115683.67","new_quantity":"0.943308"},{"side":"offer","event_time":"2025-10-27T17:39:45.661537Z","price_level":"115707.07","new_quantity":"0"},{"side":"offer","event_time":"2025-10-27T17:39:45.661537Z","price_level":"115718","new_quantity":"1"},{"side":"offer","event_time":"2025-10-27T17:39:45.661537Z","price_level":"115718.1","new_quantity":"0"}]}]}
{"channel":"l2_data","client_id":"","timestamp":"2025-10-27T17:39:45.721345531Z","sequence_num":137841,"events":[{"type":"update","product_id":"ETH-USD","updates":[{"side":"bid","event_time":"2025-10-27T17:39:45.678259Z","price_level":"4218.11","new_quantity":"0.71159267"},{"side":"bid","event_time":"2025-10-27T17:39:45.678259Z","price_level":"4217.33","new_quantity":"0"},{"side":"bid","event_time":"2025-10-27T17:39:45.678259Z","price_level":"4217.22","new_quantity":"1.83749051"},{"side":"bid","event_time":"2025-10-27T17:39:45.678259Z","price_level":"4217.13","new_quantity":"1.65838"},{"side":"offer","event_time":"2025-10-27T17:39:45.678259Z","price_level":"4219.5","new_quantity":"0.001"},{"side":"offer","event_time":"2025-10-27T17:39:45.678259Z","price_level":"4220.18","new_quantity":"0"}]}]}
{"channel":"l2_data","client_id":"","timestamp":"2025-10-27T17:39:45.747252588Z","sequence_num":137842,"events":[{"type":"update","product_id":"BTC-USD","updates":[{"side":"bid","event_time":"2025-10-27T17:39:45.689536Z","price_level":"115627.31","new_quantity":"0.00060599"},{"side":"bid","event_time":"2025-10-27T17:39:45.689536Z","price_level":"115618.99","new_quantity":"0.00432"},{"side":"bid","event_time":"2025-10-27T17:39:45.689536Z","price_level":"115618.96","new_quantity":"0.00432"},{"side":"bid","event_time":"2025-10-27T17:39:45.689536Z","price_level":"115610.14","new_quantity":"0"},{"side":"bid","event_time":"2025-10-27T17:39:45.689536Z","price_level":"115568.7","new_quantity":"1.5"},{"side":"bid","event_time":"2025-10-27T17:39:45.689536Z","price_level":"115565.2","new_quantity":"0"},{"side":"bid","event_time":"2025-10-27T17:39:45.689536Z","price_level":"114331.1","new_quantity":"0"},{"side":"offer","event_time":"2025-10-27T17:39:45.689536Z","price_level":"115640.91","new_quantity":"0"},{"side":"offer","event_time":"2025-10-27T17:39:45.689536Z","price_level":"115656.04","new_quantity":"0.00432"},{"side":"offer","event_time":"2025-10-27T17:39:45.689536Z","price_level":"115656.05","new_quantity":"0.00432"},{"side":"offer","event_time":"2025-10-27T17:39:45.689536Z","price_level":"115662","new_quantity":"0"},{"side":"offer","event_time":"2025-10-27T17:39:45.689536Z","price_level":"115665","new_quantity":"0"},{"side":"offer","event_time":"2025-10-27T17:39:45.689536Z","price_level":"115716.36","new_quantity":"0.37937079"},{"side":"offer","event_time":"2025-10-27T17:39:45.689536Z","price_level":"115718","new_quantity":"0"},{"side":"offer","event_time":"2025-10-27T17:39:45.689536Z","price_level":"115718.5","new_quantity":"1"},{"side":"offer","event_time":"2025-10-27T17:39:45.689536Z","price_level":"115718.59","new_quantity":"0"},{"side":"offer","event_time":"2025-10-27T17:39:45.689536Z","price_level":"115834.12","new_quantity":"0.08533122"},{"side":"offer","event_time":"2025-10-27T17:39:45.689536Z","price_level":"115888.48","new_quantity":"0.07007"}]}]}
{"channel":"l2_data","client_id":"","timestamp":"2025-10-27T17:39:45.77069338Z","sequence_num":137843,"events":[{"type":"update","product_id":"ETH-USD","updates":[{"side":"bid","event_time":"2025-10-27T17:39:45.724711Z","price_level":"4217.33","new_quantity":"1.65838"},{"side":"bid","event_time":"2025-10-27T17:39:45.724711Z","price_level":"4217","new_quantity":"1.97593789"},{"side":"bid","event_time":"2025-10-27T17:39:45.724711Z","price_level":"4216.98","new_quantity":"0"},{"side":"offer","event_time":"2025-10-27T17:39:45.724711Z","price_level":"4218.8","new_quantity":"0.02186499"},{"side":"offer","event_time":"2025-10-27T17:39:45.724711Z","price_level":"4218.89","new_quantity":"0"}]}]}
{"channel":"l2_data","client_id":"","timestamp":"2025-10-27T17:39:45.796855439Z","sequence_num":137844,"events":[{"type":"update","product_id":"BTC-USD","updates":[{"side":"bid","event_time":"2025-10-27T17:39:45.738849Z","price_level":"115638.6","new_quantity":"0.08228443"},{"side":"bid","event_time":"2025-10-27T17:39:45.738849Z","price_level":"115604.27","new_quantity":"0.1671767"},{"side":"bid","event_time":"2025-10-27T17:39:45.738849Z","price_level":"115595.86","new_quantity":"0.53832113"},{"side":"bid","event_time":"2025-10-27T17:39:45.738849Z","price_level":"115590.78","new_quantity":"0"},{"side":"bid","event_time":"2025-10-27T17:39:45.738849Z","price_level":"115568.71","new_quantity":"0.76393747"},{"side":"bid","event_time":"2025-10-27T17:39:45.738849Z","price_level":"115567.27","new_quantity":"0"},{"side":"offer","event_time":"2025-10-27T17:39:45.738849Z","price_level":"115647.49","new_quantity":"0"},{"side":"offer","event_time":"2025-10-27T17:39:45.738849Z","price_level":"115647.52","new_quantity":"0"},{"side":"offer","event_time":"2025-10-27T17:39:45.738849Z","price_level":"115661","new_quantity":"0"},{"side":"offer","event_time":"2025-10-27T17:39:45.738849Z","price_level":"115665","new_quantity":"0"},{"side":"offer","event_time":"2025-10-27T17:39:45.738849Z","price_level":"115669.98","new_quantity":"0"},{"side":"offer","event_time":"2025-10-27T17:39:45.738849Z","price_level":"115669.99","new_quantity":"1.25502524"},{"side":"offer","event_time":"2025-10-27T17:39:45.738849Z","price_level":"115671","new_quantity":"0.92748288"},{"side":"offer","event_time":"2025-10-27T17:39:45.738849Z","price_level":"115719.94","new_quantity":"0"},{"side":"offer","event_time":"2025-10-27T17:39:45.738849Z","price_level":"115727.15","new_quantity":"0.56827751"},{"side":"offer","event_time":"2025-10-27T17:39:45.738849Z","price_level":"115797.89","new_quantity":"0.045"}]}]}
{"channel":"l2_data","client_id":"","timestamp":"2025-10-27T17:39:46.171861053Z","sequence_num":137856,"events":[{"type":"update","product_id":"ETH-USD","updates":[{"side":"bid","event_time":"2025-10-27T17:39:46.115188Z","price_level":"4218.24","new_quantity":"1.07109662"},{"side":"bid","event_time":"2025-10-27T17:39:46.115188Z","price_level":"4218.2","new_quantity":"0.572"},{"side":"bid","event_time":"2025-10-27T17:39:46.115188Z","price_level":"4218.18","new_quantity":"0"},{"side":"bid","event_time":"2025-10-27T17:39:46.115188Z","price_level":"4218.11","new_quantity":"0.00237074"},{"side":"bid","event_time":"2025-10-27T17:39:46.115188Z","price_level":"4218.1","new_quantity":"0.572"},{"side":"bid","event_time":"2025-10-27T17:39:46.115188Z","price_level":"4218","new_quantity":"0.573"},{"side":"bid","event_time":"2025-10-27T17:39:46.115188Z","price_level":"4217.84","new_quantity":"0.02070633"},{"side":"bid","event_time":"2025-10-27T17:39:46.115188Z","price_level":"4217.83","new_quantity":"1.127"},{"side":"bid","event_time":"2025-10-27T17:39:46.115188Z","price_level":"4217.82","new_quantity":"0.11854458"},{"side":"bid","event_time":"2025-10-27T17:39:46.115188Z","price_level":"4217.81","new_quantity":"14.74057838"},{"side":"bid","event_time":"2025-10-27T17:39:46.115188Z","price_level":"4217.75","new_quantity":"3.31691"},{"side":"bid","event_time":"2025-10-27T17:39:46.115188Z","price_level":"4217.7","new_quantity":"10"},{"side":"bid","event_time":"2025-10-27T17:39:46.115188Z","price_level":"4217.64","new_quantity":"0"},{"side":"bid","event_time":"2025-10-27T17:39:46.115188Z","price_level":"4217.58","new_quantity":"0.48330631"},{"side":"bid","event_time":"2025-10-27T17:39:46.115188Z","price_level":"4217.42","new_quantity":"5.92201449"},{"side":"bid","event_time":"2025-10-27T17:39:46.115188Z","price_level":"4217.28","new_quantity":"0"},{"side":"bid","event_time":"2025-10-27T17:39:46.115188Z","price_level":"4217.25","new_quantity":"0.001"},{"side":"offer","event_time":"2025-10-27T17:39:46.115188Z","price_level":"4218.27","new_quantity":"0.18144255"},{"side":"offer","event_time":"2025-10-27T17:39:46.115188Z","price_level":"4218.28","new_quantity":"0.11853172"},{"side":"offer","event_time":"2025-10-27T17:39:46.115188Z","price_level":"4218.29","new_quantity":"0.02818477"},{"side":"offer","event_time":"2025-10-27T17:39:46.115188Z","price_level":"4218.3","new_quantity":"0"},{"side":"offer","event_time":"2025-10-27T17:39:46.115188Z","price_level":"4218.32","new_quantity":"0"},{"side":"offer","event_time":"2025-10-27T17:39:46.115188Z","price_level":"4218.39","new_quantity":"0.42491899"},{"side":"offer","event_time":"2025-10-27T17:39:46.115188Z","price_level":"4218.4","new_quantity":"0"},{"side":"offer","event_time":"2025-10-27T17:39:46.115188Z","price_level":"4218.46","new_quantity":"0.07110698"},{"side":"offer","event_time":"2025-10-27T17:39:46.115188Z","price_level":"4218.47","new_quantity":"0.6637487"},{"side":"offer","event_time":"2025-10-27T17:39:46.115188Z","price_level":"4218.48","new_quantity":"0.07111566"},{"side":"offer","event_time":"2025-10-27T17:39:46.115188Z","price_level":"4218.8","new_quantity":"0"},{"side":"offer","event_time":"2025-10-27T17:39:46.115188Z","price_level":"4218.89","new_quantity":"0.01267534"},{"side":"offer","event_time":"2025-10-27T17:39:46.115188Z","price_level":"4219.8","new_quantity":"20"},{"side":"offer","event_time":"2025-10-27T17:39:46.115188Z","price_level":"4220.44","new_quantity":"0.09965802"},{"side":"offer","event_time":"2025-10-27T17:39:46.115188Z","price_level":"4220.67","new_quantity":"8.13450975"},{"side":"offer","event_time":"2025-10-27T17:39:46.115188Z","price_level":"4221.51","new_quantity":"1.94391607"},{"side":"offer","event_time":"2025-10-27T17:39:46.115188Z","price_level":"4221.82","new_quantity":"13.39868538"},{"side":"offer","event_time":"2025-10-27T17:39:46.115188Z","price_level":"4223.73","new_quantity":"0"},{"side":"offer","event_time":"2025-10-27T17:39:46.115188Z","price_level":"4244.82","new_quantity":"0.1536"}]}]}
{"channel":"l2_data","client_id":"","timestamp":"2025-10-27T17:39:46.220853076Z","sequence_num":137858,"events":[{"type":"update","product_id":"ETH-USD","updates":[{"side":"bid","event_time":"2025-10-27T17:39:46.150649Z","price_level":"4218.11","new_quantity":"0"},{"side":"bid","event_time":"2025-10-27T17:39:46.150649Z","price_level":"4217.84","new_quantity":"0.02307722"},{"side":"offer","event_time":"2025-10-27T17:39:46.150649Z","price_level":"4219.8","new_quantity":"30"}]}]}
{"channel":"l2_data","client_id":"","timestamp":"2025-10-27T17:39:46.271052896Z","sequence_num":137859,"events":[{"type":"update","product_id":"ETH-USD","updates":[{"side":"bid","event_time":"2025-10-27T17:39:46.225393Z","price_level":"4217.55","new_quantity":"0.55637617"},{"side":"bid","event_time":"2025-10-27T17:39:46.225393Z","price_level":"4217.3","new_quantity":"0.146988"},{"side":"bid","event_time":"2025-10-27T17:39:46.225393Z","price_level":"4217.22","new_quantity":"0.62305959"},{"side":"bid","event_time":"2025-10-27T17:39:46.225393Z","price_level":"4217.2","new_quantity":"0"},{"side":"bid","event_time":"2025-10-27T17:39:46.225393Z","price_level":"4216.96","new_quantity":"0"},{"side":"offer","event_time":"2025-10-27T17:39:46.225393Z","price_level":"4218.8","new_quantity":"0.01384095"},{"side":"offer","event_time":"2025-10-27T17:39:46.225393Z","price_level":"4218.82","new_quantity":"0.50145327"},{"side":"offer","event_time":"2025-10-27T17:39:46.225393Z","price_level":"4218.89","new_quantity":"0"},{"side":"offer","event_time":"2025-10-27T17:39:46.225393Z","price_level":"4220.16","new_quantity":"5.06188168"},{"side":"offer","event_time":"2025-10-27T17:39:46.225393Z","price_level":"4221.53","new_quantity":"13.30167221"},{"side":"offer","event_time":"2025-10-27T17:39:46.225393Z","price_level":"4221.82","new_quantity":"0.09792687"},{"side":"offer","event_time":"2025-10-27T17:39:46.225393Z","price_level":"4244.82","new_quantity":"0"},{"side":"offer","event_time":"2025-10-27T17:39:46.225393Z","price_level":"4272.24","new_quantity":"0"}]}]}
{"channel":"l2_data","client_id":"","timestamp":"2025-10-27T17:39:46.318981827Z","sequence_num":137860,"events":[{"type":"update","product_id":"ETH-USD","updates":[{"side":"offer","event_time":"2025-10-27T17:39:46.281558Z","price_level":"4218.39","new_quantity":"0.07111717"},{"side":"offer","event_time":"2025-10-27T17:39:46.281558Z","price_level":"4218.46","new_quantity":"0"},{"side":"offer","event_time":"2025-10-27T17:39:46.281558Z","price_level":"4218.47","new_quantity":"0.59263287"}]}]}
{"channel":"l2_data","client_id":"","timestamp":"2025-10-27T17:39:46.369403722Z","sequence_num":137862,"events":[{"type":"update","product_id":"ETH-USD","updates":[{"side":"offer","event_time":"2025-10-27T17:39:46.324181Z","price_level":"4218.39","new_quantity":"0"},{"side":"offer","event_time":"2025-10-27T17:39:46.324181Z","price_level":"4218.4","new_quantity":"0.572"},{"side":"offer","event_time":"2025-10-27T17:39:46.324181Z","price_level":"4218.46","new_quantity":"0.07111599"},{"side":"offer","event_time":"2025-10-27T17:39:46.324181Z","price_level":"4218.8","new_quantity":"0"},{"side":"offer","event_time":"2025-10-27T17:39:46.324181Z","price_level":"4218.89","new_quantity":"0.02167591"},{"side":"offer","event_time":"2025-10-27T17:39:46.324181Z","price_level":"4244.82","new_quantity":"0.1536"}]}]}
{"channel":"l2_data","client_id":"","timestamp":"2025-10-27T17:39:45.821333305Z","sequence_num":137845,"events":[{"type":"update","product_id":"ETH-USD","updates":[{"side":"bid","event_time":"2025-10-27T17:39:45.775002Z","price_level":"4216.99","new_quantity":"0.21565049"},{"side":"offer","event_time":"2025-10-27T17:39:45.775002Z","price_level":"4229.22","new_quantity":"0"}]}]}
{"channel":"l2_data","client_id":"","timestamp":"2025-10-27T17:39:46.475979832Z","sequence_num":137865,"events":[{"type":"update","product_id":"BTC-USD","updates":[{"side":"bid","event_time":"2025-10-27T17:39:45.906007Z","price_level":"115627.31","new_quantity":"0"},{"side":"offer","event_time":"2025-10-27T17:39:45.906007Z","price_level":"115647.49","new_quantity":"0.00007725"},{"side":"offer","event_time":"2025-10-27T17:39:45.906007Z","price_level":"115647.5","new_quantity":"0.00452098"},{"side":"offer","event_time":"2025-10-27T17:39:45.906007Z","price_level":"115647.51","new_quantity":"0"},{"side":"offer","event_time":"2025-10-27T17:39:45.906007Z","price_level":"115647.52","new_quantity":"0.3097285"},{"side":"offer","event_time":"2025-10-27T17:39:45.906007Z","price_level":"115652.03","new_quantity":"0.28137808"},{"side":"offer","event_time":"2025-10-27T17:39:45.906007Z","price_level":"115655.73","new_quantity":"0"},{"side":"offer","event_time":"2025-10-27T17:39:45.906007Z","price_level":"115660.99","new_quantity":"2.11245357"},{"side":"offer","event_time":"2025-10-27T17:39:45.906007Z","price_level":"115661.55","new_quantity":"0"},{"side":"offer","event_time":"2025-10-27T17:39:45.906007Z","price_level":"115664.99","new_quantity":"0.02601863"},{"side":"offer","event_time":"2025-10-27T17:39:45.906007Z","price_level":"115669.99","new_quantity":"0.07164597"},{"side":"offer","event_time":"2025-10-27T17:39:45.906007Z","price_level":"115673.75","new_quantity":"0.13835768"}]}]}
{"channel":"l2_data","client_id":"","timestamp":"2025-10-27T17:39:46.476654756Z","sequence_num":137866,"events":[{"type":"update","product_id":"BTC-USD","updates":[{"side":"bid","event_time":"2025-10-27T17:39:45.956604Z","price_level":"115628.81","new_quantity":"0.00864836"},{"side":"bid","event_time":"2025-10-27T17:39:45.956604Z","price_level":"115627.15","new_quantity":"0"},{"side":"bid","event_time":"2025-10-27T17:39:45.956604Z","price_level":"115616.82","new_quantity":"0.12703969"},{"side":"bid","event_time":"2025-10-27T17:39:45.956604Z","price_level":"115616.81","new_quantity":"0.04"},{"side":"bid","event_time":"2025-10-27T17:39:45.956604Z","price_level":"115612.61","new_quantity":"0.08"},{"side":"offer","event_time":"2025-10-27T17:39:45.956604Z","price_level":"115664.99","new_quantity":"0.02601863"},{"side":"offer","event_time":"2025-10-27T17:39:45.956604Z","price_level":"115764.88","new_quantity":"0"},{"side":"offer","event_time":"2025-10-27T17:39:45.956604Z","price_level":"115799.08","new_quantity":"0"},{"side":"offer","event_time":"2025-10-27T17:39:45.956604Z","price_level":"115890.83","new_quantity":"0"}]}]}
{"channel":"l2_data","client_id":"","timestamp":"2025-10-27T17:39:46.4776491Z","sequence_num":137867,"events":[{"type":"update","product_id":"BTC-USD","updates":[{"side":"bid","event_time":"2025-10-27T17:39:46.00012Z","price_level":"115636.95","new_quantity":"0.02595093"},{"side":"bid","event_time":"2025-10-27T17:39:46.00012Z","price_level":"115616.07","new_quantity":"0.06378005"},{"side":"bid","event_time":"2025-10-27T17:39:46.00012Z","price_level":"114311.92","new_quantity":"0.07007"},{"side":"bid","event_time":"2025-10-27T17:39:46.00012Z","price_level":"114311.91","new_quantity":"0.07007"},{"side":"bid","event_time":"2025-10-27T17:39:46.00012Z","price_level":"114097.77","new_quantity":"0"},{"side":"offer","event_time":"2025-10-27T17:39:46.00012Z","price_level":"115643.11","new_quantity":"0.15487302"},{"side":"offer","event_time":"2025-10-27T17:39:46.00012Z","price_level":"115643.12","new_quantity":"0.2594188"},{"side":"offer","event_time":"2025-10-27T17:39:46.00012Z","price_level":"115647.49","new_quantity":"0"},{"side":"offer","event_time":"2025-10-27T17:39:46.00012Z","price_level":"115647.5","new_quantity":"0.00007725"},{"side":"offer","event_time":"2025-10-27T17:39:46.00012Z","price_level":"115647.51","new_quantity":"0.00446782"},{"side":"offer","event_time":"2025-10-27T17:39:46.00012Z","price_level":"115652.03","new_quantity":"0.12652195"},{"side":"offer","event_time":"2025-10-27T17:39:46.00012Z","price_level":"115655.74","new_quantity":"0"},{"side":"offer","event_time":"2025-10-27T17:39:46.00012Z","price_level":"115664.99","new_quantity":"0.02601863"},{"side":"offer","event_time":"2025-10-27T17:39:46.00012Z","price_level":"115735.59","new_quantity":"0"},{"side":"offer","event_time":"2025-10-27T17:39:46.00012Z","price_level":"115764.91","new_quantity":"0"},{"side":"offer","event_time":"2025-10-27T17:39:46.00012Z","price_level":"116103.1","new_quantity":"0.07007"},{"side":"offer","event_time":"2025-10-27T17:39:46.00012Z","price_level":"116960.82","new_quantity":"0.07007"}]}]}
{"channel":"l2_data","client_id":"","timestamp":"2025-10-27T17:39:46.478624679Z","sequence_num":137868,"events":[{"type":"update","product_id":"BTC-USD","updates":[{"side":"bid","event_time":"2025-10-27T17:39:46.027214Z","price_level":"115596.98","new_quantity":"0.53831591"},{"side":"bid","event_time":"2025-10-27T17:39:46.027214Z","price_level":"115595.86","new_quantity":"0"},{"side":"bid","event_time":"2025-10-27T17:39:46.027214Z","price_level":"114526.83","new_quantity":"0.07007"},{"side":"bid","event_time":"2025-10-27T17:39:46.027214Z","price_level":"114526.63","new_quantity":"0"},{"side":"bid","event_time":"2025-10-27T17:39:46.027214Z","price_level":"114311.91","new_quantity":"0"},{"side":"offer","event_time":"2025-10-27T17:39:46.027214Z","price_level":"115639.6","new_quantity":"0.02594267"},{"side":"offer","event_time":"2025-10-27T17:39:46.027214Z","price_level":"115640.92","new_quantity":"0.00000856"},{"side":"offer","event_time":"2025-10-27T17:39:46.027214Z","price_level":"115664.99","new_quantity":"0"},{"side":"offer","event_time":"2025-10-27T17:39:46.027214Z","price_level":"115667.99","new_quantity":"0"},{"side":"offer","event_time":"2025-10-27T17:39:46.027214Z","price_level":"115706.38","new_quantity":"0"},{"side":"offer","event_time":"2025-10-27T17:39:46.027214Z","price_level":"115709.99","new_quantity":"0.25574104"}]}]}
{"channel":"l2_data","client_id":"","timestamp":"2025-10-27T17:39:46.479060748Z","sequence_num":137869,"events":[{"type":"update","product_id":"BTC-USD","updates":[{"side":"bid","event_time":"2025-10-27T17:39:46.081713Z","price_level":"115626.33","new_quantity":"0.02161139"},{"side":"bid","event_time":"2025-10-27T17:39:46.081713Z","price_level":"115624.85","new_quantity":"0"},{"side":"offer","event_time":"2025-10-27T17:39:46.081713Z","price_level":"115647.5","new_quantity":"0"},{"side":"offer","event_time":"2025-10-27T17:39:46.081713Z","price_level":"115647.51","new_quantity":"0.00007725"}]}]}
{"channel":"l2_data","client_id":"","timestamp":"2025-10-27T17:39:46.474781102Z","sequence_num":137864,"events":[{"type":"update","product_id":"BTC-USD","updates":[{"side":"bid","event_time":"2025-10-27T17:39:45.859473Z","price_level":"115637.46","new_quantity":"0"},{"side":"bid","event_time":"2025-10-27T17:39:45.859473Z","price_level":"115621.11","new_quantity":"0"},{"side":"bid","event_time":"2025-10-27T17:39:45.859473Z","price_level":"115616.82","new_quantity":"0.06352068"},{"side":"bid","event_time":"2025-10-27T17:39:45.859473Z","price_level":"115616.81","new_quantity":"0"},{"side":"bid","event_time":"2025-10-27T17:39:45.859473Z","price_level":"115568.82","new_quantity":"0.76393674"},{"side":"bid","event_time":"2025-10-27T17:39:45.859473Z","price_level":"115568.71","new_quantity":"0"},{"side":"offer","event_time":"2025-10-27T17:39:45.859473Z","price_level":"115671","new_quantity":"0.7891252"},{"side":"offer","event_time":"2025-10-27T17:39:45.859473Z","price_level":"115797.89","new_quantity":"0.045"},{"side":"offer","event_time":"2025-10-27T17:39:45.859473Z","price_level":"116376.13","new_quantity":"0"}]}]}
{"channel":"l2_data","client_id":"","timestamp":"2025-10-27T17:39:46.484076314Z","sequence_num":137871,"events":[{"type":"update","product_id":"BTC-USD","updates":[{"side":"bid","event_time":"2025-10-27T17:39:46.191061Z","price_level":"115631.18","new_quantity":"0.02161192"},{"side":"bid","event_time":"2025-10-27T17:39:46.191061Z","price_level":"115629.01","new_quantity":"0"},{"side":"bid","event_time":"2025-10-27T17:39:46.191061Z","price_level":"115627.63","new_quantity":"0"},{"side":"bid","event_time":"2025-10-27T17:39:46.191061Z","price_level":"115620.65","new_quantity":"0.16656598"},{"side":"bid","event_time":"2025-10-27T17:39:46.191061Z","price_level":"115618.5","new_quantity":"0"},{"side":"bid","event_time":"2025-10-27T17:39:46.191061Z","price_level":"115615.85","new_quantity":"0.011242"},{"side":"bid","event_time":"2025-10-27T17:39:46.191061Z","price_level":"115610.22","new_quantity":"0"},{"side":"bid","event_time":"2025-10-27T17:39:46.191061Z","price_level":"115607.55","new_quantity":"0"},{"side":"bid","event_time":"2025-10-27T17:39:46.191061Z","price_level":"115604.28","new_quantity":"0"},{"side":"bid","event_time":"2025-10-27T17:39:46.191061Z","price_level":"115604.09","new_quantity":"0.0069609"},{"side":"bid","event_time":"2025-10-27T17:39:46.191061Z","price_level":"115596.71","new_quantity":"0.37042038"},{"side":"bid","event_time":"2025-10-27T17:39:46.191061Z","price_level":"115569.21","new_quantity":"0.76393416"},{"side":"bid","event_time":"2025-10-27T17:39:46.191061Z","price_level":"115568.82","new_quantity":"0"},{"side":"bid","event_time":"2025-10-27T17:39:46.191061Z","price_level":"114963.06","new_quantity":"0.07007"},{"side":"bid","event_time":"2025-10-27T17:39:46.191061Z","price_level":"114962.85","new_quantity":"0"},{"side":"bid","event_time":"2025-10-27T17:39:46.191061Z","price_level":"114319.77","new_quantity":"0.07011591"},{"side":"offer","event_time":"2025-10-27T17:39:46.191061Z","price_level":"115656.34","new_quantity":"0.16478"},{"side":"offer","event_time":"2025-10-27T17:39:46.191061Z","price_level":"115662","new_quantity":"0"},{"side":"offer","event_time":"2025-10-27T17:39:46.191061Z","price_level":"115665.99","new_quantity":"0"},{"side":"offer","event_time":"2025-10-27T17:39:46.191061Z","price_level":"115666","new_quantity":"0"},{"side":"offer","event_time":"2025-10-27T17:39:46.191061Z","price_level":"115709.25","new_quantity":"0"},{"side":"offer","event_time":"2025-10-27T17:39:46.191061Z","price_level":"115720.39","new_quantity":"0.01993432"}]}]}
{"channel":"l2_data","client_id":"","timestamp":"2025-10-27T17:39:46.484772457Z","sequence_num":137872,"events":[{"type":"update","product_id":"BTC-USD","updates":[{"side":"bid","event_time":"2025-10-27T17:39:46.249838Z","price_level":"115638.01","new_quantity":"0.04265444"},{"side":"bid","event_time":"2025-10-27T17:39:46.249838Z","price_level":"115634.01","new_quantity":"0.03569327"},{"side":"bid","event_time":"2025-10-27T17:39:46.249838Z","price_level":"115629","new_quantity":"0"},{"side":"bid","event_time":"2025-10-27T17:39:46.249838Z","price_level":"115616.82","new_quantity":"0.12831264"},{"side":"bid","event_time":"2025-10-27T17:39:46.249838Z","price_level":"115616","new_quantity":"0"},{"side":"bid","event_time":"2025-10-27T17:39:46.249838Z","price_level":"115612.62","new_quantity":"0"},{"side":"bid","event_time":"2025-10-27T17:39:46.249838Z","price_level":"115610.02","new_quantity":"0.33126551"},{"side":"bid","event_time":"2025-10-27T17:39:46.249838Z","price_level":"115493","new_quantity":"0"},{"side":"bid","event_time":"2025-10-27T17:39:46.249838Z","price_level":"115439","new_quantity":"0.2372"},{"side":"offer","event_time":"2025-10-27T17:39:46.249838Z","price_level":"115644.2","new_quantity":"0.02594163"},{"side":"offer","event_time":"2025-10-27T17:39:46.249838Z","price_level":"115645.99","new_quantity":"0"},{"side":"offer","event_time":"2025-10-27T17:39:46.249838Z","price_level":"115662","new_quantity":"0"},{"side":"offer","event_time":"2025-10-27T17:39:46.249838Z","price_level":"115665.99","new_quantity":"0"},{"side":"offer","event_time":"2025-10-27T17:39:46.249838Z","price_level":"115666","new_quantity":"0"}]}]}
{"channel":"l2_data","client_id":"","timestamp":"2025-10-27T17:39:46.486727635Z","sequence_num":137873,"events":[{"type":"update","product_id":"BTC-USD","updates":[{"side":"bid","event_time":"2025-10-27T17:39:46.301814Z","price_level":"115620.65","new_quantity":"0.38407085"},{"side":"bid","event_time":"2025-10-27T17:39:46.301814Z","price_level":"115619","new_quantity":"0.4"},{"side":"bid","event_time":"2025-10-27T17:39:46.301814Z","price_level":"115617","new_quantity":"0.4"},{"side":"bid","event_time":"2025-10-27T17:39:46.301814Z","price_level":"115616.82","new_quantity":"1.30590812"},{"side":"bid","event_time":"2025-10-27T17:39:46.301814Z","price_level":"115615","new_quantity":"0.4"},{"side":"bid","event_time":"2025-10-27T17:39:46.301814Z","price_level":"115614","new_quantity":"2"},{"side":"bid","event_time":"2025-10-27T17:39:46.301814Z","price_level":"115613","new_quantity":"0.4"},{"side":"bid","event_time":"2025-10-27T17:39:46.301814Z","price_level":"114748.03","new_quantity":"0.07007"},{"side":"bid","event_time":"2025-10-27T17:39:46.301814Z","price_level":"114747.89","new_quantity":"0"},{"side":"bid","event_time":"2025-10-27T17:39:46.301814Z","price_level":"114747.87","new_quantity":"0"},{"side":"bid","event_time":"2025-10-27T17:39:46.301814Z","price_level":"114747.77","new_quantity":"0"},{"side":"offer","event_time":"2025-10-27T17:39:46.301814Z","price_level":"115647.5","new_quantity":"0.00007732"},{"side":"offer","event_time":"2025-10-27T17:39:46.301814Z","price_level":"115647.52","new_quantity":"0"},{"side":"offer","event_time":"2025-10-27T17:39:46.301814Z","price_level":"115660.98","new_quantity":"0"},{"side":"offer","event_time":"2025-10-27T17:39:46.301814Z","price_level":"115665.99","new_quantity":"0"},{"side":"offer","event_time":"2025-10-27T17:39:46.301814Z","price_level":"115797.89","new_quantity":"0"},{"side":"offer","event_time":"2025-10-27T17:39:46.301814Z","price_level":"116376.13","new_quantity":"0.045"}]}]}
{"channel":"l2_data","client_id":"","timestamp":"2025-10-27T17:39:46.48750001Z","sequence_num":137874,"events":[{"type":"update","product_id":"BTC-USD","updates":[{"side":"bid","event_time":"2025-10-27T17:39:46.331425Z","price_level":"115627.31","new_quantity":"0.0004471"},{"side":"offer","event_time":"2025-10-27T17:39:46.331425Z","price_level":"115647.5","new_quantity":"0"},{"side":"offer","event_time":"2025-10-27T17:39:46.331425Z","price_level":"115647.52","new_quantity":"0.00007732"},{"side":"offer","event_time":"2025-10-27T17:39:46.331425Z","price_level":"115797.89","new_quantity":"0.045"}]}]}
{"channel":"l2_data","client_id":"","timestamp":"2025-10-27T17:39:46.480784809Z","sequence_num":137870,"events":[{"type":"update","product_id":"BTC-USD","updates":[{"side":"bid","event_time":"2025-10-27T17:39:46.135588Z","price_level":"115638.6","new_quantity":"0.20621606"},{"side":"bid","event_time":"2025-10-27T17:39:46.135588Z","price_level":"115638.01","new_quantity":"0.00172953"},{"side":"bid","event_time":"2025-10-27T17:39:46.135588Z","price_level":"115638","new_quantity":"0.0213"},{"side":"bid","event_time":"2025-10-27T17:39:46.135588Z","price_level":"115634.01","new_quantity":"0.26159095"},{"side":"bid","event_time":"2025-10-27T17:39:46.135588Z","price_level":"115630.69","new_quantity":"0.00864822"},{"side":"bid","event_time":"2025-10-27T17:39:46.135588Z","price_level":"115629.01","new_quantity":"0.00044755"},{"side":"bid","event_time":"2025-10-27T17:39:46.135588Z","price_level":"115629","new_quantity":"0.4"},{"side":"bid","event_time":"2025-10-27T17:39:46.135588Z","price_level":"115628.81","new_quantity":"0"},{"side":"bid","event_time":"2025-10-27T17:39:46.135588Z","price_level":"115628.8","new_quantity":"0.08648363"},{"side":"bid","event_time":"2025-10-27T17:39:46.135588Z","price_level":"115627.63","new_quantity":"0.02161192"},{"side":"bid","event_time":"2025-10-27T17:39:46.135588Z","price_level":"115626.33","new_quantity":"0"},{"side":"bid","event_time":"2025-10-27T17:39:46.135588Z","price_level":"115625.17","new_quantity":"0.16549"},{"side":"bid","event_time":"2025-10-27T17:39:46.135588Z","price_level":"115623.83","new_quantity":"0"},{"side":"bid","event_time":"2025-10-27T17:39:46.135588Z","price_level":"115623.63","new_quantity":"0.00432"},{"side":"bid","event_time":"2025-10-27T17:39:46.135588Z","price_level":"115623.6","new_quantity":"0.00432"},{"side":"bid","event_time":"2025-10-27T17:39:46.135588Z","price_level":"115621.31","new_quantity":"0"},{"side":"bid","event_time":"2025-10-27T17:39:46.135588Z","price_level":"115621.28","new_quantity":"0.00432"},{"side":"bid","event_time":"2025-10-27T17:39:46.135588Z","price_level":"115620.65","new_quantity":"0.2705992"},{"side":"bid","event_time":"2025-10-27T17:39:46.135588Z","price_level":"115618.99","new_quantity":"0"},{"side":"bid","event_time":"2025-10-27T17:39:46.135588Z","price_level":"115618.96","new_quantity":"0"},{"side":"bid","event_time":"2025-10-27T17:39:46.135588Z","price_level":"115618","new_quantity":"0"},{"side":"bid","event_time":"2025-10-27T17:39:46.135588Z","price_level":"115616.82","new_quantity":"1.46800729"},{"side":"bid","event_time":"2025-10-27T17:39:46.135588Z","price_level":"115616.55","new_quantity":"0"},{"side":"bid","event_time":"2025-10-27T17:39:46.135588Z","price_level":"115616","new_quantity":"2"},{"side":"bid","event_time":"2025-10-27T17:39:46.135588Z","price_level":"115612.62","new_quantity":"0.33125806"},{"side":"bid","event_time":"2025-10-27T17:39:46.135588Z","price_level":"115610.22","new_quantity":"0.0069609"},{"side":"bid","event_time":"2025-10-27T17:39:46.135588Z","price_level":"115610.15","new_quantity":"0"},{"side":"bid","event_time":"2025-10-27T17:39:46.135588Z","price_level":"115610.01","new_quantity":"1.16717334"},{"side":"bid","event_time":"2025-10-27T17:39:46.135588Z","price_level":"115610","new_quantity":"1"},{"side":"bid","event_time":"2025-10-27T17:39:46.135588Z","price_level":"115606.36","new_quantity":"0"},{"side":"bid","event_time":"2025-10-27T17:39:46.135588Z","price_level":"115604.28","new_quantity":"0.37035465"},{"side":"bid","event_time":"2025-10-27T17:39:46.135588Z","price_level":"115603.5","new_quantity":"0"},{"side":"bid","event_time":"2025-10-27T17:39:46.135588Z","price_level":"115596.97","new_quantity":"0"},{"side":"bid","event_time":"2025-10-27T17:39:46.135588Z","price_level":"115569.2","new_quantity":"1.5"},{"side":"bid","event_time":"2025-10-27T17:39:46.135588Z","price_level":"115568.7","new_quantity":"0"},{"side":"bid","event_time":"2025-10-27T17:39:46.135588Z","price_level":"115566","new_quantity":"0.00001"},{"side":"bid","event_time":"2025-10-27T17:39:46.135588Z","price_level":"115177.86","new_quantity":"0.07007"},{"side":"bid","event_time":"2025-10-27T17:39:46.135588Z","price_level":"115177.25","new_quantity":"0"},{"side":"bid","event_time":"2025-10-27T17:39:46.135588Z","price_level":"114962.85","new_quantity":"0.07007"},{"side":"bid","event_time":"2025-10-27T17:39:46.135588Z","price_level":"114962.55","new_quantity":"0"},{"side":"bid","event_time":"2025-10-27T17:39:46.135588Z","price_level":"114962.39","new_quantity":"0"},{"side":"bid","event_time":"2025-10-27T17:39:46.135588Z","price_level":"114530.7","new_quantity":"0"},{"side":"bid","event_time":"2025-10-27T17:39:46.135588Z","price_level":"114526.83","new_quantity":"0"},{"side":"bid","event_time":"2025-10-27T17:39:46.135588Z","price_level":"114311.92","new_quantity":"0"},{"side":"offer","event_time":"2025-10-27T17:39:46.135588Z","price_level":"115639.6","new_quantity":"0"},{"side":"offer","event_time":"2025-10-27T17:39:46.135588Z","price_level":"115643.11","new_quantity":"0"},{"side":"offer","event_time":"2025-10-27T17:39:46.135588Z","price_level":"115643.12","new_quantity":"0"},{"side":"offer","event_time":"2025-10-27T17:39:46.135588Z","price_level":"115645.99","new_quantity":"0.02594123"},{"side":"offer","event_time":"2025-10-27T17:39:46.135588Z","price_level":"115647.51","new_quantity":"0"},{"side":"offer","event_time":"2025-10-27T17:39:46.135588Z","price_level":"115647.52","new_quantity":"0.00007725"},{"side":"offer","event_time":"2025-10-27T17:39:46.135588Z","price_level":"115652.03","new_quantity":"0"},{"side":"offer","event_time":"2025-10-27T17:39:46.135588Z","price_level":"115652.04","new_quantity":"0"},{"side":"offer","event_time":"2025-10-27T17:39:46.135588Z","price_level":"115653.59","new_quantity":"0.25939533"},{"side":"offer","event_time":"2025-10-27T17:39:46.135588Z","price_level":"115656.04","new_quantity":"0"},{"side":"offer","event_time":"2025-10-27T17:39:46.135588Z","price_level":"115656.05","new_quantity":"0"},{"side":"offer","event_time":"2025-10-27T17:39:46.135588Z","price_level":"115660.98","new_quantity":"0.0059811"},{"side":"offer","event_time":"2025-10-27T17:39:46.135588Z","price_level":"115660.99","new_quantity":"0"},{"side":"offer","event_time":"2025-10-27T17:39:46.135588Z","price_level":"115661","new_quantity":"0"},{"side":"offer","event_time":"2025-10-27T17:39:46.135588Z","price_level":"115663","new_quantity":"2.00432"},{"side":"offer","event_time":"2025-10-27T17:39:46.135588Z","price_level":"115663.01","new_quantity":"0.00432"},{"side":"offer","event_time":"2025-10-27T17:39:46.135588Z","price_level":"115665.99","new_quantity":"0.24416882"},{"side":"offer","event_time":"2025-10-27T17:39:46.135588Z","price_level":"115666","new_quantity":"0.4"},{"side":"offer","event_time":"2025-10-27T17:39:46.135588Z","price_level":"115669.99","new_quantity":"0.67617908"},{"side":"offer","event_time":"2025-10-27T17:39:46.135588Z","price_level":"115671","new_quantity":"0.3891252"},{"side":"offer","event_time":"2025-10-27T17:39:46.135588Z","price_level":"115673.75","new_quantity":"0"},{"side":"offer","event_time":"2025-10-27T17:39:46.135588Z","price_level":"115677.9","new_quantity":"0.13835768"},{"side":"offer","event_time":"2025-10-27T17:39:46.135588Z","price_level":"115689.73","new_quantity":"0"},{"side":"offer","event_time":"2025-10-27T17:39:46.135588Z","price_level":"115694.05","new_quantity":"0.16812326"},{"side":"offer","event_time":"2025-10-27T17:39:46.135588Z","price_level":"116105.26","new_quantity":"0"},{"side":"offer","event_time":"2025-10-27T17:39:46.135588Z","price_level":"116536.44","new_quantity":"0.07007"},{"side":"offer","event_time":"2025-10-27T17:39:46.135588Z","price_level":"116537.81","new_quantity":"0"},{"side":"offer","event_time":"2025-10-27T17:39:46.135588Z","price_level":"116753.93","new_quantity":"0.07007"},{"side":"offer","event_time":"2025-10-27T17:39:46.135588Z","price_level":"116960.82","new_quantity":"0"},{"side":"offer","event_time":"2025-10-27T17:39:46.135588Z","price_level":"116968.56","new_quantity":"0.07007"}]}]}
{"channel":"l2_data","client_id":"","timestamp":"2025-10-27T17:39:46.515983846Z","sequence_num":137876,"events":[{"type":"update","product_id":"BTC-USD","updates":[{"side":"bid","event_time":"2025-10-27T17:39:46.449086Z","price_level":"115638.6","new_quantity":"0.15301287"},{"side":"bid","event_time":"2025-10-27T17:39:46.449086Z","price_level":"115617","new_quantity":"0"},{"side":"bid","event_time":"2025-10-27T17:39:46.449086Z","price_level":"115616.82","new_quantity":"0.58950812"},{"side":"bid","event_time":"2025-10-27T17:39:46.449086Z","price_level":"115616.07","new_quantity":"0"},{"side":"bid","event_time":"2025-10-27T17:39:46.449086Z","price_level":"115614","new_quantity":"0"},{"side":"bid","event_time":"2025-10-27T17:39:46.449086Z","price_level":"115613","new_quantity":"2.4"},{"side":"bid","event_time":"2025-10-27T17:39:46.449086Z","price_level":"115604.09","new_quantity":"0"},{"side":"offer","event_time":"2025-10-27T17:39:46.449086Z","price_level":"115671","new_quantity":"0"},{"side":"offer","event_time":"2025-10-27T17:39:46.449086Z","price_level":"115677.89","new_quantity":"0.38911186"},{"side":"offer","event_time":"2025-10-27T17:39:46.449086Z","price_level":"115705.51","new_quantity":"0.06331591"},{"side":"offer","event_time":"2025-10-27T17:39:46.449086Z","price_level":"115718.4","new_quantity":"1"},{"side":"offer","event_time":"2025-10-27T17:39:46.449086Z","price_level":"115718.5","new_quantity":"0"},{"side":"offer","event_time":"2025-10-27T17:39:46.449086Z","price_level":"116376.13","new_quantity":"0"}]}]}
{"channel":"l2_data","client_id":"","timestamp":"2025-10-27T17:39:46.671373562Z","sequence_num":137883,"events":[{"type":"update","product_id":"ETH-USD","updates":[{"side":"bid","event_time":"2025-10-27T17:39:46.631268Z","price_level":"4218.26","new_quantity":"2.096449"},{"side":"bid","event_time":"2025-10-27T17:39:46.631268Z","price_level":"4218.21","new_quantity":"0.07109662"},{"side":"bid","event_time":"2025-10-27T17:39:46.631268Z","price_level":"4217.73","new_quantity":"0"},{"side":"bid","event_time":"2025-10-27T17:39:46.631268Z","price_level":"4217.33","new_quantity":"1.65817"},{"side":"bid","event_time":"2025-10-27T17:39:46.631268Z","price_level":"4217.28","new_quantity":"6.51500894"},{"side":"bid","event_time":"2025-10-27T17:39:46.631268Z","price_level":"4217.25","new_quantity":"0.001"},{"side":"bid","event_time":"2025-10-27T17:39:46.631268Z","price_level":"4217.22","new_quantity":"1.53333014"},{"side":"bid","event_time":"2025-10-27T17:39:46.631268Z","price_level":"4217.13","new_quantity":"1.65817"},{"side":"offer","event_time":"2025-10-27T17:39:46.631268Z","price_level":"4218.28","new_quantity":"0.18965075"},{"side":"offer","event_time":"2025-10-27T17:39:46.631268Z","price_level":"4218.29","new_quantity":"1.19232384"},{"side":"offer","event_time":"2025-10-27T17:39:46.631268Z","price_level":"4218.48","new_quantity":"0"},{"side":"offer","event_time":"2025-10-27T17:39:46.631268Z","price_level":"4220.44","new_quantity":"8.22574635"},{"side":"offer","event_time":"2025-10-27T17:39:46.631268Z","price_level":"4220.48","new_quantity":"0.00764642"},{"side":"offer","event_time":"2025-10-27T17:39:46.631268Z","price_level":"4221.47","new_quantity":"1.94391607"},{"side":"offer","event_time":"2025-10-27T17:39:46.631268Z","price_level":"4221.48","new_quantity":"13.30182976"},{"side":"offer","event_time":"2025-10-27T17:39:46.631268Z","price_level":"4221.49","new_quantity":"0"},{"side":"offer","event_time":"2025-10-27T17:39:46.631268Z","price_level":"4221.5","new_quantity":"0.001"},{"side":"offer","event_time":"2025-10-27T17:39:46.631268Z","price_level":"4223.73","new_quantity":"0.1536"}]}]}
{"channel":"l2_data","client_id":"","timestamp":"2025-10-27T17:39:46.698106449Z","sequence_num":137884,"events":[{"type":"update","product_id":"BTC-USD","updates":[{"side":"bid","event_time":"2025-10-27T17:39:46.63282Z","price_level":"115638.01","new_quantity":"0.00172953"},{"side":"bid","event_time":"2025-10-27T17:39:46.63282Z","price_level":"115627.31","new_quantity":"0.00059027"},{"side":"bid","event_time":"2025-10-27T17:39:46.63282Z","price_level":"115616","new_quantity":"0.4"},{"side":"bid","event_time":"2025-10-27T17:39:46.63282Z","price_level":"115615","new_quantity":"0"},{"side":"bid","event_time":"2025-10-27T17:39:46.63282Z","price_level":"115614","new_quantity":"0.4"},{"side":"bid","event_time":"2025-10-27T17:39:46.63282Z","price_level":"115613","new_quantity":"2"},{"side":"bid","event_time":"2025-10-27T17:39:46.63282Z","price_level":"115572.6","new_quantity":"1.5"},{"side":"bid","event_time":"2025-10-27T17:39:46.63282Z","price_level":"115566","new_quantity":"0.00001"},{"side":"offer","event_time":"2025-10-27T17:39:46.63282Z","price_level":"115647.5","new_quantity":"0.00007732"},{"side":"offer","event_time":"2025-10-27T17:39:46.63282Z","price_level":"115647.52","new_quantity":"0"},{"side":"offer","event_time":"2025-10-27T17:39:46.63282Z","price_level":"115651.82","new_quantity":"0"},{"side":"offer","event_time":"2025-10-27T17:39:46.63282Z","price_level":"115671","new_quantity":"0.1383553"},{"side":"offer","event_time":"2025-10-27T17:39:46.63282Z","price_level":"115673.75","new_quantity":"0"},{"side":"offer","event_time":"2025-10-27T17:39:46.63282Z","price_level":"115718.4","new_quantity":"0"},{"side":"offer","event_time":"2025-10-27T17:39:46.63282Z","price_level":"115718.6","new_quantity":"1"}]}]}
{"channel":"l2_data","client_id":"","timestamp":"2025-10-27T17:39:46.718916112Z","sequence_num":137885,"events":[{"type":"update","product_id":"ETH-USD","updates":[{"side":"bid","event_time":"2025-10-27T17:39:46.652742Z","price_level":"4217.75","new_quantity":"1.65782"},{"side":"bid","event_time":"2025-10-27T17:39:46.652742Z","price_level":"4216.61","new_quantity":"0.6"}]}]}
{"channel":"l2_data","client_id":"","timestamp":"2025-10-27T17:39:46.746871597Z","sequence_num":137886,"events":[{"type":"update","product_id":"BTC-USD","updates":[{"side":"bid","event_time":"2025-10-27T17:39:46.684666Z","price_level":"115613.01","new_quantity":"0"},{"side":"bid","event_time":"2025-10-27T17:39:46.684666Z","price_level":"115610.02","new_quantity":"0.33126551"},{"side":"bid","event_time":"2025-10-27T17:39:46.684666Z","price_level":"115580.02","new_quantity":"0"},{"side":"bid","event_time":"2025-10-27T17:39:46.684666Z","price_level":"115572.61","new_quantity":"0.76391169"},{"side":"offer","event_time":"2025-10-27T17:39:46.684666Z","price_level":"115647.5","new_quantity":"0"},{"side":"offer","event_time":"2025-10-27T17:39:46.684666Z","price_level":"115647.51","new_quantity":"0.00187837"},{"side":"offer","event_time":"2025-10-27T17:39:46.684666Z","price_level":"115647.52","new_quantity":"0.00007732"},{"side":"offer","event_time":"2025-10-27T17:39:46.684666Z","price_level":"115660.69","new_quantity":"0.00432"},{"side":"offer","event_time":"2025-10-27T17:39:46.684666Z","price_level":"115669.98","new_quantity":"0.38911545"},{"side":"offer","event_time":"2025-10-27T17:39:46.684666Z","price_level":"115677.89","new_quantity":"0"}]}]}
{"channel":"l2_data","client_id":"","timestamp":"2025-10-27T17:39:46.769185198Z","sequence_num":137887,"events":[{"type":"update","product_id":"ETH-USD","updates":[{"side":"bid","event_time":"2025-10-27T17:39:46.724436Z","price_level":"4217.83","new_quantity":"0.002"},{"side":"bid","event_time":"2025-10-27T17:39:46.724436Z","price_level":"4217.22","new_quantity":"0.62305959"},{"side":"bid","event_time":"2025-10-27T17:39:46.724436Z","price_level":"4217.13","new_quantity":"0"},{"side":"bid","event_time":"2025-10-27T17:39:46.724436Z","price_level":"4216.35","new_quantity":"2.37084065"}]}]}
{"channel":"l2_data","client_id":"","timestamp":"2025-10-27T17:39:46.798210693Z","sequence_num":137888,"events":[{"type":"update","product_id":"BTC-USD","updates":[{"side":"bid","event_time":"2025-10-27T17:39:46.736591Z","price_level":"115616.82","new_quantity":"0.58950812"},{"side":"bid","event_time":"2025-10-27T17:39:46.736591Z","price_level":"115616.07","new_quantity":"0.06623861"},{"side":"bid","event_time":"2025-10-27T17:39:46.736591Z","price_level":"115613","new_quantity":"0"},{"side":"bid","event_time":"2025-10-27T17:39:46.736591Z","price_level":"115596.99","new_quantity":"1.15287519"},{"side":"bid","event_time":"2025-10-27T17:39:46.736591Z","price_level":"115552.34","new_quantity":"1.16521473"},{"side":"bid","event_time":"2025-10-27T17:39:46.736591Z","price_level":"115552.32","new_quantity":"0"},{"side":"bid","event_time":"2025-10-27T17:39:46.736591Z","price_level":"115507.01","new_quantity":"0.49331447"},{"side":"bid","event_time":"2025-10-27T17:39:46.736591Z","price_level":"101183.78","new_quantity":"0"},{"side":"offer","event_time":"2025-10-27T17:39:46.736591Z","price_level":"115640.35","new_quantity":"0.0259425"},{"side":"offer","event_time":"2025-10-27T17:39:46.736591Z","price_level":"115641.81","new_quantity":"0"},{"side":"offer","event_time":"2025-10-27T17:39:46.736591Z","price_level":"115647.5","new_quantity":"0.00007732"},{"side":"offer","event_time":"2025-10-27T17:39:46.736591Z","price_level":"115647.52","new_quantity":"0"},{"side":"offer","event_time":"2025-10-27T17:39:46.736591Z","price_level":"115689.73","new_quantity":"0"},{"side":"offer","event_time":"2025-10-27T17:39:46.736591Z","price_level":"115689.99","new_quantity":"1.73098871"},{"side":"offer","event_time":"2025-10-27T17:39:46.736591Z","price_level":"115694.05","new_quantity":"0.16812326"},{"side":"offer","event_time":"2025-10-27T17:39:46.736591Z","price_level":"115705.51","new_quantity":"0.06341333"},{"side":"offer","event_time":"2025-10-27T17:39:46.736591Z","price_level":"115706.38","new_quantity":"0"},{"side":"offer","event_time":"2025-10-27T17:39:46.736591Z","price_level":"115709.99","new_quantity":"0.25574104"}]}]}
{"channel":"l2_data","client_id":"","timestamp":"2025-10-27T17:39:46.921135712Z","sequence_num":137894,"events":[{"type":"update","product_id":"ETH-USD","updates":[{"side":"bid","event_time":"2025-10-27T17:39:46.861615Z","price_level":"4218.26","new_quantity":"1.575339"},{"side":"offer","event_time":"2025-10-27T17:39:46.861615Z","price_level":"4218.8","new_quantity":"0.0131133"},{"side":"offer","event_time":"2025-10-27T17:39:46.861615Z","price_level":"4221.43","new_quantity":"1.94391607"},{"side":"offer","event_time":"2025-10-27T17:39:46.861615Z","price_level":"4221.44","new_quantity":"13.3019558"},{"side":"offer","event_time":"2025-10-27T17:39:46.861615Z","price_level":"4221.45","new_quantity":"0"},{"side":"offer","event_time":"2025-10-27T17:39:46.861615Z","price_level":"4221.46","new_quantity":"0"}]}]}
{"channel":"l2_data","client_id":"","timestamp":"2025-10-27T17:39:46.94813266Z","sequence_num":137895,"events":[{"type":"update","product_id":"BTC-USD","updates":[{"side":"bid","event_time":"2025-10-27T17:39:46.896974Z","price_level":"115638.6","new_quantity":"0.09418713"},{"side":"bid","event_time":"2025-10-27T17:39:46.896974Z","price_level":"115623.83","new_quantity":"0.00067895"},{"side":"bid","event_time":"2025-10-27T17:39:46.896974Z","price_level":"115610.01","new_quantity":"1.07345717"},{"side":"bid","event_time":"2025-10-27T17:39:46.896974Z","price_level":"115608.67","new_quantity":"0"},{"side":"bid","event_time":"2025-10-27T17:39:46.896974Z","price_level":"115606.36","new_quantity":"0.731468"},{"side":"bid","event_time":"2025-10-27T17:39:46.896974Z","price_level":"115604.1","new_quantity":"0.0069609"},{"side":"bid","event_time":"2025-10-27T17:39:46.896974Z","price_level":"115573.1","new_quantity":"0"},{"side":"bid","event_time":"2025-10-27T17:39:46.896974Z","price_level":"115572.6","new_quantity":"1.5"},{"side":"offer","event_time":"2025-10-27T17:39:46.896974Z","price_level":"115659.56","new_quantity":"0"},{"side":"offer","event_time":"2025-10-27T17:39:46.896974Z","price_level":"115662","new_quantity":"0"},{"side":"offer","event_time":"2025-10-27T17:39:46.896974Z","price_level":"115666","new_quantity":"0"},{"side":"offer","event_time":"2025-10-27T17:39:46.896974Z","price_level":"115705.5","new_quantity":"0.06949097"}]}]}
{"channel":"l2_data","client_id":"","timestamp":"2025-10-27T17:39:46.994535524Z","sequence_num":137896,"events":[{"type":"update","product_id":"BTC-USD","updates":[{"side":"offer","event_time":"2025-10-27T17:39:46.94979Z","price_level":"115661.57","new_quantity":"0.00360262"},{"side":"offer","event_time":"2025-10-27T17:39:46.94979Z","price_level":"115666","new_quantity":"0"}]}]}
{"channel":"l2_data","client_id":"","timestamp":"2025-10-27T17:39:47.022026484Z","sequence_num":137897,"events":[{"type":"update","product_id":"ETH-USD","updates":[{"side":"bid","event_time":"2025-10-27T17:39:46.980642Z","price_level":"4218.16","new_quantity":"0"},{"side":"bid","event_time":"2025-10-27T17:39:46.980642Z","price_level":"4217.55","new_quantity":"1.65817"},{"side":"bid","event_time":"2025-10-27T17:39:46.980642Z","price_level":"4217.35","new_quantity":"0.62075391"},{"side":"offer","event_time":"2025-10-27T17:39:46.980642Z","price_level":"4218.27","new_quantity":"0.48303462"},{"side":"offer","event_time":"2025-10-27T17:39:46.980642Z","price_level":"4218.29","new_quantity":"1.16413907"}]}]}
{"channel":"l2_data","client_id":"","timestamp":"2025-10-27T17:39:47.043929262Z","sequence_num":137898,"events":[{"type":"update","product_id":"BTC-USD","updates":[{"side":"offer","event_time":"2025-10-27T17:39:47.00302Z","price_level":"115661.57","new_quantity":"0"},{"side":"offer","event_time":"2025-10-27T17:39:47.00302Z","price_level":"115665","new_quantity":"0"}]}]}
{"channel":"l2_data","client_id":"","timestamp":"2025-10-27T17:39:47.069105922Z","sequence_num":137899,"events":[{"type":"update","product_id":"ETH-USD","updates":[{"side":"bid","event_time":"2025-10-27T17:39:47.027124Z","price_level":"4218.22","new_quantity":"0.07109662"},{"side":"bid","event_time":"2025-10-27T17:39:47.027124Z","price_level":"4170.3","new_quantity":"0"}]}]}
{"channel":"l2_data","client_id":"","timestamp":"2025-10-27T17:39:47.094915586Z","sequence_num":137901,"events":[{"type":"update","product_id":"BTC-USD","updates":[{"side":"bid","event_time":"2025-10-27T17:39:47.039932Z","price_level":"113820.53","new_quantity":"0"}]}]}
{"channel":"l2_data","client_id":"","timestamp":"2025-10-27T17:39:47.120044672Z","sequence_num":137903,"events":[{"type":"update","product_id":"ETH-USD","updates":[{"side":"bid","event_time":"2025-10-27T17:39:47.0373Z","price_level":"4217.82","new_quantity":"0"},{"side":"bid","event_time":"2025-10-27T17:39:47.0373Z","price_level":"4217.33","new_quantity":"0"},{"side":"bid","event_time":"2025-10-27T17:39:47.0373Z","price_level":"4150.24","new_quantity":"0"},{"side":"bid","event_time":"2025-10-27T17:39:47.0373Z","price_level":"4130.19","new_quantity":"0"}]}]}
{"channel":"l2_data","client_id":"","timestamp":"2025-10-27T17:39:47.146740916Z","sequence_num":137905,"events":[{"type":"update","product_id":"BTC-USD","updates":[{"side":"bid","event_time":"2025-10-27T17:39:47.091853Z","price_level":"115604.1","new_quantity":"0"},{"side":"bid","event_time":"2025-10-27T17:39:47.091853Z","price_level":"114315.75","new_quantity":"0.07007"},{"side":"bid","event_time":"2025-10-27T17:39:47.091853Z","price_level":"114315.46","new_quantity":"0.07007"},{"side":"bid","event_time":"2025-10-27T17:39:47.091853Z","price_level":"114314.92","new_quantity":"0"},{"side":"bid","event_time":"2025-10-27T17:39:47.091853Z","price_level":"113268.87","new_quantity":"0"},{"side":"offer","event_time":"2025-10-27T17:39:47.091853Z","price_level":"115647.51","new_quantity":"0.00007649"},{"side":"offer","event_time":"2025-10-27T17:39:47.091853Z","price_level":"115647.52","new_quantity":"0.30977416"},{"side":"offer","event_time":"2025-10-27T17:39:47.091853Z","price_level":"115651.82","new_quantity":"0"},{"side":"offer","event_time":"2025-10-27T17:39:47.091853Z","price_level":"115656.33","new_quantity":"0.09837366"},{"side":"offer","event_time":"2025-10-27T17:39:47.091853Z","price_level":"115661.57","new_quantity":"0"},{"side":"offer","event_time":"2025-10-27T17:39:47.091853Z","price_level":"115662.99","new_quantity":"1.194"},{"side":"offer","event_time":"2025-10-27T17:39:47.091853Z","price_level":"116535.09","new_quantity":"0.07007"}]}]}
{"channel":"l2_data","client_id":"","timestamp":"2025-10-27T17:39:47.198091179Z","sequence_num":137906,"events":[{"type":"update","product_id":"BTC-USD","updates":[{"side":"bid","event_time":"2025-10-27T17:39:47.133877Z","price_level":"115631.18","new_quantity":"0"},{"side":"bid","event_time":"2025-10-27T17:39:47.133877Z","price_level":"115623.83","new_quantity":"0"},{"side":"bid","event_time":"2025-10-27T17:39:47.133877Z","price_level":"115603.49","new_quantity":"0"},{"side":"bid","event_time":"2025-10-27T17:39:47.133877Z","price_level":"115568.81","new_quantity":"0"},{"side":"bid","event_time":"2025-10-27T17:39:47.133877Z","price_level":"114315.46","new_quantity":"0"},{"side":"bid","event_time":"2025-10-27T17:39:47.133877Z","price_level":"114101","new_quantity":"0.07017"},{"side":"bid","event_time":"2025-10-27T17:39:47.133877Z","price_level":"114100.95","new_quantity":"0"},{"side":"offer","event_time":"2025-10-27T17:39:47.133877Z","price_level":"115665.99","new_quantity":"0.24416882"},{"side":"offer","event_time":"2025-10-27T17:39:47.133877Z","price_level":"115666","new_quantity":"0.4"},{"side":"offer","event_time":"2025-10-27T17:39:47.133877Z","price_level":"116318.69","new_quantity":"0.07007"},{"side":"offer","event_time":"2025-10-27T17:39:47.133877Z","price_level":"116318.87","new_quantity":"0.07007"},{"side":"offer","event_time":"2025-10-27T17:39:47.133877Z","price_level":"116319.3","new_quantity":"0.07007"},{"side":"offer","event_time":"2025-10-27T17:39:47.133877Z","price_level":"116319.57","new_quantity":"0.07007"},{"side":"offer","event_time":"2025-10-27T17:39:47.133877Z","price_level":"116319.73","new_quantity":"0"},{"side":"offer","event_time":"2025-10-27T17:39:47.133877Z","price_level":"116535.09","new_quantity":"0"},{"side":"offer","event_time":"2025-10-27T17:39:47.133877Z","price_level":"116536.44","new_quantity":"0"},{"side":"offer","event_time":"2025-10-27T17:39:47.133877Z","price_level":"116747.43","new_quantity":"0.07007"},{"side":"offer","event_time":"2025-10-27T17:39:47.133877Z","price_level":"116747.73","new_quantity":"0.07007"},{"side":"offer","event_time":"2025-10-27T17:39:47.133877Z","price_level":"116752.16","new_quantity":"0"}]}]}
{"channel":"l2_data","client_id":"","timestamp":"2025-10-27T17:39:47.246737995Z","sequence_num":137907,"events":[{"type":"update","product_id":"BTC-USD","updates":[{"side":"bid","event_time":"2025-10-27T17:39:47.185279Z","price_level":"115634.02","new_quantity":"0.00172959"},{"side":"bid","event_time":"2025-10-27T17:39:47.185279Z","price_level":"115634.01","new_quantity":"0.02537502"},{"side":"bid","event_time":"2025-10-27T17:39:47.185279Z","price_level":"115612","new_quantity":"2.0069609"},{"side":"bid","event_time":"2025-10-27T17:39:47.185279Z","price_level":"115573.11","new_quantity":"0"},{"side":"bid","event_time":"2025-10-27T17:39:47.185279Z","price_level":"115572.6","new_quantity":"0"},{"side":"bid","event_time":"2025-10-27T17:39:47.185279Z","price_level":"115567.27","new_quantity":"0.76394699"},{"side":"bid","event_time":"2025-10-27T17:39:47.185279Z","price_level":"115566","new_quantity":"1.50001"},{"side":"offer","event_time":"2025-10-27T17:39:47.185279Z","price_level":"115658.36","new_quantity":"0.00432"},{"side":"offer","event_time":"2025-10-27T17:39:47.185279Z","price_level":"115665.99","new_quantity":"0"},{"side":"offer","event_time":"2025-10-27T17:39:47.185279Z","price_level":"115666","new_quantity":"0"},{"side":"offer","event_time":"2025-10-27T17:39:47.185279Z","price_level":"115689.99","new_quantity":"0"},{"side":"offer","event_time":"2025-10-27T17:39:47.185279Z","price_level":"115718.1","new_quantity":"1"},{"side":"offer","event_time":"2025-10-27T17:39:47.185279Z","price_level":"115718.6","new_quantity":"0"},{"side":"offer","event_time":"2025-10-27T17:39:47.185279Z","price_level":"116318.49","new_quantity":"0.02997"},{"side":"offer","event_time":"2025-10-27T17:39:47.185279Z","price_level":"116318.69","new_quantity":"0"},{"side":"offer","event_time":"2025-10-27T17:39:47.185279Z","price_level":"116318.87","new_quantity":"0"},{"side":"offer","event_time":"2025-10-27T17:39:47.185279Z","price_level":"116319.3","new_quantity":"0"},{"side":"offer","event_time":"2025-10-27T17:39:47.185279Z","price_level":"116319.57","new_quantity":"0"},{"side":"offer","event_time":"2025-10-27T17:39:47.185279Z","price_level":"116534.75","new_quantity":"0.08723226"},{"side":"offer","event_time":"2025-10-27T17:39:47.185279Z","price_level":"116747.43","new_quantity":"0"},{"side":"offer","event_time":"2025-10-27T17:39:47.185279Z","price_level":"116747.73","new_quantity":"0"},{"side":"offer","event_time":"2025-10-27T17:39:47.185279Z","price_level":"116749.23","new_quantity":"0.07007"}]}]}
{"channel":"l2_data","client_id":"","timestamp":"2025-10-27T17:39:47.297166774Z","sequence_num":137908,"events":[{"type":"update","product_id":"BTC-USD","updates":[{"side":"bid","event_time":"2025-10-27T17:39:47.239577Z","price_level":"115612","new_quantity":"2"},{"side":"bid","event_time":"2025-10-27T17:39:47.239577Z","price_level":"115607.34","new_quantity":"0.0069609"},{"side":"bid","event_time":"2025-10-27T17:39:47.239577Z","price_level":"115567.7","new_quantity":"1.5"},{"side":"bid","event_time":"2025-10-27T17:39:47.239577Z","price_level":"115566","new_quantity":"0.00001"},{"side":"offer","event_time":"2025-10-27T17:39:47.239577Z","price_level":"115718.1","new_quantity":"0"},{"side":"offer","event_time":"2025-10-27T17:39:47.239577Z","price_level":"115718.2","new_quantity":"1"}]}]}
{"channel":"l2_data","client_id":"","timestamp":"2025-10-27T17:39:47.323841587Z","sequence_num":137909,"events":[{"type":"update","product_id":"ETH-USD","updates":[{"side":"bid","event_time":"2025-10-27T17:39:47.28281Z","price_level":"4218.26","new_quantity":"0"},{"side":"bid","event_time":"2025-10-27T17:39:47.28281Z","price_level":"4218.24","new_quantity":"0"},{"side":"bid","event_time":"2025-10-27T17:39:47.28281Z","price_level":"4218.22","new_quantity":"0"},{"side":"bid","event_time":"2025-10-27T17:39:47.28281Z","price_level":"4218.13","new_quantity":"0.07109573"},{"side":"bid","event_time":"2025-10-27T17:39:47.28281Z","price_level":"4218.09","new_quantity":"0.00237075"},{"side":"bid","event_time":"2025-10-27T17:39:47.28281Z","price_level":"4218.08","new_quantity":"0.22439"},{"side":"bid","event_time":"2025-10-27T17:39:47.28281Z","price_level":"4217.83","new_quantity":"0.002"},{"side":"bid","event_time":"2025-10-27T17:39:47.28281Z","price_level":"4217.82","new_quantity":"0.02070633"},{"side":"bid","event_time":"2025-10-27T17:39:47.28281Z","price_level":"4217.81","new_quantity":"0"},{"side":"bid","event_time":"2025-10-27T17:39:47.28281Z","price_level":"4217.8","new_quantity":"10"},{"side":"bid","event_time":"2025-10-27T17:39:47.28281Z","price_level":"4217.75","new_quantity":"0.001"},{"side":"bid","event_time":"2025-10-27T17:39:47.28281Z","price_level":"4217.73","new_quantity":"0.436"},{"side":"bid","event_time":"2025-10-27T17:39:47.28281Z","price_level":"4217.7","new_quantity":"0"},{"side":"bid","event_time":"2025-10-27T17:39:47.28281Z","price_level":"4217.67","new_quantity":"1.125"},{"side":"bid","event_time":"2025-10-27T17:39:47.28281Z","price_level":"4217.6","new_quantity":"33.790973"},{"side":"bid","event_time":"2025-10-27T17:39:47.28281Z","price_level":"4217.58","new_quantity":"0"},{"side":"bid","event_time":"2025-10-27T17:39:47.28281Z","price_level":"4217.55","new_quantity":"0"},{"side":"bid","event_time":"2025-10-27T17:39:47.28281Z","price_level":"4217.52","new_quantity":"1.65853"},{"side":"bid","event_time":"2025-10-27T17:39:47.28281Z","price_level":"4217.41","new_quantity":"15.67040822"},{"side":"bid","event_time":"2025-10-27T17:39:47.28281Z","price_level":"4217.4","new_quantity":"20"},{"side":"bid","event_time":"2025-10-27T17:39:47.28281Z","price_level":"4217.39","new_quantity":"3.31535"},{"side":"bid","event_time":"2025-10-27T17:39:47.28281Z","price_level":"4217.35","new_quantity":"0.06698569"},{"side":"bid","event_time":"2025-10-27T17:39:47.28281Z","price_level":"4217.28","new_quantity":"0.59279786"},{"side":"bid","event_time":"2025-10-27T17:39:47.28281Z","price_level":"4217.22","new_quantity":"4.07913034"},{"side":"bid","event_time":"2025-10-27T17:39:47.28281Z","price_level":"4217.08","new_quantity":"5.92249195"},{"side":"bid","event_time":"2025-10-27T17:39:47.28281Z","price_level":"4217.07","new_quantity":"0.2677885"},{"side":"bid","event_time":"2025-10-27T17:39:47.28281Z","price_level":"4216.99","new_quantity":"0"},{"side":"bid","event_time":"2025-10-27T17:39:47.28281Z","price_level":"4216.88","new_quantity":"0.21565049"},{"side":"bid","event_time":"2025-10-27T17:39:47.28281Z","price_level":"4216.75","new_quantity":"0.27703286"},{"side":"bid","event_time":"2025-10-27T17:39:47.28281Z","price_level":"4216.73","new_quantity":"0"},{"side":"bid","event_time":"2025-10-27T17:39:47.28281Z","price_level":"4216.61","new_quantity":"0"},{"side":"bid","event_time":"2025-10-27T17:39:47.28281Z","price_level":"4216.6","new_quantity":"0.00050522"},{"side":"bid","event_time":"2025-10-27T17:39:47.28281Z","price_level":"4216.27","new_quantity":"0.194152"},{"side":"bid","event_time":"2025-10-27T17:39:47.28281Z","price_level":"4216.24","new_quantity":"6.087063"},{"side":"bid","event_time":"2025-10-27T17:39:47.28281Z","price_level":"4215.98","new_quantity":"0"},{"side":"bid","event_time":"2025-10-27T17:39:47.28281Z","price_level":"4215.85","new_quantity":"0"},{"side":"bid","event_time":"2025-10-27T17:39:47.28281Z","price_level":"4215.55","new_quantity":"1.251"},{"side":"bid","event_time":"2025-10-27T17:39:47.28281Z","price_level":"4215.18","new_quantity":"5.93094408"},{"side":"bid","event_time":"2025-10-27T17:39:47.28281Z","price_level":"4215.06","new_quantity":"0"},{"side":"bid","event_time":"2025-10-27T17:39:47.28281Z","price_level":"4215.05","new_quantity":"0"},{"side":"bid","event_time":"2025-10-27T17:39:47.28281Z","price_level":"4214.85","new_quantity":"0.27025067"},{"side":"bid","event_time":"2025-10-27T17:39:47.28281Z","price_level":"4214.51","new_quantity":"8.13105423"},{"side":"bid","event_time":"2025-10-27T17:39:47.28281Z","price_level":"4214.26","new_quantity":"0"},{"side":"bid","event_time":"2025-10-27T17:39:47.28281Z","price_level":"4214.15","new_quantity":"0"},{"side":"bid","event_time":"2025-10-27T17:39:47.28281Z","price_level":"4214.04","new_quantity":"12.86438645"},{"side":"bid","event_time":"2025-10-27T17:39:47.28281Z","price_level":"4214.02","new_quantity":"0"},{"side":"bid","event_time":"2025-10-27T17:39:47.28281Z","price_level":"4213.69","new_quantity":"0.71209565"},{"side":"bid","event_time":"2025-10-27T17:39:47.28281Z","price_level":"4213.68","new_quantity":"0.47464449"},{"side":"bid","event_time":"2025-10-27T17:39:47.28281Z","price_level":"4213.66","new_quantity":"19.75262196"},{"side":"bid","event_time":"2025-10-27T17:39:47.28281Z","price_level":"4213.07","new_quantity":"0"},{"side":"bid","event_time":"2025-10-27T17:39:47.28281Z","price_level":"4211.4","new_quantity":"0.00477925"},{"side":"bid","event_time":"2025-10-27T17:39:47.28281Z","price_level":"4210.94","new_quantity":"0.83116833"},{"side":"bid","event_time":"2025-10-27T17:39:47.28281Z","price_level":"4191.59","new_quantity":"0.1536"},{"side":"offer","event_time":"2025-10-27T17:39:47.28281Z","price_level":"4218.14","new_quantity":"0"},{"side":"offer","event_time":"2025-10-27T17:39:47.28281Z","price_level":"4218.18","new_quantity":"0.19610572"},{"side":"offer","event_time":"2025-10-27T17:39:47.28281Z","price_level":"4218.19","new_quantity":"0.08051798"},{"side":"offer","event_time":"2025-10-27T17:39:47.28281Z","price_level":"4218.2","new_quantity":"0.572"},{"side":"offer","event_time":"2025-10-27T17:39:47.28281Z","price_level":"4218.24","new_quantity":"1.25644816"},{"side":"offer","event_time":"2025-10-27T17:39:47.28281Z","price_level":"4218.26","new_quantity":"0.07111937"},{"side":"offer","event_time":"2025-10-27T17:39:47.28281Z","price_level":"4218.27","new_quantity":"0.01913297"},{"side":"offer","event_time":"2025-10-27T17:39:47.28281Z","price_level":"4218.28","new_quantity":"0"},{"side":"offer","event_time":"2025-10-27T17:39:47.28281Z","price_level":"4218.29","new_quantity":"1.62727101"},{"side":"offer","event_time":"2025-10-27T17:39:47.28281Z","price_level":"4218.39","new_quantity":"0"},{"side":"offer","event_time":"2025-10-27T17:39:47.28281Z","price_level":"4218.44","new_quantity":"0.53737578"},{"side":"offer","event_time":"2025-10-27T17:39:47.28281Z","price_level":"4218.45","new_quantity":"0.5588066"},{"side":"offer","event_time":"2025-10-27T17:39:47.28281Z","price_level":"4218.46","new_quantity":"0"},{"side":"offer","event_time":"2025-10-27T17:39:47.28281Z","price_level":"4218.47","new_quantity":"0"},{"side":"offer","event_time":"2025-10-27T17:39:47.28281Z","price_level":"4218.49","new_quantity":"0.84752126"},{"side":"offer","event_time":"2025-10-27T17:39:47.28281Z","price_level":"4218.54","new_quantity":"0"},{"side":"offer","event_time":"2025-10-27T17:39:47.28281Z","price_level":"4218.68","new_quantity":"0.01508562"},{"side":"offer","event_time":"2025-10-27T17:39:47.28281Z","price_level":"4218.69","new_quantity":"0.78875792"},{"side":"offer","event_time":"2025-10-27T17:39:47.28281Z","price_level":"4218.75","new_quantity":"0.00298887"},{"side":"offer","event_time":"2025-10-27T17:39:47.28281Z","price_level":"4218.8","new_quantity":"0"},{"side":"offer","event_time":"2025-10-27T17:39:47.28281Z","price_level":"4218.81","new_quantity":"0.194152"},{"side":"offer","event_time":"2025-10-27T17:39:47.28281Z","price_level":"4218.82","new_quantity":"0"},{"side":"offer","event_time":"2025-10-27T17:39:47.28281Z","price_level":"4218.9","new_quantity":"3.08433001"},{"side":"offer","event_time":"2025-10-27T17:39:47.28281Z","price_level":"4219.09","new_quantity":"3.04588"},{"side":"offer","event_time":"2025-10-27T17:39:47.28281Z","price_level":"4219.11","new_quantity":"1.01764274"},{"side":"offer","event_time":"2025-10-27T17:39:47.28281Z","price_level":"4219.26","new_quantity":"0"},{"side":"offer","event_time":"2025-10-27T17:39:47.28281Z","price_level":"4219.33","new_quantity":"0.84955428"},{"side":"offer","event_time":"2025-10-27T17:39:47.28281Z","price_level":"4219.45","new_quantity":"0"},{"side":"offer","event_time":"2025-10-27T17:39:47.28281Z","price_level":"4219.46","new_quantity":"0"},{"side":"offer","event_time":"2025-10-27T17:39:47.28281Z","price_level":"4219.48","new_quantity":"3.941153"},{"side":"offer","event_time":"2025-10-27T17:39:47.28281Z","price_level":"4219.8","new_quantity":"30"},{"side":"offer","event_time":"2025-10-27T17:39:47.28281Z","price_level":"4220.16","new_quantity":"4.56080868"},{"side":"offer","event_time":"2025-10-27T17:39:47.28281Z","price_level":"4220.35","new_quantity":"8.12626162"},{"side":"offer","event_time":"2025-10-27T17:39:47.28281Z","price_level":"4220.4","new_quantity":"0.13679195"},{"side":"offer","event_time":"2025-10-27T17:39:47.28281Z","price_level":"4220.44","new_quantity":"0.09965802"},{"side":"offer","event_time":"2025-10-27T17:39:47.28281Z","price_level":"4220.99","new_quantity":"0"},{"side":"offer","event_time":"2025-10-27T17:39:47.28281Z","price_level":"4221.1","new_quantity":"1.94391607"},{"side":"offer","event_time":"2025-10-27T17:39:47.28281Z","price_level":"4221.29","new_quantity":"0.14427361"},{"side":"offer","event_time":"2025-10-27T17:39:47.28281Z","price_level":"4221.4","new_quantity":"13.30208185"},{"side":"offer","event_time":"2025-10-27T17:39:47.28281Z","price_level":"4221.43","new_quantity":"0"},{"side":"offer","event_time":"2025-10-27T17:39:47.28281Z","price_level":"4221.44","new_quantity":"0"},{"side":"offer","event_time":"2025-10-27T17:39:47.28281Z","price_level":"4221.62","new_quantity":"3.456964"},{"side":"offer","event_time":"2025-10-27T17:39:47.28281Z","price_level":"4221.81","new_quantity":"0"},{"side":"offer","event_time":"2025-10-27T17:39:47.28281Z","price_level":"4222.43","new_quantity":"0"},{"side":"offer","event_time":"2025-10-27T17:39:47.28281Z","price_level":"4222.59","new_quantity":"9.20519752"},{"side":"offer","event_time":"2025-10-27T17:39:47.28281Z","price_level":"4222.86","new_quantity":"0"},{"side":"offer","event_time":"2025-10-27T17:39:47.28281Z","price_level":"4223.69","new_quantity":"1.2786"},{"side":"offer","event_time":"2025-10-27T17:39:47.28281Z","price_level":"4223.73","new_quantity":"0"}]}]}
{"channel":"l2_data","client_id":"","timestamp":"2025-10-27T17:39:47.347321779Z","sequence_num":137910,"events":[{"type":"update","product_id":"BTC-USD","updates":[{"side":"bid","event_time":"2025-10-27T17:39:47.295463Z","price_level":"115638","new_quantity":"0"},{"side":"bid","event_time":"2025-10-27T17:39:47.295463Z","price_level":"115636.96","new_quantity":"0.00172955"},{"side":"bid","event_time":"2025-10-27T17:39:47.295463Z","price_level":"115634.02","new_quantity":"0"},{"side":"bid","event_time":"2025-10-27T17:39:47.295463Z","price_level":"115634.01","new_quantity":"0.07321915"},{"side":"bid","event_time":"2025-10-27T17:39:47.295463Z","price_level":"115629.75","new_quantity":"0.02161105"},{"side":"bid","event_time":"2025-10-27T17:39:47.295463Z","price_level":"115628.9","new_quantity":"0.085575"},{"side":"bid","event_time":"2025-10-27T17:39:47.295463Z","price_level":"115620.65","new_quantity":"0.624408"},{"side":"bid","event_time":"2025-10-27T17:39:47.295463Z","price_level":"115619","new_quantity":"0"},{"side":"bid","event_time":"2025-10-27T17:39:47.295463Z","price_level":"115617.65","new_quantity":"0.653682"},{"side":"bid","event_time":"2025-10-27T17:39:47.295463Z","price_level":"115616.82","new_quantity":"0.1297804"},{"side":"bid","event_time":"2025-10-27T17:39:47.295463Z","price_level":"115616","new_quantity":"0"},{"side":"bid","event_time":"2025-10-27T17:39:47.295463Z","price_level":"115614","new_quantity":"0"},{"side":"bid","event_time":"2025-10-27T17:39:47.295463Z","price_level":"115612","new_quantity":"0"},{"side":"bid","event_time":"2025-10-27T17:39:47.295463Z","price_level":"115610.01","new_quantity":"0.73011448"},{"side":"bid","event_time":"2025-10-27T17:39:47.295463Z","price_level":"115610","new_quantity":"0"},{"side":"bid","event_time":"2025-10-27T17:39:47.295463Z","price_level":"115600","new_quantity":"0"},{"side":"bid","event_time":"2025-10-27T17:39:47.295463Z","price_level":"115571.6","new_quantity":"1.5"},{"side":"bid","event_time":"2025-10-27T17:39:47.295463Z","price_level":"115567.71","new_quantity":"0.76394408"},{"side":"bid","event_time":"2025-10-27T17:39:47.295463Z","price_level":"115567.7","new_quantity":"0"},{"side":"bid","event_time":"2025-10-27T17:39:47.295463Z","price_level":"115567.27","new_quantity":"0"},{"side":"offer","event_time":"2025-10-27T17:39:47.295463Z","price_level":"115647.5","new_quantity":"0"},{"side":"offer","event_time":"2025-10-27T17:39:47.295463Z","price_level":"115647.51","new_quantity":"0.00007789"},{"side":"offer","event_time":"2025-10-27T17:39:47.295463Z","price_level":"115718.2","new_quantity":"0"},{"side":"offer","event_time":"2025-10-27T17:39:47.295463Z","price_level":"115718.6","new_quantity":"1"},{"side":"offer","event_time":"2025-10-27T17:39:47.295463Z","price_level":"116963.93","new_quantity":"0.07007"}]}]}
{"channel":"l2_data","client_id":"","timestamp":"2025-10-27T17:39:47.371791325Z","sequence_num":137911,"events":[{"type":"update","product_id":"ETH-USD","updates":[{"side":"bid","event_time":"2025-10-27T17:39:47.323591Z","price_level":"4218.15","new_quantity":"0.07109573"},{"side":"bid","event_time":"2025-10-27T17:39:47.323591Z","price_level":"4218.13","new_quantity":"0"},{"side":"bid","event_time":"2025-10-27T17:39:47.323591Z","price_level":"4218.09","new_quantity":"0"},{"side":"bid","event_time":"2025-10-27T17:39:47.323591Z","price_level":"4217.83","new_quantity":"0.00437089"},{"side":"bid","event_time":"2025-10-27T17:39:47.323591Z","price_level":"4217.81","new_quantity":"6.903708"},{"side":"bid","event_time":"2025-10-27T17:39:47.323591Z","price_level":"4217.52","new_quantity":"3.31535"},{"side":"bid","event_time":"2025-10-27T17:39:47.323591Z","price_level":"4217.39","new_quantity":"1.65682"},{"side":"bid","event_time":"2025-10-27T17:39:47.323591Z","price_level":"4217.28","new_quantity":"1.07083178"},{"side":"bid","event_time":"2025-10-27T17:39:47.323591Z","price_level":"4215","new_quantity":"6.14033254"},{"side":"bid","event_time":"2025-10-27T17:39:47.323591Z","price_level":"4213.52","new_quantity":"8.47723523"},{"side":"offer","event_time":"2025-10-27T17:39:47.323591Z","price_level":"4218.16","new_quantity":"0.29905307"},{"side":"offer","event_time":"2025-10-27T17:39:47.323591Z","price_level":"4218.17","new_quantity":"0"},{"side":"offer","event_time":"2025-10-27T17:39:47.323591Z","price_level":"4218.18","new_quantity":"0"},{"side":"offer","event_time":"2025-10-27T17:39:47.323591Z","price_level":"4218.19","new_quantity":"0.00237066"}]}]}
{"channel":"l2_data","client_id":"","timestamp":"2025-10-27T17:39:47.397252188Z","sequence_num":137913,"events":[{"type":"update","product_id":"BTC-USD","updates":[{"side":"bid","event_time":"2025-10-27T17:39:47.345512Z","price_level":"115636.96","new_quantity":"0.00172955"},{"side":"bid","event_time":"2025-10-27T17:39:47.345512Z","price_level":"115630.69","new_quantity":"0"},{"side":"bid","event_time":"2025-10-27T17:39:47.345512Z","price_level":"115629.75","new_quantity":"0"},{"side":"bid","event_time":"2025-10-27T17:39:47.345512Z","price_level":"115629.18","new_quantity":"0.00864833"},{"side":"bid","event_time":"2025-10-27T17:39:47.345512Z","price_level":"115628.37","new_quantity":"0.02161105"},{"side":"bid","event_time":"2025-10-27T17:39:47.345512Z","price_level":"115619","new_quantity":"0.4"},{"side":"bid","event_time":"2025-10-27T17:39:47.345512Z","price_level":"115616.82","new_quantity":"1.72948131"},{"side":"bid","event_time":"2025-10-27T17:39:47.345512Z","price_level":"115616","new_quantity":"0.4"},{"side":"bid","event_time":"2025-10-27T17:39:47.345512Z","price_level":"115614","new_quantity":"0.4"},{"side":"bid","event_time":"2025-10-27T17:39:47.345512Z","price_level":"115612","new_quantity":"2"},{"side":"bid","event_time":"2025-10-27T17:39:47.345512Z","price_level":"115610.01","new_quantity":"1.07761283"},{"side":"bid","event_time":"2025-10-27T17:39:47.345512Z","price_level":"115610","new_quantity":"1"},{"side":"bid","event_time":"2025-10-27T17:39:47.345512Z","price_level":"115597.72","new_quantity":"0.64312407"},{"side":"bid","event_time":"2025-10-27T17:39:47.345512Z","price_level":"115571.6","new_quantity":"0"},{"side":"bid","event_time":"2025-10-27T17:39:47.345512Z","price_level":"115567.7","new_quantity":"1.5"},{"side":"bid","event_time":"2025-10-27T17:39:47.345512Z","price_level":"115563.04","new_quantity":"1.19367066"},{"side":"offer","event_time":"2025-10-27T17:39:47.345512Z","price_level":"115658.37","new_quantity":"0.00432"},{"side":"offer","event_time":"2025-10-27T17:39:47.345512Z","price_level":"115691.86","new_quantity":"0"},{"side":"offer","event_time":"2025-10-27T17:39:47.345512Z","price_level":"116963.72","new_quantity":"0.07007"}]}]}
{"channel":"l2_data","client_id":"","timestamp":"2025-10-27T17:39:47.418873642Z","sequence_num":137914,"events":[{"type":"update","product_id":"ETH-USD","updates":[{"side":"bid","event_time":"2025-10-27T17:39:47.371187Z","price_level":"4218.09","new_quantity":"0.00237075"},{"side":"bid","event_time":"2025-10-27T17:39:47.371187Z","price_level":"4217.88","new_quantity":"0.09488712"},{"side":"bid","event_time":"2025-10-27T17:39:47.371187Z","price_level":"4217.83","new_quantity":"0.002"},{"side":"bid","event_time":"2025-10-27T17:39:47.371187Z","price_level":"4217.39","new_quantity":"0"},{"side":"bid","event_time":"2025-10-27T17:39:47.371187Z","price_level":"4217.38","new_quantity":"0.47179179"}]}]}
{"channel":"l2_data","client_id":"","timestamp":"2025-10-27T17:39:47.448703019Z","sequence_num":137915,"events":[{"type":"update","product_id":"BTC-USD","updates":[{"side":"bid","event_time":"2025-10-27T17:39:47.395888Z","price_level":"115636.96","new_quantity":"0"},{"side":"bid","event_time":"2025-10-27T17:39:47.395888Z","price_level":"115629.18","new_quantity":"0.00864833"},{"side":"bid","event_time":"2025-10-27T17:39:47.395888Z","price_level":"115617.65","new_quantity":"0"},{"side":"bid","event_time":"2025-10-27T17:39:47.395888Z","price_level":"115612.01","new_quantity":"0.33125981"},{"side":"bid","event_time":"2025-10-27T17:39:47.395888Z","price_level":"115610.02","new_quantity":"0"},{"side":"bid","event_time":"2025-10-27T17:39:47.395888Z","price_level":"115597.73","new_quantity":"0.53831242"},{"side":"bid","event_time":"2025-10-27T17:39:47.395888Z","price_level":"115596.99","new_quantity":"0"},{"side":"bid","event_time":"2025-10-27T17:39:47.395888Z","price_level":"115596.98","new_quantity":"0"},{"side":"bid","event_time":"2025-10-27T17:39:47.395888Z","price_level":"101183.78","new_quantity":"0.00446112"},{"side":"offer","event_time":"2025-10-27T17:39:47.395888Z","price_level":"115638.78","new_quantity":"0.02594285"},{"side":"offer","event_time":"2025-10-27T17:39:47.395888Z","price_level":"115640.35","new_quantity":"0"},{"side":"offer","event_time":"2025-10-27T17:39:47.395888Z","price_level":"115689.73","new_quantity":"0"},{"side":"offer","event_time":"2025-10-27T17:39:47.395888Z","price_level":"115694.05","new_quantity":"0.16812326"},{"side":"offer","event_time":"2025-10-27T17:39:47.395888Z","price_level":"115705.5","new_quantity":"0"},{"side":"offer","event_time":"2025-10-27T17:39:47.395888Z","price_level":"115709.99","new_quantity":"0.25574104"}]}]}
{"channel":"l2_data","client_id":"","timestamp":"2025-10-27T17:39:47.470810577Z","sequence_num":137916,"events":[{"type":"update","product_id":"ETH-USD","updates":[{"side":"bid","event_time":"2025-10-27T17:39:47.384526Z","price_level":"4216.88","new_quantity":"0"},{"side":"offer","event_time":"2025-10-27T17:39:47.384526Z","price_level":"4218.16","new_quantity":"0.33675217"}]}]}
{"channel":"l2_data","client_id":"","timestamp":"2025-10-27T17:39:47.497971337Z","sequence_num":137917,"events":[{"type":"update","product_id":"BTC-USD","updates":[{"side":"bid","event_time":"2025-10-27T17:39:47.450797Z","price_level":"115629.7","new_quantity":"0.02161105"},{"side":"bid","event_time":"2025-10-27T17:39:47.450797Z","price_level":"115628.37","new_quantity":"0"},{"side":"bid","event_time":"2025-10-27T17:39:47.450797Z","price_level":"115567.7","new_quantity":"0"},{"side":"bid","event_time":"2025-10-27T17:39:47.450797Z","price_level":"115566","new_quantity":"1.50001"},{"side":"offer","event_time":"2025-10-27T17:39:47.450797Z","price_level":"115671","new_quantity":"0"},{"side":"offer","event_time":"2025-10-27T17:39:47.450797Z","price_level":"115673.75","new_quantity":"0.13835564"},{"side":"offer","event_time":"2025-10-27T17:39:47.450797Z","price_level":"115718.2","new_quantity":"1"},{"side":"offer","event_time":"2025-10-27T17:39:47.450797Z","price_level":"115718.6","new_quantity":"0"},{"side":"offer","event_time":"2025-10-27T17:39:47.450797Z","price_level":"116963.93","new_quantity":"0"}]}]}
{"channel":"l2_data","client_id":"","timestamp":"2025-10-27T17:39:47.520870535Z","sequence_num":137918,"events":[{"type":"update","product_id":"ETH-USD","updates":[{"side":"bid","event_time":"2025-10-27T17:39:47.467199Z","price_level":"4218.11","new_quantity":"0.00237074"},{"side":"bid","event_time":"2025-10-27T17:39:47.467199Z","price_level":"4218.1","new_quantity":"1"},{"side":"bid","event_time":"2025-10-27T17:39:47.467199Z","price_level":"4218.09","new_quantity":"0"},{"side":"bid","event_time":"2025-10-27T17:39:47.467199Z","price_level":"4218.08","new_quantity":"1"},{"side":"bid","event_time":"2025-10-27T17:39:47.467199Z","price_level":"4217.65","new_quantity":"1.65853"},{"side":"bid","event_time":"2025-10-27T17:39:47.467199Z","price_level":"4216.88","new_quantity":"0.21565049"},{"side":"bid","event_time":"2025-10-27T17:39:47.467199Z","price_level":"4216.24","new_quantity":"1.4"},{"side":"bid","event_time":"2025-10-27T17:39:47.467199Z","price_level":"4214.78","new_quantity":"8.13053335"},{"side":"bid","event_time":"2025-10-27T17:39:47.467199Z","price_level":"4214.51","new_quantity":"0"},{"side":"bid","event_time":"2025-10-27T17:39:47.467199Z","price_level":"4213.7","new_quantity":"19.75243445"},{"side":"bid","event_time":"2025-10-27T17:39:47.467199Z","price_level":"4213.66","new_quantity":"0"},{"side":"bid","event_time":"2025-10-27T17:39:47.467199Z","price_level":"4212.69","new_quantity":"0.1536"},{"side":"offer","event_time":"2025-10-27T17:39:47.467199Z","price_level":"4219.59","new_quantity":"0.47484622"},{"side":"offer","event_time":"2025-10-27T17:39:47.467199Z","price_level":"4219.7","new_quantity":"0.49495661"},{"side":"offer","event_time":"2025-10-27T17:39:47.467199Z","price_level":"4220.81","new_quantity":"1.41386807"},{"side":"offer","event_time":"2025-10-27T17:39:47.467199Z","price_level":"4221.1","new_quantity":"0"},{"side":"offer","event_time":"2025-10-27T17:39:47.467199Z","price_level":"4221.38","new_quantity":"13.30214487"},{"side":"offer","event_time":"2025-10-27T17:39:47.467199Z","price_level":"4221.39","new_quantity":"1.94391607"},{"side":"offer","event_time":"2025-10-27T17:39:47.467199Z","price_level":"4221.4","new_quantity":"0"}]}]}
{"channel":"l2_data","client_id":"","timestamp":"2025-10-27T17:39:47.547172776Z","sequence_num":137919,"events":[{"type":"update","product_id":"BTC-USD","updates":[{"side":"bid","event_time":"2025-10-27T17:39:47.48111Z","price_level":"115616","new_quantity":"0"},{"side":"bid","event_time":"2025-10-27T17:39:47.48111Z","price_level":"115612.01","new_quantity":"0"},{"side":"bid","event_time":"2025-10-27T17:39:47.48111Z","price_level":"115609.08","new_quantity":"0.33126821"},{"side":"bid","event_time":"2025-10-27T17:39:47.48111Z","price_level":"115597.73","new_quantity":"0"},{"side":"bid","event_time":"2025-10-27T17:39:47.48111Z","price_level":"115590.78","new_quantity":"0.53834478"},{"side":"bid","event_time":"2025-10-27T17:39:47.48111Z","price_level":"115570.61","new_quantity":"0.76392491"},{"side":"bid","event_time":"2025-10-27T17:39:47.48111Z","price_level":"115570.6","new_quantity":"1.5"},{"side":"bid","event_time":"2025-10-27T17:39:47.48111Z","price_level":"115567.71","new_quantity":"0"},{"side":"bid","event_time":"2025-10-27T17:39:47.48111Z","price_level":"115566","new_quantity":"0.00001"},{"side":"offer","event_time":"2025-10-27T17:39:47.48111Z","price_level":"115662","new_quantity":"2"},{"side":"offer","event_time":"2025-10-27T17:39:47.48111Z","price_level":"115666","new_quantity":"0.4"},{"side":"offer","event_time":"2025-10-27T17:39:47.48111Z","price_level":"115671","new_quantity":"0.13835564"},{"side":"offer","event_time":"2025-10-27T17:39:47.48111Z","price_level":"115673.75","new_quantity":"0"},{"side":"offer","event_time":"2025-10-27T17:39:47.48111Z","price_level":"115689.73","new_quantity":"0.16812954"},{"side":"offer","event_time":"2025-10-27T17:39:47.48111Z","price_level":"115694.05","new_quantity":"0"},{"side":"offer","event_time":"2025-10-27T17:39:47.48111Z","price_level":"115705.5","new_quantity":"0.25575097"},{"side":"offer","event_time":"2025-10-27T17:39:47.48111Z","price_level":"115709.99","new_quantity":"0"},{"side":"offer","event_time":"2025-10-27T17:39:47.48111Z","price_level":"115718.1","new_quantity":"1"},{"side":"offer","event_time":"2025-10-27T17:39:47.48111Z","price_level":"115718.2","new_quantity":"0"}]}]}
{"channel":"l2_data","client_id":"","timestamp":"2025-10-27T17:39:47.571375128Z","sequence_num":137920,"events":[{"type":"update","product_id":"ETH-USD","updates":[{"side":"bid","event_time":"2025-10-27T17:39:47.515892Z","price_level":"4217.52","new_quantity":"1.65682"},{"side":"offer","event_time":"2025-10-27T17:39:47.515892Z","price_level":"4219.5","new_quantity":"0.001"},{"side":"offer","event_time":"2025-10-27T17:39:47.515892Z","price_level":"4219.8","new_quantity":"10"},{"side":"offer","event_time":"2025-10-27T17:39:47.515892Z","price_level":"4220.5","new_quantity":"0.10081343"}]}]}
{"channel":"l2_data","client_id":"","timestamp":"2025-10-27T17:39:47.596586387Z","sequence_num":137922,"events":[{"type":"update","product_id":"BTC-USD","updates":[{"side":"bid","event_time":"2025-10-27T17:39:47.538618Z","price_level":"115616","new_quantity":"0.4"},{"side":"offer","event_time":"2025-10-27T17:39:47.538618Z","price_level":"115638.61","new_quantity":"0.00244122"},{"side":"offer","event_time":"2025-10-27T17:39:47.538618Z","price_level":"115662","new_quantity":"0"},{"side":"offer","event_time":"2025-10-27T17:39:47.538618Z","price_level":"115666","new_quantity":"0"},{"side":"offer","event_time":"2025-10-27T17:39:47.538618Z","price_level":"115669.97","new_quantity":"0.0345892"}]}]}
{"channel":"l2_data","client_id":"","timestamp":"2025-10-27T17:39:47.621762899Z","sequence_num":137924,"events":[{"type":"update","product_id":"ETH-USD","updates":[{"side":"bid","event_time":"2025-10-27T17:39:47.571807Z","price_level":"4216.88","new_quantity":"0"},{"side":"bid","event_time":"2025-10-27T17:39:47.571807Z","price_level":"4216.26","new_quantity":"4.211308"},{"side":"bid","event_time":"2025-10-27T17:39:47.571807Z","price_level":"4191.59","new_quantity":"0"},{"side":"offer","event_time":"2025-10-27T17:39:47.571807Z","price_level":"4218.16","new_quantity":"0.3483982"},{"side":"offer","event_time":"2025-10-27T17:39:47.571807Z","price_level":"4219.4","new_quantity":"10"},{"side":"offer","event_time":"2025-10-27T17:39:47.571807Z","price_level":"4219.48","new_quantity":"0"},{"side":"offer","event_time":"2025-10-27T17:39:47.571807Z","price_level":"4219.5","new_quantity":"10.001"},{"side":"offer","event_time":"2025-10-27T17:39:47.571807Z","price_level":"4219.6","new_quantity":"20"},{"side":"offer","event_time":"2025-10-27T17:39:47.571807Z","price_level":"4221.36","new_quantity":"13.30220789"},{"side":"offer","event_time":"2025-10-27T17:39:47.571807Z","price_level":"4221.37","new_quantity":"1.94391607"},{"side":"offer","event_time":"2025-10-27T17:39:47.571807Z","price_level":"4221.38","new_quantity":"0"},{"side":"offer","event_time":"2025-10-27T17:39:47.571807Z","price_level":"4221.39","new_quantity":"0"}]}]}
{"channel":"l2_data","client_id":"","timestamp":"2025-10-27T17:39:47.647376661Z","sequence_num":137926,"events":[{"type":"update","product_id":"BTC-USD","updates":[{"side":"bid","event_time":"2025-10-27T17:39:47.602338Z","price_level":"114893.59","new_quantity":"0"},{"side":"offer","event_time":"2025-10-27T17:39:47.602338Z","price_level":"115666","new_quantity":"0"}]}]}
{"channel":"l2_data","client_id":"","timestamp":"2025-10-27T17:39:47.669636864Z","sequence_num":137927,"events":[{"type":"update","product_id":"ETH-USD","updates":[{"side":"bid","event_time":"2025-10-27T17:39:47.613531Z","price_level":"4217.65","new_quantity":"3.31611"},{"side":"bid","event_time":"2025-10-27T17:39:47.613531Z","price_level":"4216.88","new_quantity":"0.21565049"}]}]}
{"channel":"l2_data","client_id":"","timestamp":"2025-10-27T17:39:47.698220858Z","sequence_num":137928,"events":[{"type":"update","product_id":"BTC-USD","updates":[{"side":"bid","event_time":"2025-10-27T17:39:47.650316Z","price_level":"115643.52","new_quantity":"0.00008648"},{"side":"bid","event_time":"2025-10-27T17:39:47.650316Z","price_level":"115640","new_quantity":"0.0203"},{"side":"bid","event_time":"2025-10-27T17:39:47.650316Z","price_level":"115638.62","new_quantity":"0.00769815"},{"side":"bid","event_time":"2025-10-27T17:39:47.650316Z","price_level":"115638.6","new_quantity":"0.00000095"},{"side":"bid","event_time":"2025-10-27T17:39:47.650316Z","price_level":"115638","new_quantity":"0.0203"},{"side":"bid","event_time":"2025-10-27T17:39:47.650316Z","price_level":"115628.91","new_quantity":"0.0006164"},{"side":"bid","event_time":"2025-10-27T17:39:47.650316Z","price_level":"115617.65","new_quantity":"0.673372"},{"side":"bid","event_time":"2025-10-27T17:39:47.650316Z","price_level":"115612.01","new_quantity":"0.33125981"},{"side":"bid","event_time":"2025-10-27T17:39:47.650316Z","price_level":"115609.08","new_quantity":"0"},{"side":"bid","event_time":"2025-10-27T17:39:47.650316Z","price_level":"115597.73","new_quantity":"0.53831242"},{"side":"bid","event_time":"2025-10-27T17:39:47.650316Z","price_level":"115590.78","new_quantity":"0"},{"side":"bid","event_time":"2025-10-27T17:39:47.650316Z","price_level":"115580.02","new_quantity":"0.76386271"},{"side":"bid","event_time":"2025-10-27T17:39:47.650316Z","price_level":"115571.1","new_quantity":"1.5"},{"side":"bid","event_time":"2025-10-27T17:39:47.650316Z","price_level":"115570.61","new_quantity":"0"},{"side":"bid","event_time":"2025-10-27T17:39:47.650316Z","price_level":"115570.6","new_quantity":"0"},{"side":"bid","event_time":"2025-10-27T17:39:47.650316Z","price_level":"115496.77","new_quantity":"0"},{"side":"bid","event_time":"2025-10-27T17:39:47.650316Z","price_level":"114918.53","new_quantity":"0.045"},{"side":"bid","event_time":"2025-10-27T17:39:47.650316Z","price_level":"114894.76","new_quantity":"0.00216165"},{"side":"bid","event_time":"2025-10-27T17:39:47.650316Z","price_level":"114316.97","new_quantity":"0.07007"},{"side":"bid","event_time":"2025-10-27T17:39:47.650316Z","price_level":"114315.75","new_quantity":"0"},{"side":"bid","event_time":"2025-10-27T17:39:47.650316Z","price_level":"114101","new_quantity":"0.0001"},{"side":"bid","event_time":"2025-10-27T17:39:47.650316Z","price_level":"101183.78","new_quantity":"0"},{"side":"offer","event_time":"2025-10-27T17:39:47.650316Z","price_level":"115638.61","new_quantity":"0"},{"side":"offer","event_time":"2025-10-27T17:39:47.650316Z","price_level":"115638.78","new_quantity":"0"},{"side":"offer","event_time":"2025-10-27T17:39:47.650316Z","price_level":"115640.92","new_quantity":"0"},{"side":"offer","event_time":"2025-10-27T17:39:47.650316Z","price_level":"115643.53","new_quantity":"0.25296415"},{"side":"offer","event_time":"2025-10-27T17:39:47.650316Z","price_level":"115647.51","new_quantity":"0"},{"side":"offer","event_time":"2025-10-27T17:39:47.650316Z","price_level":"115647.52","new_quantity":"0"},{"side":"offer","event_time":"2025-10-27T17:39:47.650316Z","price_level":"115651.83","new_quantity":"0"},{"side":"offer","event_time":"2025-10-27T17:39:47.650316Z","price_level":"115656.32","new_quantity":"0.00007786"},{"side":"offer","event_time":"2025-10-27T17:39:47.650316Z","price_level":"115661.57","new_quantity":"0.00280479"},{"side":"offer","event_time":"2025-10-27T17:39:47.650316Z","price_level":"115681.27","new_quantity":"0"},{"side":"offer","event_time":"2025-10-27T17:39:47.650316Z","price_level":"115689.73","new_quantity":"0"},{"side":"offer","event_time":"2025-10-27T17:39:47.650316Z","price_level":"115694.05","new_quantity":"0.16812326"},{"side":"offer","event_time":"2025-10-27T17:39:47.650316Z","price_level":"115705.5","new_quantity":"0"},{"side":"offer","event_time":"2025-10-27T17:39:47.650316Z","price_level":"115709.99","new_quantity":"0.25574104"},{"side":"offer","event_time":"2025-10-27T17:39:47.650316Z","price_level":"115718.1","new_quantity":"0"},{"side":"offer","event_time":"2025-10-27T17:39:47.650316Z","price_level":"115718.3","new_quantity":"1"}]}]}
{"channel":"l2_data","client_id":"","timestamp":"2025-10-27T17:39:47.720606326Z","sequence_num":137929,"events":[{"type":"update","product_id":"ETH-USD","updates":[{"side":"bid","event_time":"2025-10-27T17:39:47.681658Z","price_level":"4218.15","new_quantity":"0"},{"side":"bid","event_time":"2025-10-27T17:39:47.681658Z","price_level":"4218.13","new_quantity":"0.07109573"},{"side":"bid","event_time":"2025-10-27T17:39:47.681658Z","price_level":"4218.09","new_quantity":"0"},{"side":"bid","event_time":"2025-10-27T17:39:47.681658Z","price_level":"4217.52","new_quantity":"0"},{"side":"offer","event_time":"2025-10-27T17:39:47.681658Z","price_level":"4218.14","new_quantity":"0.46723475"},{"side":"offer","event_time":"2025-10-27T17:39:47.681658Z","price_level":"4218.15","new_quantity":"0"},{"side":"offer","event_time":"2025-10-27T17:39:47.681658Z","price_level":"4218.16","new_quantity":"0"},{"side":"offer","event_time":"2025-10-27T17:39:47.681658Z","price_level":"4221.34","new_quantity":"13.30227091"},{"side":"offer","event_time":"2025-10-27T17:39:47.681658Z","price_level":"4221.35","new_quantity":"1.94391607"},{"side":"offer","event_time":"2025-10-27T17:39:47.681658Z","price_level":"4221.36","new_quantity":"0"},{"side":"offer","event_time":"2025-10-27T17:39:47.681658Z","price_level":"4221.37","new_quantity":"0"},{"side":"offer","event_time":"2025-10-27T17:39:47.681658Z","price_level":"4222.38","new_quantity":"0.66893505"},{"side":"offer","event_time":"2025-10-27T17:39:47.681658Z","price_level":"4223.69","new_quantity":"1.2786"},{"side":"offer","event_time":"2025-10-27T17:39:47.681658Z","price_level":"4244.78","new_quantity":"0.1536"}]}]}
{"channel":"l2_data","client_id":"","timestamp":"2025-10-27T17:39:47.747175303Z","sequence_num":137930,"events":[{"type":"update","product_id":"BTC-USD","updates":[{"side":"bid","event_time":"2025-10-27T17:39:47.702977Z","price_level":"115640","new_quantity":"0"},{"side":"bid","event_time":"2025-10-27T17:39:47.702977Z","price_level":"115629.18","new_quantity":"0"},{"side":"bid","event_time":"2025-10-27T17:39:47.702977Z","price_level":"115628.8","new_quantity":"0"},{"side":"bid","event_time":"2025-10-27T17:39:47.702977Z","price_level":"115627.45","new_quantity":"0.00864846"},{"side":"bid","event_time":"2025-10-27T17:39:47.702977Z","price_level":"115626.4","new_quantity":"0.16536"},{"side":"bid","event_time":"2025-10-27T17:39:47.702977Z","price_level":"115621.31","new_quantity":"0"},{"side":"bid","event_time":"2025-10-27T17:39:47.702977Z","price_level":"115621.28","new_quantity":"0"},{"side":"bid","event_time":"2025-10-27T17:39:47.702977Z","price_level":"115620.65","new_quantity":"0.88313079"},{"side":"bid","event_time":"2025-10-27T17:39:47.702977Z","price_level":"115618.99","new_quantity":"0.00432"},{"side":"bid","event_time":"2025-10-27T17:39:47.702977Z","price_level":"115618.96","new_quantity":"0.00432"},{"side":"bid","event_time":"2025-10-27T17:39:47.702977Z","price_level":"115618.23","new_quantity":"0.08649154"},{"side":"bid","event_time":"2025-10-27T17:39:47.702977Z","price_level":"115616.81","new_quantity":"0"},{"side":"offer","event_time":"2025-10-27T17:39:47.702977Z","price_level":"115643.53","new_quantity":"0.25621495"},{"side":"offer","event_time":"2025-10-27T17:39:47.702977Z","price_level":"115662","new_quantity":"0"},{"side":"offer","event_time":"2025-10-27T17:39:47.702977Z","price_level":"115666","new_quantity":"0"}]}]}
{"channel":"l2_data","client_id":"","timestamp":"2025-10-27T17:39:47.769105592Z","sequence_num":137931,"events":[{"type":"update","product_id":"ETH-USD","updates":[{"side":"bid","event_time":"2025-10-27T17:39:47.723276Z","price_level":"4217.81","new_quantity":"12.9806578"},{"side":"bid","event_time":"2025-10-27T17:39:47.723276Z","price_level":"4217.7","new_quantity":"10"},{"side":"bid","event_time":"2025-10-27T17:39:47.723276Z","price_level":"4217.65","new_quantity":"1.65758"},{"side":"bid","event_time":"2025-10-27T17:39:47.723276Z","price_level":"4217.42","new_quantity":"1.65853"}]}]}
{"channel":"l2_data","client_id":"","timestamp":"2025-10-27T17:39:47.797829104Z","sequence_num":137932,"events":[{"type":"update","product_id":"BTC-USD","updates":[{"side":"bid","event_time":"2025-10-27T17:39:47.732854Z","price_level":"115597.74","new_quantity":"1.53681818"},{"side":"bid","event_time":"2025-10-27T17:39:47.732854Z","price_level":"115571.1","new_quantity":"0"},{"side":"bid","event_time":"2025-10-27T17:39:47.732854Z","price_level":"115570.5","new_quantity":"1.5"},{"side":"bid","event_time":"2025-10-27T17:39:47.732854Z","price_level":"115552.35","new_quantity":"0.81388956"},{"side":"bid","event_time":"2025-10-27T17:39:47.732854Z","price_level":"115493.02","new_quantity":"0.0412921"},{"side":"offer","event_time":"2025-10-27T17:39:47.732854Z","price_level":"115662","new_quantity":"2"},{"side":"offer","event_time":"2025-10-27T17:39:47.732854Z","price_level":"115666","new_quantity":"0.4"},{"side":"offer","event_time":"2025-10-27T17:39:47.732854Z","price_level":"115689.99","new_quantity":"0.43682019"}]}]}
{"channel":"l2_data","client_id":"","timestamp":"2025-10-27T17:39:47.818910088Z","sequence_num":137933,"events":[{"type":"update","product_id":"ETH-USD","updates":[{"side":"offer","event_time":"2025-10-27T17:39:47.775223Z","price_level":"4244.78","new_quantity":"0"}]}]}
